Workbook

Sheet Team Selection
A1: VITTORIOSA LAWN TENNIS CLUB
A2: ANTES INSURANCE TEAM TOURNAMENT 2023
B3: A | C3: B | D3: C | E3: D | F3: E | G3: F
A4: CAPTAIN | B4: Grace Barbara | C4: Francesca Sciortino | D4: Victor Rutter | E4: Roberto Murdocco | F4: Darrell Pace | G4: Tiziana Anastasi
A6: MEN
A7: A1 | B7: Marc Vella Bonnici | C7: Matthew Mifsud | D7: Marcelo Villanueva | E7: Jesmond Pule' | F7: Clayton Zammit Cesare | G7: Kurt Carabott
A8: A2 | B8: Eric Roca | C8: Melchior Farrugia | D8: Trevor Rutter | E8: Clyde Grech | F8: Duncan D'Alessandro | G8: Adrian Chetcuti
A9: A3 | B9: Keith Micallef | C9: Nikolai Belli | D9: Jean Carl Azzopardi | E9: Andrew Pule' | F9: Manuel Bonello | G9: John Azzopardi
A11: B1 | B11: David Schembri | C11: Luigi Porto | D11: Ivan Cachia | E11: Fotios Evangelou | F11: Marco Mercieca | G11: Ryan Mizzi
A12: B2 | B12: George Grech | C12: Gio Marcos | D12: Jonathan Vella | E12: Chi Chi Canonce | F12: Eric Micallef | G12: James Farrugia
A13: B3 | B13: Roderick Spiteri | C13: Clint Agius | D13: Richard Byrne | E13: Kevin Formosa | F13: Gabriel Pace | G13: Willem Steenkamer
A15: C1 | B15: Joe Carabott | C15: Gene Zammit | D15: Stephen Belli | E15: Roberto Murdocco | F15: Manuel Gatt | G15: Max Anastasi
A16: C2 | B16: Clive Silvio Borg | C16: Neville Sciriha | D16: Charles Sacco | E16: Sebastian Attard | F16: Manuel Mifsud | G16: Mavric Sawyer
A17: C3 | B17: Ray Ciantar | C17: Alain Frendo | D17: Kristen Cachia | E17: Frans Ellul | F17: Etienne Formosa Carabez | G17: Julian Esposito
A18: C4 | B18: Jean Paul Vella | C18: Aaron Micallef Piccione | D18: Victor Rutter | E18: Ryan Ebejer | F18: Darrell Pace | G18: Ivan Saliba
A20: D1 | B20: Charles Micallef | C20: Matthew Schembri | D20: Simone Re | E20: Twanny Pule' | F20: Isaac Joseph Zammit | G20: Max Anastasi Jr.
A21: D2 | B21: David Camilleri | C21: Conrad Treeby Ward | D21: Charles Borg Grech | E21: Kenneth Caruana | F21: Joseph Randich | G21: Dunstan Vella
A22: D3 | B22: Dorian Demanuele | C22: Ralf Bahmuller | D22: Donald Deguzman | E22: Cory Greenland | F22: Sean Cachia | G22: Mario Abdilla
A24: LADIES
A25: A1 | B25: Sharon Mizzi | C25: Alexia Spiteri Willets | D25: Christine Schembri | E25: Annemarie Mangion | F25: Lara Pule' | G25: Martina Cuschieri
A26: A2 | B26: Elaine Grech | C26: Lucienne Meli | D26: Alison Muscat | E26: Olivia Belli | F26: Kirsty Mercieca | G26: Natalya Abela
A27: A3 | B27: Celeste Zammit Marquette | C27: Doriana Portelli | D27: Amanda Falzon | E27: Anthea Gauci | F27: Annabelle Abela | G27: Yanika Pace
A29: B1 | B29: Brenda Baldacchino | C29: Anabel Borg | D29: Silvana Portelli | E29: Romina Gauci | F29: Alexia Gouder | G29: Tiziana Anastasi
A30: B2 | B30: Deborah Farrugia | C30: Kristina Briffa | D30: Kelsey Gauci | E30: Julie Spiteri | F30: Daniela Curmi | G30: Mariska Steenkamer
A31: B3 | B31: Angele Pule' | C31: Francesca Sciortino | D31: Marthese Camoin | E31: Jennifer Mifsud | F31: Vanessa Vella | G31: Carmen Difesa
A32: B4 | B32: Lonia Carabott | C32: Jin Attard | D32: Nancy Wong | E32: Sarah Axiaq | F32: Diane Debono | G32: Ann-Marie Attard
A34: C1 | B34: Christine Seychell | C34: Helga Azzopardi | D34: Yvonne Borg Cardona | E34: Mary Borg | F34: Elisa Sacco | G34: Tanya Cassar
A35: C2 | B35: Frances Saliba Hersey | C35: Marica Cassar | D35: Christabelle Chetcuti | E35: Stefania Camilleri | F35: Jodie Stivala | G35: Heidi Tabone
A36: C3 | B36: Mary Ciantar | C36: Maria Ellul | D36: Anna Fenech | E36: Christine Scerri | F36: Claire Genovese | G36: Sabrina Xuereb

Sheet Encounters played
A2: VITTORIOSA LAWN TENNIS CLUB
A3: ANTES INSURANCE TEAM TOURNAMENT 2023
B5: Day | C5: 1 | D5: 2 | E5: 3 | F5: 4 | G5: 5 | H5: Total | J5: Day | K5: 1 | L5: 2 | M5: 3 | N5: 4 | O5: 5 | P5: Total
A6: A | B6: ='Team Selection'!B4 -> Grace Barbara | I6: B | J6: ='Team Selection'!C4 -> Francesca Sciortino
A7: A1 | B7: ='Team Selection'!B7 -> Marc Vella Bonnici | C7: {=IF(OR('Day 1'!$C$6:$K$113='Encounters played'!B7),1,"")} -> 1 | D7: {=IF(OR('Day 2'!$C$6:$K$113='Encounters played'!B7),1,"")} -> 1 | E7: {=IF(OR('Day 3'!$C$6:$K$113='Encounters played'!B7),1,"")} -> 1 | F7: {=IF(OR('Day 4'!$C$6:$K$113='Encounters played'!B7),1,"")} | G7: {=IF(OR('Day 5'!$C$6:$K$113='Encounters played'!B7),1,"")} -> 1 | H7: =SUM(C7:G7) -> 4 | I7: A1 | J7: ='Team Selection'!C7 -> Matthew Mifsud | K7: {=IF(OR('Day 1'!$C$6:$K$113='Encounters played'!J7),1,"")} -> 1 | L7: {=IF(OR('Day 2'!$C$6:$K$113='Encounters played'!J7),1,"")} -> 1 | M7: {=IF(OR('Day 3'!$C$6:$K$113='Encounters played'!J7),1,"")} -> 1 | N7: {=IF(OR('Day 4'!$C$6:$K$113='Encounters played'!J7),1,"")} | O7: {=IF(OR('Day 5'!$C$6:$K$113='Encounters played'!J7),1,"")} -> 1 | P7: =SUM(K7:O7) -> 4
A8: A2 | B8: ='Team Selection'!B8 -> Eric Roca | C8: {=IF(OR('Day 1'!$C$6:$K$113='Encounters played'!B8),1,"")} -> 1 | D8: {=IF(OR('Day 2'!$C$6:$K$113='Encounters played'!B8),1,"")} | E8: {=IF(OR('Day 3'!$C$6:$K$113='Encounters played'!B8),1,"")} | F8: {=IF(OR('Day 4'!$C$6:$K$113='Encounters played'!B8),1,"")} -> 1 | G8: {=IF(OR('Day 5'!$C$6:$K$113='Encounters played'!B8),1,"")} -> 1 | H8: =SUM(C8:G8) -> 3 | I8: A2 | J8: ='Team Selection'!C8 -> Melchior Farrugia | K8: {=IF(OR('Day 1'!$C$6:$K$113='Encounters played'!J8),1,"")} -> 1 | L8: {=IF(OR('Day 2'!$C$6:$K$113='Encounters played'!J8),1,"")} | M8: {=IF(OR('Day 3'!$C$6:$K$113='Encounters played'!J8),1,"")} | N8: {=IF(OR('Day 4'!$C$6:$K$113='Encounters played'!J8),1,"")} -> 1 | O8: {=IF(OR('Day 5'!$C$6:$K$113='Encounters played'!J8),1,"")} -> 1 | P8: =SUM(K8:O8) -> 3
A9: A3 | B9: ='Team Selection'!B9 -> Keith Micallef | C9: {=IF(OR('Day 1'!$C$6:$K$113='Encounters played'!B9),1,"")} | D9: {=IF(OR('Day 2'!$C$6:$K$113='Encounters played'!B9),1,"")} -> 1 | E9: {=IF(OR('Day 3'!$C$6:$K$113='Encounters played'!B9),1,"")} -> 1 | F9: {=IF(OR('Day 4'!$C$6:$K$113='Encounters played'!B9),1,"")} -> 1 | G9: {=IF(OR('Day 5'!$C$6:$K$113='Encounters played'!B9),1,"")} | H9: =SUM(C9:G9) -> 3 | I9: A3 | J9: ='Team Selection'!C9 -> Nikolai Belli | K9: {=IF(OR('Day 1'!$C$6:$K$113='Encounters played'!J9),1,"")} | L9: {=IF(OR('Day 2'!$C$6:$K$113='Encounters played'!J9),1,"")} -> 1 | M9: {=IF(OR('Day 3'!$C$6:$K$113='Encounters played'!J9),1,"")} -> 1 | N9: {=IF(OR('Day 4'!$C$6:$K$113='Encounters played'!J9),1,"")} -> 1 | O9: {=IF(OR('Day 5'!$C$6:$K$113='Encounters played'!J9),1,"")} | P9: =SUM(K9:O9) -> 3
A10: B1 | B10: ='Team Selection'!B11 -> David Schembri | C10: {=IF(OR('Day 1'!$C$6:$K$113='Encounters played'!B10),1,"")} -> 1 | D10: {=IF(OR('Day 2'!$C$6:$K$113='Encounters played'!B10),1,"")} -> 1 | E10: {=IF(OR('Day 3'!$C$6:$K$113='Encounters played'!B10),1,"")} | F10: {=IF(OR('Day 4'!$C$6:$K$113='Encounters played'!B10),1,"")} -> 1 | G10: {=IF(OR('Day 5'!$C$6:$K$113='Encounters played'!B10),1,"")} -> 1 | H10: =SUM(C10:G10) -> 4 | I10: B1 | J10: ='Team Selection'!C11 -> Luigi Porto | K10: {=IF(OR('Day 1'!$C$6:$K$113='Encounters played'!J10),1,"")} -> 1 | L10: {=IF(OR('Day 2'!$C$6:$K$113='Encounters played'!J10),1,"")} -> 1 | M10: {=IF(OR('Day 3'!$C$6:$K$113='Encounters played'!J10),1,"")} | N10: {=IF(OR('Day 4'!$C$6:$K$113='Encounters played'!J10),1,"")} -> 1 | O10: {=IF(OR('Day 5'!$C$6:$K$113='Encounters played'!J10),1,"")} -> 1 | P10: =SUM(K10:O10) -> 4
A11: B2 | B11: ='Team Selection'!B12 -> George Grech | C11: {=IF(OR('Day 1'!$C$6:$K$113='Encounters played'!B11),1,"")} | D11: {=IF(OR('Day 2'!$C$6:$K$113='Encounters played'!B11),1,"")} -> 1 | E11: {=IF(OR('Day 3'!$C$6:$K$113='Encounters played'!B11),1,"")} -> 1 | F11: {=IF(OR('Day 4'!$C$6:$K$113='Encounters played'!B11),1,"")} | G11: 1 | H11: =SUM(C11:G11) -> 3 | I11: B2 | J11: ='Team Selection'!C12 -> Gio Marcos | K11: {=IF(OR('Day 1'!$C$6:$K$113='Encounters played'!J11),1,"")} | L11: 1 | M11: 1 | N11: {=IF(OR('Day 4'!$C$6:$K$113='Encounters played'!J11),1,"")} -> 1 | O11: {=IF(OR('Day 5'!$C$6:$K$113='Encounters played'!J11),1,"")} | P11: =SUM(K11:O11) -> 3
A12: B3 | B12: ='Team Selection'!B13 -> Roderick Spiteri | C12: {=IF(OR('Day 1'!$C$6:$K$113='Encounters played'!B12),1,"")} -> 1 | D12: {=IF(OR('Day 2'!$C$6:$K$113='Encounters played'!B12),1,"")} | E12: {=IF(OR('Day 3'!$C$6:$K$113='Encounters played'!B12),1,"")} -> 1 | F12: {=IF(OR('Day 4'!$C$6:$K$113='Encounters played'!B12),1,"")} -> 1 | G12: {=IF(OR('Day 5'!$C$6:$K$113='Encounters played'!B12),1,"")} | H12: =SUM(C12:G12) -> 3 | I12: B3 | J12: ='Team Selection'!C13 -> Clint Agius | K12: {=IF(OR('Day 1'!$C$6:$K$113='Encounters played'!J12),1,"")} -> 1 | L12: {=IF(OR('Day 2'!$C$6:$K$113='Encounters played'!J12),1,"")} | M12: {=IF(OR('Day 3'!$C$6:$K$113='Encounters played'!J12),1,"")} -> 1 | N12: {=IF(OR('Day 4'!$C$6:$K$113='Encounters played'!J12),1,"")} | O12: {=IF(OR('Day 5'!$C$6:$K$113='Encounters played'!J12),1,"")} -> 1 | P12: =SUM(K12:O12) -> 3
A13: C1 | B13: ='Team Selection'!B15 -> Joe Carabott | C13: {=IF(OR('Day 1'!$C$6:$K$113='Encounters played'!B13),1,"")} -> 1 | D13: {=IF(OR('Day 2'!$C$6:$K$113='Encounters played'!B13),1,"")} | E13: {=IF(OR('Day 3'!$C$6:$K$113='Encounters played'!B13),1,"")} -> 1 | F13: {=IF(OR('Day 4'!$C$6:$K$113='Encounters played'!B13),1,"")} -> 1 | G13: {=IF(OR('Day 5'!$C$6:$K$113='Encounters played'!B13),1,"")} -> 1 | H13: =SUM(C13:G13) -> 4 | I13: C1 | J13: ='Team Selection'!C15 -> Gene Zammit | K13: {=IF(OR('Day 1'!$C$6:$K$113='Encounters played'!J13),1,"")} -> 1 | L13: {=IF(OR('Day 2'!$C$6:$K$113='Encounters played'!J13),1,"")} -> 1 | M13: {=IF(OR('Day 3'!$C$6:$K$113='Encounters played'!J13),1,"")} -> 1 | N13: {=IF(OR('Day 4'!$C$6:$K$113='Encounters played'!J13),1,"")} | O13: {=IF(OR('Day 5'!$C$6:$K$113='Encounters played'!J13),1,"")} | P13: =SUM(K13:O13) -> 3
A14: C2 | B14: ='Team Selection'!B16 -> Clive Silvio Borg | C14: {=IF(OR('Day 1'!$C$6:$K$113='Encounters played'!B14),1,"")} -> 1 | D14: {=IF(OR('Day 2'!$C$6:$K$113='Encounters played'!B14),1,"")} -> 1 | E14: {=IF(OR('Day 3'!$C$6:$K$113='Encounters played'!B14),1,"")} | F14: {=IF(OR('Day 4'!$C$6:$K$113='Encounters played'!B14),1,"")} -> 1 | G14: {=IF(OR('Day 5'!$C$6:$K$113='Encounters played'!B14),1,"")} -> 1 | H14: =SUM(C14:G14) -> 4 | I14: C2 | J14: ='Team Selection'!C16 -> Neville Sciriha | K14: {=IF(OR('Day 1'!$C$6:$K$113='Encounters played'!J14),1,"")} -> 1 | L14: {=IF(OR('Day 2'!$C$6:$K$113='Encounters played'!J14),1,"")} -> 1 | M14: {=IF(OR('Day 3'!$C$6:$K$113='Encounters played'!J14),1,"")} | N14: {=IF(OR('Day 4'!$C$6:$K$113='Encounters played'!J14),1,"")} -> 1 | O14: {=IF(OR('Day 5'!$C$6:$K$113='Encounters played'!J14),1,"")} -> 1 | P14: =SUM(K14:O14) -> 4
A15: C3 | B15: ='Team Selection'!B17 -> Ray Ciantar | C15: {=IF(OR('Day 1'!$C$6:$K$113='Encounters played'!B15),1,"")} -> 1 | D15: {=IF(OR('Day 2'!$C$6:$K$113='Encounters played'!B15),1,"")} -> 1 | E15: {=IF(OR('Day 3'!$C$6:$K$113='Encounters played'!B15),1,"")} -> 1 | F15: {=IF(OR('Day 4'!$C$6:$K$113='Encounters played'!B15),1,"")} | G15: {=IF(OR('Day 5'!$C$6:$K$113='Encounters played'!B15),1,"")} -> 1 | H15: =SUM(C15:G15) -> 4 | I15: C3 | J15: ='Team Selection'!C17 -> Alain Frendo | K15: {=IF(OR('Day 1'!$C$6:$K$113='Encounters played'!J15),1,"")} | L15: {=IF(OR('Day 2'!$C$6:$K$113='Encounters played'!J15),1,"")} -> 1 | M15: {=IF(OR('Day 3'!$C$6:$K$113='Encounters played'!J15),1,"")} -> 1 | N15: {=IF(OR('Day 4'!$C$6:$K$113='Encounters played'!J15),1,"")} -> 1 | O15: {=IF(OR('Day 5'!$C$6:$K$113='Encounters played'!J15),1,"")} -> 1 | P15: =SUM(K15:O15) -> 4
A16: C4 | B16: ='Team Selection'!B18 -> Jean Paul Vella | C16: {=IF(OR('Day 1'!$C$6:$K$113='Encounters played'!B16),1,"")} | D16: {=IF(OR('Day 2'!$C$6:$K$113='Encounters played'!B16),1,"")} -> 1 | E16: {=IF(OR('Day 3'!$C$6:$K$113='Encounters played'!B16),1,"")} -> 1 | F16: {=IF(OR('Day 4'!$C$6:$K$113='Encounters played'!B16),1,"")} -> 1 | G16: {=IF(OR('Day 5'!$C$6:$K$113='Encounters played'!B16),1,"")} | H16: =SUM(C16:G16) -> 3 | I16: C4 | J16: ='Team Selection'!C18 -> Aaron Micallef Piccione | K16: 1 | L16: {=IF(OR('Day 2'!$C$6:$K$113='Encounters played'!J16),1,"")} | M16: 1 | N16: {=IF(OR('Day 4'!$C$6:$K$113='Encounters played'!J16),1,"")} -> 1 | O16: {=IF(OR('Day 5'!$C$6:$K$113='Encounters played'!J16),1,"")} -> 1 | P16: =SUM(K16:O16) -> 4
A17: D1 | B17: ='Team Selection'!B20 -> Charles Micallef | C17: {=IF(OR('Day 1'!$C$6:$K$113='Encounters played'!B17),1,"")} | D17: {=IF(OR('Day 2'!$C$6:$K$113='Encounters played'!B17),1,"")} -> 1 | E17: {=IF(OR('Day 3'!$C$6:$K$113='Encounters played'!B17),1,"")} -> 1 | F17: {=IF(OR('Day 4'!$C$6:$K$113='Encounters played'!B17),1,"")} -> 1 | G17: {=IF(OR('Day 5'!$C$6:$K$113='Encounters played'!B17),1,"")} -> 1 | H17: =SUM(C17:G17) -> 4 | I17: D1 | J17: ='Team Selection'!C20 -> Matthew Schembri | K17: {=IF(OR('Day 1'!$C$6:$K$113='Encounters played'!J17),1,"")} | L17: {=IF(OR('Day 2'!$C$6:$K$113='Encounters played'!J17),1,"")} -> 1 | M17: {=IF(OR('Day 3'!$C$6:$K$113='Encounters played'!J17),1,"")} -> 1 | N17: {=IF(OR('Day 4'!$C$6:$K$113='Encounters played'!J17),1,"")} -> 1 | O17: {=IF(OR('Day 5'!$C$6:$K$113='Encounters played'!J17),1,"")} -> 1 | P17: =SUM(K17:O17) -> 4
A18: D2 | B18: ='Team Selection'!B21 -> David Camilleri | C18: {=IF(OR('Day 1'!$C$6:$K$113='Encounters played'!B18),1,"")} -> 1 | D18: {=IF(OR('Day 2'!$C$6:$K$113='Encounters played'!B18),1,"")} -> 1 | E18: {=IF(OR('Day 3'!$C$6:$K$113='Encounters played'!B18),1,"")} | F18: {=IF(OR('Day 4'!$C$6:$K$113='Encounters played'!B18),1,"")} -> 1 | G18: {=IF(OR('Day 5'!$C$6:$K$113='Encounters played'!B18),1,"")} | H18: =SUM(C18:G18) -> 3 | I18: D2 | J18: ='Team Selection'!C21 -> Conrad Treeby Ward | K18: {=IF(OR('Day 1'!$C$6:$K$113='Encounters played'!J18),1,"")} -> 1 | L18: {=IF(OR('Day 2'!$C$6:$K$113='Encounters played'!J18),1,"")} -> 1 | M18: {=IF(OR('Day 3'!$C$6:$K$113='Encounters played'!J18),1,"")} | N18: {=IF(OR('Day 4'!$C$6:$K$113='Encounters played'!J18),1,"")} | O18: {=IF(OR('Day 5'!$C$6:$K$113='Encounters played'!J18),1,"")} -> 1 | P18: =SUM(K18:O18) -> 3
A19: D3 | B19: ='Team Selection'!B22 -> Dorian Demanuele | C19: {=IF(OR('Day 1'!$C$6:$K$113='Encounters played'!B19),1,"")} -> 1 | D19: {=IF(OR('Day 2'!$C$6:$K$113='Encounters played'!B19),1,"")} | E19: {=IF(OR('Day 3'!$C$6:$K$113='Encounters played'!B19),1,"")} -> 1 | F19: {=IF(OR('Day 4'!$C$6:$K$113='Encounters played'!B19),1,"")} | G19: {=IF(OR('Day 5'!$C$6:$K$113='Encounters played'!B19),1,"")} -> 1 | H19: =SUM(C19:G19) -> 3 | I19: D3 | J19: ='Team Selection'!C22 -> Ralf Bahmuller | K19: {=IF(OR('Day 1'!$C$6:$K$113='Encounters played'!J19),1,"")} -> 1 | L19: {=IF(OR('Day 2'!$C$6:$K$113='Encounters played'!J19),1,"")} | M19: {=IF(OR('Day 3'!$C$6:$K$113='Encounters played'!J19),1,"")} -> 1 | N19: {=IF(OR('Day 4'!$C$6:$K$113='Encounters played'!J19),1,"")} -> 1 | O19: {=IF(OR('Day 5'!$C$6:$K$113='Encounters played'!J19),1,"")} | P19: =SUM(K19:O19) -> 3
A21: A1 | B21: ='Team Selection'!B25 -> Sharon Mizzi | C21: {=IF(OR('Day 1'!$C$6:$K$113='Encounters played'!B21),1,"")} -> 1 | D21: {=IF(OR('Day 2'!$C$6:$K$113='Encounters played'!B21),1,"")} -> 1 | E21: {=IF(OR('Day 3'!$C$6:$K$113='Encounters played'!B21),1,"")} -> 1 | F21: {=IF(OR('Day 4'!$C$6:$K$113='Encounters played'!B21),1,"")} | G21: {=IF(OR('Day 5'!$C$6:$K$113='Encounters played'!B21),1,"")} -> 1 | H21: =SUM(C21:G21) -> 4 | I21: A1 | J21: ='Team Selection'!C25 -> Alexia Spiteri Willets | K21: {=IF(OR('Day 1'!$C$6:$K$113='Encounters played'!J21),1,"")} -> 1 | L21: {=IF(OR('Day 2'!$C$6:$K$113='Encounters played'!J21),1,"")} -> 1 | M21: {=IF(OR('Day 3'!$C$6:$K$113='Encounters played'!J21),1,"")} -> 1 | N21: {=IF(OR('Day 4'!$C$6:$K$113='Encounters played'!J21),1,"")} | O21: {=IF(OR('Day 5'!$C$6:$K$113='Encounters played'!J21),1,"")} | P21: =SUM(K21:O21) -> 3
A22: A2 | B22: ='Team Selection'!B26 -> Elaine Grech | C22: {=IF(OR('Day 1'!$C$6:$K$113='Encounters played'!B22),1,"")} -> 1 | D22: {=IF(OR('Day 2'!$C$6:$K$113='Encounters played'!B22),1,"")} -> 1 | E22: {=IF(OR('Day 3'!$C$6:$K$113='Encounters played'!B22),1,"")} | F22: {=IF(OR('Day 4'!$C$6:$K$113='Encounters played'!B22),1,"")} -> 1 | G22: {=IF(OR('Day 5'!$C$6:$K$113='Encounters played'!B22),1,"")} | H22: =SUM(C22:G22) -> 3 | I22: A2 | J22: ='Team Selection'!C26 -> Lucienne Meli | K22: {=IF(OR('Day 1'!$C$6:$K$113='Encounters played'!J22),1,"")} -> 1 | L22: {=IF(OR('Day 2'!$C$6:$K$113='Encounters played'!J22),1,"")} | M22: {=IF(OR('Day 3'!$C$6:$K$113='Encounters played'!J22),1,"")} -> 1 | N22: {=IF(OR('Day 4'!$C$6:$K$113='Encounters played'!J22),1,"")} -> 1 | O22: {=IF(OR('Day 5'!$C$6:$K$113='Encounters played'!J22),1,"")} | P22: =SUM(K22:O22) -> 3
A23: A3 | B23: ='Team Selection'!B27 -> Celeste Zammit Marquette | C23: {=IF(OR('Day 1'!$C$6:$K$113='Encounters played'!B23),1,"")} | D23: {=IF(OR('Day 2'!$C$6:$K$113='Encounters played'!B23),1,"")} | E23: {=IF(OR('Day 3'!$C$6:$K$113='Encounters played'!B23),1,"")} -> 1 | F23: {=IF(OR('Day 4'!$C$6:$K$113='Encounters played'!B23),1,"")} -> 1 | G23: {=IF(OR('Day 5'!$C$6:$K$113='Encounters played'!B23),1,"")} -> 1 | H23: =SUM(C23:G23) -> 3 | I23: A3 | J23: ='Team Selection'!C27 -> Doriana Portelli | K23: {=IF(OR('Day 1'!$C$6:$K$113='Encounters played'!J23),1,"")} | L23: {=IF(OR('Day 2'!$C$6:$K$113='Encounters played'!J23),1,"")} -> 1 | M23: {=IF(OR('Day 3'!$C$6:$K$113='Encounters played'!J23),1,"")} | N23: {=IF(OR('Day 4'!$C$6:$K$113='Encounters played'!J23),1,"")} -> 1 | O23: {=IF(OR('Day 5'!$C$6:$K$113='Encounters played'!J23),1,"")} -> 1 | P23: =SUM(K23:O23) -> 3
A24: B1 | B24: ='Team Selection'!B29 -> Brenda Baldacchino | C24: {=IF(OR('Day 1'!$C$6:$K$113='Encounters played'!B24),1,"")} -> 1 | D24: {=IF(OR('Day 2'!$C$6:$K$113='Encounters played'!B24),1,"")} -> 1 | E24: {=IF(OR('Day 3'!$C$6:$K$113='Encounters played'!B24),1,"")} -> 1 | F24: {=IF(OR('Day 4'!$C$6:$K$113='Encounters played'!B24),1,"")} | G24: 1 | H24: =SUM(C24:G24) -> 4 | I24: B1 | J24: ='Team Selection'!C29 -> Anabel Borg | K24: {=IF(OR('Day 1'!$C$6:$K$113='Encounters played'!J24),1,"")} | L24: {=IF(OR('Day 2'!$C$6:$K$113='Encounters played'!J24),1,"")} -> 1 | M24: {=IF(OR('Day 3'!$C$6:$K$113='Encounters played'!J24),1,"")} -> 1 | N24: {=IF(OR('Day 4'!$C$6:$K$113='Encounters played'!J24),1,"")} -> 1 | O24: {=IF(OR('Day 5'!$C$6:$K$113='Encounters played'!J24),1,"")} -> 1 | P24: =SUM(K24:O24) -> 4
A25: B2 | B25: ='Team Selection'!B30 -> Deborah Farrugia | C25: {=IF(OR('Day 1'!$C$6:$K$113='Encounters played'!B25),1,"")} -> 1 | D25: {=IF(OR('Day 2'!$C$6:$K$113='Encounters played'!B25),1,"")} -> 1 | E25: {=IF(OR('Day 3'!$C$6:$K$113='Encounters played'!B25),1,"")} | F25: {=IF(OR('Day 4'!$C$6:$K$113='Encounters played'!B25),1,"")} -> 1 | G25: {=IF(OR('Day 5'!$C$6:$K$113='Encounters played'!B25),1,"")} -> 1 | H25: =SUM(C25:G25) -> 4 | I25: B2 | J25: ='Team Selection'!C30 -> Kristina Briffa | K25: {=IF(OR('Day 1'!$C$6:$K$113='Encounters played'!J25),1,"")} -> 1 | L25: {=IF(OR('Day 2'!$C$6:$K$113='Encounters played'!J25),1,"")} -> 1 | M25: {=IF(OR('Day 3'!$C$6:$K$113='Encounters played'!J25),1,"")} -> 1 | N25: {=IF(OR('Day 4'!$C$6:$K$113='Encounters played'!J25),1,"")} | O25: {=IF(OR('Day 5'!$C$6:$K$113='Encounters played'!J25),1,"")} -> 1 | P25: =SUM(K25:O25) -> 4
A26: B3 | B26: ='Team Selection'!B31 -> Angele Pule' | C26: {=IF(OR('Day 1'!$C$6:$K$113='Encounters played'!B26),1,"")} -> 1 | D26: {=IF(OR('Day 2'!$C$6:$K$113='Encounters played'!B26),1,"")} | E26: {=IF(OR('Day 3'!$C$6:$K$113='Encounters played'!B26),1,"")} -> 1 | F26: {=IF(OR('Day 4'!$C$6:$K$113='Encounters played'!B26),1,"")} -> 1 | G26: {=IF(OR('Day 5'!$C$6:$K$113='Encounters played'!B26),1,"")} -> 1 | H26: =SUM(C26:G26) -> 4 | I26: B3 | J26: ='Team Selection'!C31 -> Francesca Sciortino | K26: {=IF(OR('Day 1'!$C$6:$K$113='Encounters played'!J26),1,"")} -> 1 | L26: 1 | M26: {=IF(OR('Day 3'!$C$6:$K$113='Encounters played'!J26),1,"")} | N26: {=IF(OR('Day 4'!$C$6:$K$113='Encounters played'!J26),1,"")} -> 1 | O26: {=IF(OR('Day 5'!$C$6:$K$113='Encounters played'!J26),1,"")} -> 1 | P26: =SUM(K26:O26) -> 4
A27: B4 | B27: ='Team Selection'!B32 -> Lonia Carabott | C27: {=IF(OR('Day 1'!$C$6:$K$113='Encounters played'!B27),1,"")} | D27: {=IF(OR('Day 2'!$C$6:$K$113='Encounters played'!B27),1,"")} -> 1 | E27: {=IF(OR('Day 3'!$C$6:$K$113='Encounters played'!B27),1,"")} -> 1 | F27: {=IF(OR('Day 4'!$C$6:$K$113='Encounters played'!B27),1,"")} -> 1 | G27: {=IF(OR('Day 5'!$C$6:$K$113='Encounters played'!B27),1,"")} | H27: =SUM(C27:G27) -> 3 | I27: B4 | J27: ='Team Selection'!C32 -> Jin Attard | K27: {=IF(OR('Day 1'!$C$6:$K$113='Encounters played'!J27),1,"")} -> 1 | L27: {=IF(OR('Day 2'!$C$6:$K$113='Encounters played'!J27),1,"")} | M27: {=IF(OR('Day 3'!$C$6:$K$113='Encounters played'!J27),1,"")} -> 1 | N27: {=IF(OR('Day 4'!$C$6:$K$113='Encounters played'!J27),1,"")} -> 1 | O27: {=IF(OR('Day 5'!$C$6:$K$113='Encounters played'!J27),1,"")} | P27: =SUM(K27:O27) -> 3
A28: C1 | B28: ='Team Selection'!B34 -> Christine Seychell | C28: {=IF(OR('Day 1'!$C$6:$K$113='Encounters played'!B28),1,"")} -> 1 | D28: {=IF(OR('Day 2'!$C$6:$K$113='Encounters played'!B28),1,"")} | E28: {=IF(OR('Day 3'!$C$6:$K$113='Encounters played'!B28),1,"")} -> 1 | F28: {=IF(OR('Day 4'!$C$6:$K$113='Encounters played'!B28),1,"")} | G28: {=IF(OR('Day 5'!$C$6:$K$113='Encounters played'!B28),1,"")} -> 1 | H28: =SUM(C28:G28) -> 3 | I28: C1 | J28: ='Team Selection'!C34 -> Helga Azzopardi | K28: {=IF(OR('Day 1'!$C$6:$K$113='Encounters played'!J28),1,"")} -> 1 | L28: {=IF(OR('Day 2'!$C$6:$K$113='Encounters played'!J28),1,"")} -> 1 | M28: {=IF(OR('Day 3'!$C$6:$K$113='Encounters played'!J28),1,"")} -> 1 | N28: {=IF(OR('Day 4'!$C$6:$K$113='Encounters played'!J28),1,"")} -> 1 | O28: {=IF(OR('Day 5'!$C$6:$K$113='Encounters played'!J28),1,"")} | P28: =SUM(K28:O28) -> 4
A29: C2 | B29: ='Team Selection'!B35 -> Frances Saliba Hersey | C29: {=IF(OR('Day 1'!$C$6:$K$113='Encounters played'!B29),1,"")} -> 1 | D29: {=IF(OR('Day 2'!$C$6:$K$113='Encounters played'!B29),1,"")} -> 1 | E29: {=IF(OR('Day 3'!$C$6:$K$113='Encounters played'!B29),1,"")} | F29: {=IF(OR('Day 4'!$C$6:$K$113='Encounters played'!B29),1,"")} -> 1 | G29: {=IF(OR('Day 5'!$C$6:$K$113='Encounters played'!B29),1,"")} -> 1 | H29: =SUM(C29:G29) -> 4 | I29: C2 | J29: ='Team Selection'!C35 -> Marica Cassar | K29: {=IF(OR('Day 1'!$C$6:$K$113='Encounters played'!J29),1,"")} -> 1 | L29: {=IF(OR('Day 2'!$C$6:$K$113='Encounters played'!J29),1,"")} | M29: {=IF(OR('Day 3'!$C$6:$K$113='Encounters played'!J29),1,"")} | N29: 1 | O29: {=IF(OR('Day 5'!$C$6:$K$113='Encounters played'!J29),1,"")} -> 1 | P29: =SUM(K29:O29) -> 3
A30: C3 | B30: ='Team Selection'!B36 -> Mary Ciantar | C30: {=IF(OR('Day 1'!$C$6:$K$113='Encounters played'!B30),1,"")} | D30: {=IF(OR('Day 2'!$C$6:$K$113='Encounters played'!B30),1,"")} -> 1 | E30: {=IF(OR('Day 3'!$C$6:$K$113='Encounters played'!B30),1,"")} -> 1 | F30: {=IF(OR('Day 4'!$C$6:$K$113='Encounters played'!B30),1,"")} -> 1 | G30: {=IF(OR('Day 5'!$C$6:$K$113='Encounters played'!B30),1,"")} | H30: =SUM(C30:G30) -> 3 | I30: C3 | J30: ='Team Selection'!C36 -> Maria Ellul | K30: {=IF(OR('Day 1'!$C$6:$K$113='Encounters played'!J30),1,"")} | L30: {=IF(OR('Day 2'!$C$6:$K$113='Encounters played'!J30),1,"")} -> 1 | M30: {=IF(OR('Day 3'!$C$6:$K$113='Encounters played'!J30),1,"")} -> 1 | N30: {=IF(OR('Day 4'!$C$6:$K$113='Encounters played'!J30),1,"")} | O30: {=IF(OR('Day 5'!$C$6:$K$113='Encounters played'!J30),1,"")} -> 1 | P30: =SUM(K30:O30) -> 3
B36: Day | C36: 1 | D36: 2 | E36: 3 | F36: 4 | G36: 5 | H36: Total | J36: Day | K36: 1 | L36: 2 | M36: 3 | N36: 4 | O36: 5 | P36: Total
A37: C | B37: ='Team Selection'!D4 -> Victor Rutter | I37: D | J37: ='Team Selection'!E4 -> Roberto Murdocco
A38: A1 | B38: ='Team Selection'!D7 -> Marcelo Villanueva | C38: {=IF(OR('Day 1'!$C$6:$K$113='Encounters played'!B38),1,"")} -> 1 | D38: {=IF(OR('Day 2'!$C$6:$K$113='Encounters played'!B38),1,"")} -> 1 | E38: {=IF(OR('Day 3'!$C$6:$K$113='Encounters played'!B38),1,"")} -> 1 | F38: {=IF(OR('Day 4'!$C$6:$K$113='Encounters played'!B38),1,"")} -> 1 | G38: {=IF(OR('Day 5'!$C$6:$K$113='Encounters played'!B38),1,"")} | H38: =SUM(C38:G38) -> 4 | I38: A1 | J38: ='Team Selection'!E7 -> Jesmond Pule' | K38: {=IF(OR('Day 1'!$C$6:$K$113='Encounters played'!J38),1,"")} -> 1 | L38: {=IF(OR('Day 2'!$C$6:$K$113='Encounters played'!J38),1,"")} -> 1 | M38: {=IF(OR('Day 3'!$C$6:$K$113='Encounters played'!J38),1,"")} | N38: {=IF(OR('Day 4'!$C$6:$K$113='Encounters played'!J38),1,"")} -> 1 | O38: {=IF(OR('Day 5'!$C$6:$K$113='Encounters played'!J38),1,"")} -> 1 | P38: =SUM(K38:O38) -> 4
A39: A2 | B39: ='Team Selection'!D8 -> Trevor Rutter | C39: {=IF(OR('Day 1'!$C$6:$K$113='Encounters played'!B39),1,"")} -> 1 | D39: {=IF(OR('Day 2'!$C$6:$K$113='Encounters played'!B39),1,"")} | E39: {=IF(OR('Day 3'!$C$6:$K$113='Encounters played'!B39),1,"")} -> 1 | F39: {=IF(OR('Day 4'!$C$6:$K$113='Encounters played'!B39),1,"")} | G39: {=IF(OR('Day 5'!$C$6:$K$113='Encounters played'!B39),1,"")} -> 1 | H39: =SUM(C39:G39) -> 3 | I39: A2 | J39: ='Team Selection'!E8 -> Clyde Grech | K39: {=IF(OR('Day 1'!$C$6:$K$113='Encounters played'!J39),1,"")} -> 1 | L39: {=IF(OR('Day 2'!$C$6:$K$113='Encounters played'!J39),1,"")} | M39: {=IF(OR('Day 3'!$C$6:$K$113='Encounters played'!J39),1,"")} -> 1 | N39: {=IF(OR('Day 4'!$C$6:$K$113='Encounters played'!J39),1,"")} | O39: {=IF(OR('Day 5'!$C$6:$K$113='Encounters played'!J39),1,"")} -> 1 | P39: =SUM(K39:O39) -> 3
A40: A3 | B40: ='Team Selection'!D9 -> Jean Carl Azzopardi | C40: {=IF(OR('Day 1'!$C$6:$K$113='Encounters played'!B40),1,"")} | D40: {=IF(OR('Day 2'!$C$6:$K$113='Encounters played'!B40),1,"")} -> 1 | E40: {=IF(OR('Day 3'!$C$6:$K$113='Encounters played'!B40),1,"")} | F40: {=IF(OR('Day 4'!$C$6:$K$113='Encounters played'!B40),1,"")} -> 1 | G40: {=IF(OR('Day 5'!$C$6:$K$113='Encounters played'!B40),1,"")} -> 1 | H40: =SUM(C40:G40) -> 3 | I40: A3 | J40: ='Team Selection'!E9 -> Andrew Pule' | K40: {=IF(OR('Day 1'!$C$6:$K$113='Encounters played'!J40),1,"")} | L40: {=IF(OR('Day 2'!$C$6:$K$113='Encounters played'!J40),1,"")} -> 1 | M40: {=IF(OR('Day 3'!$C$6:$K$113='Encounters played'!J40),1,"")} -> 1 | N40: {=IF(OR('Day 4'!$C$6:$K$113='Encounters played'!J40),1,"")} -> 1 | O40: {=IF(OR('Day 5'!$C$6:$K$113='Encounters played'!J40),1,"")} | P40: =SUM(K40:O40) -> 3
A41: B1 | B41: ='Team Selection'!D11 -> Ivan Cachia | C41: {=IF(OR('Day 1'!$C$6:$K$113='Encounters played'!B41),1,"")} -> 1 | D41: {=IF(OR('Day 2'!$C$6:$K$113='Encounters played'!B41),1,"")} | E41: {=IF(OR('Day 3'!$C$6:$K$113='Encounters played'!B41),1,"")} -> 1 | F41: {=IF(OR('Day 4'!$C$6:$K$113='Encounters played'!B41),1,"")} -> 1 | G41: {=IF(OR('Day 5'!$C$6:$K$113='Encounters played'!B41),1,"")} -> 1 | H41: =SUM(C41:G41) -> 4 | I41: B1 | J41: ='Team Selection'!E11 -> Fotios Evangelou | K41: {=IF(OR('Day 1'!$C$6:$K$113='Encounters played'!J41),1,"")} -> 1 | L41: {=IF(OR('Day 2'!$C$6:$K$113='Encounters played'!J41),1,"")} | M41: {=IF(OR('Day 3'!$C$6:$K$113='Encounters played'!J41),1,"")} -> 1 | N41: {=IF(OR('Day 4'!$C$6:$K$113='Encounters played'!J41),1,"")} -> 1 | O41: {=IF(OR('Day 5'!$C$6:$K$113='Encounters played'!J41),1,"")} -> 1 | P41: =SUM(K41:O41) -> 4
A42: B2 | B42: ='Team Selection'!D12 -> Jonathan Vella | C42: 1 | D42: {=IF(OR('Day 2'!$C$6:$K$113='Encounters played'!B42),1,"")} -> 1 | E42: {=IF(OR('Day 3'!$C$6:$K$113='Encounters played'!B42),1,"")} | F42: {=IF(OR('Day 4'!$C$6:$K$113='Encounters played'!B42),1,"")} | G42: {=IF(OR('Day 5'!$C$6:$K$113='Encounters played'!B42),1,"")} -> 1 | H42: =SUM(C42:G42) -> 3 | I42: B2 | J42: ='Team Selection'!E12 -> Chi Chi Canonce | K42: {=IF(OR('Day 1'!$C$6:$K$113='Encounters played'!J42),1,"")} -> 1 | L42: {=IF(OR('Day 2'!$C$6:$K$113='Encounters played'!J42),1,"")} -> 1 | M42: {=IF(OR('Day 3'!$C$6:$K$113='Encounters played'!J42),1,"")} | N42: {=IF(OR('Day 4'!$C$6:$K$113='Encounters played'!J42),1,"")} -> 1 | O42: {=IF(OR('Day 5'!$C$6:$K$113='Encounters played'!J42),1,"")} | P42: =SUM(K42:O42) -> 3
A43: B3 | B43: ='Team Selection'!D13 -> Richard Byrne | C43: {=IF(OR('Day 1'!$C$6:$K$113='Encounters played'!B43),1,"")} | D43: {=IF(OR('Day 2'!$C$6:$K$113='Encounters played'!B43),1,"")} -> 1 | E43: {=IF(OR('Day 3'!$C$6:$K$113='Encounters played'!B43),1,"")} -> 1 | F43: {=IF(OR('Day 4'!$C$6:$K$113='Encounters played'!B43),1,"")} -> 1 | G43: {=IF(OR('Day 5'!$C$6:$K$113='Encounters played'!B43),1,"")} | H43: =SUM(C43:G43) -> 3 | I43: B3 | J43: ='Team Selection'!E13 -> Kevin Formosa | K43: {=IF(OR('Day 1'!$C$6:$K$113='Encounters played'!J43),1,"")} | L43: {=IF(OR('Day 2'!$C$6:$K$113='Encounters played'!J43),1,"")} -> 1 | M43: {=IF(OR('Day 3'!$C$6:$K$113='Encounters played'!J43),1,"")} -> 1 | N43: {=IF(OR('Day 4'!$C$6:$K$113='Encounters played'!J43),1,"")} | O43: {=IF(OR('Day 5'!$C$6:$K$113='Encounters played'!J43),1,"")} -> 1 | P43: =SUM(K43:O43) -> 3
A44: C1 | B44: ='Team Selection'!D15 -> Stephen Belli | C44: {=IF(OR('Day 1'!$C$6:$K$113='Encounters played'!B44),1,"")} -> 1 | D44: {=IF(OR('Day 2'!$C$6:$K$113='Encounters played'!B44),1,"")} -> 1 | E44: {=IF(OR('Day 3'!$C$6:$K$113='Encounters played'!B44),1,"")} -> 1 | F44: {=IF(OR('Day 4'!$C$6:$K$113='Encounters played'!B44),1,"")} | G44: 1 | H44: =SUM(C44:G44) -> 4 | I44: C1 | J44: ='Team Selection'!E15 -> Roberto Murdocco | K44: {=IF(OR('Day 1'!$C$6:$K$113='Encounters played'!J44),1,"")} -> 1 | L44: {=IF(OR('Day 2'!$C$6:$K$113='Encounters played'!J44),1,"")} -> 1 | M44: {=IF(OR('Day 3'!$C$6:$K$113='Encounters played'!J44),1,"")} -> 1 | N44: {=IF(OR('Day 4'!$C$6:$K$113='Encounters played'!J44),1,"")} -> 1 | O44: {=IF(OR('Day 5'!$C$6:$K$113='Encounters played'!J44),1,"")} | P44: =SUM(K44:O44) -> 4
A45: C2 | B45: ='Team Selection'!D16 -> Charles Sacco | C45: {=IF(OR('Day 1'!$C$6:$K$113='Encounters played'!B45),1,"")} | D45: {=IF(OR('Day 2'!$C$6:$K$113='Encounters played'!B45),1,"")} -> 1 | E45: {=IF(OR('Day 3'!$C$6:$K$113='Encounters played'!B45),1,"")} | F45: {=IF(OR('Day 4'!$C$6:$K$113='Encounters played'!B45),1,"")} -> 1 | G45: {=IF(OR('Day 5'!$C$6:$K$113='Encounters played'!B45),1,"")} -> 1 | H45: =SUM(C45:G45) -> 3 | I45: C2 | J45: ='Team Selection'!E16 -> Sebastian Attard | K45: {=IF(OR('Day 1'!$C$6:$K$113='Encounters played'!J45),1,"")} -> 1 | L45: {=IF(OR('Day 2'!$C$6:$K$113='Encounters played'!J45),1,"")} | M45: {=IF(OR('Day 3'!$C$6:$K$113='Encounters played'!J45),1,"")} -> 1 | N45: {=IF(OR('Day 4'!$C$6:$K$113='Encounters played'!J45),1,"")} -> 1 | O45: {=IF(OR('Day 5'!$C$6:$K$113='Encounters played'!J45),1,"")} -> 1 | P45: =SUM(K45:O45) -> 4
A46: C3 | B46: ='Team Selection'!D17 -> Kristen Cachia | C46: {=IF(OR('Day 1'!$C$6:$K$113='Encounters played'!B46),1,"")} -> 1 | D46: {=IF(OR('Day 2'!$C$6:$K$113='Encounters played'!B46),1,"")} | E46: {=IF(OR('Day 3'!$C$6:$K$113='Encounters played'!B46),1,"")} -> 1 | F46: {=IF(OR('Day 4'!$C$6:$K$113='Encounters played'!B46),1,"")} -> 1 | G46: {=IF(OR('Day 5'!$C$6:$K$113='Encounters played'!B46),1,"")} -> 1 | H46: =SUM(C46:G46) -> 4 | I46: C3 | J46: ='Team Selection'!E17 -> Frans Ellul | K46: {=IF(OR('Day 1'!$C$6:$K$113='Encounters played'!J46),1,"")} -> 1 | L46: {=IF(OR('Day 2'!$C$6:$K$113='Encounters played'!J46),1,"")} -> 1 | M46: {=IF(OR('Day 3'!$C$6:$K$113='Encounters played'!J46),1,"")} | N46: {=IF(OR('Day 4'!$C$6:$K$113='Encounters played'!J46),1,"")} -> 1 | O46: {=IF(OR('Day 5'!$C$6:$K$113='Encounters played'!J46),1,"")} -> 1 | P46: =SUM(K46:O46) -> 4
A47: C4 | B47: ='Team Selection'!D18 -> Victor Rutter | C47: {=IF(OR('Day 1'!$C$6:$K$113='Encounters played'!B47),1,"")} -> 1 | D47: {=IF(OR('Day 2'!$C$6:$K$113='Encounters played'!B47),1,"")} -> 1 | E47: {=IF(OR('Day 3'!$C$6:$K$113='Encounters played'!B47),1,"")} -> 1 | F47: {=IF(OR('Day 4'!$C$6:$K$113='Encounters played'!B47),1,"")} -> 1 | G47: {=IF(OR('Day 5'!$C$6:$K$113='Encounters played'!B47),1,"")} | H47: =SUM(C47:G47) -> 4 | I47: C4 | J47: ='Team Selection'!E18 -> Ryan Ebejer | K47: {=IF(OR('Day 1'!$C$6:$K$113='Encounters played'!J47),1,"")} | L47: {=IF(OR('Day 2'!$C$6:$K$113='Encounters played'!J47),1,"")} -> 1 | M47: {=IF(OR('Day 3'!$C$6:$K$113='Encounters played'!J47),1,"")} -> 1 | N47: {=IF(OR('Day 4'!$C$6:$K$113='Encounters played'!J47),1,"")} | O47: {=IF(OR('Day 5'!$C$6:$K$113='Encounters played'!J47),1,"")} -> 1 | P47: =SUM(K47:O47) -> 3
A48: D1 | B48: ='Team Selection'!D20 -> Simone Re | C48: {=IF(OR('Day 1'!$C$6:$K$113='Encounters played'!B48),1,"")} -> 1 | D48: {=IF(OR('Day 2'!$C$6:$K$113='Encounters played'!B48),1,"")} -> 1 | E48: {=IF(OR('Day 3'!$C$6:$K$113='Encounters played'!B48),1,"")} | F48: {=IF(OR('Day 4'!$C$6:$K$113='Encounters played'!B48),1,"")} -> 1 | G48: {=IF(OR('Day 5'!$C$6:$K$113='Encounters played'!B48),1,"")} -> 1 | H48: =SUM(C48:G48) -> 4 | I48: D1 | J48: ='Team Selection'!E20 -> Twanny Pule' | K48: {=IF(OR('Day 1'!$C$6:$K$113='Encounters played'!J48),1,"")} -> 1 | L48: {=IF(OR('Day 2'!$C$6:$K$113='Encounters played'!J48),1,"")} -> 1 | M48: {=IF(OR('Day 3'!$C$6:$K$113='Encounters played'!J48),1,"")} -> 1 | N48: {=IF(OR('Day 4'!$C$6:$K$113='Encounters played'!J48),1,"")} | O48: {=IF(OR('Day 5'!$C$6:$K$113='Encounters played'!J48),1,"")} -> 1 | P48: =SUM(K48:O48) -> 4
...

Sheet Standings
B2: VITTORIOSA LAWN TENNIS CLUB
B3: ANTES INSURANCE TEAM TOURNAMENT 2023
D6: ROUND 1
E8: Day 1 | F8: Total Day 1 | H8: Day 2 | I8: Total Day 2 | K8: Day 3 | L8: Total Day 3 | N8: Day 4 | O8: Total Day 4 | Q8: Day 5 | R8: Total Day 5 | T8: Total Round 1
E9: G | F9: G | H9: G | I9: G | K9: G | L9: G | N9: G | O9: G | Q9: G | R9: G | T9: G
B11: TEAM A: | C11: ='Team Selection'!B4 -> Grace Barbara | D11: Wednesday | E11: =SUM('Day 1'!J25) -> 34 | F11: =E11+E12 -> 66 | H11: =SUM('Day 2'!J60) -> 32 | I11: =H11+H12 -> 64 | K11: =SUM('Day 3'!J95) -> 35 | L11: =K11+K12 -> 79 | N11: =SUM('Day 4'!J95) -> 45 | O11: =N11+N12 -> 82 | Q11: =SUM('Day 5'!J25) -> 33 | R11: =Q11+Q12 -> 75 | T11: =+F11+I11+L11+O11+R11 -> 366
D12: Friday | E12: =SUM('Day 1'!J40) -> 32 | H12: =SUM('Day 2'!J75) -> 32 | K12: =SUM('Day 3'!J110) -> 44 | N12: =SUM('Day 4'!J110) -> 37 | Q12: =SUM('Day 5'!J40) -> 42
B14: TEAM B: | C14: ='Team Selection'!C4 -> Francesca Sciortino | D14: Wednesday | E14: =SUM('Day 1'!J95) -> 34 | F14: =E14+E15 -> 63 | H14: =SUM('Day 2'!J25) -> 38 | I14: =H14+H15 -> 80 | K14: =SUM('Day 3'!J60) -> 42 | L14: =K14+K15 -> 77 | N14: =SUM('Day 4'!K95) -> 28 | O14: =N14+N15 -> 63 | Q14: =SUM('Day 5'!J60) -> 38 | R14: =Q14+Q15 -> 79 | T14: =+F14+I14+L14+O14+R14 -> 362
D15: Friday | E15: =SUM('Day 1'!J110) -> 29 | H15: ='Day 2'!J40 -> 42 | K15: =SUM('Day 3'!J75) -> 35 | N15: =SUM('Day 4'!K110) -> 35 | Q15: ='Day 5'!J75 -> 41
B17: TEAM C: | C17: ='Team Selection'!D4 -> Victor Rutter | D17: Wednesday | E17: =SUM('Day 1'!K25) -> 38 | F17: =E17+E18 -> 79 | H17: =SUM('Day 2'!J95) -> 37 | I17: =H17+H18 -> 73 | K17: =SUM('Day 3'!J25) -> 42 | L17: =K17+K18 -> 67 | N17: =SUM('Day 4'!J60) -> 33 | O17: =N17+N18 -> 58 | Q17: =SUM('Day 5'!K60) -> 34 | R17: =Q17+Q18 -> 66 | T17: =+F17+I17+L17+O17+R17 -> 343
D18: Friday | E18: =SUM('Day 1'!K40) -> 41 | H18: ='Day 2'!J110 -> 36 | K18: =SUM('Day 3'!J40) -> 25 | N18: =SUM('Day 4'!J75) -> 25 | Q18: ='Day 5'!K75 -> 32
B20: TEAM D: | C20: ='Team Selection'!E4 -> Roberto Murdocco | D20: Wednesday | E20: =SUM('Day 1'!J60) -> 33 | F20: =E20+E21 -> 68 | H20: =SUM('Day 2'!K95) -> 36 | I20: =H20+H21 -> 72 | K20: =SUM('Day 3'!K60) -> 31 | L20: =K20+K21 -> 68 | N20: =SUM('Day 4'!J25) -> 40 | O20: =N20+N21 -> 77 | Q20: =SUM('Day 5'!K25) -> 39 | R20: =Q20+Q21 -> 70 | T20: =+F20+I20+L20+O20+R20 -> 355
D21: Friday | E21: =SUM('Day 1'!J75) -> 35 | H21: ='Day 2'!K110 -> 36 | K21: =SUM('Day 3'!K75) -> 37 | N21: =SUM('Day 4'!J40) -> 37 | Q21: =SUM('Day 5'!K40) -> 31
B23: TEAM E: | C23: ='Team Selection'!F4 -> Darrell Pace | D23: Wednesday | E23: =SUM('Day 1'!K60) -> 39 | F23: =E23+E24 -> 77 | H23: =SUM('Day 2'!K25) -> 35 | I23: =H23+H24 -> 65 | K23: =SUM('Day 3'!K95) -> 37 | L23: =K23+K24 -> 66 | N23: =SUM('Day 4'!K60) -> 39 | O23: =N23+N24 -> 87 | Q23: =SUM('Day 5'!J95) -> 40 | R23: =Q23+Q24 -> 77 | T23: =+F23+I23+L23+O23+R23 -> 372
D24: Friday | E24: =SUM('Day 1'!K75) -> 38 | H24: ='Day 2'!K40 -> 30 | K24: =SUM('Day 3'!K110) -> 29 | N24: =SUM('Day 4'!K75) -> 48 | Q24: =SUM('Day 5'!J110) -> 37
B26: TEAM F: | C26: ='Team Selection'!G4 -> Tiziana Anastasi | D26: Wednesday | E26: =SUM('Day 1'!K95) -> 39 | F26: =E26+E27 -> 82 | H26: =SUM('Day 2'!K60) -> 41 | I26: =H26+H27 -> 81 | K26: =SUM('Day 3'!K25) -> 31 | L26: =K26+K27 -> 78 | N26: =SUM('Day 4'!K25) -> 32 | O26: =N26+N27 -> 68 | Q26: =SUM('Day 5'!K95) -> 32 | R26: =Q26+Q27 -> 68 | T26: =+F26+I26+L26+O26+R26 -> 377
D27: Friday | E27: =SUM('Day 1'!K110) -> 43 | H27: ='Day 2'!K75 -> 40 | K27: =SUM('Day 3'!K40) -> 47 | N27: =SUM('Day 4'!K40) -> 36 | Q27: =SUM('Day 5'!K110) -> 36
B33: Winners:
B35: Runners Up:

Sheet Day 1
C1: ANTES INSURANCE TEAM TOURNAMENT 2023
C6: DAY 1 - 24/05/2023 & 26/05/2023
C9: Court 1
C11: Time | D11: Rubber | E11: Team A: Grace Barbara | G11: vs | H11: Team C: Victor Rutter | J11: Games
C13: 6.30 pm | D13: Men D | E13: David Camilleri | F13: Dorian Demanuele | H13: Simone Re | I13: Charles Borg Grech | J13: 9 | K13: 9
C16: 7.45 pm | D16: Lad C | E16: Christine Seychell | F16: Frances Saliba Hersey | G16: vs | H16: Yvonne Borg Cardona | I16: Christabelle Chetcuti | J16: 9 | K16: 9
C19: 9.00 pm | D19: Men A | E19: Marc Vella Bonnici | F19: Eric Roca | G19: vs | H19: Trevor Rutter | I19: Marcelo Villanueva | J19: 6 | K19: 12
C22: 6.30 pm | D22: Men B | E22: David Schembri | F22: Roderick Spiteri | G22: vs | H22: Ivan Cachia | I22: Jonathon Vella | J22: 10 | K22: 8
C24: 19
C25: Total Day 1 A | J25: =SUM(J13:J23) -> 34 | K25: =SUM(K13:K23) -> 38
C28: 6.30 pm | D28: Lad B | E28: Brenda Baldacchino | F28: Angele Pule' | G28: vs | H28: Marthese Camoin | I28: Nancy Wong | J28: 4 | K28: 14
C31: 7.45 pm | D31: Men C | E31: Joe Carabott | F31: Ray Ciantar | G31: vs | H31: Stephen Belli | I31: Kristen Cachia | J31: 7 | K31: 12
C34: 9.00 pm | D34: Lad A | E34: Sharon Mizzi | F34: Elaine Grech | G34: vs | H34: Christine Schembri | I34: Alison Muscat | J34: 10 | K34: 8
C37: 6.30 pm | D37: Mxd CB | E37: Clive Silvio Borg | F37: Deborah Farrugia | G37: vs | H37: Victor Rutter | I37: Kelsey Gauci | J37: 11 | K37: 7
C40: Total Day 1 B | J40: =SUM(J28:J38) -> 32 | K40: =SUM(K28:K38) -> 41
C42: Total Day 1 | J42: =J40+J25 -> 66 | K42: =K40+K25 -> 79
C44: Court 2
C46: Time | D46: Rubber | E46: Team D: Roberto Murdocco | G46: vs | H46: Team E: Darrell Pace | J46: Games
C48: 6.30 pm | D48: Men D | E48: Twanny Pule' | F48: Kenneth Caruana | G48: vs | H48: Isaac Joseph Zammit | I48: Joseph Randich | J48: 10 | K48: 8
C51: 7.45 pm | D51: Laf C | E51: Mary Borg | F51: Stefania Camilleri | G51: vs | H51: Elisa Sacco | I51: Jodie Stivala | J51: 7 | K51: 11
C54: 9.00 pm | D54: Men B | E54: Fotios Evangelou | F54: Chi Chi Canonce | G54: vs | H54: Marco Mercieca | I54: Eric Micallef | J54: 5 | K54: 13
C57: 7.45 pm | D57: Mxd CB | E57: Frans Ellul | F57: Jennifer Mifsud | G57: vs | H57: Manuel Mifsud | I57: Daniela Curmi | J57: 11 | K57: 7
C60: Total Day 1 A | J60: =SUM(J48:J58) -> 33 | K60: =SUM(K48:K58) -> 39
C63: 6.30 pm | D63: Men C | E63: Roberto Murdocco | F63: Sebastian Attard | G63: vs | H63: Manuel Gatt | I63: Darrell Pace | J63: 13 | K63: 6
C66: 7.45 pm | D66: Men A | E66: Jesmond Pule' | F66: Clyde Grech | G66: vs | H66: Clayton Zammit Cesare | I66: Manuel Bonelli | J66: 7 | K66: 11
C69: 9.00 pm | D69: Lad A | E69: Annemarie Mangion | F69: Anthea Gauci | G69: vs | H69: Lara Pule' | I69: Kirsty Mercieca | J69: 8 | K69: 10
C72: 7.45 pm | D72: Lad B | E72: Romina Gauci | F72: Julie Spiteri | G72: vs | H72: Alexia Gouder | I72: Vanessa Vella | J72: 7 | K72: 11
C75: Total Day 1B | J75: =SUM(J63:J73) -> 35 | K75: =SUM(K63:K73) -> 38
C77: Total Day 1 | J77: =SUM(J60+J75) -> 68 | K77: =K75+K60 -> 77
C79: Court 4
C81: Time | D81: Rubber | E81: Team B: Francesca Sciortino | G81: vs | H81: Team F: Tiziana Anastasi | J81: Games
C83: 6.30 pm | D83: Mxd CB | E83: Aaron Micallef Piccione | F83: Jin Attard | G83: vs | H83: Julian Esposito | I83: Mariska Steenkamer | J83: 6 | K83: 12
C86: 7.45 pm | D86: Men C | E86: Gene Zammit | F86: Neville Sciriha | G86: vs | H86: Max Anastasi | I86: Mavric Sawyer | J86: 12 | K86: 7
C89: 9.00 pm | D89: Lad A | E89: Alexia Spiteri Willets | F89: Lucienne Meli | G89: vs | H89: Martina Cuschieri | I89: Natalya Abela | J89: 9 | K89: 9
C92: 9.00 pm | D92: Men D | E92: Conrad Treeby Ward | F92: Ralf Bahmuller | G92: vs | H92: Max Anastasi Jr | I92: Mario Abdilla | J92: 7 | K92: 11
C95: Total Day 1 A | J95: =SUM(J83:J93) -> 34 | K95: =SUM(K83:K93) -> 39
C98: 6.30 pm | D98: Lad C | E98: Helga Azzopardi | F98: Marica Cassar | G98: vs | H98: Tanya Cassar | I98: Heidi Tabone | J98: 4 | K98: 14
C101: 7.45 pm | D101: Men A | E101: Matthew Mifsud | F101: Melchior Farrugia | G101: vs | H101: Kurt Carabott | I101: Adrian Chetucti | J101: 12 | K101: 6
C104: 9.00 pm | D104: Men B | E104: Luigi Porto | F104: Clint Agius | G104: vs | H104: Ryan Mizzi | I104: Willem Steenkamer | J104: 7 | K104: 11
C107: 9.00 pm | D107: Lad B | E107: Kristina Briffa | F107: Francesca Sciortino | G107: vs | H107: Tiziana Anastasi | I107: Carmen Difesa | J107: 6 | K107: 12
...

Sheet Day 2
C1: ANTES INSURANCE TEAM TOURNAMENT 2023
C6: Day 2 - 31/05/2023 & 02/06/2023
C9: Court 1
C11: Time | D11: Rubber | E11: Team B: Francesca Sciortino | G11: vs | H11: Team E: Darrell Pace | J11: Games
C13: 6.30 pm | D13: Men B | E13: Luigi Porto | F13: Gio Marcus | G13: vs | H13: Gabriel Pace | I13: Eric Micallef | J13: 13 | K13: 6
C16: 7.45 pm | D16: Men A | E16: Matthew Mifsud | F16: Nikolai Belli | G16: vs | H16: Clayton Zammit Cesare | I16: Duncan D'Alessandro | J16: 11 | K16: 7
C19: 9.00 pm | D19: Lad B | E19: Kristina Briffa | F19: Francesco Sciortino | G19: vs | H19: Alexia Gouder | I19: Diane Debono | J19: 7 | K19: 11
C22: 6.30 pm | D22: Men D | E22: Matthew Schembri | F22: Conrad Treeby Ward | G22: vs | H22: Isaac Joseph Zammit | I22: Sean Cachia | J22: 7 | K22: 11
C25: Total Day 2 A | J25: =SUM(J13:J23) -> 38 | K25: =SUM(K13:K23) -> 35
C28: 6.30 pm | D28: Men C | E28: Gene Zammit | F28: Neville Sciriha | G28: vs | H28: Manuel Gatt | I28: Etienne Formosa Carabez | J28: 13 | K28: 5
C31: 7.45 pm | D31: Mxd CB | E31: Alain Frendo | F31: Anabel Borg | G31: vs | H31: Darrell Pace | I31: Vanessa Vella | J31: 10 | K31: 8
C34: 9.00 pm | D34: Lad A | E34: Alexia Spiteri Willets | F34: Doriana Portelli | G34: vs | H34: Lara Pule' | I34: Annabelle Abela | J34: 11 | K34: 7
C37: 6.30 pm | D37: Lad C | E37: Helga Azzopardi | F37: Maria Ellul | G37: vs | H37: Elisa Sacco | I37: Claire Genovese | J37: 8 | K37: 10
C40: Total Day 2 B | J40: =SUM(J28:J38) -> 42 | K40: =SUM(K28:K38) -> 30
C42: Total Day 2 | J42: =J40+J25 -> 80 | K42: =K40+K25 -> 65
C44: Court 2
C46: Time | D46: Rubber | E46: Team A: Grace Barbara | G46: vs | H46: Team F: Tiziana Anastasi | J46: Games
C48: 6.30 pm | D48: Mxd CB | E48: Jean Paul Vella | F48: Deborah Farrugia | G48: vs | H48: Mavric Sawyer | I48: Mariska Steenkamer | J48: 8 | K48: 10
C51: 7.45 pm | D51: Men A | E51: Marc Vella Bonnici | F51: Keith Micallef | G51: vs | H51: Kurt Carabott | I51: John Azzopardi | J51: 15 | K51: 3
C54: 9.00 pm | D54: Lad C | E54: Frances Saliba Hersey | F54: Mary Ciantar | G54: vs | H54: Tanya Cassar | I54: Sabrina Xuereb | J54: 4 | K54: 14
C57: 7.45 pm | D57: Men B | E57: David Schembri | F57: George Grech | G57: vs | H57: Ryan Mizzi | I57: James Farrugia | J57: 5 | K57: 14
C60: Total Day 2 A | J60: =SUM(J48:J58) -> 32 | K60: =SUM(K48:K58) -> 41
C63: 6.30 pm | D63: Men C | E63: Ray Ciantar | F63: Clive Silvio Borg | G63: vs | H63: Max Anastasi | I63: Ivan Saliba | J63: 7 | K63: 11
C66: 7.45 pm | D66: Lad B | E66: Brenda Baldacchino | F66: Lonia Carabott | G66: vs | H66: Tiziana Anastasi | I66: Ann-Marie Attard | J66: 5 | K66: 13
C69: 9.00 pm | D69: Men D | E69: Charles Micallef | F69: David Camilleri | G69: vs | H69: Max Anastasi Jr. | I69: Dunstan Vella | J69: 12 | K69: 6
C72: 7.45 pm | D72: Lad A | E72: Sharon Mizzi | F72: Elaine Grech | G72: vs | H72: Martina Cuschieri | I72: Yanika Pace | J72: 8 | K72: 10
C75: Total Day 2 B | J75: =SUM(J63:J73) -> 32 | K75: =SUM(K63:K73) -> 40
C77: Total Day 2 | J77: =J75+J60 -> 64 | K77: =K75+K60 -> 81
C79: Court 4
C81: Time | D81: Rubber | E81: Team C: Victor Rutter | G81: vs | H81: Team D: Roberto Murdocco | J81: Games
C83: 6.30 pm | D83: Lad A | E83: Christine Schembri | F83: Amanda Falzon | G83: vs | H83: Annemarie Mangion | I83: Olivia Belli | J83: 9 | K83: 9
C86: 7.45 pm | D86: Mxd CB | E86: Victor Rutter | F86: Nancy Wong | G86: vs | H86: Roberto Murdocco | I86: Julie Spiteri | J86: 9 | K86: 9
C89: 9.00 pm | D89: Men B | E89: Richard Byrne | F89: Jonathan Vella | G89: vs | H89: Chi Chi Canonce | I89: Kevin Formosa | J89: 9 | K89: 10
C92: 9.00 pm | D92: Lad C | E92: Anna Fenech | F92: Yvonne Borg Cardona | G92: vs | H92: Stefania Camilleri | I92: Christine Scerri | J92: 10 | K92: 8
C95: Total Day 2 A | J95: =SUM(J83:J93) -> 37 | K95: =SUM(K83:K93) -> 36
C98: 6.30 pm | D98: Men D | E98: Donald Deguzman | F98: Simone Re | G98: vs | H98: Twanny Pule' | I98: Cory Greenland | J98: 7 | K98: 11
C101: 7.45 pm | D101: Lad B | E101: Silvana Portelli | F101: Marthese Camoin | G101: vs | H101: Romina Gauci | I101: Sarah Axiaq | J101: 13 | K101: 5
C104: 9.00 pm | D104: Men A | E104: Marcelo Villanueva | F104: Jean Carl Azzopardi | G104: vs | H104: Jesmond Pule' | I104: Andrew Pule' | J104: 10 | K104: 8
C107: 9.00 pm | D107: 9.00 pm | E107: Charles Sacco | F107: Stephen Belli | G107: vs | H107: Frans Ellul | I107: Ryan Ebejer | J107: 6 | K107: 12
C110: Total Day 2 B | J110: =SUM(J98:J108) -> 36 | K110: =SUM(K98:K108) -> 36
...

Sheet Day 3
C1: ANTES INSURANCE TEAM TOURNAMENT 2023
C6: Day 3 - 7/06/2023 & 09/06/2023
C9: Court 1
C11: Time | D11: Rubber | E11: Team C: Victor Rutter | G11: vs | H11: Team F: Tiziana Anastasi | J11: Games
C13: 5.30 pm | D13: Lad B | E13: Silvana Portelli | F13: Nancy Wong | G13: vs | H13: Mariska Steenkamer | I13: Carmen Difesa | J13: 15 | K13: 4
C16: 6.45 pm | D16: Men A | E16: Trevor Rutter | F16: Marcelo Villanueva | G16: vs | H16: Kurt Carabott | I16: Adrian Chetcuti | J16: 10 | K16: 8
C19: 8.00 pm | D19: Men C | E19: Kristen Cachia | F19: Stephen Belli | G19: vs | H19: Max Anastasi | I19: Ivan Saliba (pro) Julian Esposito | J19: 12 | K19: 6
C22: 5.30 pm | D22: Lad A | E22: Amanda Falzon | F22: Alison Muscat | G22: vs | H22: Martina Cuschieri | I22: Natalya Abela | J22: 5 | K22: 13
C25: Total Day 3 A | J25: =SUM(J13:J23) -> 42 | K25: =SUM(K13:K23) -> 31
C28: 6.30 pm | D28: Mxd CB | E28: Victor Rutter | F28: Kelsey Gauci | G28: vs | H28: Mavric Sawyer | I28: Tiziana Anastasi | J28: 7 | K28: 11
C31: 7.45 pm | D31: Men D | E31: Donald Deguzman | F31: Charles Borg Grech | G31: vs | H31: Mario Abdilla | I31: Max Anastasi Jr. | J31: 5 | K31: 13
C34: 9.00 pm | D34: Men B | E34: Ivan Cachia | F34: Richard Byrne | G34: vs | H34: Ryan Mizzi | I34: James Farrugia | J34: 7 | K34: 11
C37: 6.30 pm | D37: Lad C | E37: Yvonne Borg Cardona | F37: Christabelle Chetcuti | G37: vs | H37: Heidi Tabone | I37: Sabrina Xuereb | J37: 6 | K37: 12
C40: Total Day 3 B | J40: =SUM(J28:J38) -> 25 | K40: =SUM(K28:K38) -> 47
C42: Total Day 3 | J42: =J40+J25 -> 67 | K42: =K40+K25 -> 78
C44: Court 2
C46: Time | D46: Rubber | E46: Team B: Francesca Sciortino | G46: vs | H46: Team D: Roberto Murdocco | J46: Games
C48: 6.30 pm | D48: Men D | E48: Matthew Schembri | F48: Ralf Bahmuller | G48: vs | H48: Twanny Pule' | I48: Cory Greenland | J48: 7 | K48: 11
C51: 7.45 pm | D51: Mxd CB | E51: Alain Frendo | F51: Kristina Briffa | G51: vs | H51: Ryan Ebejer | I51: Romina Gauci | J51: 11 | K51: 7
C54: 9.00 pm | D54: Lad B | E54: Anabel Borg | F54: Jin Attard | G54: vs | H54: Jennifer Mifsud | I54: Sarah Axiaq | J54: 15 | K54: 4
C57: 9.00 pm | D57: Lad C | E57: Helga Azzopardi | F57: Maria Ellul | G57: vs | H57: Mary Borg | I57: Christine Scerri | J57: 9 | K57: 9
C60: Total Day 3 A | J60: =SUM(J48:J58) -> 42 | K60: =SUM(K48:K58) -> 31
C63: 6.30 pm | D63: Men C | E63: Gene Zammit | F63: Aaron Micallef Piccione | G63: vs | H63: Roberto Murdocco | I63: Sebastian Attard | J63: 8 | K63: 10
C66: 7.45 pm | D66: Lad A | E66: Alexia Spiteri Willets | F66: Lucienne Meli | G66: vs | H66: Annemarie Mangion | I66: Anthea Gauci | J66: 6 | K66: 12
C69: 9.00 pm | D69: Men A | E69: Matthew Mifsud | F69: Nikolai Belli | G69: vs | H69: Clyde Grech | I69: Andrew Pule' | J69: 9 | K69: 9
C72: 7.45 pm | D72: Men B | E72: Gio Marcus | F72: Clint Agius | G72: vs | H72: Fotios Evangelou | I72: Kevin Formosa | J72: 12 | K72: 6
C75: Total Day 3 B | J75: =SUM(J63:J73) -> 35 | K75: =SUM(K63:K73) -> 37
C77: Total Day 3 | J77: =J75+J60 -> 77 | K77: =K75+K60 -> 68
C79: Court 4
C81: Time | D81: Rubber | E81: Team A: Grace Barbara | G81: vs | H81: Team E: Darrell Pace | J81: Games
C83: 6.30 pm | D83: Men D | E83: Charles Micallef | F83: Dorian Demanuele | G83: vs | H83: Isaac Joseph Zammit | I83: Sean Cachia | J83: 6 | K83: 12
C86: 7.45 pm | D86: MXD | E86: Joe Carabott | F86: Brenda Baldacchino | G86: vs | H86: Manuel Mifsud | I86: Vanessa Vella | J86: 10 | K86: 8
C89: 9.00 pm | D89: Men A | E89: Marc Vella Bonnici | F89: Keith Micallef | G89: vs | H89: Clayton Zammit Cesare | I89: Manuel Bonello | J89: 9 | K89: 9
C92: 7.45 pm | D92: Men C | E92: Ray Ciantar | F92: Jean Paul Vella | G92: vs | H92: Etienne Formosa Carabez | I92: Darrell Pace | J92: 10 | K92: 8
C95: Total Day 3 A | J95: =SUM(J83:J93) -> 35 | K95: =SUM(K83:K93) -> 37
C98: 6.30 pm | D98: Men B | E98: George Grech | F98: Roderick Spiteri | G98: vs | H98: Marco Mercieca | I98: Gabriel Pace | J98: 5 | K98: 13
C101: 7.45 pm | D101: Lad A | E101: Sharon Mizzi | F101: Celeste Zammit Marquette | G101: vs | H101: Lara Pule' | I101: Annabelle Abela | J101: 15 | K101: 3
C104: 9.00 pm | D104: Lad B | E104: Angele Pule' | F104: Lonia Carabott | G104: vs | H104: Daniela Curmi | I104: Diane Debono | J104: 12 | K104: 7
C107: 9.00 pm | D107: Lad C | E107: Christine Seychell | F107: Mary Ciantar | G107: vs | H107: Jodie Stivala | I107: Claire Genovese | J107: 12 | K107: 6
C110: Total Day 3 B | J110: =SUM(J98:J108) -> 44 | K110: =SUM(K98:K108) -> 29
...

Sheet Day 4
C1: ANTES INSURANCE TEAM TOURNAMENT 2023
C6: Day 4 - 14/06/2023 & 15/06/2023
C9: Court 1
C11: Time | D11: Rubber | E11: Team D: Roberto Murdocco | G11: vs | H11: Team F: Tiziana Anstasi | J11: Games
C13: 6.30 pm | D13: Lad B | E13: Jennifer Mifsud | F13: Sarah Axiaq | G13: vs | H13: Mariska Steenkamer | I13: Carmen Difesa | J13: 7 | K13: 11
C16: 7.45 pm | D16: Lad A | E16: Annemarie Mangion | F16: Olivia Belli (promoted Anthea Gauci) | G16: vs | H16: Natalya Abela | I16: Yanika Pace | J16: 10 | K16: 8
C19: 9.00 pm | D19: Men D | E19: Kenneth Caruana | F19: Cory Greenland | G19: vs | H19: Max Anastasi Jr. | I19: Dunstan Vella | J19: 9 | K19: 9
C22: 6.30 pm | D22: Men C | E22: Roberto Murdocco | F22: Frans Ellul | G22: vs | H22: Mavric Sawyer | I22: Ivan Saliba | J22: 14 | K22: 4
C25: Total Day 4 A | J25: =SUM(J13:J23) -> 40 | K25: =SUM(K13:K23) -> 32
C28: 6.30 pm | D28: Men A | E28: Jesmond Pule' | F28: Andrew Pule' | G28: vs | H28: Adrian Chetcuti | I28: John Azzopardi | J28: 13 | K28: 6
C31: 7.45 pm | D31: MXD | E31: Sebastian Attard | F31: Julie Spiteri | G31: vs | H31: Julian Esposito | I31: Ann-Marie Attard | J31: 11 | K31: 7
C34: 9.00 pm | D34: Men B | E34: Fotios Evangelou | F34: Chi Chi Canonce | G34: vs | H34: Ryan Mizzi | I34: Willem Steenkamer | J34: 9 | K34: 9
C37: 7.45 pm | D37: Lad C | E37: Mary Borg | F37: Christine Scerri | G37: vs | H37: Tanya Cassar | I37: Heidi Tabone | J37: 4 | K37: 14
C40: Total Day 4 B | J40: =SUM(J28:J38) -> 37 | K40: =SUM(K28:K38) -> 36
C42: Total Day 4 | J42: =J40+J25 -> 77 | K42: =K40+K25 -> 68
C44: Court 2
C46: Time | D46: Rubber | E46: Team C: Victor Rutter | G46: vs | H46: Team E: Darell Pace | J46: Games
C48: 6.30 pm | D48: Lad A | E48: Christine Schembri | F48: Amanda Falzon | G48: vs | H48: Lara Pule' | I48: Kirsty Mercieca | J48: 14 | K48: 4
C51: 7.45 pm | D51: Men D | E51: Simone Re | F51: Donald Deguzman | G51: vs | H51: Sean Cachia | I51: Joseph Randich | J51: 6 | K51: 12
C54: 9.00 pm | D54: Men C | E54: Victor Rutter | F54: Kristen Cachia | G54: vs | H54: Manuel Mifsud | I54: Etienne Formosa Carabez | J54: 6 | K54: 12
C57: 7.45 pm | D57: Men B | E57: Ivan Cachia | F57: Richard Byrne | G57: vs | H57: Marco Mercieca | I57: Gabriel Pace | J57: 7 | K57: 11
C60: Total Day 4 A | J60: =SUM(J48:J58) -> 33 | K60: =SUM(K48:K58) -> 39
C63: 6.30 pm | D63: Lad C | E63: Christabelle Chetcuti | F63: Anna Fenech | G63: vs | H63: Jodie Stivala | I63: Elisa Sacco | J63: 3 | K63: 15
C66: 7.45 pm | D66: Lad B | E66: Silvana Portelli | F66: Marthese Camoin | G66: vs | H66: Daniela Curmi | I66: Alexia Gouder | J66: 3 | K66: 15
C69: 7.45 pm | D69: Men A | E69: Marcelo Villanueva | F69: Jean Carl Azzopardi | G69: vs | H69: Duncan D'Alessandro | I69: Manuel Bonello | J69: 13 | K69: 6
C72: 7.45 pm | D72: MXD | E72: Charles Sacco | F72: Kelsey Gauci | G72: vs | H72: Manuel Gatt | I72: Diane Debono | J72: 6 | K72: 12
C75: Total Day 4 B | J75: =SUM(J63:J73) -> 25 | K75: =SUM(K63:K73) -> 48
C77: Total Day 4 | J77: =J75+J60 -> 58 | K77: =K75+K60 -> 87
C79: Court 4
C81: Time | D81: Rubber | E81: Team A: Grace Barbara | G81: vs | H81: Team B: Francesca Sciortino | J81: Games
C83: 6.30 pm | D83: Men D | E83: Charles Micallef | F83: David Camilleri | G83: vs | H83: Matthew Schembri | I83: Ralf Bahmuller | J83: 13 | K83: 5
C86: 7.45 pm | D86: Men C | E86: Joe Carabott | F86: Clive Silvio Borg | G86: vs | H86: Neville Sciriha | I86: Alain Frendo | J86: 9 | K86: 9
C89: 9.00 pm | D89: Men A | E89: Eric Roca | F89: Keith Micallef | G89: vs | H89: Melchior Farrugia | I89: Nikolai Belli | J89: 12 | K89: 7
C92: 6.30 pm | D92: Lad C | E92: Frances Saliba Hersey | F92: Mary Ciantar | G92: vs | H92: Helga Azzopardi | I92: Maria Ellul (pro Marica Cassar) | J92: 11 | K92: 7
C95: Total Day 4 A | J95: =SUM(J83:J93) -> 45 | K95: =SUM(K83:K93) -> 28
C98: 6.30 pm | D98: Lad A | E98: Elaine Grech | F98: Celeste Zammit Marquette | G98: vs | H98: Lucienne Meli | I98: Doriana Portelli | J98: 8 | K98: 10
C101: 7.45 pm | D101: Men B | E101: David Schembri | F101: Roderick Spiteri | G101: vs | H101: Gio Marcos | I101: Luigi Porto | J101: 8 | K101: 10
C104: 9.00 pm | D104: Lad B | E104: Angele Pule' | F104: Lonia Carabott | G104: vs | H104: Anabel Borg | I104: Jin Attard | J104: 14 | K104: 4
C107: 9.00 pm | D107: MXD | E107: Jean Paul Vella | F107: Deborah Farrugia | G107: vs | H107: Aaron Micallef Piccione | I107: Francesca Sciortino | J107: 7 | K107: 11
C110: Total Day 4 B | J110: =SUM(J98:J108) -> 37 | K110: =SUM(K98:K108) -> 35
...

Sheet Day 5
C1: ANTES INSURANCE TEAM TOURNAMENT 2023
C6: Day 5 - 21/06/2023 & 23/06/2023
C9: Court 1
C11: Time | D11: Rubber | E11: Team A: Grace Barbara | G11: vs | H11: Team D: Roberto Murdocco | J11: Games
C13: 6.30 pm | D13: Men A | E13: Marc Vella Bonnici | F13: Eric Roca | G13: vs | H13: Jesmond Pule' | I13: Clyde Grech | J13: 11 | K13: 7
C16: 7.45 pm | D16: Men C | E16: Joe Carabott | F16: Ray Ciantar | G16: vs | H16: Sebastian Attard | I16: Ryan Ebejer | J16: 7 | K16: 11
C19: 9.00 pm | D19: Lad B | E19: Deborah Farrugia | F19: Angele Pule' | G19: vs | H19: Romina Gauci | I19: Jennifer Mifsud | J19: 8 | K19: 10
C22: 6.30 pm | D22: Men D | E22: Charles Micallef | F22: Dorian Demanuele | G22: vs | H22: Twanny Pule' | I22: Kenneth Caruana | J22: 7 | K22: 11
C25: Total Day 5 A | J25: =SUM(J13:J23) -> 33 | K25: =SUM(K13:K23) -> 39
C28: 6.30 pm | D28: Men B | E28: David Schembri | F28: Roderick Spiteri (pro) George Grech | G28: vs | H28: Fotios Evangelou | I28: Kevin Formosa | J28: 12 | K28: 6
C31: 7.45 pm | D31: Lad A | E31: Sharon Mizzi | F31: Celeste Zammit Marquette | G31: vs | H31: Romina Gauci (pro) Olivia Belli | I31: Anthea Gauci | J31: 14 | K31: 4
C34: 9.00 pm | D34: MxdCB | E34: Clive Silvio Borg | F34: Angele Pule' (pro) Brenda Baldacchino | G34: vs | H34: Frans Ellul | I34: Julie Spiteri | J34: 8 | K34: 10
C37: 6.30 pm | D37: Lad C | E37: Christine Seychell | F37: Frances Saliba Hersey | G37: vs | H37: Mary Borg | I37: Stefania Camilleri | J37: 8 | K37: 11
C40: Total Day 5B | J40: =SUM(J28:J38) -> 42 | K40: =SUM(K28:K38) -> 31
C42: Total Day 5 | J42: =J40+J25 -> 75 | K42: =K40+K25 -> 70
C44: Court 2
C46: Time | D46: Rubber | E46: Team B: Francesca Sciortino | G46: vs | H46: Team C: Victor Rutter | J46: Games
C48: 6.30 pm | D48: Lad A | E48: Alexia Spiteri Wllets | F48: Doriana Portelli | G48: vs | H48: Christine Schembri | I48: Alison Muscat | J48: 7 | K48: 11
C51: 7.45 pm | D51: Mxd CB | E51: Aaron Micallef Piccione | F51: Francesca Sciortino | G51: vs | H51: Victor Rutter (pro Stephen Belli) | I51: Nancy Wong | J51: 9 | K51: 9
C54: 9.00 pm | D54: Men A | E54: Matthew Mifsud | F54: Melchior Farrugia | G54: vs | H54: Trevor Rutter | I54: Jean Carl Azzopardi | J54: 11 | K54: 7
C57: 7.45 pm | D57: Men C | E57: Neville Sciriha | F57: Alain Frendo | G57: vs | H57: Charles Sacco | I57: Kristen Cachia | J57: 11 | K57: 7
C60: Total Day 5 A | J60: =SUM(J48:J58) -> 38 | K60: =SUM(K48:K58) -> 34
C63: 6.30 pm | D63: Lad B | E63: Anabel Borg | F63: Kristina Briffa | G63: vs | H63: Kelsey Gauci | I63: Silvana Portelli | J63: 13 | K63: 5
C66: 7.45 pm | D66: Men D | E66: Matthew Schembri | F66: Conrad Treeby Ward | G66: vs | H66: Charles Borg Grech | I66: Simone Re | J66: 9 | K66: 9
C69: 9.00 pm | D69: Men B | E69: Luigi Porto | F69: Clint Agius | G69: vs | H69: Ivan Cachia | I69: Jonathan Vella | J69: 10 | K69: 8
C72: 7.45 pm | D72: Lad C | E72: Marica Cassar | F72: Maria Ellul | G72: vs | H72: Yvonne Borg Cardona | I72: Anna Fenech | J72: 9 | K72: 10
C75: Total Day 5B | J75: =SUM(J63:J73) -> 41 | K75: =SUM(K63:K73) -> 32
C77: Total Day 5 | J77: =J75+J60 -> 79 | K77: =K75+K60 -> 66
C79: Court 4
C81: Time | D81: Rubber | E81: Team E: Darrell Pace | G81: vs | H81: Team F: Tiziana Anastasi | J81: Games
C83: 6.30 pm | D83: Men C | E83: Manuel Gatt | F83: Etienne Formosa Carabez | G83: vs | H83: Max Anastasi | I83: Julian Esposito | J83: 6 | K83: 12
C86: 7.45 pm | D86: Lad A | E86: Kirsty Mercieca | F86: Annabelle Abela | G86: vs | H86: Martina Cuschieri | I86: Yanika Pace | J86: 7 | K86: 11
C89: 9.00 pm | D89: Lad B | E89: Alexia Gouder | F89: Daniela Curmi | G89: vs | H89: Tiziana Anastasi | I89: Ann-Marie Attard | J89: 11 | K89: 7
C92: 9.00 pm | D92: Men B | E92: Marco Mercieca | F92: Eric Micallef | G92: vs | H92: James Farrugia | I92: Willem Steenkamer | J92: 16 | K92: 2
C95: Total Day 5 A | J95: =SUM(J83:J93) -> 40 | K95: =SUM(K83:K93) -> 32
C98: 6.30 pm | D98: Lad C | E98: Elisa Sacco | F98: Claire Genovese | G98: vs | H98: Tanya Cassar | I98: Sabrina Xuereb | J98: 4 | K98: 15
C101: 9.00 pm | D101: Men D | E101: Isaac Joseph Zammit | F101: Sean Cachia (pro Joe Randich) | G101: vs | H101: Dunstan Vella | I101: Mario Abdilla | J101: 11 | K101: 7
C104: 9.00 pm | D104: Mxd CB | E104: Manuel Mifsud | F104: Elisa Sacco (pro Vanessa Vella) | G104: vs | H104: Ivan Saliba | I104: Carmen Difesa | J104: 11 | K104: 7
C107: 9.00 pm | D107: Men A | E107: Clayton Zammit Cesare | F107: Duncan D'Alessandro | G107: vs | H107: Kurt Carabott | I107: John Azzopardi | J107: 11 | K107: 7
C110: Total Day 5 B | J110: =SUM(J98:J108) -> 37 | K110: =SUM(K98:K108) -> 36
...

Sheet Semi Final
C1: ANTES INSURANCE TEAM TOURNAMENT 2023
C6: Semi Final - 28/06/2023 & 30/06/2023
C9: Court 1
C11: Time | D11: Rubber | E11: Team B: Francesca Sciortino | G11: vs | H11: Team F : Tiziana Anastasi | J11: Games
C13: 6.30 pm | D13: Men C | E13: Neville Sciriha | F13: Alain Frendo | G13: vs | H13: Max Anastasi | I13: Julian Esposito | J13: 7 | K13: 11
C16: 7.45 pm | D16: Lad A | E16: Alexia Spiteri Willets | F16: Lucienne Meli | G16: vs | H16: Martina Cuschieri | I16: Natalya Abela | J16: 9 | K16: 9
C19: 9.00 pm | D19: Men D | E19: Matthew Schembri | F19: Conrad Treeby Ward | G19: vs | H19: Max Anastasi Jr | I19: Dunstan Vella | J19: 14 | K19: 5
C22: 6.30 pm | D22: Men B | E22: Luigi Porto | F22: Gio Marcus | G22: vs | H22: Ryan Mizzi | I22: James Farrugia | J22: 10 | K22: 8
