Workbook

Sheet Team Selection
A2: TENNIS TRADE TEAM TOURNAMENT 2024
B3: A | C3: B | D3: C | E3: D | F3: E | G3: F
A4: CAPTAIN | B4: Alison Muscat | C4: Lonia Carabott | D4: Kaya Sammut | E4: Kelsey Gauci | F4: Juan Sammut | G4: Francesca Sciortino
B5: Alla Maghna | C5: Love All | D5: Challengers | E5: Destroyers | F5: Elite | G5: Fireball
A6: MEN
A7: A1 | B7: Matthew Mifsud | C7: Clayton Zammit Cesare | D7: Jesmond Pule' | E7: Melchior Farrugia | F7: Matthew Borg | G7: Adrian Chetcuti
A8: A2 | B8: Clyde Grech | C8: Kurt Carabott | D8: Jean Attard | E8: Marco Mercieca | F8: Duncan D'Alessandro | G8: Claude Mifsud Wismayer
A9: A3 | B9: David Schembri | C9: Keith Micallef | D9: Manuel Bonello | E9: Gabriel Pace | F9: Kurt Cassar | G9: John Azzopardi
A11: B1 | B11: Chi Chi Canonce | C11: Roderick Spiteri | D11: Jonathan Vella | E11: Ivan Cachia | F11: Roberto Murdocco | G11: Cyril Lastimosa
A12: B2 | B12: Lydon Vella | C12: Kevin Formosa | D12: Jayboy Lastimosa | E12: Clint Agius | F12: Emman Xuereb | G12: Kristen Cachia
A13: B3 | B13: Mavric Sawyer | C13: Julian Bilocca | D13: Gene Zammit | E13: Ivan Cassar | F13: Willem Steenkamer | G13: Neville Sciriha
A15: C1 | B15: Kyle Magro | C15: Manuel Mifsud | D15: Jean Paul Vella | E15: Frans Ellul | F15: Max Anastasi | G15: Julian Esposito
A16: C2 | B16: Juan Debono | C16: Maurice Borg | D16: Steve Gambin | E16: Darrel Pace | F16: Charles Sacco | G16: Matthew Schembri
A17: C3 | B17: Victor Rutter | C17: Ryan Ebejer | D17: Dunstan Vella | E17: Isaac Joseph Zammit | F17: David Camilleri | G17: Charles Micallef
A19: D1 | B19: Donald Deguzman | C19: Cory Greenland | D19: Matthew Micallef | E19: Kenneth Caruana | F19: Antoine Bugeja | G19: Charles Borg Grech
A20: D2 | B20: Joseph Randich | C20: JP Sciberras | D20: Justin Scicluna | E20: Isaac Baldacchino | F20: Adam Green | G20: Glenn Micallef
A21: D3 | B21: Chris Vella | C21: Mario Abdilla | D21: Michael Bugeja | E21: Kevin Sciberras | F21: Twanny Pule' | G21: Robert Attard
A23: LADIES
A24: A1 | B24: Natalya Abela | C24: Lara Pule' | D24: Annmarie Mangion | E24: Martina Cuschieri | F24: Kim Fava | G24: Renette Magro
A25: A2 | B25: Amanda Falzon | C25: Kirsty Mercieca | D25: Pierina Holmin | E25: Anthea Gauci | F25: Olivia Belli | G25: Diane Fenech
A26: A3 | B26: Alison Muscat | C26: Tiziana Anastasi | D26: Anabel Borg | E26: Kelsey Gauci | F26: Annabelle Abela | G26: Julie Spiteri
A28: B1 | B28: Doriana Portelli | C28: Kristina Briffa | D28: Kaya Sammut | E28: Romina Gauci | F28: Alexia Gouder | G28: Francesca Sciortino
A29: B2 | B29: Silvana Portelli | C29: Marcette Sciriha | D29: Mariska Steenkamer | E29: Stephanie Farrugia | F29: Dominique Francica | G29: Brenda Baldacchino
A30: B3 | B30: Jin Attard | C30: Ann Marie Attard | D30: Sarah Axiaq | E30: Angele Pule' | F30: Tanya Cassar | G30: Deborah Farrugia
A32: C1 | B32: Heidi Tabone | C32: Lonia Carabott | D32: Maria Ellul | E32: Ruth Micallef | F32: Maria Angela Gambin | G32: Christine Seychell
A33: C2 | B33: Daphne Vella | C33: Marica Cassar | D33: Leanne Sammut | E33: Janice Galea | F33: Jodie Stivala | G33: Anna Napier
A34: C3 | B34: Christine Scerri | C34: Stefania Camilleri | D34: Jean Frendo | E34: Mary Borg | F34: Ben Fenech | G34: Lillian Baldacchino

Sheet Encounters Played
A2: VITTORIOSA LAWN TENNIS CLUB
A3: TENNIS TRADE TEAM TOURNAMENT 2024
B5: Day | C5: 1 | D5: 2 | E5: 3 | F5: 4 | G5: 5 | H5: Total | J5: Day | K5: 1 | L5: 2 | M5: 3 | N5: 4 | O5: 5 | P5: Total
A6: A | B6: Alison Muscat (Alla Maghna) | I6: B | J6: Lonia Carabott (Love All)
A7: A1 | B7: Matthew Mifsud | C7: 1 | D7: 1 | G7: 1 | H7: =SUM(C7:G7) -> 3 | I7: A1 | J7: Clayton Zammit Cesare | K7: 1 | L7: 1 | M7: 1 | O7: 1 | P7: =SUM(K7:O7) -> 4
A8: A2 | B8: Clyde Grech | C8: 1 | E8: 1 | G8: 1 | H8: =SUM(C8:G8) -> 3 | I8: A2 | J8: Kurt Carabott | K8: 1 | L8: 1 | N8: 1 | P8: =SUM(K8:O8) -> 3
A9: A3 | B9: David Schembri | D9: 1 | E9: 1 | H9: =SUM(C9:G9) -> 2 | I9: A3 | J9: Keith Micallef | M9: 1 | N9: 1 | O9: 1 | P9: =SUM(K9:O9) -> 3
A10: B1 | B10: Chi Chi Canonce | C10: 1 | D10: 1 | F10: 1 | G10: 1 | H10: =SUM(C10:G10) -> 4 | I10: B1 | J10: Roderick Spiteri | K10: 1 | L10: 1 | N10: 1 | O10: 1 | P10: =SUM(K10:O10) -> 4
A11: B2 | B11: Lydon Vella | C11: 1 | E11: 1 | G11: 1 | H11: =SUM(C11:G11) -> 3 | I11: B2 | J11: Kevin Formosa | L11: 1 | M11: 1 | N11: 1 | P11: =SUM(K11:O11) -> 3
A12: B3 | B12: Mavric Sawyer | D12: 1 | E12: 1 | F12: 1 | H12: =SUM(C12:G12) -> 3 | I12: B3 | J12: Julian Bilocca | K12: 1 | M12: 1 | O12: 1 | P12: =SUM(K12:O12) -> 3
A13: C1 | B13: Kyle Magro | C13: 1 | D13: 1 | E13: 1 | G13: 1 | H13: =SUM(C13:G13) -> 4 | I13: C1 | J13: Manuel Mifsud | K13: 1 | L13: 1 | M13: 1 | O13: 1 | P13: =SUM(K13:O13) -> 4
A14: C2 | B14: Juan Debono | D14: 1 | F14: 1 | G14: 1 | H14: =SUM(C14:G14) -> 3 | I14: C2 | J14: Maurice Borg | K14: 1 | N14: 1 | O14: 1 | P14: =SUM(K14:O14) -> 3
A15: C3 | B15: Victor Rutter | C15: 1 | E15: 1 | F15: 1 | H15: =SUM(C15:G15) -> 3 | I15: C3 | J15: Ryan Ebejer | L15: 1 | M15: 1 | N15: 1 | P15: =SUM(K15:O15) -> 3
A16: D1 | B16: Donald Deguzman | D16: 1 | E16: 1 | F16: 1 | G16: 1 | H16: =SUM(C16:G16) -> 4 | I16: D1 | J16: Cory Greenland | K16: 1 | L16: 1 | M16: 1 | O16: 1 | P16: =SUM(K16:O16) -> 4
A17: D2 | B17: Joseph Randich | C17: 1 | D17: 1 | F17: 1 | H17: =SUM(C17:G17) -> 3 | I17: D2 | J17: JP Sciberras | K17: 1 | N17: 1 | O17: 1 | P17: =SUM(K17:O17) -> 3
A18: D3 | B18: Chris Vella | C18: 1 | E18: 1 | G18: 1 | H18: =SUM(C18:G18) -> 3 | I18: D3 | J18: Mario Abdilla | L18: 1 | M18: 1 | N18: 1 | P18: =SUM(K18:O18) -> 3
A20: A1 | B20: Natalya Abela | C20: 1 | E20: 1 | F20: 1 | H20: =SUM(C20:G20) -> 3 | I20: A1 | J20: Lara Pule` | K20: 1 | N20: 1 | O20: 1 | P20: =SUM(K20:O20) -> 3
A21: A2 | B21: Amanda Falzon | E21: 1 | F21: 1 | G21: 1 | H21: =SUM(C21:G21) -> 3 | I21: A2 | J21: Kirsty Mercieca | K21: 1 | L21: 1 | M21: 1 | N21: 1 | P21: =SUM(K21:O21) -> 4
A22: A3 | B22: Alison Muscat | C22: 1 | G22: 1 | H22: =SUM(C22:G22) -> 2 | I22: A3 | J22: Tiziana Anastasi | L22: 1 | M22: 1 | O22: 1 | P22: =SUM(K22:O22) -> 3
A23: B1 | B23: Doriana Portelli | C23: 1 | D23: 1 | F23: 1 | G23: 1 | H23: =SUM(C23:G23) -> 4 | I23: B1 | J23: Kristina Briffa | K23: 1 | L23: 1 | N23: 1 | P23: =SUM(K23:O23) -> 3
A24: B2 | B24: Silvana Portelli | C24: 1 | E24: 1 | F24: 1 | H24: =SUM(C24:G24) -> 3 | I24: B2 | J24: Marcette Sciriha | K24: 1 | M24: 1 | O24: 1 | P24: =SUM(K24:O24) -> 3
A25: B3 | B25: Jin Attard | D25: 1 | E25: 1 | G25: 1 | H25: =SUM(C25:G25) -> 3 | I25: B3 | J25: Ann Marie Attard | L25: 1 | M25: 1 | N25: 1 | O25: 1 | P25: =SUM(K25:O25) -> 4
A26: C1 | B26: Heidi Tabone | C26: 1 | D26: 1 | E26: 1 | G26: 1 | H26: =SUM(C26:G26) -> 4 | I26: C1 | J26: Lonia Carabott | K26: 1 | L26: 1 | M26: 1 | O26: 1 | P26: =SUM(K26:O26) -> 4
A27: C2 | B27: Daphne Vella | C27: 1 | E27: 1 | F27: 1 | H27: =SUM(C27:G27) -> 3 | I27: C2 | J27: Marica Cassar | K27: 1 | N27: 1 | O27: 1 | P27: =SUM(K27:O27) -> 3
A28: C3 | B28: Christine Scerri | D28: 1 | F28: 1 | G28: 1 | H28: =SUM(C28:G28) -> 3 | I28: C3 | J28: Stefania Camilleri | L28: 1 | M28: 1 | N28: 1 | P28: =SUM(K28:O28) -> 3
B34: Day | C34: 1 | D34: 2 | E34: 3 | F34: 4 | G34: 5 | H34: Total | J34: Day | K34: 1 | L34: 2 | M34: 3 | N34: 4 | O34: 5 | P34: Total
A36: C | B36: Kaya Sammut (Challengers) | C36: Column 1 | D36: Column 2 | E36: Column 3 | F36: Column 4 | G36: Column 5 | H36: Column 6 | I36: D | J36: Kelsey Gauci (Destroyers) | K36: Column 7 | L36: Column 8 | M36: Column 9 | N36: Column 10 | O36: Column 11 | P36: Column 12
A37: A1 | B37: Jesmond Pule` | C37: 1 | D37: 1 | F37: 1 | G37: 1 | H37: =SUM(C37:G37) -> 4 | I37: A1 | J37: Melchior Farrugia | K37: 1 | L37: 1 | N37: 1 | O37: 1 | P37: =SUM(K37:O37) -> 4
A38: A2 | B38: Jean Attard | D38: 1 | E38: 1 | F38: 1 | H38: =SUM(C38:G38) -> 3 | I38: A2 | J38: Marco Mercieca | K38: 1 | L38: 1 | M38: 1 | P38: =SUM(K38:O38) -> 3
A39: A3 | B39: Manuel Bonello | C39: 1 | E39: 1 | G39: 1 | H39: =SUM(C39:G39) -> 3 | I39: A3 | J39: Gabriel Pace | M39: 1 | N39: 1 | O39: 1 | P39: =SUM(K39:O39) -> 3
A40: B1 | B40: Jonathan Vella | C40: 1 | D40: 1 | F40: 1 | G40: 1 | H40: =SUM(C40:G40) -> 4 | I40: B1 | J40: Ivan Cachia | K40: 1 | L40: 1 | N40: 1 | O40: 1 | P40: =SUM(K40:O40) -> 4
A41: B2 | B41: Jayboy Lastimosa | C41: 1 | E41: 1 | G41: 1 | H41: =SUM(C41:G41) -> 3 | I41: B2 | J41: Clint Agius | K41: 1 | M41: 1 | N41: 1 | P41: =SUM(K41:O41) -> 3
A42: B3 | B42: Gene Zammit | D42: 1 | E42: 1 | F42: 1 | H42: =SUM(C42:G42) -> 3 | I42: B3 | J42: Ivan Cassar | L42: 1 | M42: 1 | O42: 1 | P42: =SUM(K42:O42) -> 3
A43: C1 | B43: Jean Paul Vella | C43: 1 | E43: 1 | G43: 1 | H43: =SUM(C43:G43) -> 3 | I43: C1 | J43: Frans Ellul | K43: 1 | L43: 1 | M43: 1 | O43: 1 | P43: =SUM(K43:O43) -> 4
A44: C2 | B44: Steve Gambin | D44: 1 | E44: 1 | F44: 1 | H44: =SUM(C44:G44) -> 3 | I44: C2 | J44: Darrell Pace | K44: 1 | M44: 1 | N44: 1 | P44: =SUM(K44:O44) -> 3
A45: C3 | B45: Dunstan Vella | C45: 1 | D45: 1 | F45: 1 | G45: 1 | H45: =SUM(C45:G45) -> 4 | I45: C3 | J45: Isaac Joseph Zammit | L45: 1 | N45: 1 | O45: 1 | P45: =SUM(K45:O45) -> 3
A46: D1 | B46: Matthew Micallef | C46: 1 | D46: 1 | F46: 1 | H46: =SUM(C46:G46) -> 3 | I46: D1 | J46: Kenneth Caruana | K46: 1 | M46: 1 | O46: 1 | P46: =SUM(K46:O46) -> 3
A47: D2 | B47: Justin Scicluna | C47: 1 | E47: 1 | F47: 1 | G47: 1 | H47: =SUM(C47:G47) -> 4 | I47: D2 | J47: Isaac Baldacchino | K47: 1 | L47: 1 | M47: 1 | N47: 1 | P47: =SUM(K47:O47) -> 4
A48: D3 | B48: Michael Bugeja | D48: 1 | E48: 1 | G48: 1 | H48: =SUM(C48:G48) -> 3 | I48: D3 | J48: Kevin Sciberras | L48: 1 | N48: 1 | O48: 1 | P48: =SUM(K48:O48) -> 3
A50: A1 | B50: Ann Marie Mangion | C50: 1 | D50: 1 | G50: 1 | H50: =SUM(C50:G50) -> 3 | I50: A1 | J50: Martina Cuschieri | L50: 1 | M50: 1 | P50: =SUM(K50:O50) -> 2
...

Sheet Standings
B2: VITTORIOSA LAWN TENNIS CLUB
B3: TENNIS TRADE TEAM TOURNAMENT 2023
C6: ROUND 1
D8: Day 1 | E8: Total Day 1 | G8: Day 2 | H8: Total Day 2 | J8: Day 3 | K8: Total Day 3 | M8: Day 4 | N8: Total Day 4 | P8: Day 5 | Q8: Total Day 5 | S8: Total Round 1
D9: G | E9: G | G9: G | H9: G | J9: G | K9: G | M9: G | N9: G | P9: G | Q9: G | S9: G
B11: TEAM A: Alison Muscat (Alla Maghna) | C11: Wednesday | D11: =SUM('Day 1'!J21) -> 17 | E11: =D11+D12 -> 58 | G11: =SUM('Day 2'!J58) -> 37 | H11: =G11+G12 -> 65 | J11: =SUM('Day 3'!J86) -> 27 | K11: =J11+J12 -> 69 | M11: =SUM('Day 4'!J56) -> 34 | N11: =M11+M12 -> 58 | P11: =SUM('Day 5'!J88) -> 45 | Q11: =P11+P12 -> 73 | S11: =+E11+H11+K11+N11+Q11 -> 323
C12: Friday | D12: =SUM('Day 1'!J35) -> 41 | G12: =SUM('Day 2'!J71) -> 28 | J12: =SUM('Day 3'!J100) -> 42 | M12: =SUM('Day 4'!J69) -> 24 | P12: =SUM('Day 5'!J100) -> 28
B14: TEAM B: Lonia Carabott (Love All) | C14: Wednesday | D14: =SUM('Day 1'!J54) -> 31 | E14: =D14+D15 -> 52 | G14: =SUM('Day 2'!J25) -> 26 | H14: =G14+G15 -> 53 | J14: =SUM('Day 3'!J54) -> 28 | K14: =J14+J15 -> 78 | M14: =SUM('Day 4'!J86) -> 23 | N14: =M14+M15 -> 50 | P14: =SUM('Day 5'!K88) -> 28 | Q14: =P14+P15 -> 54 | S14: =+E14+H14+K14+N14+Q14 -> 287
C15: Friday | D15: =SUM('Day 1'!J66) -> 21 | G15: =SUM('Day 2'!J38) -> 27 | J15: =SUM('Day 3'!J68) -> 50 | M15: =SUM('Day 4'!J101) -> 27 | P15: =SUM('Day 5'!K100) -> 26
B17: TEAM C: Kaya Sammut (Challengers) | C17: Wednesday | D17: =SUM('Day 1'!K21) -> 37 | E17: =D17+D18 -> 69 | G17: =SUM('Day 2'!J91) -> 29 | H17: =G17+G18 -> 56 | J17: =SUM('Day 3'!K54) -> 26 | K17: =J17+J18 -> 49 | M17: =SUM('Day 4'!J25) -> 45 | N17: =M17+M18 -> 77 | P17: =SUM('Day 5'!J21) -> 29 | Q17: =P17+P18 -> 56 | S17: =+E17+H17+K17+N17+Q17 -> 307
C18: Friday | D18: =SUM('Day 1'!K35) -> 32 | G18: =SUM('Day 2'!J104) -> 27 | J18: =SUM('Day 3'!K68) -> 23 | M18: =SUM('Day 4'!J37) -> 32 | P18: =SUM('Day 5'!J36) -> 27
B20: TEAM D: Kelsey Gauci (Destroyers) | C20: Wednesday | D20: =SUM('Day 1'!J85) -> 38 | E20: =D20+D21 -> 63 | G20: =SUM('Day 2'!K25) -> 28 | H20: =G20+G21 -> 55 | J20: =SUM('Day 3'!K86) -> 28 | K20: =J20+J21 -> 58 | M20: =SUM('Day 4'!K25) -> 28 | N20: =M20+M21 -> 50 | P20: =SUM('Day 5'!J56) -> 31 | Q20: =P20+P21 -> 56 | S20: =+E20+H20+K20+N20+Q20 -> 282
C21: Friday | D21: =SUM('Day 1'!J97) -> 25 | G21: =SUM('Day 2'!K38) -> 27 | J21: =SUM('Day 3'!K100) -> 30 | M21: =SUM('Day 4'!K37) -> 22 | P21: =SUM('Day 5'!J68) -> 25
B23: TEAM E: Juan Sammut (Elite) | C23: Wednesday | D23: =SUM('Day 1'!K54) -> 42 | E23: =D23+D24 -> 75 | G23: =SUM('Day 2'!K91) -> 44 | H23: =G23+G24 -> 71 | J23: =SUM('Day 3'!J22) -> 26 | K23: =J23+J24 -> 58 | M23: =SUM('Day 4'!K56) -> 39 | N23: =M23+M24 -> 69 | P23: =SUM('Day 5'!K56) -> 41 | Q23: =P23+P24 -> 71 | S23: =+E23+H23+K23+N23+Q23 -> 344
C24: Friday | D24: =SUM('Day 1'!K66) -> 33 | G24: =SUM('Day 2'!K104) -> 27 | J24: =SUM('Day 3'!J36) -> 32 | M24: =SUM('Day 4'!K69) -> 30 | P24: =SUM('Day 5'!K68) -> 30
B26: TEAM F: Francesca Sciortino (Fireball) | C26: Wednesday | D26: =SUM('Day 1'!K85) -> 34 | E26: =D26+D27 -> 64 | G26: =SUM('Day 2'!K58) -> 36 | H26: =G26+G27 -> 62 | J26: =SUM('Day 3'!K22) -> 28 | K26: =J26+J27 -> 69 | M26: =SUM('Day 4'!K86) -> 32 | N26: =M26+M27 -> 77 | P26: =SUM('Day 5'!K21) -> 25 | Q26: =P26+P27 -> 71 | S26: =+E26+H26+K26+N26+Q26 -> 343
C27: Friday | D27: =SUM('Day 1'!K97) -> 30 | G27: =SUM('Day 2'!K71) -> 26 | J27: =SUM('Day 3'!K36) -> 41 | M27: =SUM('Day 4'!K101) -> 45 | P27: =SUM('Day 5'!K36) -> 46
B33: Winners:
B35: Runners Up:

Sheet Day 1
B2: VITTORIOSA LAWN TENNIS CLUB
B3: TENNIS TRADE TEAM TOURNAMENT 2024
C5: DAY 1 - 30/10/2024 & 01/11/2024
C8: Court 1
C10: Time | D10: Rubber | E10: Team A: Alison (Alla Maghna) | G10: vs | H10: Team C: Kaya (Challengers) | J10: Games
C11: 6.30 pm | D11: Men D | E11: Joseph Randich | F11: Chris Vella | G11: vs | H11: Matthew Micallef | I11: Justin Scicluna | J11: 6 | K11: 12 | L11: w/o 0-5
C14: 7.45 pm | D14: Lad A | E14: Natalya Abela | F14: Alison Muscat | G14: vs | H14: Ann Marie Mangion | I14: Pierina Holmin | J14: 9 | K14: 9
C17: 9.00 pm | D17: Lad B | E17: Doriana Portelli | F17: Silvana Portelli | G17: vs | H17: Kaya Sammut | I17: Mariska Steenkamer | J17: 2 | K17: 16
C21: Total Day 1 A | J21: =SUM(J11:J19) -> 17 | K21: =SUM(K11:K19) -> 37
C23: 6.30 pm | D23: Men A | E23: Matthew Mifsud | F23: Clyde Grech | G23: vs | H23: Jesmond Pule` | I23: Manuel Bonello | J23: 13 | K23: 6
C26: 6.30 pm | D26: Men B | E26: Chi Chi Canonce | F26: Lydon Vella | G26: vs | H26: Jonathan Vella | I26: Jayboy Lastimosa | J26: 9 | K26: 9
C29: 7.45 pm | D29: Lad C | E29: Heidi Tabone | F29: Daphne Vella | G29: vs | H29: Maria Ellul | I29: Leanne Sammut | J29: 9 | K29: 9
C32: 9.00 pm | D32: Men C | E32: Victor Rutter | F32: Kyle Magro | G32: vs | H32: Jean Paul Vella | I32: Dunstan Vella | J32: 10 | K32: 8
C35: Total Day 1B | J35: =SUM(J23:J33) -> 41 | K35: =SUM(K23:K33) -> 32
C37: Total Day 1 | J37: =J35+J21 -> 58 | K37: =K35+K21 -> 69
C39: Court 2
C41: Time | D41: Rubber | E41: Team B: Lonia (Love all) | G41: vs | H41: Team E: Juan (Elite) | J41: Games
C42: 6.30 pm | D42: Lad C | E42: Lonia Carabott | F42: Marica Cassar | G42: vs | H42: Maria Angela Gambin | I42: Bernardette Fenech | J42: 7 | K42: 11
C45: 7.45 pm | D45: Men A | E45: Clayton Zammit Cesare | F45: Kurt Carabott | G45: vs | H45: Matthew Borg | I45: Duncan D`alessandro | J45: 10 | K45: 9
C48: 7.45 pm | D48: Lad A | E48: Lara Pule` | F48: Kirsty Mercieca | G48: vs | H48: Kim Fava | I48: Olivia Belli | J48: 6 | K48: 12
C51: 9.00 pm | D51: Men D | E51: Cory Greenland | F51: JP Sciberras | G51: vs | H51: Antoine Bugeja | I51: Twanny Pule` | J51: 8 | K51: 10
C54: Total Day 1 A | J54: =SUM(J42:J52) -> 31 | K54: =SUM(K42:K52) -> 42
C56: 6.30 pm | D56: Lad B | E56: Kristina Briffa | F56: Marcette Sciriha | G56: vs | H56: Alexia Gouder | I56: Dominique Francica | J56: 5 | K56: 13
C59: 7.45 pm | D59: Men B | E59: Roderick Spiteri | F59: Julian Bilocca | G59: vs | H59: Roberto Murdocco | I59: Emman Xuereb | J59: 9 | K59: 9
C62: 9.00 pm | D62: Men C | E62: Manuel Mifsud | F62: Maurice Borg | G62: vs | H62: Max Anastasi | I62: David Camilleri | J62: 7 | K62: 11
C66: Total Day 1B | J66: =SUM(J56:J64) -> 21 | K66: =SUM(K56:K64) -> 33
C68: Total Day 1 | J68: =SUM(J54+J66) -> 52 | K68: =K66+K54 -> 75
C70: Court 4
C72: Time | D72: Rubber | E72: Team D: Kelsey (Destroyers) | G72: vs | H72: Team F: Francesca (Fireball) | J72: Games
C73: 6.30 pm | D73: Lad C | E73: Ruth Micallef | F73: Janice Galea | G73: vs | H73: Christine Seychell | I73: Anna Napier | J73: 10 | K73: 8
C76: 6.30 pm | D76: Men C | E76: Frans Ellul | F76: Darrell Pace | G76: vs | H76: Julian Esposito | I76: Charles Micallef | J76: 9 | K76: 9
C79: 8.00 pm | D79: Lad B | E79: Romina Gauci | F79: Stephanie Farrugia | G79: vs | H79: Francesca Sciortino | I79: Brenda Baldacchino | J79: 11 | K79: 7
C82: 9.00 pm | D82: Men B | E82: Ivan Cachia | F82: Clint Agius | G82: vs | H82: Cyril Lastimosa | I82: Kristen Cachia | J82: 8 | K82: 10
C85: Total Day 1 A | J85: =SUM(J73:J83) -> 38 | K85: =SUM(K73:K83) -> 34
C87: 6.30 pm | D87: Lad A | E87: Anthea Gauci | F87: Kelsey Gauci | G87: vs | H87: Renette Magro | I87: Julie Spiteri | J87: 1 | K87: 17
C90: 7.45 pm | D90: Men D | E90: Kenneth Caruana | F90: Isaac Baldacchino | G90: vs | H90: Charles Borg Grech | I90: Robert Attard | J90: 14 | K90: 4
C93: 9.00 pm | D93: Men A | E93: Melchior Farrugia | F93: Marco Mercieca | G93: vs | H93: Adrian Chetcuti | I93: Claude Mifsud Wismayer | J93: 10 | K93: 9
C97: Total Day 1B | J97: =SUM(J87:J95) -> 25 | K97: =SUM(K87:K95) -> 30
C99: Total Day 1 | J99: =J97+J85 -> 63 | K99: =K97+K85 -> 64

Sheet Day 2
B2: VITTORIOSA LAWN TENNIS CLUB
B3: TENNIS TRADE TEAM TOURNAMENT 2024
C6: DAY 2 - 08/11/2024 & 04/12/2024
C9: Court 1
C11: Time | D11: Rubber | E11: Team B: Lonia (Love All) | H11: Team D: Kelsey (Destroyers) | J11: Games
C13: 6.30 pm | D13: Men D | E13: Cory Greenland | F13: Mario Abdilla | G13: vs | H13: Kevin Sciberras | I13: Isaac Baldacchino | J13: 12 | K13: 7
C16: 7.45 pm | D16: Lad A | E16: Kirsty Mercieca | F16: Tiziana Anastasi | G16: vs | H16: Martina Cuschieri | I16: Kelsey Gauci | J16: 11 | K16: 7
C19: 9.00 pm | D19: Men A | E19: Clayton Zammit Cesare | F19: Kurt Carabott | G19: vs | H19: Melchior Farrugia | I19: Marco Mercieca | J19: 9 | K19: 9
C22: 6.30 pm | D22: Lad C | E22: Lonia Carabott | F22: Stefania Camilleri | G22: vs | H22: Janice Galea | I22: Mary Borg | J22: 6 | K22: 12
C25: Total Day 2 A | J25: =SUM(J15:J23) -> 26 | K25: =SUM(K15:K23) -> 28
C28: 6.30 pm | D28: Men B | E28: Roderick Spiteri | F28: Kevin Formosa | G28: vs | H28: Ivan Cachia | I28: Ivan Cassar | J28: 9 | K28: 9
C31: 7.45 pm | D31: Lad B | E31: Kristina Briffa | F31: Ann Marie Attard | G31: vs | H31: Romina Gauci | I31: Angele Pule' | J31: 9 | K31: 9
C34: 9.00 pm | D34: Men C | E34: Manuel Mifsud | F34: Mario Abdilla (pro Ryan Ebejer) | G34: vs | H34: Frans Ellul | I34: Isaac Joseph Zammit | J34: 9 | K34: 9
C38: Total Day 2 B | J38: =SUM(J28:J36) -> 27 | K38: =SUM(K28:K36) -> 27
C40: Total Day 2 | J40: =J38+J25 -> 53 | K40: =K38+K25 -> 55
C42: Court 2
C44: Time | D44: Rubber | E44: Team A: Alison (Alla Maghna) | G44: vs | H44: Team F: Francesca (Fireball) | J44: Games
C46: 7.45pm | D46: Lad B | E46: Doriana Portelli | F46: Jin Attard | G46: vs | H46: Brenda Baldacchino | I46: Deborah Farrugia | J46: 15 | K46: 3
C49: 6.30 pm | D49: Lad A | E49: Alison Muscat | F49: Natalaya Abela | G49: vs | H49: Renette Magro | I49: Diane Fenech | J49: 4 | K49: 14
C52: 6.30 pm | D52: Men D | E52: Donald Deguzman | F52: Joseph Randich | G52: vs | H52: Glenn Micallef | I52: Robert Attard | J52: 12 | K52: 7
C55: 7.45pm | D55: Men B | E55: Lydon Vella (PRO)Chi Chi Canonce | F55: Kyle Magro (PRO)Mavric Sawyer | G55: vs | H55: Kristen Cachia | I55: Julian Esposito (PRO) Neville Sciriha | J55: 6 | K55: 12
J58: =SUM(J46:J56) -> 37 | K58: =SUM(K46:K56) -> 36
C61: 6.30 pm | D61: Men A | E61: Matthew Mifsud | F61: David Schembri | G61: vs | H61: Adrian Chetcuti | I61: John Azzopardi | J61: 11 | K61: 7
C64: 7.45 pm | D64: Men C | E64: Kyle Magro | F64: Juan Debono | G64: vs | H64: Julian Esposito | I64: Matthew Schembri | J64: 8 | K64: 10
C67: 9.00 pm | D67: Lad C | E67: Heidi Tabone | F67: Christine Scerri | G67: vs | H67: Christine Seychell | I67: Lillian Baldacchino | J67: 9 | K67: 9
C71: Total Day 2 B | J71: =SUM(J61:J69) -> 28 | K71: =SUM(K61:K69) -> 26
C73: Total Day 2 | J73: =J71+J58 -> 65 | K73: =K71+K58 -> 62
C75: Court 4
C77: Time | D77: Rubber | E77: Team C: Kaya (Challengers) | H77: Team E: Juan (Elite) | J77: Games
C79: 6.30 pm | D79: Lad C | E79: Maria Ellul | F79: Jean Frendo | G79: vs | H79: Maria Angela Gambin | I79: Jodie Stivala | J79: 3 | K79: 15
C82: 7.45 pm | D82: Lad A | E82: Annmarie Mangion | F82: Anabel Borg | G82: vs | H82: Olivia Belli | I82: Annabelle Abela | J82: 11 | K82: 7
C85: 9.00 pm | D85: Lad B | E85: Kaya Sammut | F85: Sarah Axiaq | G85: vs | H85: Alexia Gouder | I85: Tanya Cassar | J85: 9 | K85: 9
C88: 7.45 pm | D88: Men D | E88: Matthew Micallef | F88: Justin Scicluna (Dem) Michael Bugeja | G88: vs | H88: Antoine Bugeja | I88: Adam Green | J88: 6 | K88: 13
C91: Total Day 2 A | J91: =SUM(J79:J89) -> 29 | K91: =SUM(K79:K89) -> 44
C94: 6.30 pm | D94: Men B | E94: Jonathan Vella | F94: Gene Zammit | G94: vs | H94: Emman Xuereb | I94: Willem Steenkamer | J94: 9 | K94: 9
C97: 7.45 pm | D97: Men A | E97: Jesmond Pule' | F97: Jean Attard | G97: vs | H97: Duncan D'Alessandro | I97: Kurt Cassar | J97: 14 | K97: 4
C100: 9.00 pm | D100: Men C | E100: Steve Gambin | F100: Dunstan Vella | G100: vs | H100: Max Anastasi | I100: Charles Sacco | J100: 4 | K100: 14
C104: Total Day 2 B | J104: =SUM(J94:J102) -> 27 | K104: =SUM(K94:K102) -> 27
C106: Total Day 2 | J106: =J104+J91 -> 56 | K106: =K104+K91 -> 71

Sheet Day 3
C2: VITTORIOSA LAWN TENNIS CLUB
C3: TENNIS TRADE TEAM TOURNAMENT 2024
C5: Day 3 - 13/11/2024 & 15/11/2024
C8: Court 1
C10: Time | D10: Rubber | E10: Team E: Juan (Elite) | G10: vs | H10: Team F: Francesca (Fireball) | J10: Games
C12: 6.30 pm | D12: Men A | E12: Matthew Borg | F12: Kurt Cassar | G12: vs | H12: Claude Mifsud Wismayer | I12: John Azzopardi | J12: 10 | K12: 8
C15: 7.45 pm | D15: Lad A | E15: Kim Fava | F15: Olivia Belli | G15: vs | H15: Renette Magro | I15: Diane Fenech | J15: 10 | K15: 8
C18: 9.00 pm | D18: Men D | E18: Adam Green | F18: Anthony Pule' | G18: vs | H18: Charles Borg Grech | I18: Glenn Micallef | J18: 6 | K18: 12
C22: Total Day 3 A | J22: =SUM(J12:J20) -> 26 | K22: =SUM(K12:K20) -> 28
C24: 6.30 pm | D24: Lad B | E24: Domenique Francica | F24: Tanya Cassar | G24: vs | H24: Francesca Sciortino | I24: Deborah Farrugia | J24: 9 | K24: 10
C27: 7.45 pm | D27: Men C | E27: Charles Sacco | F27: David Camilleri | G27: vs | H27: Julian Esposito | I27: Charles Micallef | J27: 7 | K27: 11
C30: 9.00 pm | D30: Men B | E30: Roberto Murdocco | F30: Willem Stennkamer | G30: vs | H30: Kristen Cachia | I30: Neville Sciriha | J30: 8 | K30: 10
D33: Lad C | E33: Jodie Stivala | F33: Bernardette Fenech | G33: vs | H33: Anna Napier | I33: Lillian Baldacchino | J33: 8 | K33: 10
C36: Total Day 3 B | J36: =SUM(J24:J34) -> 32 | K36: =SUM(K24:K34) -> 41
C38: Total Day 3 | J38: =J36+J22 -> 58 | K38: =K36+K22 -> 69
C40: Court 2
C42: Time | D42: Rubber | E42: Team B: Lonia (Love All) | G42: vs | H42: Team C: Kaya (Challengers) | J42: Games
C44: 6.30 pm | D44: Men C | E44: Manuel Mifsud | F44: Ryan Ebejer | G44: vs | H44: Jean Paul Vella | I44: Steve Gambin | J44: 7 | K44: 11
C47: 7.45 pm | D47: Lad C | E47: Lonia Carabott | F47: Stefania Camilleri | G47: vs | H47: Leanne Sammur | I47: Jean Frendo | J47: 14 | K47: 4
C50: 9.00 pm | D50: Men B | E50: Kevin Formosa | F50: Julian Bilocca | G50: vs | H50: Jayboy Lastimosa | I50: Gene Zammit | J50: 7 | K50: 11
C54: Total Day 3 A | J54: =SUM(J44:J52) -> 28 | K54: =SUM(K44:K52) -> 26
C56: 6.30 pm | D56: Men A | E56: Clayton Zammit Cesare | F56: Keith Micallef | G56: vs | H56: Jean Atard | I56: Manuel Bonello | J56: 13 | K56: 5
C59: 7.45 pm | D59: Lad B | E59: Marcette Sciriha | F59: Ann Marie Attard | G59: vs | H59: Mariska Steenkamer | I59: Sarah Axiaq | J59: 8 | K59: 11
C62: 9.00 pm | D62: Lad A | E62: Kirsty Mercieca | F62: Tiziana Anastasi | G62: vs | H62: Pierina Holmin | I62: Anabel Borg | J62: 13 | K62: 5
C65: 7.45pm | D65: Men D | E65: Cory Greenland | F65: Mario Abdilla | G65: vs | H65: Justin Scicluna | I65: Michael Bugeja | J65: 16 | K65: 2
C68: Total Day 3 B | J68: =SUM(J56:J66) -> 50 | K68: =SUM(K56:K66) -> 23
C70: Total Day 3 | J70: =J68+J54 -> 78 | K70: =K68+K54 -> 49
C72: Court 4
C74: Time | D74: Rubber | E74: Team A: Alison (Alla Maghna) | G74: vs | H74: Team D: Kelsey (Destroyers) | J74: Games
C76: 6.30 pm | D76: Lad B | E76: Jin Attard | F76: Silvana Portelli | G76: vs | H76: Romina Gauci | I76: Angele Pule' | J76: 11 | K76: 8
C79: 7.45 pm | D79: Lad A | E79: Natalya Abela | F79: Amanda Falzon | G79: vs | H79: Martina Cuschieri | I79: Kelsey Gauci | J79: 10 | K79: 8
C82: 9.00 pm | D82: Men A | E82: Clyde Grech | F82: David Schembri | G82: vs | H82: Marco Mercieca | I82: Gabriel Pace | J82: 6 | K82: 12
C86: Total Day 3 A | J86: =SUM(J76:J84) -> 27 | K86: =SUM(K76:K84) -> 28
C88: 6.30 pm | D88: Men C | E88: Kyle Magro | F88: Victor Rutter | G88: vs | H88: Frans Ellul | I88: Darrell Pace | J88: 14 | K88: 4
C91: 7.45 pm | D91: Men B | E91: Lydon Vella | F91: Mavric Sawyer | G91: vs | H91: Clint Agius | I91: Ivan Cassar | J91: 6 | K91: 12
C94: 9.00 pm | D94: Men D | E94: Donald Deguzman | F94: Chris Vella | G94: vs | H94: Kenneth Caruana | I94: Isaac Baldacchino | J94: 11 | K94: 7
C97: 9.00pm | D97: Lad C | E97: Heidi Tabone | F97: Daphne Vella | G97: vs | H97: Ruth Micallef | I97: Mary Borg | J97: 11 | K97: 7
C100: Total Day 3 B | J100: =SUM(J88:J98) -> 42 | K100: =SUM(K88:K98) -> 30
C102: Total Day 3 | J102: =J100+J86 -> 69 | K102: =K100+K86 -> 58

Sheet Day 4
C2: VITTORIOSA LAWN TENNIS CLUB
C3: TENNIS TRADE TEAM TOURNAMENT 2024
B6: Day 4 - 20/11/2024 & 22/11/2024
C9: Court 1
C11: Time | D11: Rubber | E11: Team C: Kaya (Challengers) | G11: vs | H11: Team D: Kelsey (Destroyers) | J11: Games
C12: Court 1
C13: 6.30 pm | D13: Men C | E13: Dunstan Vella | F13: Steve Gambin | G13: vs | H13: Darrell Pace | I13: Isaac Joseph Zammit | J13: 11 | K13: 7
C16: 7.45 pm | D16: Men B | E16: Jonathan Vella | F16: Gene Zammit | G16: vs | H16: Ivan Cachia | I16: Clint Agius | J16: 10 | K16: 8
C19: 7.45 pm | D19: Men D | E19: Matthew Micallef | F19: Justin Scicluna | G19: vs | H19: Isaac Baldacchino | I19: Kevin Sciberras | J19: 11 | K19: 7
C22: 45647 | D22: Lad A | E22: Ann Marie Mangion | F22: Anabel Borg | G22: vs | H22: Martina Cuschieri | I22: Anthea Gauci | J22: 13 | K22: 6
C25: Total Day 4 A | J25: =SUM(J13:J23) -> 45 | K25: =SUM(K13:K23) -> 28
C27: 6.30 pm | D27: Lad B | E27: Kaya Sammut | F27: Sarah Axiaq | G27: vs | H27: Stephanie Farrugia | I27: Angele Pule` | J27: 12 | K27: 6
C30: 6.30 pm | D30: Lad C | E30: Maria Ellul | F30: Leanne Sammut | G30: vs | H30: Ruth Micallef | I30: Mary Borg | J30: 11 | K30: 7
C33: 7.45 pm | D33: Men A | E33: Jesmond Pule` | F33: Jean Attard | G33: vs | H33: Melchior Farrugia | I33: Gabriel Pace | J33: 9 | K33: 9
C37: Total Day 4 B | J37: =SUM(J27:J35) -> 32 | K37: =SUM(K27:K35) -> 22
C39: Total Day 4 | J39: =J37+J25 -> 77 | K39: =K37+K25 -> 50
C41: Court 2
C43: Time | D43: Rubber | E43: Team A: Alison (Alla Maghna) | G43: vs | H43: Team E: Juan (Elite) | J43: Games
C44: 6.30 pm | D44: Lad A | E44: Natalya Abela | F44: Amanda Falzon | G44: vs | H44: Kim Fava | I44: Annabelle Abela | J44: 11 | K44: 8
C47: 6.30 pm | D47: Lad C | E47: Christine Scerri | F47: Daphne Vella | G47: vs | H47: Maria Angela Gambin | I47: Jodie Stivala | J47: 6 | K47: 12
C50: 7.45 pm | D50: Lad B | E50: Doriana Portelli | F50: Silvana Portelli | G50: vs | H50: Alexia Gouder | I50: Tanya Cassar | J50: 7 | K50: 11
C53: 9.00 pm | D53: Men A | E53: Matthew Mifsud | F53: David Schembri | G53: vs | H53: Matthew Borg | I53: Duncan D`Alessandro | J53: 10 | K53: 8
C56: Total Day 4 A | J56: =SUM(J44:J54) -> 34 | K56: =SUM(K44:K54) -> 39
C59: 9.00 pm | D59: Men B | E59: Chi Chi Canonce | F59: Mavric Sawyer | G59: vs | H59: Roberto Murdocco | I59: Emman Xuereb | J59: 0 | K59: 18 | L59: w/o
C62: 6.30 pm | D62: Men D | E62: Donald Deguzman | F62: Joseph Randich | G62: vs | H62: Antoine Bugeja | I62: Anthony Pule` | J62: 15 | K62: 3
C65: 9.00 pm | D65: Men C | E65: Juan Debono | F65: Victor Rutter | G65: vs | H65: Max Anastasi | I65: Charles Sacco | J65: 9 | K65: 9
C69: Total Day 4 B | J69: =SUM(J59:J67) -> 24 | K69: =SUM(K59:K67) -> 30
C71: Total Day 4 | J71: =J69+J56 -> 58 | K71: =K69+K56 -> 69
C73: Court 4
C75: Time | D75: Rubber | E75: Team B: Lonia (Love All) | G75: vs | H75: Team F: Francesca (Fireball) | J75: Games
C76: 6.30 pm | D76: Lad C | E76: Marica Cassar | F76: Stefania Camilleri | G76: vs | H76: Christine Seychell | I76: Anna Napier | J76: 6 | K76: 12
C79: 7.45 pm | D79: Lad A | E79: Lara Pule` | F79: Kirsty Mercieca | G79: vs | H79: Diane Fenech | I79: Julie Spiteri | J79: 12 | K79: 7
C82: 7.45 pm | D82: Lad B | E82: Kristina Briffa | F82: Ann Marie Attard | G82: vs | H82: Francesca Sciortino | I82: Deborah Farrugia | J82: 5 | K82: 13
C86: Total Day 4 A | J86: =SUM(J76:J84) -> 23 | K86: =SUM(K76:K84) -> 32
C89: 6.30 pm | D89: Men D | E89: Mario Abdilla | F89: JP Sciberras | G89: vs | H89: Charles Borg Grech | I89: Glenn Micallef | J89: 9 | K89: 9
C92: 7.45 pm | D92: Men C | E92: Maurice Borg | F92: Ryan Ebejer | G92: vs | H92: Matthew Schembri | I92: Charles Micallef | J92: 8 | K92: 10
C95: Mon 16th 8.30pm | D95: Men A | E95: Kurt Carabott | F95: Keith Micallef | G95: vs | H95: Adrian Chetcuti | I95: John Azzopardi | J95: 5 | K95: 13
C98: 9.00 pm | D98: Men B | E98: Roderick Spiteri | F98: Kevin Formosa | G98: vs | H98: Cyril Lastimosa | I98: Kristen Cachia | J98: 5 | K98: 13
C101: Total Day 4 B | J101: =SUM(J89:J99) -> 27 | K101: =SUM(K89:K99) -> 45
C103: Total Day 4 | J103: =J101+J86 -> 50 | K103: =K101+K86 -> 77

Sheet Day 5
C2: VITTORIOSA LAWN TENNIS CLUB
C3: TENNIS TRADE TEAM TOURNAMENT 2024
C5: Day 5 - 29/11/2024 & 02/12/2024
C8: Court 1
C10: Time | D10: Rubber | E10: Team C: Kaya (Challengers) | G10: vs | H10: Team F: Francesca (Fireball) | J10: Games
C11: 7.45 pm | D11: Men A | E11: Jesmond Pule' | F11: Manuel Bonello | G11: vs | H11: Adrian Chetcuti | I11: Claude Mifsud Wismayer | J11: 11 | K11: 7
C14: 9.00 pm | D14: Men C | E14: Jean Paul Vella | F14: Dunstan Vella | G14: vs | H14: Julian Esposito | I14: Matthew Schembri | J14: 7 | K14: 11
C17: 18 Dec 8.30 pm | D17: Lad B | E17: Kaya Sammut | F17: Mariska Steenkamer | G17: vs | H17: Francesca Sciortino | I17: Brenda Baldacchino | J17: 11 | K17: 7
C21: Total Day 5 A | J21: =SUM(J11:J19) -> 29 | K21: =SUM(K11:K19) -> 25
C24: 6.30 pm | D24: Lad C | E24: Leanne Sammut | F24: Jean Frendo | G24: vs | H24: Christine Seychell | I24: Lillian Baldacchino | J24: 5 | K24: 14
C27: 6.30 pm | D27: Lad A | E27: Annmarie Mangion | F27: Pierina Holmin | G27: vs | H27: Renette Magro | I27: Julie Spiteri | J27: 7 | K27: 11
C30: 7.45 pm | D30: Men B | E30: Jonathan Vella | F30: Jayboy Lastimosa | G30: vs | H30: Cyril Lastimosa | I30: Neville Sciriha | J30: 10 | K30: 8
C33: 7.45 pm | D33: Men D | E33: Justin Scicluna | F33: Michael Bugeja | G33: vs | H33: Glenn Micallef | I33: Robert Attard | J33: 5 | K33: 13
C36: Total Day 5B | J36: =SUM(J24:J34) -> 27 | K36: =SUM(K24:K34) -> 46
C38: Total Day 5 | J38: =J36+J21 -> 56 | K38: =K36+K21 -> 71
C40: Court 2
C42: Time | D42: Rubber | E42: Team D: Kelsey (Destroyers) | G42: vs | H42: Team E: Juan (Elite) | J42: Games
C44: 6.30 pm | D44: Lad B | E44: Romina Gauci | F44: Stephanie Farrugia | G44: vs | H44: Alexia Gouder | I44: Dominique Francica | J44: 1 | K44: 17
C47: 7.45 pm | D47: Men C | E47: Frans Ellul | F47: Isaac Joseph Zammit | G47: vs | H47: Charles Sacco | I47: David Camilleri | J47: 11 | K47: 7
C50: 9.00 pm | D50: Men D | E50: Kenneth Caruana | F50: Kevin Sciberras | G50: vs | H50: Antoine Bugeja | I50: Adam Green | J50: 10 | K50: 8
C53: 9.00 pm | D53: Men B | E53: Ivan Cachia | F53: Ivan Cassar | G53: vs | H53: Roberto Murdocco | I53: Max Anastasi (pro Willen Steenkamer) | J53: 9 | K53: 9
C56: Total Day 5 A | J56: =SUM(J44:J54) -> 31 | K56: =SUM(K44:K54) -> 41
C58: 6.30 pm | D58: Lad C | E58: Janice Galea | F58: Mary Borg | G58: vs | H58: Maria Angela Gambin | I58: Bernardette Fenech | J58: 6 | K58: 13
C61: 7.45 pm | D61: Lad A | E61: Anthea Gauci | F61: Kelsey Gauci | G61: vs | H61: Kim Fava | I61: Annabelle Abela | J61: 7 | K61: 11
C64: 9.00 pm | D64: Men A | E64: Melchior Farrugia | F64: Gabriel Pace | G64: vs | H64: Matthew Borg | I64: Kurt Cassar | J64: 12 | K64: 6
C68: Total Day 5B | J68: =SUM(J58:J66) -> 25 | K68: =SUM(K58:K66) -> 30
C70: Total Day 5 | J70: =J68+J56 -> 56 | K70: =K68+K56 -> 71
C72: Court 4
C74: Time | D74: Rubber | E74: Team A: Alison (Alla Maghna) | G74: vs | H74: Team B: Lonia (Love All) | J74: Games
C76: 6.30 pm | D76: Men D | E76: Donald Deguzman | F76: Chris Vella | G76: vs | H76: Cory Greenland | I76: Jean Paul Sciberras | J76: 11 | K76: 7
C79: 6.30 pm | D79: Lad C | E79: Heidi Tabone | F79: Christine Scerri | G79: vs | H79: Lonia Carabott | I79: Marica Cassar | J79: 9 | K79: 10
C82: 7.45 pm | D82: Lad B | E82: Doriana Portelli | F82: Jin Attard | G82: vs | H82: Marcette Sciriha | I82: Ann-Marie Attard | J82: 13 | K82: 5
C85: 9.00 pm | D85: Men C | E85: Kyle Magro | F85: Juan Debono | G85: vs | H85: Manuel Mifsud | I85: Maurice Borg | J85: 12 | K85: 6
C88: Total Day 5 A | J88: =SUM(J76:J86) -> 45 | K88: =SUM(K76:K86) -> 28
C90: 6.30 pm | D90: Lad A | E90: Amanda Falzon | F90: Alison Muscat | G90: vs | H90: Lara Pule` | I90: Tiziana Anastasi | J90: 9 | K90: 9
C93: 7.45 pm | D93: Men A | E93: Matthew Mifsud | F93: Clyde Grech | G93: vs | H93: Clayton Zammit Cesare | I93: Keith Micallef | J93: 10 | K93: 8
C96: 9.00 pm | D96: Men B | E96: Chi Chi Canonce | F96: Lydon Vella | G96: vs | H96: Roderick Spiteri | I96: Julian Bilocca | J96: 9 | K96: 9
C100: Total Day 5 B | J100: =SUM(J90:J98) -> 28 | K100: =SUM(K90:K98) -> 26
C102: Total Day 5 | J102: =J100+J88 -> 73 | K102: =K100+K88 -> 54

Sheet Semi Final
C2: VITTORIOSA LAWN TENNIS CLUB
C3: TENNIS TRADE TEAM TOURNAMENT 2024
C6: Semi Final -
C9: Court 1
C11: Time | D11: Rubber | E11: Team : CHALLENGERS | G11: vs | H11: Team : ELITE CREW | J11: Games
C12: 6.30 pm | D12: Men D | E12: Justin Scicluna | F12: Matthew Micallef | G12: vs | H12: Antoine Bugeja | I12: Anthony Pule' | J12: 10 | K12: 8
C15: 7.45 pm | D15: Men A | E15: Jesmond Pule' | F15: Jean Attard | G15: vs | H15: Matthew Borg | I15: Duncan D'Alessandro | J15: 14 | K15: 4
C18: 9.00 pm | D18: Lad A | E18: Annmarie Mangion | F18: Pierina Holmin | G18: vs | H18: Kim Fava | I18: Olivia Belli | J18: 11 | K18: 7
C22: Total Day 2 A | J22: =SUM(J12:J20) -> 35 | K22: =SUM(K12:K20) -> 19
C24: 6.30 pm | D24: Men B | E24: Jonathan Vella | F24: Jayboy Lastimosa | G24: vs | H24: Emman Xuereb | I24: Roberto Murdocco | J24: 12 | K24: 7
C27: 6.30 pm | D27: Lad C | E27: Maria Ellul | F27: Leanne Sammut | G27: vs | H27: Maria Angela Gambin | I27: Jodie Stivala | J27: 7 | K27: 11
C30: 7.45 pm | D30: Men C | E30: Jean Paul Vella | F30: Steve Gambin | G30: vs | H30: Max Anastasi | I30: Charles Sacco | J30: 13 | K30: 5
C33: 9.00 pm | D33: Lad B | E33: Kaya Sammut | F33: Mariska Steenkamer | G33: vs | H33: Alexia Gouder | I33: Dominique Francica | J33: 11 | K33: 7
C36: Total Day 2B | J36: =SUM(J24:J34) -> 43 | K36: =SUM(K24:K34) -> 30
C38: Total Day 2 | J38: =J22+J36 -> 78 | K38: =K22+K36 -> 49
C40: Court 2
C42: Time | D42: Rubber | E42: Team : FIREBALL | G42: vs | H42: Team : ALLA MAGHNA | J42: Games
C43: 6.30 pm | D43: Men A | E43: Adrian Chetcuti | F43: John Azzopardi | G43: vs | H43: Matthew Mifsud | I43: Clyde Grech | J43: 5 | K43: 13
C46: 7.45 pm | D46: Men B | E46: Cyril Lastimosa | F46: Kristen Cachia | G46: vs | H46: Chi Chi Canonce | I46: Lydon Vella | J46: 10 | K46: 9
C49: 9.00 pm | D49: Lad A | E49: Renette Magro | F49: Diane Fenech | G49: vs | H49: Natalya Abela | I49: Amanda Falzon | J49: 13 | K49: 5
C53: Total Day 2 A | J53: =SUM(J43:J51) -> 28 | K53: =SUM(K43:K51) -> 27
C55: 6.30 pm | D55: Men D | E55: Glenn Micallef | F55: Robert Attard | G55: vs | H55: Joseph Randich | I55: Donald Deguzman | J55: 6 | K55: 12
C58: 7.45 pm | D58: Men C | E58: Julian Esposito | F58: Matthew Schembri | G58: vs | H58: Kyle Magro | I58: Juan Debono | J58: 9 | K58: 9
C61: 7.45 pm | D61: Lad C | E61: Christine Seychell | F61: Anna Napier | G61: vs | H61: Heidi Tabone | I61: Daphne Vella | J61: 13 | K61: 5
C64: 9.00 pm | D64: Lad B | E64: Francesca Sciortino | F64: Deborah Farrugia | G64: vs | H64: Doriana Portelli | I64: Silvana Portelli | J64: 11 | K64: 7
C67: Total Day 2B | J67: =SUM(J55:J65) -> 39 | K67: =SUM(K55:K65) -> 33
C69: Total Day 2 | J69: =J53+J67 -> 67 | K69: =K53+K67 -> 60

Sheet Final
B2: VITTORIOSA LAWN TENNIS CLUB
B3: TENNIS TRADE TEAM TOURNAMENT 2024
C6: Final - 22/01/25
C11: Time | D11: Rubber | E11: Team C: Kaya Sammut (Challengers) | G11: vs | H11: Team E: Francesca Sciortino (Fireball) | J11: Games
C13: 6.30 pm | D13: Men A | E13: Manuel Bonello | F13: Jean Attard | G13: vs | H13: Adrian Chetcuti | I13: Claude Mifsud Wismayer | J13: 11 | K13: 7
C16: 6.30 pm | D16: Lad C | E16: Maria Ellul | F16: Leanne Sammut | G16: vs | H16: Anna Napier | I16: Christine Seychell | J16: 9 | K16: 9
C19: 6.30 pm | D19: Men D | E19: Justin Scicluna | F19: Matthew Micallef | G19: vs | H19: Glenn Micallef | I19: Robert Attard | J19: 7 | K19: 11
C22: 7.45 pm | D22: Lad B | E22: Kaya Sammut | F22: Mariska Stennkamer | G22: vs | H22: Francesca Sciortino | I22: Brenda Baldacchino | J22: 11 | K22: 7
C25: 7.45 pm | D25: Lad A | E25: Annmarie Mangion | F25: Pierina Holmin | G25: vs | H25: Renette Magro | I25: Julie Spiteri | J25: 5 | K25: 13
C28: 7.45 pm | D28: Men C | E28: Jean Paul Tabone | F28: Steve Gambin | G28: vs | H28: Julian Esposito | I28: Matthew Schembri | J28: 11 | K28: 8
C31: 7.45 pm | D31: Men B | E31: Gene Zammit | F31: Jayboy Lastimosa | G31: vs | H31: Kristen Cachia | I31: Cyril Lastimosa | J31: 9 | K31: 9
C34: 9.00pm | G34: vs
G37: vs
C40: Total Final | J40: =J13+J16+J19+J22+J25+J28+J31+J34+J37 -> 63 | K40: =K13+K16+K19+K22+K25+K28+K31+K34 -> 64
