Workbook

Sheet Team Selection
A1: VITTORIOSA LAWN TENNIS CLUB
A3: WILSON AUTUMN TEAM TOURNAMENT 2021
B4: A | C4: B | D4: C | E4: D | F4: E | G4: F
A5: CAPTAIN | B5: Darrell Pace | C5: Roberto Murdocco | D5: Olivia Belli | E5: Lonia Carabott | F5: Diane Debono | G5: Christine Scerri
A7: MEN
A8: A1 | B8: Marc Vella Bonnici | C8: Marcelo Villanueva | D8: Jesmond Pule | E8: Kurt Carabott | F8: Clyde Grech | G8: Adrian Chetcuti
A9: A2 | B9: Trevor Rutter | C9: Andrew Spiteri Willets | D9: Nicolai Belli | E9: Kurt Sapiano | F9: Norbert Coleiro | G9: Nicholas Gollcher
A10: A3 | B10: Clive Borg | C10: David Schembri | D10: Marco Mercieca | E10: Reuben Borg | F10: John Azzopardi | G10: Keith Micallef
A12: B1 | B12: George Grech | C12: Duncan D'Alessandro | D12: Luigi Porto | E12: Albert Pace Asciak | F12: Melchior Farrugia | G12: Andrew Pule
A13: B2 | B13: James Farrugia | C13: Roderick Spiteri | D13: Richard Byrne | E13: Willem Steenkamer | F13: Ivan Cachia | G13: Eric Roca
A14: B3 | B14: Gabriel Pace | C14: Marco Borg | D14: Stephen Belli | E14: Tobias Kristensen | F14: Neville Sciriha | G14: Earvin Grech Meli
A16: C1 | B16: Eric Micallef | C16: ROBERTO MURDOCCO | D16: Maurice Borg | E16: Joe Carabott | F16: Keith Tanti | G16: Kevin Formosa
A17: C2 | B17: Jonathan Vella | C17: Gene Zammit | D17: Ryan Mizzi | E17: Mavric Sawyer | F17: Frans Ellul | G17: Stefan Licari
A18: C3 | B18: James Brincat | C18: Clint Agius | D18: John Sciberras | E18: Max Anastasi | F18: Victor Rutter | G18: Matthew Schembri
A19: C4 | B19: DARRELL PACE | C19: Manuel Mifsud | D19: Ray Ciantar | E19: Julian Esposito | F19: Alain Frendo | G19: Juan Debono
A21: D1 | B21: Jake Gatt | C21: Charles Sacco | D21: Mario Abdilla | E21: Kenneth Caruana | F21: Aaron Micallef Piccone | G21: Jesmond Cachia
A22: D2 | B22: Ahmed Eln Akroud | C22: Anthony Pule' | D22: Isaac Joseph Zammit | E22: Ralf Bahmuller | F22: Shawn Roderick Sciberras | G22: Charles Borg Grech
A23: D3 | B23: Kristen Cachia | C23: Joseph Randich | D23: Ryan Ebejer | E23: Max Anastasi Jr | F23: Franco Montesin | G23: Matthew Napier
A25: LADIES
A26: A1 | B26: Nicole Fava | C26: Erica Azzopardi | D26: Kim Fava | E26: Alexia Spiteri Willets | F26: Martina Cuschieri | G26: Christine Schembri
A27: A2 | B27: Sharon Mizzi | C27: Amanda Falzon | D27: OLIVIA BELLI | E27: Rebecca Pace | F27: Elaine Grech | G27: Yanika Pace
A28: A3 | B28: Alison Muscat | C28: Doriana Portelli | D28: Sarah Vella | E28: Anthea Gauci | F28: Kirsty Mercieca | G28: Audrey Friggieri
A30: B1 | B30: Silvana Portelli | C30: Annabelle Abela | D30: Romina Gauci | E30: Julia Barbara | F30: Tiziana Anastasi | G30: Yasmine Hefny
A31: B2 | B31: Brenda Baldacchino | C31: Nancy Wong | D31: Mariska Steenkamer | E31: Marcette Sciriha | F31: Dominique Francica | G31: Rowena Caruana
A32: B3 | B32: Monica Muscat | C32: Deborah Farrugia | D32: Alexia Gouder | E32: Monique Attard | F32: Tanya Cassar | G32: Carmen Difesa
A33: B4 | B33: Anabele Borg | C33: Andrea Mifsud | D33: Ceridwen Scerri | E33: LONIA CARABOTT | F33: DIANE DEBONO | G33: Jennifer Mifsud
A35: C1 | B35: Ruth Micallef | C35: Jennifer Roca | D35: Yvonne Borg Cardona | E35: Josette D'Alessandro | F35: Christine Seychell | G35: Anna Buhagiar
A36: C2 | B36: Nicole Lia | C36: Josette Cassar | D36: Helga Azzopardi | E36: Mary Borg | F36: Michelle Mahoney | G36: CHRISTINE SCERRI
A37: C3 | B37: Kristina Briffa | C37: Joyce Scerri | D37: Bernardette Fenech | E37: Claire Genovese | F37: Mary Ciantar | G37: Yvette Rutter

Sheet Standings
B2: VITTORIOSA LAWN TENNIS CLUB
B3: WILSON AUTUMN TEAM TOURNAMENT 2021
C6: ROUND 1
D8: Day 1 | F8: Total Day 1 | I8: Day 2 | K8: Total Day 2 | N8: Day 3 | P8: Total Day 3 | S8: Day 4 | U8: Total Day 4 | X8: Day 5 | Z8: Total Day 5 | AC8: Total Round 1
D9: G | E9: S | F9: G | G9: S | I9: G | J9: S | K9: G | L9: S | N9: G | O9: S | P9: G | Q9: S | S9: G | T9: S | U9: G | V9: S | X9: G | Y9: S | Z9: G | AA9: S | AC9: G | AD9: S
B11: TEAM A: Darrell Pace | C11: Wednesday | D11: =SUM('Day 1'!J23) -> 30 | E11: =SUM('Day 1'!L23) -> 2 | F11: =D11+D12 -> 74 | G11: =E11+E12 -> 9 | I11: =SUM('Day 2'!J55) -> 39 | J11: =SUM('Day 2'!L55) -> 6 | K11: =I11+I12 -> 78 | L11: =SUM(J11+J12) -> 10 | N11: =SUM('Day 3'!J88) -> 38 | O11: =SUM('Day 3'!L88) -> 4 | P11: =N11+N12 -> 81 | Q11: =O11+O12 -> 8 | S11: =SUM('Day 4'!J55) -> 22 | T11: =SUM('Day 4'!L55) -> 2 | U11: =S11+S12 -> 61 | V11: =T11+T12 -> 5 | X11: =SUM('Day 5'!J87) -> 40 | Y11: =SUM('Day 5'!L87) -> 5 | Z11: =X11+X12 -> 80 | AA11: =Y11+Y12 -> 11 | AC11: =+F11+K11+P11+U11+Z11 -> 374 | AD11: =+G11+L11+Q11+V11+AA11 -> 43
C12: Friday | D12: =SUM('Day 1'!J37) -> 44 | E12: =SUM('Day 1'!L37) -> 7 | I12: =SUM('Day 2'!J69) -> 39 | J12: =SUM('Day 2'!L69) -> 4 | N12: =SUM('Day 3'!J102) -> 43 | O12: =SUM('Day 3'!L102) -> 4 | S12: =SUM('Day 4'!J69) -> 39 | T12: =SUM('Day 4'!L69) -> 3 | X12: =SUM('Day 5'!J101) -> 40 | Y12: =SUM('Day 5'!L101) -> 6
B14: TEAM B: Roberto Murdocco | C14: Wednesday | D14: =SUM('Day 1'!J56) -> 30 | E14: =SUM('Day 1'!L56) -> 2 | F14: =D14+D15 -> 76 | G14: =E14+E15 -> 9 | I14: =SUM('Day 2'!J22) -> 34 | J14: =SUM('Day 2'!L22) -> 2 | K14: =I14+I15 -> 70 | L14: =SUM(J14+J15) -> 7 | N14: =SUM('Day 3'!J55) -> 32 | O14: =SUM('Day 3'!L55) -> 3 | P14: =N14+N15 -> 72 | Q14: =O14+O15 -> 9 | S14: =SUM('Day 4'!J88) -> 28 | T14: =SUM('Day 4'!L88) -> 3 | U14: =S14+S15 -> 67 | V14: =T14+T15 -> 8 | X14: =SUM('Day 5'!K87) -> 30 | Y14: =SUM('Day 5'!M87) -> 3 | Z14: =X14+X15 -> 52 | AA14: =Y14+Y15 -> 5 | AC14: =+F14+K14+P14+U14+Z14 -> 337 | AD14: =+G14+L14+Q14+V14+AA14 -> 38
C15: Friday | D15: =SUM('Day 1'!J70) -> 46 | E15: =SUM('Day 1'!L70) -> 7 | I15: =SUM('Day 2'!J36) -> 36 | J15: =SUM('Day 2'!L36) -> 5 | N15: =SUM('Day 3'!J69) -> 40 | O15: =SUM('Day 3'!L69) -> 6 | S15: =SUM('Day 4'!J102) -> 39 | T15: =SUM('Day 4'!L102) -> 5 | X15: =SUM('Day 5'!K101) -> 22 | Y15: =SUM('Day 5'!M101) -> 2
B17: TEAM C: Olivia Belli | C17: Wednesday | D17: =SUM('Day 1'!K23) -> 44 | E17: =SUM('Day 1'!M23) -> 6 | F17: =D17+D18 -> 69 | G17: =E17+E18 -> 7 | I17: =SUM('Day 2'!J88) -> 34 | J17: =SUM('Day 2'!L88) -> 3 | K17: =I17+I18 -> 71 | L17: =SUM(J17+J18) -> 8 | N17: =SUM('Day 3'!K55) -> 39 | O17: =SUM('Day 3'!M55) -> 5 | P17: =N17+N18 -> 78 | Q17: =O17+O18 -> 7 | S17: =SUM('Day 4'!J22) -> 41 | T17: =SUM('Day 4'!L22) -> 5 | U17: =S17+S18 -> 87 | V17: =T17+T18 -> 11 | X17: =SUM('Day 5'!J21) -> 36 | Y17: =SUM('Day 5'!L21) -> 4 | Z17: =X17+X18 -> 70 | AA17: =Y17+Y18 -> 8 | AC17: =+F17+K17+P17+U17+Z17 -> 375 | AD17: =+G17+L17+Q17+V17+AA17 -> 41
C18: Friday | D18: =SUM('Day 1'!K37) -> 25 | E18: =SUM('Day 1'!M37) -> 1 | I18: =SUM('Day 2'!J102) -> 37 | J18: =SUM('Day 2'!L102) -> 5 | N18: =SUM('Day 3'!K69) -> 39 | O18: =SUM('Day 3'!M69) -> 2 | S18: =SUM('Day 4'!J36) -> 46 | T18: =SUM('Day 4'!L36) -> 6 | X18: =SUM('Day 5'!J35) -> 34 | Y18: =SUM('Day 5'!L35) -> 4
B20: TEAM D: Lonia Carabott | C20: Wednesday | D20: =SUM('Day 1'!J89) -> 38 | E20: =SUM('Day 1'!L89) -> 5 | F20: =D20+D21 -> 81 | G20: =E20+E21 -> 11 | I20: =SUM('Day 2'!K22) -> 44 | J20: =SUM('Day 2'!M22) -> 6 | K20: =I20+I21 -> 73 | L20: =SUM(J20+J21) -> 9 | N20: =SUM('Day 3'!K88) -> 30 | O20: =SUM('Day 3'!M88) -> 4 | P20: =N20+N21 -> 70 | Q20: =O20+O21 -> 8 | S20: =SUM('Day 4'!K22) -> 33 | T20: =SUM('Day 4'!M22) -> 3 | U20: =S20+S21 -> 62 | V20: =T20+T21 -> 5 | X20: =SUM('Day 5'!J54) -> 40 | Y20: =SUM('Day 5'!L54) -> 5 | Z20: =X20+X21 -> 77 | AA20: =Y20+Y21 -> 7 | AC20: =+F20+K20+P20+U20+Z20 -> 363 | AD20: =+G20+L20+Q20+V20+AA20 -> 40
C21: Friday | D21: =SUM('Day 1'!J104) -> 43 | E21: =SUM('Day 1'!L104) -> 6 | I21: =SUM('Day 2'!K36) -> 29 | J21: =SUM('Day 2'!M36) -> 3 | N21: =SUM('Day 3'!K102) -> 40 | O21: =SUM('Day 3'!M102) -> 4 | S21: =SUM('Day 4'!K36) -> 29 | T21: =SUM('Day 4'!M36) -> 2 | X21: =SUM('Day 5'!J68) -> 37 | Y21: =SUM('Day 5'!L68) -> 2
B23: TEAM E: Diane Debono | C23: Wednesday | D23: =SUM('Day 1'!K56) -> 43 | E23: =SUM('Day 1'!M56) -> 6 | F23: =D23+D24 -> 76 | G23: =E23+E24 -> 7 | I23: =SUM('Day 2'!K88) -> 41 | J23: =SUM('Day 2'!M88) -> 5 | K23: =I23+I24 -> 74 | L23: =SUM(J23+J24) -> 8 | N23: =SUM('Day 3'!J22) -> 44 | O23: =SUM('Day 3'!L22) -> 6 | P23: =N23+N24 -> 83 | Q23: =O23+O24 -> 10 | S23: =SUM('Day 4'!K55) -> 46 | T23: =SUM('Day 4'!M55) -> 6 | U23: =S23+S24 -> 93 | V23: =T23+T24 -> 11 | X23: =SUM('Day 5'!K54) -> 36 | Y23: =SUM('Day 5'!M54) -> 3 | Z23: =X23+X24 -> 84 | AA23: =Y23+Y24 -> 9 | AC23: =+F23+K23+P23+U23+Z23 -> 410 | AD23: =+G23+L23+Q23+V23+AA23 -> 45
C24: Friday | D24: =SUM('Day 1'!K70) -> 33 | E24: =SUM('Day 1'!M70) -> 1 | I24: =SUM('Day 2'!K102) -> 33 | J24: =SUM('Day 2'!M102) -> 3 | N24: =SUM('Day 3'!J36) -> 39 | O24: =SUM('Day 3'!L36) -> 4 | S24: =SUM('Day 4'!K69) -> 47 | T24: =SUM('Day 4'!M69) -> 5 | X24: =SUM('Day 5'!K68) -> 48 | Y24: =SUM('Day 5'!M68) -> 6
B26: TEAM F: Christine Scerri | C26: Wednesday | D26: =SUM('Day 1'!K89) -> 37 | E26: =SUM('Day 1'!M89) -> 3 | F26: =D26+D27 -> 61 | G26: =E26+E27 -> 5 | I26: =SUM('Day 2'!K55) -> 29 | J26: =SUM('Day 2'!M55) -> 2 | K26: =I26+I27 -> 67 | L26: =SUM(J26+J27) -> 6 | N26: =SUM('Day 3'!K22) -> 29 | O26: =SUM('Day 3'!M22) -> 2 | P26: =N26+N27 -> 67 | Q26: =O26+O27 -> 6 | S26: =SUM('Day 4'!K88) -> 35 | T26: =SUM('Day 4'!M88) -> 5 | U26: =S26+S27 -> 74 | V26: =T26+T27 -> 8 | X26: =SUM('Day 5'!K21) -> 39 | Y26: =SUM('Day 5'!M21) -> 4 | Z26: =X26+X27 -> 75 | AA26: =Y26+Y27 -> 8 | AC26: =+F26+K26+P26+U26+Z26 -> 344 | AD26: =+G26+L26+Q26+V26+AA26 -> 33
C27: Friday | D27: =SUM('Day 1'!K104) -> 24 | E27: =SUM('Day 1'!M104) -> 2 | I27: =SUM('Day 2'!K69) -> 38 | J27: =SUM('Day 2'!M69) -> 4 | N27: =SUM('Day 3'!K36) -> 38 | O27: =SUM('Day 3'!M36) -> 4 | S27: =SUM('Day 4'!K102) -> 39 | T27: =SUM('Day 4'!M102) -> 3 | X27: =SUM('Day 5'!K35) -> 36 | Y27: =SUM('Day 5'!M35) -> 4
B33: Winners:
B35: Runners Up:

Sheet Encounters played
A2: VITTORIOSA LAWN TENNIS CLUB
A3: WILSON AUTUMN TEAM TOURNAMENT 2021
B5: Day | C5: 1 | D5: 2 | E5: 3 | F5: 4 | G5: 5 | H5: Total | J5: Day | K5: 1 | L5: 2 | M5: 3 | N5: 4 | O5: 5 | P5: Total
A6: A | B6: Darrell Pace | I6: B | J6: Roberto Murdocco
A7: A1 | B7: Marc Vella Bonnici | C7: 1 | D7: 1 | E7: 1 | G7: 1 | H7: =SUM(C7:G7) -> 4 | I7: A1 | J7: Marcelo Villanueva | K7: 1 | L7: 1 | M7: 1 | N7: 1 | P7: =SUM(K7:O7) -> 4
A8: A2 | B8: Trevor Rutter | C8: 1 | D8: 1 | F8: 1 | H8: =SUM(C8:G8) -> 3 | I8: A2 | J8: Andrew Spiteri Willets | K8: 1 | L8: 1 | O8: 1 | P8: =SUM(K8:O8) -> 3
A9: A3 | B9: Clive Borg | E9: 1 | F9: 1 | G9: 1 | H9: =SUM(C9:G9) -> 3 | I9: A3 | J9: David Schembri | M9: 1 | N9: 1 | O9: 1 | P9: =SUM(K9:O9) -> 3
A10: B1 | B10: George Grech | C10: 1 | D10: 1 | F10: 1 | G10: 1 | H10: =SUM(C10:G10) -> 4 | I10: B1 | J10: Duncan D'Alessandro | K10: 1 | L10: 1 | N10: 1 | O10: 1 | P10: =SUM(K10:O10) -> 4
A11: B2 | B11: James Farrugia | C11: 1 | E11: 1 | F11: 1 | H11: =SUM(C11:G11) -> 3 | I11: B2 | J11: Roderick Spiteri | K11: 1 | M11: 1 | O11: 1 | P11: =SUM(K11:O11) -> 3
A12: B3 | B12: Gabriel Pace | D12: 1 | E12: 1 | G12: 1 | H12: =SUM(C12:G12) -> 3 | I12: B3 | J12: Marco Borg | L12: 1 | M12: 1 | N12: 1 | P12: =SUM(K12:O12) -> 3
A13: C1 | B13: Eric Micallef | C13: 1 | D13: 1 | E13: 1 | G13: 1 | H13: =SUM(C13:G13) -> 4 | I13: C1 | J13: ROBERTO MURDOCCO | L13: 1 | M13: 1 | N13: 1 | O13: 1 | P13: =SUM(K13:O13) -> 4
A14: C2 | B14: Jonathan Vella | C14: 1 | D14: 1 | F14: 1 | G14: 1 | H14: =SUM(C14:G14) -> 4 | I14: C2 | J14: Gene Zammit | K14: 1 | L14: 1 | M14: 1 | O14: 1 | P14: =SUM(K14:O14) -> 4
A15: C3 | B15: James Brincat | C15: 1 | E15: 1 | F15: 1 | G15: 1 | H15: =SUM(C15:G15) -> 4 | I15: C3 | J15: Clint Agius | K15: 1 | L15: 1 | N15: 1 | P15: =SUM(K15:O15) -> 3
A16: C4 | B16: DARRELL PACE | D16: 1 | E16: 1 | F16: 1 | H16: =SUM(C16:G16) -> 3 | I16: C4 | J16: Manuel Mifsud | K16: 1 | M16: 1 | N16: 1 | O16: 1 | P16: =SUM(K16:O16) -> 4
A17: D1 | B17: Jake Gatt | C17: 1 | D17: 1 | F17: 1 | G17: 1 | H17: =SUM(C17:G17) -> 4 | I17: D1 | J17: Charles Sacco | K17: 1 | L17: 1 | N17: 1 | P17: =SUM(K17:O17) -> 3
A18: D2 | B18: Ahmed Eln Akroud | D18: 1 | E18: 1 | G18: 1 | H18: =SUM(C18:G18) -> 3 | I18: D2 | J18: Anthony Pule' | K18: 1 | M18: 1 | N18: 1 | P18: =SUM(K18:O18) -> 3
A19: D3 | B19: Kristen Cachia | C19: 1 | E19: 1 | F19: 1 | H19: =SUM(C19:G19) -> 3 | I19: D3 | J19: Joseph Randich | L19: 1 | M19: 1 | P19: =SUM(K19:O19) -> 2
A21: A1 | B21: Nicole Fava | C21: 1 | E21: 1 | F21: 1 | G21: 1 | H21: =SUM(C21:G21) -> 4 | I21: A1 | J21: Erica Azzopardi | K21: 1 | L21: 1 | M21: 1 | P21: =SUM(K21:O21) -> 3
A22: A2 | B22: Sharon Mizzi | D22: 1 | E22: 1 | G22: 1 | H22: =SUM(C22:G22) -> 3 | I22: A2 | J22: Amanda Falzon | K22: 1 | N22: 1 | P22: =SUM(K22:O22) -> 2
A23: A3 | B23: Alison Muscat | C23: 1 | D23: 1 | F23: 1 | H23: =SUM(C23:G23) -> 3 | I23: A3 | J23: Doriana Portelli | L23: 1 | M23: 1 | N23: 1 | P23: =SUM(K23:O23) -> 3
A24: B1 | B24: Silvana Portelli | C24: 1 | D24: 1 | E24: 1 | G24: 1 | H24: =SUM(C24:G24) -> 4 | I24: B1 | J24: Annabelle Abela | K24: 1 | L24: 1 | M24: 1 | O24: 1 | P24: =SUM(K24:O24) -> 4
A25: B2 | B25: Brenda Baldacchino | C25: 1 | D25: 1 | F25: 1 | G25: 1 | H25: =SUM(C25:G25) -> 4 | I25: B2 | J25: Nancy Wong | K25: 1 | L25: 1 | M25: 1 | N25: 1 | P25: =SUM(K25:O25) -> 4
A26: B3 | B26: Monica Muscat | C26: 1 | E26: 1 | F26: 1 | H26: =SUM(C26:G26) -> 3 | I26: B3 | J26: Deborah Farrugia | K26: 1 | N26: 1 | O26: 1 | P26: =SUM(K26:O26) -> 3
A27: B4 | B27: Anabel Borg | D27: 1 | E27: 1 | F27: 1 | G27: 1 | H27: =SUM(C27:G27) -> 4 | I27: B4 | J27: Andrea Mifsud | L27: 1 | M27: 1 | N27: 1 | O27: 1 | P27: =SUM(K27:O27) -> 4
A28: C1 | B28: Ruth Micallef | C28: 1 | D28: 1 | G28: 1 | H28: =SUM(C28:G28) -> 3 | I28: C1 | J28: Jennifer Roca | K28: 1 | M28: 1 | N28: 1 | P28: =SUM(K28:O28) -> 3
A29: C2 | B29: Nicole Lia | C29: 1 | E29: 1 | F29: 1 | G29: 1 | H29: =SUM(C29:G29) -> 4 | I29: C2 | J29: Josette Cassar | K29: 1 | L29: 1 | N29: 1 | P29: =SUM(K29:O29) -> 3
A30: C3 | B30: Kristina Briffa | D30: 1 | E30: 1 | F30: 1 | H30: =SUM(C30:G30) -> 3 | I30: C3 | J30: Joyce Scerri | L30: 1 | M30: 1 | P30: =SUM(K30:O30) -> 2
B42: Day | C42: 1 | D42: 2 | E42: 3 | F42: 4 | G42: 5 | H42: Total | J42: Day | K42: 1 | L42: 2 | M42: 3 | N42: 4 | O42: 5 | P42: Total
A43: C | B43: Olivia Belli | I43: D | J43: Lonia Carabott
A44: A1 | B44: Jesmond Pule | C44: 1 | D44: 1 | F44: 1 | G44: 1 | H44: =SUM(C44:G44) -> 4 | I44: A1 | J44: Kurt Carabott | K44: 1 | M44: 1 | N44: 1 | O44: 1 | P44: =SUM(K44:O44) -> 4
A45: A2 | B45: Nikolai Bell | C45: 1 | E45: 1 | G45: 1 | H45: =SUM(C45:G45) -> 3 | I45: A2 | J45: Kurt Sapiano | K45: 1 | L45: 1 | N45: 1 | P45: =SUM(K45:O45) -> 3
A46: A3 | B46: Marco Mercieca | D46: 1 | E46: 1 | F46: 1 | H46: =SUM(C46:G46) -> 3 | I46: A3 | J46: Reuben Borg | L46: 1 | M46: 1 | O46: 1 | P46: =SUM(K46:O46) -> 3
A47: B1 | B47: Luigi Porto | C47: 1 | D47: 1 | E47: 1 | G47: 1 | H47: =SUM(C47:G47) -> 4 | I47: B1 | J47: Albert Pace Asciak | K47: 1 | L47: 1 | N47: 1 | P47: =SUM(K47:O47) -> 3
A48: B2 | B48: Richard Byrne | C48: 1 | E48: 1 | F48: 1 | H48: =SUM(C48:G48) -> 3 | I48: B2 | J48: Willem Steenkamer | L48: 1 | M48: 1 | N48: 1 | O48: 1 | P48: =SUM(K48:O48) -> 4
A49: B3 | B49: Stephen Belli | D49: 1 | F49: 1 | G49: 1 | H49: =SUM(C49:G49) -> 3 | I49: B3 | J49: Tobias Kristensen | K49: 1 | M49: 1 | O49: 1 | P49: =SUM(K49:O49) -> 3
A50: C1 | B50: Maurice Borg | D50: 1 | E50: 1 | F50: 1 | G50: 1 | H50: =SUM(C50:G50) -> 4 | I50: C1 | J50: Joe Carabott | K50: 1 | L50: 1 | N50: 1 | O50: 1 | P50: =SUM(K50:O50) -> 4
A51: C2 | B51: Ryan Mizzi | C51: 1 | D51: 1 | F51: 1 | G51: 1 | H51: =SUM(C51:G51) -> 4 | I51: C2 | J51: Mavric Sawyer | K51: 1 | M51: 1 | N51: 1 | O51: 1 | P51: =SUM(K51:O51) -> 4
A52: C3 | B52: John Sciberras | C52: 1 | D52: 1 | E52: 1 | G52: 1 | H52: =SUM(C52:G52) -> 4 | I52: C3 | J52: Max Anastasi | K52: 1 | L52: 1 | M52: 1 | N52: 1 | P52: =SUM(K52:O52) -> 4
A53: C4 | B53: Ray Ciantar | C53: 1 | E53: 1 | F53: 1 | H53: =SUM(C53:G53) -> 3 | I53: C4 | J53: Julian Esposito | L53: 1 | M53: 1 | O53: 1 | P53: =SUM(K53:O53) -> 3
A54: D1 | B54: Mario Abdilla | C54: 1 | D54: 1 | F54: 1 | G54: 1 | H54: =SUM(C54:G54) -> 4 | I54: D1 | J54: Kenneth Caruana | L54: 1 | N54: 1 | O54: 1 | P54: =SUM(K54:O54) -> 3
...

Sheet Day 1
C1: Wilson Team Tournament 2021
C5: DAY 1 - 3/11/2021 & 5/11/2021
C8: Court 1
C10: Time | D10: Rubber | E10: Team A: Darrell Pace | G10: vs | H10: Team C: Olivia Belli | J10: Games | L10: Sets
C11: 6.30 pm | D11: Lad C | E11: Ruth Micallef | F11: Nicole Lia | G11: vs | H11: Yvonne Borg Cardona | I11: Bernardette Fenech | J11: 3 | K11: 6 | L11: =IF(J11>K11,1,0) + IF(J12>K12,1,0) -> 0 | M11: =IF(J11<K11,1,0) + IF(J12<K12,1,0) -> 2
J12: 2 | K12: 6
C14: 7.45 pm | D14: Men C | E14: Jonathan Vella | F14: Eric Micallef | G14: vs | H14: Ray Ciantar | I14: Ryan Mizzi | J14: 2 | K14: 6 | L14: =IF(J14>K14,1,0) + IF(J15>K15,1,0) -> 1 | M14: =IF(J14<K14,1,0) + IF(J15<K15,1,0) -> 1
J15: 6 | K15: 3
C17: 9.00 pm | D17: Men B | E17: George Grech | F17: James Farrugia | G17: vs | H17: Luigi Porto | I17: Richard Byrne | J17: 5 | K17: 7 | L17: =(IF(J17>K17,1,0)+IF(J18>K18,1,0)) -> 1 | M17: =(IF(J17<K17,1,0)+IF(J18<K18,1,0)) -> 1
J18: 6 | K18: 4
C20: 6.30 pm | D20: Lad B | E20: Silvana Portelli | F20: Monica Muscat | G20: vs | H20: Romina Gauci | I20: Alexia Gouder | J20: 4 | K20: 6 | L20: =IF(J20>K20, 1, 0) + IF(J21>K21, 1, 0) -> 0 | M20: =IF(J20<K20, 1, 0) + IF(J21<K21, 1, 0) -> 2
J21: 2 | K21: 6
C23: Total Day 1 A | J23: =SUM(J11:J21) -> 30 | K23: =SUM(K11:K21) -> 44 | L23: =SUM(L11:L20) -> 2 | M23: =SUM(M11:M20) -> 6
C25: 6.30 pm | D25: Men D | E25: Jake Gatt | F25: Kirsten Cachia | G25: vs | H25: Mario Abdilla | I25: Ryan Ebjer | J25: 6 | K25: 4 | L25: =(IF(J25>K25,1,0)+IF(J26>K26,1,0)) -> 2 | M25: =(IF(J25<K25,1,0)+IF(J26<K26,1,0)) -> 0
J26: 7 | K26: 5
C28: 7.45 pm | D28: Lad A | E28: Nicole Fava | F28: Alison Muscat | G28: vs | H28: Kim Fava | I28: Olivia Belli | J28: 6 | K28: 2 | L28: =(IF(J28>K28,1,0)+IF(J29>K29,1,0)) -> 1 | M28: =(IF(J28<K28,1,0)+IF(J29<K29,1,0)) -> 1
J29: 0 | K29: 6
C31: 9.00 pm | D31: Lad A | E31: Marc Vella Bonnici | F31: Trevor Rutter | G31: vs | H31: Jesmond Pule' | I31: Nikolai Belli | J31: 6 | K31: 0 | L31: =(IF(J31>K31,1,0)+IF(J32>K32,1,0)) -> 2 | M31: =(IF(J31<K31,1,0)+IF(J32<K32,1,0)) -> 0
J32: 7 | K32: 5
C34: 6.30 pm | D34: MXD CB | E34: James Brincat | F34: Brenda Baldacchino | G34: vs | H34: John Sciberras | I34: Ceridwen Scerri | J34: 6 | K34: 1 | L34: =(IF(J34>K34,1,0)+IF(J35>K35,1,0)) -> 2 | M34: =(IF(J34<K34,1,0)+IF(J35<K35,1,0)) -> 0
J35: 6 | K35: 2
C37: Total Day 1B | J37: =SUM(J25:J35) -> 44 | K37: =SUM(K25:K35) -> 25 | L37: =SUM(L25:L35) -> 7 | M37: =SUM(M25:M35) -> 1
C39: Total Day 1 | J39: =J37+J23 -> 74 | K39: =K37+K23 -> 69 | L39: =L37+L23 -> 9 | M39: =M37+M23 -> 7
C41: Court 2
C43: Time | D43: Rubber | E43: Team B: Roberto Murdocco | G43: vs | H43: Team E: Diane Debono | J43: Games | L43: Sets
C44: 6.30 pm | D44: Lad C | E44: Jennifer Roca | F44: Josette Cassar | G44: vs | H44: Christine Seychell | I44: Michelle Mahoney | J44: 7 | K44: 6 | L44: =(IF(J44>K44,1,0)+IF(J45>K45,1,0)) -> 2 | M44: =(IF(J44<K44,1,0)+IF(J45<K45,1,0)) -> 0
J45: 6 | K45: 1
C47: 7.45 pm | D47: Men c | E47: Gene Zammit | F47: Manuel Mifsud | G47: vs | H47: Frans Ellul | I47: Keith Tanti | J47: 4 | K47: 6 | L47: =(IF(J47>K47,1,0)+IF(J48>K48,1,0)) -> 0 | M47: =(IF(J47<K47,1,0)+IF(J48<K48,1,0)) -> 2
J48: 2 | K48: 6
C50: 9.00 pm | D50: Men B | E50: Duncan D'alessandro | F50: Roderick Spiteri | G50: vs | H50: Melchior Farrugia | I50: Ivan Cachia | J50: 3 | K50: 6 | L50: =(IF(J50>K50,1,0)+IF(J51>K51,1,0)) -> 0 | M50: =(IF(J50<K50,1,0)+IF(J51<K51,1,0)) -> 2
J51: 4 | K51: 6
C53: 7.45 pm | D53: Lad B | E53: Nancy Wong | F53: Deborah Farrugia | G53: vs | H53: Tiziana Borg Anastasi | I53: Dominique Francica | J53: 1 | K53: 6 | L53: =(IF(J53>K53,1,0)+IF(J54>K54,1,0)) -> 0 | M53: =(IF(J53<K53,1,0)+IF(J54<K54,1,0)) -> 2
J54: 3 | K54: 6
C56: Total Day 1 A | J56: =SUM(J44:J54) -> 30 | K56: =SUM(K44:K54) -> 43 | L56: =SUM(L44:L54) -> 2 | M56: =SUM(M44:M54) -> 6
C58: 6.3 | D58: Men D | E58: Charles Sacco | F58: Anthony Pule' | G58: vs | H58: Aaron Micallef Piccione | I58: Shawn Roderick Sciberras | J58: 6 | K58: 4 | L58: =(IF(J58>K58,1,0)+IF(J59>K59,1,0)) -> 2 | M58: =(IF(J58<K58,1,0)+IF(J59<K59,1,0)) -> 0
J59: 6 | K59: 4
C61: 7.45 | D61: Men A | E61: Marcelo Villanueva | F61: Andrew Spiteri Willets | G61: vs | H61: Clyde Grech | I61: Norbert Coleiro | J61: 6 | K61: 3 | L61: =(IF(J61>K61,1,0)+IF(J62>K62,1,0)) -> 2 | M61: =(IF(J61<K61,1,0)+IF(J62<K62,1,0)) -> 0
J62: 6 | K62: 4
C64: 9 | D64: Lad A | E64: Erika Azzopardi | F64: Amanda Falzon | G64: vs | H64: Martina Cuschieri | I64: Elaine Grech | J64: 6 | K64: 4 | L64: =(IF(J64>K64,1,0)+IF(J65>K65,1,0)) -> 1 | M64: =(IF(J64<K64,1,0)+IF(J65<K65,1,0)) -> 1
J65: 3 | K65: 6
...

Sheet Day 2
C1: Wilson Team Tournament 2021
C4: Day 2 10/11-2021 - 12/11/2021
C7: Court 1
C9: Time | D9: Rubber | E9: Team B: Roberto Murdocco | H9: Team D: Lonia Carabott | J9: Games | L9: Sets
C10: 6.30 pm | D10: MXD CB | E10: Gene Zammit | F10: Nancy Wong | G10: vs | H10: Julian Esposito | I10: Marcette Sciriha | J10: 6 | K10: 7 | L10: =IF(J10>K10,1,0) + IF(J11>K11,1,0) -> 0 | M10: =IF(J10<K10,1,0) + IF(J11<K11,1,0) -> 2
J11: 2 | K11: 6
C13: 7.45 pm | D13: Men B | E13: Duncan D'Alessandro | F13: Marco Borg | G13: vs | H13: Albert Pace Asciak | I13: Willem Steenkamer | J13: 3 | K13: 6 | L13: =IF(J13>K13,1,0) + IF(J14>K14,1,0) -> 0 | M13: =IF(J13<K13,1,0) + IF(J14<K14,1,0) -> 2
J14: 4 | K14: 6
C16: 9.00 pm | D16: Men A | E16: Marcelo Villanueva | F16: Andrew Spiteri Willets | G16: vs | H16: Kurt Sapiano | I16: Reuben Borg | J16: 4 | K16: 6 | L16: =(IF(J16>K16,1,0)+IF(J17>K17,1,0)) -> 1 | M16: =(IF(J16<K16,1,0)+IF(J17<K17,1,0)) -> 1
J17: 6 | K17: 4
C19: 6.30 pm | D19: Men C | E19: Roberto Murdocco | F19: Clint Agius | G19: vs | H19: Joe Carabott | I19: Max Anastasi | J19: 6 | K19: 3 | L19: =(IF(J19>K19,1,0)+IF(J20>K20,1,0)) -> 1 | M19: =(IF(J19<K19,1,0)+IF(J20<K20,1,0)) -> 1
J20: 3 | K20: 6
C22: Total Day 2 A | J22: =SUM(J10:J20) -> 34 | K22: =SUM(K10:K20) -> 44 | L22: =SUM(L10:L20) -> 2 | M22: =SUM(M10:M20) -> 6
C24: 6.30 pm | D24: Men D | E24: Charles Sacco | F24: Joseph Randich | G24: vs | H24: Kenneth Caruana | I24: Ralf Bahmuller | J24: 6 | K24: 2 | L24: =(IF(J24>K24,1,0)+IF(J25>K25,1,0)) -> 2 | M24: =(IF(J24<K24,1,0)+IF(J25<K25,1,0)) -> 0
J25: 6 | K25: 0
C26: 7.45 pm
D27: Lad B | E27: Annabelle Abela | F27: Andrea Mifsud | G27: vs | H27: Julia Barbara | I27: Lonia Carabott | J27: 3 | K27: 6 | L27: =(IF(J27>K27,1,0)+IF(J28>K28,1,0)) -> 0 | M27: =(IF(J27<K27,1,0)+IF(J28<K28,1,0)) -> 2
J28: 2 | K28: 6
C30: 9.00 pm | D30: Lad A | E30: Erika Azzopardi | F30: Doriana Portelli | G30: vs | H30: Alexia Spiteri Willets | I30: Anthea Gauci | J30: 6 | K30: 3 | L30: =(IF(J30>K30,1,0)+IF(J31>K31,1,0)) -> 2 | M30: =(IF(J30<K30,1,0)+IF(J31<K31,1,0)) -> 0
J31: 6 | K31: 2
C33: 6.30 pm | D33: Lad C | E33: Josette Cassar | F33: Joyce Scerri | G33: vs | H33: Mary Borg | I33: Claire Genovese | J33: 6 | K33: 4 | L33: =(IF(J33>K33,1,0)+IF(J34>K34,1,0)) -> 1 | M33: =(IF(J33<K33,1,0)+IF(J34<K34,1,0)) -> 1
J34: 1 | K34: 6
C36: Total Day 2 B | J36: =SUM(J24:J34) -> 36 | K36: =SUM(K24:K34) -> 29 | L36: =SUM(L24:L34) -> 5 | M36: =SUM(M24:M34) -> 3
C38: Total Day 2 | J38: =J36+J22 -> 70 | K38: =K36+K22 -> 73 | L38: =L36+L22 -> 7 | M38: =M36+M22 -> 9
C40: Court 2
C42: Time | D42: Rubber | E42: Team A: Darrell Pace | G42: vs | H42: Team F: Christine Scerri | J42: Games | L42: Sets
C43: 6.30 pm | D43: Lad A | E43: Sharon Mizzi | F43: Alison Muscat | G43: vs | H43: Christine Schembri | I43: Audrey Friggieri | J43: 7 | K43: 6 | L43: =(IF(J43>K43,1,0)+IF(J44>K44,1,0)) -> 2 | M43: =(IF(J43<K43,1,0)+IF(J44<K44,1,0)) -> 0
J44: 6 | K44: 1
C46: 7.45 pm | D46: Men B | E46: George Grech | F46: Gabriel Pace | G46: vs | H46: Eric Roca | I46: Andrew Pule' | J46: 2 | K46: 6 | L46: =(IF(J46>K46,1,0)+IF(J47>K47,1,0)) -> 0 | M46: =(IF(J46<K46,1,0)+IF(J47<K47,1,0)) -> 2
J47: 0 | K47: 6
C49: 9.00 pm | D49: Men A | E49: Marc Vella Bonnici | F49: Trevor Rutter | G49: vs | H49: Adrian Chetcuti | I49: Keith Micallef | J49: 6 | K49: 4 | L49: =(IF(J49>K49,1,0)+IF(J50>K50,1,0)) -> 2 | M49: =(IF(J49<K49,1,0)+IF(J50<K50,1,0)) -> 0
J50: 6 | K50: 4
C52: 7.45pm | D52: MXD CB | E52: Jonathan Vella | F52: Brenda Baldacchino | G52: vs | H52: Juan Debono | I52: Jennifer Mifsud | J52: 6 | K52: 2 | L52: =(IF(J52>K52,1,0)+IF(J53>K53,1,0)) -> 2 | M52: =(IF(J52<K52,1,0)+IF(J53<K53,1,0)) -> 0
J53: 6 | K53: 0
J55: =SUM(J43:J53) -> 39 | K55: =SUM(K43:K53) -> 29 | L55: =SUM(L43:L53) -> 6 | M55: =SUM(M43:M53) -> 2
C57: 6.30 pm | D57: Men D | E57: Jake Gatt | F57: Ahmed Elnakroud | G57: vs | H57: Charles Borg Grech | I57: Matthew Napier | J57: 4 | K57: 6 | L57: =(IF(J57>K57,1,0)+IF(J58>K58,1,0)) -> 1 | M57: =(IF(J57<K57,1,0)+IF(J58<K58,1,0)) -> 1
J58: 6 | K58: 0 | N58: ret.
C60: 7.45 pm | D60: Lad B | E60: Silvana Portelli | F60: Anabel Borg | G60: vs | H60: Yasmine Hefny | I60: Carmen Difesa | J60: 2 | K60: 6 | L60: =(IF(J60>K60,1,0)+IF(J61>K61,1,0)) -> 0 | M60: =(IF(J60<K60,1,0)+IF(J61<K61,1,0)) -> 2
J61: 2 | K61: 6
C63: 9.00 pm | D63: Men C | E63: Eric Micallef | F63: Darrell Pace | G63: vs | H63: Stefan Licari | I63: Kevin Formosa | J63: 6 | K63: 7 | L63: =(IF(J63>K63,1,0)+IF(J64>K64,1,0)) -> 1 | M63: =(IF(J63<K63,1,0)+IF(J64<K64,1,0)) -> 1
...

Sheet Day 3
C1: Wilson Team Tournament 2021
C4: Day 3 - 17/11/2021 & 19/11/2021
C7: Court 1
C9: Time | D9: Rubber | E9: Team E: Diane Debono | G9: vs | H9: Team F: Christine Scerri | J9: Games | L9: Sets
C10: 6.30 pm | D10: Men A | E10: Norbert Coleiro | F10: John Azzopardi | G10: vs | H10: Nicholas Gollcher | I10: Keith Micallef | J10: 7 | K10: 5 | L10: =IF(J10>K10,1,0) + IF(J11>K11,1,0) -> 1 | M10: =IF(J10<K10,1,0) + IF(J11<K11,1,0) -> 1
J11: 1 | K11: 6
N12: 2
C13: 7.45 pm | D13: Lad A | E13: Martina Cuschieri | F13: Elaine Grech | G13: vs | H13: Christine Schembri | I13: Yanika Pace | J13: 6 | K13: 2 | L13: =IF(J13>K13,1,0) + IF(J14>K14,1,0) -> 2 | M13: 0
J14: 6 | K14: 0
C16: 9.00 pm | D16: MXD CB | E16: Frans Ellul | F16: Tiziana Borg Anastasi | G16: vs | H16: Stefan Licari | I16: Yasmine Hefny | J16: 6 | K16: 4 | L16: =(IF(J16>K16,1,0)+IF(J17>K17,1,0)) -> 2 | M16: =(IF(J16<K16,1,0)+IF(J17<K17,1,0)) -> 0
J17: 6 | K17: 1
C19: 6.30 pm | D19: Men D | E19: Aaron Micallef Piccione | F19: Franco Montesin | G19: vs | H19: Charles Borg Grech | I19: Arthur Napier | J19: 6 | K19: 4 | L19: =(IF(J19>K19,1,0)+IF(J20>K20,1,0)) -> 1 | M19: =(IF(J19<K19,1,0)+IF(J20<K20,1,0)) -> 1
J20: 6 | K20: 7
C22: Total Day 3 A | J22: =SUM(J10:J20) -> 44 | K22: =SUM(K10:K20) -> 29 | L22: =SUM(L10:L20) -> 6 | M22: =SUM(M10:M20) -> 2
C24: 6.30 pm | D24: Men C | E24: Victor Rutter | F24: Alain Frendo | G24: vs | H24: Matthew Schembri | I24: Juan Debono | J24: 2 | K24: 6 | L24: =(IF(J24>K24,1,0)+IF(J25>K25,1,0)) -> 1 | M24: =(IF(J24<K24,1,0)+IF(J25<K25,1,0)) -> 1
J25: 7 | K25: 5
C27: 7.45 pm | D27: Lad B | E27: Dominique Francica | F27: Diane Debono | G27: vs | H27: Carmen Difesa | I27: Rowena Caruana | J27: 6 | K27: 4 | L27: =(IF(J27>K27,1,0)+IF(J28>K28,1,0)) -> 2 | M27: =(IF(J27<K27,1,0)+IF(J28<K28,1,0)) -> 0
J28: 6 | K28: 3
C30: 9.00 pm | D30: Men B | E30: Melchior Farrugia | F30: Neville Sciriha | G30: vs | H30: Andrew Pule' | I30: Earvin Grech Meli | J30: 5 | K30: 7 | L30: =(IF(J30>K30,1,0)+IF(J31>K31,1,0)) -> 1 | M30: =(IF(J30<K30,1,0)+IF(J31<K31,1,0)) -> 1
J31: 6 | K31: 1
C33: 6.30pm | D33: Lad C | E33: Mary Ciantar | F33: Michelle Mahoney | G33: vs | H33: Yvette Rutter | I33: Anna Buhagiar | J33: 4 | K33: 6 | L33: =(IF(J33>K33,1,0)+IF(J34>K34,1,0)) -> 0 | M33: =(IF(J33<K33,1,0)+IF(J34<K34,1,0)) -> 2
J34: 3 | K34: 6
C36: Total Day 3 B | J36: =SUM(J24:J34) -> 39 | K36: =SUM(K24:K34) -> 38 | L36: =SUM(L24:L34) -> 4 | M36: =SUM(M24:M34) -> 4
C38: Total Day 3 | J38: =J36+J22 -> 83 | K38: =K36+K22 -> 67 | L38: =L36+L22 -> 10 | M38: =M36+M22 -> 6
C40: Court 2
C42: Time | D42: Rubber | E42: Team B: Roberto Murdocco | G42: vs | H42: Team C: Olivia Belli | J42: Games | L42: Sets
C43: 6.30 pm | D43: Men C | E43: Roberto Murdocco | F43: Gene Zammit | G43: vs | H43: Maurice Borg | I43: John Sciberras | J43: 1 | K43: 6 | L43: =(IF(J43>K43,1,0)+IF(J44>K44,1,0)) -> 1 | M43: =(IF(J43<K43,1,0)+IF(J44<K44,1,0)) -> 1
J44: 6 | K44: 1
C46: 7.45 pm | D46: Men B | E46: Roderick Spiteri | F46: Marco Borg | G46: vs | H46: Luigi Porto | I46: Richard Byrne | J46: 6 | K46: 7 | L46: =(IF(J46>K46,1,0)+IF(J47>K47,1,0)) -> 0 | M46: =(IF(J46<K46,1,0)+IF(J47<K47,1,0)) -> 2
J47: 1 | K47: 6
C49: 9.00 pm | D49: Men A | E49: Marcelo Villanueva | F49: David Schembri | G49: vs | H49: Nikolai Belli | I49: Marco Mercieca | J49: 6 | K49: 3 | L49: =(IF(J49>K49,1,0)+IF(J50>K50,1,0)) -> 1 | M49: =(IF(J49<K49,1,0)+IF(J50<K50,1,0)) -> 1
J50: 3 | K50: 6
C52: 7.45 pm | D52: Lad B | E52: Nancy Wong | F52: Andrea Mifsud | G52: vs | H52: Mariska Steenkamer | I52: Ceridwen Scerri | J52: 3 | K52: 6 | L52: =(IF(J52>K52,1,0)+IF(J53>K53,1,0)) -> 1 | M52: =(IF(J52<K52,1,0)+IF(J53<K53,1,0)) -> 1
J53: 6 | K53: 4
C55: Total Day 3 A | J55: =SUM(J43:J53) -> 32 | K55: =SUM(K43:K53) -> 39 | L55: =SUM(L43:L53) -> 3 | M55: =SUM(M43:M53) -> 5
C57: 6.30 pm | D57: Lad C | E57: Jennifer Roca | F57: Joyce Scerri | G57: vs | H57: Yvonne Borg Cardona | I57: Bernardette Fenech | J57: 1 | K57: 6 | L57: =(IF(J57>K57,1,0)+IF(J58>K58,1,0)) -> 0 | M57: =(IF(J57<K57,1,0)+IF(J58<K58,1,0)) -> 2
J58: 0 | K58: 6
C60: 7.45 pm | D60: Lad A | E60: Erika Azzopardi | F60: Doriana Portelli | G60: vs | H60: Olivia Belli | I60: Sarah vella | J60: 6 | K60: 4 | L60: =(IF(J60>K60,1,0)+IF(J61>K61,1,0)) -> 2 | M60: =(IF(J60<K60,1,0)+IF(J61<K61,1,0)) -> 0
J61: 7 | K61: 5
C63: 9.00 pm | D63: MXD CB | E63: Manuel Mifsud | F63: Annabelle Abela | G63: vs | H63: Ray Ciantar | I63: Romina Gauci | J63: 6 | K63: 4 | L63: =(IF(J63>K63,1,0)+IF(J64>K64,1,0)) -> 2 | M63: =(IF(J63<K63,1,0)+IF(J64<K64,1,0)) -> 0
...

Sheet Day 4
C1: Wilson Team Tournament 2021
C3: Day 4 - 24/11/2021 & 26/11/2021
C6: Court 1
C8: Time | D8: Rubber | E8: Team C: Olivia Belli | G8: vs | H8: Team D: Lonia Carabott | J8: Games | L8: Sets
C9: Court 1
C10: 6.30 pm | D10: Men A | E10: Jesmond Pule' | F10: Marco Mercieca | G10: vs | H10: Kurt Carabott | I10: Kurt Sapiano | J10: 7 | K10: 5 | L10: =IF(J10>K10,1,0) + IF(J11>K11,1,0) -> 2 | M10: =IF(J10<K10,1,0) + IF(J11<K11,1,0) -> 0
J11: 6 | K11: 3
C13: 7.45 pm | D13: Men B | E13: Stephen Belli | F13: Richard Byrne | G13: vs | H13: Albert Pace Asciak | I13: Willem Steenkamer | J13: 6 | K13: 3 | L13: =IF(J13>K13,1,0) + IF(J14>K14,1,0) -> 1 | M13: =IF(J13<K13,1,0) + IF(J14<K14,1,0) -> 1
J14: 4 | K14: 6
C16: 9.00 pm | D16: Men D | E16: Mario Abdilla | F16: Isaac Joseph Zammit | G16: vs | H16: Kenneth Caruana | I16: Max Anastasi Jr | J16: 6 | K16: 3 | L16: =(IF(J16>K16,1,0)+IF(J17>K17,1,0)) -> 1 | M16: =(IF(J16<K16,1,0)+IF(J17<K17,1,0)) -> 1
J17: 5 | K17: 7
C19: 6.30 pm | D19: Lad C | E19: Helga Azzopardi | F19: Bernardette Fenech | G19: vs | H19: Josette D'Alessandro | I19: Mary Borg | J19: 1 | K19: 6 | L19: =(IF(J19>K19,1,0)+IF(J20>K20,1,0)) -> 1 | M19: =(IF(J19<K19,1,0)+IF(J20<K20,1,0)) -> 1
J20: 6 | K20: 0
C22: Total Day 4 A | J22: =SUM(J10:J20) -> 41 | K22: =SUM(K10:K20) -> 33 | L22: =SUM(L10:L20) -> 5 | M22: =SUM(M10:M20) -> 3
C24: 6.30 pm | D24: Lad A | E24: Olivia Belli | F24: Kim Fava | G24: vs | H24: Alexia Spiteri Willets | I24: Rebecca Pace | J24: 6 | K24: 1 | L24: =(IF(J24>K24,1,0)+IF(J25>K25,1,0)) -> 2 | M24: =(IF(J24<K24,1,0)+IF(J25<K25,1,0)) -> 0
J25: 6 | K25: 2
C27: 7.45 pm | D27: MXD CB | E27: Maurice Borg | F27: Mariska Steenkamer | G27: vs | H27: Joe Carabott | I27: Julia Barbara | J27: 6 | K27: 4 | L27: =(IF(J27>K27,1,0)+IF(J28>K28,1,0)) -> 2 | M27: =(IF(J27<K27,1,0)+IF(J28<K28,1,0)) -> 0
J28: 6 | K28: 2
C30: 9.00 pm | D30: Lad B | E30: Alexia Gouder | F30: Ceridwen Scerri | G30: vs | H30: Monique Attard | I30: Lonia Carabott | J30: 4 | K30: 6 | L30: =(IF(J30>K30,1,0)+IF(J31>K31,1,0)) -> 1 | M30: =(IF(J30<K30,1,0)+IF(J31<K31,1,0)) -> 1
J31: 6 | K31: 4
C33: 7.45 pm | D33: Men C | E33: Ryan Mizzi | F33: Ray Ciantar | G33: vs | H33: Max Anastasi | I33: Mavric Sawyer | J33: 6 | K33: 7 | L33: =(IF(J33>K33,1,0)+IF(J34>K34,1,0)) -> 1 | M33: =(IF(J33<K33,1,0)+IF(J34<K34,1,0)) -> 1
J34: 6 | K34: 3
C36: Total Day 4 B | J36: =SUM(J24:J34) -> 46 | K36: =SUM(K24:K34) -> 29 | L36: =SUM(L24:L34) -> 6 | M36: =SUM(M24:M34) -> 2
C38: Total Day 4 | J38: =J36+J22 -> 87 | K38: =K36+K22 -> 62 | L38: =L36+L22 -> 11 | M38: =M36+M22 -> 5
C40: Court 2
C42: Time | D42: Rubber | E42: Team A: Darrell Pace | G42: vs | H42: Team E: Diane Debono | J42: Games | L42: Sets
C43: 6.30 pm | D43: Lad A | E43: Nicole Fava | F43: Alison Muscat | G43: vs | H43: Martina Cuschieri | I43: Kirsty Mercieca | J43: 1 | K43: 6 | L43: =(IF(J43>K43,1,0)+IF(J44>K44,1,0)) -> 0 | M43: =(IF(J43<K43,1,0)+IF(J44<K44,1,0)) -> 2
J44: 1 | K44: 6
C46: 7.45 pm | D46: Men A | E46: Trevor Rutter | F46: Clive Borg | G46: vs | H46: Clyde Grech | I46: Norbert Coleiro | J46: 3 | K46: 6 | L46: =(IF(J46>K46,1,0)+IF(J47>K47,1,0)) -> 0 | M46: =(IF(J46<K46,1,0)+IF(J47<K47,1,0)) -> 2
J47: 2 | K47: 6
C49: 9.00 pm | D49: Men C | E49: Jonathan Vella | F49: Darrell Pace | G49: vs | H49: Keith Tanti | I49: Alain Frendo | J49: 1 | K49: 6 | L49: =(IF(J49>K49,1,0)+IF(J50>K50,1,0)) -> 0 | M49: =(IF(J49<K49,1,0)+IF(J50<K50,1,0)) -> 2
J50: 1 | K50: 6
C52: 7.45 pm | D52: Lad B | E52: Brenda Baldacchino | F52: Anabel Borg | G52: vs | H52: Tanya Cassar | I52: Diane Debono | J52: 7 | K52: 6 | L52: =(IF(J52>K52,1,0)+IF(J53>K53,1,0)) -> 2 | M52: =(IF(J52<K52,1,0)+IF(J53<K53,1,0)) -> 0
J53: 6 | K53: 4
C55: Total Day 4 A | J55: =SUM(J43:J53) -> 22 | K55: =SUM(K43:K53) -> 46 | L55: =SUM(L43:L53) -> 2 | M55: =SUM(M43:M53) -> 6
C57: 6.30 pm | D57: MXD CB | E57: James Brincat | F57: Monica Muscat | G57: vs | H57: Frans Ellul | I57: Tiziana Borg Anastasi | J57: 7 | K57: 6 | L57: =(IF(J57>K57,1,0)+IF(J58>K58,1,0)) -> 1 | M57: =(IF(J57<K57,1,0)+IF(J58<K58,1,0)) -> 1
J58: 6 | K58: 7
C60: 7.45 pm | D60: Lad C | E60: Nicole Lia | F60: Kristina Briffa | G60: vs | H60: Michelle Mahoney | I60: Mary Ciantar | J60: 6 | K60: 4 | L60: =(IF(J60>K60,1,0)+IF(J61>K61,1,0)) -> 1 | M60: =(IF(J60<K60,1,0)+IF(J61<K61,1,0)) -> 1
J61: 0 | K61: 6
C63: 9.00 pm | D63: Men B | E63: George Grech | F63: James Farrugia | G63: vs | H63: Melchior Farrugia | I63: Ivan Cachia | J63: 5 | K63: 7 | L63: =(IF(J63>K63,1,0)+IF(J64>K64,1,0)) -> 0 | M63: =(IF(J63<K63,1,0)+IF(J64<K64,1,0)) -> 2
...

Sheet Day 5
C1: Wilson Team Tournament 2021
C3: Day 5
C6: Court 1
C8: Time | D8: Rubber | E8: Team C: Olivia Belli | G8: vs | H8: Team F: Christine Scerri | J8: Games | L8: Sets
C9: 6.30 pm | D9: Lad A | E9: Kim Fava | F9: Sarah Vella | G9: vs | H9: Christine Schembri | I9: Audrey Friggieri | J9: 6 | K9: 4 | L9: =IF(J9>K9,1,0) + IF(J10>K10,1,0) -> 2 | M9: =IF(J9<K9,1,0) + IF(J10<K10,1,0) -> 0
J10: 6 | K10: 3
C12: 7.45 pm | D12: Men D | E12: Ryan Ebejer | F12: Mario Abdilla | G12: vs | H12: Jesmond Cachia | I12: Charles Borg Grech | J12: 4 | K12: 6 | L12: =IF(J12>K12,1,0) + IF(J13>K13,1,0) -> 0 | M12: =IF(J12<K12,1,0) + IF(J13<K13,1,0) -> 2
J13: 3 | K13: 6
C15: 9.00 pm | D15: Lad B | E15: Romina Gauci | F15: Alexia Gouder | G15: vs | H15: Carmen Difesa | I15: Yasmine Hefny | J15: 6 | K15: 3 | L15: =(IF(J15>K15,1,0)+IF(J16>K16,1,0)) -> 1 | M15: =(IF(J15<K15,1,0)+IF(J16<K16,1,0)) -> 1
J16: 0 | K16: 6
C18: 6.30 pm | D18: Mxd CB | E18: John Sciberras | F18: Mariska Steenkamer | G18: vs | H18: Matthew Schembri | I18: Rowena Caruana | J18: 5 | K18: 7 | L18: =(IF(J18>K18,1,0)+IF(J19>K19,1,0)) -> 1 | M18: =(IF(J18<K18,1,0)+IF(J19<K19,1,0)) -> 1
J19: 6 | K19: 4
C21: Total Day 5 A | J21: =SUM(J9:J19) -> 36 | K21: =SUM(K9:K19) -> 39 | L21: =SUM(L9:L19) -> 4 | M21: =SUM(M9:M19) -> 4
C23: 6.30 pm | D23: Lad C | E23: Yvonne Borg Cardona | F23: Helga Azzopardi | G23: vs | H23: Christine Scerri | I23: Yvette Rutter | J23: 6 | K23: 1 | L23: =(IF(J23>K23,1,0)+IF(J24>K24,1,0)) -> 2 | M23: =(IF(J23<K23,1,0)+IF(J24<K24,1,0)) -> 0
J24: 6 | K24: 3
C26: 7.45 pm | D26: Men C | E26: Ryan Mizzi | F26: Maurice Borg | G26: vs | H26: Kevin Formosa | I26: Stefan Licari | J26: 4 | K26: 6 | L26: =(IF(J26>K26,1,0)+IF(J27>K27,1,0)) -> 0 | M26: =(IF(J26<K26,1,0)+IF(J27<K27,1,0)) -> 2
J27: 1 | K27: 6
C29: 9.00 pm | D29: Men B | E29: Stephen Belli | F29: Luigi Porto | G29: vs | H29: Andrew Pule' | I29: Earvin Grech Meli | J29: 3 | K29: 6 | L29: =(IF(J29>K29,1,0)+IF(J30>K30,1,0)) -> 1 | M29: =(IF(J29<K29,1,0)+IF(J30<K30,1,0)) -> 1
J30: 7 | K30: 6
C32: 6.30pm | D32: Men A | E32: Nikolai Belli | F32: Jesmond Pule' | G32: vs | H32: Adrian Chetcuti | I32: Keith Micallef | J32: 6 | K32: 2 | L32: =(IF(J32>K32,1,0)+IF(J33>K33,1,0)) -> 1 | M32: =(IF(J32<K32,1,0)+IF(J33<K33,1,0)) -> 1
J33: 1 | K33: 6
C35: Total Day 5B | J35: =SUM(J23:J33) -> 34 | K35: =SUM(K23:K33) -> 36 | L35: =SUM(L23:L33) -> 4 | M35: =SUM(M23:M33) -> 4
C37: Total Day 5 | J37: =J35+J21 -> 70 | K37: =K35+K21 -> 75 | L37: =L35+L21 -> 8 | M37: =M35+M21 -> 8
C39: Court 2
C41: Time | D41: Rubber | E41: Team D: Lonia Carabott | G41: vs | H41: Team E: Diane Debono | J41: Games | L41: Sets
C42: 6.30 pm | D42: Men D | E42: Kenneth Caruana | F42: Max Anastasi Jr | G42: vs | H42: Franco Montesin | I42: Shawn Roaderick Sciberras | J42: 7 | K42: 6 | L42: =(IF(J42>K42,1,0)+IF(J43>K43,1,0)) -> 1 | M42: =(IF(J42<K42,1,0)+IF(J43<K43,1,0)) -> 1
J43: 3 | K43: 6
C45: 7.45 pm | D45: Lad A | E45: Alexia Spiteri Willets | F45: Anthea Gauci | G45: vs | H45: Elaine Grech | I45: Kirsty Mercieca | J45: 6 | K45: 1 | L45: =(IF(J45>K45,1,0)+IF(J46>K46,1,0)) -> 1 | M45: =(IF(J45<K45,1,0)+IF(J46<K46,1,0)) -> 1
J46: 3 | K46: 6
C48: 9.00 pm | D48: Mxd CB | E48: Joe Carabott | F48: Monique Attard | G48: vs | H48: Victor Rutter | I48: Tanya Cassar | J48: 6 | K48: 3 | L48: =(IF(J48>K48,1,0)+IF(J49>K49,1,0)) -> 2 | M48: =(IF(J48<K48,1,0)+IF(J49<K49,1,0)) -> 0
J49: 7 | K49: 5
C51: 7.45 pm | D51: Men A | E51: Kurt Carabott | F51: Rueben Borg | G51: vs | H51: Clyde Grech | I51: John Azzopardi | J51: 6 | K51: 3 | L51: =(IF(J51>K51,1,0)+IF(J52>K52,1,0)) -> 1 | M51: =(IF(J51<K51,1,0)+IF(J52<K52,1,0)) -> 1
J52: 2 | K52: 6
C54: Total Day 5 A | J54: =SUM(J42:J52) -> 40 | K54: =SUM(K42:K52) -> 36 | L54: =SUM(L42:L52) -> 5 | M54: =SUM(M42:M52) -> 3
C56: 6.30 pm | D56: Lad C | E56: Josette D'Alessandro | F56: Claire Genovese | G56: vs | H56: Christine Seychell | I56: Mary Ciantar | J56: 2 | K56: 6 | L56: =(IF(J56>K56,1,0)+IF(J57>K57,1,0)) -> 1 | M56: =(IF(J56<K56,1,0)+IF(J57<K57,1,0)) -> 1
J57: 6 | K57: 4
C59: 7.45 pm | D59: Men B | E59: Willem Steenkamer | F59: Tobias Kristensen | G59: vs | H59: Melchior Farrugia | I59: Neville Sciriha | J59: 3 | K59: 6 | L59: =(IF(J59>K59,1,0)+IF(J60>K60,1,0)) -> 0 | M59: =(IF(J59<K59,1,0)+IF(J60<K60,1,0)) -> 2
J60: 6 | K60: 7
C62: 7.45 pm | D62: Men C | E62: Mavric Sawyer | F62: Julian Esposito | G62: vs | H62: Keith Tanti | I62: Alain Frendo | J62: 4 | K62: 6 | L62: =(IF(J62>K62,1,0)+IF(J63>K63,1,0)) -> 0 | M62: =(IF(J62<K62,1,0)+IF(J63<K63,1,0)) -> 2
J63: 6 | K63: 7
...

Sheet Semi Final
C1: Wilson Team Tournament 2021
C4: Semi Final - 21/1/22
C7: Court 1
C9: Time | D9: Rubber | E9: Team E : Diane Debono | G9: vs | H9: Team D : Lonia Carabott | J9: Games | L9: Sets
C10: 6.30 pm | D10: Men B | E10: Melchior Farrugia | F10: Ivan Cachia | G10: vs | H10: Albert Pace Axiaq | I10: Willem Steenamer | J10: 6 | K10: 4 | L10: =(IF(J10>K10,1,0)+IF(J11>K11,1,0)) -> 2 | M10: =(IF(J10<K10,1,0)+IF(J11<K11,1,0)) -> 0
J11: 7 | K11: 5
C13: 7.45 pm | D13: Men D | E13: Aaron Micallef Piccione | F13: Franco Montesin | G13: vs | H13: Kenneth Caruana | I13: Max Junior Anastasi | J13: 3 | K13: 6 | L13: =(IF(J13>K13,1,0)+IF(J14>K14,1,0)) -> 0 | M13: =(IF(J13<K13,1,0)+IF(J14<K14,1,0)) -> 2
J14: 3 | K14: 6
C16: 9.00 pm | D16: Men C | E16: Frans Ellul | F16: Keith Tanti | G16: vs | H16: Max Anastasi | I16: Joe Carabott | J16: 6 | K16: 3 | L16: =(IF(J16>K16,1,0)+IF(J17>K17,1,0)) -> 1 | M16: =(IF(J16<K16,1,0)+IF(J17<K17,1,0)) -> 1
J17: 3 | K17: 6
C19: 6.30 pm | D19: Lad B | E19: Dominique Francica | F19: Tiziana Borg Anastasi | G19: vs | H19: Julia Barbara | I19: Marcette Sciriha | J19: 3 | K19: 6 | L19: =(IF(J19>K19,1,0)+IF(J20>K20,1,0)) -> 1 | M19: =(IF(J19<K19,1,0)+IF(J20<K20,1,0)) -> 1
J20: 6 | K20: 4
C22: Total Day 2 A | J22: =SUM(J10:J20) -> 37 | K22: =SUM(K10:K20) -> 40 | L22: =SUM(L10:L20) -> 4 | M22: =SUM(M10:M20) -> 4
C24: 6.30 pm | D24: Lad C | E24: Christine Seychell | F24: Mary Ciantar | G24: vs | H24: Josette D'Alessandro | I24: Mary Borg | J24: 2 | K24: 6 | L24: =(IF(J24>K24,1,0)+IF(J25>K25,1,0)) -> 0 | M24: =(IF(J24<K24,1,0)+IF(J25<K25,1,0)) -> 2
J25: 3 | K25: 6 | N25: T/B 7-3
C27: 7.45 pm | D27: Lad A | E27: Martina Cuschieri | F27: Elaine Grech | G27: vs | H27: Alexia Spiteri Willets | I27: Rebecca Pace | J27: 7 | K27: 5 | L27: =(IF(J27>K27,1,0)+IF(J28>K28,1,0)) -> 2 | M27: =(IF(J27<K27,1,0)+IF(J28<K28,1,0)) -> 0
J28: 6 | K28: 3
C30: 9.00 pm | D30: Mxd CB | E30: Alain Frendo | F30: Tanya Cassar | G30: vs | H30: Mavric Sawyer | I30: Monique Attard | J30: 6 | K30: 7 | L30: =(IF(J30>K30,1,0)+IF(J31>K31,1,0)) -> 1 | M30: =(IF(J30<K30,1,0)+IF(J31<K31,1,0)) -> 1
J31: 6 | K31: 3
C33: 7.45 pm | D33: Men A | E33: Clyde Grech | F33: John Azzopardi | H33: Kurt Sapiano | I33: Rueben Borg | J33: 6 | K33: 4 | L33: =(IF(J33>K33,1,0)+IF(J34>K34,1,0)) -> 1 | M33: =(IF(J33<K33,1,0)+IF(J34<K34,1,0)) -> 1
J34: 4 | K34: 6
C36: Total Day 2B | J36: =SUM(J24:J34) -> 40 | K36: =SUM(K24:K34) -> 40 | L36: =SUM(L24:L34) -> 4 | M36: =SUM(M24:M34) -> 4
C38: Total Day 2 | J38: =J36+J22 -> 77 | K38: =K36+K22 -> 80 | L38: =L36+L22 -> 8 | M38: =M36+M22 -> 8
C40: Court 2
C42: Time | D42: Rubber | E42: Team B: Darrell Pace | G42: vs | H42: Team C: Olivia Belli | J42: Games | L42: Sets
C43: 6.30 pm | D43: Men A | E43: Marc Vella Bonnici | F43: Trevor Rutter | G43: vs | H43: Nikolai Belli | I43: Jesmond Pule | J43: 7 | K43: 6 | L43: =(IF(J43>K43,1,0)+IF(J44>K44,1,0)) -> 2 | M43: =(IF(J43<K43,1,0)+IF(J44<K44,1,0)) -> 0
J44: 6 | K44: 3
C46: 7.45 pm | D46: Mxd CB | E46: Jonathan Vella | F46: Brenda Baldacchino | G46: vs | H46: Maurice Borg | I46: Mariska Steenkamer | J46: 2 | K46: 6 | L46: =(IF(J46>K46,1,0)+IF(J47>K47,1,0)) -> 0 | M46: =(IF(J46<K46,1,0)+IF(J47<K47,1,0)) -> 2
J47: 4 | K47: 6
C49: 9.00 pm | D49: Lad A | E49: Nicole Fava | F49: Alison Muscat | G49: vs | H49: Kim Fava | I49: Olivia Belli | J49: 0 | K49: 6 | L49: =(IF(J49>K49,1,0)+IF(J50>K50,1,0)) -> 0 | M49: =(IF(J49<K49,1,0)+IF(J50<K50,1,0)) -> 2
J50: 0 | K50: 6
C52: 7.45 pm | D52: Men B | E52: George Grech | F52: Gabriel Pace | G52: vs | H52: Luigi Porto | I52: Richard Bryne | J52: 2 | K52: 6 | L52: =(IF(J52>K52,1,0)+IF(J53>K53,1,0)) -> 0 | M52: =(IF(J52<K52,1,0)+IF(J53<K53,1,0)) -> 2
J53: 0 | K53: 6
C55: Total Day 2 A | J55: =SUM(J43:J53) -> 21 | K55: =SUM(K43:K53) -> 45 | L55: =SUM(L43:L53) -> 2 | M55: =SUM(M43:M53) -> 6
C57: 6.30 pm | D57: Men D | E57: Jake Gatt | F57: Kristen Cachia | G57: vs | H57: Mario Abdilla | I57: Isaac Zammit | J57: 7 | K57: 6 | L57: =(IF(J57>K57,1,0)+IF(J58>K58,1,0)) -> 1 | M57: =(IF(J57<K57,1,0)+IF(J58<K58,1,0)) -> 1
J58: 3 | K58: 6
C60: 7.45 pm | D60: Lad C | E60: Ruth Micallef | F60: Kristina Briffa | G60: vs | H60: Yvonne Borg Cardona | I60: Helga Azzopardi | J60: 6 | K60: 2 | L60: =(IF(J60>K60,1,0)+IF(J61>K61,1,0)) -> 2 | M60: =(IF(J60<K60,1,0)+IF(J61<K61,1,0)) -> 0
J61: 7 | K61: 5
C63: 9.00 pm | D63: Men C | E63: Eric Micallef | F63: James Brincat | G63: vs | H63: John Sciberras | I63: Ray Ciantar | J63: 6 | K63: 4 | L63: =(IF(J63>K63,1,0)+IF(J64>K64,1,0)) -> 2 | M63: =(IF(J63<K63,1,0)+IF(J64<K64,1,0)) -> 0
J64: 6 | K64: 2
...

Sheet Final
C1: Wilson Team Tournament 2021
C4: FINAL
C8: Time | D8: Rubber | E8: Team C : Olivia Belli | G8: vs | H8: Team D : Lonia Carabott | J8: Games | L8: Sets
C9: 6.30 pm crt 2 | D9: Lad A | E9: Olivia Belli | F9: Kim Fava | G9: vs | H9: Alexia Spiteri Willets | I9: Rebecca Pace | J9: 6 | K9: 3 | L9: =(IF(J9>K9,1,0)+IF(J10>K10,1,0)) -> 2 | M9: =(IF(J9<K9,1,0)+IF(J10<K10,1,0)) -> 0
J10: 6 | K10: 1
C12: 6.30 pm crt 1 | D12: Lad C | E12: Helga Azzopardi | F12: Yvonne Borg Cardona | G12: vs | H12: Josette D'Alessandro | I12: Mary Borg | J12: 6 | K12: 4 | L12: =(IF(J12>K12,1,0)+IF(J13>K13,1,0)) -> 2 | M12: =(IF(J12<K12,1,0)+IF(J13<K13,1,0)) -> 0
J13: 6 | K13: 3 | N13: T/B 7-5
C15: 6.30 pm crt 3 | D15: MXD CB | E15: Maurice Borg | F15: Mariska Steenkamer | G15: vs | H15: Joe Carabott | I15: Monique Attard | J15: 3 | K15: 6 | L15: =(IF(J15>K15,1,0)+IF(J16>K16,1,0)) -> 0 | M15: =(IF(J15<K15,1,0)+IF(J16<K16,1,0)) -> 2
J16: 2 | K16: 6
C18: 6.30 pm crt 4 | D18: Men B | E18: Luigi Porto | F18: Richard Byrne | G18: vs | H18: Willem Steenkamer | I18: Albert Pace Asciak | J18: 6 | K18: 3 | L18: =(IF(J18>K18,1,0)+IF(J19>K19,1,0)) -> 1 | M18: =(IF(J18<K18,1,0)+IF(J19<K19,1,0)) -> 1
J19: 3 | K19: 6
C21: 8.00 pm crt 2 | D21: Lad B | E21: Alexia Gouder | F21: Romina Gauci | G21: vs | H21: Julia Barbara | I21: Marcette Sciriha | J21: 6 | K21: 3 | L21: =(IF(J21>K21,1,0)+IF(J22>K22,1,0)) -> 2 | M21: =(IF(J21<K21,1,0)+IF(J22<K22,1,0)) -> 0
J22: 6 | K22: 4
C24: 8.00 pm crt 4 | D24: Men C | E24: Ray Ciantar | F24: John Sciberras | H24: Max Anastasi | I24: Mavric Sawyer | J24: 0 | K24: 0 | L24: =(IF(J24>K24,1,0)+IF(J25>K25,1,0)) -> 0 | M24: =(IF(J24<K24,1,0)+IF(J25<K25,1,0)) -> 0
J25: 0 | K25: 0
C27: 8.00 pm crt 3 | D27: Men D | E27: Mario Abdilla | F27: Isaac Zammit | G27: vs | H27: Max Anastasi Jr | I27: Kenneth Caruana | J27: 6 | K27: 3 | L27: =(IF(J27>K27,1,0)+IF(J28>K28,1,0)) -> 1 | M27: =(IF(J27<K27,1,0)+IF(J28<K28,1,0)) -> 1
J28: 0 | K28: 6
C30: 8.00 pm crt 1 | D30: Men A | E30: Nikolai Belli | F30: Jesmond Pule' | G30: vs | H30: Kurt Sapiano | I30: Reuben Borg | J30: 6 | K30: 2 | L30: =(IF(J30>K30,1,0)+IF(J31>K31,1,0)) -> 1 | M30: =(IF(J30<K30,1,0)+IF(J31<K31,1,0)) -> 1
J31: 2 | K31: 6
C33: Total Final | J33: =SUM(J9+J10+J12+J13+J15+J16+J18+J19+J21+J22+J24+J25+J27+J28+J30+J31) -> 64 | K33: =SUM(K9+K10+K12+K13+K15+K16+K18+K19+K21+K22+K24+K25+K27+K28+K30+K31) -> 56 | L33: =SUM(L9+L10+L12+L13+L15+L16+L18+L19+L21+L22+L24+L25+L27+L28+L30+L31) -> 9 | M33: =SUM(M9+M10+M12+M13+M15+M16+M18+M19+M21+M22+M24+M25+M27+M28+M30+M31) -> 5
