Workbook

Sheet Players - Men
A1: H & S Singles Tournament 2026
B6: Men Division 1
A7: 1 | B7: Trevor Rutter
A8: 2 | B8: Jean Attard
A9: 3 | B9: Josef Cristiano
A10: 4 | B10: Sebastian Sanchez
A11: 5 | B11: Jean Carl Azzopardi
A12: 6 | B12: Karl Debattista
A13: 7 | B13: Fotios Evangelou
B15: Men Division 2 - Group A | E15: Men Division 2 - Group B
A16: 1 | B16: Kristen Cachia | D16: 1 | E16: Jonathan Martinelli
A17: 2 | B17: Emman Xuereb | D17: 2 | E17: Peter Khiev
A18: 3 | B18: Sandro Pecorella | D18: 3 | E18: John Mifsud
A19: 4 | B19: Justin Graeme Christie | D19: 4 | E19: Luke Genuis
A20: 5 | B20: Ivan Cassar | D20: 5 | E20: Tobias Kristensen
A21: 6 | B21: Jurgen Farrugia | D21: 6 | E21: Etienne Formosa Carabez
A22: 7 | B22: Jean Paul Vella | D22: 7 | E22: Steve Gambin
B24: Men Division 3 - Group A | E24: Men Division 3 Group B
A25: 1 | B25: Manuel Mifsud | D25: 1 | E25: Matthias Sciriha
A26: 2 | B26: Matthew Caruana | D26: 2 | E26: Kenneth Farrugia
A27: 3 | B27: Juan Sammut | D27: 3 | E27: Simone Re
A28: 4 | B28: Artiom Kricenko | D28: 4 | E28: Matthew Micallef
A29: 5 | B29: Jason Lee Evans | D29: 5 | E29: Jurgen Cachia
A30: 6 | B30: Chris Vella | D30: 6 | E30: Redent Scicluna
B32: Men Division 4 - Group A | E32: Men Division 4 Group B
A33: 1 | B33: Clive Silvio Borg | D33: 1 | E33: David Camilleri
A34: 2 | B34: Julian Galea Naudi | D34: 2 | E34: Braydon Galea
A35: 3 | B35: JP Sciberras | D35: 3 | E35: Isaac Joseph Zammit
A36: 4 | B36: Matthias Cremona | D36: 4 | E36: Daniele Privitera
A37: 5 | B37: Mickey Mitic | D37: 5 | E37: Kevin Sciberras
A38: 6 | B38: Sean Cachia | D38: 6 | E38: Glenn Micallef
B41: Men Division 5
A42: 1 | B42: Twesigye Twekye
A43: 2 | B43: Justin Scicluna
A44: 3 | B44: Frank Agius
A45: 4 | B45: Chris Boot
A46: 5 | B46: Oliver Brincat
A47: 6 | B47: Mark Napier
A48: 7 | B48: Antoine Bugeja

Sheet Men Div 1
A1: H & S Singles Tournament 2026
A5: Division 1
A7: Players | B7: Set Scores | H7: Tie | P7: Players | Q7: Set Scores | W7: Tie | AE7: Player | AF7: Matches Played | AG7: Points Overall | AH7: Games Won | AI7: Sets Won
B8: Score | C8: Set 1 Work | E8: Score | F8: Set 2 Work | H8: Score | I8: Tie Work | J8: Game Played | K8: Sets Points Work | L8: Sets & Tie Points Work | M8: Games Wins Work | N8: Sets Wins Work | Q8: Score | R8: Set 1 Work | T8: Score | U8: Set 2 Work | W8: Score | X8: Tie Work | Y8: Game Played | Z8: Sets Points Work | AA8: Sets & Tie Points Work | AB8: Games Wins Work | AC8: Sets Wins Work | AJ8: Winner Working | AK8: Total Games Work | AL8: Winner
A9: =AE9 -> Trevor Rutter | B9: 3 | C9: =IF(B9>B11,1,0) -> 0 | E9: 4 | F9: =IF(E9>E11,1,0) -> 0 | I9: =IF(H9>H11,1,0) -> 0 | J9: =IF(B9="",0,1) -> 1 | K9: =IF(C9+F9=2,3,IF(C9+F9=1,1,0)) -> 0 | L9: =IF(K9=3,3,IF(I9+K9=2,2,IF(K9=1,1,0))) -> 0 | M9: =B9+E9 -> 7 | N9: =C9+F9+I9 -> 0 | P9: =AE9 -> Trevor Rutter | Q9: 6 | R9: =IF(Q9>Q11,1,0) -> 1 | T9: 6 | U9: =IF(T9>T11,1,0) -> 1 | X9: =IF(W9>W11,1,0) -> 0 | Y9: =IF(Q9="",0,1) -> 1 | Z9: =IF(R9+U9=2,3,IF(R9+U9=1,1,0)) -> 3 | AA9: =IF(Z9=3,3,IF(X9+Z9=2,2,IF(Z9=1,1,0))) -> 3 | AB9: =Q9+T9 -> 12 | AC9: =R9+U9+X9 -> 2 | AE9: ='Players - Men'!B7 -> Trevor Rutter | AF9: =J9+Y9+J13+Y13+J17+J49 -> 5 | AG9: =L9+AA9+L13+AA13+L17+L49 -> 11 | AH9: =M9+AB9+M13+AB13+M17+M49 -> 56 | AI9: =N9+AC9+N13+AC13+N17+N49 -> 8 | AJ9: =MAX(AG9:AG19) -> 11 | AK9: =SUM(AF9:AF19) -> 26 | AL9: =IF(AG9=$AJ$9,AE9,IF(AG11=$AJ$9,AE11,IF(AG13=$AJ$9,AE13,IF(AG15=$AJ$9,AE15,IF(AG17=$AJ$9,AE17,IF(AG19=$AJ$9,AE19,"")))))) -> Trevor Rutter
A10: vs. | P10: vs.
A11: =AE11 -> Jean Attard | B11: 6 | C11: =IF(B11>B9,1,0) -> 1 | E11: 6 | F11: =IF(E11>E9,1,0) -> 1 | I11: =IF(H11>H9,1,0) -> 0 | J11: =IF(B11="",0,1) -> 1 | K11: =IF(C11+F11=2,3,IF(C11+F11=1,1,0)) -> 3 | L11: =IF(K11=3,3,IF(I11+K11=2,2,IF(K11=1,1,0))) -> 3 | M11: =B11+E11 -> 12 | N11: =C11+F11+I11 -> 2 | P11: =AE13 -> Josef Cristiano | Q11: 1 | R11: =IF(Q11>Q9,1,0) -> 0 | T11: 1 | U11: =IF(T11>T9,1,0) -> 0 | X11: =IF(W11>W9,1,0) -> 0 | Y11: =IF(Q11="",0,1) -> 1 | Z11: =IF(R11+U11=2,3,IF(R11+U11=1,1,0)) -> 0 | AA11: =IF(Z11=3,3,IF(X11+Z11=2,2,IF(Z11=1,1,0))) -> 0 | AB11: =Q11+T11 -> 2 | AC11: =R11+U11+X11 -> 0 | AE11: ='Players - Men'!B8 -> Jean Attard | AF11: =J11+Y25+J25+Y21+J21+Y45 -> 4 | AG11: =L11+AA25+L25+AA21+L21+AA45 -> 6 | AH11: =M11+AB25+M25+AB21+M21+AB45 -> 35 | AI11: =N11+AC25+N25+AC21+N21+AC45 -> 4
A13: =AE9 -> Trevor Rutter | B13: 7 | C13: =IF(B13>B15,1,0) -> 1 | E13: 6 | F13: =IF(E13>E15,1,0) -> 0 | H13: 10 | I13: =IF(H13>H15,1,0) -> 1 | J13: =IF(B13="",0,1) -> 1 | K13: =IF(C13+F13=2,3,IF(C13+F13=1,1,0)) -> 1 | L13: =IF(K13=3,3,IF(I13+K13=2,2,IF(K13=1,1,0))) -> 2 | M13: =B13+E13 -> 13 | N13: =C13+F13+I13 -> 2 | P13: =AE9 -> Trevor Rutter | R13: =IF(Q13>Q15,1,0) -> 0 | U13: =IF(T13>T15,1,0) -> 0 | X13: =IF(W13>W15,1,0) -> 0 | Y13: =IF(Q13="",0,1) -> 0 | Z13: =IF(R13+U13=2,3,IF(R13+U13=1,1,0)) -> 0 | AA13: =IF(Z13=3,3,IF(X13+Z13=2,2,IF(Z13=1,1,0))) -> 0 | AB13: =Q13+T13 -> 0 | AC13: =R13+U13+X13 -> 0 | AE13: ='Players - Men'!B9 -> Josef Cristiano | AF13: =Y29+Y11+Y33+J33+J23+J45 -> 5 | AG13: =AA29+AA11+AA33+L33+L23+L45 -> 6 | AH13: =AB29+AB11+AB33+M33+M23+M45 -> 40 | AI13: =AC29+AC11+AC33+N33+N23+N45 -> 5
A14: vs. | P14: vs.
A15: =AE15 -> Sebastian Sanchez | B15: 6 | C15: =IF(B15>B13,1,0) -> 0 | E15: 7 | F15: =IF(E15>E13,1,0) -> 1 | H15: 8 | I15: =IF(H15>H13,1,0) -> 0 | J15: =IF(B15="",0,1) -> 1 | K15: =IF(C15+F15=2,3,IF(C15+F15=1,1,0)) -> 1 | L15: =IF(K15=3,3,IF(I15+K15=2,2,IF(K15=1,1,0))) -> 1 | M15: =B15+E15 -> 13 | N15: =C15+F15+I15 -> 1 | P15: =AE17 -> Jean Carl Azzopardi | R15: =IF(Q15>Q13,1,0) -> 0 | U15: =IF(T15>T13,1,0) -> 0 | X15: =IF(W15>W13,1,0) -> 0 | Y15: =IF(Q15="",0,1) -> 0 | Z15: =IF(R15+U15=2,3,IF(R15+U15=1,1,0)) -> 0 | AA15: =IF(Z15=3,3,IF(X15+Z15=2,2,IF(Z15=1,1,0))) -> 0 | AB15: =Q15+T15 -> 0 | AC15: =R15+U15+X15 -> 0 | AE15: ='Players - Men'!B10 -> Sebastian Sanchez | AF15: =Y31+J37+J15+Y23+J29+J43 -> 4 | AG15: =AA31+L37+L15+AA23+L29+L43 -> 8 | AH15: =AB31+M37+M15+AB23+M29+M43 -> 45 | AI15: =AC31+N37+N15+AC23+N29+N43 -> 6
A17: =AE9 -> Trevor Rutter | B17: 6 | C17: =IF(B17>B19,1,0) -> 1 | E17: 6 | F17: =IF(E17>E19,1,0) -> 1 | I17: =IF(H17>H19,1,0) -> 0 | J17: =IF(B17="",0,1) -> 1 | K17: =IF(C17+F17=2,3,IF(C17+F17=1,1,0)) -> 3 | L17: =IF(K17=3,3,IF(I17+K17=2,2,IF(K17=1,1,0))) -> 3 | M17: =B17+E17 -> 12 | N17: =C17+F17+I17 -> 2 | P17: =AE17 -> Jean Carl Azzopardi | R17: =IF(Q17>Q19,1,0) -> 0 | U17: =IF(T17>T19,1,0) -> 0 | X17: =IF(W17>W19,1,0) -> 0 | Y17: =IF(Q17="",0,1) -> 0 | Z17: =IF(R17+U17=2,3,IF(R17+U17=1,1,0)) -> 0 | AA17: =IF(Z17=3,3,IF(X17+Z17=2,2,IF(Z17=1,1,0))) -> 0 | AB17: =Q17+T17 -> 0 | AC17: =R17+U17+X17 -> 0 | AE17: ='Players - Men'!B11 -> Jean Carl Azzopardi | AF17: =Y17+J39+J27+Y15+J35+Y41 -> 4 | AG17: =AA17+L39+L27+AA15+L35+AA41 -> 11 | AH17: =AB17+M39+M27+AB15+M35+AB41 -> 47 | AI17: =AC17+N39+N27+AC15+N35+AC41 -> 8
A18: vs. | P18: vs.
A19: =AE19 -> Karl Debattista | B19: 3 | C19: =IF(B19>B17,1,0) -> 0 | E19: 2 | F19: =IF(E19>E17,1,0) -> 0 | I19: =IF(H19>H17,1,0) -> 0 | J19: =IF(B19="",0,1) -> 1 | K19: =IF(C19+F19=2,3,IF(C19+F19=1,1,0)) -> 0 | L19: =IF(K19=3,3,IF(I19+K19=2,2,IF(K19=1,1,0))) -> 0 | M19: =B19+E19 -> 5 | N19: =C19+F19+I19 -> 0 | P19: =AE19 -> Karl Debattista | R19: =IF(Q19>Q17,1,0) -> 0 | U19: =IF(T19>T17,1,0) -> 0 | X19: =IF(W19>W17,1,0) -> 0 | Y19: =IF(Q19="",0,1) -> 0 | Z19: =IF(R19+U19=2,3,IF(R19+U19=1,1,0)) -> 0 | AA19: =IF(Z19=3,3,IF(X19+Z19=2,2,IF(Z19=1,1,0))) -> 0 | AB19: =Q19+T19 -> 0 | AC19: =R19+U19+X19 -> 0 | AE19: ='Players - Men'!B12 -> Karl Debattista | AF19: =Y19+Y27+Y35+J19+J31+Y39 -> 4 | AG19: =AA19+AA35+L31+AA27+L19+AA39 -> 5 | AH19: =AB19+AB27+AB35+M19+M31+AB39 -> 38 | AI19: =AC19+AC27+AC35+N19+N31+AC39 -> 4
A21: =AE11 -> Jean Attard | B21: 4 | C21: =IF(B21>B23,1,0) -> 0 | E21: 1 | F21: =IF(E21>E23,1,0) -> 0 | I21: =IF(H21>H23,1,0) -> 0 | J21: =IF(B21="",0,1) -> 1 | K21: =IF(C21+F21=2,3,IF(C21+F21=1,1,0)) -> 0 | L21: =IF(K21=3,3,IF(I21+K21=2,2,IF(K21=1,1,0))) -> 0 | M21: =B21+E21 -> 5 | N21: =C21+F21+I21 -> 0 | P21: =AE11 -> Jean Attard | R21: =IF(Q21>Q23,1,0) -> 0 | U21: =IF(T21>T23,1,0) -> 0 | X21: =IF(W21>W23,1,0) -> 0 | Y21: =IF(Q21="",0,1) -> 0 | Z21: =IF(R21+U21=2,3,IF(R21+U21=1,1,0)) -> 0 | AA21: =IF(Z21=3,3,IF(X21+Z21=2,2,IF(Z21=1,1,0))) -> 0 | AB21: =Q21+T21 -> 0 | AC21: =R21+U21+X21 -> 0 | AE21: ='Players - Men'!B13 -> Fotios Evangelou | AF21: =J41+J47+J51+Y37+Y43+Y47 -> 6 | AG21: =L41+L47+L51+AA37+AA43+AA47 -> 1 | AH21: =M41+M47+M51+AB37+AB43+AB47 -> 27 | AI21: =N41+N47+N51+AC37+AC43+AC47 -> 1
A22: vs. | P22: vs.
A23: =AE13 -> Josef Cristiano | B23: 6 | C23: =IF(B23>B21,1,0) -> 1 | E23: 6 | F23: =IF(E23>E21,1,0) -> 1 | I23: =IF(H23>H21,1,0) -> 0 | J23: =IF(B23="",0,1) -> 1 | K23: =IF(C23+F23=2,3,IF(C23+F23=1,1,0)) -> 3 | L23: =IF(K23=3,3,IF(I23+K23=2,2,IF(K23=1,1,0))) -> 3 | M23: =B23+E23 -> 12 | N23: =C23+F23+I23 -> 2 | P23: =AE15 -> Sebastian Sanchez | R23: =IF(Q23>Q21,1,0) -> 0 | U23: =IF(T23>T21,1,0) -> 0 | X23: =IF(W23>W21,1,0) -> 0 | Y23: =IF(Q23="",0,1) -> 0 | Z23: =IF(R23+U23=2,3,IF(R23+U23=1,1,0)) -> 0 | AA23: =IF(Z23=3,3,IF(X23+Z23=2,2,IF(Z23=1,1,0))) -> 0 | AB23: =Q23+T23 -> 0 | AC23: =R23+U23+X23 -> 0 | AE23: Division Winner
A25: =AE11 -> Jean Attard | B25: 5 | C25: =IF(B25>B27,1,0) -> 0 | E25: 1 | F25: =IF(E25>E27,1,0) -> 0 | I25: =IF(H25>H27,1,0) -> 0 | J25: =IF(B25="",0,1) -> 1 | K25: =IF(C25+F25=2,3,IF(C25+F25=1,1,0)) -> 0 | L25: =IF(K25=3,3,IF(I25+K25=2,2,IF(K25=1,1,0))) -> 0 | M25: =B25+E25 -> 6 | N25: =C25+F25+I25 -> 0 | P25: =AE11 -> Jean Attard | U25: =IF(T25>T27,1,0) -> 0 | X25: =IF(W25>W27,1,0) -> 0 | Y25: =IF(Q25="",0,1) -> 0 | Z25: =IF(R25+U25=2,3,IF(R25+U25=1,1,0)) -> 0 | AA25: =IF(Z25=3,3,IF(X25+Z25=2,2,IF(Z25=1,1,0))) -> 0 | AB25: =Q25+T25 -> 0 | AC25: =R25+U25+X25 -> 0
A26: vs. | P26: vs. | AE26: Division Runner UP
A27: =AE17 -> Jean Carl Azzopardi | B27: 7 | C27: =IF(B27>B25,1,0) -> 1 | E27: 6 | F27: =IF(E27>E25,1,0) -> 1 | I27: =IF(H27>H25,1,0) -> 0 | J27: =IF(B27="",0,1) -> 1 | K27: =IF(C27+F27=2,3,IF(C27+F27=1,1,0)) -> 3 | L27: =IF(K27=3,3,IF(I27+K27=2,2,IF(K27=1,1,0))) -> 3 | M27: =B27+E27 -> 13 | N27: =C27+F27+I27 -> 2 | P27: =AE19 -> Karl Debattista | U27: =IF(T27>T25,1,0) -> 0 | X27: =IF(W27>W25,1,0) -> 0 | Y27: =IF(Q27="",0,1) -> 0 | Z27: =IF(R27+U27=2,3,IF(R27+U27=1,1,0)) -> 0 | AA27: =IF(Z27=3,3,IF(X27+Z27=2,2,IF(Z27=1,1,0))) -> 0 | AB27: =Q27+T27 -> 0 | AC27: =R27+U27+X27 -> 0
A29: =AE15 -> Sebastian Sanchez | B29: 6 | C29: =IF(B29>B31,1,0) -> 1 | E29: 7 | F29: =IF(E29>E31,1,0) -> 1 | I29: =IF(H29>H31,1,0) -> 0 | J29: =IF(B29="",0,1) -> 1 | K29: =IF(C29+F29=2,3,IF(C29+F29=1,1,0)) -> 3 | L29: =IF(K29=3,3,IF(I29+K29=2,2,IF(K29=1,1,0))) -> 3 | M29: =B29+E29 -> 13 | N29: =C29+F29+I29 -> 2 | P29: =AE13 -> Josef Cristiano | R29: =IF(Q29>Q31,1,0) -> 0 | U29: =IF(T29>T31,1,0) -> 0 | X29: =IF(W29>W31,1,0) -> 0 | Y29: =IF(Q29="",0,1) -> 0 | Z29: =IF(R29+U29=2,3,IF(R29+U29=1,1,0)) -> 0 | AA29: =IF(Z29=3,3,IF(X29+Z29=2,2,IF(Z29=1,1,0))) -> 0 | AB29: =Q29+T29 -> 0 | AC29: =R29+U29+X29 -> 0
A30: vs. | P30: vs.
A31: =AE19 -> Karl Debattista | B31: 4 | C31: =IF(B31>B29,1,0) -> 0 | E31: 5 | F31: =IF(E31>E29,1,0) -> 0 | I31: =IF(H31>H29,1,0) -> 0 | J31: =IF(B31="",0,1) -> 1 | K31: =IF(C31+F31=2,3,IF(C31+F31=1,1,0)) -> 0 | L31: =IF(K31=3,3,IF(I31+K31=2,2,IF(K31=1,1,0))) -> 0 | M31: =B31+E31 -> 9 | N31: =C31+F31+I31 -> 0 | P31: =AE15 -> Sebastian Sanchez | R31: =IF(Q31>Q29,1,0) -> 0 | U31: =IF(T31>T29,1,0) -> 0 | X31: =IF(W31>W29,1,0) -> 0 | Y31: =IF(Q31="",0,1) -> 0 | Z31: =IF(R31+U31=2,3,IF(R31+U31=1,1,0)) -> 0 | AA31: =IF(Z31=3,3,IF(X31+Z31=2,2,IF(Z31=1,1,0))) -> 0 | AB31: =Q31+T31 -> 0 | AC31: =R31+U31+X31 -> 0
A33: =AE13 -> Josef Cristiano | B33: 3 | C33: =IF(B33>B35,1,0) -> 0 | E33: 2 | F33: =IF(E33>E35,1,0) -> 0 | I33: =IF(H33>H35,1,0) -> 0 | J33: =IF(B33="",0,1) -> 1 | K33: =IF(C33+F33=2,3,IF(C33+F33=1,1,0)) -> 0 | L33: =IF(K33=3,3,IF(I33+K33=2,2,IF(K33=1,1,0))) -> 0 | M33: =B33+E33 -> 5 | N33: =C33+F33+I33 -> 0 | P33: =AE13 -> Josef Cristiano | Q33: 7 | R33: =IF(Q33>Q35,1,0) -> 1 | T33: 5 | U33: =IF(T33>T35,1,0) -> 0 | W33: 4 | X33: =IF(W33>W35,1,0) -> 0 | Y33: =IF(Q33="",0,1) -> 1 | Z33: =IF(R33+U33=2,3,IF(R33+U33=1,1,0)) -> 1 | AA33: =IF(Z33=3,3,IF(X33+Z33=2,2,IF(Z33=1,1,0))) -> 1 | AB33: =Q33+T33 -> 12 | AC33: =R33+U33+X33 -> 1
A34: vs. | P34: vs.
A35: =AE17 -> Jean Carl Azzopardi | B35: 6 | C35: =IF(B35>B33,1,0) -> 1 | E35: 6 | F35: =IF(E35>E33,1,0) -> 1 | I35: =IF(H35>H33,1,0) -> 0 | J35: =IF(B35="",0,1) -> 1 | K35: =IF(C35+F35=2,3,IF(C35+F35=1,1,0)) -> 3 | L35: =IF(K35=3,3,IF(I35+K35=2,2,IF(K35=1,1,0))) -> 3 | M35: =B35+E35 -> 12 | N35: =C35+F35+I35 -> 2 | P35: =AE19 -> Karl Debattista | Q35: 5 | R35: =IF(Q35>Q33,1,0) -> 0 | T35: 7 | U35: =IF(T35>T33,1,0) -> 1 | W35: 10 | X35: =IF(W35>W33,1,0) -> 1 | Y35: =IF(Q35="",0,1) -> 1 | Z35: =IF(R35+U35=2,3,IF(R35+U35=1,1,0)) -> 1 | AA35: =IF(Z35=3,3,IF(X35+Z35=2,2,IF(Z35=1,1,0))) -> 2 | AB35: =Q35+T35 -> 12 | AC35: =R35+U35+X35 -> 2
A37: =AE15 -> Sebastian Sanchez | B37: 6 | C37: =IF(B37>B39,1,0) -> 1 | E37: 1 | F37: =IF(E37>E39,1,0) -> 0 | H37: 0 | I37: =IF(H37>H39,1,0) -> 0 | J37: =IF(B37="",0,1) -> 1 | K37: =IF(C37+F37=2,3,IF(C37+F37=1,1,0)) -> 1 | L37: =IF(K37=3,3,IF(I37+K37=2,2,IF(K37=1,1,0))) -> 1 | M37: =B37+E37 -> 7 | N37: =C37+F37+I37 -> 1 | P37: =AE21 -> Fotios Evangelou | Q37: 1 | R37: =IF(Q37>Q39,1,0) -> 0 | T37: 1 | U37: =IF(T37>T39,1,0) -> 0 | X37: =IF(W37>W35,1,0) -> 0 | Y37: =IF(Q37="",0,1) -> 1 | Z37: =IF(R37+U37=2,3,IF(R37+U37=1,1,0)) -> 0 | AA37: =IF(Z37=3,3,IF(X37+Z37=2,2,IF(Z37=1,1,0))) -> 0 | AB37: =Q37+T37 -> 2 | AC37: =R37+U37+X37 -> 0
A38: vs. | P38: vs.
A39: =AE17 -> Jean Carl Azzopardi | B39: 4 | C39: =IF(B39>B37,1,0) -> 0 | E39: 6 | F39: =IF(E39>E37,1,0) -> 1 | H39: 10 | I39: =IF(H39>H37,1,0) -> 1 | J39: =IF(B39="",0,1) -> 1 | K39: =IF(C39+F39=2,3,IF(C39+F39=1,1,0)) -> 1 | L39: =IF(K39=3,3,IF(I39+K39=2,2,IF(K39=1,1,0))) -> 2 | M39: =B39+E39 -> 10 | N39: =C39+F39+I39 -> 2 | P39: =AE19 -> Karl Debattista | Q39: 6 | R39: =IF(Q39>Q37,1,0) -> 1 | T39: 6 | U39: =IF(T39>T37,1,0) -> 1 | X39: =IF(W39>W37,1,0) -> 0 | Y39: =IF(Q39="",0,1) -> 1 | Z39: =IF(R39+U39=2,3,IF(R39+U39=1,1,0)) -> 3 | AA39: =IF(Z39=3,3,IF(X39+Z39=2,2,IF(Z39=1,1,0))) -> 3 | AB39: =Q39+T39 -> 12 | AC39: =R39+U39+X39 -> 2
A41: =AE21 -> Fotios Evangelou | B41: 3 | C41: =IF(B41>B43,1,0) -> 0 | E41: 2 | F41: =IF(E41>E43,1,0) -> 0 | I41: =IF(H41>H39,1,0) -> 0 | J41: =IF(B41="",0,1) -> 1 | K41: =IF(C41+F41=2,3,IF(C41+F41=1,1,0)) -> 0 | L41: =IF(K41=3,3,IF(I41+K41=2,2,IF(K41=1,1,0))) -> 0 | M41: =B41+E41 -> 5 | N41: =C41+F41+I41 -> 0 | P41: =AE17 -> Jean Carl Azzopardi | Q41: 6 | R41: =IF(Q41>Q43,1,0) -> 1 | T41: 6 | U41: =IF(T41>T43,1,0) -> 1 | X41: =IF(W41>W39,1,0) -> 0 | Y41: =IF(Q41="",0,1) -> 1 | Z41: =IF(R41+U41=2,3,IF(R41+U41=1,1,0)) -> 3 | AA41: =IF(Z41=3,3,IF(X41+Z41=2,2,IF(Z41=1,1,0))) -> 3 | AB41: =Q41+T41 -> 12 | AC41: =R41+U41+X41 -> 2
A42: vs. | P42: vs.
A43: =AE15 -> Sebastian Sanchez | B43: 6 | C43: =IF(B43>B41,1,0) -> 1 | E43: 6 | F43: =IF(E43>E41,1,0) -> 1 | I43: =IF(H43>H41,1,0) -> 0 | J43: =IF(B43="",0,1) -> 1 | K43: =IF(C43+F43=2,3,IF(C43+F43=1,1,0)) -> 3 | L43: =IF(K43=3,3,IF(I43+K43=2,2,IF(K43=1,1,0))) -> 3 | M43: =B43+E43 -> 12 | N43: =C43+F43+I43 -> 2 | P43: =AE21 -> Fotios Evangelou | Q43: 2 | R43: =IF(Q43>Q41,1,0) -> 0 | T43: 1 | U43: =IF(T43>T41,1,0) -> 0 | X43: =IF(W43>W41,1,0) -> 0 | Y43: =IF(Q43="",0,1) -> 1 | Z43: =IF(R43+U43=2,3,IF(R43+U43=1,1,0)) -> 0 | AA43: =IF(Z43=3,3,IF(X43+Z43=2,2,IF(Z43=1,1,0))) -> 0 | AB43: =Q43+T43 -> 3 | AC43: =R43+U43+X43 -> 0
A45: =AE13 -> Josef Cristiano | B45: 3 | C45: =IF(B45>B47,1,0) -> 0 | E45: 6 | F45: =IF(E45>E47,1,0) -> 1 | H45: 10 | I45: =IF(H45>H43,1,0) -> 1 | J45: =IF(B45="",0,1) -> 1 | K45: =IF(C45+F45=2,3,IF(C45+F45=1,1,0)) -> 1 | L45: =IF(K45=3,3,IF(I45+K45=2,2,IF(K45=1,1,0))) -> 2 | M45: =B45+E45 -> 9 | N45: =C45+F45+I45 -> 2 | P45: =AE11 -> Jean Attard | Q45: 6 | R45: =IF(Q45>Q47,1,0) -> 1 | T45: 6 | U45: =IF(T45>T47,1,0) -> 1 | X45: =IF(W45>W43,1,0) -> 0 | Y45: =IF(Q45="",0,1) -> 1 | Z45: =IF(R45+U45=2,3,IF(R45+U45=1,1,0)) -> 3 | AA45: =IF(Z45=3,3,IF(X45+Z45=2,2,IF(Z45=1,1,0))) -> 3 | AB45: =Q45+T45 -> 12 | AC45: =R45+U45+X45 -> 2
A46: vs. | P46: vs.
A47: =AE21 -> Fotios Evangelou | B47: 6 | C47: =IF(B47>B45,1,0) -> 1 | E47: 2 | F47: =IF(E47>E45,1,0) -> 0 | H47: 7 | I47: =IF(H47>H45,1,0) -> 0 | J47: =IF(B47="",0,1) -> 1 | K47: =IF(C47+F47=2,3,IF(C47+F47=1,1,0)) -> 1 | L47: =IF(K47=3,3,IF(I47+K47=2,2,IF(K47=1,1,0))) -> 1 | M47: =B47+E47 -> 8 | N47: =C47+F47+I47 -> 1 | P47: =AE21 -> Fotios Evangelou | Q47: 1 | R47: =IF(Q47>Q45,1,0) -> 0 | T47: 3 | U47: =IF(T47>T45,1,0) -> 0 | X47: =IF(W47>W45,1,0) -> 0 | Y47: =IF(Q47="",0,1) -> 1 | Z47: =IF(R47+U47=2,3,IF(R47+U47=1,1,0)) -> 0 | AA47: =IF(Z47=3,3,IF(X47+Z47=2,2,IF(Z47=1,1,0))) -> 0 | AB47: =Q47+T47 -> 4 | AC47: =R47+U47+X47 -> 0
A49: =AE9 -> Trevor Rutter | B49: 6 | C49: =IF(B49>B51,1,0) -> 1 | E49: 6 | F49: =IF(E49>E51,1,0) -> 1 | I49: =IF(H49>H47,1,0) -> 0 | J49: =IF(B49="",0,1) -> 1 | K49: =IF(C49+F49=2,3,IF(C49+F49=1,1,0)) -> 3 | L49: =IF(K49=3,3,IF(I49+K49=2,2,IF(K49=1,1,0))) -> 3 | M49: =B49+E49 -> 12 | N49: =C49+F49+I49 -> 2
A50: vs.
A51: =AE21 -> Fotios Evangelou | B51: 3 | C51: =IF(B51>B49,1,0) -> 0 | E51: 2 | F51: =IF(E51>E49,1,0) -> 0 | I51: =IF(H51>H49,1,0) -> 0 | J51: =IF(B51="",0,1) -> 1 | K51: =IF(C51+F51=2,3,IF(C51+F51=1,1,0)) -> 0 | L51: =IF(K51=3,3,IF(I51+K51=2,2,IF(K51=1,1,0))) -> 0 | M51: =B51+E51 -> 5 | N51: =C51+F51+I51 -> 0

Sheet Men Div 2
A1: H & S Singles Tournament 2026
A5: Division 2 - Group A
A7: Players | B7: Set Scores | H7: Tie | P7: Players | Q7: Set Scores | W7: Tie | AE7: Player | AF7: Matches Played | AG7: Points Overall | AH7: Games Won | AI7: Sets Won
B8: Score | C8: Set 1 Work | E8: Score | F8: Set 2 Work | H8: Score | I8: Tie Work | J8: Game Played | K8: Sets Points Work | L8: Sets & Tie Points Work | M8: Games Wins Work | N8: Sets Wins Work | Q8: Score | R8: Set 1 Work | T8: Score | U8: Set 2 Work | W8: Score | X8: Tie Work | Y8: Game Played | Z8: Sets Points Work | AA8: Sets & Tie Points Work | AB8: Games Wins Work | AC8: Sets Wins Work | AJ8: Winner Working | AK8: Total Games Work | AL8: Winner
A9: =AE9 -> Kristen Cachia | B9: 0 | C9: =IF(B9>B11,1,0) -> 0 | E9: 0 | F9: =IF(E9>E11,1,0) -> 0 | I9: =IF(H9>H11,1,0) -> 0 | J9: =IF(B9="",0,1) -> 1 | K9: =IF(C9+F9=2,3,IF(C9+F9=1,1,0)) -> 0 | L9: =IF(K9=3,3,IF(I9+K9=2,2,IF(K9=1,1,0))) -> 0 | M9: =B9+E9 -> 0 | N9: =C9+F9+I9 -> 0 | P9: =AE9 -> Kristen Cachia | Q9: 6 | R9: =IF(Q9>Q11,1,0) -> 1 | T9: 6 | U9: =IF(T9>T11,1,0) -> 1 | X9: =IF(W9>W11,1,0) -> 0 | Y9: =IF(Q9="",0,1) -> 1 | Z9: =IF(R9+U9=2,3,IF(R9+U9=1,1,0)) -> 3 | AA9: =IF(Z9=3,3,IF(X9+Z9=2,2,IF(Z9=1,1,0))) -> 3 | AB9: =Q9+T9 -> 12 | AC9: =R9+U9+X9 -> 2 | AE9: ='Players - Men'!B16 -> Kristen Cachia | AF9: =J9+Y9+J13+Y13+J17+J49 -> 5 | AG9: =L9+AA9+L13+AA13+L17+L49 -> 9 | AH9: =M9+AB9+M13+AB13+M17+M49 -> 41 | AI9: =N9+AC9+N13+AC13+N17+N49 -> 6 | AJ9: =MAX(AG9:AG19) -> 11 | AK9: =SUM(AF9:AF19) -> 32 | AL9: =IF(AG9=$AJ$9,AE9,IF(AG11=$AJ$9,AE11,IF(AG13=$AJ$9,AE13,IF(AG15=$AJ$9,AE15,IF(AG17=$AJ$9,AE17,IF(AG19=$AJ$9,AE19,"")))))) -> Justin Graeme Christie
A10: vs. | P10: vs.
A11: =AE11 -> Emman Xuereb | B11: 0 | C11: =IF(B11>B9,1,0) -> 0 | E11: 0 | F11: =IF(E11>E9,1,0) -> 0 | I11: =IF(H11>H9,1,0) -> 0 | J11: =IF(B11="",0,1) -> 1 | K11: =IF(C11+F11=2,3,IF(C11+F11=1,1,0)) -> 0 | L11: =IF(K11=3,3,IF(I11+K11=2,2,IF(K11=1,1,0))) -> 0 | M11: =B11+E11 -> 0 | N11: =C11+F11+I11 -> 0 | P11: =AE13 -> Sandro Pecorella | Q11: 1 | R11: =IF(Q11>Q9,1,0) -> 0 | T11: 3 | U11: =IF(T11>T9,1,0) -> 0 | X11: =IF(W11>W9,1,0) -> 0 | Y11: =IF(Q11="",0,1) -> 1 | Z11: =IF(R11+U11=2,3,IF(R11+U11=1,1,0)) -> 0 | AA11: =IF(Z11=3,3,IF(X11+Z11=2,2,IF(Z11=1,1,0))) -> 0 | AB11: =Q11+T11 -> 4 | AC11: =R11+U11+X11 -> 0 | AE11: ='Players - Men'!B17 -> Emman Xuereb | AF11: =J11+Y25+J25+Y21+J21+Y45 -> 6 | AG11: =L11+AA25+L25+AA21+L21+AA45 -> 0 | AH11: =M11+AB25+M25+AB21+M21+AB45 -> 0 | AI11: =N11+AC25+N25+AC21+N21+AC45 -> 0
A13: =AE9 -> Kristen Cachia | B13: 0 | C13: =IF(B13>B15,1,0) -> 0 | E13: 5 | F13: =IF(E13>E15,1,0) -> 0 | I13: =IF(H13>H15,1,0) -> 0 | J13: =IF(B13="",0,1) -> 1 | K13: =IF(C13+F13=2,3,IF(C13+F13=1,1,0)) -> 0 | L13: =IF(K13=3,3,IF(I13+K13=2,2,IF(K13=1,1,0))) -> 0 | M13: =B13+E13 -> 5 | N13: =C13+F13+I13 -> 0 | P13: =AE9 -> Kristen Cachia | Q13: 6 | R13: =IF(Q13>Q15,1,0) -> 1 | T13: 6 | U13: =IF(T13>T15,1,0) -> 1 | X13: =IF(W13>W15,1,0) -> 0 | Y13: =IF(Q13="",0,1) -> 1 | Z13: =IF(R13+U13=2,3,IF(R13+U13=1,1,0)) -> 3 | AA13: =IF(Z13=3,3,IF(X13+Z13=2,2,IF(Z13=1,1,0))) -> 3 | AB13: =Q13+T13 -> 12 | AC13: =R13+U13+X13 -> 2 | AE13: ='Players - Men'!B18 -> Sandro Pecorella | AF13: =Y29+Y11+Y33+J33+J23+J45 -> 6 | AG13: =AA29+AA11+AA33+L33+L23+L45 -> 2 | AH13: =AB29+AB11+AB33+M33+M23+M45 -> 23 | AI13: =AC29+AC11+AC33+N33+N23+N45 -> 2
A14: vs. | P14: vs.
A15: =AE15 -> Justin Graeme Christie | B15: 6 | C15: =IF(B15>B13,1,0) -> 1 | E15: 7 | F15: =IF(E15>E13,1,0) -> 1 | I15: =IF(H15>H13,1,0) -> 0 | J15: =IF(B15="",0,1) -> 1 | K15: =IF(C15+F15=2,3,IF(C15+F15=1,1,0)) -> 3 | L15: =IF(K15=3,3,IF(I15+K15=2,2,IF(K15=1,1,0))) -> 3 | M15: =B15+E15 -> 13 | N15: =C15+F15+I15 -> 2 | P15: =AE17 -> Ivan Cassar | Q15: 4 | R15: =IF(Q15>Q13,1,0) -> 0 | T15: 3 | U15: =IF(T15>T13,1,0) -> 0 | X15: =IF(W15>W13,1,0) -> 0 | Y15: =IF(Q15="",0,1) -> 1 | Z15: =IF(R15+U15=2,3,IF(R15+U15=1,1,0)) -> 0 | AA15: =IF(Z15=3,3,IF(X15+Z15=2,2,IF(Z15=1,1,0))) -> 0 | AB15: =Q15+T15 -> 7 | AC15: =R15+U15+X15 -> 0 | AE15: ='Players - Men'!B19 -> Justin Graeme Christie | AF15: =Y31+J37+J15+Y23+J29+J43 -> 5 | AG15: =AA31+L37+L15+AA23+L29+L43 -> 11 | AH15: =AB31+M37+M15+AB23+M29+M43 -> 49 | AI15: =AC31+N37+N15+AC23+N29+N43 -> 8
A17: =AE9 -> Kristen Cachia | C17: =IF(B17>B19,1,0) -> 0 | F17: =IF(E17>E19,1,0) -> 0 | I17: =IF(H17>H19,1,0) -> 0 | J17: =IF(B17="",0,1) -> 0 | K17: =IF(C17+F17=2,3,IF(C17+F17=1,1,0)) -> 0 | L17: =IF(K17=3,3,IF(I17+K17=2,2,IF(K17=1,1,0))) -> 0 | M17: =B17+E17 -> 0 | N17: =C17+F17+I17 -> 0 | P17: =AE17 -> Ivan Cassar | Q17: 2 | R17: =IF(Q17>Q19,1,0) -> 0 | T17: 0 | U17: =IF(T17>T19,1,0) -> 0 | X17: =IF(W17>W19,1,0) -> 0 | Y17: =IF(Q17="",0,1) -> 1 | Z17: =IF(R17+U17=2,3,IF(R17+U17=1,1,0)) -> 0 | AA17: =IF(Z17=3,3,IF(X17+Z17=2,2,IF(Z17=1,1,0))) -> 0 | AB17: =Q17+T17 -> 2 | AC17: =R17+U17+X17 -> 0 | AE17: ='Players - Men'!B20 -> Ivan Cassar | AF17: =Y17+J39+J27+Y15+J35+Y41 -> 5 | AG17: =AA17+L39+L27+AA15+L35+AA41 -> 6 | AH17: =AB17+M39+M27+AB15+M35+AB41 -> 34 | AI17: =AC17+N39+N27+AC15+N35+AC41 -> 4
A18: vs. | P18: vs.
A19: =AE19 -> Jurgen Farrugia | C19: =IF(B19>B17,1,0) -> 0 | F19: =IF(E19>E17,1,0) -> 0 | I19: =IF(H19>H17,1,0) -> 0 | J19: =IF(B19="",0,1) -> 0 | K19: =IF(C19+F19=2,3,IF(C19+F19=1,1,0)) -> 0 | L19: =IF(K19=3,3,IF(I19+K19=2,2,IF(K19=1,1,0))) -> 0 | M19: =B19+E19 -> 0 | N19: =C19+F19+I19 -> 0 | P19: =AE19 -> Jurgen Farrugia | Q19: 6 | R19: =IF(Q19>Q17,1,0) -> 1 | T19: 6 | U19: =IF(T19>T17,1,0) -> 1 | X19: =IF(W19>W17,1,0) -> 0 | Y19: =IF(Q19="",0,1) -> 1 | Z19: =IF(R19+U19=2,3,IF(R19+U19=1,1,0)) -> 3 | AA19: =IF(Z19=3,3,IF(X19+Z19=2,2,IF(Z19=1,1,0))) -> 3 | AB19: =Q19+T19 -> 12 | AC19: =R19+U19+X19 -> 2 | AE19: ='Players - Men'!B21 -> Jurgen Farrugia | AF19: =Y19+Y27+Y35+J19+J31+Y39 -> 5 | AG19: =AA19+AA35+L31+AA27+L19+AA39 -> 10 | AH19: =AB19+AB27+AB35+M19+M31+AB39 -> 44 | AI19: =AC19+AC27+AC35+N19+N31+AC39 -> 7
A21: =AE11 -> Emman Xuereb | B21: 0 | C21: =IF(B21>B23,1,0) -> 0 | E21: 0 | F21: =IF(E21>E23,1,0) -> 0 | I21: =IF(H21>H23,1,0) -> 0 | J21: =IF(B21="",0,1) -> 1 | K21: =IF(C21+F21=2,3,IF(C21+F21=1,1,0)) -> 0 | L21: =IF(K21=3,3,IF(I21+K21=2,2,IF(K21=1,1,0))) -> 0 | M21: =B21+E21 -> 0 | N21: =C21+F21+I21 -> 0 | P21: =AE11 -> Emman Xuereb | Q21: 0 | R21: =IF(Q21>Q23,1,0) -> 0 | T21: 0 | U21: =IF(T21>T23,1,0) -> 0 | X21: =IF(W21>W23,1,0) -> 0 | Y21: =IF(Q21="",0,1) -> 1 | Z21: =IF(R21+U21=2,3,IF(R21+U21=1,1,0)) -> 0 | AA21: =IF(Z21=3,3,IF(X21+Z21=2,2,IF(Z21=1,1,0))) -> 0 | AB21: =Q21+T21 -> 0 | AC21: =R21+U21+X21 -> 0 | AE21: ='Players - Men'!B22 -> Jean Paul Vella | AF21: =J41+J47+J51+Y37+Y43+Y47 -> 6 | AG21: =L41+L47+L51+AA37+AA43+AA47 -> 1 | AH21: =M41+M47+M51+AB37+AB43+AB47 -> 23 | AI21: =N41+N47+N51+AC37+AC43+AC47 -> 1
A22: vs. | P22: vs.
A23: =AE13 -> Sandro Pecorella | B23: 0 | C23: =IF(B23>B21,1,0) -> 0 | E23: 0 | F23: =IF(E23>E21,1,0) -> 0 | I23: =IF(H23>H21,1,0) -> 0 | J23: =IF(B23="",0,1) -> 1 | K23: =IF(C23+F23=2,3,IF(C23+F23=1,1,0)) -> 0 | L23: =IF(K23=3,3,IF(I23+K23=2,2,IF(K23=1,1,0))) -> 0 | M23: =B23+E23 -> 0 | N23: =C23+F23+I23 -> 0 | P23: =AE15 -> Justin Graeme Christie | Q23: 0 | R23: =IF(Q23>Q21,1,0) -> 0 | T23: 0 | U23: =IF(T23>T21,1,0) -> 0 | X23: =IF(W23>W21,1,0) -> 0 | Y23: =IF(Q23="",0,1) -> 1 | Z23: =IF(R23+U23=2,3,IF(R23+U23=1,1,0)) -> 0 | AA23: =IF(Z23=3,3,IF(X23+Z23=2,2,IF(Z23=1,1,0))) -> 0 | AB23: =Q23+T23 -> 0 | AC23: =R23+U23+X23 -> 0
AE24: Group A Winner
A25: =AE11 -> Emman Xuereb | B25: 0 | C25: =IF(B25>B27,1,0) -> 0 | E25: 0 | F25: =IF(E25>E27,1,0) -> 0 | I25: =IF(H25>H27,1,0) -> 0 | J25: =IF(B25="",0,1) -> 1 | K25: =IF(C25+F25=2,3,IF(C25+F25=1,1,0)) -> 0 | L25: =IF(K25=3,3,IF(I25+K25=2,2,IF(K25=1,1,0))) -> 0 | M25: =B25+E25 -> 0 | N25: =C25+F25+I25 -> 0 | P25: =AE11 -> Emman Xuereb | Q25: 0 | R25: =IF(Q25>Q27,1,0) -> 0 | T25: 0 | U25: =IF(T25>T27,1,0) -> 0 | X25: =IF(W25>W27,1,0) -> 0 | Y25: =IF(Q25="",0,1) -> 1 | Z25: =IF(R25+U25=2,3,IF(R25+U25=1,1,0)) -> 0 | AA25: =IF(Z25=3,3,IF(X25+Z25=2,2,IF(Z25=1,1,0))) -> 0 | AB25: =Q25+T25 -> 0 | AC25: =R25+U25+X25 -> 0
A26: vs. | P26: vs.
A27: =AE17 -> Ivan Cassar | B27: 0 | C27: =IF(B27>B25,1,0) -> 0 | E27: 0 | F27: =IF(E27>E25,1,0) -> 0 | I27: =IF(H27>H25,1,0) -> 0 | J27: =IF(B27="",0,1) -> 1 | K27: =IF(C27+F27=2,3,IF(C27+F27=1,1,0)) -> 0 | L27: =IF(K27=3,3,IF(I27+K27=2,2,IF(K27=1,1,0))) -> 0 | M27: =B27+E27 -> 0 | N27: =C27+F27+I27 -> 0 | P27: =AE19 -> Jurgen Farrugia | Q27: 0 | R27: =IF(Q27>Q25,1,0) -> 0 | T27: 0 | U27: =IF(T27>T25,1,0) -> 0 | X27: =IF(W27>W25,1,0) -> 0 | Y27: =IF(Q27="",0,1) -> 1 | Z27: =IF(R27+U27=2,3,IF(R27+U27=1,1,0)) -> 0 | AA27: =IF(Z27=3,3,IF(X27+Z27=2,2,IF(Z27=1,1,0))) -> 0 | AB27: =Q27+T27 -> 0 | AC27: =R27+U27+X27 -> 0
A29: =AE15 -> Justin Graeme Christie | B29: 6 | C29: =IF(B29>B31,1,0) -> 1 | E29: 6 | F29: =IF(E29>E31,1,0) -> 0 | H29: 10 | I29: =IF(H29>H31,1,0) -> 1 | J29: =IF(B29="",0,1) -> 1 | K29: =IF(C29+F29=2,3,IF(C29+F29=1,1,0)) -> 1 | L29: =IF(K29=3,3,IF(I29+K29=2,2,IF(K29=1,1,0))) -> 2 | M29: =B29+E29 -> 12 | N29: =C29+F29+I29 -> 2 | P29: =AE13 -> Sandro Pecorella | Q29: 0 | R29: =IF(Q29>Q31,1,0) -> 0 | T29: 1 | U29: =IF(T29>T31,1,0) -> 0 | X29: =IF(W29>W31,1,0) -> 0 | Y29: =IF(Q29="",0,1) -> 1 | Z29: =IF(R29+U29=2,3,IF(R29+U29=1,1,0)) -> 0 | AA29: =IF(Z29=3,3,IF(X29+Z29=2,2,IF(Z29=1,1,0))) -> 0 | AB29: =Q29+T29 -> 1 | AC29: =R29+U29+X29 -> 0
A30: vs. | P30: vs.
A31: =AE19 -> Jurgen Farrugia | B31: 1 | C31: =IF(B31>B29,1,0) -> 0 | E31: 7 | F31: =IF(E31>E29,1,0) -> 1 | H31: 7 | I31: =IF(H31>H29,1,0) -> 0 | J31: =IF(B31="",0,1) -> 1 | K31: =IF(C31+F31=2,3,IF(C31+F31=1,1,0)) -> 1 | L31: =IF(K31=3,3,IF(I31+K31=2,2,IF(K31=1,1,0))) -> 1 | M31: =B31+E31 -> 8 | N31: =C31+F31+I31 -> 1 | P31: =AE15 -> Justin Graeme Christie | Q31: 6 | R31: =IF(Q31>Q29,1,0) -> 1 | T31: 6 | U31: =IF(T31>T29,1,0) -> 1 | X31: =IF(W31>W29,1,0) -> 0 | Y31: =IF(Q31="",0,1) -> 1 | Z31: =IF(R31+U31=2,3,IF(R31+U31=1,1,0)) -> 3 | AA31: =IF(Z31=3,3,IF(X31+Z31=2,2,IF(Z31=1,1,0))) -> 3 | AB31: =Q31+T31 -> 12 | AC31: =R31+U31+X31 -> 2
A33: =AE13 -> Sandro Pecorella | B33: 4 | C33: =IF(B33>B35,1,0) -> 0 | E33: 1 | F33: =IF(E33>E35,1,0) -> 0 | I33: =IF(H33>H35,1,0) -> 0 | J33: =IF(B33="",0,1) -> 1 | K33: =IF(C33+F33=2,3,IF(C33+F33=1,1,0)) -> 0 | L33: =IF(K33=3,3,IF(I33+K33=2,2,IF(K33=1,1,0))) -> 0 | M33: =B33+E33 -> 5 | N33: =C33+F33+I33 -> 0 | P33: =AE13 -> Sandro Pecorella | Q33: 3 | R33: =IF(Q33>Q35,1,0) -> 0 | T33: 0 | U33: =IF(T33>T35,1,0) -> 0 | X33: =IF(W33>W35,1,0) -> 0 | Y33: =IF(Q33="",0,1) -> 1 | Z33: =IF(R33+U33=2,3,IF(R33+U33=1,1,0)) -> 0 | AA33: =IF(Z33=3,3,IF(X33+Z33=2,2,IF(Z33=1,1,0))) -> 0 | AB33: =Q33+T33 -> 3 | AC33: =R33+U33+X33 -> 0
A34: vs. | P34: vs.
A35: =AE17 -> Ivan Cassar | B35: 6 | C35: =IF(B35>B33,1,0) -> 1 | E35: 6 | F35: =IF(E35>E33,1,0) -> 1 | I35: =IF(H35>H33,1,0) -> 0 | J35: =IF(B35="",0,1) -> 1 | K35: =IF(C35+F35=2,3,IF(C35+F35=1,1,0)) -> 3 | L35: =IF(K35=3,3,IF(I35+K35=2,2,IF(K35=1,1,0))) -> 3 | M35: =B35+E35 -> 12 | N35: =C35+F35+I35 -> 2 | P35: =AE19 -> Jurgen Farrugia | Q35: 6 | R35: =IF(Q35>Q33,1,0) -> 1 | T35: 6 | U35: =IF(T35>T33,1,0) -> 1 | X35: =IF(W35>W33,1,0) -> 0 | Y35: =IF(Q35="",0,1) -> 1 | Z35: =IF(R35+U35=2,3,IF(R35+U35=1,1,0)) -> 3 | AA35: =IF(Z35=3,3,IF(X35+Z35=2,2,IF(Z35=1,1,0))) -> 3 | AB35: =Q35+T35 -> 12 | AC35: =R35+U35+X35 -> 2
A37: =AE15 -> Justin Graeme Christie | C37: =IF(B37>B39,1,0) -> 0 | F37: =IF(E37>E39,1,0) -> 0 | I37: =IF(H37>H39,1,0) -> 0 | J37: =IF(B37="",0,1) -> 0 | K37: =IF(C37+F37=2,3,IF(C37+F37=1,1,0)) -> 0 | L37: =IF(K37=3,3,IF(I37+K37=2,2,IF(K37=1,1,0))) -> 0 | M37: =B37+E37 -> 0 | N37: =C37+F37+I37 -> 0 | P37: =AE21 -> Jean Paul Vella | Q37: 2 | R37: =IF(Q37>Q39,1,0) -> 0 | T37: 1 | U37: =IF(T37>T39,1,0) -> 0 | X37: =IF(W37>W39,1,0) -> 0 | Y37: =IF(Q37="",0,1) -> 1 | Z37: =IF(R37+U37=2,3,IF(R37+U37=1,1,0)) -> 0 | AA37: =IF(Z37=3,3,IF(X37+Z37=2,2,IF(Z37=1,1,0))) -> 0 | AB37: =Q37+T37 -> 3 | AC37: =R37+U37+X37 -> 0
A38: vs. | P38: vs.
A39: =AE17 -> Ivan Cassar | C39: =IF(B39>B37,1,0) -> 0 | F39: =IF(E39>E37,1,0) -> 0 | I39: =IF(H39>H37,1,0) -> 0 | J39: =IF(B39="",0,1) -> 0 | K39: =IF(C39+F39=2,3,IF(C39+F39=1,1,0)) -> 0 | L39: =IF(K39=3,3,IF(I39+K39=2,2,IF(K39=1,1,0))) -> 0 | M39: =B39+E39 -> 0 | N39: =C39+F39+I39 -> 0 | P39: =AE19 -> Jurgen Farrugia | Q39: 6 | R39: =IF(Q39>Q37,1,0) -> 1 | T39: 6 | U39: =IF(T39>T37,1,0) -> 1 | X39: =IF(W39>W37,1,0) -> 0 | Y39: =IF(Q39="",0,1) -> 1 | Z39: =IF(R39+U39=2,3,IF(R39+U39=1,1,0)) -> 3 | AA39: =IF(Z39=3,3,IF(X39+Z39=2,2,IF(Z39=1,1,0))) -> 3 | AB39: =Q39+T39 -> 12 | AC39: =R39+U39+X39 -> 2
A41: =AE21 -> Jean Paul Vella | B41: 0 | C41: =IF(B41>B43,1,0) -> 0 | E41: 0 | F41: =IF(E41>E43,1,0) -> 0 | I41: =IF(H41>H43,1,0) -> 0 | J41: =IF(B41="",0,1) -> 1 | K41: =IF(C41+F41=2,3,IF(C41+F41=1,1,0)) -> 0 | L41: =IF(K41=3,3,IF(I41+K41=2,2,IF(K41=1,1,0))) -> 0 | M41: =B41+E41 -> 0 | N41: =C41+F41+I41 -> 0 | P41: =AE17 -> Ivan Cassar | Q41: 6 | R41: =IF(Q41>Q43,1,0) -> 1 | T41: 7 | U41: =IF(T41>T43,1,0) -> 1 | X41: =IF(W41>W43,1,0) -> 0 | Y41: =IF(Q41="",0,1) -> 1 | Z41: =IF(R41+U41=2,3,IF(R41+U41=1,1,0)) -> 3 | AA41: =IF(Z41=3,3,IF(X41+Z41=2,2,IF(Z41=1,1,0))) -> 3 | AB41: =Q41+T41 -> 13 | AC41: =R41+U41+X41 -> 2
A42: vs. | P42: vs.
A43: =AE15 -> Justin Graeme Christie | B43: 6 | C43: =IF(B43>B41,1,0) -> 1 | E43: 6 | F43: =IF(E43>E41,1,0) -> 1 | I43: =IF(H43>H41,1,0) -> 0 | J43: =IF(B43="",0,1) -> 1 | K43: =IF(C43+F43=2,3,IF(C43+F43=1,1,0)) -> 3 | L43: =IF(K43=3,3,IF(I43+K43=2,2,IF(K43=1,1,0))) -> 3 | M43: =B43+E43 -> 12 | N43: =C43+F43+I43 -> 2 | P43: =AE21 -> Jean Paul Vella | Q43: 1 | R43: =IF(Q43>Q41,1,0) -> 0 | T43: 5 | U43: =IF(T43>T41,1,0) -> 0 | X43: =IF(W43>W41,1,0) -> 0 | Y43: =IF(Q43="",0,1) -> 1 | Z43: =IF(R43+U43=2,3,IF(R43+U43=1,1,0)) -> 0 | AA43: =IF(Z43=3,3,IF(X43+Z43=2,2,IF(Z43=1,1,0))) -> 0 | AB43: =Q43+T43 -> 6 | AC43: =R43+U43+X43 -> 0
A45: =AE13 -> Sandro Pecorella | B45: 7 | C45: =IF(B45>B47,1,0) -> 1 | E45: 3 | F45: =IF(E45>E47,1,0) -> 0 | H45: 10 | I45: =IF(H45>H47,1,0) -> 1 | J45: =IF(B45="",0,1) -> 1 | K45: =IF(C45+F45=2,3,IF(C45+F45=1,1,0)) -> 1 | L45: =IF(K45=3,3,IF(I45+K45=2,2,IF(K45=1,1,0))) -> 2 | M45: =B45+E45 -> 10 | N45: =C45+F45+I45 -> 2 | P45: =AE11 -> Emman Xuereb | Q45: 0 | R45: =IF(Q45>Q47,1,0) -> 0 | T45: 0 | U45: =IF(T45>T47,1,0) -> 0 | X45: =IF(W45>W47,1,0) -> 0 | Y45: =IF(Q45="",0,1) -> 1 | Z45: =IF(R45+U45=2,3,IF(R45+U45=1,1,0)) -> 0 | AA45: =IF(Z45=3,3,IF(X45+Z45=2,2,IF(Z45=1,1,0))) -> 0 | AB45: =Q45+T45 -> 0 | AC45: =R45+U45+X45 -> 0
A46: vs. | P46: vs.
A47: =AE21 -> Jean Paul Vella | B47: 5 | C47: =IF(B47>B45,1,0) -> 0 | E47: 6 | F47: =IF(E47>E45,1,0) -> 1 | H47: 6 | I47: =IF(H47>H45,1,0) -> 0 | J47: =IF(B47="",0,1) -> 1 | K47: =IF(C47+F47=2,3,IF(C47+F47=1,1,0)) -> 1 | L47: =IF(K47=3,3,IF(I47+K47=2,2,IF(K47=1,1,0))) -> 1 | M47: =B47+E47 -> 11 | N47: =C47+F47+I47 -> 1 | P47: =AE21 -> Jean Paul Vella | Q47: 0 | R47: =IF(Q47>Q45,1,0) -> 0 | T47: 0 | U47: =IF(T47>T45,1,0) -> 0 | X47: =IF(W47>W45,1,0) -> 0 | Y47: =IF(Q47="",0,1) -> 1 | Z47: =IF(R47+U47=2,3,IF(R47+U47=1,1,0)) -> 0 | AA47: =IF(Z47=3,3,IF(X47+Z47=2,2,IF(Z47=1,1,0))) -> 0 | AB47: =Q47+T47 -> 0 | AC47: =R47+U47+X47 -> 0
A49: =AE9 -> Kristen Cachia | B49: 6 | C49: =IF(B49>B51,1,0) -> 1 | E49: 6 | F49: =IF(E49>E51,1,0) -> 1 | I49: =IF(H49>H51,1,0) -> 0 | J49: =IF(B49="",0,1) -> 1 | K49: =IF(C49+F49=2,3,IF(C49+F49=1,1,0)) -> 3 | L49: =IF(K49=3,3,IF(I49+K49=2,2,IF(K49=1,1,0))) -> 3 | M49: =B49+E49 -> 12 | N49: =C49+F49+I49 -> 2
A50: vs.
A51: =AE21 -> Jean Paul Vella | B51: 0 | C51: =IF(B51>B49,1,0) -> 0 | E51: 3 | F51: =IF(E51>E49,1,0) -> 0 | I51: =IF(H51>H49,1,0) -> 0 | J51: =IF(B51="",0,1) -> 1 | K51: =IF(C51+F51=2,3,IF(C51+F51=1,1,0)) -> 0 | L51: =IF(K51=3,3,IF(I51+K51=2,2,IF(K51=1,1,0))) -> 0 | M51: =B51+E51 -> 3 | N51: =C51+F51+I51 -> 0
A54: Division 2 - Group B
A56: Players | B56: Set Scores | H56: Tie | P56: Players | Q56: Set Scores | W56: Tie | AE56: Player | AF56: Matches Played | AG56: Points Overall | AH56: Games Won | AI56: Sets Won
...

Sheet Men Div 3
A1: H & S Singles Tournament 2026
A5: Men Division 3 - Group A
A7: Players | B7: Set Scores | H7: Tie | P7: Players | Q7: Set Scores | W7: Tie | AE7: Player | AF7: Matches Played | AG7: Points Overall | AH7: Games Won | AI7: Sets Won
B8: Score | C8: Set 1 Work | E8: Score | F8: Set 2 Work | H8: Score | I8: Tie Work | J8: Game Played | K8: Sets Points Work | L8: Sets & Tie Points Work | M8: Games Wins Work | N8: Sets Wins Work | Q8: Score | R8: Set 1 Work | T8: Score | U8: Set 2 Work | W8: Score | X8: Tie Work | Y8: Game Played | Z8: Sets Points Work | AA8: Sets & Tie Points Work | AB8: Games Wins Work | AC8: Sets Wins Work | AJ8: Winner Working | AK8: Runner Up Working | AL8: Total Games Work | AM8: Winner | AN8: Runner Up
A9: =AE9 -> Manuel Mifsud | C9: =IF(B9>B11,1,0) -> 0 | F9: =IF(E9>E11,1,0) -> 0 | I9: =IF(H9>H11,1,0) -> 0 | J9: =IF(B9="",0,1) -> 0 | K9: =IF(C9+F9=2,3,IF(C9+F9=1,1,0)) -> 0 | L9: =IF(K9=3,3,IF(I9+K9=2,2,IF(K9=1,1,0))) -> 0 | M9: =B9+E9 -> 0 | N9: =C9+F9+I9 -> 0 | P9: =AE9 -> Manuel Mifsud | Q9: 6 | R9: =IF(Q9>Q11,1,0) -> 1 | T9: 7 | U9: =IF(T9>T11,1,0) -> 1 | X9: =IF(W9>W11,1,0) -> 0 | Y9: =IF(Q9="",0,1) -> 1 | Z9: =IF(R9+U9=2,3,IF(R9+U9=1,1,0)) -> 3 | AA9: =IF(Z9=3,3,IF(X9+Z9=2,2,IF(Z9=1,1,0))) -> 3 | AB9: =Q9+T9 -> 13 | AC9: =R9+U9+X9 -> 2 | AE9: ='Players - Men'!B25 -> Manuel Mifsud | AF9: =J9+Y9+J13+Y13+J17 -> 4 | AG9: =L9+AA9+L13+AA13+L17 -> 9 | AH9: =M9+AB9+M13+AB13+M17 -> 43 | AI9: =N9+AC9+N13+AC13+N17 -> 7 | AJ9: =MAX(AG9:AG19) -> 9 | AK9: =LARGE(AG9:AG19, 2) -> 9 | AL9: =SUM(AF9:AF19) -> 22 | AM9: =IF(AG9=$AJ$9,AE9,IF(AG11=$AJ$9,AE11,IF(AG13=$AJ$9,AE13,IF(AG15=$AJ$9,AE15,IF(AG17=$AJ$9,AE17,""))))) -> Manuel Mifsud | AN9: =IF(AG9=$AK$9,AE9,IF(AG11=$AK$9,AE11,IF(AG13=$AK$9,AE13,IF(AG15=$AK$9,AE15,IF(AG17=$AK$9,AE17,""))))) -> Manuel Mifsud
A10: vs. | P10: vs.
A11: =AE11 -> Matthew Caruana | C11: =IF(B11>B9,1,0) -> 0 | F11: =IF(E11>E9,1,0) -> 0 | I11: =IF(H11>H9,1,0) -> 0 | J11: =IF(B11="",0,1) -> 0 | K11: =IF(C11+F11=2,3,IF(C11+F11=1,1,0)) -> 0 | L11: =IF(K11=3,3,IF(I11+K11=2,2,IF(K11=1,1,0))) -> 0 | M11: =B11+E11 -> 0 | N11: =C11+F11+I11 -> 0 | P11: =AE13 -> Juan Sammut | Q11: 0 | R11: =IF(Q11>Q9,1,0) -> 0 | T11: 5 | U11: =IF(T11>T9,1,0) -> 0 | X11: =IF(W11>W9,1,0) -> 0 | Y11: =IF(Q11="",0,1) -> 1 | Z11: =IF(R11+U11=2,3,IF(R11+U11=1,1,0)) -> 0 | AA11: =IF(Z11=3,3,IF(X11+Z11=2,2,IF(Z11=1,1,0))) -> 0 | AB11: =Q11+T11 -> 5 | AC11: =R11+U11+X11 -> 0 | AE11: ='Players - Men'!B26 -> Matthew Caruana | AF11: =J11+Y25+J25+Y21+J21 -> 3 | AG11: =L11+AA25+L25+AA21+L21 -> 9 | AH11: =M11+AB25+M25+AB21+M21 -> 36 | AI11: =N11+AC25+N25+AC21+N21 -> 6
A13: =AE9 -> Manuel Mifsud | B13: 6 | C13: =IF(B13>B15,1,0) -> 1 | E13: 2 | F13: =IF(E13>E15,1,0) -> 0 | H13: 13 | I13: =IF(H13>H15,1,0) -> 0 | J13: =IF(B13="",0,1) -> 1 | K13: =IF(C13+F13=2,3,IF(C13+F13=1,1,0)) -> 1 | L13: =IF(K13=3,3,IF(I13+K13=2,2,IF(K13=1,1,0))) -> 1 | M13: =B13+E13 -> 8 | N13: =C13+F13+I13 -> 1 | P13: =AE9 -> Manuel Mifsud | Q13: 6 | R13: =IF(Q13>Q15,1,0) -> 1 | T13: 7 | U13: =IF(T13>T15,1,0) -> 1 | X13: =IF(W13>W15,1,0) -> 0 | Y13: =IF(Q13="",0,1) -> 1 | Z13: =IF(R13+U13=2,3,IF(R13+U13=1,1,0)) -> 3 | AA13: =IF(Z13=3,3,IF(X13+Z13=2,2,IF(Z13=1,1,0))) -> 3 | AB13: =Q13+T13 -> 13 | AC13: =R13+U13+X13 -> 2 | AE13: ='Players - Men'!B27 -> Juan Sammut | AF13: =Y29+Y11+Y33+J33+J23 -> 3 | AG13: =AA29+AA11+AA33+L33+L23 -> 0 | AH13: =AB29+AB11+AB33+M33+M23 -> 19 | AI13: =AC29+AC11+AC33+N33+N23 -> 0
A14: vs. | P14: vs.
A15: =AE15 -> Artiom Kricenko | B15: 1 | C15: =IF(B15>B13,1,0) -> 0 | E15: 6 | F15: =IF(E15>E13,1,0) -> 1 | H15: 15 | I15: =IF(H15>H13,1,0) -> 1 | J15: =IF(B15="",0,1) -> 1 | K15: =IF(C15+F15=2,3,IF(C15+F15=1,1,0)) -> 1 | L15: =IF(K15=3,3,IF(I15+K15=2,2,IF(K15=1,1,0))) -> 2 | M15: =B15+E15 -> 7 | N15: =C15+F15+I15 -> 2 | P15: =AE17 -> Jason Lee Evans | Q15: 4 | R15: =IF(Q15>Q13,1,0) -> 0 | T15: 5 | U15: =IF(T15>T13,1,0) -> 0 | X15: =IF(W15>W13,1,0) -> 0 | Y15: =IF(Q15="",0,1) -> 1 | Z15: =IF(R15+U15=2,3,IF(R15+U15=1,1,0)) -> 0 | AA15: =IF(Z15=3,3,IF(X15+Z15=2,2,IF(Z15=1,1,0))) -> 0 | AB15: =Q15+T15 -> 9 | AC15: =R15+U15+X15 -> 0 | AE15: ='Players - Men'!B28 -> Artiom Kricenko | AF15: =Y31+J37+J15+Y23+J29 -> 4 | AG15: =AA31+L37+L15+AA23+L29 -> 7 | AH15: =AB31+M37+M15+AB23+M29 -> 33 | AI15: =AC31+N37+N15+AC23+N29 -> 6
A17: =AE9 -> Manuel Mifsud | B17: 3 | C17: =IF(B17>B19,1,0) -> 0 | E17: 6 | F17: =IF(E17>E19,1,0) -> 1 | H17: 10 | I17: =IF(H17>H19,1,0) -> 1 | J17: =IF(B17="",0,1) -> 1 | K17: =IF(C17+F17=2,3,IF(C17+F17=1,1,0)) -> 1 | L17: =IF(K17=3,3,IF(I17+K17=2,2,IF(K17=1,1,0))) -> 2 | M17: =B17+E17 -> 9 | N17: =C17+F17+I17 -> 2 | P17: =AE17 -> Jason Lee Evans | Q17: 6 | R17: =IF(Q17>Q19,1,0) -> 1 | T17: 7 | U17: =IF(T17>T19,1,0) -> 1 | X17: =IF(W17>W19,1,0) -> 0 | Y17: =IF(Q17="",0,1) -> 1 | Z17: =IF(R17+U17=2,3,IF(R17+U17=1,1,0)) -> 3 | AA17: =IF(Z17=3,3,IF(X17+Z17=2,2,IF(Z17=1,1,0))) -> 3 | AB17: =Q17+T17 -> 13 | AC17: =R17+U17+X17 -> 2 | AE17: ='Players - Men'!B29 -> Jason Lee Evans | AF17: =Y17+J39+J27+Y15+J35 -> 4 | AG17: =AA17+L39+L27+AA15+L35 -> 7 | AH17: =AB17+M39+M27+AB15+M35 -> 42 | AI17: =AC17+N39+N27+AC15+N35 -> 5
A18: vs. | P18: vs.
A19: =AE19 -> Chris Vella | B19: 6 | C19: =IF(B19>B17,1,0) -> 1 | E19: 4 | F19: =IF(E19>E17,1,0) -> 0 | H19: 4 | I19: =IF(H19>H17,1,0) -> 0 | J19: =IF(B19="",0,1) -> 1 | K19: =IF(C19+F19=2,3,IF(C19+F19=1,1,0)) -> 1 | L19: =IF(K19=3,3,IF(I19+K19=2,2,IF(K19=1,1,0))) -> 1 | M19: =B19+E19 -> 10 | N19: =C19+F19+I19 -> 1 | P19: =AE19 -> Chris Vella | Q19: 3 | R19: =IF(Q19>Q17,1,0) -> 0 | T19: 5 | U19: =IF(T19>T17,1,0) -> 0 | X19: =IF(W19>W17,1,0) -> 0 | Y19: =IF(Q19="",0,1) -> 1 | Z19: =IF(R19+U19=2,3,IF(R19+U19=1,1,0)) -> 0 | AA19: =IF(Z19=3,3,IF(X19+Z19=2,2,IF(Z19=1,1,0))) -> 0 | AB19: =Q19+T19 -> 8 | AC19: =R19+U19+X19 -> 0 | AE19: ='Players - Men'!B30 -> Chris Vella | AF19: =Y19+Y27+Y35+J19+J31 -> 4 | AG19: =AA19+AA27+AA35+L19+L31 -> 1 | AH19: =AB19+AB27+AB35+M19+M31 -> 35 | AI19: =AC19+AC27+AC35+N19+N31 -> 1
A21: =AE11 -> Matthew Caruana | B21: 6 | C21: =IF(B21>B23,1,0) -> 1 | E21: 6 | F21: =IF(E21>E23,1,0) -> 1 | I21: =IF(H21>H23,1,0) -> 0 | J21: =IF(B21="",0,1) -> 1 | K21: =IF(C21+F21=2,3,IF(C21+F21=1,1,0)) -> 3 | L21: =IF(K21=3,3,IF(I21+K21=2,2,IF(K21=1,1,0))) -> 3 | M21: =B21+E21 -> 12 | N21: =C21+F21+I21 -> 2 | P21: =AE11 -> Matthew Caruana | Q21: 6 | R21: =IF(Q21>Q23,1,0) -> 1 | T21: 6 | U21: =IF(T21>T23,1,0) -> 1 | X21: =IF(W21>W23,1,0) -> 0 | Y21: =IF(Q21="",0,1) -> 1 | Z21: =IF(R21+U21=2,3,IF(R21+U21=1,1,0)) -> 3 | AA21: =IF(Z21=3,3,IF(X21+Z21=2,2,IF(Z21=1,1,0))) -> 3 | AB21: =Q21+T21 -> 12 | AC21: =R21+U21+X21 -> 2 | AE21: Division Winner
A22: vs. | P22: vs.
A23: =AE13 -> Juan Sammut | B23: 3 | C23: =IF(B23>B21,1,0) -> 0 | E23: 3 | F23: =IF(E23>E21,1,0) -> 0 | I23: =IF(H23>H21,1,0) -> 0 | J23: =IF(B23="",0,1) -> 1 | K23: =IF(C23+F23=2,3,IF(C23+F23=1,1,0)) -> 0 | L23: =IF(K23=3,3,IF(I23+K23=2,2,IF(K23=1,1,0))) -> 0 | M23: =B23+E23 -> 6 | N23: =C23+F23+I23 -> 0 | P23: =AE15 -> Artiom Kricenko | Q23: 1 | R23: =IF(Q23>Q21,1,0) -> 0 | T23: 4 | U23: =IF(T23>T21,1,0) -> 0 | X23: =IF(W23>W21,1,0) -> 0 | Y23: =IF(Q23="",0,1) -> 1 | Z23: =IF(R23+U23=2,3,IF(R23+U23=1,1,0)) -> 0 | AA23: =IF(Z23=3,3,IF(X23+Z23=2,2,IF(Z23=1,1,0))) -> 0 | AB23: =Q23+T23 -> 5 | AC23: =R23+U23+X23 -> 0
A25: =AE11 -> Matthew Caruana | C25: =IF(B25>B27,1,0) -> 0 | F25: =IF(E25>E27,1,0) -> 0 | I25: =IF(H25>H27,1,0) -> 0 | J25: =IF(B25="",0,1) -> 0 | K25: =IF(C25+F25=2,3,IF(C25+F25=1,1,0)) -> 0 | L25: =IF(K25=3,3,IF(I25+K25=2,2,IF(K25=1,1,0))) -> 0 | M25: =B25+E25 -> 0 | N25: =C25+F25+I25 -> 0 | P25: =AE11 -> Matthew Caruana | Q25: 6 | R25: =IF(Q25>Q27,1,0) -> 1 | T25: 6 | U25: =IF(T25>T27,1,0) -> 1 | X25: =IF(W25>W27,1,0) -> 0 | Y25: =IF(Q25="",0,1) -> 1 | Z25: =IF(R25+U25=2,3,IF(R25+U25=1,1,0)) -> 3 | AA25: =IF(Z25=3,3,IF(X25+Z25=2,2,IF(Z25=1,1,0))) -> 3 | AB25: =Q25+T25 -> 12 | AC25: =R25+U25+X25 -> 2
A26: vs. | P26: vs.
A27: =AE17 -> Jason Lee Evans | C27: =IF(B27>B25,1,0) -> 0 | F27: =IF(E27>E25,1,0) -> 0 | I27: =IF(H27>H25,1,0) -> 0 | J27: =IF(B27="",0,1) -> 0 | K27: =IF(C27+F27=2,3,IF(C27+F27=1,1,0)) -> 0 | L27: =IF(K27=3,3,IF(I27+K27=2,2,IF(K27=1,1,0))) -> 0 | M27: =B27+E27 -> 0 | N27: =C27+F27+I27 -> 0 | P27: =AE19 -> Chris Vella | Q27: 2 | R27: =IF(Q27>Q25,1,0) -> 0 | T27: 4 | U27: =IF(T27>T25,1,0) -> 0 | X27: =IF(W27>W25,1,0) -> 0 | Y27: =IF(Q27="",0,1) -> 1 | Z27: =IF(R27+U27=2,3,IF(R27+U27=1,1,0)) -> 0 | AA27: =IF(Z27=3,3,IF(X27+Z27=2,2,IF(Z27=1,1,0))) -> 0 | AB27: =Q27+T27 -> 6 | AC27: =R27+U27+X27 -> 0
A29: =AE15 -> Artiom Kricenko | B29: 7 | C29: =IF(B29>B31,1,0) -> 1 | E29: 7 | F29: =IF(E29>E31,1,0) -> 1 | I29: =IF(H29>H31,1,0) -> 0 | J29: =IF(B29="",0,1) -> 1 | K29: =IF(C29+F29=2,3,IF(C29+F29=1,1,0)) -> 3 | L29: =IF(K29=3,3,IF(I29+K29=2,2,IF(K29=1,1,0))) -> 3 | M29: =B29+E29 -> 14 | N29: =C29+F29+I29 -> 2 | P29: =AE13 -> Juan Sammut | R29: =IF(Q29>Q31,1,0) -> 0 | U29: =IF(T29>T31,1,0) -> 0 | X29: =IF(W29>W31,1,0) -> 0 | Y29: =IF(Q29="",0,1) -> 0 | Z29: =IF(R29+U29=2,3,IF(R29+U29=1,1,0)) -> 0 | AA29: =IF(Z29=3,3,IF(X29+Z29=2,2,IF(Z29=1,1,0))) -> 0 | AB29: =Q29+T29 -> 0 | AC29: =R29+U29+X29 -> 0
A30: vs. | P30: vs.
A31: =AE19 -> Chris Vella | B31: 6 | C31: =IF(B31>B29,1,0) -> 0 | E31: 5 | F31: =IF(E31>E29,1,0) -> 0 | I31: =IF(H31>H29,1,0) -> 0 | J31: =IF(B31="",0,1) -> 1 | K31: =IF(C31+F31=2,3,IF(C31+F31=1,1,0)) -> 0 | L31: =IF(K31=3,3,IF(I31+K31=2,2,IF(K31=1,1,0))) -> 0 | M31: =B31+E31 -> 11 | N31: =C31+F31+I31 -> 0 | P31: =AE15 -> Artiom Kricenko | R31: =IF(Q31>Q29,1,0) -> 0 | U31: =IF(T31>T29,1,0) -> 0 | X31: =IF(W31>W29,1,0) -> 0 | Y31: =IF(Q31="",0,1) -> 0 | Z31: =IF(R31+U31=2,3,IF(R31+U31=1,1,0)) -> 0 | AA31: =IF(Z31=3,3,IF(X31+Z31=2,2,IF(Z31=1,1,0))) -> 0 | AB31: =Q31+T31 -> 0 | AC31: =R31+U31+X31 -> 0
A33: =AE13 -> Juan Sammut | B33: 4 | C33: =IF(B33>B35,1,0) -> 0 | E33: 4 | F33: =IF(E33>E35,1,0) -> 0 | I33: =IF(H33>H35,1,0) -> 0 | J33: =IF(B33="",0,1) -> 1 | K33: =IF(C33+F33=2,3,IF(C33+F33=1,1,0)) -> 0 | L33: =IF(K33=3,3,IF(I33+K33=2,2,IF(K33=1,1,0))) -> 0 | M33: =B33+E33 -> 8 | N33: =C33+F33+I33 -> 0 | P33: =AE13 -> Juan Sammut | R33: =IF(Q33>Q35,1,0) -> 0 | U33: =IF(T33>T35,1,0) -> 0 | X33: =IF(W33>W35,1,0) -> 0 | Y33: =IF(Q33="",0,1) -> 0 | Z33: =IF(R33+U33=2,3,IF(R33+U33=1,1,0)) -> 0 | AA33: =IF(Z33=3,3,IF(X33+Z33=2,2,IF(Z33=1,1,0))) -> 0 | AB33: =Q33+T33 -> 0 | AC33: =R33+U33+X33 -> 0
A34: vs. | P34: vs.
A35: =AE17 -> Jason Lee Evans | B35: 6 | C35: =IF(B35>B33,1,0) -> 1 | E35: 6 | F35: =IF(E35>E33,1,0) -> 1 | I35: =IF(H35>H33,1,0) -> 0 | J35: =IF(B35="",0,1) -> 1 | K35: =IF(C35+F35=2,3,IF(C35+F35=1,1,0)) -> 3 | L35: =IF(K35=3,3,IF(I35+K35=2,2,IF(K35=1,1,0))) -> 3 | M35: =B35+E35 -> 12 | N35: =C35+F35+I35 -> 2 | P35: =AE19 -> Chris Vella | R35: =IF(Q35>Q33,1,0) -> 0 | U35: =IF(T35>T33,1,0) -> 0 | X35: =IF(W35>W33,1,0) -> 0 | Y35: =IF(Q35="",0,1) -> 0 | Z35: =IF(R35+U35=2,3,IF(R35+U35=1,1,0)) -> 0 | AA35: =IF(Z35=3,3,IF(X35+Z35=2,2,IF(Z35=1,1,0))) -> 0 | AB35: =Q35+T35 -> 0 | AC35: =R35+U35+X35 -> 0
A37: =AE15 -> Artiom Kricenko | B37: 6 | C37: =IF(B37>B39,1,0) -> 1 | E37: 1 | F37: =IF(E37>E39,1,0) -> 0 | H37: 11 | I37: =IF(H37>H39,1,0) -> 1 | J37: =IF(B37="",0,1) -> 1 | K37: =IF(C37+F37=2,3,IF(C37+F37=1,1,0)) -> 1 | L37: =IF(K37=3,3,IF(I37+K37=2,2,IF(K37=1,1,0))) -> 2 | M37: =B37+E37 -> 7 | N37: =C37+F37+I37 -> 2
A38: vs.
A39: =AE17 -> Jason Lee Evans | B39: 2 | C39: =IF(B39>B37,1,0) -> 0 | E39: 6 | F39: =IF(E39>E37,1,0) -> 1 | H39: 9 | I39: =IF(H39>H37,1,0) -> 0 | J39: =IF(B39="",0,1) -> 1 | K39: =IF(C39+F39=2,3,IF(C39+F39=1,1,0)) -> 1 | L39: =IF(K39=3,3,IF(I39+K39=2,2,IF(K39=1,1,0))) -> 1 | M39: =B39+E39 -> 8 | N39: =C39+F39+I39 -> 1
A42: Men Division 3 - Group B
A44: Players | B44: Set Scores | H44: Tie | P44: Players | Q44: Set Scores | W44: Tie | AE44: Player | AF44: Matches Played | AG44: Points Overall | AH44: Games Won | AI44: Sets Won
B45: Score | C45: Set 1 Work | E45: Score | F45: Set 2 Work | H45: Score | I45: Tie Work | J45: Game Played | K45: Sets Points Work | L45: Sets & Tie Points Work | M45: Games Wins Work | N45: Sets Wins Work | Q45: Score | R45: Set 1 Work | T45: Score | U45: Set 2 Work | W45: Score | X45: Tie Work | Y45: Game Played | Z45: Sets Points Work | AA45: Sets & Tie Points Work | AB45: Games Wins Work | AC45: Sets Wins Work
A46: =AE46 -> Matthias Sciriha | B46: 6 | C46: =IF(B46>B48,1,0) -> 1 | E46: 7 | F46: =IF(E46>E48,1,0) -> 1 | I46: =IF(H46>H48,1,0) -> 0 | J46: =IF(B46="",0,1) -> 1 | K46: =IF(C46+F46=2,3,IF(C46+F46=1,1,0)) -> 3 | L46: =IF(K46=3,3,IF(I46+K46=2,2,IF(K46=1,1,0))) -> 3 | M46: =B46+E46 -> 13 | N46: =C46+F46+I46 -> 2 | P46: =AE46 -> Matthias Sciriha | Q46: 6 | R46: =IF(Q46>Q48,1,0) -> 1 | T46: 4 | U46: =IF(T46>T48,1,0) -> 0 | W46: 11 | X46: =IF(W46>W48,1,0) -> 1 | Y46: =IF(Q46="",0,1) -> 1 | Z46: =IF(R46+U46=2,3,IF(R46+U46=1,1,0)) -> 1 | AA46: =IF(Z46=3,3,IF(X46+Z46=2,2,IF(Z46=1,1,0))) -> 2 | AB46: =Q46+T46 -> 10 | AC46: =R46+U46+X46 -> 2 | AE46: ='Players - Men'!E25 -> Matthias Sciriha | AF46: =J46+Y46+J50+Y50+J54 -> 3 | AG46: =L46+AA46+L50+AA50+L54 -> 8 | AH46: =M46+AB46+M50+AB50+M54 -> 35 | AI46: =N46+AC46+N50+AC50+N54 -> 6
A47: vs. | P47: vs.
A48: =AE48 -> Kenneth Farrugia | B48: 3 | C48: =IF(B48>B46,1,0) -> 0 | E48: 6 | F48: =IF(E48>E46,1,0) -> 0 | I48: =IF(H48>H46,1,0) -> 0 | J48: =IF(B48="",0,1) -> 1 | K48: =IF(C48+F48=2,3,IF(C48+F48=1,1,0)) -> 0 | L48: =IF(K48=3,3,IF(I48+K48=2,2,IF(K48=1,1,0))) -> 0 | M48: =B48+E48 -> 9 | N48: =C48+F48+I48 -> 0 | P48: =AE50 -> Simone Re | Q48: 3 | R48: =IF(Q48>Q46,1,0) -> 0 | T48: 6 | U48: =IF(T48>T46,1,0) -> 1 | W48: 9 | X48: =IF(W48>W46,1,0) -> 0 | Y48: =IF(Q48="",0,1) -> 1 | Z48: =IF(R48+U48=2,3,IF(R48+U48=1,1,0)) -> 1 | AA48: =IF(Z48=3,3,IF(X48+Z48=2,2,IF(Z48=1,1,0))) -> 1 | AB48: =Q48+T48 -> 9 | AC48: =R48+U48+X48 -> 1 | AE48: ='Players - Men'!E26 -> Kenneth Farrugia | AF48: =J48+Y62+J62+Y58+J58 -> 4 | AG48: =L48+AA62+L62+AA58+L58 -> 7 | AH48: =M48+AB62+M62+AB58+M58 -> 44 | AI48: =N48+AC62+N62+AC58+N58 -> 5
A50: =AE46 -> Matthias Sciriha | C50: =IF(B50>B52,1,0) -> 0 | F50: =IF(E50>E52,1,0) -> 0 | I50: =IF(H50>H52,1,0) -> 0 | J50: =IF(B50="",0,1) -> 0 | K50: =IF(C50+F50=2,3,IF(C50+F50=1,1,0)) -> 0 | L50: =IF(K50=3,3,IF(I50+K50=2,2,IF(K50=1,1,0))) -> 0 | M50: =B50+E50 -> 0 | N50: =C50+F50+I50 -> 0 | P50: =AE46 -> Matthias Sciriha | Q50: 6 | R50: =IF(Q50>Q52,1,0) -> 1 | T50: 6 | U50: =IF(T50>T52,1,0) -> 1 | X50: =IF(W50>W52,1,0) -> 0 | Y50: =IF(Q50="",0,1) -> 1 | Z50: =IF(R50+U50=2,3,IF(R50+U50=1,1,0)) -> 3 | AA50: =IF(Z50=3,3,IF(X50+Z50=2,2,IF(Z50=1,1,0))) -> 3 | AB50: =Q50+T50 -> 12 | AC50: =R50+U50+X50 -> 2 | AE50: ='Players - Men'!E27 -> Simone Re | AF50: =Y66+Y48+Y70+J70+J60 -> 4 | AG50: =AA66+AA48+AA70+L70+L60 -> 7 | AH50: =AB66+AB48+AB70+M70+M60 -> 42 | AI50: =AC66+AC48+AC70+N70+N60 -> 5
A51: vs. | P51: vs.
A52: =AE52 -> Matthew Micallef | C52: =IF(B52>B50,1,0) -> 0 | F52: =IF(E52>E50,1,0) -> 0 | I52: =IF(H52>H50,1,0) -> 0 | J52: =IF(B52="",0,1) -> 0 | K52: =IF(C52+F52=2,3,IF(C52+F52=1,1,0)) -> 0 | L52: =IF(K52=3,3,IF(I52+K52=2,2,IF(K52=1,1,0))) -> 0 | M52: =B52+E52 -> 0 | N52: =C52+F52+I52 -> 0 | P52: =AE54 -> Jurgen Cachia | Q52: 3 | R52: =IF(Q52>Q50,1,0) -> 0 | T52: 3 | U52: =IF(T52>T50,1,0) -> 0 | X52: =IF(W52>W50,1,0) -> 0 | Y52: =IF(Q52="",0,1) -> 1 | Z52: =IF(R52+U52=2,3,IF(R52+U52=1,1,0)) -> 0 | AA52: =IF(Z52=3,3,IF(X52+Z52=2,2,IF(Z52=1,1,0))) -> 0 | AB52: =Q52+T52 -> 6 | AC52: =R52+U52+X52 -> 0 | AE52: ='Players - Men'!E28 -> Matthew Micallef | AF52: =Y68+J74+J52+Y60+J66 -> 4 | AG52: =AA68+L74+L52+AA60+L66 -> 9 | AH52: =AB68+M74+M52+AB60+M66 -> 48 | AI52: =AC68+N74+N52+AC60+N66 -> 7
A54: =AE46 -> Matthias Sciriha | C54: =IF(B54>B56,1,0) -> 0 | F54: =IF(E54>E56,1,0) -> 0 | I54: =IF(H54>H56,1,0) -> 0 | J54: =IF(B54="",0,1) -> 0 | K54: =IF(C54+F54=2,3,IF(C54+F54=1,1,0)) -> 0 | L54: =IF(K54=3,3,IF(I54+K54=2,2,IF(K54=1,1,0))) -> 0 | M54: =B54+E54 -> 0 | N54: =C54+F54+I54 -> 0 | P54: =AE54 -> Jurgen Cachia | Q54: 0 | R54: =IF(Q54>Q56,1,0) -> 0 | T54: 0 | U54: =IF(T54>T56,1,0) -> 0 | X54: =IF(W54>W56,1,0) -> 0 | Y54: =IF(Q54="",0,1) -> 1 | Z54: =IF(R54+U54=2,3,IF(R54+U54=1,1,0)) -> 0 | AA54: =IF(Z54=3,3,IF(X54+Z54=2,2,IF(Z54=1,1,0))) -> 0 | AB54: =Q54+T54 -> 0 | AC54: =R54+U54+X54 -> 0 | AD54: w/o | AE54: ='Players - Men'!E29 -> Jurgen Cachia | AF54: =Y54+J76+J64+Y52+J72 -> 5 | AG54: =AA54+L76+L64+AA52+L72 -> 2 | AH54: =AB54+M76+M64+AB52+M72 -> 27 | AI54: =AC54+N76+N64+AC52+N72 -> 2
A55: vs. | P55: vs.
A56: =AE56 -> Redent Scicluna | C56: =IF(B56>B54,1,0) -> 0 | F56: =IF(E56>E54,1,0) -> 0 | I56: =IF(H56>H54,1,0) -> 0 | J56: =IF(B56="",0,1) -> 0 | K56: =IF(C56+F56=2,3,IF(C56+F56=1,1,0)) -> 0 | L56: =IF(K56=3,3,IF(I56+K56=2,2,IF(K56=1,1,0))) -> 0 | M56: =B56+E56 -> 0 | N56: =C56+F56+I56 -> 0 | P56: =AE56 -> Redent Scicluna | Q56: 6 | R56: =IF(Q56>Q54,1,0) -> 1 | T56: 6 | U56: =IF(T56>T54,1,0) -> 1 | X56: =IF(W56>W54,1,0) -> 0 | Y56: =IF(Q56="",0,1) -> 1 | Z56: =IF(R56+U56=2,3,IF(R56+U56=1,1,0)) -> 3 | AA56: =IF(Z56=3,3,IF(X56+Z56=2,2,IF(Z56=1,1,0))) -> 3 | AB56: =Q56+T56 -> 12 | AC56: =R56+U56+X56 -> 2 | AE56: ='Players - Men'!E30 -> Redent Scicluna | AF56: =Y56+Y64+Y72+J56+J68 -> 4 | AG56: =AA56+AA64+AA72+L56+L68 -> 3 | AH56: =AB56+AB64+AB72+M56+M68 -> 28 | AI56: =AC56+AC64+AC72+N56+N68 -> 2
...

Sheet Men Div 4
A1: H & S Singles Tournament 2026
A5: Men Division 4 - Group A
A7: Players | B7: Set Scores | H7: Tie | P7: Players | Q7: Set Scores | W7: Tie | AE7: Player | AF7: Matches Played | AG7: Points Overall | AH7: Games Won | AI7: Sets Won
B8: Score | C8: Set 1 Work | E8: Score | F8: Set 2 Work | H8: Score | I8: Tie Work | J8: Game Played | K8: Sets Points Work | L8: Sets & Tie Points Work | M8: Games Wins Work | N8: Sets Wins Work | Q8: Score | R8: Set 1 Work | T8: Score | U8: Set 2 Work | W8: Score | X8: Tie Work | Y8: Game Played | Z8: Sets Points Work | AA8: Sets & Tie Points Work | AB8: Games Wins Work | AC8: Sets Wins Work | AJ8: Winner Working | AK8: Runner Up Working | AL8: Total Games Work | AM8: Winner | AN8: Runner Up
A9: =AE9 -> Clive Silvio Borg | B9: 6 | C9: =IF(B9>B11,1,0) -> 1 | E9: 6 | F9: =IF(E9>E11,1,0) -> 1 | I9: =IF(H9>H11,1,0) -> 0 | J9: =IF(B9="",0,1) -> 1 | K9: =IF(C9+F9=2,3,IF(C9+F9=1,1,0)) -> 3 | L9: =IF(K9=3,3,IF(I9+K9=2,2,IF(K9=1,1,0))) -> 3 | M9: =B9+E9 -> 12 | N9: =C9+F9+I9 -> 2 | P9: =AE9 -> Clive Silvio Borg | Q9: 6 | R9: =IF(Q9>Q11,1,0) -> 1 | T9: 4 | U9: =IF(T9>T11,1,0) -> 0 | W9: 5 | X9: =IF(W9>W11,1,0) -> 0 | Y9: =IF(Q9="",0,1) -> 1 | Z9: =IF(R9+U9=2,3,IF(R9+U9=1,1,0)) -> 1 | AA9: =IF(Z9=3,3,IF(X9+Z9=2,2,IF(Z9=1,1,0))) -> 1 | AB9: =Q9+T9 -> 10 | AC9: =R9+U9+X9 -> 1 | AE9: ='Players - Men'!B33 -> Clive Silvio Borg | AF9: =J9+Y9+J13+Y13+J17 -> 2 | AG9: =L9+AA9+L13+AA13+L17 -> 4 | AH9: =M9+AB9+M13+AB13+M17 -> 22 | AI9: =N9+AC9+N13+AC13+N17 -> 3 | AJ9: =MAX(AG9:AG19) -> 12 | AK9: =LARGE(AG9:AG19, 2) -> 7 | AL9: =SUM(AF9:AF19) -> 20 | AM9: =IF(AG9=$AJ$9,AE9,IF(AG11=$AJ$9,AE11,IF(AG13=$AJ$9,AE13,IF(AG15=$AJ$9,AE15,IF(AG17=$AJ$9,AE17,""))))) -> Matthias Cremona | AN9: =IF(AG9=$AK$9,AE9,IF(AG11=$AK$9,AE11,IF(AG13=$AK$9,AE13,IF(AG15=$AK$9,AE15,IF(AG17=$AK$9,AE17,""))))) -> JP Sciberras
A10: vs. | P10: vs.
A11: =AE11 -> Julian Galea Naudi | B11: 0 | C11: =IF(B11>B9,1,0) -> 0 | E11: 2 | F11: =IF(E11>E9,1,0) -> 0 | I11: =IF(H11>H9,1,0) -> 0 | J11: =IF(B11="",0,1) -> 1 | K11: =IF(C11+F11=2,3,IF(C11+F11=1,1,0)) -> 0 | L11: =IF(K11=3,3,IF(I11+K11=2,2,IF(K11=1,1,0))) -> 0 | M11: =B11+E11 -> 2 | N11: =C11+F11+I11 -> 0 | P11: =AE13 -> JP Sciberras | Q11: 3 | R11: =IF(Q11>Q9,1,0) -> 0 | T11: 6 | U11: =IF(T11>T9,1,0) -> 1 | W11: 10 | X11: =IF(W11>W9,1,0) -> 1 | Y11: =IF(Q11="",0,1) -> 1 | Z11: =IF(R11+U11=2,3,IF(R11+U11=1,1,0)) -> 1 | AA11: =IF(Z11=3,3,IF(X11+Z11=2,2,IF(Z11=1,1,0))) -> 2 | AB11: =Q11+T11 -> 9 | AC11: =R11+U11+X11 -> 2 | AE11: ='Players - Men'!B34 -> Julian Galea Naudi | AF11: =J11+Y25+J25+Y21+J21 -> 3 | AG11: =L11+AA25+L25+AA21+L21 -> 0 | AH11: =M11+AB25+M25+AB21+M21 -> 7 | AI11: =N11+AC25+N25+AC21+N21 -> 0
A13: =AE9 -> Clive Silvio Borg | C13: =IF(B13>B15,1,0) -> 0 | F13: =IF(E13>E15,1,0) -> 0 | I13: =IF(H13>H15,1,0) -> 0 | J13: =IF(B13="",0,1) -> 0 | K13: =IF(C13+F13=2,3,IF(C13+F13=1,1,0)) -> 0 | L13: =IF(K13=3,3,IF(I13+K13=2,2,IF(K13=1,1,0))) -> 0 | M13: =B13+E13 -> 0 | N13: =C13+F13+I13 -> 0 | P13: =AE9 -> Clive Silvio Borg | R13: =IF(Q13>Q15,1,0) -> 0 | U13: =IF(T13>T15,1,0) -> 0 | X13: =IF(W13>W15,1,0) -> 0 | Y13: =IF(Q13="",0,1) -> 0 | Z13: =IF(R13+U13=2,3,IF(R13+U13=1,1,0)) -> 0 | AA13: =IF(Z13=3,3,IF(X13+Z13=2,2,IF(Z13=1,1,0))) -> 0 | AB13: =Q13+T13 -> 0 | AC13: =R13+U13+X13 -> 0 | AE13: ='Players - Men'!B35 -> JP Sciberras | AF13: =Y29+Y11+Y33+J33+J23 -> 5 | AG13: =AA29+AA11+AA33+L33+L23 -> 7 | AH13: =AB29+AB11+AB33+M33+M23 -> 48 | AI13: =AC29+AC11+AC33+N33+N23 -> 6
A14: vs. | P14: vs.
A15: =AE15 -> Matthias Cremona | C15: =IF(B15>B13,1,0) -> 0 | F15: =IF(E15>E13,1,0) -> 0 | I15: =IF(H15>H13,1,0) -> 0 | J15: =IF(B15="",0,1) -> 0 | K15: =IF(C15+F15=2,3,IF(C15+F15=1,1,0)) -> 0 | L15: =IF(K15=3,3,IF(I15+K15=2,2,IF(K15=1,1,0))) -> 0 | M15: =B15+E15 -> 0 | N15: =C15+F15+I15 -> 0 | P15: =AE17 -> Mickey Mitic | R15: =IF(Q15>Q13,1,0) -> 0 | U15: =IF(T15>T13,1,0) -> 0 | X15: =IF(W15>W13,1,0) -> 0 | Y15: =IF(Q15="",0,1) -> 0 | Z15: =IF(R15+U15=2,3,IF(R15+U15=1,1,0)) -> 0 | AA15: =IF(Z15=3,3,IF(X15+Z15=2,2,IF(Z15=1,1,0))) -> 0 | AB15: =Q15+T15 -> 0 | AC15: =R15+U15+X15 -> 0 | AE15: ='Players - Men'!B36 -> Matthias Cremona | AF15: =Y31+J37+J15+Y23+J29 -> 4 | AG15: =AA31+L37+L15+AA23+L29 -> 12 | AH15: =AB31+M37+M15+AB23+M29 -> 49 | AI15: =AC31+N37+N15+AC23+N29 -> 8
A17: =AE9 -> Clive Silvio Borg | C17: =IF(B17>B19,1,0) -> 0 | F17: =IF(E17>E19,1,0) -> 0 | I17: =IF(H17>H19,1,0) -> 0 | J17: =IF(B17="",0,1) -> 0 | K17: =IF(C17+F17=2,3,IF(C17+F17=1,1,0)) -> 0 | L17: =IF(K17=3,3,IF(I17+K17=2,2,IF(K17=1,1,0))) -> 0 | M17: =B17+E17 -> 0 | N17: =C17+F17+I17 -> 0 | P17: =AE17 -> Mickey Mitic | Q17: 3 | R17: =IF(Q17>Q19,1,0) -> 0 | T17: 1 | U17: =IF(T17>T19,1,0) -> 0 | X17: =IF(W17>W19,1,0) -> 0 | Y17: =IF(Q17="",0,1) -> 1 | Z17: =IF(R17+U17=2,3,IF(R17+U17=1,1,0)) -> 0 | AA17: =IF(Z17=3,3,IF(X17+Z17=2,2,IF(Z17=1,1,0))) -> 0 | AB17: =Q17+T17 -> 4 | AC17: =R17+U17+X17 -> 0 | AE17: ='Players - Men'!B37 -> Mickey Mitic | AF17: =Y17+J39+J27+Y15+J35 -> 3 | AG17: =AA17+L39+L27+AA15+L35 -> 1 | AH17: =AB17+M39+M27+AB15+M35 -> 21 | AI17: =AC17+N39+N27+AC15+N35 -> 1
A18: vs. | P18: vs.
A19: =AE19 -> Sean Cachia | C19: =IF(B19>B17,1,0) -> 0 | F19: =IF(E19>E17,1,0) -> 0 | I19: =IF(H19>H17,1,0) -> 0 | J19: =IF(B19="",0,1) -> 0 | K19: =IF(C19+F19=2,3,IF(C19+F19=1,1,0)) -> 0 | L19: =IF(K19=3,3,IF(I19+K19=2,2,IF(K19=1,1,0))) -> 0 | M19: =B19+E19 -> 0 | N19: =C19+F19+I19 -> 0 | P19: =AE19 -> Sean Cachia | Q19: 6 | R19: =IF(Q19>Q17,1,0) -> 1 | T19: 6 | U19: =IF(T19>T17,1,0) -> 1 | X19: =IF(W19>W17,1,0) -> 0 | Y19: =IF(Q19="",0,1) -> 1 | Z19: =IF(R19+U19=2,3,IF(R19+U19=1,1,0)) -> 3 | AA19: =IF(Z19=3,3,IF(X19+Z19=2,2,IF(Z19=1,1,0))) -> 3 | AB19: =Q19+T19 -> 12 | AC19: =R19+U19+X19 -> 2 | AE19: ='Players - Men'!B38 -> Sean Cachia | AF19: =Y19+Y27+Y35+J19+J31 -> 3 | AG19: =AA19+AA27+AA35+L19+L31 -> 6 | AH19: =AB19+AB27+AB35+M19+M31 -> 28 | AI19: =AC19+AC27+AC35+N19+N31 -> 4
A21: =AE11 -> Julian Galea Naudi | B21: 0 | C21: =IF(B21>B23,1,0) -> 0 | E21: 2 | F21: =IF(E21>E23,1,0) -> 0 | I21: =IF(H21>H23,1,0) -> 0 | J21: =IF(B21="",0,1) -> 1 | K21: =IF(C21+F21=2,3,IF(C21+F21=1,1,0)) -> 0 | L21: =IF(K21=3,3,IF(I21+K21=2,2,IF(K21=1,1,0))) -> 0 | M21: =B21+E21 -> 2 | N21: =C21+F21+I21 -> 0 | P21: =AE11 -> Julian Galea Naudi | Q21: 2 | R21: =IF(Q21>Q23,1,0) -> 0 | T21: 1 | U21: =IF(T21>T23,1,0) -> 0 | X21: =IF(W21>W23,1,0) -> 0 | Y21: =IF(Q21="",0,1) -> 1 | Z21: =IF(R21+U21=2,3,IF(R21+U21=1,1,0)) -> 0 | AA21: =IF(Z21=3,3,IF(X21+Z21=2,2,IF(Z21=1,1,0))) -> 0 | AB21: =Q21+T21 -> 3 | AC21: =R21+U21+X21 -> 0 | AE21: Division Winner
A22: vs. | P22: vs.
A23: =AE13 -> JP Sciberras | B23: 6 | C23: =IF(B23>B21,1,0) -> 1 | E23: 6 | F23: =IF(E23>E21,1,0) -> 1 | I23: =IF(H23>H21,1,0) -> 0 | J23: =IF(B23="",0,1) -> 1 | K23: =IF(C23+F23=2,3,IF(C23+F23=1,1,0)) -> 3 | L23: =IF(K23=3,3,IF(I23+K23=2,2,IF(K23=1,1,0))) -> 3 | M23: =B23+E23 -> 12 | N23: =C23+F23+I23 -> 2 | P23: =AE15 -> Matthias Cremona | Q23: 6 | R23: =IF(Q23>Q21,1,0) -> 1 | T23: 6 | U23: =IF(T23>T21,1,0) -> 1 | X23: =IF(W23>W21,1,0) -> 0 | Y23: =IF(Q23="",0,1) -> 1 | Z23: =IF(R23+U23=2,3,IF(R23+U23=1,1,0)) -> 3 | AA23: =IF(Z23=3,3,IF(X23+Z23=2,2,IF(Z23=1,1,0))) -> 3 | AB23: =Q23+T23 -> 12 | AC23: =R23+U23+X23 -> 2
A25: =AE11 -> Julian Galea Naudi | C25: =IF(B25>B27,1,0) -> 0 | F25: =IF(E25>E27,1,0) -> 0 | I25: =IF(H25>H27,1,0) -> 0 | J25: =IF(B25="",0,1) -> 0 | K25: =IF(C25+F25=2,3,IF(C25+F25=1,1,0)) -> 0 | L25: =IF(K25=3,3,IF(I25+K25=2,2,IF(K25=1,1,0))) -> 0 | M25: =B25+E25 -> 0 | N25: =C25+F25+I25 -> 0 | P25: =AE11 -> Julian Galea Naudi | R25: =IF(Q25>Q27,1,0) -> 0 | U25: =IF(T25>T27,1,0) -> 0 | X25: =IF(W25>W27,1,0) -> 0 | Y25: =IF(Q25="",0,1) -> 0 | Z25: =IF(R25+U25=2,3,IF(R25+U25=1,1,0)) -> 0 | AA25: =IF(Z25=3,3,IF(X25+Z25=2,2,IF(Z25=1,1,0))) -> 0 | AB25: =Q25+T25 -> 0 | AC25: =R25+U25+X25 -> 0
A26: vs. | P26: vs.
A27: =AE17 -> Mickey Mitic | C27: =IF(B27>B25,1,0) -> 0 | F27: =IF(E27>E25,1,0) -> 0 | I27: =IF(H27>H25,1,0) -> 0 | J27: =IF(B27="",0,1) -> 0 | K27: =IF(C27+F27=2,3,IF(C27+F27=1,1,0)) -> 0 | L27: =IF(K27=3,3,IF(I27+K27=2,2,IF(K27=1,1,0))) -> 0 | M27: =B27+E27 -> 0 | N27: =C27+F27+I27 -> 0 | P27: =AE19 -> Sean Cachia | R27: =IF(Q27>Q25,1,0) -> 0 | U27: =IF(T27>T25,1,0) -> 0 | X27: =IF(W27>W25,1,0) -> 0 | Y27: =IF(Q27="",0,1) -> 0 | Z27: =IF(R27+U27=2,3,IF(R27+U27=1,1,0)) -> 0 | AA27: =IF(Z27=3,3,IF(X27+Z27=2,2,IF(Z27=1,1,0))) -> 0 | AB27: =Q27+T27 -> 0 | AC27: =R27+U27+X27 -> 0
A29: =AE15 -> Matthias Cremona | B29: 6 | C29: =IF(B29>B31,1,0) -> 1 | E29: 6 | F29: =IF(E29>E31,1,0) -> 1 | I29: =IF(H29>H31,1,0) -> 0 | J29: =IF(B29="",0,1) -> 1 | K29: =IF(C29+F29=2,3,IF(C29+F29=1,1,0)) -> 3 | L29: =IF(K29=3,3,IF(I29+K29=2,2,IF(K29=1,1,0))) -> 3 | M29: =B29+E29 -> 12 | N29: =C29+F29+I29 -> 2 | P29: =AE13 -> JP Sciberras | Q29: 2 | R29: =IF(Q29>Q31,1,0) -> 0 | T29: 5 | U29: =IF(T29>T31,1,0) -> 0 | X29: =IF(W29>W31,1,0) -> 0 | Y29: =IF(Q29="",0,1) -> 1 | Z29: =IF(R29+U29=2,3,IF(R29+U29=1,1,0)) -> 0 | AA29: =IF(Z29=3,3,IF(X29+Z29=2,2,IF(Z29=1,1,0))) -> 0 | AB29: =Q29+T29 -> 7 | AC29: =R29+U29+X29 -> 0
A30: vs. | P30: vs.
