Workbook

Sheet Team Selection
A1: VITTORIOSA LAWN TENNIS CLUB
A2: SAN MICHEL TEAM TOURNAMENT - 2025
B4: TEAM A | C4: TEAM B | D4: TEAM C | E4: TEAM D | F4: TEAM E | G4: TEAM F
A5: CAPTAIN | B5: Roberto Murdocco | C5: Kelsey Gauci | D5: Gabriel Pace | E5: Lucienne Meli | F5: Juan Sammut | G5: Francesca Sciortino
A6: MEN
A7: A1 | B7: Clayton Zammit Cesare | C7: Melchior Farrugia | D7: Matthew Mifsud | E7: Matthew Borg | F7: Duncan D'Alessandro | G7: Adrian Chetcuti
A8: A2 | B8: Marco Mercieca | C8: Manuel Bonello | D8: Nikolai Belli | E8: Trevor Rutter | F8: Clyde Grech | G8: Jean Attard
A9: A3 | B9: David Mifsud | C9: Keith Micallef | D9: Gabriel Pace | E9: Fotios Evangelou | F9: Andrew Pule' | G9: Eric Roca
A11: B1 | B11: Luigi Porto | C11: Kurt Cassar | D11: Ivan Cachia | E11: David Schembri | F11: JP Holland | G11: Kristen Cachia
A12: B2 | B12: Roberto Murdocco | C12: Clint Agius | D12: Jonathan Martinelli | E12: Jonathan Vella | F12: Ivan Cassar | G12: Jayboy Lastimosa
A13: B3 | B13: Emman Xuereb | C13: Kevin Formosa | D13: Gene Zammit | E13: Cyril Lastimosa | F13: Kyle Magro | G13: Willem Steenkamer
A15: C1 | B15: Manuel Mifsud | C15: Matthias Sciriha | D15: Etienne Formosa Carabez | E15: Artiom Kirichenko | F15: Jean Paul Vella | G15: Julian Esposito
A16: C2 | B16: James Brincat | C16: Aaron Micallef Piccione | D16: Steve Gambin | E16: Charles Sacco | F16: Juan Debono | G16: Matthew Schembri
A17: C3 | B17: Kenneth Farrugia | C17: David Camilleri | D17: Darrell Pace | E17: Victor Rutter | F17: Juan Sammut | G17: Maurice Borg
A19: D1 | B19: Simone Re | C19: Donald Deguzman | D19: Conrad Treeby Ward | E19: Antoine Bugeja | F19: Kenneth Caruana | G19: Dunstan Vella
A20: D2 | B20: Joseph Randich | C20: Matthew Micallef | D20: Cory Greenland | E20: Glenn Micallef | F20: Robert Attard | G20: Jason Lee Evans
A21: D3 | B21: Arthur Napier | C21: JP Sciberras | D21: Mario Abdilla | E21: Twanny Pule' | F21: Kevin Sciberras | G21: Chris Vella
A22: LADIES
A23: A1 | B23: Natalya Abela | C23: Alexia Spiteri Willets | D23: Martina Cuschieri | E23: AnnMarie Mangion | F23: Leanne Vassallo | G23: Renette Magro
A24: A2 | B24: Diane Fenech | C24: Kirsty Mercieca | D24: Becky Hayes | E24: Pierina Holmin | F24: Elaine Grech | G24: Lara Pule'
A25: A3 | B25: Annabelle Abela | C25: Rebecca Pace | D25: Kaya Sammut | E25: Lucienne Meli | F25: Alison Muscat | G25: Olivia Belli
A27: B1 | B27: Anabel Borg | C27: Anthea Gauci | D27: Julie Spiteri | E27: Yanika Pace | F27: Amanda Falzon | G27: Francesca Sciortino
A28: B2 | B28: Rowena Caruana | C28: Marcette Sciriha | D28: Kristina Briffa | E28: Dorianne Buhagiar | F28: Romina Gauci | G28: Stephanie Farrugia
A29: B3 | B29: Silvana Portelli | C29: Brenda Baldacchino | D29: Deborah Farrugia | E29: Nancy Wong | F29: Ann-Marie Attard | G29: Mariska Steenkamer
A31: C1 | B31: Angele Pule' | C31: Tanya Cassar | D31: Maria Angela Gambin | E31: Ruth Micallef | F31: Maria Ellul | G31: Jin Attard
A32: C2 | B32: Lonia Carabott | C32: Jodie Stivala | D32: Janice Galea | E32: Ceridwen Scerri | F32: Christine Seychell | G32: Jennifer Roca
A33: C3 | B33: Mary Borg | C33: Leanne Sammut | D33: Christine Scerri | E33: Karolina Papiernik | F33: Chirstabelle Chetcuti | G33: Daphne Vella

Sheet Encounters Played
B1: VITTORIOSA LAWN TENNIS CLUB
B2: SAN MICHEL TEAM TOURNAMENT - 2025
A5: A | B5: Roberto Murdocco | C5: Day 1 | D5: Day 2 | E5: Day 3 | F5: Day 4 | G5: Day 5 | H5: Day 6 | I5: Day 7 | J5: Day 8 | K5: Day 9 | L5: Day 10 | M5: TOTAL
A6: A1 | B6: Clayton Zammit Cesare | C6: 1 | D6: 1 | E6: 1 | G6: 1 | H6: 1 | J6: 1 | K6: 1 | L6: 1 | M6: =SUM(C6:L6) -> 8
A7: A2 | B7: Marco Mercieca | C7: 1 | E7: 1 | F7: 1 | G7: 1 | I7: 1 | L7: 1 | M7: =SUM(C7:L7) -> 6
A8: A3 | B8: David Mifsud | D8: 1 | F8: 1 | H8: 1 | I8: 1 | J8: 1 | K8: 1 | M8: =SUM(C8:L8) -> 6
A9: B1 | B9: Luigi Porto | C9: 1 | D9: 1 | F9: 1 | G9: 1 | H9: 1 | J9: 1 | L9: 1 | M9: =SUM(C9:L9) -> 7
A10: B2 | B10: Roberto Murdocco | C10: 1 | E10: 1 | G10: 1 | I10: 1 | J10: 1 | K10: 1 | L10: 1 | M10: =SUM(C10:L10) -> 7
A11: B3 | B11: Emman Xuereb | D11: 1 | E11: 1 | F11: 1 | H11: 1 | I11: 1 | K11: 1 | M11: =SUM(C11:L11) -> 6
A12: C1 | B12: Manuel Mifsud | C12: 1 | E12: 1 | F12: 1 | G12: 1 | H12: 1 | J12: 1 | L12: 1 | M12: =SUM(C12:L12) -> 7
A13: C2 | B13: James Brincat | C13: 1 | D13: 1 | E13: 1 | F13: 1 | I13: 1 | K13: 1 | L13: 1 | M13: =SUM(C13:L13) -> 7
A14: C3 | B14: Kenneth Farrugia | D14: 1 | G14: 1 | H14: 1 | I14: 1 | J14: 1 | K14: 1 | M14: =SUM(C14:L14) -> 6
A15: D1 | B15: Simone Re | C15: 1 | D15: 1 | E15: 1 | F15: 1 | H15: 1 | J15: 1 | K15: 1 | L15: 1 | M15: =SUM(C15:L15) -> 8
A16: D2 | B16: Joseph Randich | C16: 1 | E16: 1 | F16: 1 | G16: 1 | I16: 1 | L16: 1 | M16: =SUM(C16:L16) -> 6
A17: D3 | B17: Arthur Napier | D17: 1 | G17: 1 | H17: 1 | I17: 1 | J17: 1 | K17: 1 | M17: =SUM(C17:L17) -> 6
A18: A1 | B18: Natalya Abela | C18: 1 | D18: 1 | E18: 1 | G18: 1 | H18: 1 | I18: 1 | J18: 1 | K18: 1 | M18: =SUM(C18:L18) -> 8
A19: A2 | B19: Diane Fenech | C19: 1 | F19: 1 | G19: 1 | I19: 1 | J19: 1 | L19: 1 | M19: =SUM(C19:L19) -> 6
A20: A3 | B20: Annabelle Abela | D20: 1 | E20: 1 | F20: 1 | H20: 1 | K20: 1 | L20: 1 | M20: =SUM(C20:L20) -> 6
A21: B1 | B21: Anabel Borg | C21: 1 | E21: 1 | G21: 1 | H21: 1 | I21: 1 | J21: 1 | K21: 1 | M21: =SUM(C21:L21) -> 7
A22: B2 | B22: Rowena Caruana | D22: 1 | E22: 1 | F22: 1 | G22: 1 | I22: 1 | K22: 1 | L22: 1 | M22: =SUM(C22:L22) -> 7
A23: B3 | B23: Silvana Portelli | C23: 1 | D23: 1 | F23: 1 | H23: 1 | J23: 1 | L23: 1 | M23: =SUM(C23:L23) -> 6
A24: C1 | B24: Angele Pule' | C24: 1 | D24: 1 | F24: 1 | G24: 1 | H24: 1 | I24: 1 | J24: 1 | L24: 1 | M24: =SUM(C24:L24) -> 8
A25: C2 | B25: Lonia Carabott | C25: 1 | E25: 1 | G25: 1 | H25: 1 | K25: 1 | L25: 1 | M25: =SUM(C25:L25) -> 6
A26: C3 | B26: Mary Borg | D26: 1 | E26: 1 | F26: 1 | I26: 1 | J26: 1 | K26: 1 | M26: =SUM(C26:L26) -> 6
A28: B | B28: Kelsey Gauci | C28: Day 1 | D28: Day 2 | E28: Day 3 | F28: Day 4 | G28: Day 5 | H28: Day 6 | I28: Day 7 | J28: Day 8 | K28: Day 9 | L28: Day 10 | M28: TOTAL
A29: A1 | B29: Melchior Farrugia | C29: 1 | D29: 1 | E29: 1 | G29: 1 | H29: 1 | I29: 1 | L29: 1 | M29: =SUM(C29:L29) -> 7
A30: A2 | B30: Manuel Bonello | C30: 1 | E30: 1 | F30: 1 | G30: 1 | H30: 1 | J30: 1 | K30: 1 | M30: =SUM(C30:L30) -> 7
A31: A3 | B31: Keith Micallef | D31: 1 | F31: 1 | I31: 1 | J31: 1 | K31: 1 | L31: 1 | M31: =SUM(C31:L31) -> 6
A32: B1 | B32: Kurt Cassar | C32: 1 | D32: 1 | E32: 1 | G32: 1 | H32: 1 | J32: 1 | L32: 1 | M32: =SUM(C32:L32) -> 7
A33: B2 | B33: Clint Agius | C33: 1 | D33: 1 | E33: 1 | F33: 1 | G33: 1 | I33: 1 | K33: 1 | L33: 1 | M33: =SUM(C33:L33) -> 8
A34: B3 | B34: Kevin Formosa | F34: 1 | H34: 1 | I34: 1 | J34: 1 | K34: 1 | M34: =SUM(C34:L34) -> 5
A35: C1 | B35: Matthias Sciriha | C35: 1 | D35: 1 | E35: 1 | F35: 1 | H35: 1 | I35: 1 | J35: 1 | L35: 1 | M35: =SUM(C35:L35) -> 8
A36: C2 | B36: Aaron Micallef Piccione | D36: 1 | G36: 1 | H36: 1 | I36: 1 | J36: 1 | K36: 1 | M36: =SUM(C36:L36) -> 6
A37: C3 | B37: David Camilleri | C37: 1 | E37: 1 | F37: 1 | G37: 1 | K37: 1 | L37: 1 | M37: =SUM(C37:L37) -> 6
A38: D1 | B38: Donald Deguzman | C38: 1 | E38: 1 | G38: 1 | H38: 1 | J38: 1 | L38: 1 | M38: =SUM(C38:L38) -> 6
A39: D2 | B39: Matthew Micallef | C39: 1 | D39: 1 | F39: 1 | G39: 1 | I39: 1 | K39: 1 | L39: 1 | M39: =SUM(C39:L39) -> 7
A40: D3 | B40: JP Sciberras | D40: 1 | E40: 1 | F40: 1 | H40: 1 | I40: 1 | J40: 1 | K40: 1 | M40: =SUM(C40:L40) -> 7
A41: A1 | B41: Alexia Spiteri Willets | C41: 1 | D41: 1 | E41: 1 | G41: 1 | J41: 1 | L41: 1 | M41: =SUM(C41:L41) -> 6
A42: A2 | B42: Kirsty Mercieca | C42: 1 | E42: 1 | F42: 1 | H42: 1 | I42: 1 | K42: 1 | M42: =SUM(C42:L42) -> 6
A43: A3 | B43: Rebecca Pace | D43: 1 | F43: 1 | G43: 1 | H43: 1 | I43: 1 | J43: 1 | K43: 1 | L43: 1 | M43: =SUM(C43:L43) -> 8
...

Sheet Standings
B1: VITTORIOSA LAWN TENNIS CLUB
B2: SAN MICHEL TEAM TOURNAMENT - 2025
C7: ROUND 1
D9: Day 1 | F9: Total Day 1 | I9: Day 2 | K9: Total Day 2 | N9: Day 3 | P9: Total Day 3 | S9: Day 4 | U9: Total Day 4 | X9: Day 5 | Z9: Total Day 5 | AC9: Total Round 1
D10: G | E10: S | F10: G | G10: S | I10: G | J10: S | K10: G | L10: S | N10: G | O10: S | P10: G | Q10: S | S10: G | T10: S | U10: G | V10: S | X10: G | Y10: S | Z10: G | AA10: S | AC10: G | AD10: S
B12: TEAM A: Roberto Murdocco | C12: Fri | D12: ='Day 1'!J25 -> 37 | E12: ='Day 1'!L25 -> 5 | F12: =D12+D13 -> 67 | G12: =SUM(E12+E13) -> 8 | I12: ='Day 2 '!J58 -> 31 | J12: ='Day 2 '!L58 -> 3 | K12: =I12+I13 -> 62 | L12: =J12+J13 -> 7 | N12: ='Day 3'!J95 -> 23 | O12: ='Day 3'!L95 -> 3 | P12: =N12+N13 -> 64 | Q12: =O12+O13 -> 8 | S12: ='Day 4'!J95 -> 36 | T12: ='Day 4'!L95 -> 5 | U12: =S12+S13 -> 75 | V12: =T12+T13 -> 10 | X12: ='Day 5'!J25 -> 32 | Y12: ='Day 5'!L25 -> 2 | Z12: =X12+X13 -> 66 | AA12: =Y12+Y13 -> 6 | AC12: =D12+D13+I12+I13+N12+N13+S12+S13+X12+X13 -> 334 | AD12: =SUM(G12+G13+L12+L13+Q12+Q13+V12+V13+AA12+AA13) -> 39
C13: Sat | D13: ='Day 1'!J38 -> 30 | E13: ='Day 1'!L38 -> 3 | I13: ='Day 2 '!J71 -> 31 | J13: ='Day 2 '!L71 -> 4 | N13: ='Day 3'!J110 -> 41 | O13: ='Day 3'!L110 -> 5 | S13: ='Day 4'!J110 -> 39 | T13: ='Day 4'!L110 -> 5 | X13: ='Day 5'!J40 -> 34 | Y13: ='Day 5'!L40 -> 4
B15: TEAM B: Kelsey Gauci | C15: Fri | D15: ='Day 1'!J91 -> 40 | E15: ='Day 1'!L91 -> 4 | F15: =SUM(D15+D16) -> 70 | G15: =SUM(E15:E16) -> 8 | I15: ='Day 2 '!J25 -> 21 | J15: ='Day 2 '!L25 -> 2 | K15: =SUM(I15+I16) -> 58 | L15: =SUM(J15+J16) -> 8 | N15: ='Day 3'!K60 -> 37 | O15: ='Day 3'!M60 -> 4 | P15: =SUM(N15+N16) -> 64 | Q15: =SUM(O15+O16) -> 7 | S15: ='Day 4'!K95 -> 26 | T15: ='Day 4'!M95 -> 1 | U15: =SUM(S15+S16) -> 60 | V15: =T15+T16 -> 4 | X15: ='Day 5'!J60 -> 18 | Y15: ='Day 5'!L60 -> 1 | Z15: =SUM(X15+X16) -> 44 | AA15: =SUM(Y15+Y16) -> 3 | AC15: =D15+D16+I15+I16+N15+N16+S15+S16+X15+X16 -> 296 | AD15: =SUM(G15+G16+L15+L16+Q15+Q16+V15+V16+AA15+AA16) -> 30
C16: Sat | D16: ='Day 1'!J104 -> 30 | E16: ='Day 1'!L104 -> 4 | I16: ='Day 2 '!J38 -> 37 | J16: ='Day 2 '!L38 -> 6 | N16: ='Day 3'!K75 -> 27 | O16: ='Day 3'!M75 -> 3 | S16: ='Day 4'!K110 -> 34 | T16: ='Day 4'!M110 -> 3 | X16: ='Day 5'!J75 -> 26 | Y16: ='Day 5'!L75 -> 2
B18: TEAM C: Gabriel Pace | C18: Fri | D18: ='Day 1'!K25 -> 26 | E18: ='Day 1'!M25 -> 3 | F18: =D18+D19 -> 50 | G18: =E18+E19 -> 6 | I18: ='Day 2 '!J91 -> 32 | J18: ='Day 2 '!L91 -> 3 | K18: =I18+I19 -> 52 | L18: =J18+J19 -> 5 | N18: ='Day 3'!J25 -> 15 | O18: ='Day 3'!L25 -> 0 | P18: =N18+N19 -> 51 | Q18: =O18+O19 -> 3 | S18: ='Day 4'!J60 -> 47 | T18: ='Day 4'!L60 -> 6 | U18: =S18+S19 -> 76 | V18: =T18+T19 -> 10 | X18: ='Day 5'!K60 -> 45 | Y18: ='Day 5'!M60 -> 7 | Z18: =X18+X19 -> 76 | AA18: =SUM(Y18+Y19) -> 11 | AC18: =D18+D19+I18+I19+N18+N19+S18+S19+X18+X19 -> 305 | AD18: =SUM(E18+E19+J18+J19+O18+O19+T18+T19+Y18+Y19) -> 35
C19: Sat | D19: ='Day 1'!K38 -> 24 | E19: ='Day 1'!M38 -> 3 | I19: ='Day 2 '!J104 -> 20 | J19: ='Day 2 '!L104 -> 2 | N19: ='Day 3'!J40 -> 36 | O19: ='Day 3'!L40 -> 3 | S19: ='Day 4'!J75 -> 29 | T19: ='Day 4'!L75 -> 4 | X19: ='Day 5'!K75 -> 31 | Y19: ='Day 5'!M75 -> 4
B21: TEAM D: Lucienne Meli | C21: Fri | D21: ='Day 1'!J58 -> 41 | E21: ='Day 1'!L58 -> 5 | F21: =D21+D22 -> 77 | G21: =SUM(E21+E22) -> 10 | I21: ='Day 2 '!K91 -> 45 | J21: ='Day 2 '!M91 -> 5 | K21: =I21+I22 -> 73 | L21: =J21+J22 -> 9 | N21: ='Day 3'!J60 -> 33 | O21: ='Day 3'!L60 -> 4 | P21: =N21+N22 -> 63 | Q21: =O21+O22 -> 7 | S21: ='Day 4'!J25 -> 29 | T21: ='Day 4'!L25 -> 3 | U21: =S21+S22 -> 63 | V21: =T21+T22 -> 6 | X21: ='Day 5'!K25 -> 45 | Y21: ='Day 5'!M25 -> 6 | Z21: =X21+X22 -> 73 | AA21: =SUM(Y21+Y22) -> 8 | AC21: =D21+D22+I21+I22+N21+N22+S21+S22+X21+X22 -> 349 | AD21: =SUM(E21+E22+J21+J22+O21+O22+T21+T22+Y21+Y22) -> 40
C22: Sat | D22: ='Day 1'!J71 -> 36 | E22: ='Day 1'!L71 -> 5 | I22: ='Day 2 '!K104 -> 28 | J22: ='Day 2 '!M104 -> 4 | N22: ='Day 3'!J75 -> 30 | O22: ='Day 3'!L75 -> 3 | S22: ='Day 4'!J40 -> 34 | T22: ='Day 4'!L40 -> 3 | X22: ='Day 5'!K40 -> 28 | Y22: ='Day 5'!M40 -> 2
B24: TEAM E: Juan Sammut | C24: Fri | D24: ='Day 1'!K58 -> 36 | E24: ='Day 1'!M58 -> 3 | F24: =D24+D25 -> 64 | G24: =E24+E25 -> 4 | I24: ='Day 2 '!K25 -> 44 | J24: ='Day 2 '!M25 -> 6 | K24: =I24+I25 -> 68 | L24: =J24+J25 -> 6 | N24: ='Day 3'!K95 -> 26 | O24: ='Day 3'!M95 -> 3 | P24: =N24+N25 -> 57 | Q24: =O24+O25 -> 6 | S24: ='Day 4'!K60 -> 41 | T24: ='Day 4'!M60 -> 2 | U24: =S24+S25 -> 61 | V24: =T24+T25 -> 4 | X24: ='Day 5'!J95 -> 22 | Y24: ='Day 5'!L95 -> 2 | Z24: =X24+X25 -> 48 | AA24: =Y24+Y25 -> 3 | AC24: =D24+D25+I24+I25+N24+N25+S24+S25+X24+X25 -> 298 | AD24: =E24+E25+J24+J25+O24+O25+T24+T25+Y24+Y25 -> 23
C25: Sat | D25: ='Day 1'!K71 -> 28 | E25: ='Day 1'!M71 -> 1 | I25: ='Day 2 '!K38 -> 24 | J25: ='Day 2 '!M38 -> 0 | N25: ='Day 3'!K110 -> 31 | O25: ='Day 3'!M110 -> 3 | S25: ='Day 4'!K75 -> 20 | T25: ='Day 4'!M75 -> 2 | X25: ='Day 5'!J110 -> 26 | Y25: ='Day 5'!L110 -> 1
B27: TEAM F: Francesca Sciortino | C27: Fri | D27: ='Day 1'!K91 -> 43 | E27: ='Day 1'!M91 -> 4 | F27: =D27+D28 -> 68 | G27: =E27+E28 -> 6 | I27: ='Day 2 '!K58 -> 45 | J27: ='Day 2 '!M58 -> 5 | K27: =I27+I28 -> 71 | L27: =J27+J28 -> 7 | N27: ='Day 3'!K25 -> 37 | O27: ='Day 3'!M25 -> 6 | P27: =N27+N28 -> 77 | Q27: =O27+O28 -> 11 | S27: ='Day 4'!K25 -> 31 | T27: ='Day 4'!M25 -> 3 | U27: =S27+S28 -> 74 | V27: =SUM(T27+T28) -> 8 | X27: ='Day 5'!K95 -> 30 | Y27: ='Day 5'!M95 -> 4 | Z27: =X27+X28 -> 75 | AA27: =Y27+Y28 -> 11 | AC27: =D27+D28+I27+I28+N27+N28+S27+S28+X27+X28 -> 365 | AD27: =E27+E28+J27+J28+O27+O28+T27+T28+Y27+Y28 -> 43
C28: Sat | D28: ='Day 1'!K104 -> 25 | E28: ='Day 1'!M104 -> 2 | I28: ='Day 2 '!K71 -> 26 | J28: ='Day 2 '!M71 -> 2 | N28: ='Day 3'!K40 -> 40 | O28: ='Day 3'!M40 -> 5 | S28: ='Day 4'!K40 -> 43 | T28: ='Day 4'!M40 -> 5 | X28: ='Day 5'!K110 -> 45 | Y28: ='Day 5'!M110 -> 7
C31: ROUND 2
D33: Day 6 | F33: Total Day 6 | I33: Day 7 | K33: Total Day 7 | N33: Day 8 | P33: Total Day 8 | S33: Day 9 | U33: Total Day 9 | X33: Day 10 | Z33: Total Day 10 | AC33: Total Rounds 1 & 2
D34: G | E34: S | F34: G | G34: S | I34: G | J34: S | K34: G | L34: S | N34: G | O34: S | P34: G | Q34: S | S34: G | T34: S | U34: G | V34: S | X34: G | Y34: S | Z34: G | AA34: S | AC34: G | AD34: S
B36: TEAM A: Roberto Murdocco | C36: Fri | D36: ='Day 6'!J25 -> 36 | E36: ='Day 6'!L25 -> 4 | F36: =SUM(D36+D37) -> 67 | G36: =SUM(E36+E37) -> 7 | I36: ='Day 7'!J60 -> 35 | J36: ='Day 7'!L60 -> 4 | K36: =I36+I37 -> 49 | L36: =J36+J37 -> 4 | N36: ='Day 8'!J95 -> 36 | O36: ='Day 8'!L95 -> 5 | P36: =N36+N37 -> 73 | Q36: =O36+O37 -> 8 | S36: =SUM('Day 9'!J95) -> 47 | T36: =SUM('Day 9'!L95) -> 7 | U36: =S36+S37 -> 75 | V36: =T36+T37 -> 11 | X36: =SUM('Day 10'!J25) -> 33 | Y36: =SUM('Day 10'!L25) -> 3 | Z36: =X36+X37 -> 57 | AA36: =Y36+Y37 -> 6 | AC36: =SUM(AC12+AC13+F36+F37+K36+K37+P36+P37+U36+U37+Z36+Z37) -> 655 | AD36: =SUM(AD12+G36+L36+Q36+V36+AA36) -> 75
C37: Sat | D37: ='Day 6'!J40 -> 31 | E37: ='Day 6'!L40 -> 3 | I37: ='Day 7'!J75 -> 14 | J37: ='Day 7'!L75 -> 0 | N37: ='Day 8'!J110 -> 37 | O37: ='Day 8'!L110 -> 3 | S37: =SUM('Day 9'!J110) -> 28 | T37: =SUM('Day 9'!L110) -> 4 | X37: =SUM('Day 10'!J40) -> 24 | Y37: =SUM('Day 10'!L40) -> 3
B39: TEAM B: Kelsey Gauci | C39: Fri | D39: ='Day 6'!J95 -> 25 | E39: ='Day 6'!L95 -> 2 | F39: =SUM(D39+D40) -> 66 | G39: =SUM(E39+E40) -> 7 | I39: ='Day 7'!J25 -> 29 | J39: ='Day 7'!L25 -> 4 | K39: =I39+I40 -> 53 | L39: =J39+J40 -> 6 | N39: ='Day 8'!K60 -> 18 | O39: ='Day 8'!M60 -> 2 | P39: =N39+N40 -> 43 | Q39: =O39+O40 -> 4 | S39: =SUM('Day 9'!K95) -> 29 | T39: =SUM('Day 9'!M95) -> 1 | U39: =S39+S40 -> 53 | V39: =T39+T40 -> 3 | X39: =SUM('Day 10'!J60) -> 16 | Y39: =SUM('Day 10'!L60) -> 1 | Z39: =X39+X40 -> 33 | AA39: =Y39+Y40 -> 1 | AC39: =SUM(AC15+AC16+F39+F40+K39+K40+P39+P40+U39+U40+Z39+Z40) -> 544 | AD39: =SUM(AD15+G39+L39+Q39+V39+AA39) -> 51
C40: Sat | D40: ='Day 6'!J110 -> 41 | E40: ='Day 6'!L110 -> 5 | I40: ='Day 7'!J40 -> 24 | J40: ='Day 7'!L40 -> 2 | N40: ='Day 8'!K75 -> 25 | O40: ='Day 8'!M75 -> 2 | S40: =SUM('Day 9'!K110) -> 24 | T40: =SUM('Day 9'!M110) -> 2 | X40: =SUM('Day 10'!J75) -> 17 | Y40: =SUM('Day 10'!L75) -> 0
B42: TEAM C: Gabriel Pace | C42: Fri | D42: ='Day 6'!K25 -> 34 | E42: ='Day 6'!M25 -> 4 | F42: =SUM(D42+D43) -> 61 | G42: =SUM(E42+E43) -> 7 | I42: ='Day 7'!J95 -> 31 | J42: ='Day 7'!L95 -> 4 | K42: =I42+I43 -> 64 | L42: =J42+J43 -> 7 | N42: ='Day 8'!J25 -> 12 | O42: ='Day 8'!L25 -> 0 | P42: =N42+N43 -> 58 | Q42: =O42+O43 -> 5 | S42: =SUM('Day 9'!J60) -> 33 | T42: =SUM('Day 9'!L60) -> 4 | U42: =S42+S43 -> 64 | V42: =T42+T43 -> 8 | X42: =SUM('Day 10'!K60) -> 32 | Y42: =SUM('Day 10'!M60) -> 5 | Z42: =X42+X43 -> 81 | AA42: =Y42+Y43 -> 13 | AC42: =SUM(AC18+AC19+F42+F43+K42+K43+P42+P43+U42+U43+Z42+Z43) -> 633 | AD42: =SUM(AD18+G42+L42+Q42+V42+AA42) -> 75
C43: Sat | D43: ='Day 6'!K40 -> 27 | E43: ='Day 6'!M40 -> 3 | I43: ='Day 7'!J110 -> 33 | J43: ='Day 7'!L110 -> 3 | N43: ='Day 8'!J40 -> 46 | O43: ='Day 8'!L40 -> 5 | S43: =SUM('Day 9'!J75) -> 31 | T43: =SUM('Day 9'!L75) -> 4 | X43: =SUM('Day 10'!K75) -> 49 | Y43: =SUM('Day 10'!M75) -> 8
B45: TEAM D: Lucienne Meli | C45: Fri | D45: ='Day 6'!J60 -> 32 | E45: ='Day 6'!L60 -> 4 | F45: =SUM(D45+D46) -> 72 | G45: =SUM(E45+E46) -> 9 | I45: ='Day 7'!K95 -> 28 | J45: ='Day 7'!M95 -> 2 | K45: =I45+I46 -> 69 | L45: =J45+J46 -> 7 | N45: ='Day 8'!J60 -> 29 | O45: ='Day 8'!L60 -> 4 | P45: =N45+N46 -> 71 | Q45: =O45+O46 -> 10 | S45: =SUM('Day 9'!J25) -> 33 | T45: =SUM('Day 9'!L25) -> 4 | U45: =S45+S46 -> 54 | V45: =T45+T46 -> 6 | X45: =SUM('Day 10'!K25) -> 40 | Y45: =SUM('Day 10'!M25) -> 5 | Z45: =X45+X46 -> 71 | AA45: =Y45+Y46 -> 8 | AC45: =SUM(AC21+AC22+F45+F46+K45+K46+P45+P46+U45+U46+Z45+Z46) -> 686 | AD45: =SUM(AD21+G45+L45+Q45+V45+AA45) -> 80
C46: Sat | D46: ='Day 6'!J75 -> 40 | E46: ='Day 6'!L75 -> 5 | I46: ='Day 7'!K110 -> 41 | J46: ='Day 7'!M110 -> 5 | N46: ='Day 8'!J75 -> 42 | O46: ='Day 8'!L75 -> 6 | S46: =SUM('Day 9'!J40) -> 21 | T46: =SUM('Day 9'!L40) -> 2 | X46: =SUM('Day 10'!K40) -> 31 | Y46: =SUM('Day 10'!M40) -> 3
B48: TEAM E: Juan Sammut | C48: Fri | D48: ='Day 6'!K60 -> 27 | E48: ='Day 6'!M60 -> 2 | F48: =SUM(D48+D49) -> 59 | G48: =SUM(E48+E49) -> 5 | I48: ='Day 7'!K25 -> 25 | J48: ='Day 7'!M25 -> 2 | K48: =I48+I49 -> 64 | L48: =J48+J49 -> 8 | N48: ='Day 8'!K95 -> 24 | O48: ='Day 8'!M95 -> 1 | P48: =N48+N49 -> 64 | Q48: =O48+O49 -> 6 | S48: =SUM('Day 9'!K60) -> 36 | T48: =SUM('Day 9'!M60) -> 4 | U48: =S48+S49 -> 57 | V48: =T48+T49 -> 6 | X48: =SUM('Day 10'!J95) -> 28 | Y48: =SUM('Day 10'!L95) -> 3 | Z48: =X48+X49 -> 51 | AA48: =Y48+Y49 -> 5 | AC48: =SUM(AC24+AC25+F48+F49+K48+K49+P48+P49+U48+U49+Z48+Z49) -> 593 | AD48: =SUM(AD24+G48+L48+Q48+V48+AA48) -> 53
C49: Sat | D49: ='Day 6'!K75 -> 32 | E49: ='Day 6'!M75 -> 3 | I49: ='Day 7'!K40 -> 39 | J49: ='Day 7'!M40 -> 6 | N49: ='Day 8'!K110 -> 40 | O49: ='Day 8'!M110 -> 5 | S49: =SUM('Day 9'!K75) -> 21 | T49: =SUM('Day 9'!M75) -> 2 | X49: =SUM('Day 10'!J110) -> 23 | Y49: =SUM('Day 10'!L110) -> 2
B51: TEAM F: Francesca Sciortino | C51: Fri | D51: ='Day 6'!K95 -> 29 | E51: ='Day 6'!M95 -> 4 | F51: =SUM(D51+D52) -> 67 | G51: =SUM(E51+E52) -> 7 | I51: ='Day 7'!K60 -> 33 | J51: ='Day 7'!M60 -> 4 | K51: =I51+I52 -> 69 | L51: =J51+J52 -> 10 | N51: ='Day 8'!K25 -> 36 | O51: ='Day 8'!M25 -> 6 | P51: =N51+N52 -> 72 | Q51: =O51+O52 -> 9 | S51: =SUM('Day 9'!K25) -> 36 | T51: =SUM('Day 9'!M25) -> 4 | U51: =S51+S52 -> 70 | V51: =T51+T52 -> 8 | X51: =SUM('Day 10'!K95) -> 39 | Y51: =SUM('Day 10'!M95) -> 5 | Z51: =X51+X52 -> 74 | AA51: =Y51+Y52 -> 9 | AC51: =SUM(AC27+AC28+F51+F52+K51+K52+P51+P52+U51+U52+Z51+Z52) -> 717 | AD51: =SUM(AD27+G51+L51+Q51+V51+AA51) -> 86
C52: Sat | D52: ='Day 6'!K110 -> 38 | E52: ='Day 6'!M110 -> 3 | I52: ='Day 7'!K75 -> 36 | J52: ='Day 7'!M75 -> 6 | N52: ='Day 8'!K40 -> 36 | O52: ='Day 8'!M40 -> 3 | S52: =SUM('Day 9'!K40) -> 34 | T52: =SUM('Day 9'!M40) -> 4 | X52: =SUM('Day 10'!K110) -> 35 | Y52: =SUM('Day 10'!M110) -> 4
Q55: `

Sheet Day 1
C1: VLTC SAN MICHEL TEAM TOURNAMENT 2025
C6: DAY 1 - 31/01/2025 & 01/02/2025
C9: Court 1
C11: Time | D11: Rubber | E11: TEAM A: Roberto Murdocco | G11: vs | H11: TEAM C: Gabriel Pace | J11: Games | L11: Sets
C13: 6.30 pm | D13: Lad A | E13: Natalya Abela | F13: Diane Fenech | G13: vs | H13: Martina Cuschieri | I13: Yana Cachia | J13: 6 | K13: 4 | L13: =IF(AND(J13>K13,J14>K14),2,IF(J13>K13,1,IF(J14>K14,1,0))) -> 1 | M13: =IF(AND(K13>J13,K14>J14),2,IF(K13>J13,1,IF(K14>J14,1,0))) -> 1
J14: 2 | K14: 6
C16: 7.45 pm | D16: Lad B | E16: Anabel Borg | F16: Silvana Portelli | G16: vs | H16: Julie Spiteri | I16: Deborah Farrugia | J16: 5 | K16: 7 | L16: =IF(AND(J16>K16,J17>K17),2,IF(J16>K16,1,IF(J17>K17,1,0))) -> 0 | M16: =IF(AND(K16>J16,K17>J17),2,IF(K16>J16,1,IF(K17>J17,1,0))) -> 2
J17: 0 | K17: 6
C19: 9.00 pm | D19: Men A | E19: Clayton Zammit Cesare | F19: Marco Mercieca | G19: vs | H19: Matthew Mifsud | I19: Nikolai Belli | J19: 6 | K19: 0 | L19: =IF(AND(J19>K19,J20>K20),2,IF(J19>K19,1,IF(J20>K20,1,0))) -> 2 | M19: =IF(AND(K19>J19,K20>J20),2,IF(K19>J19,1,IF(K20>J20,1,0))) -> 0
J20: 6 | K20: 2
C22: 6.30pm | D22: Lad C | E22: Angele Pule' | F22: Lonia Carabott | G22: vs | H22: Janice Galea | I22: Christine Scerri | J22: 6 | K22: 0 | L22: =IF(AND(J22>K22,J23>K23),2,IF(J22>K22,1,IF(J23>K23,1,0))) -> 2 | M22: =IF(AND(K22>J22,K23>J23),2,IF(K22>J22,1,IF(K23>J23,1,0))) -> 0
J23: 6 | K23: 1
C25: Total Day 1 A | J25: =SUM(J13:J23) -> 37 | K25: =SUM(K13:K23) -> 26 | L25: =SUM(L13:L23) -> 5 | M25: =SUM(M13:M23) -> 3
C28: 3.30pm | D28: Men B | E28: Luigi Porto | F28: Roberto Murdocco | G28: vs | H28: Ivan Cachia | I28: Jonathan Martinelli | J28: 3 | K28: 6 | L28: =IF(AND(J28>K28,J29>K29),2,IF(J28>K28,1,IF(J29>K29,1,0))) -> 1 | M28: =IF(AND(K28>J28,K29>J29),2,IF(K28>J28,1,IF(K29>J29,1,0))) -> 1
J29: 6 | K29: 1
C31: 5.00pm | D31: Men D | E31: Simone Re | F31: Kenneth Farrugia (Dem Joseph Randich) | G31: vs | H31: Cory Greenland | I31: Mario Abdilla | J31: 4 | K31: 6 | L31: =IF(AND(J31>K31,J32>K32),2,IF(J31>K31,1,IF(J32>K32,1,0))) -> 0 | M31: =IF(AND(K31>J31,K32>J32),2,IF(K31>J31,1,IF(K32>J32,1,0))) -> 2
J32: 5 | K32: 7
C34: 6.30pm | D34: Men C | E34: Manuel Mifsud | F34: James Brincat | G34: vs | H34: Steve Gambin | I34: Darrell Pace | J34: 6 | K34: 4 | L34: =IF(AND(J34>K34,J35>K35),2,IF(J34>K34,1,IF(J35>K35,1,0))) -> 2 | M34: =IF(AND(K34>J34,K35>J35),2,IF(K34>J34,1,IF(K35>J35,1,0))) -> 0
J35: 6 | K35: 0
C38: Total Day 1B | J38: =SUM(J28:J36) -> 30 | K38: =SUM(K28:K36) -> 24 | L38: =SUM(L28:L36) -> 3 | M38: =SUM(M28:M36) -> 3
C40: Total Day 1 | J40: =J38+J25 -> 67 | K40: =K38+K25 -> 50 | L40: =L38+L25 -> 8 | M40: =M38+M25 -> 6
C42: Court 2
C44: Time | D44: Rubber | E44: TEAM D: Lucienne Meli | G44: vs | H44: TEAM E: Juan Sammut | J44: Games | L44: Sets
C46: 6.30 pm | D46: Lad A | E46: Pierina Holmin | F46: Yanika Pace(pro Lucienne Meli) | G46: vs | H46: Elaine Grech | I46: Alison Muscat | J46: 6 | K46: 4 | L46: =IF(AND(J46>K46,J47>K47),2,IF(J46>K46,1,IF(J47>K47,1,0))) -> 2 | M46: =IF(AND(K46>J46,K47>J47),2,IF(K46>J46,1,IF(K47>J47,1,0))) -> 0
J47: 7 | K47: 5
C49: 7.45 pm | D49: Lad C | E49: Ruth Micallef | F49: Ceridwen Scerri | G49: vs | H49: Christine Seychell | I49: Christabelle Chetcuti | J49: 6 | K49: 4 | L49: =IF(AND(J49>K49,J50>K50),2,IF(J49>K49,1,IF(J50>K50,1,0))) -> 2 | M49: =IF(AND(K49>J49,K50>J50),2,IF(K49>J49,1,IF(K50>J50,1,0))) -> 0
J50: 6 | K50: 1
C52: 9.00 pm | D52: Men A | E52: Matthew Borg | F52: Fotios Evangelou | G52: vs | H52: Duncan D'Alessandro | I52: Clyde Grech | J52: 6 | K52: 4 | L52: =IF(AND(J52>K52,J53>K53),2,IF(J52>K52,1,IF(J53>K53,1,0))) -> 1 | M52: =IF(AND(K52>J52,K53>J53),2,IF(K52>J52,1,IF(K53>J53,1,0))) -> 1
J53: 4 | K53: 6
C55: 7.45 pm | D55: Lad B | E55: Yanika Pace | F55: Nancy Wong | G55: vs | H55: Amanda Falzon | I55: Romina Gauci | J55: 3 | K55: 6 | L55: =IF(AND(J55>K55,J56>K56),2,IF(J55>K55,1,IF(J56>K56,1,0))) -> 0 | M55: =IF(AND(K55>J55,K56>J56),2,IF(K55>J55,1,IF(K56>J56,1,0))) -> 2
J56: 3 | K56: 6
C58: Total Day 1 A | J58: =SUM(J46:J56) -> 41 | K58: =SUM(K46:K56) -> 36 | L58: =SUM(L46:L56) -> 5 | M58: =SUM(M46:M56) -> 3
C61: 3.30 pm | D61: Men C | E61: Charles Sacco | F61: Victor Rutter | G61: vs | H61: Juan Debono | I61: Juan Sammut | J61: 7 | K61: 6 | L61: =IF(AND(J61>K61,J62>K62),2,IF(J61>K61,1,IF(J62>K62,1,0))) -> 2 | M61: =IF(AND(K61>J61,K62>J62),2,IF(K61>J61,1,IF(K62>J62,1,0))) -> 0
J62: 6 | K62: 3
C64: 5.00pm | D64: Men D | E64: Glenn Micallef | F64: Twanny Pule' | G64: vs | H64: Kenneth Caruana | I64: Robert Attard | J64: 6 | K64: 4 | L64: =IF(AND(J64>K64,J65>K65),2,IF(J64>K64,1,IF(J65>K65,1,0))) -> 1 | M64: =IF(AND(K64>J64,K65>J65),2,IF(K64>J64,1,IF(K65>J65,1,0))) -> 1
J65: 4 | K65: 6
C67: 6.30pm | D67: Men B | E67: David Schembri | F67: Cyril Lastimosa | G67: vs | H67: Jean Paul Tabone (Pro Stefan Holmin) | I67: Ivan Cassar | J67: 6 | K67: 3 | L67: =IF(AND(J67>K67,J68>K68),2,IF(J67>K67,1,IF(J68>K68,1,0))) -> 2 | M67: =IF(AND(K67>J67,K68>J68),2,IF(K67>J67,1,IF(K68>J68,1,0))) -> 0
J68: 7 | K68: 6
C71: Total Day 1B | J71: =SUM(J61:J69) -> 36 | K71: =SUM(K61:K69) -> 28 | L71: =SUM(L61:L69) -> 5 | M71: =SUM(M61:M69) -> 1
C73: Total Day 1 | J73: =J71+J58 -> 77 | K73: =K71+K58 -> 64 | L73: =L71+L58 -> 10 | M73: =M71+M58 -> 4
...

Sheet Day 2 
C1: SAN MICHEL TEAM TOURNAMENT 2025
C6: Day 2- 14/02/2025 & 15/02/2025
C9: Court 1
C11: Time | D11: Rubber | E11: Team B: Kelsey Gauci | G11: vs | H11: Team E: Juan Sammut | J11: Games | L11: Sets
C13: 8.30pm | D13: Men A | E13: Melchior Farrugia | F13: Keith Micallef | G13: vs | H13: Clyde Grech | I13: Andrew Pule' | J13: 0 | K13: 6 | L13: =IF(AND(J13>K13,J14>K14),2,IF(J13>K13,1,IF(J14>K14,1,0))) -> 0 | M13: =IF(AND(K13>J13,K14>J14),2,IF(K13>J13,1,IF(K14>J14,1,0))) -> 2 | N13: w/o due to injury
J14: 0 | K14: 6
C16: 7.45 pm | D16: Lad B | E16: Marcette Sciriha | F16: Brenda Baldacchino | G16: vs | H16: Amanda Falzon | I16: Ann Marie Attard | J16: 4 | K16: 6 | L16: =IF(AND(J16>K16,J17>K17),2,IF(J16>K16,1,IF(J17>K17,1,0))) -> 0 | M16: =IF(AND(K16>J16,K17>J17),2,IF(K16>J16,1,IF(K17>J17,1,0))) -> 2
J17: 1 | K17: 6
C19: 9.00 pm | D19: Lad A | E19: Alexia Spiteri Willets | F19: Kelsey Gauci | G19: vs | H19: Leanne Vassallo | I19: Alison Muscat | J19: 1 | K19: 6 | L19: =IF(AND(J19>K19,J20>K20),2,IF(J19>K19,1,IF(J20>K20,1,0))) -> 1 | M19: =IF(AND(K19>J19,K20>J20),2,IF(K19>J19,1,IF(K20>J20,1,0))) -> 1
J20: 6 | K20: 3
C22: 6.30 pm | D22: Men D | E22: Matthew Micallef | F22: JP Sciberras | G22: vs | H22: Kenneth Caruana | I22: Kevin Sciberras | J22: 7 | K22: 5 | L22: =IF(AND(J22>K22,J23>K23),2,IF(J22>K22,1,IF(J23>K23,1,0))) -> 1 | M22: =IF(AND(K22>J22,K23>J23),2,IF(K22>J22,1,IF(K23>J23,1,0))) -> 1
J23: 2 | K23: 6
C25: Total Day 2 A | J25: =SUM(J13:J23) -> 21 | K25: =SUM(K13:K23) -> 44 | L25: =SUM(L13:L23) -> 2 | M25: =SUM(M13:M23) -> 6
C28: 3.30 pm | D28: Men B | E28: Kurt Cassar | F28: Clint Agius | G28: vs | H28: Ivan Cassar | I28: Kyle Magro | J28: 6 | K28: 4 | L28: =IF(AND(J28>K28,J29>K29),2,IF(J28>K28,1,IF(J29>K29,1,0))) -> 2 | M28: =IF(AND(K28>J28,K29>J29),2,IF(K28>J28,1,IF(K29>J29,1,0))) -> 0
J29: 6 | K29: 4
C31: 3.00 pm | D31: Men C | E31: Aaron Micallef Piccione | F31: Matthias Sciriha | G31: vs | H31: Jean Paul Vella | I31: Juan Debono | J31: 6 | K31: 3 | L31: =IF(AND(J31>K31,J32>K32),2,IF(J31>K31,1,IF(J32>K32,1,0))) -> 2 | M31: =IF(AND(K31>J31,K32>J32),2,IF(K31>J31,1,IF(K32>J32,1,0))) -> 0
J32: 6 | K32: 4
C34: 4.15 pm | D34: Lad C | E34: Leanne Sammut | F34: Jodie Stivala | G34: vs | H34: Maria Ellul | I34: Christine Seychell | J34: 6 | K34: 3 | L34: =IF(AND(J34>K34,J35>K35),2,IF(J34>K34,1,IF(J35>K35,1,0))) -> 2 | M34: =IF(AND(K34>J34,K35>J35),2,IF(K34>J34,1,IF(K35>J35,1,0))) -> 0
J35: 7 | K35: 6
C38: Total Day 2B | J38: =SUM(J28:J36) -> 37 | K38: =SUM(K28:K36) -> 24 | L38: =SUM(L28:L36) -> 6 | M38: =SUM(M28:M36) -> 0
C40: Total Day 2 | J40: =J38+J25 -> 58 | K40: =K38+K25 -> 68 | L40: =L38+L25 -> 8 | M40: =M38+M25 -> 6
C42: Court 2
C44: Time | D44: Rubber | E44: Team A: Roberto Murdocco | G44: vs | H44: Team F: Francesca Sciortino | J44: Games | L44: Sets
C46: 6.30 pm | D46: Men A | E46: Clayton Zammit Cesare | F46: David Mifsud | G46: vs | H46: Adrian Chetcuti | I46: Eric Roca | J46: 7 | K46: 5 | L46: =IF(AND(J46>K46,J47>K47),2,IF(J46>K46,1,IF(J47>K47,1,0))) -> 2 | M46: =IF(AND(K46>J46,K47>J47),2,IF(K46>J46,1,IF(K47>J47,1,0))) -> 0
J47: 6 | K47: 4
C49: 7.45 pm | D49: Lad A | E49: Natalya Abela | F49: Annabelle Abela | G49: vs | H49: Renette Magro | I49: Lara Pule' | J49: 0 | K49: 6 | L49: =IF(AND(J49>K49,J50>K50),2,IF(J49>K49,1,IF(J50>K50,1,0))) -> 0 | M49: =IF(AND(K49>J49,K50>J50),2,IF(K49>J49,1,IF(K50>J50,1,0))) -> 2
J50: 0 | K50: 6
C52: 7.45 pm | D52: Men D | E52: Simone Re | F52: Arthur Napier | G52: vs | H52: Dunstan Vella | I52: Chris Vella | J52: 2 | K52: 6 | L52: =IF(AND(J52>K52,J53>K53),2,IF(J52>K52,1,IF(J53>K53,1,0))) -> 0 | M52: =IF(AND(K52>J52,K53>J53),2,IF(K52>J52,1,IF(K53>J53,1,0))) -> 2
J53: 5 | K53: 7
C55: 6.30 pm | D55: Men C | E55: James Brincat | F55: Kenneth Farrugia | G55: vs | H55: Julian Esposito | I55: Alain Frendo | J55: 4 | K55: 6 | L55: =IF(AND(J55>K55,J56>K56),2,IF(J55>K55,1,IF(J56>K56,1,0))) -> 1 | M55: =IF(AND(K55>J55,K56>J56),2,IF(K55>J55,1,IF(K56>J56,1,0))) -> 1
J56: 7 | K56: 5
C58: Total Day 2 A | J58: =SUM(J46:J56) -> 31 | K58: =SUM(K46:K56) -> 45 | L58: =SUM(L46:L56) -> 3 | M58: =SUM(M46:M56) -> 5
C61: 8.30pm | D61: Lad B | E61: Rowena Caruana | F61: Silvana Portelli | G61: vs | H61: Stephania Farrugia | I61: Mariska Steenkamer | J61: 7 | K61: 5 | L61: =IF(AND(J61>K61,J62>K62),2,IF(J61>K61,1,IF(J62>K62,1,0))) -> 2 | M61: =IF(AND(K61>J61,K62>J62),2,IF(K61>J61,1,IF(K62>J62,1,0))) -> 0
J62: 6 | K62: 4
C64: 7.00pm | D64: Lad C | E64: Angele Pule' | F64: Mary Borg | G64: vs | H64: Jin Attard | I64: Jennifer Roca | J64: 4 | K64: 6 | L64: =IF(AND(J64>K64,J65>K65),2,IF(J64>K64,1,IF(J65>K65,1,0))) -> 0 | M64: =IF(AND(K64>J64,K65>J65),2,IF(K64>J64,1,IF(K65>J65,1,0))) -> 2
J65: 2 | K65: 6
C67: 5.30 pm | D67: Men B | E67: Emman Xuereb | F67: Luigi Porto | G67: vs | H67: Willem Steenkamer | I67: Kristen Cachia | J67: 6 | K67: 3 | L67: =IF(AND(J67>K67,J68>K68),2,IF(J67>K67,1,IF(J68>K68,1,0))) -> 2 | M67: =IF(AND(K67>J67,K68>J68),2,IF(K67>J67,1,IF(K68>J68,1,0))) -> 0
J68: 6 | K68: 2
C71: Total Day 2B | J71: =SUM(J61:J69) -> 31 | K71: =SUM(K61:K69) -> 26 | L71: =SUM(L61:L69) -> 4 | M71: =SUM(M61:M69) -> 2
C73: Total Day 2 | J73: =J71+J58 -> 62 | K73: =K71+K58 -> 71 | L73: =L71+L58 -> 7 | M73: =M71+M58 -> 7
...

Sheet Day 3
C1: SAN MICHEL TEAM TOURNAMENT 2025
C6: Day 3 - 21/02/2025 & 22/02/2025
C9: Court 1
C11: Time | D11: Rubber | E11: TEAM C: Gabriel Pace | G11: vs | H11: TEAM F: Francesca Sciortino | J11: Games | L11: Sets
C13: 6.30 pm | D13: Lad A | E13: Martina Cuschieri | F13: Becky Hayes | G13: vs | H13: Renette Magro | I13: Lara Pule' | J13: 1 | K13: 6 | L13: =IF(AND(J13>K13,J14>K14),2,IF(J13>K13,1,IF(J14>K14,1,0))) -> 0 | M13: =IF(AND(K13>J13,K14>J14),2,IF(K13>J13,1,IF(K14>J14,1,0))) -> 2
J14: 1 | K14: 6
C16: 6.30 pm | D16: Men C | E16: Etienne Formosa Carabez | F16: Darrell Pace | G16: vs | H16: Matthew Schembri | I16: Maurice Borg | J16: 1 | K16: 6 | L16: =IF(AND(J16>K16,J17>K17),2,IF(J16>K16,1,IF(J17>K17,1,0))) -> 0 | M16: =IF(AND(K16>J16,K17>J17),2,IF(K16>J16,1,IF(K17>J17,1,0))) -> 2
J17: 4 | K17: 6
C19: 9.00 pm | D19: Lad B | E19: Julie Spiteri | F19: Kristina Briffa | G19: vs | H19: Francesca Sciortino | I19: Mariska Steenkamer | J19: 2 | K19: 6 | L19: =IF(AND(J19>K19,J20>K20),2,IF(J19>K19,1,IF(J20>K20,1,0))) -> 0 | M19: =IF(AND(K19>J19,K20>J20),2,IF(K19>J19,1,IF(K20>J20,1,0))) -> 2
J20: 6 | K20: 7
C22: 9.00 pm | L22: =IF(AND(J22>K22,J23>K23),2,IF(J22>K22,1,IF(J23>K23,1,0))) -> 0 | M22: =IF(AND(K22>J22,K23>J23),2,IF(K22>J22,1,IF(K23>J23,1,0))) -> 0
C25: Total Day 3 A | J25: =SUM(J13:J23) -> 15 | K25: =SUM(K13:K23) -> 37 | L25: =SUM(L13:L23) -> 0 | M25: =SUM(M13:M23) -> 6
C28: 3.30 pm | D28: Men B | E28: Ivan Cachia | F28: Gene Zammit | G28: vs | H28: Kristen Cachia | I28: Jayboy Lastimosa | J28: 6 | K28: 3 | L28: =IF(AND(J28>K28,J29>K29),2,IF(J28>K28,1,IF(J29>K29,1,0))) -> 1 | M28: =IF(AND(K28>J28,K29>J29),2,IF(K28>J28,1,IF(K29>J29,1,0))) -> 1
J29: 3 | K29: 6
C31: 5.00pm | D31: Men A | E31: Gabriel Pace | F31: Nikolai Belli | G31: vs | H31: Jean Attard | I31: Eric Roca | J31: 4 | K31: 6 | L31: =IF(AND(J31>K31,J32>K32),2,IF(J31>K31,1,IF(J32>K32,1,0))) -> 0 | M31: =IF(AND(K31>J31,K32>J32),2,IF(K31>J31,1,IF(K32>J32,1,0))) -> 2
J32: 3 | K32: 6
C34: 5.00pm | D34: Men D | E34: Cory Greenland | F34: Mario Abdilla | G34: vs | H34: Dunstan Vella | I34: Jason Lee Evans | J34: 4 | K34: 6 | L34: =IF(AND(J34>K34,J35>K35),2,IF(J34>K34,1,IF(J35>K35,1,0))) -> 1 | M34: =IF(AND(K34>J34,K35>J35),2,IF(K34>J34,1,IF(K35>J35,1,0))) -> 1
J35: 6 | K35: 3
C37: 6.30pm | D37: Lad C | E37: Maria Angela Gambin | F37: Christine Scerri | G37: vs | H37: Jin Atard | I37: Daphne Vella | J37: 6 | K37: 4 | L37: =IF(AND(J37>K37,J38>K38),2,IF(J37>K37,1,IF(J38>K38,1,0))) -> 1 | M37: =IF(AND(K37>J37,K38>J38),2,IF(K37>J37,1,IF(K38>J38,1,0))) -> 1
J38: 4 | K38: 6
C40: Total Day 3B | J40: =SUM(J28:J38) -> 36 | K40: =SUM(K28:K38) -> 40 | L40: =SUM(L28:L38) -> 3 | M40: =SUM(M28:M38) -> 5
C42: Total Day 3 | J42: =J40+J25 -> 51 | K42: =K40+K25 -> 77 | L42: =L40+L25 -> 3 | M42: =M40+M25 -> 11
C44: Court 2
C46: Time | D46: Rubber | E46: TEAM D: Lucienne Meli | G46: vs | H46: TEAM B: Kelsey Gauci | J46: Games | L46: Sets
C48: 6.30 pm | D48: Men A | E48: Trevor Rutter | F48: Fotios Evangelou | G48: vs | H48: Melchior Farrugia | I48: Manuel Bonello | J48: 6 | K48: 1 | L48: =IF(AND(J48>K48,J49>K49),2,IF(J48>K48,1,IF(J49>K49,1,0))) -> 1 | M48: =IF(AND(K48>J48,K49>J49),2,IF(K48>J48,1,IF(K49>J49,1,0))) -> 1
J49: 6 | K49: 7
C51: 7.45 pm | D51: Lad A | E51: Annmarie Mangion | F51: Lucienne Meli | G51: vs | H51: Alexia Spiteri Willets | I51: Kirsty Mercieca | J51: 6 | K51: 4 | L51: =IF(AND(J51>K51,J52>K52),2,IF(J51>K51,1,IF(J52>K52,1,0))) -> 2 | M51: =IF(AND(K51>J51,K52>J52),2,IF(K51>J51,1,IF(K52>J52,1,0))) -> 0
J52: 7 | K52: 5
C54: 7.45 pm | D54: Lad B | E54: Dorianne Buhagiar | F54: Nancy Wong | G54: vs | H54: Marcette Sciriha | I54: Tanya Cassar (Pro Anthea Gauci) | J54: 0 | K54: 6 | L54: =IF(AND(J54>K54,J55>K55),2,IF(J54>K54,1,IF(J55>K55,1,0))) -> 1 | M54: =IF(AND(K54>J54,K55>J55),2,IF(K54>J54,1,IF(K55>J55,1,0))) -> 1
J55: 6 | K55: 2
C57: 9.00 pm | D57: Men D | E57: Glenn Micallef | F57: Isaac Joseph Zammit | G57: vs | H57: Donald Dugazman | I57: JP Sciberras | J57: 2 | K57: 6 | L57: =IF(AND(J57>K57,J58>K58),2,IF(J57>K57,1,IF(J58>K58,1,0))) -> 0 | M57: =IF(AND(K57>J57,K58>J58),2,IF(K57>J57,1,IF(K58>J58,1,0))) -> 2
J58: 0 | K58: 6 | N58: Ret
C60: Total Day 3 A | J60: =SUM(J48:J58) -> 33 | K60: =SUM(K48:K58) -> 37 | L60: =SUM(L48:L58) -> 4 | M60: =SUM(M48:M58) -> 4
C63: 3.30 pm | D63: Men C | E63: Artiom Kiricenko | F63: Glenn Micallef (pro Victor Rutter) | G63: vs | H63: Matthias Sciriha | I63: David Camilleri | J63: 6 | K63: 2 | L63: =IF(AND(J63>K63,J64>K64),2,IF(J63>K63,1,IF(J64>K64,1,0))) -> 1 | M63: =IF(AND(K63>J63,K64>J64),2,IF(K63>J63,1,IF(K64>J64,1,0))) -> 1
J64: 2 | K64: 6
C66: 5.00pm | D66: Men B | E66: Jonathan Vella | F66: David Schembri | G66: vs | H66: Kurt Cassar | I66: Clint Agius | J66: 6 | K66: 7 | L66: =IF(AND(J66>K66,J67>K67),2,IF(J66>K66,1,IF(J67>K67,1,0))) -> 1 | M66: =IF(AND(K66>J66,K67>J67),2,IF(K66>J66,1,IF(K67>J67,1,0))) -> 1
J67: 6 | K67: 4
C69: 6.00 pm | D69: Lad C | E69: Ceridwen Scerri | F69: Karolina Papiernik | G69: vs | H69: Jodie Stivala | I69: Leanne Sammut | J69: 4 | K69: 6 | L69: =IF(AND(J69>K69,J70>K70),2,IF(J69>K69,1,IF(J70>K70,1,0))) -> 1 | M69: =IF(AND(K69>J69,K70>J70),2,IF(K69>J69,1,IF(K70>J70,1,0))) -> 1
J70: 6 | K70: 2
L72: =IF(AND(J72>K72,J73>K73),2,IF(J72>K72,1,IF(J73>K73,1,0))) -> 0 | M72: =IF(AND(K72>J72,K73>J73),2,IF(K72>J72,1,IF(K73>J73,1,0))) -> 0
...

Sheet Day 4
C1: SAN MICHEL TEAM TOURNAMENT 2020
C6: Day 4 - 24/02/2025 & 28/02/2025
C9: Court 1
C11: Time | D11: Rubber | E11: Team D: Lucienne Meli | H11: Team F: Francesca Sciortino | J11: Games | L11: Sets
C13: 6.30 pm | D13: Men A | E13: Matthew Borg | F13: Trevor Rutter | G13: vs | H13: Adrian Chetcuti | I13: Jean Attard | J13: 7 | K13: 6 | L13: =IF(AND(J13>K13,J14>K14),2,IF(J13>K13,1,IF(J14>K14,1,0))) -> 1 | M13: =IF(AND(K13>J13,K14>J14),2,IF(K13>J13,1,IF(K14>J14,1,0))) -> 1
J14: 4 | K14: 6
C16: 7.45 pm | D16: Men D | E16: Ceridwen Scerri | F16: Karolina Papiernak | G16: vs | H16: Jennifer Roca | I16: Daphne Vella | J16: 6 | K16: 3 | L16: =IF(AND(J16>K16,J17>K17),2,IF(J16>K16,1,IF(J17>K17,1,0))) -> 2 | M16: =IF(AND(K16>J16,K17>J17),2,IF(K16>J16,1,IF(K17>J17,1,0))) -> 0
J17: 6 | K17: 4
C19: 9.00 pm | G19: vs | L19: =IF(AND(J19>K19,J20>K20),2,IF(J19>K19,1,IF(J20>K20,1,0))) -> 0 | M19: =IF(AND(K19>J19,K20>J20),2,IF(K19>J19,1,IF(K20>J20,1,0))) -> 0
C22: 7.45 pm | D22: Lad C | E22: Anthony Pule' | F22: Glenn Micallef | G22: vs | H22: Jason Lee Evans | I22: Chris Vella | J22: 3 | K22: 6 | L22: =IF(AND(J22>K22,J23>K23),2,IF(J22>K22,1,IF(J23>K23,1,0))) -> 0 | M22: =IF(AND(K22>J22,K23>J23),2,IF(K22>J22,1,IF(K23>J23,1,0))) -> 2
J23: 3 | K23: 6
C25: Total Day 4 A | J25: =SUM(J13:J23) -> 29 | K25: =SUM(K13:K23) -> 31 | L25: =SUM(L13:L23) -> 3 | M25: =SUM(M13:M23) -> 3
C28: 6.30 pm | D28: Men C | E28: Artiom Kiricenko | F28: Charles Sacco | G28: vs | H28: Matthew Schembri | I28: Maurice Borg | J28: 2 | K28: 6 | L28: =IF(AND(J28>K28,J29>K29),2,IF(J28>K28,1,IF(J29>K29,1,0))) -> 1 | M28: =IF(AND(K28>J28,K29>J29),2,IF(K28>J28,1,IF(K29>J29,1,0))) -> 1
J29: 7 | K29: 5
C31: 7.45 pm | D31: Lad A | E31: Pierina Holmin | F31: Annmarie Mangion | G31: vs | H31: Renette Magro | I31: Olivia Belli | J31: 0 | K31: 6 | L31: =IF(AND(J31>K31,J32>K32),2,IF(J31>K31,1,IF(J32>K32,1,0))) -> 0 | M31: =IF(AND(K31>J31,K32>J32),2,IF(K31>J31,1,IF(K32>J32,1,0))) -> 2
J32: 1 | K32: 6
C34: 9.00 pm | D34: Lad B | E34: Yanika Pace | F34: Dorianne Buhagiar | G34: vs | H34: Francesca Sciortino | I34: Mariska Steenkamer | J34: 6 | K34: 3 | L34: =IF(AND(J34>K34,J35>K35),2,IF(J34>K34,1,IF(J35>K35,1,0))) -> 1 | M34: =IF(AND(K34>J34,K35>J35),2,IF(K34>J34,1,IF(K35>J35,1,0))) -> 1
J35: 6 | K35: 7
C37: 6.30 pm | D37: Men B | E37: David Schembri | F37: Cyril Lastimosa | G37: vs | H37: Kristen Cachia | I37: Willem Steenkamer | J37: 6 | K37: 7 | L37: =IF(AND(J37>K37,J38>K38),2,IF(J37>K37,1,IF(J38>K38,1,0))) -> 1 | M37: =IF(AND(K37>J37,K38>J38),2,IF(K37>J37,1,IF(K38>J38,1,0))) -> 1
J38: 6 | K38: 3
C40: Total Day 4B | J40: =SUM(J28:J38) -> 34 | K40: =SUM(K28:K38) -> 43 | L40: =SUM(L28:L38) -> 3 | M40: =SUM(M28:M38) -> 5
C42: Total Day 4 | J42: =J40+J25 -> 63 | K42: =K40+K25 -> 74 | L42: =L40+L25 -> 6 | M42: =M40+M25 -> 8
C44: Court 2
C46: Time | D46: Rubber | E46: TEAM C: Gabriel Pace | H46: TEAM E: Juan Sammut | J46: Games | L46: Sets
C48: 6.30 pm | D48: Lad A | E48: Martina Cuschieri | F48: Kaya Sammut | G48: vs | H48: Leanne Vassallo | I48: Alison Muscat | J48: 7 | K48: 5 | L48: =IF(AND(J48>K48,J49>K49),2,IF(J48>K48,1,IF(J49>K49,1,0))) -> 2 | M48: =IF(AND(K48>J48,K49>J49),2,IF(K48>J48,1,IF(K49>J49,1,0))) -> 0
J49: 6 | K49: 4
C51: 7.45 pm | D51: Lad C | E51: Maria Angela Gambin | F51: Janice Galea | G51: vs | H51: Maria Ellul | I51: Christabelle Chetcuti | J51: 7 | K51: 5 | L51: =IF(AND(J51>K51,J52>K52),2,IF(J51>K51,1,IF(J52>K52,1,0))) -> 2 | M51: =IF(AND(K51>J51,K52>J52),2,IF(K51>J51,1,IF(K52>J52,1,0))) -> 0
J52: 6 | K52: 4
C54: 9.00 pm | D54: Men C | E54: Etienne Formosa Carabez | F54: Darrell Pace | G54: vs | H54: Jean Paul Vella | I54: Juan Debono | J54: 6 | K54: 7 | L54: =IF(AND(J54>K54,J55>K55),2,IF(J54>K54,1,IF(J55>K55,1,0))) -> 1 | M54: =IF(AND(K54>J54,K55>J55),2,IF(K54>J54,1,IF(K55>J55,1,0))) -> 1
J55: 7 | K55: 6
C57: 6.30 pm | D57: Men B | E57: Jonathan Martinelli | F57: Gene Zammit | G57: vs | H57: Ivan Cassar | I57: Kyle Magro | J57: 6 | K57: 4 | L57: =IF(AND(J57>K57,J58>K58),2,IF(J57>K57,1,IF(J58>K58,1,0))) -> 1 | M57: =IF(AND(K57>J57,K58>J58),2,IF(K57>J57,1,IF(K58>J58,1,0))) -> 1
J58: 2 | K58: 6
C60: Total Day 4 A | J60: =SUM(J48:J58) -> 47 | K60: =SUM(K48:K58) -> 41 | L60: =SUM(L48:L58) -> 6 | M60: =SUM(M48:M58) -> 2
C63: 6.30 pm | D63: Men A | E63: Matthew Mifsud | F63: Nikolai Belli | G63: vs | H63: Duncan D'Alessandro | I63: Clyde Magro | J63: 7 | K63: 5 | L63: =IF(AND(J63>K63,J64>K64),2,IF(J63>K63,1,IF(J64>K64,1,0))) -> 1 | M63: =IF(AND(K63>J63,K64>J64),2,IF(K63>J63,1,IF(K64>J64,1,0))) -> 1
J64: 1 | K64: 6
C66: 7.45pm | D66: Lad B | E66: Julie Spiteri | F66: Deborah Farrugia | G66: vs | H66: Amanda Falzon | I66: Ann Marie Attard | J66: 6 | K66: 3 | L66: =IF(AND(J66>K66,J67>K67),2,IF(J66>K66,1,IF(J67>K67,1,0))) -> 1 | M66: =IF(AND(K66>J66,K67>J67),2,IF(K66>J66,1,IF(K67>J67,1,0))) -> 1
J67: 3 | K67: 6
C69: 7.45pm | G69: vs | L69: =IF(AND(J69>K69,J70>K70),2,IF(J69>K69,1,IF(J70>K70,1,0))) -> 0 | M69: =IF(AND(K69>J69,K70>J70),2,IF(K69>J69,1,IF(K70>J70,1,0))) -> 0
C72: 9.00pm | D72: Men D | E72: Conrad Treeby Ward | F72: Cory Greenland | G72: vs | H72: Robert Attard | I72: Kevin Sciberras | J72: 6 | K72: 0 | L72: =IF(AND(J72>K72,J73>K73),2,IF(J72>K72,1,IF(J73>K73,1,0))) -> 2 | M72: =IF(AND(K72>J72,K73>J73),2,IF(K72>J72,1,IF(K73>J73,1,0))) -> 0
J73: 6 | K73: 0
...

Sheet Day 5
C1: SAN MICHEL TEAM TOURNAMENT 2025
C6: Day 5 - 08/03/2025 & 08/03/2025
C9: Court 1
C11: Time | D11: Rubber | E11: TEAM A: Roberto Murdocco | H11: TEAM D: Lucienne Meli | J11: Games | L11: Sets
C13: 6.30 pm | D13: Men A | E13: Clayton Zammit Cesare | F13: Marco Mercieca | G13: vs | H13: Matthew Borg | I13: Fotios Evangelou | J13: 6 | K13: 3 | L13: =IF(AND(J13>K13,J14>K14),2,IF(J13>K13,1,IF(J14>K14,1,0))) -> 2 | M13: =IF(AND(K13>J13,K14>J14),2,IF(K13>J13,1,IF(K14>J14,1,0))) -> 0
J14: 6 | K14: 4
C15: 6
C16: 7.45 pm | D16: Men D | E16: Joseph Randich | F16: Arthur Napier | G16: vs | H16: Antoine Bugeja | I16: Glenn Micallef | J16: 6 | K16: 7 | L16: =IF(AND(J16>K16,J17>K17),2,IF(J16>K16,1,IF(J17>K17,1,0))) -> 0 | M16: =IF(AND(K16>J16,K17>J17),2,IF(K16>J16,1,IF(K17>J17,1,0))) -> 2
J17: 2 | K17: 6
C19: 9.00 pm | D19: Lad B | E19: Anabel Borg | F19: Rowena Caruana | G19: vs | H19: Yanika Pace | I19: Nancy Wong | J19: 2 | K19: 6 | L19: =IF(AND(J19>K19,J20>K20),2,IF(J19>K19,1,IF(J20>K20,1,0))) -> 0 | M19: =IF(AND(K19>J19,K20>J20),2,IF(K19>J19,1,IF(K20>J20,1,0))) -> 2
J20: 2 | K20: 6
C22: 7.45 pm | D22: Lad C | E22: Lonia Carabott | F22: Angele Pule | G22: vs | H22: Ruth Micallef | I22: Ceridwen Scerri | J22: 2 | K22: 6 | L22: =IF(AND(J22>K22,J23>K23),2,IF(J22>K22,1,IF(J23>K23,1,0))) -> 0 | M22: =IF(AND(K22>J22,K23>J23),2,IF(K22>J22,1,IF(K23>J23,1,0))) -> 2
J23: 6 | K23: 7
C25: Total Day 5 A | J25: =SUM(J13:J23) -> 32 | K25: =SUM(K13:K23) -> 45 | L25: =SUM(L13:L23) -> 2 | M25: =SUM(M13:M23) -> 6
C28: 3.30 pm | D28: Lad A | E28: Natalya Abela | F28: Diane Fenech | G28: vs | H28: Annmarie Mangion | I28: Lucienne Meli | J28: 7 | K28: 6 | L28: =IF(AND(J28>K28,J29>K29),2,IF(J28>K28,1,IF(J29>K29,1,0))) -> 2 | M28: =IF(AND(K28>J28,K29>J29),2,IF(K28>J28,1,IF(K29>J29,1,0))) -> 0
J29: 7 | K29: 6
C31: 4.15 pm | G31: vs | L31: =IF(AND(J31>K31,J32>K32),2,IF(J31>K31,1,IF(J32>K32,1,0))) -> 0 | M31: =IF(AND(K31>J31,K32>J32),2,IF(K31>J31,1,IF(K32>J32,1,0))) -> 0
C34: 5.00pm | D34: Men B | E34: Luigi Porto | F34: Roberto Murdocco | G34: vs | H34: Cyril Lastimosa | I34: Jonathan Vella | J34: 3 | K34: 6 | L34: =IF(AND(J34>K34,J35>K35),2,IF(J34>K34,1,IF(J35>K35,1,0))) -> 0 | M34: =IF(AND(K34>J34,K35>J35),2,IF(K34>J34,1,IF(K35>J35,1,0))) -> 2
J35: 5 | K35: 7
C37: 6.30pm | D37: Men C | E37: Manuel Mifsud | F37: Kenneth Farrugia | G37: vs | H37: Artiom Kiricenko | I37: Victor Rutter | J37: 6 | K37: 2 | L37: =IF(AND(J37>K37,J38>K38),2,IF(J37>K37,1,IF(J38>K38,1,0))) -> 2 | M37: =IF(AND(K37>J37,K38>J38),2,IF(K37>J37,1,IF(K38>J38,1,0))) -> 0
J38: 6 | K38: 1
C40: Total Day 5B | J40: =SUM(J28:J38) -> 34 | K40: =SUM(K28:K38) -> 28 | L40: =SUM(L28:L38) -> 4 | M40: =SUM(M28:M38) -> 2
C42: Total Day 5 | J42: =J40+J25 -> 66 | K42: =K40+K25 -> 73 | L42: =L40+L25 -> 6 | M42: =M40+M25 -> 8
C44: Court 2
C46: Time | D46: Rubber | E46: TEAM B: Kelsey Gauci | H46: TEAM C: Gabriel Pace | J46: Games | L46: Sets
C48: 6.30 pm | D48: Men A | E48: Melchior Farriuga | F48: Emmanuel Bonello | G48: vs | H48: Matthew Mifsud | I48: Gabriel Pace | J48: 4 | K48: 6 | L48: =IF(AND(J48>K48,J49>K49),2,IF(J48>K48,1,IF(J49>K49,1,0))) -> 1 | M48: =IF(AND(K48>J48,K49>J49),2,IF(K48>J48,1,IF(K49>J49,1,0))) -> 1
J49: 6 | K49: 3
C51: 7.45 pm | D51: Men D | E51: Donald Deguzman | F51: Matthew Micallef | G51: vs | H51: Conrad Treeby Ward | I51: Cory Greenland | J51: 0 | K51: 6 | L51: =IF(AND(J51>K51,J52>K52),2,IF(J51>K51,1,IF(J52>K52,1,0))) -> 0 | M51: =IF(AND(K51>J51,K52>J52),2,IF(K51>J51,1,IF(K52>J52,1,0))) -> 2 | N51: w/o
J52: 0 | K52: 6
C54: 9.00 pm | D54: Lad B | E54: Anthea Gauci | F54: Brenda Baldacchino | G54: vs | H54: Julie Spiteri | I54: Kristina Briffa | J54: 2 | K54: 6 | L54: =IF(AND(J54>K54,J55>K55),2,IF(J54>K54,1,IF(J55>K55,1,0))) -> 0 | M54: =IF(AND(K54>J54,K55>J55),2,IF(K54>J54,1,IF(K55>J55,1,0))) -> 2
J55: 1 | K55: 6
D57: Lad C | E57: Tanya Cassar | F57: Jodie Stivala | G57: vs | H57: Maria Angela Gambin | I57: Janice Galea | J57: 2 | K57: 6 | L57: =IF(AND(J57>K57,J58>K58),2,IF(J57>K57,1,IF(J58>K58,1,0))) -> 0 | M57: =IF(AND(K57>J57,K58>J58),2,IF(K57>J57,1,IF(K58>J58,1,0))) -> 2
J58: 3 | K58: 6
C60: Total Day 5 A | J60: =SUM(J48:J58) -> 18 | K60: =SUM(K48:K58) -> 45 | L60: =SUM(L48:L58) -> 1 | M60: =SUM(M48:M58) -> 7
C63: 3.30 pm | D63: Lad A | E63: Alexia Spiteri Willets | F63: Rebecca Pace | G63: vs | H63: Becky Hayes | I63: Kaya Sammut | J63: 6 | K63: 7 | L63: =IF(AND(J63>K63,J64>K64),2,IF(J63>K63,1,IF(J64>K64,1,0))) -> 1 | M63: =IF(AND(K63>J63,K64>J64),2,IF(K63>J63,1,IF(K64>J64,1,0))) -> 1
J64: 6 | K64: 2
C66: 5.00pm | D66: Men C | E66: Aaron Micallef Piccione | F66: David Camilleri | G66: vs | H66: Steve Gambin | I66: Etienne Formosa Carabez | J66: 1 | K66: 6 | L66: =IF(AND(J66>K66,J67>K67),2,IF(J66>K66,1,IF(J67>K67,1,0))) -> 0 | M66: =IF(AND(K66>J66,K67>J67),2,IF(K66>J66,1,IF(K67>J67,1,0))) -> 2
J67: 4 | K67: 6
C69: 6.30pm | D69: Men B | E69: Kurt Cassar | F69: Clint Agius | G69: vs | H69: Jonathan Martinelli | I69: Gene Zammit | J69: 6 | K69: 4 | L69: =IF(AND(J69>K69,J70>K70),2,IF(J69>K69,1,IF(J70>K70,1,0))) -> 1 | M69: =IF(AND(K69>J69,K70>J70),2,IF(K69>J69,1,IF(K70>J70,1,0))) -> 1
J70: 3 | K70: 6
...

Sheet Day 6
C1: SAN MICHEL TEAM TOURNAMENT 2025
C6: Day 6 - 14/03/2025 & 15/03/2025
C9: Court 1
C11: Time | D11: Rubber | E11: TEAM A: Roberto Murdocco | H11: TEAM C: Gabriel Pace | J11: Games | L11: Sets
C13: 6.30 pm | D13: Men B | E13: Luigi Porto | F13: Emman Xuereb | G13: vs | H13: Ivan Cachia | I13: Gene Zammit | J13: 6 | K13: 3 | L13: =IF(AND(J13>K13,J14>K14),2,IF(J13>K13,1,IF(J14>K14,1,0))) -> 2 | M13: =IF(AND(K13>J13,K14>J14),2,IF(K13>J13,1,IF(K14>J14,1,0))) -> 0
J14: 6 | K14: 3
C16: 7.45 pm | D16: Lad B | E16: Anabel Borg | F16: Silvana Portelli | G16: vs | H16: Julie Spiteri | I16: Deborah Farrugia | J16: 4 | K16: 6 | L16: =IF(AND(J16>K16,J17>K17),2,IF(J16>K16,1,IF(J17>K17,1,0))) -> 0 | M16: =IF(AND(K16>J16,K17>J17),2,IF(K16>J16,1,IF(K17>J17,1,0))) -> 2
J17: 1 | K17: 6
C19: 9.00 pm | D19: Men C | E19: Manuel Mifsud | F19: Kenneth Farrugia | G19: vs | H19: Etienne Formosa Carabez | I19: Darrell Pace | J19: 3 | K19: 6 | L19: =IF(AND(J19>K19,J20>K20),2,IF(J19>K19,1,IF(J20>K20,1,0))) -> 1 | M19: =IF(AND(K19>J19,K20>J20),2,IF(K19>J19,1,IF(K20>J20,1,0))) -> 1
J20: 6 | K20: 2
C22: 6.30 pm | D22: Lad C | E22: Angele Pule' | F22: Lonia Carabott | G22: vs | H22: Maria Angela Gambin | I22: Christine Scerri | J22: 4 | K22: 6 | L22: =IF(AND(J22>K22,J23>K23),2,IF(J22>K22,1,IF(J23>K23,1,0))) -> 1 | M22: =IF(AND(K22>J22,K23>J23),2,IF(K22>J22,1,IF(K23>J23,1,0))) -> 1
J23: 6 | K23: 2
C25: Total Day 6 A | J25: =SUM(J13:J23) -> 36 | K25: =SUM(K13:K23) -> 34 | L25: =SUM(L13:L23) -> 4 | M25: =SUM(M13:M23) -> 4
C28: 3.00 pm | D28: Men D | E28: Simone Re | F28: Athur Napier | G28: vs | H28: Conrad Treeby Ward | I28: Maria Abdilla | J28: 3 | K28: 6 | L28: =IF(AND(J28>K28,J29>K29),2,IF(J28>K28,1,IF(J29>K29,1,0))) -> 0 | M28: =IF(AND(K28>J28,K29>J29),2,IF(K28>J28,1,IF(K29>J29,1,0))) -> 2
J29: 6 | K29: 7
C31: 4.15 pm | D31: Men A | E31: Clayton Zammit Cesare | F31: David Mifsud | G31: vs | H31: Nikolai Belli | I31: Gabriel Pace | J31: 6 | K31: 3 | L31: =IF(AND(J31>K31,J32>K32),2,IF(J31>K31,1,IF(J32>K32,1,0))) -> 2 | M31: =IF(AND(K31>J31,K32>J32),2,IF(K31>J31,1,IF(K32>J32,1,0))) -> 0
J32: 6 | K32: 2
C34: 5.30 pm | D34: Lad A | E34: Natalya Abela | F34: Annabelle Abela | G34: vs | H34: Becky Hayes | I34: Kaya Sammut | J34: 4 | K34: 6 | L34: =IF(AND(J34>K34,J35>K35),2,IF(J34>K34,1,IF(J35>K35,1,0))) -> 1 | M34: =IF(AND(K34>J34,K35>J35),2,IF(K34>J34,1,IF(K35>J35,1,0))) -> 1
J35: 6 | K35: 3
C37: 3.00 pm | L37: =IF(AND(J37>K37,J38>K38),2,IF(J37>K37,1,IF(J38>K38,1,0))) -> 0 | M37: =IF(AND(K37>J37,K38>J38),2,IF(K37>J37,1,IF(K38>J38,1,0))) -> 0
C40: Total Day 6B | J40: =SUM(J28:J38) -> 31 | K40: =SUM(K28:K38) -> 27 | L40: =SUM(L28:L38) -> 3 | M40: =SUM(M28:M38) -> 3
C42: Total Day 6 | J42: =J40+J25 -> 67 | K42: =K40+K25 -> 61 | L42: =L40+L25 -> 7 | M42: =M40+M25 -> 7
C44: Court 2
C46: Time | D46: Rubber | E46: TEAM D: Lucienne Meli | H46: TEAM E: Juan Debono | J46: Games | L46: Sets
C48: 6.30 pm | D48: Lad B | E48: Yanika Pace | F48: Nancy Wong | G48: vs | H48: Amanda Falzon | I48: Romina Gauci | J48: 3 | K48: 6 | L48: =IF(AND(J48>K48,J49>K49),2,IF(J48>K48,1,IF(J49>K49,1,0))) -> 1 | M48: =IF(AND(K48>J48,K49>J49),2,IF(K48>J48,1,IF(K49>J49,1,0))) -> 1
J49: 7 | K49: 5
C51: 7.45 pm | D51: Lad A | E51: Annemarie Mangion | F51: Lucienne Meli | G51: vs | H51: Leanne Vassallo | I51: Alison Muscat | J51: 3 | K51: 6 | L51: =IF(AND(J51>K51,J52>K52),2,IF(J51>K51,1,IF(J52>K52,1,0))) -> 1 | M51: =IF(AND(K51>J51,K52>J52),2,IF(K51>J51,1,IF(K52>J52,1,0))) -> 1
J52: 7 | K52: 6
C54: 9.00 pm | D54: Men A | E54: Matthew Borg | F54: Trevor Rutter | G54: vs | H54: Clyde Grech | I54: Ivan Cassar (pro Andrew Pule') | J54: 6 | K54: 2 | L54: =IF(AND(J54>K54,J55>K55),2,IF(J54>K54,1,IF(J55>K55,1,0))) -> 2 | M54: =IF(AND(K54>J54,K55>J55),2,IF(K54>J54,1,IF(K55>J55,1,0))) -> 0
J55: 6 | K55: 2
L57: =IF(AND(J57>K57,J58>K58),2,IF(J57>K57,1,IF(J58>K58,1,0))) -> 0 | M57: =IF(AND(K57>J57,K58>J58),2,IF(K57>J57,1,IF(K58>J58,1,0))) -> 0
C60: Total Day 6 A | J60: =SUM(J48:J58) -> 32 | K60: =SUM(K48:K58) -> 27 | L60: =SUM(L48:L58) -> 4 | M60: =SUM(M48:M58) -> 2
C63: 3.00 pm | D63: Men C | E63: Chalres Sacco | F63: Victor Rutter | G63: vs | H63: Jean Paul Vella | I63: Juan Sammut | J63: 4 | K63: 6 | L63: =IF(AND(J63>K63,J64>K64),2,IF(J63>K63,1,IF(J64>K64,1,0))) -> 0 | M63: =IF(AND(K63>J63,K64>J64),2,IF(K63>J63,1,IF(K64>J64,1,0))) -> 2
J64: 4 | K64: 6
C66: 5.00pm | D66: Men B | E66: David Schembri | F66: Jonathan Vella | G66: vs | H66: JP Holland | I66: Kyle Magro | J66: 6 | K66: 2 | L66: =IF(AND(J66>K66,J67>K67),2,IF(J66>K66,1,IF(J67>K67,1,0))) -> 2 | M66: =IF(AND(K66>J66,K67>J67),2,IF(K66>J66,1,IF(K67>J67,1,0))) -> 0
J67: 6 | K67: 0
C69: 5.00pm | D69: Lad C | E69: Ruth Micallef | F69: Karolina Papiernak | G69: vs | H69: Christine Seychell | I69: Christabelle Chetcuti | J69: 2 | K69: 6 | L69: =IF(AND(J69>K69,J70>K70),2,IF(J69>K69,1,IF(J70>K70,1,0))) -> 1 | M69: =IF(AND(K69>J69,K70>J70),2,IF(K69>J69,1,IF(K70>J70,1,0))) -> 1
J70: 6 | K70: 4
C72: 6.30pm | D72: Men D | E72: Antoine Bugeja | F72: Anthony Pule' | G72: vs | H72: Kenneth Caruana | I72: Robert Attard | J72: 6 | K72: 4 | L72: =IF(AND(J72>K72,J73>K73),2,IF(J72>K72,1,IF(J73>K73,1,0))) -> 2 | M72: =IF(AND(K72>J72,K73>J73),2,IF(K72>J72,1,IF(K73>J73,1,0))) -> 0
J73: 6 | K73: 4
...

Sheet Day 7
C1: SAN MICHEL TEAM TOURNAMENT 2025
C6: Day 7 - 21/03/2025 & 14/04/2025
C9: Court 1
C11: Time | D11: Rubber | E11: TEAM B: Kelsey Gauci | H11: TEAM E: Juan Sammut | J11: Games | L11: Sets
C13: 6.30 pm | D13: Lad C | E13: Tanya Cassar | F13: Jodie Stivala | G13: vs | H13: Maria Ellul | I13: Christine Seychelle | J13: 6 | K13: 2 | L13: =IF(AND(J13>K13,J14>K14),2,IF(J13>K13,1,IF(J14>K14,1,0))) -> 2 | M13: =IF(AND(K13>J13,K14>J14),2,IF(K13>J13,1,IF(K14>J14,1,0))) -> 0
J14: 6 | K14: 4
C16: 7.45 pm | D16: Men C | E16: Mattias Sciriha | F16: Aaron Micallef Piccione | G16: vs | H16: Jean Paul Vella | I16: Juan Sammut | J16: 6 | K16: 3 | L16: =IF(AND(J16>K16,J17>K17),2,IF(J16>K16,1,IF(J17>K17,1,0))) -> 2 | M16: =IF(AND(K16>J16,K17>J17),2,IF(K16>J16,1,IF(K17>J17,1,0))) -> 0
J17: 6 | K17: 4
C19: 9.00 pm | D19: Men B | E19: Clint Agius | F19: Kevin Formosa | G19: vs | H19: JP Holland | I19: Kyle Magro | J19: 2 | K19: 6 | L19: =IF(AND(J19>K19,J20>K20),2,IF(J19>K19,1,IF(J20>K20,1,0))) -> 0 | M19: =IF(AND(K19>J19,K20>J20),2,IF(K19>J19,1,IF(K20>J20,1,0))) -> 2
J20: 3 | K20: 6
C22: 8.30 pm | G22: vs | L22: =IF(AND(J22>K22,J23>K23),2,IF(J22>K22,1,IF(J23>K23,1,0))) -> 0 | M22: =IF(AND(K22>J22,K23>J23),2,IF(K22>J22,1,IF(K23>J23,1,0))) -> 0
C25: Total Day 7 A | J25: =SUM(J13:J23) -> 29 | K25: =SUM(K13:K23) -> 25 | L25: =SUM(L13:L23) -> 4 | M25: =SUM(M13:M23) -> 2
C28: 3.00 pm | D28: Men A | E28: Melchior Farrugia | F28: Keith Micallef | G28: vs | H28: Duncan D'Alessandro | I28: Clyde Grech | J28: 2 | K28: 6 | L28: =IF(AND(J28>K28,J29>K29),2,IF(J28>K28,1,IF(J29>K29,1,0))) -> 1 | M28: =IF(AND(K28>J28,K29>J29),2,IF(K28>J28,1,IF(K29>J29,1,0))) -> 1
J29: 6 | K29: 3
C31: 7.45 pm | D31: Lad A | E31: Kirsty Mercieca | F31: Rebecca Pace | G31: vs | H31: Leanne Vassallo | I31: Elaine Grech | J31: 3 | K31: 6 | L31: =IF(AND(J31>K31,J32>K32),2,IF(J31>K31,1,IF(J32>K32,1,0))) -> 0 | M31: =IF(AND(K31>J31,K32>J32),2,IF(K31>J31,1,IF(K32>J32,1,0))) -> 2
J32: 0 | K32: 6
C34: 9.00 pm | D34: Men D | E34: Matthew Micallef | F34: JP Sciberras | G34: vs | H34: Kenneth Caruana | I34: Kevin Sciberras | J34: 6 | K34: 0 | L34: =IF(AND(J34>K34,J35>K35),2,IF(J34>K34,1,IF(J35>K35,1,0))) -> 1 | M34: =IF(AND(K34>J34,K35>J35),2,IF(K34>J34,1,IF(K35>J35,1,0))) -> 1
J35: 2 | K35: 6
C37: 5.00pm | D37: Lad B | E37: Brenda Baldacchino (pro Anthea Gauci) | F37: Tanya Cassar (pro Marcette Sciriha) | G37: vs | H37: Amanda Falzon | I37: Romina Gauci | J37: 3 | K37: 6 | L37: =IF(AND(J37>K37,J38>K38),2,IF(J37>K37,1,IF(J38>K38,1,0))) -> 0 | M37: =IF(AND(K37>J37,K38>J38),2,IF(K37>J37,1,IF(K38>J38,1,0))) -> 2
J38: 2 | K38: 6
C40: Total Day 7B | J40: =SUM(J28:J38) -> 24 | K40: =SUM(K28:K38) -> 39 | L40: =SUM(L28:L38) -> 2 | M40: =SUM(M28:M38) -> 6
C42: Total Day 7 | J42: =J40+J25 -> 53 | K42: =K40+K25 -> 64 | L42: =L40+L25 -> 6 | M42: =M40+M25 -> 8
C44: Court 2
C46: Time | D46: Rubber | E46: TEAM A: Roberto Murdocco | H46: TEAM F: Francesca Sciortino | J46: Games | L46: Sets
C48: 6.30 pm | D48: Men C | E48: James Brincat | F48: Kenneth Farrugia | G48: vs | H48: Julian Esposito | I48: Matthew Schembri | J48: 6 | K48: 1 | L48: =IF(AND(J48>K48,J49>K49),2,IF(J48>K48,1,IF(J49>K49,1,0))) -> 2 | M48: =IF(AND(K48>J48,K49>J49),2,IF(K48>J48,1,IF(K49>J49,1,0))) -> 0
J49: 6 | K49: 4
C51: 7.45 pm | D51: Lad B | E51: Anabel Borg | F51: Rowena Caruana | G51: vs | H51: Francesca Sciortino | I51: Stephanie Farrugia | J51: 2 | K51: 6 | L51: =IF(AND(J51>K51,J52>K52),2,IF(J51>K51,1,IF(J52>K52,1,0))) -> 0 | M51: =IF(AND(K51>J51,K52>J52),2,IF(K51>J51,1,IF(K52>J52,1,0))) -> 2
J52: 4 | K52: 6
C54: 9.00 pm | D54: Lad A | E54: Natalya Abela | F54: Diane Fenech | G54: vs | H54: Lara Pule' | I54: Oliva Belli | J54: 3 | K54: 6 | L54: =IF(AND(J54>K54,J55>K55),2,IF(J54>K54,1,IF(J55>K55,1,0))) -> 1 | M54: =IF(AND(K54>J54,K55>J55),2,IF(K54>J54,1,IF(K55>J55,1,0))) -> 1
J55: 6 | K55: 2
C57: 7.45 pm | D57: Lad C | E57: Angele Pule' | F57: Mary Borg | G57: vs | H57: Jin Attard | I57: Daphne Vella | J57: 2 | K57: 6 | L57: =IF(AND(J57>K57,J58>K58),2,IF(J57>K57,1,IF(J58>K58,1,0))) -> 1 | M57: =IF(AND(K57>J57,K58>J58),2,IF(K57>J57,1,IF(K58>J58,1,0))) -> 1
J58: 6 | K58: 2
C60: Total Day 7 A | J60: =SUM(J48:J58) -> 35 | K60: =SUM(K48:K58) -> 33 | L60: =SUM(L48:L58) -> 4 | M60: =SUM(M48:M58) -> 4
C63: 6.30 pm | D63: Men B | E63: Roberto Murdocco | F63: Emman Xuereb | G63: vs | H63: Kristen Cachia | I63: Willem Stennkamer | J63: 3 | K63: 6 | L63: =IF(AND(J63>K63,J64>K64),2,IF(J63>K63,1,IF(J64>K64,1,0))) -> 0 | M63: =IF(AND(K63>J63,K64>J64),2,IF(K63>J63,1,IF(K64>J64,1,0))) -> 2
J64: 2 | K64: 6
C66: 9.00pm | D66: Men A | E66: Marco Mercieca | F66: David Mifsud | G66: vs | H66: Adrian Chetcuti | I66: Eric Roca | J66: 3 | K66: 6 | L66: =IF(AND(J66>K66,J67>K67),2,IF(J66>K66,1,IF(J67>K67,1,0))) -> 0 | M66: =IF(AND(K66>J66,K67>J67),2,IF(K66>J66,1,IF(K67>J67,1,0))) -> 2
J67: 2 | K67: 6
C69: 3.00 pm | D69: Men D | E69: Joseph Randich | F69: Arthur Napier | G69: vs | H69: Dunstan Vella | I69: Jason Lee Evans | J69: 4 | K69: 6 | L69: =IF(AND(J69>K69,J70>K70),2,IF(J69>K69,1,IF(J70>K70,1,0))) -> 0 | M69: =IF(AND(K69>J69,K70>J70),2,IF(K69>J69,1,IF(K70>J70,1,0))) -> 2
J70: 0 | K70: 6
C72: 7.00 pm | D72: Lad A | L72: =IF(AND(J72>K72,J73>K73),2,IF(J72>K72,1,IF(J73>K73,1,0))) -> 0 | M72: =IF(AND(K72>J72,K73>J73),2,IF(K72>J72,1,IF(K73>J73,1,0))) -> 0
...

Sheet Day 8
C1: SAN MICHEL TEAM TOURNAMENT 2025
C6: Day 8 - 04/04/2025 & 05/04/2025
C9: Court 1
C11: Time | D11: Rubber | E11: TEAM C: Gabriel Pace | H11: TEAM F: Francesca Sciortino | J11: Games | L11: Sets
C13: 6.30 pm | D13: Lad B | E13: Julie Spiteri | F13: Deborah Farrugia | G13: vs | H13: Francesca Sciortino | I13: Mariksa Steenkamer | J13: 3 | K13: 6 | L13: =IF(AND(J13>K13,J14>K14),2,IF(J13>K13,1,IF(J14>K14,1,0))) -> 0 | M13: =IF(AND(K13>J13,K14>J14),2,IF(K13>J13,1,IF(K14>J14,1,0))) -> 2
J14: 2 | K14: 6
C16: 7.45 pm | D16: Lad A | E16: Marina Cuschieri | F16: Kaya Sammut | G16: vs | H16: Renette Magro | I16: Lara Pule' | J16: 1 | K16: 6 | L16: =IF(AND(J16>K16,J17>K17),2,IF(J16>K16,1,IF(J17>K17,1,0))) -> 0 | M16: =IF(AND(K16>J16,K17>J17),2,IF(K16>J16,1,IF(K17>J17,1,0))) -> 2
J17: 2 | K17: 6
C19: 9.00 pm | D19: Men B | E19: Jonathan Martinelli | F19: Gene Zammit | G19: vs | H19: Jayboy Lastimosa | I19: Willem Steenkamer | J19: 2 | K19: 6 | L19: =IF(AND(J19>K19,J20>K20),2,IF(J19>K19,1,IF(J20>K20,1,0))) -> 0 | M19: =IF(AND(K19>J19,K20>J20),2,IF(K19>J19,1,IF(K20>J20,1,0))) -> 2
J20: 2 | K20: 6
C22: 7.00 pm | G22: vs | L22: =IF(AND(J22>K22,J23>K23),2,IF(J22>K22,1,IF(J23>K23,1,0))) -> 0 | M22: =IF(AND(K22>J22,K23>J23),2,IF(K22>J22,1,IF(K23>J23,1,0))) -> 0
C25: Total Day 8 A | J25: =SUM(J13:J23) -> 12 | K25: =SUM(K13:K23) -> 36 | L25: =SUM(L13:L23) -> 0 | M25: =SUM(M13:M23) -> 6
C28: 3.30 pm | D28: Men A | E28: Matthew Mifsud | F28: Gabriel Pace | G28: vs | H28: Adrian Chetcuti | I28: Kristen Cachia (pro Jean Attard) | J28: 6 | K28: 7 | L28: =IF(AND(J28>K28,J29>K29),2,IF(J28>K28,1,IF(J29>K29,1,0))) -> 1 | M28: =IF(AND(K28>J28,K29>J29),2,IF(K28>J28,1,IF(K29>J29,1,0))) -> 1
J29: 6 | K29: 3
C31: 3.30 pm | D31: Men D | E31: Conrad Treeby Ward | F31: Cory Greenland | G31: vs | H31: Dunstan Vella | I31: Jason Lee Evans | J31: 2 | K31: 6 | L31: =IF(AND(J31>K31,J32>K32),2,IF(J31>K31,1,IF(J32>K32,1,0))) -> 1 | M31: =IF(AND(K31>J31,K32>J32),2,IF(K31>J31,1,IF(K32>J32,1,0))) -> 1
J32: 6 | K32: 2
C34: 5.00 pm | D34: Men C | E34: Etieene Formosa Carabez | F34: steve Gambin | G34: vs | H34: Julian Esposito | I34: Maurice Borg | J34: 6 | K34: 7 | L34: =IF(AND(J34>K34,J35>K35),2,IF(J34>K34,1,IF(J35>K35,1,0))) -> 1 | M34: =IF(AND(K34>J34,K35>J35),2,IF(K34>J34,1,IF(K35>J35,1,0))) -> 1
J35: 7 | K35: 5
C37: 6.30 pm | D37: Lad C | E37: Maria Angela Gambin | F37: Janice Galea | G37: vs | H37: Jennifer Roca | I37: Daphne Vella | J37: 6 | K37: 1 | L37: =IF(AND(J37>K37,J38>K38),2,IF(J37>K37,1,IF(J38>K38,1,0))) -> 2 | M37: =IF(AND(K37>J37,K38>J38),2,IF(K37>J37,1,IF(K38>J38,1,0))) -> 0
J38: 7 | K38: 5
C40: Total Day 8 B | J40: =SUM(J28:J38) -> 46 | K40: =SUM(K28:K38) -> 36 | L40: =SUM(L28:L38) -> 5 | M40: =SUM(M28:M38) -> 3
C42: Total Day 8 | J42: =J40+J25 -> 58 | K42: =K40+K25 -> 72 | L42: =L40+L25 -> 5 | M42: =M40+M25 -> 9
C44: Court 2
C46: Time | D46: Rubber | E46: TEAM D: Lucienne Meli | H46: TEAM B: Kelsey Gauci | J46: Games | L46: Sets
