Workbook

Sheet Team Selection
A1: VITTORIOSA LAWN TENNIS CLUB
A2: SAN MICHEL TEAM TOURNAMENT - 2026
B4: TEAM A | C4: TEAM B | D4: TEAM C | E4: TEAM D | F4: TEAM E | G4: TEAM F
A5: CAPTAIN | B5: Christine Scerri | C5: Cory Greenland | D5: Jean Paul Sciberras | E5: Juan Sammut | F5: Roberto Murdocco | G5: Diane Fenech
A6: MEN
A7: A1 | B7: Clayton Zammit Cesare | C7: Gareth Magri | D7: Matthew Pace | E7: Duncan D'Alessandro | F7: Trevor Rutter | G7: Kurt Carabott
A8: A2 | B8: Andrew Pule' | C8: Fotios Evangelou | D8: Manuel Bonello | E8: Jesmond Pule' | F8: Marco Mercieca | G8: Jean Attard
A9: A3 | B9: Jonathan Martinelli | C9: Javier Viloria | D9: Peter Khiev | E9: David Mifsud | F9: Ivan Cachia | G9: Andrew Spiteri Willets
A11: B1 | B11: Cyril Lastimosa | C11: Kristen Cachia | D11: Jonathan Vella | E11: David Schembri | F11: Emman Xuereb | G11: Sergey Kasatkin
A12: B2 | B12: Clint Agius | C12: Ivan Cassar | D12: Willlem Steenkamer | E12: George Grech | F12: Luke Genuis | G12: Richard Curmi
A13: B3 | B13: Sandro Pecorella | C13: Tobias Kristensen | D13: Jean Paul Vella | E13: Jurgen Farrugia | F13: Roberto Murdocco | G13: Steve Gambin
A15: C1 | B15: Alain Frendo | C15: Kenneth Farrugia | D15: Matthew Schembri | E15: Etienne Formosa Carabez | F15: Max Anastasi | G15: Julian Esposito
A16: C2 | B16: Charles Sacco | C16: Manuel Mifsud | D16: Jason Lee Evans | E16: Juan Sammut | F16: Jordan Lastimosa | G16: Simone Re
A17: C3 | B17: Redent Scicluna | C17: Cory Greenland | D17: Jean Paul Sciberras | E17: Sam Micallef | F17: Aaron Micallef Piccone | G17: Dunstan Vella
A19: D1 | B19: Daniele Privitera | C19: David Camilleri | D19: Kenneth Caruana | E19: Joseph Randich | F19: Matthias Cremona | G19: Ryan Ebejer
A20: D2 | B20: Antoine Bugeja | C20: Matthew Napier | D20: Kevin Sciberras | E20: Clifford Debono | F20: Braydon Galea | G20: Clinton Cutajar
A21: D3 | B21: Dorian Demanuele | C21: Mario Abdilla | D21: Alberto Bafumi | E21: Owen Farrugia | F21: Oliver Brincat | G21: Robert Attard
A23: LADIES
A24: A1 | B24: Amanda Falzon | C24: Christine Schembri | D24: Alexia Spiteri Willets | E24: Leanne Vassallo | F24: AnnMarie Mangion | G24: Renette Magro
A25: A2 | B25: Kirsty Mercieca | C25: Kaya Sammut | D25: Lucienne Meli | E25: Alison Muscat | F25: Elaine Grech | G25: Christina Bonett
A26: A3 | B26: Yanika Pace | C26: Kelsey Gauci | D26: Olivia Belli | E26: Louise Qi | F26: Mae Jane Manzanares | G26: Anthea Gauci
A28: B1 | B28: Silvana Portelli | C28: Andrea Magaldi | D28: Kristina Briffa | E28: Anabel Borg | F28: Dorianne Buhagiar | G28: Maria Angela Gambin
A29: B2 | B29: Deborah Farrugia | C29: Giada Sciberras | D29: Brenda Baldacchino | E29: Sue Stevenson | F29: Nancy Wong | G29: Ann-Marie Attard
A30: B3 | B30: Tiffany Fenech | C30: Sabrina Xuereb | D30: Jade Sammut | E30: Sarah Axiaq | F30: Mariska Steenkamer | G30: Romina Gauci
A32: C1 | B32: Janice Galea | C32: Karolina Papiernik | D32: Francesca Mamo | E32: Frances Saliba Hersey | F32: Leanne Sammut | G32: Tiziana Spiteri
A33: C2 | B33: Josette Cassar | C33: Alida Borg | D33: Jodie Stivala | E33: Jennifer Roca | F33: Maria Ellul | G33: Daphne Vella
A34: C3 | B34: Christine Scerri | C34: Christabel Chetcuti | D34: Brenda Bugeja | E34: Mary Borg | F34: Roberta Grixti | G34: Kim Bonello

Sheet Encounters Played
B1: VITTORIOSA LAWN TENNIS CLUB
B2: SAN MICHEL TEAM TOURNAMENT - 2026
A5: A | B5: Christine Scerri | C5: Day 1 | D5: Day 2 | E5: Day 3 | F5: Day 4 | G5: Day 5 | H5: Day 6 | I5: Day 7 | J5: Day 8 | K5: Day 9 | L5: Day 10 | M5: TOTAL
A6: A1 | B6: Clayton Zammit Cesare | C6: 1 | D6: 1 | E6: 1 | G6: 1 | H6: 1 | I6: 1 | K6: 1 | L6: 1 | M6: =SUM(C6:L6) -> 8
A7: A2 | B7: Andrew Pule' | C7: 1 | E7: 1 | F7: 1 | H7: 1 | J7: 1 | K7: 1 | M7: =SUM(C7:L7) -> 6
A8: A3 | B8: Jonathan Martinelli | D8: 1 | F8: 1 | G8: 1 | I8: 1 | J8: 1 | L8: 1 | M8: =SUM(C8:L8) -> 6
A9: B1 | B9: Cyril Lastimosa | C9: 1 | D9: 1 | E9: 1 | F9: 1 | G9: 1 | H9: 1 | K9: 1 | L9: 1 | M9: =SUM(C9:L9) -> 8
A10: B2 | B10: Clint Agius | C10: 1 | E10: 1 | F10: 1 | H10: 1 | I10: 1 | J10: 1 | M10: =SUM(C10:L10) -> 6
A11: B3 | B11: Sandro Pecorella | D11: 1 | G11: 1 | I11: 1 | J11: 1 | K11: 1 | L11: 1 | M11: =SUM(C11:L11) -> 6
A12: C1 | B12: Alain Frendo | C12: 1 | D12: 1 | F12: 1 | G12: 1 | H12: 1 | I12: 1 | J12: 1 | L12: 1 | M12: =SUM(C12:L12) -> 8
A13: C2 | B13: Charles Sacco | C13: 1 | E13: 1 | F13: 1 | G13: 1 | I13: 1 | K13: 1 | M13: =SUM(C13:L13) -> 6
A14: C3 | B14: Redent Scicluna | D14: 1 | E14: 1 | H14: 1 | J14: 1 | K14: 1 | L14: 1 | M14: =SUM(C14:L14) -> 6
A15: D1 | B15: Daniele Privitera | D15: 1 | F15: 1 | G15: 1 | H15: 1 | I15: 1 | J15: 1 | L15: 1 | M15: =SUM(C15:L15) -> 7
A16: D2 | B16: Antoine Bugeja | C16: 1 | E16: 1 | F16: 1 | H16: 1 | J16: 1 | K16: 1 | L16: 1 | M16: =SUM(C16:L16) -> 7
A17: D3 | B17: Dorian Demanuele | C17: 1 | D17: 1 | E17: 1 | G17: 1 | I17: 1 | K17: 1 | M17: =SUM(C17:L17) -> 6
A18: A1 | B18: Amanda Falzon | D18: 1 | E18: 1 | F18: 1 | G18: 1 | H18: 1 | I18: 1 | K18: 1 | L18: 1 | M18: =SUM(C18:L18) -> 8
A19: A2 | B19: Kirsty Mercieca | C19: 1 | D19: 1 | F19: 1 | H19: 1 | J19: 1 | L19: 1 | M19: =SUM(C19:L19) -> 6
A20: A3 | B20: Yanika Pace | C20: 1 | E20: 1 | G20: 1 | I20: 1 | J20: 1 | K20: 1 | M20: =SUM(C20:L20) -> 6
A21: B1 | B21: Silvana Portelli | C21: 1 | D21: 1 | F21: 1 | G21: 1 | H21: 1 | J21: 1 | K21: 1 | L21: 1 | M21: =SUM(C21:L21) -> 8
A22: B2 | B22: Deborah Farrugia | C22: 1 | E22: 1 | H22: 1 | I22: 1 | K22: 1 | L22: 1 | M22: =SUM(C22:L22) -> 6
A23: B3 | B23: Tiffany Fenech | D23: 1 | E23: 1 | F23: 1 | G23: 1 | I23: 1 | J23: 1 | M23: =SUM(C23:L23) -> 6
A24: C1 | B24: Janice Galea | C24: 1 | D24: 1 | F24: 1 | G24: 1 | H24: 1 | L24: 1 | M24: =SUM(C24:L24) -> 6
A25: C2 | B25: Josette Cassar | C25: 1 | E25: 1 | F25: 1 | I25: 1 | J25: 1 | K25: 1 | M25: =SUM(C25:L25) -> 6
A26: C3 | B26: Christine Scerri | D26: 1 | E26: 1 | G26: 1 | H26: 1 | I26: 1 | J26: 1 | K26: 1 | L26: 1 | M26: =SUM(C26:L26) -> 8
A28: B | B28: Cory Greenland | C28: Day 1 | D28: Day 2 | E28: Day 3 | F28: Day 4 | G28: Day 5 | H28: Day 6 | I28: Day 7 | J28: Day 8 | K28: Day 9 | L28: Day 10 | M28: TOTAL
A29: A1 | B29: Gareth Magri | C29: 1 | E29: 1 | F29: 1 | G29: 1 | H29: 1 | I29: 1 | J29: 1 | K29: 1 | M29: =SUM(C29:L29) -> 8
A30: A2 | B30: Fotios Evangelou | C30: 1 | D30: 1 | F30: 1 | G30: 1 | I30: 1 | L30: 1 | M30: =SUM(C30:L30) -> 6
A31: A3 | B31: Javier Viloria | D31: 1 | E31: 1 | H31: 1 | J31: 1 | K31: 1 | L31: 1 | M31: =SUM(C31:L31) -> 6
A32: B1 | B32: Kristen Cachia | D32: 1 | E32: 1 | G32: 1 | H32: 1 | I32: 1 | J32: 1 | K32: 1 | L32: 1 | M32: =SUM(C32:L32) -> 8
A33: B2 | B33: Ivan Cassar | C33: 1 | D33: 1 | F33: 1 | G33: 1 | J33: 1 | L33: 1 | M33: =SUM(C33:L33) -> 6
A34: B3 | B34: Tobias Kristensen | C34: 1 | E34: 1 | F34: 1 | H34: 1 | I34: 1 | K34: 1 | M34: =SUM(C34:L34) -> 6
A35: C1 | B35: Kenneth Farrugia | C35: 1 | E35: 1 | F35: 1 | G35: 1 | H35: 1 | I35: 1 | J35: 1 | K35: 1 | M35: =SUM(C35:L35) -> 8
A36: C2 | B36: Manuel Mifsud | C36: 1 | D36: 1 | E36: 1 | H36: 1 | J36: 1 | L36: 1 | M36: =SUM(C36:L36) -> 6
A37: C3 | B37: Cory Greenland | D37: 1 | F37: 1 | G37: 1 | I37: 1 | K37: 1 | L37: 1 | M37: =SUM(C37:L37) -> 6
A38: D1 | B38: David Camilleri | C38: 1 | E38: 1 | F38: 1 | G38: 1 | H38: 1 | I38: 1 | J38: 1 | L38: 1 | M38: =SUM(C38:L38) -> 8
A39: D2 | B39: Matthew Napier | C39: 1 | D39: 1 | F39: 1 | H39: 1 | K39: 1 | L39: 1 | M39: =SUM(C39:L39) -> 6
A40: D3 | B40: Mario Abdilla | D40: 1 | E40: 1 | G40: 1 | I40: 1 | J40: 1 | K40: 1 | M40: =SUM(C40:L40) -> 6
A41: A1 | B41: Christine Schembri | D41: 1 | E41: 1 | F41: 1 | G41: 1 | H41: 1 | I41: 1 | J41: 1 | L41: 1 | M41: =SUM(C41:L41) -> 8
A42: A2 | B42: Kaya Sammut | C42: 1 | E42: 1 | G42: 1 | I42: 1 | J42: 1 | K42: 1 | M42: =SUM(C42:L42) -> 6
A43: A3 | B43: Kelsey Gauci | C43: 1 | D43: 1 | F43: 1 | H43: 1 | K43: 1 | L43: 1 | M43: =SUM(C43:L43) -> 6
...

Sheet Standings
B1: VITTORIOSA LAWN TENNIS CLUB
B2: SAN MICHEL TEAM TOURNAMENT - 2026
C7: ROUND 1
D9: Day 1 | F9: Total Day 1 | I9: Day 2 | K9: Total Day 2 | N9: Day 3 | P9: Total Day 3 | S9: Day 4 | U9: Total Day 4 | X9: Day 5 | Z9: Total Day 5 | AC9: Total Round 1
D10: G | E10: S | F10: G | G10: S | I10: G | J10: S | K10: G | L10: S | N10: G | O10: S | P10: G | Q10: S | S10: G | T10: S | U10: G | V10: S | X10: G | Y10: S | Z10: G | AA10: S | AC10: G | AD10: S
B12: TEAM A: Christine Scerri | C12: Fri | D12: ='Day 1'!J25 -> 40 | E12: ='Day 1'!L25 -> 4 | F12: =D12+D13 -> 66 | G12: =SUM(E12+E13) -> 5 | I12: ='Day 2 '!J60 -> 47 | J12: ='Day 2 '!L60 -> 7 | K12: =I12+I13 -> 67 | L12: =J12+J13 -> 8 | N12: ='Day 3'!J95 -> 25 | O12: ='Day 3'!L95 -> 3 | P12: =N12+N13 -> 60 | Q12: =O12+O13 -> 5 | S12: ='Day 4'!J95 -> 30 | T12: ='Day 4'!L95 -> 2 | U12: =S12+S13 -> 49 | V12: =T12+T13 -> 3 | X12: ='Day 5'!J25 -> 37 | Y12: ='Day 5'!L25 -> 6 | Z12: =X12+X13 -> 76 | AA12: =Y12+Y13 -> 9 | AC12: =D12+D13+I12+I13+N12+N13+S12+S13+X12+X13 -> 318 | AD12: =SUM(G12+G13+L12+L13+Q12+Q13+V12+V13+AA12+AA13) -> 30
C13: Sat | D13: ='Day 1'!J40 -> 26 | E13: ='Day 1'!L40 -> 1 | I13: ='Day 2 '!J75 -> 20 | J13: ='Day 2 '!L75 -> 1 | N13: ='Day 3'!J110 -> 35 | O13: ='Day 3'!L110 -> 2 | S13: ='Day 4'!J110 -> 19 | T13: ='Day 4'!L110 -> 1 | X13: ='Day 5'!J40 -> 39 | Y13: ='Day 5'!L40 -> 3
B15: TEAM B: Cory Greenland | C15: Fri | D15: ='Day 1'!J95 -> 36 | E15: ='Day 1'!L95 -> 5 | F15: =SUM(D15+D16) -> 68 | G15: =SUM(E15:E16) -> 7 | I15: ='Day 2 '!J25 -> 42 | J15: ='Day 2 '!L25 -> 4 | K15: =SUM(I15+I16) -> 68 | L15: =SUM(J15+J16) -> 6 | N15: ='Day 3'!K60 -> 41 | O15: ='Day 3'!M60 -> 3 | P15: =SUM(N15+N16) -> 73 | Q15: =SUM(O15+O16) -> 7 | S15: ='Day 4'!K95 -> 41 | T15: ='Day 4'!M95 -> 6 | U15: =SUM(S15+S16) -> 75 | V15: =T15+T16 -> 11 | X15: ='Day 5'!J60 -> 41 | Y15: ='Day 5'!L60 -> 5 | Z15: =SUM(X15+X16) -> 70 | AA15: =SUM(Y15+Y16) -> 8 | AC15: =D15+D16+I15+I16+N15+N16+S15+S16+X15+X16 -> 354 | AD15: =SUM(G15+G16+L15+L16+Q15+Q16+V15+V16+AA15+AA16) -> 39
C16: Sat | D16: ='Day 1'!J110 -> 32 | E16: ='Day 1'!L110 -> 2 | I16: ='Day 2 '!J40 -> 26 | J16: ='Day 2 '!L40 -> 2 | N16: ='Day 3'!K75 -> 32 | O16: ='Day 3'!M75 -> 4 | S16: ='Day 4'!K110 -> 34 | T16: ='Day 4'!M110 -> 5 | X16: ='Day 5'!J75 -> 29 | Y16: ='Day 5'!L75 -> 3
B18: TEAM C: Jean Paul Sciberras | C18: Fri | D18: ='Day 1'!K25 -> 33 | E18: ='Day 1'!M25 -> 4 | F18: =D18+D19 -> 69 | G18: =E18+E19 -> 9 | I18: ='Day 2 '!J95 -> 46 | J18: ='Day 2 '!L95 -> 6 | K18: =I18+I19 -> 69 | L18: =J18+J19 -> 8 | N18: ='Day 3'!J25 -> 34 | O18: ='Day 3'!L25 -> 2 | P18: =N18+N19 -> 53 | Q18: =O18+O19 -> 3 | S18: ='Day 4'!J60 -> 31 | T18: ='Day 4'!L60 -> 4 | U18: =S18+S19 -> 53 | V18: =T18+T19 -> 6 | X18: ='Day 5'!K60 -> 31 | Y18: ='Day 5'!M60 -> 3 | Z18: =X18+X19 -> 59 | AA18: =SUM(Y18+Y19) -> 6 | AC18: =D18+D19+I18+I19+N18+N19+S18+S19+X18+X19 -> 303 | AD18: =SUM(E18+E19+J18+J19+O18+O19+T18+T19+Y18+Y19) -> 32
C19: Sat | D19: ='Day 1'!K40 -> 36 | E19: ='Day 1'!M40 -> 5 | I19: ='Day 2 '!J110 -> 23 | J19: ='Day 2 '!L110 -> 2 | N19: ='Day 3'!J40 -> 19 | O19: ='Day 3'!L40 -> 1 | S19: ='Day 4'!J75 -> 22 | T19: ='Day 4'!L75 -> 2 | X19: ='Day 5'!K75 -> 28 | Y19: ='Day 5'!M75 -> 3
B21: TEAM D: Juan Sammut | C21: Fri | D21: ='Day 1'!J60 -> 26 | E21: ='Day 1'!L60 -> 1 | F21: =D21+D22 -> 52 | G21: =SUM(E21+E22) -> 4 | I21: ='Day 2 '!K95 -> 28 | J21: ='Day 2 '!M95 -> 2 | K21: =I21+I22 -> 56 | L21: =J21+J22 -> 6 | N21: ='Day 3'!J60 -> 43 | O21: ='Day 3'!L60 -> 5 | P21: =N21+N22 -> 68 | Q21: =O21+O22 -> 7 | S21: ='Day 4'!J25 -> 35 | T21: ='Day 4'!L25 -> 4 | U21: =S21+S22 -> 72 | V21: =T21+T22 -> 9 | X21: ='Day 5'!K25 -> 13 | Y21: ='Day 5'!M25 -> 0 | Z21: =X21+X22 -> 55 | AA21: =SUM(Y21+Y22) -> 5 | AC21: =D21+D22+I21+I22+N21+N22+S21+S22+X21+X22 -> 303 | AD21: =SUM(E21+E22+J21+J22+O21+O22+T21+T22+Y21+Y22) -> 31
C22: Sat | D22: ='Day 1'!J75 -> 26 | E22: ='Day 1'!L75 -> 3 | I22: ='Day 2 '!K110 -> 28 | J22: ='Day 2 '!M110 -> 4 | N22: ='Day 3'!J75 -> 25 | O22: ='Day 3'!L75 -> 2 | S22: ='Day 4'!J40 -> 37 | T22: ='Day 4'!L40 -> 5 | X22: ='Day 5'!K40 -> 42 | Y22: ='Day 5'!M40 -> 5
B24: TEAM E: Roberto Murdocco | C24: Fri | D24: ='Day 1'!K60 -> 45 | E24: ='Day 1'!M60 -> 7 | F24: =D24+D25 -> 72 | G24: =E24+E25 -> 10 | I24: ='Day 2 '!K25 -> 36 | J24: ='Day 2 '!M25 -> 4 | K24: =I24+I25 -> 66 | L24: =J24+J25 -> 8 | N24: ='Day 3'!K95 -> 27 | O24: ='Day 3'!M95 -> 3 | P24: =N24+N25 -> 67 | Q24: =O24+O25 -> 9 | S24: ='Day 4'!K60 -> 35 | T24: ='Day 4'!M60 -> 4 | U24: =S24+S25 -> 68 | V24: =T24+T25 -> 8 | X24: ='Day 5'!J95 -> 40 | Y24: ='Day 5'!L95 -> 4 | Z24: =X24+X25 -> 75 | AA24: =Y24+Y25 -> 9 | AC24: =D24+D25+I24+I25+N24+N25+S24+S25+X24+X25 -> 348 | AD24: =E24+E25+J24+J25+O24+O25+T24+T25+Y24+Y25 -> 44
C25: Sat | D25: ='Day 1'!K75 -> 27 | E25: ='Day 1'!M75 -> 3 | I25: ='Day 2 '!K40 -> 30 | J25: ='Day 2 '!M40 -> 4 | N25: ='Day 3'!K110 -> 40 | O25: ='Day 3'!M110 -> 6 | S25: ='Day 4'!K75 -> 33 | T25: ='Day 4'!M75 -> 4 | X25: ='Day 5'!J110 -> 35 | Y25: ='Day 5'!L110 -> 5
B27: TEAM F: Diane Fenech | C27: Fri | D27: ='Day 1'!K95 -> 25 | E27: ='Day 1'!M95 -> 3 | F27: =D27+D28 -> 59 | G27: =E27+E28 -> 7 | I27: ='Day 2 '!K60 -> 33 | J27: ='Day 2 '!M60 -> 1 | K27: =I27+I28 -> 65 | L27: =J27+J28 -> 6 | N27: ='Day 3'!K25 -> 40 | O27: ='Day 3'!M25 -> 6 | P27: =N27+N28 -> 74 | Q27: =O27+O28 -> 11 | S27: ='Day 4'!K25 -> 26 | T27: ='Day 4'!M25 -> 2 | U27: =S27+S28 -> 57 | V27: =SUM(T27+T28) -> 5 | X27: ='Day 5'!K95 -> 40 | Y27: ='Day 5'!M95 -> 4 | Z27: =X27+X28 -> 67 | AA27: =Y27+Y28 -> 5 | AC27: =D27+D28+I27+I28+N27+N28+S27+S28+X27+X28 -> 322 | AD27: =E27+E28+J27+J28+O27+O28+T27+T28+Y27+Y28 -> 34
C28: Sat | D28: ='Day 1'!K110 -> 34 | E28: ='Day 1'!M110 -> 4 | I28: ='Day 2 '!K75 -> 32 | J28: ='Day 2 '!M75 -> 5 | N28: ='Day 3'!K40 -> 34 | O28: ='Day 3'!M40 -> 5 | S28: ='Day 4'!K40 -> 31 | T28: ='Day 4'!M40 -> 3 | X28: ='Day 5'!K110 -> 27 | Y28: ='Day 5'!M110 -> 1
C31: ROUND 2
D33: Day 6 | F33: Total Day 6 | I33: Day 7 | K33: Total Day 7 | N33: Day 8 | P33: Total Day 8 | S33: Day 9 | U33: Total Day 9 | X33: Day 10 | Z33: Total Day 10 | AC33: Total Rounds 1 & 2
D34: G | E34: S | F34: G | G34: S | I34: G | J34: S | K34: G | L34: S | N34: G | O34: S | P34: G | Q34: S | S34: G | T34: S | U34: G | V34: S | X34: G | Y34: S | Z34: G | AA34: S | AC34: G | AD34: S
B36: TEAM A: Christine Scerri | C36: Fri | D36: ='Day 6'!J25 -> 40 | E36: ='Day 6'!L25 -> 5 | F36: =SUM(D36+D37) -> 77 | G36: =SUM(E36+E37) -> 11 | I36: ='Day 7'!J60 -> 24 | J36: ='Day 7'!L60 -> 3 | K36: =I36+I37 -> 46 | L36: =J36+J37 -> 3 | N36: ='Day 8'!J95 -> 26 | O36: ='Day 8'!L95 -> 2 | P36: =N36+N37 -> 58 | Q36: =O36+O37 -> 4 | S36: =SUM('Day 9'!J95) -> 28 | T36: =SUM('Day 9'!L95) -> 2 | U36: =S36+S37 -> 54 | V36: =T36+T37 -> 5 | X36: =SUM('Day 10'!J25) -> 31 | Y36: =SUM('Day 10'!L25) -> 4 | Z36: =X36+X37 -> 67 | AA36: =Y36+Y37 -> 6 | AC36: =SUM(AC12+AC13+F36+F37+K36+K37+P36+P37+U36+U37+Z36+Z37) -> 620 | AD36: =SUM(AD12+G36+L36+Q36+V36+AA36) -> 59
C37: Sat | D37: ='Day 6'!J40 -> 37 | E37: ='Day 6'!L40 -> 6 | I37: ='Day 7'!J75 -> 22 | J37: ='Day 7'!L75 -> 0 | N37: ='Day 8'!J110 -> 32 | O37: ='Day 8'!L110 -> 2 | S37: =SUM('Day 9'!J110) -> 26 | T37: =SUM('Day 9'!L110) -> 3 | X37: =SUM('Day 10'!J40) -> 36 | Y37: =SUM('Day 10'!L40) -> 2
B39: TEAM B: Cory Greenland | C39: Fri | D39: ='Day 6'!J95 -> 39 | E39: ='Day 6'!L95 -> 4 | F39: =SUM(D39+D40) -> 78 | G39: =SUM(E39+E40) -> 9 | I39: ='Day 7'!J25 -> 37 | J39: ='Day 7'!L25 -> 4 | K39: =I39+I40 -> 72 | L39: =J39+J40 -> 7 | N39: ='Day 8'!K60 -> 36 | O39: ='Day 8'!M60 -> 6 | P39: =N39+N40 -> 81 | Q39: =O39+O40 -> 10 | S39: =SUM('Day 9'!K95) -> 42 | T39: =SUM('Day 9'!M95) -> 6 | U39: =S39+S40 -> 74 | V39: =T39+T40 -> 9 | X39: =SUM('Day 10'!J60) -> 29 | Y39: =SUM('Day 10'!L60) -> 4 | Z39: =X39+X40 -> 66 | AA39: =Y39+Y40 -> 8 | AC39: =SUM(AC15+AC16+F39+F40+K39+K40+P39+P40+U39+U40+Z39+Z40) -> 725 | AD39: =SUM(AD15+G39+L39+Q39+V39+AA39) -> 82
C40: Sat | D40: ='Day 6'!J110 -> 39 | E40: ='Day 6'!L110 -> 5 | I40: ='Day 7'!J40 -> 35 | J40: ='Day 7'!L40 -> 3 | N40: ='Day 8'!K75 -> 45 | O40: ='Day 8'!M75 -> 4 | S40: =SUM('Day 9'!K110) -> 32 | T40: =SUM('Day 9'!M110) -> 3 | X40: =SUM('Day 10'!J75) -> 37 | Y40: =SUM('Day 10'!L75) -> 4
B42: TEAM C: Jean Paul Sciberras | C42: Fri | D42: ='Day 6'!K25 -> 33 | E42: ='Day 6'!M25 -> 3 | F42: =SUM(D42+D43) -> 48 | G42: =SUM(E42+E43) -> 3 | I42: ='Day 7'!J95 -> 32 | J42: ='Day 7'!L95 -> 3 | K42: =I42+I43 -> 78 | L42: =J42+J43 -> 8 | N42: ='Day 8'!J25 -> 46 | O42: ='Day 8'!L25 -> 6 | P42: =N42+N43 -> 74 | Q42: =O42+O43 -> 9 | S42: =SUM('Day 9'!J60) -> 36 | T42: =SUM('Day 9'!L60) -> 5 | U42: =S42+S43 -> 60 | V42: =T42+T43 -> 6 | X42: =SUM('Day 10'!K60) -> 28 | Y42: =SUM('Day 10'!M60) -> 2 | Z42: =X42+X43 -> 62 | AA42: =Y42+Y43 -> 6 | AC42: =SUM(AC18+AC19+F42+F43+K42+K43+P42+P43+U42+U43+Z42+Z43) -> 625 | AD42: =SUM(AD18+G42+L42+Q42+V42+AA42) -> 64
C43: Sat | D43: ='Day 6'!K40 -> 15 | E43: ='Day 6'!M40 -> 0 | I43: ='Day 7'!J110 -> 46 | J43: ='Day 7'!L110 -> 5 | N43: ='Day 8'!J40 -> 28 | O43: ='Day 8'!L40 -> 3 | S43: =SUM('Day 9'!J75) -> 24 | T43: =SUM('Day 9'!L75) -> 1 | X43: =SUM('Day 10'!K75) -> 34 | Y43: =SUM('Day 10'!M75) -> 4
B45: TEAM D: Juan Sammut | C45: Fri | D45: ='Day 6'!J60 -> 17 | E45: ='Day 6'!L60 -> 1 | F45: =SUM(D45+D46) -> 44 | G45: =SUM(E45+E46) -> 3 | I45: ='Day 7'!K95 -> 33 | J45: ='Day 7'!M95 -> 3 | K45: =I45+I46 -> 75 | L45: =J45+J46 -> 6 | N45: ='Day 8'!J60 -> 9 | O45: ='Day 8'!L60 -> 0 | P45: =N45+N46 -> 46 | Q45: =O45+O46 -> 4 | S45: =SUM('Day 9'!J25) -> 29 | T45: =SUM('Day 9'!L25) -> 3 | U45: =S45+S46 -> 55 | V45: =T45+T46 -> 6 | X45: =SUM('Day 10'!K25) -> 27 | Y45: =SUM('Day 10'!M25) -> 2 | Z45: =X45+X46 -> 69 | AA45: =Y45+Y46 -> 8 | AC45: =SUM(AC21+AC22+F45+F46+K45+K46+P45+P46+U45+U46+Z45+Z46) -> 592 | AD45: =SUM(AD21+G45+L45+Q45+V45+AA45) -> 58
C46: Sat | D46: ='Day 6'!J75 -> 27 | E46: ='Day 6'!L75 -> 2 | I46: ='Day 7'!K110 -> 42 | J46: ='Day 7'!M110 -> 3 | N46: ='Day 8'!J75 -> 37 | O46: ='Day 8'!L75 -> 4 | S46: =SUM('Day 9'!J40) -> 26 | T46: =SUM('Day 9'!L40) -> 3 | X46: =SUM('Day 10'!K40) -> 42 | Y46: =SUM('Day 10'!M40) -> 6
B48: TEAM E: Roberto Murdocco | C48: Fri | D48: ='Day 6'!K60 -> 33 | E48: ='Day 6'!M60 -> 5 | F48: =SUM(D48+D49) -> 77 | G48: =SUM(E48+E49) -> 11 | I48: ='Day 7'!K25 -> 29 | J48: ='Day 7'!M25 -> 2 | K48: =I48+I49 -> 65 | L48: =J48+J49 -> 7 | N48: ='Day 8'!K95 -> 31 | O48: ='Day 8'!M95 -> 4 | P48: =N48+N49 -> 77 | Q48: =O48+O49 -> 10 | S48: =SUM('Day 9'!K60) -> 25 | T48: =SUM('Day 9'!M60) -> 1 | U48: =S48+S49 -> 71 | V48: =T48+T49 -> 8 | X48: =SUM('Day 10'!J95) -> 25 | Y48: =SUM('Day 10'!L95) -> 2 | Z48: =X48+X49 -> 60 | AA48: =Y48+Y49 -> 6 | AC48: =SUM(AC24+AC25+F48+F49+K48+K49+P48+P49+U48+U49+Z48+Z49) -> 698 | AD48: =SUM(AD24+G48+L48+Q48+V48+AA48) -> 86
C49: Sat | D49: ='Day 6'!K75 -> 44 | E49: ='Day 6'!M75 -> 6 | I49: ='Day 7'!K40 -> 36 | J49: ='Day 7'!M40 -> 5 | N49: ='Day 8'!K110 -> 46 | O49: ='Day 8'!M110 -> 6 | S49: =SUM('Day 9'!K75) -> 46 | T49: =SUM('Day 9'!M75) -> 7 | X49: =SUM('Day 10'!J110) -> 35 | Y49: =SUM('Day 10'!L110) -> 4
B51: TEAM F: Diane Fenech | C51: Fri | D51: ='Day 6'!K95 -> 42 | E51: ='Day 6'!M95 -> 4 | F51: =SUM(D51+D52) -> 70 | G51: =SUM(E51+E52) -> 5 | I51: ='Day 7'!K60 -> 40 | J51: ='Day 7'!M60 -> 5 | K51: =I51+I52 -> 76 | L51: =J51+J52 -> 11 | N51: ='Day 8'!K25 -> 25 | O51: ='Day 8'!M25 -> 2 | P51: =N51+N52 -> 54 | Q51: =O51+O52 -> 5 | S51: =SUM('Day 9'!K25) -> 32 | T51: =SUM('Day 9'!M25) -> 3 | U51: =S51+S52 -> 72 | V51: =T51+T52 -> 8 | X51: =SUM('Day 10'!K95) -> 33 | Y51: =SUM('Day 10'!M95) -> 4 | Z51: =X51+X52 -> 66 | AA51: =Y51+Y52 -> 8 | AC51: =SUM(AC27+AC28+F51+F52+K51+K52+P51+P52+U51+U52+Z51+Z52) -> 660 | AD51: =SUM(AD27+G51+L51+Q51+V51+AA51) -> 71
C52: Sat | D52: ='Day 6'!K110 -> 28 | E52: ='Day 6'!M110 -> 1 | I52: ='Day 7'!K75 -> 36 | J52: ='Day 7'!M75 -> 6 | N52: ='Day 8'!K40 -> 29 | O52: ='Day 8'!M40 -> 3 | S52: =SUM('Day 9'!K40) -> 40 | T52: =SUM('Day 9'!M40) -> 5 | X52: =SUM('Day 10'!K110) -> 33 | Y52: =SUM('Day 10'!M110) -> 4
Q55: `

Sheet Day 1
C1: SAN MICHEL TEAM TOURNAMENT 2026
C6: DAY 1 - 30/01/2026 - 31/01/2026
C9: Court 1
C11: Time | D11: Rubber | E11: TEAM A: Christine Scerri | G11: vs | H11: TEAM C: Jean Paul Sciberras | J11: Games | L11: Sets
C13: 6.30 pm | D13: Lad A | E13: Kirsty Mercieca | F13: Yanika Pace | G13: vs | H13: Alexia Spiteri Willets | I13: Lucienne Meli | J13: 4 | K13: 6 | L13: =IF(AND(J13>K13,J14>K14),2,IF(J13>K13,1,IF(J14>K14,1,0))) -> 1 | M13: =IF(AND(K13>J13,K14>J14),2,IF(K13>J13,1,IF(K14>J14,1,0))) -> 1
J14: 6 | K14: 3
C16: 7.45 pm | D16: Men C | E16: Alain Frendo | F16: Charles Sacco | G16: vs | H16: Matthew Schembri | I16: Jason Lee Evans | J16: 5 | K16: 7 | L16: =IF(AND(J16>K16,J17>K17),2,IF(J16>K16,1,IF(J17>K17,1,0))) -> 0 | M16: =IF(AND(K16>J16,K17>J17),2,IF(K16>J16,1,IF(K17>J17,1,0))) -> 2
J17: 4 | K17: 6
C19: 9.00 pm | D19: Men A | E19: Clayton Zammit Cesare | F19: Andrew Pule' | G19: vs | H19: Manuel Bonello | I19: Jonathan Vella (pro) Peter Khiev | J19: 6 | K19: 0 | L19: =IF(AND(J19>K19,J20>K20),2,IF(J19>K19,1,IF(J20>K20,1,0))) -> 2 | M19: =IF(AND(K19>J19,K20>J20),2,IF(K19>J19,1,IF(K20>J20,1,0))) -> 0
J20: 6 | K20: 2
C22: 6.30pm | D22: Lad B | E22: Silvana Portelli | F22: Deborah Farrugia | G22: vs | H22: Kristina Briffa | I22: Brenda Baldacchino | J22: 3 | K22: 6 | L22: =IF(AND(J22>K22,J23>K23),2,IF(J22>K22,1,IF(J23>K23,1,0))) -> 1 | M22: =IF(AND(K22>J22,K23>J23),2,IF(K22>J22,1,IF(K23>J23,1,0))) -> 1
J23: 6 | K23: 3
C25: Total Day 1 A | J25: =SUM(J13:J23) -> 40 | K25: =SUM(K13:K23) -> 33 | L25: =SUM(L13:L23) -> 4 | M25: =SUM(M13:M23) -> 4
C28: 3.30pm | D28: Men D | E28: Antoine Bugeja | F28: Dorian Demanuele | G28: vs | H28: Kevin Sciberras | I28: Kenneth Caruana | J28: 5 | K28: 7 | L28: =IF(AND(J28>K28,J29>K29),2,IF(J28>K28,1,IF(J29>K29,1,0))) -> 0 | M28: =IF(AND(K28>J28,K29>J29),2,IF(K28>J28,1,IF(K29>J29,1,0))) -> 2
J29: 4 | K29: 6
C31: 5.00pm | D31: Men B | E31: Alain Frendo(PRO)Cyril Lastimosa | F31: Clint Agius | G31: vs | H31: Jonatahn Vella | I31: Jean Paul Vella | J31: 6 | K31: 4 | L31: =IF(AND(J31>K31,J32>K32),2,IF(J31>K31,1,IF(J32>K32,1,0))) -> 1 | M31: =IF(AND(K31>J31,K32>J32),2,IF(K31>J31,1,IF(K32>J32,1,0))) -> 1
J32: 6 | K32: 7
C34: 6.30pm | D34: Lad C | E34: Janice Galea | F34: Josette Cassar | G34: vs | H34: Jodie Stivala | I34: Francesca | J34: 4 | K34: 6 | L34: =IF(AND(J34>K34,J35>K35),2,IF(J34>K34,1,IF(J35>K35,1,0))) -> 0 | M34: =IF(AND(K34>J34,K35>J35),2,IF(K34>J34,1,IF(K35>J35,1,0))) -> 2
J35: 1 | K35: 6
G37: vs | L37: =IF(AND(J37>K37,J38>K38),2,IF(J37>K37,1,IF(J38>K38,1,0))) -> 0 | M37: =IF(AND(K37>J37,K38>J38),2,IF(K37>J37,1,IF(K38>J38,1,0))) -> 0
C40: Total Day 1B | J40: =SUM(J28:J38) -> 26 | K40: =SUM(K28:K38) -> 36 | L40: =SUM(L28:L38) -> 1 | M40: =SUM(M28:M38) -> 5
C42: Total Day 1 | J42: =J40+J25 -> 66 | K42: =K40+K25 -> 69 | L42: =L40+L25 -> 5 | M42: =M40+M25 -> 9
C44: Court 2
C46: Time | D46: Rubber | E46: TEAM D: Juan Sammut | G46: vs | H46: TEAM E: Roberto Murdocco | J46: Games | L46: Sets
C48: 6.30 pm | D48: Men D | E48: Joseph Randich | F48: Clifford Debono | G48: vs | H48: Matthias Cremona | I48: Oliver Brincat | J48: 4 | K48: 6 | L48: =IF(AND(J48>K48,J49>K49),2,IF(J48>K48,1,IF(J49>K49,1,0))) -> 0 | M48: =IF(AND(K48>J48,K49>J49),2,IF(K48>J48,1,IF(K49>J49,1,0))) -> 2
J49: 2 | K49: 6
C51: 7.45 pm | D51: Lad B | E51: Anabel Borg | F51: Sue Stevenson | G51: vs | H51: Dorianne Buhagiar | I51: Nancy Wong | J51: 0 | K51: 6 | L51: =IF(AND(J51>K51,J52>K52),2,IF(J51>K51,1,IF(J52>K52,1,0))) -> 1 | M51: =IF(AND(K51>J51,K52>J52),2,IF(K51>J51,1,IF(K52>J52,1,0))) -> 1
J52: 6 | K52: 2
C54: 9.00 pm | D54: Men A | E54: Duncan D'Alessandro | F54: David Mifsud | G54: vs | H54: Trevor Rutter | I54: Marco Mercieca | J54: 0 | K54: 6 | L54: =IF(AND(J54>K54,J55>K55),2,IF(J54>K54,1,IF(J55>K55,1,0))) -> 0 | M54: =IF(AND(K54>J54,K55>J55),2,IF(K54>J54,1,IF(K55>J55,1,0))) -> 2
J55: 6 | K55: 7
C57: 7.45 pm | D57: Men C | E57: Etienne Formosa Carabez | F57: Sam Micallef | G57: vs | H57: Max Anastasi | I57: Aaron Micallef Piccione | J57: 4 | K57: 6 | L57: =IF(AND(J57>K57,J58>K58),2,IF(J57>K57,1,IF(J58>K58,1,0))) -> 0 | M57: =IF(AND(K57>J57,K58>J58),2,IF(K57>J57,1,IF(K58>J58,1,0))) -> 2
J58: 4 | K58: 6
C60: Total Day 1 A | J60: =SUM(J48:J58) -> 26 | K60: =SUM(K48:K58) -> 45 | L60: =SUM(L48:L58) -> 1 | M60: =SUM(M48:M58) -> 7
C63: 3.30 pm | D63: Men B | E63: David Schembri | F63: George Grech | G63: vs | H63: Luke Genuis | I63: Roberto Murdocco | J63: 7 | K63: 5 | L63: =IF(AND(J63>K63,J64>K64),2,IF(J63>K63,1,IF(J64>K64,1,0))) -> 1 | M63: =IF(AND(K63>J63,K64>J64),2,IF(K63>J63,1,IF(K64>J64,1,0))) -> 1
J64: 3 | K64: 6
C66: 5.00pm | D66: Lad C | E66: Frances Saliba Hersey | F66: Jennifer Roca | G66: vs | H66: Maria Ellul | I66: Roberta Grixti | J66: 6 | K66: 3 | L66: =IF(AND(J66>K66,J67>K67),2,IF(J66>K66,1,IF(J67>K67,1,0))) -> 2 | M66: =IF(AND(K66>J66,K67>J67),2,IF(K66>J66,1,IF(K67>J67,1,0))) -> 0
J67: 6 | K67: 1
C69: 6.30pm | D69: Lad A | E69: Louse Qi | F69: Leanne Vassallo | G69: vs | H69: Annmarie Mangion | I69: Mae Jane Manzanares | J69: 2 | K69: 6 | L69: =IF(AND(J69>K69,J70>K70),2,IF(J69>K69,1,IF(J70>K70,1,0))) -> 0 | M69: =IF(AND(K69>J69,K70>J70),2,IF(K69>J69,1,IF(K70>J70,1,0))) -> 2
J70: 2 | K70: 6
G72: vs | L72: =IF(AND(J72>K72,J73>K73),2,IF(J72>K72,1,IF(J73>K73,1,0))) -> 0 | M72: =IF(AND(K72>J72,K73>J73),2,IF(K72>J72,1,IF(K73>J73,1,0))) -> 0
...

Sheet Day 2 
C1: SAN MICHEL TEAM TOURNAMENT 2026
C6: Day 2 - 06/02/2026 - 07/02/2026
C9: Court 1
C11: Time | D11: Rubber | E11: Team B: Cory Greenland | G11: vs | H11: Team E: Roberto Murdocco | J11: Games | L11: Sets
C13: 6.30pm | D13: Men A | E13: Fotos Evangelou | F13: Javier Viloria | G13: vs | H13: Trevor Rutter | I13: Ivan Cachia | J13: 6 | K13: 2 | L13: =IF(AND(J13>K13,J14>K14),2,IF(J13>K13,1,IF(J14>K14,1,0))) -> 2 | M13: =IF(AND(K13>J13,K14>J14),2,IF(K13>J13,1,IF(K14>J14,1,0))) -> 0
J14: 6 | K14: 2
C16: 7.45 pm | D16: Lad A | E16: Christine Schembri | F16: Kelsey Gauci | G16: vs | H16: Annmarie Mangion | I16: Elaine Grech | J16: 5 | K16: 7 | L16: =IF(AND(J16>K16,J17>K17),2,IF(J16>K16,1,IF(J17>K17,1,0))) -> 0 | M16: =IF(AND(K16>J16,K17>J17),2,IF(K16>J16,1,IF(K17>J17,1,0))) -> 2
J17: 4 | K17: 6
C19: 9.00 pm | D19: Lad B | E19: Andrea Magaldi | F19: Giada Sciberras | G19: vs | H19: Nancy Wong | I19: Mariska Steenkamer | J19: 6 | K19: 3 | L19: =IF(AND(J19>K19,J20>K20),2,IF(J19>K19,1,IF(J20>K20,1,0))) -> 1 | M19: =IF(AND(K19>J19,K20>J20),2,IF(K19>J19,1,IF(K20>J20,1,0))) -> 1
J20: 6 | K20: 7
C22: 6.30 pm | D22: Lad C | E22: Alida Borg | F22: Christabelle Chetcuti | G22: vs | H22: Leanne Sammut | I22: Roberta Grixti | J22: 6 | K22: 3 | L22: =IF(AND(J22>K22,J23>K23),2,IF(J22>K22,1,IF(J23>K23,1,0))) -> 1 | M22: =IF(AND(K22>J22,K23>J23),2,IF(K22>J22,1,IF(K23>J23,1,0))) -> 1
J23: 3 | K23: 6
C25: Total Day 2 A | J25: =SUM(J13:J23) -> 42 | K25: =SUM(K13:K23) -> 36 | L25: =SUM(L13:L23) -> 4 | M25: =SUM(M13:M23) -> 4
C28: 3.30 pm | D28: Men D | E28: Matthew Napier | F28: Mario Abdilla | G28: vs | H28: Matthias Cremona | I28: Braydon Galea | J28: 3 | K28: 6 | L28: =IF(AND(J28>K28,J29>K29),2,IF(J28>K28,1,IF(J29>K29,1,0))) -> 0 | M28: =IF(AND(K28>J28,K29>J29),2,IF(K28>J28,1,IF(K29>J29,1,0))) -> 2
J29: 2 | K29: 6
C31: 5.00 pm | D31: Men C | E31: Manuel Mifsud | F31: Cory Greenland | G31: vs | H31: Aaron Micallef Piccione | I31: Jordan Lastimosa | J31: 5 | K31: 7 | L31: =IF(AND(J31>K31,J32>K32),2,IF(J31>K31,1,IF(J32>K32,1,0))) -> 1 | M31: =IF(AND(K31>J31,K32>J32),2,IF(K31>J31,1,IF(K32>J32,1,0))) -> 1
J32: 6 | K32: 1
C34: 6.30 pm | D34: Men B | E34: Kristen Cachia | F34: Ivan Cassar | G34: vs | H34: Emman Xuereb | I34: Roberto Murdocco | J34: 4 | K34: 6 | L34: =IF(AND(J34>K34,J35>K35),2,IF(J34>K34,1,IF(J35>K35,1,0))) -> 1 | M34: =IF(AND(K34>J34,K35>J35),2,IF(K34>J34,1,IF(K35>J35,1,0))) -> 1
J35: 6 | K35: 4
C37: 5.30 pm | G37: vs | L37: =IF(AND(J37>K37,J38>K38),2,IF(J37>K37,1,IF(J38>K38,1,0))) -> 0 | M37: =IF(AND(K37>J37,K38>J38),2,IF(K37>J37,1,IF(K38>J38,1,0))) -> 0
C40: Total Day 2B | J40: =SUM(J28:J38) -> 26 | K40: =SUM(K28:K38) -> 30 | L40: =SUM(L28:L38) -> 2 | M40: =SUM(M28:M38) -> 4
C42: Total Day 2 | J42: =J40+J25 -> 68 | K42: =K40+K25 -> 66 | L42: =L40+L25 -> 6 | M42: =M40+M25 -> 8
C44: Court 2
C46: Time | D46: Rubber | E46: Team A: Christine Scerri | G46: vs | H46: Team F: Diane Fenech | J46: Games | L46: Sets
C48: 6.30 pm | D48: Lad C | E48: Janice Galea | F48: Christine Scerri | G48: vs | H48: Tiziana Spiteri | I48: Kim Bonello | J48: 6 | K48: 4 | L48: =IF(AND(J48>K48,J49>K49),2,IF(J48>K48,1,IF(J49>K49,1,0))) -> 2 | M48: =IF(AND(K48>J48,K49>J49),2,IF(K48>J48,1,IF(K49>J49,1,0))) -> 0
J49: 6 | K49: 3
C51: 7.45 pm | D51: Men A | E51: Clayton Zammit Cesare | F51: Jonathan Martinelli | G51: vs | H51: Kurt Carabott | I51: Andrew Spiteri Willets | J51: 6 | K51: 4 | L51: =IF(AND(J51>K51,J52>K52),2,IF(J51>K51,1,IF(J52>K52,1,0))) -> 2 | M51: =IF(AND(K51>J51,K52>J52),2,IF(K51>J51,1,IF(K52>J52,1,0))) -> 0
J52: 6 | K52: 4
C54: 9.00 pm | D54: Lad A | E54: Amanda Falzon | F54: Kirsty Mercieca | G54: vs | H54: Christina Bonett | I54: Anthea Gauci | J54: 7 | K54: 6 | L54: =IF(AND(J54>K54,J55>K55),2,IF(J54>K54,1,IF(J55>K55,1,0))) -> 2 | M54: =IF(AND(K54>J54,K55>J55),2,IF(K54>J54,1,IF(K55>J55,1,0))) -> 0
J55: 6 | K55: 4
C57: 7.45 pm | D57: Men D | E57: Daniele Privitera | F57: Dorian Demanuele | G57: vs | H57: Ryan Ebejer | I57: Robert Attard | J57: 6 | K57: 2 | L57: =IF(AND(J57>K57,J58>K58),2,IF(J57>K57,1,IF(J58>K58,1,0))) -> 1 | M57: =IF(AND(K57>J57,K58>J58),2,IF(K57>J57,1,IF(K58>J58,1,0))) -> 1
J58: 4 | K58: 6
C60: Total Day 2 A | J60: =SUM(J48:J58) -> 47 | K60: =SUM(K48:K58) -> 33 | L60: =SUM(L48:L58) -> 7 | M60: =SUM(M48:M58) -> 1
C63: 3.30pm | D63: Men B | E63: Cyril Lastimosa | F63: Sandro Pecorella | G63: vs | H63: Sergey Kasatkin | I63: Richard Curmi | J63: 1 | K63: 6 | L63: =IF(AND(J63>K63,J64>K64),2,IF(J63>K63,1,IF(J64>K64,1,0))) -> 1 | M63: =IF(AND(K63>J63,K64>J64),2,IF(K63>J63,1,IF(K64>J64,1,0))) -> 1
J64: 6 | K64: 2
C66: 5.00pm | D66: Lad B | E66: Deborah Farrugia | F66: Tiffany Fenech | G66: vs | H66: Maria Angela Gambin | I66: Ann Marie Attard | J66: 3 | K66: 6 | L66: =IF(AND(J66>K66,J67>K67),2,IF(J66>K66,1,IF(J67>K67,1,0))) -> 0 | M66: =IF(AND(K66>J66,K67>J67),2,IF(K66>J66,1,IF(K67>J67,1,0))) -> 2
J67: 3 | K67: 6
C69: 6.30 pm | D69: Men C | E69: Alain Frendo | F69: Redent Scicluna | G69: vs | H69: Julian Esposito | I69: Dunstan Vella | J69: 3 | K69: 6 | L69: =IF(AND(J69>K69,J70>K70),2,IF(J69>K69,1,IF(J70>K70,1,0))) -> 0 | M69: =IF(AND(K69>J69,K70>J70),2,IF(K69>J69,1,IF(K70>J70,1,0))) -> 2
J70: 4 | K70: 6
C72: 4.15 pm | G72: vs | L72: =IF(AND(J72>K72,J73>K73),2,IF(J72>K72,1,IF(J73>K73,1,0))) -> 0 | M72: =IF(AND(K72>J72,K73>J73),2,IF(K72>J72,1,IF(K73>J73,1,0))) -> 0
...

Sheet Day 3
C1: SAN MICHEL TEAM TOURNAMENT 2026
C6: Day 3 -
C9: Court 1
C11: Time | D11: Rubber | E11: TEAM C: JEAN PAUL | G11: vs | H11: TEAM F: DIANE | J11: Games | L11: Sets
C13: 6.30 pm | D13: Lad A | E13: Alexia Spiteri Willets | F13: Lucienne Meli | G13: vs | H13: Renette Magro | I13: Anthea Gauci | J13: 4 | K13: 6 | L13: =IF(AND(J13>K13,J14>K14),2,IF(J13>K13,1,IF(J14>K14,1,0))) -> 1 | M13: =IF(AND(K13>J13,K14>J14),2,IF(K13>J13,1,IF(K14>J14,1,0))) -> 1
J14: 6 | K14: 1
C16: 6.30 pm | D16: Men A | E16: Manuel Bonello | F16: Peter Khiev | G16: vs | H16: Kurt Carabott | I16: Jean Attard | J16: 3 | K16: 6 | L16: =IF(AND(J16>K16,J17>K17),2,IF(J16>K16,1,IF(J17>K17,1,0))) -> 0 | M16: =IF(AND(K16>J16,K17>J17),2,IF(K16>J16,1,IF(K17>J17,1,0))) -> 2
J17: 4 | K17: 6
C19: 7.45 pm | D19: Men C | E19: Jean Paul Sciberras | F19: Matthew Schembri | G19: vs | H19: Simone Re | I19: Dunstan Vella | J19: 3 | K19: 6 | L19: =IF(AND(J19>K19,J20>K20),2,IF(J19>K19,1,IF(J20>K20,1,0))) -> 0 | M19: =IF(AND(K19>J19,K20>J20),2,IF(K19>J19,1,IF(K20>J20,1,0))) -> 2
J20: 4 | K20: 6
C22: 9.00 pm | D22: Lad B | E22: Kristina Briffa | F22: Jade Sammut | G22: vs | H22: Maria Angela Gambin | I22: Ann Marie Attard | J22: 4 | K22: 6 | L22: =IF(AND(J22>K22,J23>K23),2,IF(J22>K22,1,IF(J23>K23,1,0))) -> 1 | M22: =IF(AND(K22>J22,K23>J23),2,IF(K22>J22,1,IF(K23>J23,1,0))) -> 1
J23: 6 | K23: 3
C25: Total Day 3 A | J25: =SUM(J13:J23) -> 34 | K25: =SUM(K13:K23) -> 40 | L25: =SUM(L13:L23) -> 2 | M25: =SUM(M13:M23) -> 6
C28: 3.30 pm | D28: Men D | E28: Kevin Sciberras | F28: Alberto Bafumi | G28: vs | H28: Ryan Ebejer | I28: Clinton Cutajar | J28: 6 | K28: 3 | L28: =IF(AND(J28>K28,J29>K29),2,IF(J28>K28,1,IF(J29>K29,1,0))) -> 1 | M28: =IF(AND(K28>J28,K29>J29),2,IF(K28>J28,1,IF(K29>J29,1,0))) -> 1
J29: 6 | K29: 7
C31: 5.00pm | D31: Men B | E31: Jonathan Vella | F31: Jean Paul Vella | G31: vs | H31: Sergey Kasatkin | I31: Steve Gambin | J31: 1 | K31: 6 | L31: =IF(AND(J31>K31,J32>K32),2,IF(J31>K31,1,IF(J32>K32,1,0))) -> 0 | M31: =IF(AND(K31>J31,K32>J32),2,IF(K31>J31,1,IF(K32>J32,1,0))) -> 2
J32: 3 | K32: 6
C34: 6.30pm | D34: Lad C | E34: Brenda Bugeja | F34: Francesca Mamo | G34: vs | H34: Tiziana Spiteri | I34: Daphne Vella | J34: 1 | K34: 6 | L34: =IF(AND(J34>K34,J35>K35),2,IF(J34>K34,1,IF(J35>K35,1,0))) -> 0 | M34: =IF(AND(K34>J34,K35>J35),2,IF(K34>J34,1,IF(K35>J35,1,0))) -> 2
J35: 2 | K35: 6
G37: vs | L37: =IF(AND(J37>K37,J38>K38),2,IF(J37>K37,1,IF(J38>K38,1,0))) -> 0 | M37: =IF(AND(K37>J37,K38>J38),2,IF(K37>J37,1,IF(K38>J38,1,0))) -> 0
C40: Total Day 3B | J40: =SUM(J28:J38) -> 19 | K40: =SUM(K28:K38) -> 34 | L40: =SUM(L28:L38) -> 1 | M40: =SUM(M28:M38) -> 5
C42: Total Day 3 | J42: =J40+J25 -> 53 | K42: =K40+K25 -> 74 | L42: =L40+L25 -> 3 | M42: =M40+M25 -> 11
C44: Court 2
C46: Time | D46: Rubber | E46: TEAM D: JUAN | G46: vs | H46: TEAM B: CORY | J46: Games | L46: Sets
C48: 6.30 pm | D48: Lad C | E48: Frances Saliba Hersey | F48: Jennifer Roca | G48: vs | H48: Karolina Papiernik | I48: Christabelle Chetcuti | J48: 6 | K48: 3 | L48: =IF(AND(J48>K48,J49>K49),2,IF(J48>K48,1,IF(J49>K49,1,0))) -> 2 | M48: =IF(AND(K48>J48,K49>J49),2,IF(K48>J48,1,IF(K49>J49,1,0))) -> 0
J49: 7 | K49: 5
C51: 7.45 pm | D51: Men D | E51: Clifford Debono | F51: Omar Farrugia | G51: vs | H51: David Camilleri | I51: Mario Abdilla | J51: 6 | K51: 7 | L51: =IF(AND(J51>K51,J52>K52),2,IF(J51>K51,1,IF(J52>K52,1,0))) -> 0 | M51: =IF(AND(K51>J51,K52>J52),2,IF(K51>J51,1,IF(K52>J52,1,0))) -> 2
J52: 2 | K52: 6
C54: 7.45 pm | D54: Lad A | E54: Leanne Vassallo | F54: Alison Muscat | G54: vs | H54: Christine Schembri | I54: Kaya Sammut | J54: 6 | K54: 3 | L54: =IF(AND(J54>K54,J55>K55),2,IF(J54>K54,1,IF(J55>K55,1,0))) -> 2 | M54: =IF(AND(K54>J54,K55>J55),2,IF(K54>J54,1,IF(K55>J55,1,0))) -> 0
J55: 7 | K55: 5
C57: 9.00 pm | D57: Men B | E57: David Schembri | F57: Jurgen Farrugia | G57: vs | H57: Kristen Cachia | I57: Tobias Kristensen | J57: 7 | K57: 6 | L57: =IF(AND(J57>K57,J58>K58),2,IF(J57>K57,1,IF(J58>K58,1,0))) -> 1 | M57: =IF(AND(K57>J57,K58>J58),2,IF(K57>J57,1,IF(K58>J58,1,0))) -> 1
J58: 2 | K58: 6
C60: Total Day 3 A | J60: =SUM(J48:J58) -> 43 | K60: =SUM(K48:K58) -> 41 | L60: =SUM(L48:L58) -> 5 | M60: =SUM(M48:M58) -> 3
C63: 3.30 pm | D63: Men C | E63: Etienne Formosa Carabez | F63: Sam Micallef | G63: vs | H63: Kenneth Farrugia | I63: Manuel Mifsud | J63: 6 | K63: 7 | L63: =IF(AND(J63>K63,J64>K64),2,IF(J63>K63,1,IF(J64>K64,1,0))) -> 0 | M63: =IF(AND(K63>J63,K64>J64),2,IF(K63>J63,1,IF(K64>J64,1,0))) -> 2
J64: 3 | K64: 6
C66: 5.00pm | D66: Men A | E66: Duncan D`Alessandro | F66: Jesmond Pule` | G66: vs | H66: Gareth Magri | I66: Javier Viloria | J66: 2 | K66: 6 | L66: =IF(AND(J66>K66,J67>K67),2,IF(J66>K66,1,IF(J67>K67,1,0))) -> 1 | M66: =IF(AND(K66>J66,K67>J67),2,IF(K66>J66,1,IF(K67>J67,1,0))) -> 1
J67: 6 | K67: 4
C69: 6.30 pm | D69: Lad B | E69: Sue Stevenson | F69: Sarah Axiaq | G69: vs | H69: Giada Sciberras | I69: Sabrina Xuereb | J69: 6 | K69: 3 | L69: =IF(AND(J69>K69,J70>K70),2,IF(J69>K69,1,IF(J70>K70,1,0))) -> 1 | M69: =IF(AND(K69>J69,K70>J70),2,IF(K69>J69,1,IF(K70>J70,1,0))) -> 1
J70: 2 | K70: 6
L72: =IF(AND(J72>K72,J73>K73),2,IF(J72>K72,1,IF(J73>K73,1,0))) -> 0 | M72: =IF(AND(K72>J72,K73>J73),2,IF(K72>J72,1,IF(K73>J73,1,0))) -> 0
...

Sheet Day 4
C1: SAN MICHEL TEAM TOURNAMENT 2026
C6: Day 4 - 20/02/2026 & 21/02/2026
C9: Court 1
C11: Time | D11: Rubber | E11: Team D: Juan | H11: Team F: Diane | J11: Games | L11: Sets
C13: 6.30 pm | D13: Lad C | E13: Frances Saliba Hersey | F13: Mary Borg | G13: vs | H13: Daphne Vella | I13: Kim Bonello | J13: 6 | K13: 4 | L13: =IF(AND(J13>K13,J14>K14),2,IF(J13>K13,1,IF(J14>K14,1,0))) -> 2 | M13: =IF(AND(K13>J13,K14>J14),2,IF(K13>J13,1,IF(K14>J14,1,0))) -> 0
J14: 6 | K14: 1
C16: 7.45 pm | D16: Men A | E16: Duncan D'Alessandro | F16: David Mifsud | G16: vs | H16: Kurt Carabott | I16: Jean Attard | J16: 5 | K16: 7 | L16: =IF(AND(J16>K16,J17>K17),2,IF(J16>K16,1,IF(J17>K17,1,0))) -> 0 | M16: =IF(AND(K16>J16,K17>J17),2,IF(K16>J16,1,IF(K17>J17,1,0))) -> 2
J17: 5 | K17: 7 | N17: Ret
C19: 9.00 pm | D19: Lad B | E19: Sue Stevenson | F19: Sarah Axiaq | G19: vs | H19: AnnMarie Attard | I19: Romina Gauci | J19: 6 | K19: 2 | L19: =IF(AND(J19>K19,J20>K20),2,IF(J19>K19,1,IF(J20>K20,1,0))) -> 2 | M19: =IF(AND(K19>J19,K20>J20),2,IF(K19>J19,1,IF(K20>J20,1,0))) -> 0
J20: 7 | K20: 5
C22: 7.45 pm | G22: vs | L22: =IF(AND(J22>K22,J23>K23),2,IF(J22>K22,1,IF(J23>K23,1,0))) -> 0 | M22: =IF(AND(K22>J22,K23>J23),2,IF(K22>J22,1,IF(K23>J23,1,0))) -> 0
C25: Total Day 4 A | J25: =SUM(J13:J23) -> 35 | K25: =SUM(K13:K23) -> 26 | L25: =SUM(L13:L23) -> 4 | M25: =SUM(M13:M23) -> 2
C28: 3.30 pm | D28: Men D | E28: Joseph Randich | F28: Owen Farrugia | G28: vs | H28: Ryan Ebejer | I28: Robert Attard | J28: 6 | K28: 4 | L28: =IF(AND(J28>K28,J29>K29),2,IF(J28>K28,1,IF(J29>K29,1,0))) -> 1 | M28: =IF(AND(K28>J28,K29>J29),2,IF(K28>J28,1,IF(K29>J29,1,0))) -> 1
J29: 4 | K29: 6
C31: 5.00 pm | D31: Lad A | E31: Alison Muscat | F31: Louise Qi | G31: vs | H31: Renette Magro | I31: Christina Bonett | J31: 0 | K31: 6 | L31: =IF(AND(J31>K31,J32>K32),2,IF(J31>K31,1,IF(J32>K32,1,0))) -> 0 | M31: =IF(AND(K31>J31,K32>J32),2,IF(K31>J31,1,IF(K32>J32,1,0))) -> 2
J32: 3 | K32: 6
C34: 5.00 pm | D34: Men C | E34: Etienne Formosa Carabez | F34: Juan Sammut | G34: vs | H34: Simone Re | I34: Dunstan Vella | J34: 6 | K34: 3 | L34: =IF(AND(J34>K34,J35>K35),2,IF(J34>K34,1,IF(J35>K35,1,0))) -> 2 | M34: =IF(AND(K34>J34,K35>J35),2,IF(K34>J34,1,IF(K35>J35,1,0))) -> 0
J35: 6 | K35: 2
C37: 6.30 pm | D37: Men B | E37: David Schembri | F37: George Grech | G37: vs | H37: Sergey Kasatkin | I37: Richard Curmi | J37: 6 | K37: 4 | L37: =IF(AND(J37>K37,J38>K38),2,IF(J37>K37,1,IF(J38>K38,1,0))) -> 2 | M37: =IF(AND(K37>J37,K38>J38),2,IF(K37>J37,1,IF(K38>J38,1,0))) -> 0
J38: 6 | K38: 0
C40: Total Day 4B | J40: =SUM(J28:J38) -> 37 | K40: =SUM(K28:K38) -> 31 | L40: =SUM(L28:L38) -> 5 | M40: =SUM(M28:M38) -> 3
C42: Total Day 4 | J42: =J40+J25 -> 72 | K42: =K40+K25 -> 57 | L42: =L40+L25 -> 9 | M42: =M40+M25 -> 5
C44: Court 2
C46: Time | D46: Rubber | E46: TEAM C: Jean Paul | H46: TEAM E: Roberto | J46: Games | L46: Sets
C48: 6.30 pm | D48: Lad A | E48: Alexia Spiteri Willets | F48: Olivia Belli | G48: vs | H48: Annmarie Mangion | I48: Mae Jane Manzanares | J48: 0 | K48: 6 | L48: =IF(AND(J48>K48,J49>K49),2,IF(J48>K48,1,IF(J49>K49,1,0))) -> 0 | M48: =IF(AND(K48>J48,K49>J49),2,IF(K48>J48,1,IF(K49>J49,1,0))) -> 2
J49: 3 | K49: 6
C51: 7.45 pm | D51: Lad C | E51: Francesca Mamo | F51: Jodie Stivala | G51: vs | H51: Leanne Sammut | I51: Roberta Grixti | J51: 6 | K51: 0 | L51: =IF(AND(J51>K51,J52>K52),2,IF(J51>K51,1,IF(J52>K52,1,0))) -> 2 | M51: =IF(AND(K51>J51,K52>J52),2,IF(K51>J51,1,IF(K52>J52,1,0))) -> 0
J52: 7 | K52: 6
C54: 9.00 pm | D54: Men A | E54: Matthew Pace | F54: Peter Khiev | G54: vs | H54: Trevor Rutter | I54: Ivan Cachia | J54: 6 | K54: 2 | L54: =IF(AND(J54>K54,J55>K55),2,IF(J54>K54,1,IF(J55>K55,1,0))) -> 2 | M54: =IF(AND(K54>J54,K55>J55),2,IF(K54>J54,1,IF(K55>J55,1,0))) -> 0
J55: 6 | K55: 3
C57: 6.30 pm | D57: Men B | E57: Jean Paul Vella | F57: Willem Steenkamer | G57: vs | H57: Emman Xuereb | I57: Luke Genuis | J57: 3 | K57: 6 | L57: =IF(AND(J57>K57,J58>K58),2,IF(J57>K57,1,IF(J58>K58,1,0))) -> 0 | M57: =IF(AND(K57>J57,K58>J58),2,IF(K57>J57,1,IF(K58>J58,1,0))) -> 2
J58: 0 | K58: 6
C60: Total Day 4 A | J60: =SUM(J48:J58) -> 31 | K60: =SUM(K48:K58) -> 35 | L60: =SUM(L48:L58) -> 4 | M60: =SUM(M48:M58) -> 4
C63: 3.30 pm | D63: Men D | E63: Kevin Sciberras | F63: Alberto Bufumi | G63: vs | H63: Matthias Cremona | I63: Oliver Brincat | J63: 3 | K63: 6 | L63: =IF(AND(J63>K63,J64>K64),2,IF(J63>K63,1,IF(J64>K64,1,0))) -> 0 | M63: =IF(AND(K63>J63,K64>J64),2,IF(K63>J63,1,IF(K64>J64,1,0))) -> 2
J64: 4 | K64: 6
C66: 5.00pm | D66: Men C | E66: Jason Lee Evans | F66: Jean Paul Sciberras | G66: vs | H66: Aaron Micallef Piccione | I66: Jordan Lastimosa | J66: 6 | K66: 4 | L66: =IF(AND(J66>K66,J67>K67),2,IF(J66>K66,1,IF(J67>K67,1,0))) -> 2 | M66: =IF(AND(K66>J66,K67>J67),2,IF(K66>J66,1,IF(K67>J67,1,0))) -> 0
J67: 7 | K67: 5
D69: Lad B | E69: Brenda Baldacchino | F69: Jade Sammut | G69: vs | H69: Dorianne Buhagiar | I69: Mariska Steenkamer | J69: 1 | K69: 6 | L69: =IF(AND(J69>K69,J70>K70),2,IF(J69>K69,1,IF(J70>K70,1,0))) -> 0 | M69: =IF(AND(K69>J69,K70>J70),2,IF(K69>J69,1,IF(K70>J70,1,0))) -> 2
J70: 1 | K70: 6
G72: vs | L72: =IF(AND(J72>K72,J73>K73),2,IF(J72>K72,1,IF(J73>K73,1,0))) -> 0 | M72: =IF(AND(K72>J72,K73>J73),2,IF(K72>J72,1,IF(K73>J73,1,0))) -> 0
...

Sheet Day 5
C1: SAN MICHEL TEAM TOURNAMENT 2026
C6: Day 5 - 27/02/2026 & 28/02/2026
C9: Court 1
C11: Time | D11: Rubber | E11: TEAM A: Christine Scerri | H11: TEAM D: Juan Sammut | J11: Games | L11: Sets
C13: 6.30 pm | D13: Men A | E13: Clayton Zammit Cesare | F13: Jonathan Martinelli | G13: vs | H13: Duncan D`Alessandro | I13: David Mifsud | J13: 6 | K13: 1 | L13: =IF(AND(J13>K13,J14>K14),2,IF(J13>K13,1,IF(J14>K14,1,0))) -> 2 | M13: =IF(AND(K13>J13,K14>J14),2,IF(K13>J13,1,IF(K14>J14,1,0))) -> 0
J14: 6 | K14: 3
C15: 6
C16: 6.30 pm | D16: Lad C | E16: Janice Galea | F16: Christine Scerri | G16: vs | H16: Jennifer Roca | I16: Mary Borg | J16: 7 | K16: 6 | L16: =IF(AND(J16>K16,J17>K17),2,IF(J16>K16,1,IF(J17>K17,1,0))) -> 2 | M16: =IF(AND(K16>J16,K17>J17),2,IF(K16>J16,1,IF(K17>J17,1,0))) -> 0
J17: 6 | K17: 0
C19: 7.45 pm | D19: Men C | E19: Charles Sacco | F19: Alain Frendo | G19: vs | H19: Juan Sammut | I19: Sam Micallef | J19: 6 | K19: 2 | L19: =IF(AND(J19>K19,J20>K20),2,IF(J19>K19,1,IF(J20>K20,1,0))) -> 2 | M19: =IF(AND(K19>J19,K20>J20),2,IF(K19>J19,1,IF(K20>J20,1,0))) -> 0
J20: 6 | K20: 1
G22: vs | L22: =IF(AND(J22>K22,J23>K23),2,IF(J22>K22,1,IF(J23>K23,1,0))) -> 0 | M22: =IF(AND(K22>J22,K23>J23),2,IF(K22>J22,1,IF(K23>J23,1,0))) -> 0
C25: Total Day 5 A | J25: =SUM(J13:J23) -> 37 | K25: =SUM(K13:K23) -> 13 | L25: =SUM(L13:L23) -> 6 | M25: =SUM(M13:M23) -> 0
C28: 3.30 pm | D28: Men D | E28: Daniele Privitera | F28: Dorian Demanuele | G28: vs | H28: Clifford Debono | I28: Owen Farrugia | J28: 7 | K28: 5 | L28: =IF(AND(J28>K28,J29>K29),2,IF(J28>K28,1,IF(J29>K29,1,0))) -> 2 | M28: =IF(AND(K28>J28,K29>J29),2,IF(K28>J28,1,IF(K29>J29,1,0))) -> 0
J29: 6 | K29: 0
C31: 5.00 pm | D31: Men B | E31: Cyril Lastimosa | F31: Sandro Pecorella | G31: vs | H31: David Schembri | I31: Jurgen Farrugia | J31: 2 | K31: 6 | L31: =IF(AND(J31>K31,J32>K32),2,IF(J31>K31,1,IF(J32>K32,1,0))) -> 1 | M31: =IF(AND(K31>J31,K32>J32),2,IF(K31>J31,1,IF(K32>J32,1,0))) -> 1
J32: 7 | K32: 6
C34: 5.00pm | D34: Lad A | E34: Amanda Falzon | F34: Yanika Pace | G34: vs | H34: Leanne Vassallo | I34: Alison Muscat | J34: 4 | K34: 6 | L34: =IF(AND(J34>K34,J35>K35),2,IF(J34>K34,1,IF(J35>K35,1,0))) -> 0 | M34: =IF(AND(K34>J34,K35>J35),2,IF(K34>J34,1,IF(K35>J35,1,0))) -> 2
J35: 4 | K35: 6
C37: 6.30pm | D37: Lad B | E37: Silvana Portelli | F37: Tiffany Fenech | G37: vs | H37: Anabel Borg | I37: Sarah Axiaq | J37: 5 | K37: 7 | L37: =IF(AND(J37>K37,J38>K38),2,IF(J37>K37,1,IF(J38>K38,1,0))) -> 0 | M37: =IF(AND(K37>J37,K38>J38),2,IF(K37>J37,1,IF(K38>J38,1,0))) -> 2
J38: 4 | K38: 6
C40: Total Day 5B | J40: =SUM(J28:J38) -> 39 | K40: =SUM(K28:K38) -> 42 | L40: =SUM(L28:L38) -> 3 | M40: =SUM(M28:M38) -> 5
C42: Total Day 5 | J42: =J40+J25 -> 76 | K42: =K40+K25 -> 55 | L42: =L40+L25 -> 9 | M42: =M40+M25 -> 5
C44: Court 2
C46: Time | D46: Rubber | E46: TEAM B: Cory Greenland | H46: TEAM C: Jean Paul Sciberras | J46: Games | L46: Sets
C48: 6.30 pm | D48: Lad A | E48: Christine Schembri | F48: Kaya Sammut | G48: vs | H48: Olivia Belli | I48: Lucienne Meli | J48: 6 | K48: 3 | L48: =IF(AND(J48>K48,J49>K49),2,IF(J48>K48,1,IF(J49>K49,1,0))) -> 2 | M48: =IF(AND(K48>J48,K49>J49),2,IF(K48>J48,1,IF(K49>J49,1,0))) -> 0
J49: 6 | K49: 1
C51: 7.45 pm | D51: Lad C | E51: Karolina Papiernik | F51: Christabelle Chetcuti | G51: vs | H51: Francesca Mamo | I51: Brenda Bugeja | J51: 6 | K51: 1 | L51: =IF(AND(J51>K51,J52>K52),2,IF(J51>K51,1,IF(J52>K52,1,0))) -> 1 | M51: =IF(AND(K51>J51,K52>J52),2,IF(K51>J51,1,IF(K52>J52,1,0))) -> 1
J52: 3 | K52: 6
C54: 7.45 pm | D54: Men C | E54: Kenneth Farrugia | F54: Cory Greenland | G54: vs | H54: Matthew Schembri | I54: Jason Lee Evans | J54: 6 | K54: 4 | L54: =IF(AND(J54>K54,J55>K55),2,IF(J54>K54,1,IF(J55>K55,1,0))) -> 1 | M54: =IF(AND(K54>J54,K55>J55),2,IF(K54>J54,1,IF(K55>J55,1,0))) -> 1
J55: 3 | K55: 6
C57: 9.00 pm | D57: Lad B | E57: Giada Sciberras | F57: Sabrina Xuereb | G57: vs | H57: Kristina Briffa | I57: Brenda Baldacchino | J57: 6 | K57: 3 | L57: =IF(AND(J57>K57,J58>K58),2,IF(J57>K57,1,IF(J58>K58,1,0))) -> 1 | M57: =IF(AND(K57>J57,K58>J58),2,IF(K57>J57,1,IF(K58>J58,1,0))) -> 1
J58: 5 | K58: 7
C60: Total Day 5 A | J60: =SUM(J48:J58) -> 41 | K60: =SUM(K48:K58) -> 31 | L60: =SUM(L48:L58) -> 5 | M60: =SUM(M48:M58) -> 3
C63: 3.30 pm | D63: Men D | E63: David Camilleri | F63: Mario Abdilla | G63: vs | H63: Kevin Sciberras(PRO)Kenneth Caruana | I63: Alberto Bafumi | J63: 3 | K63: 6 | L63: =IF(AND(J63>K63,J64>K64),2,IF(J63>K63,1,IF(J64>K64,1,0))) -> 1 | M63: =IF(AND(K63>J63,K64>J64),2,IF(K63>J63,1,IF(K64>J64,1,0))) -> 1
J64: 6 | K64: 3
C66: 5.00pm | D66: Men B | E66: Kristen Cachia | F66: Ivan Cassar | G66: vs | H66: Willem Steenkamer | I66: Jean Paul Vella | J66: 4 | K66: 6 | L66: =IF(AND(J66>K66,J67>K67),2,IF(J66>K66,1,IF(J67>K67,1,0))) -> 1 | M66: =IF(AND(K66>J66,K67>J67),2,IF(K66>J66,1,IF(K67>J67,1,0))) -> 1
J67: 6 | K67: 4
C69: 6.30pm | D69: Men A | E69: Gareth Magri | F69: Fotios Evangelou | G69: vs | H69: Manuel Bonello | I69: Matthew Pace | J69: 6 | K69: 3 | L69: =IF(AND(J69>K69,J70>K70),2,IF(J69>K69,1,IF(J70>K70,1,0))) -> 1 | M69: =IF(AND(K69>J69,K70>J70),2,IF(K69>J69,1,IF(K70>J70,1,0))) -> 1
J70: 4 | K70: 6
...

Sheet Day 6
B1: SAN MICHEL TEAM TOURNAMENT 2026
C6: Day 6 - 06/03/2026 & 07/03/2026
C9: Court 1
C11: Time | D11: Rubber | E11: TEAM A: Christine Scerri | H11: TEAM C: Jean Paul Sciberras | J11: Games | L11: Sets
C13: 6.30 pm | D13: Lad A | E13: Amanda Falzon | F13: Kirsty Mercieca | G13: vs | H13: Alexia Spiteri Willets | I13: Kristina Briffa(pro)Olivia Belli | J13: 6 | K13: 3 | L13: =IF(AND(J13>K13,J14>K14),2,IF(J13>K13,1,IF(J14>K14,1,0))) -> 2 | M13: =IF(AND(K13>J13,K14>J14),2,IF(K13>J13,1,IF(K14>J14,1,0))) -> 0
J14: 6 | K14: 2
C16: 7.45 pm | D16: Men C | E16: Alain Frendo | F16: Redent Scicluna | G16: vs | H16: Matthew Schembri | I16: Jean Paul Sciberras | J16: 6 | K16: 7 | L16: =IF(AND(J16>K16,J17>K17),2,IF(J16>K16,1,IF(J17>K17,1,0))) -> 1 | M16: =IF(AND(K16>J16,K17>J17),2,IF(K16>J16,1,IF(K17>J17,1,0))) -> 1
J17: 6 | K17: 3
C19: 7.45 pm | D19: Lad C | E19: Janice Galea | F19: Christine Scerri | G19: vs | H19: Francesca Mamo | I19: Jodie Stivala | J19: 2 | K19: 6 | L19: =IF(AND(J19>K19,J20>K20),2,IF(J19>K19,1,IF(J20>K20,1,0))) -> 1 | M19: =IF(AND(K19>J19,K20>J20),2,IF(K19>J19,1,IF(K20>J20,1,0))) -> 1
J20: 6 | K20: 4
C22: 9.00 pm | D22: Lad B | E22: Silvana Portelli | F22: Deborah Farrugia | G22: vs | H22: Brenda Baldacchino | I22: Jade Sammut | J22: 2 | K22: 6 | L22: =IF(AND(J22>K22,J23>K23),2,IF(J22>K22,1,IF(J23>K23,1,0))) -> 1 | M22: =IF(AND(K22>J22,K23>J23),2,IF(K22>J22,1,IF(K23>J23,1,0))) -> 1
J23: 6 | K23: 2
C25: Total Day 6 A | J25: =SUM(J13:J23) -> 40 | K25: =SUM(K13:K23) -> 33 | L25: =SUM(L13:L23) -> 5 | M25: =SUM(M13:M23) -> 3
C28: 9.00 pm | D28: Men A | E28: Clayton Zammit Cesare | F28: Andrew Pule' | G28: vs | H28: Manuel Bonello(pro)Matthew Pace | I28: Peter Khiev | J28: 6 | K28: 3 | L28: =IF(AND(J28>K28,J29>K29),2,IF(J28>K28,1,IF(J29>K29,1,0))) -> 2 | M28: =IF(AND(K28>J28,K29>J29),2,IF(K28>J28,1,IF(K29>J29,1,0))) -> 0
J29: 6 | K29: 0
C31: 3.30 pm | D31: Men B | E31: Cyril Lastimosa | F31: Clint Agius | G31: vs | H31: Jean Paul Vella | I31: Willem Steenkamer | J31: 6 | K31: 0 | L31: =IF(AND(J31>K31,J32>K32),2,IF(J31>K31,1,IF(J32>K32,1,0))) -> 2 | M31: =IF(AND(K31>J31,K32>J32),2,IF(K31>J31,1,IF(K32>J32,1,0))) -> 0
J32: 6 | K32: 4
C34: 6.30 pm | D34: Men D | E34: Daniele Privitera | F34: Antoine Bugeja | G34: vs | H34: Kevin Sciberras(pro)Kenneth Caruana | I34: Alberto Bafumi | J34: 6 | K34: 2 | L34: =IF(AND(J34>K34,J35>K35),2,IF(J34>K34,1,IF(J35>K35,1,0))) -> 2 | M34: =IF(AND(K34>J34,K35>J35),2,IF(K34>J34,1,IF(K35>J35,1,0))) -> 0
J35: 7 | K35: 6
L37: =IF(AND(J37>K37,J38>K38),2,IF(J37>K37,1,IF(J38>K38,1,0))) -> 0 | M37: =IF(AND(K37>J37,K38>J38),2,IF(K37>J37,1,IF(K38>J38,1,0))) -> 0
C40: Total Day 6B | J40: =SUM(J28:J38) -> 37 | K40: =SUM(K28:K38) -> 15 | L40: =SUM(L28:L38) -> 6 | M40: =SUM(M28:M38) -> 0
C42: Total Day 6 | J42: =J40+J25 -> 77 | K42: =K40+K25 -> 48 | L42: =L40+L25 -> 11 | M42: =M40+M25 -> 3
C44: Court 2
C46: Time | D46: Rubber | E46: TEAM D: Juan Sammut | H46: TEAM E: Roberto Murdocco | J46: Games | L46: Sets
C48: 6.30 pm | D48: Lad C | E48: Frances Saliba Hersey | F48: Mary Borg | G48: vs | H48: Leanne Sammut | I48: Roberta Grixti | J48: 6 | K48: 3 | L48: =IF(AND(J48>K48,J49>K49),2,IF(J48>K48,1,IF(J49>K49,1,0))) -> 1 | M48: =IF(AND(K48>J48,K49>J49),2,IF(K48>J48,1,IF(K49>J49,1,0))) -> 1
J49: 2 | K49: 6
C51: 7.45 pm | D51: Men D | E51: Joseph Randich | F51: Owen Farrugia | G51: vs | H51: Matthias Cremona | I51: Oliver Brincat | J51: 3 | K51: 6 | L51: =IF(AND(J51>K51,J52>K52),2,IF(J51>K51,1,IF(J52>K52,1,0))) -> 0 | M51: =IF(AND(K51>J51,K52>J52),2,IF(K51>J51,1,IF(K52>J52,1,0))) -> 2
J52: 2 | K52: 6
C54: 9.00 pm | D54: Lad B | E54: Anabel Borg | F54: Sarah Axiaq | G54: vs | H54: Nancy Wong | I54: Mariska Steenkamer | J54: 2 | K54: 6 | L54: =IF(AND(J54>K54,J55>K55),2,IF(J54>K54,1,IF(J55>K55,1,0))) -> 0 | M54: =IF(AND(K54>J54,K55>J55),2,IF(K54>J54,1,IF(K55>J55,1,0))) -> 2
J55: 2 | K55: 6
L57: =IF(AND(J57>K57,J58>K58),2,IF(J57>K57,1,IF(J58>K58,1,0))) -> 0 | M57: =IF(AND(K57>J57,K58>J58),2,IF(K57>J57,1,IF(K58>J58,1,0))) -> 0
C60: Total Day 6 A | J60: =SUM(J48:J58) -> 17 | K60: =SUM(K48:K58) -> 33 | L60: =SUM(L48:L58) -> 1 | M60: =SUM(M48:M58) -> 5
C63: 3.30 pm | D63: Men A | E63: Jesmond Pule' | F63: David Mifsud | G63: vs | H63: Trevor Rutter | I63: Marco Mercieca | J63: 0 | K63: 6 | L63: =IF(AND(J63>K63,J64>K64),2,IF(J63>K63,1,IF(J64>K64,1,0))) -> 0 | M63: =IF(AND(K63>J63,K64>J64),2,IF(K63>J63,1,IF(K64>J64,1,0))) -> 2
J64: 2 | K64: 6
C66: 5.00pm | D66: Men B | E66: George Grech | F66: Jurgen Farrugia | G66: vs | H66: Emman Xuereb | I66: Roberto Murdocco | J66: 6 | K66: 1 | L66: =IF(AND(J66>K66,J67>K67),2,IF(J66>K66,1,IF(J67>K67,1,0))) -> 1 | M66: =IF(AND(K66>J66,K67>J67),2,IF(K66>J66,1,IF(K67>J67,1,0))) -> 1
J67: 5 | K67: 7
C69: 6.00pm | D69: Men C | E69: Juan Sammut | F69: Sam Micallef | G69: vs | H69: Aaron Micallef Piccione | I69: Jordan Lastimosa | J69: 7 | K69: 6 | L69: =IF(AND(J69>K69,J70>K70),2,IF(J69>K69,1,IF(J70>K70,1,0))) -> 1 | M69: =IF(AND(K69>J69,K70>J70),2,IF(K69>J69,1,IF(K70>J70,1,0))) -> 1
J70: 2 | K70: 6
C72: 6.30pm | D72: Lad A | E72: Leanne Vassallo | F72: Alison Muscat | G72: vs | H72: Annmarie Mangion | I72: Mae Jane Manzanares | J72: 4 | K72: 6 | L72: =IF(AND(J72>K72,J73>K73),2,IF(J72>K72,1,IF(J73>K73,1,0))) -> 0 | M72: =IF(AND(K72>J72,K73>J73),2,IF(K72>J72,1,IF(K73>J73,1,0))) -> 2
J73: 1 | K73: 6
...

Sheet Day 7
C1: SAN MICHEL TEAM TOURNAMENT 2026
C6: Day 7 - 13/03/2026 & 14/03/2026
C9: Court 1
C11: Time | D11: Rubber | E11: TEAM B: Cory Greenland | H11: TEAM E: Roberto Murdocco | J11: Games | L11: Sets
C13: 6.30 pm | D13: Lad C | E13: Karolina Papiernik | F13: Christabelle Chetcuti | G13: vs | H13: Leanne Sammut | I13: Maria Ellul | J13: 6 | K13: 4 | L13: =IF(AND(J13>K13,J14>K14),2,IF(J13>K13,1,IF(J14>K14,1,0))) -> 1 | M13: =IF(AND(K13>J13,K14>J14),2,IF(K13>J13,1,IF(K14>J14,1,0))) -> 1
J14: 5 | K14: 7
C16: 7.45 pm | G16: vs | L16: =IF(AND(J16>K16,J17>K17),2,IF(J16>K16,1,IF(J17>K17,1,0))) -> 0 | M16: =IF(AND(K16>J16,K17>J17),2,IF(K16>J16,1,IF(K17>J17,1,0))) -> 0
C19: 9.00 pm | D19: Men C | E19: Kenneth Farrugia | F19: Cory Greenland | G19: vs | H19: Max Anastasi | I19: Jordan Lastimosa | J19: 7 | K19: 5 | L19: =IF(AND(J19>K19,J20>K20),2,IF(J19>K19,1,IF(J20>K20,1,0))) -> 1 | M19: =IF(AND(K19>J19,K20>J20),2,IF(K19>J19,1,IF(K20>J20,1,0))) -> 1
J20: 6 | K20: 7
C22: 3.30 pm | D22: Men A | E22: Gareth Magri | F22: Fotios Evangelou | G22: vs | H22: Marco Mercieca | I22: Ivan Cachia | J22: 6 | K22: 0 | L22: =IF(AND(J22>K22,J23>K23),2,IF(J22>K22,1,IF(J23>K23,1,0))) -> 2 | M22: =IF(AND(K22>J22,K23>J23),2,IF(K22>J22,1,IF(K23>J23,1,0))) -> 0
J23: 7 | K23: 6
C25: Total Day 7 A | J25: =SUM(J13:J23) -> 37 | K25: =SUM(K13:K23) -> 29 | L25: =SUM(L13:L23) -> 4 | M25: =SUM(M13:M23) -> 2
C28: 3.30 pm | D28: Lad B | E28: Andrea Magalgi | F28: Giada Sciberras | G28: vs | H28: Nancy Wong | I28: Mariska Steenkameer | J28: 6 | K28: 1 | L28: =IF(AND(J28>K28,J29>K29),2,IF(J28>K28,1,IF(J29>K29,1,0))) -> 2 | M28: =IF(AND(K28>J28,K29>J29),2,IF(K28>J28,1,IF(K29>J29,1,0))) -> 0
J29: 6 | K29: 3
C31: 5.00 pm | D31: Lad A | E31: Christine Schembri | F31: Kaya Sammut | G31: vs | H31: Annmarie Mangion | I31: Elaine Grech | J31: 3 | K31: 6 | L31: =IF(AND(J31>K31,J32>K32),2,IF(J31>K31,1,IF(J32>K32,1,0))) -> 0 | M31: =IF(AND(K31>J31,K32>J32),2,IF(K31>J31,1,IF(K32>J32,1,0))) -> 2
J32: 3 | K32: 6
C34: 5.00 pm | D34: Men B | E34: Kristen Cachia | F34: Tobias Kristensen | G34: vs | H34: Emman Xuereb | I34: Luke Genuis | J34: 6 | K34: 7 | L34: =IF(AND(J34>K34,J35>K35),2,IF(J34>K34,1,IF(J35>K35,1,0))) -> 1 | M34: =IF(AND(K34>J34,K35>J35),2,IF(K34>J34,1,IF(K35>J35,1,0))) -> 1
J35: 6 | K35: 1
C37: 6.30 pm | D37: Men D | E37: David Camilleri | F37: Mario Abdilla | G37: vs | H37: Matthias Cremona | I37: Braydon Galea | J37: 2 | K37: 6 | L37: =IF(AND(J37>K37,J38>K38),2,IF(J37>K37,1,IF(J38>K38,1,0))) -> 0 | M37: =IF(AND(K37>J37,K38>J38),2,IF(K37>J37,1,IF(K38>J38,1,0))) -> 2
J38: 3 | K38: 6
C40: Total Day 7B | J40: =SUM(J28:J38) -> 35 | K40: =SUM(K28:K38) -> 36 | L40: =SUM(L28:L38) -> 3 | M40: =SUM(M28:M38) -> 5
C42: Total Day 7 | J42: =J40+J25 -> 72 | K42: =K40+K25 -> 65 | L42: =L40+L25 -> 7 | M42: =M40+M25 -> 7
C44: Court 2
C46: Time | D46: Rubber | E46: TEAM A: Christine Scerri | H46: TEAM F: Diane Fenech | J46: Games | L46: Sets
C48: 6.30 pm | D48: Men A | E48: Clayton Zammit Cesare | F48: Jonathan Martinelli | G48: vs | H48: Kurt Carabott | I48: Andrew Spiteri Willets | J48: 6 | K48: 3 | L48: =IF(AND(J48>K48,J49>K49),2,IF(J48>K48,1,IF(J49>K49,1,0))) -> 2 | M48: =IF(AND(K48>J48,K49>J49),2,IF(K48>J48,1,IF(K49>J49,1,0))) -> 0
J49: 6 | K49: 4
C51: 7.45 pm | D51: Lad A | E51: Amanda Falzon | F51: Yanika Pace | G51: vs | H51: Renette Magro | I51: Christina Bonett | J51: 0 | K51: 6 | L51: =IF(AND(J51>K51,J52>K52),2,IF(J51>K51,1,IF(J52>K52,1,0))) -> 0 | M51: =IF(AND(K51>J51,K52>J52),2,IF(K51>J51,1,IF(K52>J52,1,0))) -> 2
J52: 2 | K52: 6
C54: 9.00 pm | D54: Men C | E54: Alain Frendo | F54: Charles Sacco | G54: vs | H54: Julian Esposito | I54: Simone Re | J54: 3 | K54: 6 | L54: =IF(AND(J54>K54,J55>K55),2,IF(J54>K54,1,IF(J55>K55,1,0))) -> 1 | M54: =IF(AND(K54>J54,K55>J55),2,IF(K54>J54,1,IF(K55>J55,1,0))) -> 1
J55: 6 | K55: 3
C57: 7.45 pm | D57: Lad C | E57: Josette Cassar | F57: Christine Scerri | G57: vs | H57: Tiziana Spiteri | I57: Daphne Vella | J57: 1 | K57: 6 | L57: =IF(AND(J57>K57,J58>K58),2,IF(J57>K57,1,IF(J58>K58,1,0))) -> 0 | M57: =IF(AND(K57>J57,K58>J58),2,IF(K57>J57,1,IF(K58>J58,1,0))) -> 2
J58: 0 | K58: 6
C60: Total Day 7 A | J60: =SUM(J48:J58) -> 24 | K60: =SUM(K48:K58) -> 40 | L60: =SUM(L48:L58) -> 3 | M60: =SUM(M48:M58) -> 5
C63: 3.30 pm | D63: Men B | E63: Clint Agius | F63: Charles Sacco(pro)Sandro Pecorella | G63: vs | H63: Sergey Kasatkin | I63: Richard Curmi | J63: 4 | K63: 6 | L63: =IF(AND(J63>K63,J64>K64),2,IF(J63>K63,1,IF(J64>K64,1,0))) -> 0 | M63: =IF(AND(K63>J63,K64>J64),2,IF(K63>J63,1,IF(K64>J64,1,0))) -> 2
J64: 4 | K64: 6
C66: 5.00pm | D66: Lad B | E66: Tiffany Fenech | F66: Deborah Farrugia | G66: vs | H66: Maria Angela Gambin | I66: Romina Gauci | J66: 4 | K66: 6 | L66: =IF(AND(J66>K66,J67>K67),2,IF(J66>K66,1,IF(J67>K67,1,0))) -> 0 | M66: =IF(AND(K66>J66,K67>J67),2,IF(K66>J66,1,IF(K67>J67,1,0))) -> 2
J67: 3 | K67: 6
C69: 6.30 pm | D69: Men D | E69: Daniele Privitera | F69: Dorian Demanuele | G69: vs | H69: Ryan Ebejer | I69: Clinton Cutajar | J69: 4 | K69: 6 | L69: =IF(AND(J69>K69,J70>K70),2,IF(J69>K69,1,IF(J70>K70,1,0))) -> 0 | M69: =IF(AND(K69>J69,K70>J70),2,IF(K69>J69,1,IF(K70>J70,1,0))) -> 2
J70: 3 | K70: 6
L72: =IF(AND(J72>K72,J73>K73),2,IF(J72>K72,1,IF(J73>K73,1,0))) -> 0 | M72: =IF(AND(K72>J72,K73>J73),2,IF(K72>J72,1,IF(K73>J73,1,0))) -> 0
...

Sheet Day 8
C1: SAN MICHEL TEAM TOURNAMENT 2026
C6: Day 8 - 20/03/2026 & 21/03/2026
C9: Court 1
C11: Time | D11: Rubber | E11: TEAM C: Jean Paul Sciberras | H11: TEAM F: Diane Fenech | J11: Games | L11: Sets
C13: 6.30 pm | D13: Men A | E13: Manuel Bonello | F13: Matthew Pace | G13: vs | H13: Kurt Carabott | I13: Jean Attard | J13: 6 | K13: 2 | L13: =IF(AND(J13>K13,J14>K14),2,IF(J13>K13,1,IF(J14>K14,1,0))) -> 2 | M13: =IF(AND(K13>J13,K14>J14),2,IF(K13>J13,1,IF(K14>J14,1,0))) -> 0
J14: 6 | K14: 0
C16: 6.30 pm | D16: Men D | E16: Kevin Sciberras | F16: Alberto Bafumi | G16: vs | H16: Ryan Ebejer | I16: Clinton Cutajar | J16: 3 | K16: 6 | L16: =IF(AND(J16>K16,J17>K17),2,IF(J16>K16,1,IF(J17>K17,1,0))) -> 0 | M16: =IF(AND(K16>J16,K17>J17),2,IF(K16>J16,1,IF(K17>J17,1,0))) -> 2
J17: 6 | K17: 7
C19: 7.45 pm | D19: Lad B | E19: Kristina Briffa | F19: Brenda Baldacchino | G19: vs | H19: Maria Angela Gambin | I19: Ann Marie Attard | J19: 6 | K19: 3 | L19: =IF(AND(J19>K19,J20>K20),2,IF(J19>K19,1,IF(J20>K20,1,0))) -> 2 | M19: =IF(AND(K19>J19,K20>J20),2,IF(K19>J19,1,IF(K20>J20,1,0))) -> 0
J20: 7 | K20: 6
C22: 9.00 pm | D22: Lad C | E22: Francesca Mamo | F22: Jodie Stivala | G22: vs | H22: Tiziana Spiteri | I22: Kim Bonello | J22: 6 | K22: 1 | L22: =IF(AND(J22>K22,J23>K23),2,IF(J22>K22,1,IF(J23>K23,1,0))) -> 2 | M22: =IF(AND(K22>J22,K23>J23),2,IF(K22>J22,1,IF(K23>J23,1,0))) -> 0
J23: 6 | K23: 0
C25: Total Day 8 A | J25: =SUM(J13:J23) -> 46 | K25: =SUM(K13:K23) -> 25 | L25: =SUM(L13:L23) -> 6 | M25: =SUM(M13:M23) -> 2
C28: 3.30 pm | D28: Lad A | E28: Alexia Spiteri Willets | F28: Olivia Belli | G28: vs | H28: Renette Magro | I28: Anthea Gauci | J28: 3 | K28: 6 | L28: =IF(AND(J28>K28,J29>K29),2,IF(J28>K28,1,IF(J29>K29,1,0))) -> 0 | M28: =IF(AND(K28>J28,K29>J29),2,IF(K28>J28,1,IF(K29>J29,1,0))) -> 2
J29: 0 | K29: 6
C31: 3.30 pm | D31: Men B | E31: Jonathan Vella | F31: Willem Steenkamer | G31: vs | H31: Sergey Kasatkin | I31: Steve Gambin | J31: 6 | K31: 3 | L31: =IF(AND(J31>K31,J32>K32),2,IF(J31>K31,1,IF(J32>K32,1,0))) -> 2 | M31: =IF(AND(K31>J31,K32>J32),2,IF(K31>J31,1,IF(K32>J32,1,0))) -> 0
J32: 6 | K32: 2
C34: 5.00 pm | D34: Men C | E34: Matthew Schembri | F34: Jean Paul Sciberras | G34: vs | H34: Julian Esposito | I34: Simone Re | J34: 6 | K34: 7 | L34: =IF(AND(J34>K34,J35>K35),2,IF(J34>K34,1,IF(J35>K35,1,0))) -> 1 | M34: =IF(AND(K34>J34,K35>J35),2,IF(K34>J34,1,IF(K35>J35,1,0))) -> 1
J35: 7 | K35: 5
C37: 6.30 pm | G37: vs | L37: =IF(AND(J37>K37,J38>K38),2,IF(J37>K37,1,IF(J38>K38,1,0))) -> 0 | M37: =IF(AND(K37>J37,K38>J38),2,IF(K37>J37,1,IF(K38>J38,1,0))) -> 0
C40: Total Day 8 B | J40: =SUM(J28:J38) -> 28 | K40: =SUM(K28:K38) -> 29 | L40: =SUM(L28:L38) -> 3 | M40: =SUM(M28:M38) -> 3
C42: Total Day 8 | J42: =J40+J25 -> 74 | K42: =K40+K25 -> 54 | L42: =L40+L25 -> 9 | M42: =M40+M25 -> 5
C44: Court 2
C46: Time | D46: Rubber | E46: TEAM D: Juan Sammut | H46: TEAM B: Cory Greenland | J46: Games | L46: Sets
