Workbook

Sheet Players Men
A1: VITTORIOSA LAWN TENNIS CLUB MENS CHOSEN DOUBLES 2024
B5: Men Division 1 - Group A | F5: Men Division 1 - Group B
A6: 1 | B6: Matthew Borg/Jean Attard | E6: 1 | F6: Duncan D'Alessandro/Jesmond Pule’
A7: 2 | B7: Gavin Borg/Massimo Giovannini | E7: 2 | F7: Gabriel Pace/Nikolai Belli
A8: 3 | B8: Claude Mifsud Wismayer/Adrian Chetcuti | E8: 3 | F8: Reuben Borg/Luigi Porto
A9: 4 | B9: Trevor Rutter/Jean Carl Azzopardi | E9: 4 | F9: Matthew Borg/Roderick Spiteri
A10: 5 | B10: Matthew Mifsud/Melchior Farrugia | E10: 5 | F10: David Schembri/Fotis Evangelou
B12: Men Division 2 - Group A | F12: Men Division 2 - Group B
A13: 1 | B13: Ivan Cachia/Willem Steenkamer | E13: 1 | F13: Manuel Mifsud/Julian Esposito
A14: 2 | B14: Chi Chi Canonce/Kristen Cachia | E14: 2 | F14: Ivan Cassar/Kurt Cassar
A15: 3 | B15: Gene Zammit/Justin Graeme Christie | E15: 3 | F15: Mavric Sawyer/Keith Tanti
A16: 4 | B16: Jonathan Vella/Clint Aguis | E16: 4 | F16: Neville Sciriha/Roberto Murdocco
A17: 5 | B17: Jonathan Martinelli/Daryl Pace | E17: 5 | F17: Etienne Formosa Carabez/Javier Viloria
B19: Men Division 3
A20: 1 | B20: Denis Caruana/Duncan Zammit
A21: 2 | B21: Aaron Micallef Piccone/Adrian Sciberras
A22: 3 | B22: Cory Greenland/Benjamin Valencia
A23: 4 | B23: Dunstan Vella/Cyril Lastimosa
A24: 5 | B24: Maurice Borg/Kenneth Caruana
A25: 6 | B25: Kenneth Farrugia/Juan Sammut
B27: Men Division 4
A28: 1 | B28: Charles Micallef/Charles Grech
A29: 2 | B29: Antoine Bugeja/Simone Ercolani
A30: 3 | B30: Kevin Sciberras/Justin Scicluna
A31: 4 | B31: Sean Cachia/Isaac Joseph Zammit
A32: 5 | B32: Robert Attard/Steve Gambin
A33: 6 | B33: Isaac Baldacchino/JP Sciberras

Sheet Men Div 1
A1: VITTORIOSA LAWN TENNIS CLUB Sports Experience Chosen Doubles 2024
A5: Men Division 1 - Group A
A7: Players | B7: Set Scores | H7: Tie | P7: Players | Q7: Set Scores | W7: Tie | AE7: Player | AF7: Matches Played | AG7: Points Overall | AH7: Games Won | AI7: Sets Won
B8: Score | C8: Set 1 Work | E8: Score | F8: Set 2 Work | H8: Score | I8: Tie Work | J8: Game Played | K8: Sets Points Work | L8: Sets & Tie Points Work | M8: Games Wins Work | N8: Sets Wins Work | Q8: Score | R8: Set 1 Work | T8: Score | U8: Set 2 Work | W8: Score | X8: Tie Work | Y8: Game Played | Z8: Sets Points Work | AA8: Sets & Tie Points Work | AB8: Games Wins Work | AC8: Sets Wins Work | AJ8: Winner Working | AK8: Total Games Work | AL8: Winner
A9: =AE9 -> Matthew Borg/Jean Attard | B9: 7 | C9: =IF(B9>B11,1,0) -> 1 | E9: 6 | F9: =IF(E9>E11,1,0) -> 0 | H9: 10 | I9: =IF(H9>H11,1,0) -> 1 | J9: =IF(B9="",0,1) -> 1 | K9: =IF(C9+F9=2,3,IF(C9+F9=1,1,0)) -> 1 | L9: =IF(K9=3,3,IF(I9+K9=2,2,IF(K9=1,1,0))) -> 2 | M9: =B9+E9 -> 13 | N9: =C9+F9+I9 -> 2 | P9: =AE9 -> Matthew Borg/Jean Attard | Q9: 6 | R9: =IF(Q9>Q11,1,0) -> 1 | T9: 6 | U9: =IF(T9>T11,1,0) -> 1 | X9: =IF(W9>W11,1,0) -> 0 | Y9: =IF(Q9="",0,1) -> 1 | Z9: =IF(R9+U9=2,3,IF(R9+U9=1,1,0)) -> 3 | AA9: =IF(Z9=3,3,IF(X9+Z9=2,2,IF(Z9=1,1,0))) -> 3 | AB9: =Q9+T9 -> 12 | AC9: =R9+U9+X9 -> 2 | AE9: ='Players Men'!B6 -> Matthew Borg/Jean Attard | AF9: =J9+Y9+Y13+J13 -> 4 | AG9: =L9+AA9+L13+AA13 -> 9 | AH9: =M9+AB9+M13+AB13 -> 46 | AI9: =N9+AC9+N13+AC13 -> 7 | AJ9: =MAX(AG9:AG19) -> 11 | AK9: =SUM(AF9:AF19) -> 20 | AL9: =IF(AG9=$AJ$9,AE9,IF(AG11=$AJ$9,AE11,IF(AG13=$AJ$9,AE13,IF(AG15=$AJ$9,AE15,IF(AG17=$AJ$9,AE17,IF(AG19=$AJ$9,AE19,"")))))) -> Matthew Mifsud/Melchior Farrugia
A10: vs. | P10: vs.
A11: =AE11 -> Gavin Borg/Massimo Giovannini | B11: 5 | C11: =IF(B11>B9,1,0) -> 0 | E11: 7 | F11: =IF(E11>E9,1,0) -> 1 | H11: 5 | I11: =IF(H11>H9,1,0) -> 0 | J11: =IF(B11="",0,1) -> 1 | K11: =IF(C11+F11=2,3,IF(C11+F11=1,1,0)) -> 1 | L11: =IF(K11=3,3,IF(I11+K11=2,2,IF(K11=1,1,0))) -> 1 | M11: =B11+E11 -> 12 | N11: =C11+F11+I11 -> 1 | P11: =AE13 -> Claude Mifsud Wismayer/Adrian Chetcuti | Q11: 2 | R11: =IF(Q11>Q9,1,0) -> 0 | T11: 0 | U11: =IF(T11>T9,1,0) -> 0 | X11: =IF(W11>W9,1,0) -> 0 | Y11: =IF(Q11="",0,1) -> 1 | Z11: =IF(R11+U11=2,3,IF(R11+U11=1,1,0)) -> 0 | AA11: =IF(Z11=3,3,IF(X11+Z11=2,2,IF(Z11=1,1,0))) -> 0 | AB11: =Q11+T11 -> 2 | AC11: =R11+U11+X11 -> 0 | AE11: ='Players Men'!B7 -> Gavin Borg/Massimo Giovannini | AF11: =J11+J25+Y21+J21 -> 4 | AG11: =L11+L25+AA21+L21 -> 1 | AH11: =M11+M25+AB21+M21 -> 29 | AI11: =N11+N25+AC21+N21 -> 1
A13: =AE9 -> Matthew Borg/Jean Attard | B13: 6 | C13: =IF(B13>B15,1,0) -> 1 | E13: 6 | F13: =IF(E13>E15,1,0) -> 1 | I13: =IF(H13>H15,1,0) -> 0 | J13: =IF(B13="",0,1) -> 1 | K13: =IF(C13+F13=2,3,IF(C13+F13=1,1,0)) -> 3 | L13: =IF(K13=3,3,IF(I13+K13=2,2,IF(K13=1,1,0))) -> 3 | M13: =B13+E13 -> 12 | N13: =C13+F13+I13 -> 2 | P13: =AE9 -> Matthew Borg/Jean Attard | Q13: 3 | R13: =IF(Q13>Q15,1,0) -> 0 | T13: 6 | U13: =IF(T13>T15,1,0) -> 1 | W13: 8 | X13: =IF(W13>W15,1,0) -> 0 | Y13: =IF(Q13="",0,1) -> 1 | Z13: =IF(R13+U13=2,3,IF(R13+U13=1,1,0)) -> 1 | AA13: =IF(Z13=3,3,IF(X13+Z13=2,2,IF(Z13=1,1,0))) -> 1 | AB13: =Q13+T13 -> 9 | AC13: =R13+U13+X13 -> 1 | AE13: ='Players Men'!B8 -> Claude Mifsud Wismayer/Adrian Chetcuti | AF13: =Y17+J23+J17+Y11 -> 4 | AG13: =L17+AA17+AA11+L23 -> 4 | AH13: =M17+AB11+M23+AB17 -> 29 | AI13: =N17+AC17+AC11+N23 -> 3
A14: vs. | P14: vs.
A15: =AE15 -> Trevor Rutter/Jean Carl Azzopardi | B15: 3 | C15: =IF(B15>B13,1,0) -> 0 | E15: 4 | F15: =IF(E15>E13,1,0) -> 0 | I15: =IF(H15>H13,1,0) -> 0 | J15: =IF(B15="",0,1) -> 1 | K15: =IF(C15+F15=2,3,IF(C15+F15=1,1,0)) -> 0 | L15: =IF(K15=3,3,IF(I15+K15=2,2,IF(K15=1,1,0))) -> 0 | M15: =B15+E15 -> 7 | N15: =C15+F15+I15 -> 0 | P15: =AE17 -> Matthew Mifsud/Melchior Farrugia | Q15: 6 | R15: =IF(Q15>Q13,1,0) -> 1 | T15: 3 | U15: =IF(T15>T13,1,0) -> 0 | W15: 10 | X15: =IF(W15>W13,1,0) -> 1 | Y15: =IF(Q15="",0,1) -> 1 | Z15: =IF(R15+U15=2,3,IF(R15+U15=1,1,0)) -> 1 | AA15: =IF(Z15=3,3,IF(X15+Z15=2,2,IF(Z15=1,1,0))) -> 2 | AB15: =Q15+T15 -> 9 | AC15: =R15+U15+X15 -> 2 | AE15: ='Players Men'!B9 -> Trevor Rutter/Jean Carl Azzopardi | AF15: =Y19+J15+Y23+J29 -> 4 | AG15: =AA19+L15+AA23+L29 -> 5 | AH15: =AB19+M15+AB23+M29 -> 34 | AI15: =AC19+N15+AC23+N29 -> 4
A17: =AE13 -> Claude Mifsud Wismayer/Adrian Chetcuti | B17: 4 | C17: =IF(B17>B19,1,0) -> 0 | E17: 2 | F17: =IF(E17>E19,1,0) -> 0 | I17: =IF(H17>H19,1,0) -> 0 | J17: =IF(B17="",0,1) -> 1 | K17: =IF(C17+F17=2,3,IF(C17+F17=1,1,0)) -> 0 | L17: =IF(K17=3,3,IF(I17+K17=2,2,IF(K17=1,1,0))) -> 0 | M17: =B17+E17 -> 6 | N17: =C17+F17+I17 -> 0 | P17: =AE13 -> Claude Mifsud Wismayer/Adrian Chetcuti | Q17: 3 | R17: =IF(Q17>Q19,1,0) -> 0 | T17: 6 | U17: =IF(T17>T19,1,0) -> 1 | W17: 5 | X17: =IF(W17>W19,1,0) -> 0 | Y17: =IF(Q17="",0,1) -> 1 | Z17: =IF(R17+U17=2,3,IF(R17+U17=1,1,0)) -> 1 | AA17: =IF(Z17=3,3,IF(X17+Z17=2,2,IF(Z17=1,1,0))) -> 1 | AB17: =Q17+T17 -> 9 | AC17: =R17+U17+X17 -> 1 | AE17: ='Players Men'!B10 -> Matthew Mifsud/Melchior Farrugia | AF17: =Y15+J27+J19+J31 -> 4 | AG17: =AA15+L27+L19+L31 -> 11 | AH17: =AB15+M27+M19+M31 -> 46 | AI17: =N31+N27+AC15+N19 -> 8
A18: vs. | P18: vs.
A19: =AE17 -> Matthew Mifsud/Melchior Farrugia | B19: 6 | C19: =IF(B19>B17,1,0) -> 1 | E19: 6 | F19: =IF(E19>E17,1,0) -> 1 | I19: =IF(H19>H17,1,0) -> 0 | J19: =IF(B19="",0,1) -> 1 | K19: =IF(C19+F19=2,3,IF(C19+F19=1,1,0)) -> 3 | L19: =IF(K19=3,3,IF(I19+K19=2,2,IF(K19=1,1,0))) -> 3 | M19: =B19+E19 -> 12 | N19: =C19+F19+I19 -> 2 | P19: =AE15 -> Trevor Rutter/Jean Carl Azzopardi | Q19: 6 | R19: =IF(Q19>Q17,1,0) -> 1 | T19: 3 | U19: =IF(T19>T17,1,0) -> 0 | W19: 10 | X19: =IF(W19>W17,1,0) -> 1 | Y19: =IF(Q19="",0,1) -> 1 | Z19: =IF(R19+U19=2,3,IF(R19+U19=1,1,0)) -> 1 | AA19: =IF(Z19=3,3,IF(X19+Z19=2,2,IF(Z19=1,1,0))) -> 2 | AB19: =Q19+T19 -> 9 | AC19: =R19+U19+X19 -> 2 | AE19: Group A Winner
AE20: Matthew Mifsud/Melchior Farrugia
A21: =AE11 -> Gavin Borg/Massimo Giovannini | B21: 2 | C21: =IF(B21>B23,1,0) -> 0 | E21: 3 | F21: =IF(E21>E23,1,0) -> 0 | I21: =IF(H21>H23,1,0) -> 0 | J21: =IF(B21="",0,1) -> 1 | K21: =IF(C21+F21=2,3,IF(C21+F21=1,1,0)) -> 0 | L21: =IF(K21=3,3,IF(I21+K21=2,2,IF(K21=1,1,0))) -> 0 | M21: =B21+E21 -> 5 | N21: =C21+F21+I21 -> 0 | P21: =AE11 -> Gavin Borg/Massimo Giovannini | Q21: 2 | R21: =IF(Q21>Q23,1,0) -> 0 | T21: 3 | U21: =IF(T21>T23,1,0) -> 0 | X21: =IF(W21>W23,1,0) -> 0 | Y21: =IF(Q21="",0,1) -> 1 | Z21: =IF(R21+U21=2,3,IF(R21+U21=1,1,0)) -> 0 | AA21: =IF(Z21=3,3,IF(X21+Z21=2,2,IF(Z21=1,1,0))) -> 0 | AB21: =Q21+T21 -> 5 | AC21: =R21+U21+X21 -> 0
A22: vs. | P22: vs.
A23: =AE13 -> Claude Mifsud Wismayer/Adrian Chetcuti | B23: 6 | C23: =IF(B23>B21,1,0) -> 1 | E23: 6 | F23: =IF(E23>E21,1,0) -> 1 | I23: =IF(H23>H21,1,0) -> 0 | J23: =IF(B23="",0,1) -> 1 | K23: =IF(C23+F23=2,3,IF(C23+F23=1,1,0)) -> 3 | L23: =IF(K23=3,3,IF(I23+K23=2,2,IF(K23=1,1,0))) -> 3 | M23: =B23+E23 -> 12 | N23: =C23+F23+I23 -> 2 | P23: =AE15 -> Trevor Rutter/Jean Carl Azzopardi | Q23: 6 | R23: =IF(Q23>Q21,1,0) -> 1 | T23: 6 | U23: =IF(T23>T21,1,0) -> 1 | X23: =IF(W23>W21,1,0) -> 0 | Y23: =IF(Q23="",0,1) -> 1 | Z23: =IF(R23+U23=2,3,IF(R23+U23=1,1,0)) -> 3 | AA23: =IF(Z23=3,3,IF(X23+Z23=2,2,IF(Z23=1,1,0))) -> 3 | AB23: =Q23+T23 -> 12 | AC23: =R23+U23+X23 -> 2
A25: =AE11 -> Gavin Borg/Massimo Giovannini | B25: 5 | C25: =IF(B25>B27,1,0) -> 0 | E25: 2 | F25: =IF(E25>E27,1,0) -> 0 | I25: =IF(H25>H27,1,0) -> 0 | J25: =IF(B25="",0,1) -> 1 | K25: =IF(C25+F25=2,3,IF(C25+F25=1,1,0)) -> 0 | L25: =IF(K25=3,3,IF(I25+K25=2,2,IF(K25=1,1,0))) -> 0 | M25: =B25+E25 -> 7 | N25: =C25+F25+I25 -> 0 | O25: Ret
A26: vs.
A27: =AE17 -> Matthew Mifsud/Melchior Farrugia | B27: 7 | C27: =IF(B27>B25,1,0) -> 1 | E27: 6 | F27: =IF(E27>E25,1,0) -> 1 | I27: =IF(H27>H25,1,0) -> 0 | J27: =IF(B27="",0,1) -> 1 | K27: =IF(C27+F27=2,3,IF(C27+F27=1,1,0)) -> 3 | L27: =IF(K27=3,3,IF(I27+K27=2,2,IF(K27=1,1,0))) -> 3 | M27: =B27+E27 -> 13 | N27: =C27+F27+I27 -> 2
A29: =AE15 -> Trevor Rutter/Jean Carl Azzopardi | B29: 2 | C29: =IF(B29>B31,1,0) -> 0 | E29: 4 | F29: =IF(E29>E31,1,0) -> 0 | I29: =IF(H29>H31,1,0) -> 0 | J29: =IF(B29="",0,1) -> 1 | K29: =IF(C29+F29=2,3,IF(C29+F29=1,1,0)) -> 0 | L29: =IF(K29=3,3,IF(I29+K29=2,2,IF(K29=1,1,0))) -> 0 | M29: =B29+E29 -> 6 | N29: =C29+F29+I29 -> 0
A30: vs.
A31: =AE17 -> Matthew Mifsud/Melchior Farrugia | B31: 6 | C31: =IF(B31>B29,1,0) -> 1 | E31: 6 | F31: =IF(E31>E29,1,0) -> 1 | I31: =IF(H31>H29,1,0) -> 0 | J31: =IF(B31="",0,1) -> 1 | K31: =IF(C31+F31=2,3,IF(C31+F31=1,1,0)) -> 3 | L31: =IF(K31=3,3,IF(I31+K31=2,2,IF(K31=1,1,0))) -> 3 | M31: =B31+E31 -> 12 | N31: =C31+F31+I31 -> 2
A53: Men Division 1 - Group B
A55: Players | B55: Set Scores | H55: Tie | P55: Players | Q55: Set Scores | W55: Tie | AE55: Player | AF55: Matches Played | AG55: Points Overall | AH55: Games Won | AI55: Sets Won
B56: Score | C56: Set 1 Work | E56: Score | F56: Set 2 Work | H56: Score | I56: Tie Work | J56: Game Played | K56: Sets Points Work | L56: Sets & Tie Points Work | M56: Games Wins Work | N56: Sets Wins Work | Q56: Score | R56: Set 1 Work | T56: Score | U56: Set 2 Work | W56: Score | X56: Tie Work | Y56: Game Played | Z56: Sets Points Work | AA56: Sets & Tie Points Work | AB56: Games Wins Work | AC56: Sets Wins Work | AJ56: Winner Working | AK56: Total Games Work | AL56: Winner
A57: =AE57 -> Duncan D'Alessandro/Jesmond Pule’ | B57: 7 | C57: =IF(B57>B59,1,0) -> 1 | E57: 3 | F57: =IF(E57>E59,1,0) -> 0 | H57: 10 | I57: =IF(H57>H59,1,0) -> 1 | J57: =IF(B57="",0,1) -> 1 | K57: =IF(C57+F57=2,3,IF(C57+F57=1,1,0)) -> 1 | L57: =IF(K57=3,3,IF(I57+K57=2,2,IF(K57=1,1,0))) -> 2 | M57: =B57+E57 -> 10 | N57: =C57+F57+I57 -> 2 | P57: =AE57 -> Duncan D'Alessandro/Jesmond Pule’ | Q57: 6 | R57: =IF(Q57>Q59,1,0) -> 1 | T57: 6 | U57: =IF(T57>T59,1,0) -> 1 | X57: =IF(W57>W59,1,0) -> 0 | Y57: =IF(Q57="",0,1) -> 1 | Z57: =IF(R57+U57=2,3,IF(R57+U57=1,1,0)) -> 3 | AA57: =IF(Z57=3,3,IF(X57+Z57=2,2,IF(Z57=1,1,0))) -> 3 | AB57: =Q57+T57 -> 12 | AC57: =R57+U57+X57 -> 2 | AE57: ='Players Men'!F6 -> Duncan D'Alessandro/Jesmond Pule’ | AF57: =J57+Y57+J61+Y61 -> 4 | AG57: =L57+AA57+L61+AA61 -> 11 | AH57: =M57+AB57+M61+AB61 -> 47 | AI57: =N57+AC57+N61+AC61 -> 8 | AJ57: =MAX(AG57:AG66) -> 11 | AK57: =SUM(AF57:AF66) -> 18 | AL57: =IF(AG57=$AJ$57,AE57,IF(AG59=$AJ$57,AE59,IF(AG61=$AJ$57,AE61,IF(AG63=$AJ$57,AE63,IF(AG65=$AJ$57,AE65,IF(#REF!=$AJ$57,#REF!,"")))))) -> Duncan D'Alessandro/Jesmond Pule’
A58: vs. | P58: vs.
A59: =AE59 -> Gabriel Pace/Nikolai Belli | B59: 6 | C59: =IF(B59>B57,1,0) -> 0 | E59: 6 | F59: =IF(E59>E57,1,0) -> 1 | H59: 6 | I59: =IF(H59>H57,1,0) -> 0 | J59: =IF(B59="",0,1) -> 1 | K59: =IF(C59+F59=2,3,IF(C59+F59=1,1,0)) -> 1 | L59: =IF(K59=3,3,IF(I59+K59=2,2,IF(K59=1,1,0))) -> 1 | M59: =B59+E59 -> 12 | N59: =C59+F59+I59 -> 1 | P59: =AE61 -> Reuben Borg/Luigi Porto | Q59: 3 | R59: =IF(Q59>Q57,1,0) -> 0 | T59: 1 | U59: =IF(T59>T57,1,0) -> 0 | X59: =IF(W59>W57,1,0) -> 0 | Y59: =IF(Q59="",0,1) -> 1 | Z59: =IF(R59+U59=2,3,IF(R59+U59=1,1,0)) -> 0 | AA59: =IF(Z59=3,3,IF(X59+Z59=2,2,IF(Z59=1,1,0))) -> 0 | AB59: =Q59+T59 -> 4 | AC59: =R59+U59+X59 -> 0 | AE59: ='Players Men'!F7 -> Gabriel Pace/Nikolai Belli | AF59: =J59+J73+Y69+J69 -> 3 | AG59: =L59+L73+AA69+L69 -> 6 | AH59: =M59+M73+AB69+M69 -> 37 | AI59: =N59+N73+AC69+N69 -> 5
A61: =AE57 -> Duncan D'Alessandro/Jesmond Pule’ | B61: 7 | C61: =IF(B61>B63,1,0) -> 1 | E61: 6 | F61: =IF(E61>E63,1,0) -> 1 | I61: =IF(H61>H63,1,0) -> 0 | J61: =IF(B61="",0,1) -> 1 | K61: =IF(C61+F61=2,3,IF(C61+F61=1,1,0)) -> 3 | L61: =IF(K61=3,3,IF(I61+K61=2,2,IF(K61=1,1,0))) -> 3 | M61: =B61+E61 -> 13 | N61: =C61+F61+I61 -> 2 | P61: =AE57 -> Duncan D'Alessandro/Jesmond Pule’ | Q61: 6 | R61: =IF(Q61>Q63,1,0) -> 1 | T61: 6 | U61: =IF(T61>T63,1,0) -> 1 | X61: =IF(W61>W63,1,0) -> 0 | Y61: =IF(Q61="",0,1) -> 1 | Z61: =IF(R61+U61=2,3,IF(R61+U61=1,1,0)) -> 3 | AA61: =IF(Z61=3,3,IF(X61+Z61=2,2,IF(Z61=1,1,0))) -> 3 | AB61: =Q61+T61 -> 12 | AC61: =R61+U61+X61 -> 2 | AE61: ='Players Men'!F8 -> Reuben Borg/Luigi Porto | AF61: =Y65+Y59+J65+J71 -> 3 | AG61: =AA65+AA59+L65+L71 -> 4 | AH61: =AB65+AB59+M65+M71 -> 28 | AI61: =AC65+AC59+N65+N71 -> 3
A62: vs. | P62: vs.
A63: =AE63 -> Matthew Borg/Roderick Spiteri | B63: 5 | C63: =IF(B63>B61,1,0) -> 0 | E63: 1 | F63: =IF(E63>E61,1,0) -> 0 | I63: =IF(H63>H61,1,0) -> 0 | J63: =IF(B63="",0,1) -> 1 | K63: =IF(C63+F63=2,3,IF(C63+F63=1,1,0)) -> 0 | L63: =IF(K63=3,3,IF(I63+K63=2,2,IF(K63=1,1,0))) -> 0 | M63: =B63+E63 -> 6 | N63: =C63+F63+I63 -> 0 | P63: =AE65 -> David Schembri/Fotis Evangelou | Q63: 3 | R63: =IF(Q63>Q61,1,0) -> 0 | T63: 2 | U63: =IF(T63>T61,1,0) -> 0 | X63: =IF(W63>W61,1,0) -> 0 | Y63: =IF(Q63="",0,1) -> 1 | Z63: =IF(R63+U63=2,3,IF(R63+U63=1,1,0)) -> 0 | AA63: =IF(Z63=3,3,IF(X63+Z63=2,2,IF(Z63=1,1,0))) -> 0 | AB63: =Q63+T63 -> 5 | AC63: =R63+U63+X63 -> 0 | AE63: ='Players Men'!F9 -> Matthew Borg/Roderick Spiteri | AF63: =Y67+J77+J63+Y71 -> 4 | AG63: =AA67+L77+L63+AA71 -> 2 | AH63: =AB67+M77+M63+AB71 -> 22 | AI63: =AC67+N77+N63+AC71 -> 2
A65: =AE61 -> Reuben Borg/Luigi Porto | B65: 5 | C65: =IF(B65>B67,1,0) -> 0 | E65: 7 | F65: =IF(E65>E67,1,0) -> 1 | H65: 4 | I65: =IF(H65>H67,1,0) -> 0 | J65: =IF(B65="",0,1) -> 1 | K65: =IF(C65+F65=2,3,IF(C65+F65=1,1,0)) -> 1 | L65: =IF(K65=3,3,IF(I65+K65=2,2,IF(K65=1,1,0))) -> 1 | M65: =B65+E65 -> 12 | N65: =C65+F65+I65 -> 1 | P65: =AE61 -> Reuben Borg/Luigi Porto | Q65: 6 | R65: =IF(Q65>Q67,1,0) -> 1 | T65: 6 | U65: =IF(T65>T67,1,0) -> 1 | X65: =IF(W65>W67,1,0) -> 0 | Y65: =IF(Q65="",0,1) -> 1 | Z65: =IF(R65+U65=2,3,IF(R65+U65=1,1,0)) -> 3 | AA65: =IF(Z65=3,3,IF(X65+Z65=2,2,IF(Z65=1,1,0))) -> 3 | AB65: =Q65+T65 -> 12 | AC65: =R65+U65+X65 -> 2 | AD65: w/o | AE65: ='Players Men'!F10 -> David Schembri/Fotis Evangelou | AF65: =J79+J75+Y63+J67 -> 4 | AG65: =L79+L75+AA63+L67 -> 4 | AH65: =M79+M75+AB63+M67 -> 36 | AI65: =N79+N75+AC63+N67 -> 4
A66: vs. | P66: vs.
A67: =AE65 -> David Schembri/Fotis Evangelou | B67: 7 | C67: =IF(B67>B65,1,0) -> 1 | E67: 5 | F67: =IF(E67>E65,1,0) -> 0 | H67: 10 | I67: =IF(H67>H65,1,0) -> 1 | J67: =IF(B67="",0,1) -> 1 | K67: =IF(C67+F67=2,3,IF(C67+F67=1,1,0)) -> 1 | L67: =IF(K67=3,3,IF(I67+K67=2,2,IF(K67=1,1,0))) -> 2 | M67: =B67+E67 -> 12 | N67: =C67+F67+I67 -> 2 | P67: =AE63 -> Matthew Borg/Roderick Spiteri | Q67: 0 | R67: =IF(Q67>Q65,1,0) -> 0 | T67: 0 | U67: =IF(T67>T65,1,0) -> 0 | X67: =IF(W67>W65,1,0) -> 0 | Y67: =IF(Q67="",0,1) -> 1 | Z67: =IF(R67+U67=2,3,IF(R67+U67=1,1,0)) -> 0 | AA67: =IF(Z67=3,3,IF(X67+Z67=2,2,IF(Z67=1,1,0))) -> 0 | AB67: =Q67+T67 -> 0 | AC67: =R67+U67+X67 -> 0 | AE67: Group B Winner
AE68: Duncan D'Alessandro/Jesmond Pule'
A69: =AE59 -> Gabriel Pace/Nikolai Belli | C69: =IF(B69>B71,1,0) -> 0 | F69: =IF(E69>E71,1,0) -> 0 | I69: =IF(H69>H71,1,0) -> 0 | J69: =IF(B69="",0,1) -> 0 | K69: =IF(C69+F69=2,3,IF(C69+F69=1,1,0)) -> 0 | L69: =IF(K69=3,3,IF(I69+K69=2,2,IF(K69=1,1,0))) -> 0 | M69: =B69+E69 -> 0 | N69: =C69+F69+I69 -> 0 | P69: =AE59 -> Gabriel Pace/Nikolai Belli | Q69: 6 | R69: =IF(Q69>Q71,1,0) -> 1 | T69: 6 | U69: =IF(T69>T71,1,0) -> 1 | X69: =IF(W69>W71,1,0) -> 0 | Y69: =IF(Q69="",0,1) -> 1 | Z69: =IF(R69+U69=2,3,IF(R69+U69=1,1,0)) -> 3 | AA69: =IF(Z69=3,3,IF(X69+Z69=2,2,IF(Z69=1,1,0))) -> 3 | AB69: =Q69+T69 -> 12 | AC69: =R69+U69+X69 -> 2
A70: vs. | P70: vs. | AE70: Final
A71: =AE61 -> Reuben Borg/Luigi Porto | C71: =IF(B71>B69,1,0) -> 0 | F71: =IF(E71>E69,1,0) -> 0 | I71: =IF(H71>H69,1,0) -> 0 | J71: =IF(B71="",0,1) -> 0 | K71: =IF(C71+F71=2,3,IF(C71+F71=1,1,0)) -> 0 | L71: =IF(K71=3,3,IF(I71+K71=2,2,IF(K71=1,1,0))) -> 0 | M71: =B71+E71 -> 0 | N71: =C71+F71+I71 -> 0 | P71: =AE63 -> Matthew Borg/Roderick Spiteri | Q71: 2 | R71: =IF(Q71>Q69,1,0) -> 0 | T71: 4 | U71: =IF(T71>T69,1,0) -> 0 | X71: =IF(W71>W69,1,0) -> 0 | Y71: =IF(Q71="",0,1) -> 1 | Z71: =IF(R71+U71=2,3,IF(R71+U71=1,1,0)) -> 0 | AA71: =IF(Z71=3,3,IF(X71+Z71=2,2,IF(Z71=1,1,0))) -> 0 | AB71: =Q71+T71 -> 6 | AC71: =R71+U71+X71 -> 0
AE72: Players | AF72: Set Scores | AL72: Tie
...

Sheet Men Div 2
A1: VITTORIOSA LAWN TENNIS CLUB Sports Experience Chosen Doubles 2024
A5: Men Division 2 - Group A
A7: Players | B7: Set Scores | H7: Tie | P7: Players | Q7: Set Scores | W7: Tie | AE7: Player | AF7: Matches Played | AG7: Points Overall | AH7: Games Won | AI7: Sets Won
B8: Score | C8: Set 1 Work | E8: Score | F8: Set 2 Work | H8: Score | I8: Tie Work | J8: Game Played | K8: Sets Points Work | L8: Sets & Tie Points Work | M8: Games Wins Work | N8: Sets Wins Work | Q8: Score | R8: Set 1 Work | T8: Score | U8: Set 2 Work | W8: Score | X8: Tie Work | Y8: Game Played | Z8: Sets Points Work | AA8: Sets & Tie Points Work | AB8: Games Wins Work | AC8: Sets Wins Work | AJ8: Winner Working | AK8: Total Games Work | AL8: Winner
A9: =AE9 -> Ivan Cachia/Willem Steenkamer | B9: 4 | C9: =IF(B9>B11,1,0) -> 0 | E9: 6 | F9: =IF(E9>E11,1,0) -> 1 | H9: 6 | I9: =IF(H9>H11,1,0) -> 0 | J9: =IF(B9="",0,1) -> 1 | K9: =IF(C9+F9=2,3,IF(C9+F9=1,1,0)) -> 1 | L9: =IF(K9=3,3,IF(I9+K9=2,2,IF(K9=1,1,0))) -> 1 | M9: =B9+E9 -> 10 | N9: =C9+F9+I9 -> 1 | P9: =AE9 -> Ivan Cachia/Willem Steenkamer | Q9: 2 | R9: =IF(Q9>Q11,1,0) -> 0 | T9: 6 | U9: =IF(T9>T11,1,0) -> 1 | W9: 5 | X9: =IF(W9>W11,1,0) -> 0 | Y9: =IF(Q9="",0,1) -> 1 | Z9: =IF(R9+U9=2,3,IF(R9+U9=1,1,0)) -> 1 | AA9: =IF(Z9=3,3,IF(X9+Z9=2,2,IF(Z9=1,1,0))) -> 1 | AB9: =Q9+T9 -> 8 | AC9: =R9+U9+X9 -> 1 | AE9: ='Players Men'!B13 -> Ivan Cachia/Willem Steenkamer | AF9: =J9+Y9+Y13+J13 -> 4 | AG9: =L9+AA9+L13+AA13 -> 5 | AH9: =M9+AB9+M13+AB13 -> 36 | AI9: =N9+AC9+N13+AC13 -> 5 | AJ9: =MAX(AG9:AG19) -> 8 | AK9: =SUM(AF9:AF19) -> 20 | AL9: =IF(AG9=$AJ$9,AE9,IF(AG11=$AJ$9,AE11,IF(AG13=$AJ$9,AE13,IF(AG15=$AJ$9,AE15,IF(AG17=$AJ$9,AE17,IF(AG19=$AJ$9,AE19,"")))))) -> Chi Chi Canonce/Kristen Cachia
A10: vs. | P10: vs.
A11: =AE11 -> Chi Chi Canonce/Kristen Cachia | B11: 6 | C11: =IF(B11>B9,1,0) -> 1 | E11: 4 | F11: =IF(E11>E9,1,0) -> 0 | H11: 10 | I11: =IF(H11>H9,1,0) -> 1 | J11: =IF(B11="",0,1) -> 1 | K11: =IF(C11+F11=2,3,IF(C11+F11=1,1,0)) -> 1 | L11: =IF(K11=3,3,IF(I11+K11=2,2,IF(K11=1,1,0))) -> 2 | M11: =B11+E11 -> 10 | N11: =C11+F11+I11 -> 2 | P11: =AE13 -> Gene Zammit/Justin Graeme Christie | Q11: 6 | R11: =IF(Q11>Q9,1,0) -> 1 | T11: 1 | U11: =IF(T11>T9,1,0) -> 0 | W11: 10 | X11: =IF(W11>W9,1,0) -> 1 | Y11: =IF(Q11="",0,1) -> 1 | Z11: =IF(R11+U11=2,3,IF(R11+U11=1,1,0)) -> 1 | AA11: =IF(Z11=3,3,IF(X11+Z11=2,2,IF(Z11=1,1,0))) -> 2 | AB11: =Q11+T11 -> 7 | AC11: =R11+U11+X11 -> 2 | AE11: ='Players Men'!B14 -> Chi Chi Canonce/Kristen Cachia | AF11: =J11+J25+Y21+J21 -> 4 | AG11: =L11+L25+AA21+L21 -> 8 | AH11: =M11+M25+AB21+M21 -> 35 | AI11: =N11+N25+AC21+N21 -> 6
A13: =AE9 -> Ivan Cachia/Willem Steenkamer | B13: 7 | C13: =IF(B13>B15,1,0) -> 1 | E13: 1 | F13: =IF(E13>E15,1,0) -> 0 | H13: 5 | I13: =IF(H13>H15,1,0) -> 0 | J13: =IF(B13="",0,1) -> 1 | K13: =IF(C13+F13=2,3,IF(C13+F13=1,1,0)) -> 1 | L13: =IF(K13=3,3,IF(I13+K13=2,2,IF(K13=1,1,0))) -> 1 | M13: =B13+E13 -> 8 | N13: =C13+F13+I13 -> 1 | P13: =AE9 -> Ivan Cachia/Willem Steenkamer | Q13: 3 | R13: =IF(Q13>Q15,1,0) -> 0 | T13: 7 | U13: =IF(T13>T15,1,0) -> 1 | W13: 10 | X13: =IF(W13>W15,1,0) -> 1 | Y13: =IF(Q13="",0,1) -> 1 | Z13: =IF(R13+U13=2,3,IF(R13+U13=1,1,0)) -> 1 | AA13: =IF(Z13=3,3,IF(X13+Z13=2,2,IF(Z13=1,1,0))) -> 2 | AB13: =Q13+T13 -> 10 | AC13: =R13+U13+X13 -> 2 | AE13: ='Players Men'!B15 -> Gene Zammit/Justin Graeme Christie | AF13: =Y17+J23+J17+Y11 -> 4 | AG13: =L17+AA17+AA11+L23 -> 8 | AH13: =M17+AB11+M23+AB17 -> 38 | AI13: =N17+AC17+AC11+N23 -> 6
A14: vs. | P14: vs.
A15: =AE15 -> Jonathan Vella/Clint Aguis | B15: 5 | C15: =IF(B15>B13,1,0) -> 0 | E15: 6 | F15: =IF(E15>E13,1,0) -> 1 | H15: 10 | I15: =IF(H15>H13,1,0) -> 1 | J15: =IF(B15="",0,1) -> 1 | K15: =IF(C15+F15=2,3,IF(C15+F15=1,1,0)) -> 1 | L15: =IF(K15=3,3,IF(I15+K15=2,2,IF(K15=1,1,0))) -> 2 | M15: =B15+E15 -> 11 | N15: =C15+F15+I15 -> 2 | P15: =AE17 -> Jonathan Martinelli/Daryl Pace | Q15: 6 | R15: =IF(Q15>Q13,1,0) -> 1 | T15: 5 | U15: =IF(T15>T13,1,0) -> 0 | W15: 8 | X15: =IF(W15>W13,1,0) -> 0 | Y15: =IF(Q15="",0,1) -> 1 | Z15: =IF(R15+U15=2,3,IF(R15+U15=1,1,0)) -> 1 | AA15: =IF(Z15=3,3,IF(X15+Z15=2,2,IF(Z15=1,1,0))) -> 1 | AB15: =Q15+T15 -> 11 | AC15: =R15+U15+X15 -> 1 | AE15: ='Players Men'!B16 -> Jonathan Vella/Clint Aguis | AF15: =Y19+J15+Y23+J29 -> 4 | AG15: =AA19+L15+AA23+L29 -> 7 | AH15: =AB19+M15+AB23+M29 -> 42 | AI15: =AC19+N15+AC23+N29 -> 6
A17: =AE13 -> Gene Zammit/Justin Graeme Christie | B17: 6 | C17: =IF(B17>B19,1,0) -> 1 | E17: 6 | F17: =IF(E17>E19,1,0) -> 1 | I17: =IF(H17>H19,1,0) -> 0 | J17: =IF(B17="",0,1) -> 1 | K17: =IF(C17+F17=2,3,IF(C17+F17=1,1,0)) -> 3 | L17: =IF(K17=3,3,IF(I17+K17=2,2,IF(K17=1,1,0))) -> 3 | M17: =B17+E17 -> 12 | N17: =C17+F17+I17 -> 2 | P17: =AE13 -> Gene Zammit/Justin Graeme Christie | Q17: 7 | R17: =IF(Q17>Q19,1,0) -> 1 | T17: 6 | U17: =IF(T17>T19,1,0) -> 1 | X17: =IF(W17>W19,1,0) -> 0 | Y17: =IF(Q17="",0,1) -> 1 | Z17: =IF(R17+U17=2,3,IF(R17+U17=1,1,0)) -> 3 | AA17: =IF(Z17=3,3,IF(X17+Z17=2,2,IF(Z17=1,1,0))) -> 3 | AB17: =Q17+T17 -> 13 | AC17: =R17+U17+X17 -> 2 | AE17: ='Players Men'!B17 -> Jonathan Martinelli/Daryl Pace | AF17: =Y15+J27+J19+J31 -> 4 | AG17: =AA15+L27+L19+L31 -> 2 | AH17: =AB15+M27+M19+M31 -> 35 | AI17: =N31+N27+AC15+N19 -> 2
A18: vs. | P18: vs.
A19: =AE17 -> Jonathan Martinelli/Daryl Pace | B19: 4 | C19: =IF(B19>B17,1,0) -> 0 | E19: 3 | F19: =IF(E19>E17,1,0) -> 0 | I19: =IF(H19>H17,1,0) -> 0 | J19: =IF(B19="",0,1) -> 1 | K19: =IF(C19+F19=2,3,IF(C19+F19=1,1,0)) -> 0 | L19: =IF(K19=3,3,IF(I19+K19=2,2,IF(K19=1,1,0))) -> 0 | M19: =B19+E19 -> 7 | N19: =C19+F19+I19 -> 0 | P19: =AE15 -> Jonathan Vella/Clint Aguis | Q19: 6 | R19: =IF(Q19>Q17,1,0) -> 0 | T19: 2 | U19: =IF(T19>T17,1,0) -> 0 | X19: =IF(W19>W17,1,0) -> 0 | Y19: =IF(Q19="",0,1) -> 1 | Z19: =IF(R19+U19=2,3,IF(R19+U19=1,1,0)) -> 0 | AA19: =IF(Z19=3,3,IF(X19+Z19=2,2,IF(Z19=1,1,0))) -> 0 | AB19: =Q19+T19 -> 8 | AC19: =R19+U19+X19 -> 0 | AE19: Group A Winner
AE20: Chi Chi Canonce/Kristen Cachia
A21: =AE11 -> Chi Chi Canonce/Kristen Cachia | B21: 6 | C21: =IF(B21>B23,1,0) -> 1 | E21: 6 | F21: =IF(E21>E23,1,0) -> 1 | I21: =IF(H21>H23,1,0) -> 0 | J21: =IF(B21="",0,1) -> 1 | K21: =IF(C21+F21=2,3,IF(C21+F21=1,1,0)) -> 3 | L21: =IF(K21=3,3,IF(I21+K21=2,2,IF(K21=1,1,0))) -> 3 | M21: =B21+E21 -> 12 | N21: =C21+F21+I21 -> 2 | P21: =AE11 -> Chi Chi Canonce/Kristen Cachia | Q21: 0 | R21: =IF(Q21>Q23,1,0) -> 0 | T21: 0 | U21: =IF(T21>T23,1,0) -> 0 | X21: =IF(W21>W23,1,0) -> 0 | Y21: =IF(Q21="",0,1) -> 1 | Z21: =IF(R21+U21=2,3,IF(R21+U21=1,1,0)) -> 0 | AA21: =IF(Z21=3,3,IF(X21+Z21=2,2,IF(Z21=1,1,0))) -> 0 | AB21: =Q21+T21 -> 0 | AC21: =R21+U21+X21 -> 0
A22: vs. | P22: vs.
A23: =AE13 -> Gene Zammit/Justin Graeme Christie | B23: 4 | C23: =IF(B23>B21,1,0) -> 0 | E23: 2 | F23: =IF(E23>E21,1,0) -> 0 | I23: =IF(H23>H21,1,0) -> 0 | J23: =IF(B23="",0,1) -> 1 | K23: =IF(C23+F23=2,3,IF(C23+F23=1,1,0)) -> 0 | L23: =IF(K23=3,3,IF(I23+K23=2,2,IF(K23=1,1,0))) -> 0 | M23: =B23+E23 -> 6 | N23: =C23+F23+I23 -> 0 | P23: =AE15 -> Jonathan Vella/Clint Aguis | Q23: 6 | R23: =IF(Q23>Q21,1,0) -> 1 | T23: 6 | U23: =IF(T23>T21,1,0) -> 1 | X23: =IF(W23>W21,1,0) -> 0 | Y23: =IF(Q23="",0,1) -> 1 | Z23: =IF(R23+U23=2,3,IF(R23+U23=1,1,0)) -> 3 | AA23: =IF(Z23=3,3,IF(X23+Z23=2,2,IF(Z23=1,1,0))) -> 3 | AB23: =Q23+T23 -> 12 | AC23: =R23+U23+X23 -> 2
A25: =AE11 -> Chi Chi Canonce/Kristen Cachia | B25: 6 | C25: =IF(B25>B27,1,0) -> 1 | E25: 7 | F25: =IF(E25>E27,1,0) -> 1 | I25: =IF(H25>H27,1,0) -> 0 | J25: =IF(B25="",0,1) -> 1 | K25: =IF(C25+F25=2,3,IF(C25+F25=1,1,0)) -> 3 | L25: =IF(K25=3,3,IF(I25+K25=2,2,IF(K25=1,1,0))) -> 3 | M25: =B25+E25 -> 13 | N25: =C25+F25+I25 -> 2
A26: vs.
A27: =AE17 -> Jonathan Martinelli/Daryl Pace | B27: 2 | C27: =IF(B27>B25,1,0) -> 0 | E27: 6 | F27: =IF(E27>E25,1,0) -> 0 | I27: =IF(H27>H25,1,0) -> 0 | J27: =IF(B27="",0,1) -> 1 | K27: =IF(C27+F27=2,3,IF(C27+F27=1,1,0)) -> 0 | L27: =IF(K27=3,3,IF(I27+K27=2,2,IF(K27=1,1,0))) -> 0 | M27: =B27+E27 -> 8 | N27: =C27+F27+I27 -> 0
A29: =AE15 -> Jonathan Vella/Clint Aguis | B29: 6 | C29: =IF(B29>B31,1,0) -> 1 | E29: 5 | F29: =IF(E29>E31,1,0) -> 0 | H29: 10 | I29: =IF(H29>H31,1,0) -> 1 | J29: =IF(B29="",0,1) -> 1 | K29: =IF(C29+F29=2,3,IF(C29+F29=1,1,0)) -> 1 | L29: =IF(K29=3,3,IF(I29+K29=2,2,IF(K29=1,1,0))) -> 2 | M29: =B29+E29 -> 11 | N29: =C29+F29+I29 -> 2
A30: vs.
A31: =AE17 -> Jonathan Martinelli/Daryl Pace | B31: 2 | C31: =IF(B31>B29,1,0) -> 0 | E31: 7 | F31: =IF(E31>E29,1,0) -> 1 | H31: 4 | I31: =IF(H31>H29,1,0) -> 0 | J31: =IF(B31="",0,1) -> 1 | K31: =IF(C31+F31=2,3,IF(C31+F31=1,1,0)) -> 1 | L31: =IF(K31=3,3,IF(I31+K31=2,2,IF(K31=1,1,0))) -> 1 | M31: =B31+E31 -> 9 | N31: =C31+F31+I31 -> 1
A61: Men Division 2 - Group B
A63: Players | B63: Set Scores | H63: Tie | P63: Players | Q63: Set Scores | W63: Tie | AE63: Player | AF63: Matches Played | AG63: Points Overall | AH63: Games Won | AI63: Sets Won
B64: Score | C64: Set 1 Work | E64: Score | F64: Set 2 Work | H64: Score | I64: Tie Work | J64: Game Played | K64: Sets Points Work | L64: Sets & Tie Points Work | M64: Games Wins Work | N64: Sets Wins Work | Q64: Score | R64: Set 1 Work | T64: Score | U64: Set 2 Work | W64: Score | X64: Tie Work | Y64: Game Played | Z64: Sets Points Work | AA64: Sets & Tie Points Work | AB64: Games Wins Work | AC64: Sets Wins Work | AJ64: Winner Working | AK64: Total Games Work | AL64: Winner
A65: =AE65 -> Manuel Mifsud/Julian Esposito | B65: 4 | C65: =IF(B65>B67,1,0) -> 0 | E65: 3 | F65: =IF(E65>E67,1,0) -> 0 | I65: =IF(H65>H67,1,0) -> 0 | J65: =IF(B65="",0,1) -> 1 | K65: =IF(C65+F65=2,3,IF(C65+F65=1,1,0)) -> 0 | L65: =IF(K65=3,3,IF(I65+K65=2,2,IF(K65=1,1,0))) -> 0 | M65: =B65+E65 -> 7 | N65: =C65+F65+I65 -> 0 | P65: =AE65 -> Manuel Mifsud/Julian Esposito | Q65: 3 | R65: =IF(Q65>Q67,1,0) -> 0 | T65: 1 | U65: =IF(T65>T67,1,0) -> 0 | X65: =IF(W65>W67,1,0) -> 0 | Y65: =IF(Q65="",0,1) -> 1 | Z65: =IF(R65+U65=2,3,IF(R65+U65=1,1,0)) -> 0 | AA65: =IF(Z65=3,3,IF(X65+Z65=2,2,IF(Z65=1,1,0))) -> 0 | AB65: =Q65+T65 -> 4 | AC65: =R65+U65+X65 -> 0 | AE65: ='Players Men'!F13 -> Manuel Mifsud/Julian Esposito | AF65: =J65+Y65+J69+Y69 -> 4 | AG65: =L65+AA65+L69+AA69 -> 0 | AH65: =M65+AB65+M69+AB69 -> 27 | AI65: =N65+AC65+N69+AC69 -> 0 | AJ65: =MAX(AG65:AG74) -> 10 | AK65: =SUM(AF65:AF74) -> 20 | AL65: =IF(AG65=$AJ$65,AE65,IF(AG67=$AJ$65,AE67,IF(AG69=$AJ$65,AE69,IF(AG71=$AJ$65,AE71,IF(AG73=$AJ$65,AE73,IF(#REF!=$AJ$65,#REF!,"")))))) -> Ivan Cassar/Kurt Cassar
A66: vs. | P66: vs.
A67: =AE67 -> Ivan Cassar/Kurt Cassar | B67: 6 | C67: =IF(B67>B65,1,0) -> 1 | E67: 6 | F67: =IF(E67>E65,1,0) -> 1 | I67: =IF(H67>H65,1,0) -> 0 | J67: =IF(B67="",0,1) -> 1 | K67: =IF(C67+F67=2,3,IF(C67+F67=1,1,0)) -> 3 | L67: =IF(K67=3,3,IF(I67+K67=2,2,IF(K67=1,1,0))) -> 3 | M67: =B67+E67 -> 12 | N67: =C67+F67+I67 -> 2 | P67: =AE69 -> Mavric Sawyer/Keith Tanti | Q67: 6 | R67: =IF(Q67>Q65,1,0) -> 1 | T67: 6 | U67: =IF(T67>T65,1,0) -> 1 | X67: =IF(W67>W65,1,0) -> 0 | Y67: =IF(Q67="",0,1) -> 1 | Z67: =IF(R67+U67=2,3,IF(R67+U67=1,1,0)) -> 3 | AA67: =IF(Z67=3,3,IF(X67+Z67=2,2,IF(Z67=1,1,0))) -> 3 | AB67: =Q67+T67 -> 12 | AC67: =R67+U67+X67 -> 2 | AE67: ='Players Men'!F14 -> Ivan Cassar/Kurt Cassar | AF67: =J67+J81+Y77+J77 -> 4 | AG67: =L67+L81+AA77+L77 -> 10 | AH67: =M67+M81+AB77+M77 -> 43 | AI67: =N67+N81+AC77+N77 -> 7
A69: =AE65 -> Manuel Mifsud/Julian Esposito | B69: 4 | C69: =IF(B69>B71,1,0) -> 0 | E69: 4 | F69: =IF(E69>E71,1,0) -> 0 | I69: =IF(H69>H71,1,0) -> 0 | J69: =IF(B69="",0,1) -> 1 | K69: =IF(C69+F69=2,3,IF(C69+F69=1,1,0)) -> 0 | L69: =IF(K69=3,3,IF(I69+K69=2,2,IF(K69=1,1,0))) -> 0 | M69: =B69+E69 -> 8 | N69: =C69+F69+I69 -> 0 | P69: =AE65 -> Manuel Mifsud/Julian Esposito | Q69: 3 | R69: =IF(Q69>Q71,1,0) -> 0 | T69: 5 | U69: =IF(T69>T71,1,0) -> 0 | X69: =IF(W69>W71,1,0) -> 0 | Y69: =IF(Q69="",0,1) -> 1 | Z69: =IF(R69+U69=2,3,IF(R69+U69=1,1,0)) -> 0 | AA69: =IF(Z69=3,3,IF(X69+Z69=2,2,IF(Z69=1,1,0))) -> 0 | AB69: =Q69+T69 -> 8 | AC69: =R69+U69+X69 -> 0 | AE69: ='Players Men'!F15 -> Mavric Sawyer/Keith Tanti | AF69: =Y73+Y67+J73+J79 -> 4 | AG69: =AA73+AA67+L73+L79 -> 10 | AH69: =AB73+AB67+M73+M79 -> 42 | AI69: =AC73+AC67+N73+N79 -> 8
A70: vs. | P70: vs.
A71: =AE71 -> Neville Sciriha/Roberto Murdocco | B71: 6 | C71: =IF(B71>B69,1,0) -> 1 | E71: 6 | F71: =IF(E71>E69,1,0) -> 1 | I71: =IF(H71>H69,1,0) -> 0 | J71: =IF(B71="",0,1) -> 1 | K71: =IF(C71+F71=2,3,IF(C71+F71=1,1,0)) -> 3 | L71: =IF(K71=3,3,IF(I71+K71=2,2,IF(K71=1,1,0))) -> 3 | M71: =B71+E71 -> 12 | N71: =C71+F71+I71 -> 2 | P71: =AE73 -> Etienne Formosa Carabez/Javier Viloria | Q71: 6 | R71: =IF(Q71>Q69,1,0) -> 1 | T71: 7 | U71: =IF(T71>T69,1,0) -> 1 | X71: =IF(W71>W69,1,0) -> 0 | Y71: =IF(Q71="",0,1) -> 1 | Z71: =IF(R71+U71=2,3,IF(R71+U71=1,1,0)) -> 3 | AA71: =IF(Z71=3,3,IF(X71+Z71=2,2,IF(Z71=1,1,0))) -> 3 | AB71: =Q71+T71 -> 13 | AC71: =R71+U71+X71 -> 2 | AE71: ='Players Men'!F16 -> Neville Sciriha/Roberto Murdocco | AF71: =Y75+J85+J71+Y79 -> 4 | AG71: =AA75+L85+L71+AA79 -> 4 | AH71: =AB75+M85+M71+AB79 -> 33 | AI71: =AC75+N85+N71+AC79 -> 3
A73: =AE69 -> Mavric Sawyer/Keith Tanti | B73: 6 | C73: =IF(B73>B75,1,0) -> 1 | E73: 6 | F73: =IF(E73>E75,1,0) -> 1 | I73: =IF(H73>H75,1,0) -> 0 | J73: =IF(B73="",0,1) -> 1 | K73: =IF(C73+F73=2,3,IF(C73+F73=1,1,0)) -> 3 | L73: =IF(K73=3,3,IF(I73+K73=2,2,IF(K73=1,1,0))) -> 3 | M73: =B73+E73 -> 12 | N73: =C73+F73+I73 -> 2 | P73: =AE69 -> Mavric Sawyer/Keith Tanti | Q73: 4 | R73: =IF(Q73>Q75,1,0) -> 0 | T73: 6 | U73: =IF(T73>T75,1,0) -> 1 | W73: 11 | X73: =IF(W73>W75,1,0) -> 1 | Y73: =IF(Q73="",0,1) -> 1 | Z73: =IF(R73+U73=2,3,IF(R73+U73=1,1,0)) -> 1 | AA73: =IF(Z73=3,3,IF(X73+Z73=2,2,IF(Z73=1,1,0))) -> 2 | AB73: =Q73+T73 -> 10 | AC73: =R73+U73+X73 -> 2 | AE73: ='Players Men'!F17 -> Etienne Formosa Carabez/Javier Viloria | AF73: =J87+J83+Y71+J75 -> 4 | AG73: =L87+L83+AA71+L75 -> 6 | AH73: =M87+M83+AB71+M75 -> 34 | AI73: =N87+N83+AC71+N75 -> 4
A74: vs. | P74: vs.
A75: =AE73 -> Etienne Formosa Carabez/Javier Viloria | B75: 1 | C75: =IF(B75>B73,1,0) -> 0 | E75: 3 | F75: =IF(E75>E73,1,0) -> 0 | I75: =IF(H75>H73,1,0) -> 0 | J75: =IF(B75="",0,1) -> 1 | K75: =IF(C75+F75=2,3,IF(C75+F75=1,1,0)) -> 0 | L75: =IF(K75=3,3,IF(I75+K75=2,2,IF(K75=1,1,0))) -> 0 | M75: =B75+E75 -> 4 | N75: =C75+F75+I75 -> 0 | P75: =AE71 -> Neville Sciriha/Roberto Murdocco | Q75: 6 | R75: =IF(Q75>Q73,1,0) -> 1 | T75: 4 | U75: =IF(T75>T73,1,0) -> 0 | W75: 9 | X75: =IF(W75>W73,1,0) -> 0 | Y75: =IF(Q75="",0,1) -> 1 | Z75: =IF(R75+U75=2,3,IF(R75+U75=1,1,0)) -> 1 | AA75: =IF(Z75=3,3,IF(X75+Z75=2,2,IF(Z75=1,1,0))) -> 1 | AB75: =Q75+T75 -> 10 | AC75: =R75+U75+X75 -> 1 | AE75: Group B Winner
AE76: Mavric Sawyer/Keith Tanti
A77: =AE67 -> Ivan Cassar/Kurt Cassar | B77: 1 | C77: =IF(B77>B79,1,0) -> 0 | E77: 6 | F77: =IF(E77>E79,1,0) -> 1 | H77: 9 | I77: =IF(H77>H79,1,0) -> 0 | J77: =IF(B77="",0,1) -> 1 | K77: =IF(C77+F77=2,3,IF(C77+F77=1,1,0)) -> 1 | L77: =IF(K77=3,3,IF(I77+K77=2,2,IF(K77=1,1,0))) -> 1 | M77: =B77+E77 -> 7 | N77: =C77+F77+I77 -> 1 | P77: =AE67 -> Ivan Cassar/Kurt Cassar | Q77: 6 | R77: =IF(Q77>Q79,1,0) -> 1 | T77: 6 | U77: =IF(T77>T79,1,0) -> 1 | X77: =IF(W77>W79,1,0) -> 0 | Y77: =IF(Q77="",0,1) -> 1 | Z77: =IF(R77+U77=2,3,IF(R77+U77=1,1,0)) -> 3 | AA77: =IF(Z77=3,3,IF(X77+Z77=2,2,IF(Z77=1,1,0))) -> 3 | AB77: =Q77+T77 -> 12 | AC77: =R77+U77+X77 -> 2
A78: vs. | P78: vs.
A79: =AE69 -> Mavric Sawyer/Keith Tanti | B79: 6 | C79: =IF(B79>B77,1,0) -> 1 | E79: 2 | F79: =IF(E79>E77,1,0) -> 0 | H79: 11 | I79: =IF(H79>H77,1,0) -> 1 | J79: =IF(B79="",0,1) -> 1 | K79: =IF(C79+F79=2,3,IF(C79+F79=1,1,0)) -> 1 | L79: =IF(K79=3,3,IF(I79+K79=2,2,IF(K79=1,1,0))) -> 2 | M79: =B79+E79 -> 8 | N79: =C79+F79+I79 -> 2 | P79: =AE71 -> Neville Sciriha/Roberto Murdocco | Q79: 3 | R79: =IF(Q79>Q77,1,0) -> 0 | T79: 3 | U79: =IF(T79>T77,1,0) -> 0 | X79: =IF(W79>W77,1,0) -> 0 | Y79: =IF(Q79="",0,1) -> 1 | Z79: =IF(R79+U79=2,3,IF(R79+U79=1,1,0)) -> 0 | AA79: =IF(Z79=3,3,IF(X79+Z79=2,2,IF(Z79=1,1,0))) -> 0 | AB79: =Q79+T79 -> 6 | AC79: =R79+U79+X79 -> 0
A81: =AE67 -> Ivan Cassar/Kurt Cassar | B81: 6 | C81: =IF(B81>B83,1,0) -> 1 | E81: 6 | F81: =IF(E81>E83,1,0) -> 1 | I81: =IF(H81>H83,1,0) -> 0 | J81: =IF(B81="",0,1) -> 1 | K81: =IF(C81+F81=2,3,IF(C81+F81=1,1,0)) -> 3 | L81: =IF(K81=3,3,IF(I81+K81=2,2,IF(K81=1,1,0))) -> 3 | M81: =B81+E81 -> 12 | N81: =C81+F81+I81 -> 2
...

Sheet Men Div 3
A1: VITTORIOSA LAWN TENNIS CLUB Sports Experience Chosen Doubles 2024
A5: Men Division 3
A7: Players | B7: Set Scores | H7: Tie | P7: Players | Q7: Set Scores | W7: Tie | AE7: Player | AF7: Matches Played | AG7: Points Overall | AH7: Games Won | AI7: Sets Won
B8: Score | C8: Set 1 Work | E8: Score | F8: Set 2 Work | H8: Score | I8: Tie Work | J8: Game Played | K8: Sets Points Work | L8: Sets & Tie Points Work | M8: Games Wins Work | N8: Sets Wins Work | Q8: Score | R8: Set 1 Work | T8: Score | U8: Set 2 Work | W8: Score | X8: Tie Work | Y8: Game Played | Z8: Sets Points Work | AA8: Sets & Tie Points Work | AB8: Games Wins Work | AC8: Sets Wins Work | AJ8: Winner Working | AK8: Runner Up Working | AL8: Total Games Work | AM8: Winner | AN8: Runner Up
A9: =AE9 -> Denis Caruana/Duncan Zammit | B9: 6 | C9: =IF(B9>B11,1,0) -> 1 | E9: 6 | F9: =IF(E9>E11,1,0) -> 1 | I9: =IF(H9>H11,1,0) -> 0 | J9: =IF(B9="",0,1) -> 1 | K9: =IF(C9+F9=2,3,IF(C9+F9=1,1,0)) -> 3 | L9: =IF(K9=3,3,IF(I9+K9=2,2,IF(K9=1,1,0))) -> 3 | M9: =B9+E9 -> 12 | N9: =C9+F9+I9 -> 2 | P9: =AE9 -> Denis Caruana/Duncan Zammit | Q9: 6 | R9: =IF(Q9>Q11,1,0) -> 1 | T9: 6 | U9: =IF(T9>T11,1,0) -> 1 | X9: =IF(W9>W11,1,0) -> 0 | Y9: =IF(Q9="",0,1) -> 1 | Z9: =IF(R9+U9=2,3,IF(R9+U9=1,1,0)) -> 3 | AA9: =IF(Z9=3,3,IF(X9+Z9=2,2,IF(Z9=1,1,0))) -> 3 | AB9: =Q9+T9 -> 12 | AC9: =R9+U9+X9 -> 2 | AE9: ='Players Men'!B20 -> Denis Caruana/Duncan Zammit | AF9: =J9+Y9+J13+Y13+J17 -> 5 | AG9: =L9+AA9+L13+AA13+L17 -> 13 | AH9: =M9+AB9+M13+AB13+M17 -> 59 | AI9: =N9+AC9+N13+AC13+N17 -> 9 | AJ9: =MAX(AG9:AG19) -> 14 | AK9: =LARGE(AG9:AG19, 2) -> 13 | AL9: =SUM(AF9:AF19) -> 30 | AM9: =IF(AG9=$AJ$9,AE9,IF(AG11=$AJ$9,AE11,IF(AG13=$AJ$9,AE13,IF(AG15=$AJ$9,AE15,IF(AG17=$AJ$9,AE17,IF(AG19=$AJ$9,AE19,"")))))) -> Dunstan Vella/Cyril Lastimosa | AN9: =IF(AG9=$AK$9,AE9,IF(AG11=$AK$9,AE11,IF(AG13=$AK$9,AE13,IF(AG15=$AK$9,AE15,IF(AG17=$AK$9,AE17,IF(AG19=$AK$9,AE19,"")))))) -> Denis Caruana/Duncan Zammit
A10: vs. | P10: vs.
A11: =AE11 -> Aaron Micallef Piccone/Adrian Sciberras | B11: 2 | C11: =IF(B11>B9,1,0) -> 0 | E11: 1 | F11: =IF(E11>E9,1,0) -> 0 | I11: =IF(H11>H9,1,0) -> 0 | J11: =IF(B11="",0,1) -> 1 | K11: =IF(C11+F11=2,3,IF(C11+F11=1,1,0)) -> 0 | L11: =IF(K11=3,3,IF(I11+K11=2,2,IF(K11=1,1,0))) -> 0 | M11: =B11+E11 -> 3 | N11: =C11+F11+I11 -> 0 | P11: =AE13 -> Cory Greenland/Benjamin Valencia | Q11: 3 | R11: =IF(Q11>Q9,1,0) -> 0 | T11: 2 | U11: =IF(T11>T9,1,0) -> 0 | X11: =IF(W11>W9,1,0) -> 0 | Y11: =IF(Q11="",0,1) -> 1 | Z11: =IF(R11+U11=2,3,IF(R11+U11=1,1,0)) -> 0 | AA11: =IF(Z11=3,3,IF(X11+Z11=2,2,IF(Z11=1,1,0))) -> 0 | AB11: =Q11+T11 -> 5 | AC11: =R11+U11+X11 -> 0 | AE11: ='Players Men'!B21 -> Aaron Micallef Piccone/Adrian Sciberras | AF11: =J11+Y25+J25+Y21+J21 -> 5 | AG11: =L11+AA25+L25+AA21+L21 -> 3 | AH11: =M11+AB25+M25+AB21+M21 -> 38 | AI11: =N11+AC25+N25+AC21+N21 -> 2
A13: =AE9 -> Denis Caruana/Duncan Zammit | B13: 6 | C13: =IF(B13>B15,1,0) -> 1 | E13: 4 | F13: =IF(E13>E15,1,0) -> 0 | H13: 5 | I13: =IF(H13>H15,1,0) -> 0 | J13: =IF(B13="",0,1) -> 1 | K13: =IF(C13+F13=2,3,IF(C13+F13=1,1,0)) -> 1 | L13: =IF(K13=3,3,IF(I13+K13=2,2,IF(K13=1,1,0))) -> 1 | M13: =B13+E13 -> 10 | N13: =C13+F13+I13 -> 1 | P13: =AE9 -> Denis Caruana/Duncan Zammit | Q13: 6 | R13: =IF(Q13>Q15,1,0) -> 1 | T13: 6 | U13: =IF(T13>T15,1,0) -> 1 | X13: =IF(W13>W15,1,0) -> 0 | Y13: =IF(Q13="",0,1) -> 1 | Z13: =IF(R13+U13=2,3,IF(R13+U13=1,1,0)) -> 3 | AA13: =IF(Z13=3,3,IF(X13+Z13=2,2,IF(Z13=1,1,0))) -> 3 | AB13: =Q13+T13 -> 12 | AC13: =R13+U13+X13 -> 2 | AE13: ='Players Men'!B22 -> Cory Greenland/Benjamin Valencia | AF13: =Y29+Y11+Y33+J33+J23 -> 5 | AG13: =AA29+AA11+AA33+L33+L23 -> 2 | AH13: =AB29+AB11+AB33+M33+M23 -> 32 | AI13: =AC29+AC11+AC33+N33+N23 -> 2
A14: vs. | P14: vs.
A15: =AE15 -> Dunstan Vella/Cyril Lastimosa | B15: 3 | C15: =IF(B15>B13,1,0) -> 0 | E15: 6 | F15: =IF(E15>E13,1,0) -> 1 | H15: 10 | I15: =IF(H15>H13,1,0) -> 1 | J15: =IF(B15="",0,1) -> 1 | K15: =IF(C15+F15=2,3,IF(C15+F15=1,1,0)) -> 1 | L15: =IF(K15=3,3,IF(I15+K15=2,2,IF(K15=1,1,0))) -> 2 | M15: =B15+E15 -> 9 | N15: =C15+F15+I15 -> 2 | P15: =AE17 -> Maurice Borg/Kenneth Caruana | Q15: 4 | R15: =IF(Q15>Q13,1,0) -> 0 | T15: 4 | U15: =IF(T15>T13,1,0) -> 0 | X15: =IF(W15>W13,1,0) -> 0 | Y15: =IF(Q15="",0,1) -> 1 | Z15: =IF(R15+U15=2,3,IF(R15+U15=1,1,0)) -> 0 | AA15: =IF(Z15=3,3,IF(X15+Z15=2,2,IF(Z15=1,1,0))) -> 0 | AB15: =Q15+T15 -> 8 | AC15: =R15+U15+X15 -> 0 | AE15: ='Players Men'!B23 -> Dunstan Vella/Cyril Lastimosa | AF15: =Y31+J37+J15+Y23+J29 -> 5 | AG15: =AA31+L37+L15+AA23+L29 -> 14 | AH15: =AB31+M37+M15+AB23+M29 -> 58 | AI15: =AC31+N37+N15+AC23+N29 -> 10
A17: =AE9 -> Denis Caruana/Duncan Zammit | B17: 7 | C17: =IF(B17>B19,1,0) -> 1 | E17: 6 | F17: =IF(E17>E19,1,0) -> 1 | I17: =IF(H17>H19,1,0) -> 0 | J17: =IF(B17="",0,1) -> 1 | K17: =IF(C17+F17=2,3,IF(C17+F17=1,1,0)) -> 3 | L17: =IF(K17=3,3,IF(I17+K17=2,2,IF(K17=1,1,0))) -> 3 | M17: =B17+E17 -> 13 | N17: =C17+F17+I17 -> 2 | P17: =AE17 -> Maurice Borg/Kenneth Caruana | Q17: 6 | R17: =IF(Q17>Q19,1,0) -> 1 | T17: 3 | U17: =IF(T17>T19,1,0) -> 0 | W17: 10 | X17: =IF(W17>W19,1,0) -> 1 | Y17: =IF(Q17="",0,1) -> 1 | Z17: =IF(R17+U17=2,3,IF(R17+U17=1,1,0)) -> 1 | AA17: =IF(Z17=3,3,IF(X17+Z17=2,2,IF(Z17=1,1,0))) -> 2 | AB17: =Q17+T17 -> 9 | AC17: =R17+U17+X17 -> 2 | AE17: ='Players Men'!B24 -> Maurice Borg/Kenneth Caruana | AF17: =Y17+J39+J27+Y15+J35 -> 5 | AG17: =AA17+L39+L27+AA15+L35 -> 8 | AH17: =AB17+M39+M27+AB15+M35 -> 47 | AI17: =AC17+N39+N27+AC15+N35 -> 6
A18: vs. | P18: vs.
A19: =AE19 -> Kenneth Farrugia/Juan Sammut | B19: 6 | C19: =IF(B19>B17,1,0) -> 0 | E19: 1 | F19: =IF(E19>E17,1,0) -> 0 | I19: =IF(H19>H17,1,0) -> 0 | J19: =IF(B19="",0,1) -> 1 | K19: =IF(C19+F19=2,3,IF(C19+F19=1,1,0)) -> 0 | L19: =IF(K19=3,3,IF(I19+K19=2,2,IF(K19=1,1,0))) -> 0 | M19: =B19+E19 -> 7 | N19: =C19+F19+I19 -> 0 | P19: =AE19 -> Kenneth Farrugia/Juan Sammut | Q19: 3 | R19: =IF(Q19>Q17,1,0) -> 0 | T19: 6 | U19: =IF(T19>T17,1,0) -> 1 | W19: 7 | X19: =IF(W19>W17,1,0) -> 0 | Y19: =IF(Q19="",0,1) -> 1 | Z19: =IF(R19+U19=2,3,IF(R19+U19=1,1,0)) -> 1 | AA19: =IF(Z19=3,3,IF(X19+Z19=2,2,IF(Z19=1,1,0))) -> 1 | AB19: =Q19+T19 -> 9 | AC19: =R19+U19+X19 -> 1 | AE19: ='Players Men'!B25 -> Kenneth Farrugia/Juan Sammut | AF19: =Y19+Y27+Y35+J19+J31 -> 5 | AG19: =AA19+AA27+AA35+L19+L31 -> 5 | AH19: =AB19+AB27+AB35+M19+M31 -> 43 | AI19: =AC19+AC27+AC35+N19+N31 -> 4
A21: =AE11 -> Aaron Micallef Piccone/Adrian Sciberras | B21: 6 | C21: =IF(B21>B23,1,0) -> 1 | E21: 6 | F21: =IF(E21>E23,1,0) -> 1 | I21: =IF(H21>H23,1,0) -> 0 | J21: =IF(B21="",0,1) -> 1 | K21: =IF(C21+F21=2,3,IF(C21+F21=1,1,0)) -> 3 | L21: =IF(K21=3,3,IF(I21+K21=2,2,IF(K21=1,1,0))) -> 3 | M21: =B21+E21 -> 12 | N21: =C21+F21+I21 -> 2 | P21: =AE11 -> Aaron Micallef Piccone/Adrian Sciberras | Q21: 5 | R21: =IF(Q21>Q23,1,0) -> 0 | T21: 4 | U21: =IF(T21>T23,1,0) -> 0 | X21: =IF(W21>W23,1,0) -> 0 | Y21: =IF(Q21="",0,1) -> 1 | Z21: =IF(R21+U21=2,3,IF(R21+U21=1,1,0)) -> 0 | AA21: =IF(Z21=3,3,IF(X21+Z21=2,2,IF(Z21=1,1,0))) -> 0 | AB21: =Q21+T21 -> 9 | AC21: =R21+U21+X21 -> 0 | AE21: Division Winner
A22: vs. | P22: vs. | AE22: =IF(AL9=30,AM9,"") -> Dunstan Vella/Cyril Lastimosa
A23: =AE13 -> Cory Greenland/Benjamin Valencia | B23: 4 | C23: =IF(B23>B21,1,0) -> 0 | E23: 3 | F23: =IF(E23>E21,1,0) -> 0 | I23: =IF(H23>H21,1,0) -> 0 | J23: =IF(B23="",0,1) -> 1 | K23: =IF(C23+F23=2,3,IF(C23+F23=1,1,0)) -> 0 | L23: =IF(K23=3,3,IF(I23+K23=2,2,IF(K23=1,1,0))) -> 0 | M23: =B23+E23 -> 7 | N23: =C23+F23+I23 -> 0 | P23: =AE15 -> Dunstan Vella/Cyril Lastimosa | Q23: 7 | R23: =IF(Q23>Q21,1,0) -> 1 | T23: 6 | U23: =IF(T23>T21,1,0) -> 1 | X23: =IF(W23>W21,1,0) -> 0 | Y23: =IF(Q23="",0,1) -> 1 | Z23: =IF(R23+U23=2,3,IF(R23+U23=1,1,0)) -> 3 | AA23: =IF(Z23=3,3,IF(X23+Z23=2,2,IF(Z23=1,1,0))) -> 3 | AB23: =Q23+T23 -> 13 | AC23: =R23+U23+X23 -> 2
A25: =AE11 -> Aaron Micallef Piccone/Adrian Sciberras | B25: 5 | C25: =IF(B25>B27,1,0) -> 0 | E25: 4 | F25: =IF(E25>E27,1,0) -> 0 | I25: =IF(H25>H27,1,0) -> 0 | J25: =IF(B25="",0,1) -> 1 | K25: =IF(C25+F25=2,3,IF(C25+F25=1,1,0)) -> 0 | L25: =IF(K25=3,3,IF(I25+K25=2,2,IF(K25=1,1,0))) -> 0 | M25: =B25+E25 -> 9 | N25: =C25+F25+I25 -> 0 | P25: =AE11 -> Aaron Micallef Piccone/Adrian Sciberras | Q25: 2 | R25: =IF(Q25>Q27,1,0) -> 0 | T25: 3 | U25: =IF(T25>T27,1,0) -> 0 | X25: =IF(W25>W27,1,0) -> 0 | Y25: =IF(Q25="",0,1) -> 1 | Z25: =IF(R25+U25=2,3,IF(R25+U25=1,1,0)) -> 0 | AA25: =IF(Z25=3,3,IF(X25+Z25=2,2,IF(Z25=1,1,0))) -> 0 | AB25: =Q25+T25 -> 5 | AC25: =R25+U25+X25 -> 0 | AE25: Division Runner Up
A26: vs. | P26: vs. | AE26: =IF(AL9=30,AN9,"") -> Denis Caruana/Duncan Zammit
A27: =AE17 -> Maurice Borg/Kenneth Caruana | B27: 7 | C27: =IF(B27>B25,1,0) -> 1 | E27: 6 | F27: =IF(E27>E25,1,0) -> 1 | I27: =IF(H27>H25,1,0) -> 0 | J27: =IF(B27="",0,1) -> 1 | K27: =IF(C27+F27=2,3,IF(C27+F27=1,1,0)) -> 3 | L27: =IF(K27=3,3,IF(I27+K27=2,2,IF(K27=1,1,0))) -> 3 | M27: =B27+E27 -> 13 | N27: =C27+F27+I27 -> 2 | P27: =AE19 -> Kenneth Farrugia/Juan Sammut | Q27: 6 | R27: =IF(Q27>Q25,1,0) -> 1 | T27: 6 | U27: =IF(T27>T25,1,0) -> 1 | X27: =IF(W27>W25,1,0) -> 0 | Y27: =IF(Q27="",0,1) -> 1 | Z27: =IF(R27+U27=2,3,IF(R27+U27=1,1,0)) -> 3 | AA27: =IF(Z27=3,3,IF(X27+Z27=2,2,IF(Z27=1,1,0))) -> 3 | AB27: =Q27+T27 -> 12 | AC27: =R27+U27+X27 -> 2
A29: =AE15 -> Dunstan Vella/Cyril Lastimosa | B29: 6 | C29: =IF(B29>B31,1,0) -> 1 | E29: 6 | F29: =IF(E29>E31,1,0) -> 1 | I29: =IF(H29>H31,1,0) -> 0 | J29: =IF(B29="",0,1) -> 1 | K29: =IF(C29+F29=2,3,IF(C29+F29=1,1,0)) -> 3 | L29: =IF(K29=3,3,IF(I29+K29=2,2,IF(K29=1,1,0))) -> 3 | M29: =B29+E29 -> 12 | N29: =C29+F29+I29 -> 2 | P29: =AE13 -> Cory Greenland/Benjamin Valencia | Q29: 0 | R29: =IF(Q29>Q31,1,0) -> 0 | T29: 3 | U29: =IF(T29>T31,1,0) -> 0 | X29: =IF(W29>W31,1,0) -> 0 | Y29: =IF(Q29="",0,1) -> 1 | Z29: =IF(R29+U29=2,3,IF(R29+U29=1,1,0)) -> 0 | AA29: =IF(Z29=3,3,IF(X29+Z29=2,2,IF(Z29=1,1,0))) -> 0 | AB29: =Q29+T29 -> 3 | AC29: =R29+U29+X29 -> 0
A30: vs. | P30: vs.
A31: =AE19 -> Kenneth Farrugia/Juan Sammut | B31: 2 | C31: =IF(B31>B29,1,0) -> 0 | E31: 3 | F31: =IF(E31>E29,1,0) -> 0 | I31: =IF(H31>H29,1,0) -> 0 | J31: =IF(B31="",0,1) -> 1 | K31: =IF(C31+F31=2,3,IF(C31+F31=1,1,0)) -> 0 | L31: =IF(K31=3,3,IF(I31+K31=2,2,IF(K31=1,1,0))) -> 0 | M31: =B31+E31 -> 5 | N31: =C31+F31+I31 -> 0 | P31: =AE15 -> Dunstan Vella/Cyril Lastimosa | Q31: 6 | R31: =IF(Q31>Q29,1,0) -> 1 | T31: 6 | U31: =IF(T31>T29,1,0) -> 1 | X31: =IF(W31>W29,1,0) -> 0 | Y31: =IF(Q31="",0,1) -> 1 | Z31: =IF(R31+U31=2,3,IF(R31+U31=1,1,0)) -> 3 | AA31: =IF(Z31=3,3,IF(X31+Z31=2,2,IF(Z31=1,1,0))) -> 3 | AB31: =Q31+T31 -> 12 | AC31: =R31+U31+X31 -> 2
A33: =AE13 -> Cory Greenland/Benjamin Valencia | B33: 2 | C33: =IF(B33>B35,1,0) -> 0 | E33: 3 | F33: =IF(E33>E35,1,0) -> 0 | I33: =IF(H33>H35,1,0) -> 0 | J33: =IF(B33="",0,1) -> 1 | K33: =IF(C33+F33=2,3,IF(C33+F33=1,1,0)) -> 0 | L33: =IF(K33=3,3,IF(I33+K33=2,2,IF(K33=1,1,0))) -> 0 | M33: =B33+E33 -> 5 | N33: =C33+F33+I33 -> 0 | P33: =AE13 -> Cory Greenland/Benjamin Valencia | Q33: 6 | R33: =IF(Q33>Q35,1,0) -> 0 | T33: 6 | U33: =IF(T33>T35,1,0) -> 1 | W33: 10 | X33: =IF(W33>W35,1,0) -> 1 | Y33: =IF(Q33="",0,1) -> 1 | Z33: =IF(R33+U33=2,3,IF(R33+U33=1,1,0)) -> 1 | AA33: =IF(Z33=3,3,IF(X33+Z33=2,2,IF(Z33=1,1,0))) -> 2 | AB33: =Q33+T33 -> 12 | AC33: =R33+U33+X33 -> 2
A34: vs. | P34: vs.
A35: =AE17 -> Maurice Borg/Kenneth Caruana | B35: 6 | C35: =IF(B35>B33,1,0) -> 1 | E35: 6 | F35: =IF(E35>E33,1,0) -> 1 | I35: =IF(H35>H33,1,0) -> 0 | J35: =IF(B35="",0,1) -> 1 | K35: =IF(C35+F35=2,3,IF(C35+F35=1,1,0)) -> 3 | L35: =IF(K35=3,3,IF(I35+K35=2,2,IF(K35=1,1,0))) -> 3 | M35: =B35+E35 -> 12 | N35: =C35+F35+I35 -> 2 | P35: =AE19 -> Kenneth Farrugia/Juan Sammut | Q35: 7 | R35: =IF(Q35>Q33,1,0) -> 1 | T35: 3 | U35: =IF(T35>T33,1,0) -> 0 | W35: 7 | X35: =IF(W35>W33,1,0) -> 0 | Y35: =IF(Q35="",0,1) -> 1 | Z35: =IF(R35+U35=2,3,IF(R35+U35=1,1,0)) -> 1 | AA35: =IF(Z35=3,3,IF(X35+Z35=2,2,IF(Z35=1,1,0))) -> 1 | AB35: =Q35+T35 -> 10 | AC35: =R35+U35+X35 -> 1
A37: =AE15 -> Dunstan Vella/Cyril Lastimosa | B37: 6 | C37: =IF(B37>B39,1,0) -> 1 | E37: 6 | F37: =IF(E37>E39,1,0) -> 1 | I37: =IF(H37>H39,1,0) -> 0 | J37: =IF(B37="",0,1) -> 1 | K37: =IF(C37+F37=2,3,IF(C37+F37=1,1,0)) -> 3 | L37: =IF(K37=3,3,IF(I37+K37=2,2,IF(K37=1,1,0))) -> 3 | M37: =B37+E37 -> 12 | N37: =C37+F37+I37 -> 2
A38: vs.
A39: =AE17 -> Maurice Borg/Kenneth Caruana | B39: 3 | C39: =IF(B39>B37,1,0) -> 0 | E39: 2 | F39: =IF(E39>E37,1,0) -> 0 | I39: =IF(H39>H37,1,0) -> 0 | J39: =IF(B39="",0,1) -> 1 | K39: =IF(C39+F39=2,3,IF(C39+F39=1,1,0)) -> 0 | L39: =IF(K39=3,3,IF(I39+K39=2,2,IF(K39=1,1,0))) -> 0 | M39: =B39+E39 -> 5 | N39: =C39+F39+I39 -> 0

Sheet Men Div 4
A1: VITTORIOSA LAWN TENNIS CLUB Sports Experience Chosen Doubles 2024
A5: Men Division 4
A7: Players | B7: Set Scores | H7: Tie | P7: Players | Q7: Set Scores | W7: Tie | AE7: Player | AF7: Matches Played | AG7: Points Overall | AH7: Games Won | AI7: Sets Won
B8: Score | C8: Set 1 Work | E8: Score | F8: Set 2 Work | H8: Score | I8: Tie Work | J8: Game Played | K8: Sets Points Work | L8: Sets & Tie Points Work | M8: Games Wins Work | N8: Sets Wins Work | Q8: Score | R8: Set 1 Work | T8: Score | U8: Set 2 Work | W8: Score | X8: Tie Work | Y8: Game Played | Z8: Sets Points Work | AA8: Sets & Tie Points Work | AB8: Games Wins Work | AC8: Sets Wins Work | AJ8: Winner Working | AK8: Runner Up Working | AL8: Total Games Work | AM8: Winner | AN8: Runner Up
A9: =AE9 -> Charles Micallef/Charles Grech | B9: 5 | C9: =IF(B9>B11,1,0) -> 0 | E9: 6 | F9: =IF(E9>E11,1,0) -> 1 | H9: 10 | I9: =IF(H9>H11,1,0) -> 1 | J9: =IF(B9="",0,1) -> 1 | K9: =IF(C9+F9=2,3,IF(C9+F9=1,1,0)) -> 1 | L9: =IF(K9=3,3,IF(I9+K9=2,2,IF(K9=1,1,0))) -> 2 | M9: =B9+E9 -> 11 | N9: =C9+F9+I9 -> 2 | P9: =AE9 -> Charles Micallef/Charles Grech | Q9: 6 | R9: =IF(Q9>Q11,1,0) -> 1 | T9: 6 | U9: =IF(T9>T11,1,0) -> 1 | X9: =IF(W9>W11,1,0) -> 0 | Y9: =IF(Q9="",0,1) -> 1 | Z9: =IF(R9+U9=2,3,IF(R9+U9=1,1,0)) -> 3 | AA9: =IF(Z9=3,3,IF(X9+Z9=2,2,IF(Z9=1,1,0))) -> 3 | AB9: =Q9+T9 -> 12 | AC9: =R9+U9+X9 -> 2 | AE9: ='Players Men'!B28 -> Charles Micallef/Charles Grech | AF9: =J9+Y9+J13+Y13+J17 -> 5 | AG9: =L9+AA9+L13+AA13+L17 -> 10 | AH9: =M9+AB9+M13+AB13+M17 -> 54 | AI9: =N9+AC9+N13+AC13+N17 -> 8 | AJ9: =MAX(AG9:AG19) -> 13 | AK9: =LARGE(AG9:AG19, 2) -> 12 | AL9: =SUM(AF9:AF19) -> 30 | AM9: =IF(AG9=$AJ$9,AE9,IF(AG11=$AJ$9,AE11,IF(AG13=$AJ$9,AE13,IF(AG15=$AJ$9,AE15,IF(AG17=$AJ$9,AE17,IF(AG19=$AJ$9,AE19,"")))))) -> Sean Cachia/Isaac Joseph Zammit | AN9: =IF(AG9=$AK$9,AE9,IF(AG11=$AK$9,AE11,IF(AG13=$AK$9,AE13,IF(AG15=$AK$9,AE15,IF(AG17=$AK$9,AE17,IF(AG19=$AK$9,AE19,"")))))) -> Robert Attard/Steve Gambin
A10: vs. | P10: vs.
A11: =AE11 -> Antoine Bugeja/Simone Ercolani | B11: 7 | C11: =IF(B11>B9,1,0) -> 1 | E11: 4 | F11: =IF(E11>E9,1,0) -> 0 | H11: 6 | I11: =IF(H11>H9,1,0) -> 0 | J11: =IF(B11="",0,1) -> 1 | K11: =IF(C11+F11=2,3,IF(C11+F11=1,1,0)) -> 1 | L11: =IF(K11=3,3,IF(I11+K11=2,2,IF(K11=1,1,0))) -> 1 | M11: =B11+E11 -> 11 | N11: =C11+F11+I11 -> 1 | P11: =AE13 -> Kevin Sciberras/Justin Scicluna | Q11: 3 | R11: =IF(Q11>Q9,1,0) -> 0 | T11: 0 | U11: =IF(T11>T9,1,0) -> 0 | X11: =IF(W11>W9,1,0) -> 0 | Y11: =IF(Q11="",0,1) -> 1 | Z11: =IF(R11+U11=2,3,IF(R11+U11=1,1,0)) -> 0 | AA11: =IF(Z11=3,3,IF(X11+Z11=2,2,IF(Z11=1,1,0))) -> 0 | AB11: =Q11+T11 -> 3 | AC11: =R11+U11+X11 -> 0 | AE11: ='Players Men'!B29 -> Antoine Bugeja/Simone Ercolani | AF11: =J11+Y25+J25+Y21+J21 -> 5 | AG11: =L11+AA25+L25+AA21+L21 -> 7 | AH11: =M11+AB25+M25+AB21+M21 -> 45 | AI11: =N11+AC25+N25+AC21+N21 -> 5
A13: =AE9 -> Charles Micallef/Charles Grech | B13: 4 | C13: =IF(B13>B15,1,0) -> 0 | E13: 6 | F13: =IF(E13>E15,1,0) -> 1 | H13: 6 | I13: =IF(H13>H15,1,0) -> 0 | J13: =IF(B13="",0,1) -> 1 | K13: =IF(C13+F13=2,3,IF(C13+F13=1,1,0)) -> 1 | L13: =IF(K13=3,3,IF(I13+K13=2,2,IF(K13=1,1,0))) -> 1 | M13: =B13+E13 -> 10 | N13: =C13+F13+I13 -> 1 | P13: =AE9 -> Charles Micallef/Charles Grech | Q13: 6 | R13: =IF(Q13>Q15,1,0) -> 1 | T13: 3 | U13: =IF(T13>T15,1,0) -> 0 | W13: 8 | X13: =IF(W13>W15,1,0) -> 0 | Y13: =IF(Q13="",0,1) -> 1 | Z13: =IF(R13+U13=2,3,IF(R13+U13=1,1,0)) -> 1 | AA13: =IF(Z13=3,3,IF(X13+Z13=2,2,IF(Z13=1,1,0))) -> 1 | AB13: =Q13+T13 -> 9 | AC13: =R13+U13+X13 -> 1 | AE13: ='Players Men'!B30 -> Kevin Sciberras/Justin Scicluna | AF13: =Y29+Y11+Y33+J33+J23 -> 5 | AG13: =AA29+AA11+AA33+L33+L23 -> 1 | AH13: =AB29+AB11+AB33+M33+M23 -> 22 | AI13: =AC29+AC11+AC33+N33+N23 -> 1
A14: vs. | P14: vs.
A15: =AE15 -> Sean Cachia/Isaac Joseph Zammit | B15: 6 | C15: =IF(B15>B13,1,0) -> 1 | E15: 1 | F15: =IF(E15>E13,1,0) -> 0 | H15: 10 | I15: =IF(H15>H13,1,0) -> 1 | J15: =IF(B15="",0,1) -> 1 | K15: =IF(C15+F15=2,3,IF(C15+F15=1,1,0)) -> 1 | L15: =IF(K15=3,3,IF(I15+K15=2,2,IF(K15=1,1,0))) -> 2 | M15: =B15+E15 -> 7 | N15: =C15+F15+I15 -> 2 | P15: =AE17 -> Robert Attard/Steve Gambin | Q15: 4 | R15: =IF(Q15>Q13,1,0) -> 0 | T15: 6 | U15: =IF(T15>T13,1,0) -> 1 | W15: 10 | X15: =IF(W15>W13,1,0) -> 1 | Y15: =IF(Q15="",0,1) -> 1 | Z15: =IF(R15+U15=2,3,IF(R15+U15=1,1,0)) -> 1 | AA15: =IF(Z15=3,3,IF(X15+Z15=2,2,IF(Z15=1,1,0))) -> 2 | AB15: =Q15+T15 -> 10 | AC15: =R15+U15+X15 -> 2 | AE15: ='Players Men'!B31 -> Sean Cachia/Isaac Joseph Zammit | AF15: =Y31+J37+J15+Y23+J29 -> 5 | AG15: =AA31+L37+L15+AA23+L29 -> 13 | AH15: =AB31+M37+M15+AB23+M29 -> 55 | AI15: =AC31+N37+N15+AC23+N29 -> 10
A17: =AE9 -> Charles Micallef/Charles Grech | B17: 6 | C17: =IF(B17>B19,1,0) -> 1 | E17: 6 | F17: =IF(E17>E19,1,0) -> 1 | I17: =IF(H17>H19,1,0) -> 0 | J17: =IF(B17="",0,1) -> 1 | K17: =IF(C17+F17=2,3,IF(C17+F17=1,1,0)) -> 3 | L17: =IF(K17=3,3,IF(I17+K17=2,2,IF(K17=1,1,0))) -> 3 | M17: =B17+E17 -> 12 | N17: =C17+F17+I17 -> 2 | P17: =AE17 -> Robert Attard/Steve Gambin | Q17: 6 | R17: =IF(Q17>Q19,1,0) -> 1 | T17: 6 | U17: =IF(T17>T19,1,0) -> 1 | X17: =IF(W17>W19,1,0) -> 0 | Y17: =IF(Q17="",0,1) -> 1 | Z17: =IF(R17+U17=2,3,IF(R17+U17=1,1,0)) -> 3 | AA17: =IF(Z17=3,3,IF(X17+Z17=2,2,IF(Z17=1,1,0))) -> 3 | AB17: =Q17+T17 -> 12 | AC17: =R17+U17+X17 -> 2 | AE17: ='Players Men'!B32 -> Robert Attard/Steve Gambin | AF17: =Y17+J39+J27+Y15+J35 -> 5 | AG17: =AA17+L39+L27+AA15+L35 -> 12 | AH17: =AB17+M39+M27+AB15+M35 -> 56 | AI17: =AC17+N39+N27+AC15+N35 -> 9
A18: vs. | P18: vs.
A19: =AE19 -> Isaac Baldacchino/JP Sciberras | B19: 2 | C19: =IF(B19>B17,1,0) -> 0 | E19: 2 | F19: =IF(E19>E17,1,0) -> 0 | I19: =IF(H19>H17,1,0) -> 0 | J19: =IF(B19="",0,1) -> 1 | K19: =IF(C19+F19=2,3,IF(C19+F19=1,1,0)) -> 0 | L19: =IF(K19=3,3,IF(I19+K19=2,2,IF(K19=1,1,0))) -> 0 | M19: =B19+E19 -> 4 | N19: =C19+F19+I19 -> 0 | P19: =AE19 -> Isaac Baldacchino/JP Sciberras | Q19: 0 | R19: =IF(Q19>Q17,1,0) -> 0 | T19: 4 | U19: =IF(T19>T17,1,0) -> 0 | X19: =IF(W19>W17,1,0) -> 0 | Y19: =IF(Q19="",0,1) -> 1 | Z19: =IF(R19+U19=2,3,IF(R19+U19=1,1,0)) -> 0 | AA19: =IF(Z19=3,3,IF(X19+Z19=2,2,IF(Z19=1,1,0))) -> 0 | AB19: =Q19+T19 -> 4 | AC19: =R19+U19+X19 -> 0 | AE19: ='Players Men'!B33 -> Isaac Baldacchino/JP Sciberras | AF19: =Y19+Y27+Y35+J19+J31 -> 5 | AG19: =AA19+AA27+AA35+L19+L31 -> 2 | AH19: =AB19+AB27+AB35+M19+M31 -> 27 | AI19: =AC19+AC27+AC35+N19+N31 -> 2
A21: =AE11 -> Antoine Bugeja/Simone Ercolani | B21: 6 | C21: =IF(B21>B23,1,0) -> 1 | E21: 6 | F21: =IF(E21>E23,1,0) -> 1 | I21: =IF(H21>H23,1,0) -> 0 | J21: =IF(B21="",0,1) -> 1 | K21: =IF(C21+F21=2,3,IF(C21+F21=1,1,0)) -> 3 | L21: =IF(K21=3,3,IF(I21+K21=2,2,IF(K21=1,1,0))) -> 3 | M21: =B21+E21 -> 12 | N21: =C21+F21+I21 -> 2 | P21: =AE11 -> Antoine Bugeja/Simone Ercolani | Q21: 4 | R21: =IF(Q21>Q23,1,0) -> 0 | T21: 4 | U21: =IF(T21>T23,1,0) -> 0 | X21: =IF(W21>W23,1,0) -> 0 | Y21: =IF(Q21="",0,1) -> 1 | Z21: =IF(R21+U21=2,3,IF(R21+U21=1,1,0)) -> 0 | AA21: =IF(Z21=3,3,IF(X21+Z21=2,2,IF(Z21=1,1,0))) -> 0 | AB21: =Q21+T21 -> 8 | AC21: =R21+U21+X21 -> 0 | AE21: Division Winner
A22: vs. | P22: vs. | AE22: =IF(AL9=30,AM9,"") -> Sean Cachia/Isaac Joseph Zammit
A23: =AE13 -> Kevin Sciberras/Justin Scicluna | B23: 2 | C23: =IF(B23>B21,1,0) -> 0 | E23: 0 | F23: =IF(E23>E21,1,0) -> 0 | I23: =IF(H23>H21,1,0) -> 0 | J23: =IF(B23="",0,1) -> 1 | K23: =IF(C23+F23=2,3,IF(C23+F23=1,1,0)) -> 0 | L23: =IF(K23=3,3,IF(I23+K23=2,2,IF(K23=1,1,0))) -> 0 | M23: =B23+E23 -> 2 | N23: =C23+F23+I23 -> 0 | P23: =AE15 -> Sean Cachia/Isaac Joseph Zammit | Q23: 6 | R23: =IF(Q23>Q21,1,0) -> 1 | T23: 6 | U23: =IF(T23>T21,1,0) -> 1 | X23: =IF(W23>W21,1,0) -> 0 | Y23: =IF(Q23="",0,1) -> 1 | Z23: =IF(R23+U23=2,3,IF(R23+U23=1,1,0)) -> 3 | AA23: =IF(Z23=3,3,IF(X23+Z23=2,2,IF(Z23=1,1,0))) -> 3 | AB23: =Q23+T23 -> 12 | AC23: =R23+U23+X23 -> 2
A25: =AE11 -> Antoine Bugeja/Simone Ercolani | B25: 2 | C25: =IF(B25>B27,1,0) -> 0 | E25: 0 | F25: =IF(E25>E27,1,0) -> 0 | I25: =IF(H25>H27,1,0) -> 0 | J25: =IF(B25="",0,1) -> 1 | K25: =IF(C25+F25=2,3,IF(C25+F25=1,1,0)) -> 0 | L25: =IF(K25=3,3,IF(I25+K25=2,2,IF(K25=1,1,0))) -> 0 | M25: =B25+E25 -> 2 | N25: =C25+F25+I25 -> 0 | P25: =AE11 -> Antoine Bugeja/Simone Ercolani | Q25: 6 | R25: =IF(Q25>Q27,1,0) -> 1 | T25: 6 | U25: =IF(T25>T27,1,0) -> 1 | X25: =IF(W25>W27,1,0) -> 0 | Y25: =IF(Q25="",0,1) -> 1 | Z25: =IF(R25+U25=2,3,IF(R25+U25=1,1,0)) -> 3 | AA25: =IF(Z25=3,3,IF(X25+Z25=2,2,IF(Z25=1,1,0))) -> 3 | AB25: =Q25+T25 -> 12 | AC25: =R25+U25+X25 -> 2 | AE25: Division Runner Up
A26: vs. | P26: vs. | AE26: =IF(AL9=30,AN9,"") -> Robert Attard/Steve Gambin
A27: =AE17 -> Robert Attard/Steve Gambin | B27: 6 | C27: =IF(B27>B25,1,0) -> 1 | E27: 6 | F27: =IF(E27>E25,1,0) -> 1 | I27: =IF(H27>H25,1,0) -> 0 | J27: =IF(B27="",0,1) -> 1 | K27: =IF(C27+F27=2,3,IF(C27+F27=1,1,0)) -> 3 | L27: =IF(K27=3,3,IF(I27+K27=2,2,IF(K27=1,1,0))) -> 3 | M27: =B27+E27 -> 12 | N27: =C27+F27+I27 -> 2 | P27: =AE19 -> Isaac Baldacchino/JP Sciberras | Q27: 1 | R27: =IF(Q27>Q25,1,0) -> 0 | T27: 4 | U27: =IF(T27>T25,1,0) -> 0 | X27: =IF(W27>W25,1,0) -> 0 | Y27: =IF(Q27="",0,1) -> 1 | Z27: =IF(R27+U27=2,3,IF(R27+U27=1,1,0)) -> 0 | AA27: =IF(Z27=3,3,IF(X27+Z27=2,2,IF(Z27=1,1,0))) -> 0 | AB27: =Q27+T27 -> 5 | AC27: =R27+U27+X27 -> 0
A29: =AE15 -> Sean Cachia/Isaac Joseph Zammit | B29: 7 | C29: =IF(B29>B31,1,0) -> 1 | E29: 6 | F29: =IF(E29>E31,1,0) -> 1 | I29: =IF(H29>H31,1,0) -> 0 | J29: =IF(B29="",0,1) -> 1 | K29: =IF(C29+F29=2,3,IF(C29+F29=1,1,0)) -> 3 | L29: =IF(K29=3,3,IF(I29+K29=2,2,IF(K29=1,1,0))) -> 3 | M29: =B29+E29 -> 13 | N29: =C29+F29+I29 -> 2 | P29: =AE13 -> Kevin Sciberras/Justin Scicluna | Q29: 0 | R29: =IF(Q29>Q31,1,0) -> 0 | T29: 2 | U29: =IF(T29>T31,1,0) -> 0 | X29: =IF(W29>W31,1,0) -> 0 | Y29: =IF(Q29="",0,1) -> 1 | Z29: =IF(R29+U29=2,3,IF(R29+U29=1,1,0)) -> 0 | AA29: =IF(Z29=3,3,IF(X29+Z29=2,2,IF(Z29=1,1,0))) -> 0 | AB29: =Q29+T29 -> 2 | AC29: =R29+U29+X29 -> 0
A30: vs. | P30: vs.
A31: =AE19 -> Isaac Baldacchino/JP Sciberras | B31: 5 | C31: =IF(B31>B29,1,0) -> 0 | E31: 2 | F31: =IF(E31>E29,1,0) -> 0 | I31: =IF(H31>H29,1,0) -> 0 | J31: =IF(B31="",0,1) -> 1 | K31: =IF(C31+F31=2,3,IF(C31+F31=1,1,0)) -> 0 | L31: =IF(K31=3,3,IF(I31+K31=2,2,IF(K31=1,1,0))) -> 0 | M31: =B31+E31 -> 7 | N31: =C31+F31+I31 -> 0 | P31: =AE15 -> Sean Cachia/Isaac Joseph Zammit | Q31: 6 | R31: =IF(Q31>Q29,1,0) -> 1 | T31: 6 | U31: =IF(T31>T29,1,0) -> 1 | X31: =IF(W31>W29,1,0) -> 0 | Y31: =IF(Q31="",0,1) -> 1 | Z31: =IF(R31+U31=2,3,IF(R31+U31=1,1,0)) -> 3 | AA31: =IF(Z31=3,3,IF(X31+Z31=2,2,IF(Z31=1,1,0))) -> 3 | AB31: =Q31+T31 -> 12 | AC31: =R31+U31+X31 -> 2
A33: =AE13 -> Kevin Sciberras/Justin Scicluna | B33: 3 | C33: =IF(B33>B35,1,0) -> 0 | E33: 3 | F33: =IF(E33>E35,1,0) -> 0 | I33: =IF(H33>H35,1,0) -> 0 | J33: =IF(B33="",0,1) -> 1 | K33: =IF(C33+F33=2,3,IF(C33+F33=1,1,0)) -> 0 | L33: =IF(K33=3,3,IF(I33+K33=2,2,IF(K33=1,1,0))) -> 0 | M33: =B33+E33 -> 6 | N33: =C33+F33+I33 -> 0 | P33: =AE13 -> Kevin Sciberras/Justin Scicluna | Q33: 6 | R33: =IF(Q33>Q35,1,0) -> 1 | T33: 3 | U33: =IF(T33>T35,1,0) -> 0 | W33: 6 | X33: =IF(W33>W35,1,0) -> 0 | Y33: =IF(Q33="",0,1) -> 1 | Z33: =IF(R33+U33=2,3,IF(R33+U33=1,1,0)) -> 1 | AA33: =IF(Z33=3,3,IF(X33+Z33=2,2,IF(Z33=1,1,0))) -> 1 | AB33: =Q33+T33 -> 9 | AC33: =R33+U33+X33 -> 1
A34: vs. | P34: vs.
A35: =AE17 -> Robert Attard/Steve Gambin | B35: 6 | C35: =IF(B35>B33,1,0) -> 1 | E35: 6 | F35: =IF(E35>E33,1,0) -> 1 | I35: =IF(H35>H33,1,0) -> 0 | J35: =IF(B35="",0,1) -> 1 | K35: =IF(C35+F35=2,3,IF(C35+F35=1,1,0)) -> 3 | L35: =IF(K35=3,3,IF(I35+K35=2,2,IF(K35=1,1,0))) -> 3 | M35: =B35+E35 -> 12 | N35: =C35+F35+I35 -> 2 | P35: =AE19 -> Isaac Baldacchino/JP Sciberras | Q35: 1 | R35: =IF(Q35>Q33,1,0) -> 0 | T35: 6 | U35: =IF(T35>T33,1,0) -> 1 | W35: 10 | X35: =IF(W35>W33,1,0) -> 1 | Y35: =IF(Q35="",0,1) -> 1 | Z35: =IF(R35+U35=2,3,IF(R35+U35=1,1,0)) -> 1 | AA35: =IF(Z35=3,3,IF(X35+Z35=2,2,IF(Z35=1,1,0))) -> 2 | AB35: =Q35+T35 -> 7 | AC35: =R35+U35+X35 -> 2
A37: =AE15 -> Sean Cachia/Isaac Joseph Zammit | B37: 6 | C37: =IF(B37>B39,1,0) -> 1 | E37: 5 | F37: =IF(E37>E39,1,0) -> 0 | H37: 10 | I37: =IF(H37>H39,1,0) -> 1 | J37: =IF(B37="",0,1) -> 1 | K37: =IF(C37+F37=2,3,IF(C37+F37=1,1,0)) -> 1 | L37: =IF(K37=3,3,IF(I37+K37=2,2,IF(K37=1,1,0))) -> 2 | M37: =B37+E37 -> 11 | N37: =C37+F37+I37 -> 2
A38: vs.
A39: =AE17 -> Robert Attard/Steve Gambin | B39: 3 | C39: =IF(B39>B37,1,0) -> 0 | E39: 7 | F39: =IF(E39>E37,1,0) -> 1 | H39: 5 | I39: =IF(H39>H37,1,0) -> 0 | J39: =IF(B39="",0,1) -> 1 | K39: =IF(C39+F39=2,3,IF(C39+F39=1,1,0)) -> 1 | L39: =IF(K39=3,3,IF(I39+K39=2,2,IF(K39=1,1,0))) -> 1 | M39: =B39+E39 -> 10 | N39: =C39+F39+I39 -> 1

Sheet Players Ladies
A1: VITTORIOSA LAWN TENNIS CLUB LADIES CHOSEN DOUBLES 2024
B5: Ladies Division 1
A6: 1 | B6: Renette Magra/Diane Fenech
A7: 2 | B7: Alexia Spiteri Willets/Kirsty Mercieca
A8: 3 | B8: Natalya Abela/Yana Marie Cachia
A9: 4 | B9: Annabelle Abela/Alison Muscat
A10: 5 | B10: Christine Schembri/Luiza Andreozzi
A11: 5 | B11: Roberta Fenech/Christina Bonett
B13: Ladies Division 2 - Group A | F13: Ladies Division 2 - Group B
A14: 1 | B14: Diane Farrugia/Anna Napier | E14: 1 | F14: Nancy Wong/Rowena Caruana
A15: 2 | B15: Kristina Briffa/Sarah Axiaq | E15: 2 | F15: Angele Pule'/Jennifer Mifsud
A16: 3 | B16: Brenda Baldacchino/Deborah Farrugia | E16: 3 | F16: Hiedi Tabone/Anabel Borg
A17: 4 | B17: Mariska Steenkamer/Romina Gauci | E17: 4 | F17: Marcette Sciriha/Tanya Cassar
A18: 5 | B18: Francesca Sciortino/Julie Spiteri | E18: 5 | F18: Ann Marie Attard/Christine Seychell
