Workbook

Sheet Players - Men
A1: Troy Shipping Agency Singles Tournament 2024
B5: Men Division 1 - Group A | E5: Men Division 1 - Group B
A6: 1 | B6: Reuben Borg | D6: 1 | E6: Trevor Rutter
A7: 2 | B7: Melchior Farrugia | D7: 2 | E7: Matthew Pace
A8: 3 | B8: Matthew Borg | D8: 3 | E8: Andrew Pule'
A9: 4 | B9: Jean Attard | D9: 4 | E9: Fotios Evangelou
A10: 5 | B10: Adrian Manduca | D10: 5 | E10: Marco Mercieca
A11: 6 | B11: Keith Micallef | D11: 6 | E11: Daniel Falzon
B13: Men Division 2 - Group A | E13: Men Division 2 - Group B
A14: 1 | B14: Andre' Farrugia | D14: 1 | E14: Roderick Spiteri
A15: 2 | B15: Liam Dixon | D15: 2 | E15: Daniel Farrugia
A16: 3 | B16: Tobias Kristensen | D16: 3 | E16: Georges Meekers
A17: 4 | B17: Gabriel Pace | D17: 4 | E17: Jay Boy Lastimosa
A18: 5 | B18: Chi Chi Canonce | D18: 5 | E18: Emman Xuereb
A19: 6 | B19: Eric Micallef | D19: 6 | E19: Cyril Lastimosa
B21: Men Division 3
A22: 1 | B22: Mavric Sawyer
A23: 2 | B23: Artiom Kiricenko
A24: 3 | B24: Kristen Cachia
A25: 4 | B25: Denis Caruana
A26: 5 | B26: Ryan Ebejer
A27: 6 | B27: Max Anastasi Jr
B29: Men Division 4
A30: 1 | B30: Lydon Vella
A31: 2 | B31: Kenneth Farrugia
A32: 3 | B32: M. Ibnu Wahyudi Mohamad Ibnu Wahyudi
A33: 4 | B33: Etienne Formosa Carabez
A34: 5 | B34: Ivan Cassar
A35: 6 | B35: Kurt Cassar
B37: Men Division 5
A38: 1 | B38: JP Sciberras
A39: 2 | B39: Adrian Duca
A40: 3 | B40: Cory Greenland
A41: 4 | B41: Matthew Micallef
A42: 5 | B42: Donald Deguzman
A43: 6 | B43: Juan Sammut

Sheet Men Div 1
A1: Troy Shipping Agency Singles Tournament 2024
A5: Division 1 - Group A
A7: Players | B7: Set Scores | H7: Tie | P7: Players | Q7: Set Scores | W7: Tie | AE7: Player | AF7: Games | AG7: Points | AH7: Games Won | AI7: Sets Won
B8: Score | C8: Set 1 Work | E8: Score | F8: Set 2 Work | H8: Score | I8: Tie Work | J8: Game Played | K8: Sets Points Work | L8: Sets & Tie Points Work | M8: Games Wins Work | N8: Sets Wins Work | Q8: Score | R8: Set 1 Work | T8: Score | U8: Set 2 Work | W8: Score | X8: Tie Work | Y8: Game Played | Z8: Sets Points Work | AA8: Sets & Tie Points Work | AB8: Games Wins Work | AC8: Sets Wins Work | AJ8: Winner Working | AK8: Total Games Work | AL8: Winner
A9: =AE9 -> Reuben Borg | B9: 6 | C9: =IF(B9>B11,1,0) -> 0 | E9: 3 | F9: =IF(E9>E11,1,0) -> 0 | I9: =IF(H9>H11,1,0) -> 0 | J9: =IF(B9="",0,1) -> 1 | K9: =IF(C9+F9=2,3,IF(C9+F9=1,1,0)) -> 0 | L9: =IF(K9=3,3,IF(I9+K9=2,2,IF(K9=1,1,0))) -> 0 | M9: =B9+E9 -> 9 | N9: =C9+F9+I9 -> 0 | P9: =AE9 -> Reuben Borg | Q9: 6 | R9: =IF(Q9>Q11,1,0) -> 1 | T9: 6 | U9: =IF(T9>T11,1,0) -> 1 | X9: =IF(W9>W11,1,0) -> 0 | Y9: =IF(Q9="",0,1) -> 1 | Z9: =IF(R9+U9=2,3,IF(R9+U9=1,1,0)) -> 3 | AA9: =IF(Z9=3,3,IF(X9+Z9=2,2,IF(Z9=1,1,0))) -> 3 | AB9: =Q9+T9 -> 12 | AC9: =R9+U9+X9 -> 2 | AE9: ='Players - Men'!B6 -> Reuben Borg | AF9: =J9+Y9+J13+Y13+J17 -> 5 | AG9: =L9+AA9+L13+AA13+L17 -> 10 | AH9: =M9+AB9+M13+AB13+M17 -> 53 | AI9: =N9+AC9+N13+AC13+N17 -> 7 | AJ9: =MAX(AG9:AG19) -> 11 | AK9: =SUM(AF9:AF19) -> 30 | AL9: =IF(AG9=$AJ$9,AE9,IF(AG11=$AJ$9,AE11,IF(AG13=$AJ$9,AE13,IF(AG15=$AJ$9,AE15,IF(AG17=$AJ$9,AE17,IF(AG19=$AJ$9,AE19,"")))))) -> Melchior Farrugia
A10: vs. | P10: vs.
A11: =AE11 -> Melchior Farrugia | B11: 7 | C11: =IF(B11>B9,1,0) -> 1 | E11: 6 | F11: =IF(E11>E9,1,0) -> 1 | I11: =IF(H11>H9,1,0) -> 0 | J11: =IF(B11="",0,1) -> 1 | K11: =IF(C11+F11=2,3,IF(C11+F11=1,1,0)) -> 3 | L11: =IF(K11=3,3,IF(I11+K11=2,2,IF(K11=1,1,0))) -> 3 | M11: =B11+E11 -> 13 | N11: =C11+F11+I11 -> 2 | P11: =AE13 -> Matthew Borg | Q11: 2 | R11: =IF(Q11>Q9,1,0) -> 0 | T11: 3 | U11: =IF(T11>T9,1,0) -> 0 | X11: =IF(W11>W9,1,0) -> 0 | Y11: =IF(Q11="",0,1) -> 1 | Z11: =IF(R11+U11=2,3,IF(R11+U11=1,1,0)) -> 0 | AA11: =IF(Z11=3,3,IF(X11+Z11=2,2,IF(Z11=1,1,0))) -> 0 | AB11: =Q11+T11 -> 5 | AC11: =R11+U11+X11 -> 0 | AE11: ='Players - Men'!B7 -> Melchior Farrugia | AF11: =J11+Y25+J25+Y21+J21 -> 5 | AG11: =L11+AA25+L25+AA21+L21 -> 11 | AH11: =M11+AB25+M25+AB21+M21 -> 49 | AI11: =N11+AC25+N25+AC21+N21 -> 9
A13: =AE9 -> Reuben Borg | B13: 0 | C13: =IF(B13>B15,1,0) -> 0 | E13: 6 | F13: =IF(E13>E15,1,0) -> 1 | H13: 6 | I13: =IF(H13>H15,1,0) -> 0 | J13: =IF(B13="",0,1) -> 1 | K13: =IF(C13+F13=2,3,IF(C13+F13=1,1,0)) -> 1 | L13: =IF(K13=3,3,IF(I13+K13=2,2,IF(K13=1,1,0))) -> 1 | M13: =B13+E13 -> 6 | N13: =C13+F13+I13 -> 1 | P13: =AE9 -> Reuben Borg | Q13: 7 | R13: =IF(Q13>Q15,1,0) -> 1 | T13: 7 | U13: =IF(T13>T15,1,0) -> 1 | X13: =IF(W13>W15,1,0) -> 0 | Y13: =IF(Q13="",0,1) -> 1 | Z13: =IF(R13+U13=2,3,IF(R13+U13=1,1,0)) -> 3 | AA13: =IF(Z13=3,3,IF(X13+Z13=2,2,IF(Z13=1,1,0))) -> 3 | AB13: =Q13+T13 -> 14 | AC13: =R13+U13+X13 -> 2 | AE13: ='Players - Men'!B8 -> Matthew Borg | AF13: =Y29+Y11+Y33+J33+J23 -> 5 | AG13: =AA29+AA11+AA33+L33+L23 -> 5 | AH13: =AB29+AB11+AB33+M33+M23 -> 39 | AI13: =AC29+AC11+AC33+N33+N23 -> 5
A14: vs. | P14: vs.
A15: =AE15 -> Jean Attard | B15: 6 | C15: =IF(B15>B13,1,0) -> 1 | E15: 4 | F15: =IF(E15>E13,1,0) -> 0 | H15: 10 | I15: =IF(H15>H13,1,0) -> 1 | J15: =IF(B15="",0,1) -> 1 | K15: =IF(C15+F15=2,3,IF(C15+F15=1,1,0)) -> 1 | L15: =IF(K15=3,3,IF(I15+K15=2,2,IF(K15=1,1,0))) -> 2 | M15: =B15+E15 -> 10 | N15: =C15+F15+I15 -> 2 | P15: =AE17 -> Adrian Manduca | Q15: 6 | R15: =IF(Q15>Q13,1,0) -> 0 | T15: 6 | U15: =IF(T15>T13,1,0) -> 0 | X15: =IF(W15>W13,1,0) -> 0 | Y15: =IF(Q15="",0,1) -> 1 | Z15: =IF(R15+U15=2,3,IF(R15+U15=1,1,0)) -> 0 | AA15: =IF(Z15=3,3,IF(X15+Z15=2,2,IF(Z15=1,1,0))) -> 0 | AB15: =Q15+T15 -> 12 | AC15: =R15+U15+X15 -> 0 | AE15: ='Players - Men'!B9 -> Jean Attard | AF15: =Y31+J37+J15+Y23+J29 -> 5 | AG15: =AA31+L37+L15+AA23+L29 -> 8 | AH15: =AB31+M37+M15+AB23+M29 -> 52 | AI15: =AC31+N37+N15+AC23+N29 -> 7
A17: =AE9 -> Reuben Borg | B17: 6 | C17: =IF(B17>B19,1,0) -> 1 | E17: 6 | F17: =IF(E17>E19,1,0) -> 1 | I17: =IF(H17>H19,1,0) -> 0 | J17: =IF(B17="",0,1) -> 1 | K17: =IF(C17+F17=2,3,IF(C17+F17=1,1,0)) -> 3 | L17: =IF(K17=3,3,IF(I17+K17=2,2,IF(K17=1,1,0))) -> 3 | M17: =B17+E17 -> 12 | N17: =C17+F17+I17 -> 2 | P17: =AE17 -> Adrian Manduca | Q17: 6 | R17: =IF(Q17>Q19,1,0) -> 0 | T17: 6 | U17: =IF(T17>T19,1,0) -> 1 | W17: 10 | X17: =IF(W17>W19,1,0) -> 1 | Y17: =IF(Q17="",0,1) -> 1 | Z17: =IF(R17+U17=2,3,IF(R17+U17=1,1,0)) -> 1 | AA17: =IF(Z17=3,3,IF(X17+Z17=2,2,IF(Z17=1,1,0))) -> 2 | AB17: =Q17+T17 -> 12 | AC17: =R17+U17+X17 -> 2 | AE17: ='Players - Men'!B10 -> Adrian Manduca | AF17: =Y17+J39+J27+Y15+J35 -> 5 | AG17: =AA17+L39+L27+AA15+L35 -> 5 | AH17: =AB17+M39+M27+AB15+M35 -> 49 | AI17: =AC17+N39+N27+AC15+N35 -> 4
A18: vs. | P18: vs.
A19: =AE19 -> Keith Micallef | B19: 1 | C19: =IF(B19>B17,1,0) -> 0 | E19: 3 | F19: =IF(E19>E17,1,0) -> 0 | I19: =IF(H19>H17,1,0) -> 0 | J19: =IF(B19="",0,1) -> 1 | K19: =IF(C19+F19=2,3,IF(C19+F19=1,1,0)) -> 0 | L19: =IF(K19=3,3,IF(I19+K19=2,2,IF(K19=1,1,0))) -> 0 | M19: =B19+E19 -> 4 | N19: =C19+F19+I19 -> 0 | P19: =AE19 -> Keith Micallef | Q19: 7 | R19: =IF(Q19>Q17,1,0) -> 1 | T19: 4 | U19: =IF(T19>T17,1,0) -> 0 | W19: 7 | X19: =IF(W19>W17,1,0) -> 0 | Y19: =IF(Q19="",0,1) -> 1 | Z19: =IF(R19+U19=2,3,IF(R19+U19=1,1,0)) -> 1 | AA19: =IF(Z19=3,3,IF(X19+Z19=2,2,IF(Z19=1,1,0))) -> 1 | AB19: =Q19+T19 -> 11 | AC19: =R19+U19+X19 -> 1 | AE19: ='Players - Men'!B11 -> Keith Micallef | AF19: =Y19+Y27+Y35+J19+J31 -> 5 | AG19: =AA19+AA35+L31+AA27+L19 -> 6 | AH19: =AB19+AB27+AB35+M19+M31 -> 48 | AI19: =AC19+AC27+AC35+N19+N31 -> 6
A21: =AE11 -> Melchior Farrugia | B21: 4 | C21: =IF(B21>B23,1,0) -> 0 | E21: 6 | F21: =IF(E21>E23,1,0) -> 1 | H21: 10 | I21: =IF(H21>H23,1,0) -> 1 | J21: =IF(B21="",0,1) -> 1 | K21: =IF(C21+F21=2,3,IF(C21+F21=1,1,0)) -> 1 | L21: =IF(K21=3,3,IF(I21+K21=2,2,IF(K21=1,1,0))) -> 2 | M21: =B21+E21 -> 10 | N21: =C21+F21+I21 -> 2 | P21: =AE11 -> Melchior Farrugia | Q21: 6 | R21: =IF(Q21>Q23,1,0) -> 1 | T21: 0 | U21: =IF(T21>T23,1,0) -> 0 | W21: 10 | X21: =IF(W21>W23,1,0) -> 1 | Y21: =IF(Q21="",0,1) -> 1 | Z21: =IF(R21+U21=2,3,IF(R21+U21=1,1,0)) -> 1 | AA21: =IF(Z21=3,3,IF(X21+Z21=2,2,IF(Z21=1,1,0))) -> 2 | AB21: =Q21+T21 -> 6 | AC21: =R21+U21+X21 -> 2 | AE21: Group A Winner
A22: vs. | P22: vs. | AE22: Melchior Farrugia
A23: =AE13 -> Matthew Borg | B23: 6 | C23: =IF(B23>B21,1,0) -> 1 | E23: 4 | F23: =IF(E23>E21,1,0) -> 0 | H23: 3 | I23: =IF(H23>H21,1,0) -> 0 | J23: =IF(B23="",0,1) -> 1 | K23: =IF(C23+F23=2,3,IF(C23+F23=1,1,0)) -> 1 | L23: =IF(K23=3,3,IF(I23+K23=2,2,IF(K23=1,1,0))) -> 1 | M23: =B23+E23 -> 10 | N23: =C23+F23+I23 -> 1 | P23: =AE15 -> Jean Attard | Q23: 3 | R23: =IF(Q23>Q21,1,0) -> 0 | T23: 6 | U23: =IF(T23>T21,1,0) -> 1 | W23: 5 | X23: =IF(W23>W21,1,0) -> 0 | Y23: =IF(Q23="",0,1) -> 1 | Z23: =IF(R23+U23=2,3,IF(R23+U23=1,1,0)) -> 1 | AA23: =IF(Z23=3,3,IF(X23+Z23=2,2,IF(Z23=1,1,0))) -> 1 | AB23: =Q23+T23 -> 9 | AC23: =R23+U23+X23 -> 1
A25: =AE11 -> Melchior Farrugia | B25: 7 | C25: =IF(B25>B27,1,0) -> 1 | E25: 6 | F25: =IF(E25>E27,1,0) -> 1 | I25: =IF(H25>H27,1,0) -> 0 | J25: =IF(B25="",0,1) -> 1 | K25: =IF(C25+F25=2,3,IF(C25+F25=1,1,0)) -> 3 | L25: =IF(K25=3,3,IF(I25+K25=2,2,IF(K25=1,1,0))) -> 3 | M25: =B25+E25 -> 13 | N25: =C25+F25+I25 -> 2 | P25: =AE11 -> Melchior Farrugia | Q25: 7 | R25: =IF(Q25>Q27,1,0) -> 1 | T25: 0 | U25: =IF(T25>T27,1,0) -> 0 | W25: 4 | X25: =IF(W25>W27,1,0) -> 0 | Y25: =IF(Q25="",0,1) -> 1 | Z25: =IF(R25+U25=2,3,IF(R25+U25=1,1,0)) -> 1 | AA25: =IF(Z25=3,3,IF(X25+Z25=2,2,IF(Z25=1,1,0))) -> 1 | AB25: =Q25+T25 -> 7 | AC25: =R25+U25+X25 -> 1
A26: vs. | P26: vs.
A27: =AE17 -> Adrian Manduca | B27: 5 | C27: =IF(B27>B25,1,0) -> 0 | E27: 4 | F27: =IF(E27>E25,1,0) -> 0 | I27: =IF(H27>H25,1,0) -> 0 | J27: =IF(B27="",0,1) -> 1 | K27: =IF(C27+F27=2,3,IF(C27+F27=1,1,0)) -> 0 | L27: =IF(K27=3,3,IF(I27+K27=2,2,IF(K27=1,1,0))) -> 0 | M27: =B27+E27 -> 9 | N27: =C27+F27+I27 -> 0 | P27: =AE19 -> Keith Micallef | Q27: 6 | R27: =IF(Q27>Q25,1,0) -> 0 | T27: 6 | U27: =IF(T27>T25,1,0) -> 1 | W27: 10 | X27: =IF(W27>W25,1,0) -> 1 | Y27: =IF(Q27="",0,1) -> 1 | Z27: =IF(R27+U27=2,3,IF(R27+U27=1,1,0)) -> 1 | AA27: =IF(Z27=3,3,IF(X27+Z27=2,2,IF(Z27=1,1,0))) -> 2 | AB27: =Q27+T27 -> 12 | AC27: =R27+U27+X27 -> 2
A29: =AE15 -> Jean Attard | B29: 6 | C29: =IF(B29>B31,1,0) -> 1 | E29: 3 | F29: =IF(E29>E31,1,0) -> 0 | H29: 9 | I29: =IF(H29>H31,1,0) -> 0 | J29: =IF(B29="",0,1) -> 1 | K29: =IF(C29+F29=2,3,IF(C29+F29=1,1,0)) -> 1 | L29: =IF(K29=3,3,IF(I29+K29=2,2,IF(K29=1,1,0))) -> 1 | M29: =B29+E29 -> 9 | N29: =C29+F29+I29 -> 1 | P29: =AE13 -> Matthew Borg | Q29: 4 | R29: =IF(Q29>Q31,1,0) -> 0 | T29: 7 | U29: =IF(T29>T31,1,0) -> 1 | W29: 10 | X29: =IF(W29>W31,1,0) -> 1 | Y29: =IF(Q29="",0,1) -> 1 | Z29: =IF(R29+U29=2,3,IF(R29+U29=1,1,0)) -> 1 | AA29: =IF(Z29=3,3,IF(X29+Z29=2,2,IF(Z29=1,1,0))) -> 2 | AB29: =Q29+T29 -> 11 | AC29: =R29+U29+X29 -> 2
A30: vs. | P30: vs.
A31: =AE19 -> Keith Micallef | B31: 3 | C31: =IF(B31>B29,1,0) -> 0 | E31: 6 | F31: =IF(E31>E29,1,0) -> 1 | H31: 11 | I31: =IF(H31>H29,1,0) -> 1 | J31: =IF(B31="",0,1) -> 1 | K31: =IF(C31+F31=2,3,IF(C31+F31=1,1,0)) -> 1 | L31: =IF(K31=3,3,IF(I31+K31=2,2,IF(K31=1,1,0))) -> 2 | M31: =B31+E31 -> 9 | N31: =C31+F31+I31 -> 2 | P31: =AE15 -> Jean Attard | Q31: 6 | R31: =IF(Q31>Q29,1,0) -> 1 | T31: 6 | U31: =IF(T31>T29,1,0) -> 0 | W31: 4 | X31: =IF(W31>W29,1,0) -> 0 | Y31: =IF(Q31="",0,1) -> 1 | Z31: =IF(R31+U31=2,3,IF(R31+U31=1,1,0)) -> 1 | AA31: =IF(Z31=3,3,IF(X31+Z31=2,2,IF(Z31=1,1,0))) -> 1 | AB31: =Q31+T31 -> 12 | AC31: =R31+U31+X31 -> 1
A33: =AE13 -> Matthew Borg | B33: 0 | C33: =IF(B33>B35,1,0) -> 0 | E33: 0 | F33: =IF(E33>E35,1,0) -> 0 | I33: =IF(H33>H35,1,0) -> 0 | J33: =IF(B33="",0,1) -> 1 | K33: =IF(C33+F33=2,3,IF(C33+F33=1,1,0)) -> 0 | L33: =IF(K33=3,3,IF(I33+K33=2,2,IF(K33=1,1,0))) -> 0 | M33: =B33+E33 -> 0 | N33: =C33+F33+I33 -> 0 | O33: w/o | P33: =AE13 -> Matthew Borg | Q33: 7 | R33: =IF(Q33>Q35,1,0) -> 1 | T33: 6 | U33: =IF(T33>T35,1,0) -> 0 | W33: 10 | X33: =IF(W33>W35,1,0) -> 1 | Y33: =IF(Q33="",0,1) -> 1 | Z33: =IF(R33+U33=2,3,IF(R33+U33=1,1,0)) -> 1 | AA33: =IF(Z33=3,3,IF(X33+Z33=2,2,IF(Z33=1,1,0))) -> 2 | AB33: =Q33+T33 -> 13 | AC33: =R33+U33+X33 -> 2
A34: vs. | P34: vs.
A35: =AE17 -> Adrian Manduca | B35: 6 | C35: =IF(B35>B33,1,0) -> 1 | E35: 6 | F35: =IF(E35>E33,1,0) -> 1 | I35: =IF(H35>H33,1,0) -> 0 | J35: =IF(B35="",0,1) -> 1 | K35: =IF(C35+F35=2,3,IF(C35+F35=1,1,0)) -> 3 | L35: =IF(K35=3,3,IF(I35+K35=2,2,IF(K35=1,1,0))) -> 3 | M35: =B35+E35 -> 12 | N35: =C35+F35+I35 -> 2 | P35: =AE19 -> Keith Micallef | Q35: 5 | R35: =IF(Q35>Q33,1,0) -> 0 | T35: 7 | U35: =IF(T35>T33,1,0) -> 1 | W35: 8 | X35: =IF(W35>W33,1,0) -> 0 | Y35: =IF(Q35="",0,1) -> 1 | Z35: =IF(R35+U35=2,3,IF(R35+U35=1,1,0)) -> 1 | AA35: =IF(Z35=3,3,IF(X35+Z35=2,2,IF(Z35=1,1,0))) -> 1 | AB35: =Q35+T35 -> 12 | AC35: =R35+U35+X35 -> 1
A37: =AE15 -> Jean Attard | B37: 6 | C37: =IF(B37>B39,1,0) -> 1 | E37: 6 | F37: =IF(E37>E39,1,0) -> 1 | I37: =IF(H37>H39,1,0) -> 0 | J37: =IF(B37="",0,1) -> 1 | K37: =IF(C37+F37=2,3,IF(C37+F37=1,1,0)) -> 3 | L37: =IF(K37=3,3,IF(I37+K37=2,2,IF(K37=1,1,0))) -> 3 | M37: =B37+E37 -> 12 | N37: =C37+F37+I37 -> 2
A38: vs.
A39: =AE17 -> Adrian Manduca | B39: 1 | C39: =IF(B39>B37,1,0) -> 0 | E39: 3 | F39: =IF(E39>E37,1,0) -> 0 | I39: =IF(H39>H37,1,0) -> 0 | J39: =IF(B39="",0,1) -> 1 | K39: =IF(C39+F39=2,3,IF(C39+F39=1,1,0)) -> 0 | L39: =IF(K39=3,3,IF(I39+K39=2,2,IF(K39=1,1,0))) -> 0 | M39: =B39+E39 -> 4 | N39: =C39+F39+I39 -> 0
A41: Division 1 - Group B
A43: Players | B43: Set Scores | H43: Tie | P43: Players | Q43: Set Scores | W43: Tie | AE43: Player | AF43: Games | AG43: Points | AH43: Games Won | AI43: Sets Won
B44: Score | C44: Set 1 Work | E44: Score | F44: Set 2 Work | H44: Score | I44: Tie Work | J44: Game Played | K44: Sets Points Work | L44: Sets & Tie Points Work | M44: Games Wins Work | N44: Sets Wins Work | Q44: Score | R44: Set 1 Work | T44: Score | U44: Set 2 Work | W44: Score | X44: Tie Work | Y44: Game Played | Z44: Sets Points Work | AA44: Sets & Tie Points Work | AB44: Games Wins Work | AC44: Sets Wins Work | AJ44: Winner Working | AK44: Total Games Work | AL44: Winner
A45: =AE45 -> Trevor Rutter | B45: 2 | C45: =IF(B45>B47,1,0) -> 0 | E45: 0 | F45: =IF(E45>E47,1,0) -> 0 | I45: =IF(H45>H47,1,0) -> 0 | J45: =IF(B45="",0,1) -> 1 | K45: =IF(C45+F45=2,3,IF(C45+F45=1,1,0)) -> 0 | L45: =IF(K45=3,3,IF(I45+K45=2,2,IF(K45=1,1,0))) -> 0 | M45: =B45+E45 -> 2 | N45: =C45+F45+I45 -> 0 | P45: =AE45 -> Trevor Rutter | Q45: 6 | R45: =IF(Q45>Q47,1,0) -> 1 | T45: 6 | U45: =IF(T45>T47,1,0) -> 1 | X45: =IF(W45>W47,1,0) -> 0 | Y45: =IF(Q45="",0,1) -> 1 | Z45: =IF(R45+U45=2,3,IF(R45+U45=1,1,0)) -> 3 | AA45: =IF(Z45=3,3,IF(X45+Z45=2,2,IF(Z45=1,1,0))) -> 3 | AB45: =Q45+T45 -> 12 | AC45: =R45+U45+X45 -> 2 | AE45: ='Players - Men'!E6 -> Trevor Rutter | AF45: =J45+Y45+J49+Y49+J53 -> 5 | AG45: =L45+AA45+L49+AA49+L53 -> 12 | AH45: =M45+AB45+M49+AB49+M53 -> 50 | AI45: =N45+AC45+N49+AC49+N53 -> 8 | AJ45: =MAX(AG45:AG55) -> 14 | AK45: =SUM(AF45:AF55) -> 30 | AL45: =IF(AG45=$AJ$45,AE45,IF(AG47=$AJ$45,AE47,IF(AG49=$AJ$45,AE49,IF(AG51=$AJ$45,AE51,IF(AG53=$AJ$45,AE53,IF(AG55=$AJ$45,AE55,"")))))) -> Matthew Pace
A46: vs. | P46: vs.
A47: =AE47 -> Matthew Pace | B47: 6 | C47: =IF(B47>B45,1,0) -> 1 | E47: 6 | F47: =IF(E47>E45,1,0) -> 1 | I47: =IF(H47>H45,1,0) -> 0 | J47: =IF(B47="",0,1) -> 1 | K47: =IF(C47+F47=2,3,IF(C47+F47=1,1,0)) -> 3 | L47: =IF(K47=3,3,IF(I47+K47=2,2,IF(K47=1,1,0))) -> 3 | M47: =B47+E47 -> 12 | N47: =C47+F47+I47 -> 2 | P47: =AE49 -> Andrew Pule' | Q47: 3 | R47: =IF(Q47>Q45,1,0) -> 0 | T47: 4 | U47: =IF(T47>T45,1,0) -> 0 | X47: =IF(W47>W45,1,0) -> 0 | Y47: =IF(Q47="",0,1) -> 1 | Z47: =IF(R47+U47=2,3,IF(R47+U47=1,1,0)) -> 0 | AA47: =IF(Z47=3,3,IF(X47+Z47=2,2,IF(Z47=1,1,0))) -> 0 | AB47: =Q47+T47 -> 7 | AC47: =R47+U47+X47 -> 0 | AE47: ='Players - Men'!E7 -> Matthew Pace | AF47: =J47+Y61+J61+Y57+J57 -> 5 | AG47: =L47+AA61+L61+AA57+L57 -> 14 | AH47: =M47+AB61+M61+AB57+M57 -> 60 | AI47: =N47+AC61+N61+AC57+N57 -> 10
A49: =AE45 -> Trevor Rutter | B49: 6 | C49: =IF(B49>B51,1,0) -> 1 | E49: 6 | F49: =IF(E49>E51,1,0) -> 1 | I49: =IF(H49>H51,1,0) -> 0 | J49: =IF(B49="",0,1) -> 1 | K49: =IF(C49+F49=2,3,IF(C49+F49=1,1,0)) -> 3 | L49: =IF(K49=3,3,IF(I49+K49=2,2,IF(K49=1,1,0))) -> 3 | M49: =B49+E49 -> 12 | N49: =C49+F49+I49 -> 2 | P49: =AE45 -> Trevor Rutter | Q49: 6 | R49: =IF(Q49>Q51,1,0) -> 1 | T49: 6 | U49: =IF(T49>T51,1,0) -> 1 | X49: =IF(W49>W51,1,0) -> 0 | Y49: =IF(Q49="",0,1) -> 1 | Z49: =IF(R49+U49=2,3,IF(R49+U49=1,1,0)) -> 3 | AA49: =IF(Z49=3,3,IF(X49+Z49=2,2,IF(Z49=1,1,0))) -> 3 | AB49: =Q49+T49 -> 12 | AC49: =R49+U49+X49 -> 2 | AE49: ='Players - Men'!E8 -> Andrew Pule' | AF49: =Y65+Y47+Y69+J69+J59 -> 5 | AG49: =AA65+AA47+AA69+L69+L59 -> 4 | AH49: =AB65+AB47+AB69+M69+M59 -> 35 | AI49: =AC65+AC47+AC69+N69+N59 -> 3
A50: vs. | P50: vs.
A51: =AE51 -> Fotios Evangelou | B51: 2 | C51: =IF(B51>B49,1,0) -> 0 | E51: 3 | F51: =IF(E51>E49,1,0) -> 0 | I51: =IF(H51>H49,1,0) -> 0 | J51: =IF(B51="",0,1) -> 1 | K51: =IF(C51+F51=2,3,IF(C51+F51=1,1,0)) -> 0 | L51: =IF(K51=3,3,IF(I51+K51=2,2,IF(K51=1,1,0))) -> 0 | M51: =B51+E51 -> 5 | N51: =C51+F51+I51 -> 0 | P51: =AE53 -> Marco Mercieca | Q51: 3 | R51: =IF(Q51>Q49,1,0) -> 0 | T51: 1 | U51: =IF(T51>T49,1,0) -> 0 | X51: =IF(W51>W49,1,0) -> 0 | Y51: =IF(Q51="",0,1) -> 1 | Z51: =IF(R51+U51=2,3,IF(R51+U51=1,1,0)) -> 0 | AA51: =IF(Z51=3,3,IF(X51+Z51=2,2,IF(Z51=1,1,0))) -> 0 | AB51: =Q51+T51 -> 4 | AC51: =R51+U51+X51 -> 0 | AE51: ='Players - Men'!E9 -> Fotios Evangelou | AF51: =Y67+J73+J51+Y59+J65 -> 5 | AG51: =AA67+L73+L51+AA59+L65 -> 5 | AH51: =AB67+M73+M51+AB59+M65 -> 34 | AI51: =AC67+N73+N51+AC59+N65 -> 4
A53: =AE45 -> Trevor Rutter | B53: 6 | C53: =IF(B53>B55,1,0) -> 1 | E53: 6 | F53: =IF(E53>E55,1,0) -> 1 | I53: =IF(H53>H55,1,0) -> 0 | J53: =IF(B53="",0,1) -> 1 | K53: =IF(C53+F53=2,3,IF(C53+F53=1,1,0)) -> 3 | L53: =IF(K53=3,3,IF(I53+K53=2,2,IF(K53=1,1,0))) -> 3 | M53: =B53+E53 -> 12 | N53: =C53+F53+I53 -> 2 | P53: =AE53 -> Marco Mercieca | Q53: 6 | R53: =IF(Q53>Q55,1,0) -> 1 | T53: 6 | U53: =IF(T53>T55,1,0) -> 1 | X53: =IF(W53>W55,1,0) -> 0 | Y53: =IF(Q53="",0,1) -> 1 | Z53: =IF(R53+U53=2,3,IF(R53+U53=1,1,0)) -> 3 | AA53: =IF(Z53=3,3,IF(X53+Z53=2,2,IF(Z53=1,1,0))) -> 3 | AB53: =Q53+T53 -> 12 | AC53: =R53+U53+X53 -> 2 | AE53: ='Players - Men'!E10 -> Marco Mercieca | AF53: =Y53+J75+J63+Y51+J71 -> 5 | AG53: =AA53+L75+L63+AA51+L71 -> 10 | AH53: =AB53+M75+M63+AB51+M71 -> 50 | AI53: =AC53+N75+N63+AC51+N71 -> 7
A54: vs. | P54: vs.
A55: =AE55 -> Daniel Falzon | B55: 1 | C55: =IF(B55>B53,1,0) -> 0 | E55: 2 | F55: =IF(E55>E53,1,0) -> 0 | I55: =IF(H55>H53,1,0) -> 0 | J55: =IF(B55="",0,1) -> 1 | K55: =IF(C55+F55=2,3,IF(C55+F55=1,1,0)) -> 0 | L55: =IF(K55=3,3,IF(I55+K55=2,2,IF(K55=1,1,0))) -> 0 | M55: =B55+E55 -> 3 | N55: =C55+F55+I55 -> 0 | P55: =AE55 -> Daniel Falzon | Q55: 1 | R55: =IF(Q55>Q53,1,0) -> 0 | T55: 1 | U55: =IF(T55>T53,1,0) -> 0 | X55: =IF(W55>W53,1,0) -> 0 | Y55: =IF(Q55="",0,1) -> 1 | Z55: =IF(R55+U55=2,3,IF(R55+U55=1,1,0)) -> 0 | AA55: =IF(Z55=3,3,IF(X55+Z55=2,2,IF(Z55=1,1,0))) -> 0 | AB55: =Q55+T55 -> 2 | AC55: =R55+U55+X55 -> 0 | AE55: ='Players - Men'!E11 -> Daniel Falzon | AF55: =Y55+Y63+Y71+J55+J67 -> 5 | AG55: =AA55+AA63+AA71+L55+L67 -> 0 | AH55: =AB55+AB63+AB71+M55+M67 -> 19 | AI55: =AC55+AC63+AC71+N55+N67 -> 0
...

Sheet Men Div 2
A1: Troy Shipping Agency Singles Tournament 2024
A5: Division 2 - Group A
A7: Players | B7: Set Scores | H7: Tie | P7: Players | Q7: Set Scores | W7: Tie | AE7: Player | AF7: Games | AG7: Points | AH7: Games Won | AI7: Sets Won
B8: Score | C8: Set 1 Work | E8: Score | F8: Set 2 Work | H8: Score | I8: Tie Work | J8: Game Played | K8: Sets Points Work | L8: Sets & Tie Points Work | M8: Games Wins Work | N8: Sets Wins Work | Q8: Score | R8: Set 1 Work | T8: Score | U8: Set 2 Work | W8: Score | X8: Tie Work | Y8: Game Played | Z8: Sets Points Work | AA8: Sets & Tie Points Work | AB8: Games Wins Work | AC8: Sets Wins Work | AJ8: Winner Working | AK8: Total Games Work | AL8: Winner
A9: =AE9 -> Andre' Farrugia | B9: 6 | C9: =IF(B9>B11,1,0) -> 1 | E9: 6 | F9: =IF(E9>E11,1,0) -> 1 | I9: =IF(H9>H11,1,0) -> 0 | J9: =IF(B9="",0,1) -> 1 | K9: =IF(C9+F9=2,3,IF(C9+F9=1,1,0)) -> 3 | L9: =IF(K9=3,3,IF(I9+K9=2,2,IF(K9=1,1,0))) -> 3 | M9: =B9+E9 -> 12 | N9: =C9+F9+I9 -> 2 | P9: =AE9 -> Andre' Farrugia | Q9: 6 | R9: =IF(Q9>Q11,1,0) -> 0 | T9: 6 | U9: =IF(T9>T11,1,0) -> 1 | W9: 14 | X9: =IF(W9>W11,1,0) -> 1 | Y9: =IF(Q9="",0,1) -> 1 | Z9: =IF(R9+U9=2,3,IF(R9+U9=1,1,0)) -> 1 | AA9: =IF(Z9=3,3,IF(X9+Z9=2,2,IF(Z9=1,1,0))) -> 2 | AB9: =Q9+T9 -> 12 | AC9: =R9+U9+X9 -> 2 | AE9: ='Players - Men'!B14 -> Andre' Farrugia | AF9: =J9+Y9+J13+Y13+J17 -> 5 | AG9: =L9+AA9+L13+AA13+L17 -> 12 | AH9: =M9+AB9+M13+AB13+M17 -> 53 | AI9: =N9+AC9+N13+AC13+N17 -> 10 | AJ9: =MAX(AG9:AG19) -> 12 | AK9: =SUM(AF9:AF19) -> 30 | AL9: =IF(AG9=$AJ$9,AE9,IF(AG11=$AJ$9,AE11,IF(AG13=$AJ$9,AE13,IF(AG15=$AJ$9,AE15,IF(AG17=$AJ$9,AE17,IF(AG19=$AJ$9,AE19,"")))))) -> Andre' Farrugia
A10: vs. | P10: vs.
A11: =AE11 -> Liam Dixon | B11: 3 | C11: =IF(B11>B9,1,0) -> 0 | E11: 2 | F11: =IF(E11>E9,1,0) -> 0 | I11: =IF(H11>H9,1,0) -> 0 | J11: =IF(B11="",0,1) -> 1 | K11: =IF(C11+F11=2,3,IF(C11+F11=1,1,0)) -> 0 | L11: =IF(K11=3,3,IF(I11+K11=2,2,IF(K11=1,1,0))) -> 0 | M11: =B11+E11 -> 5 | N11: =C11+F11+I11 -> 0 | P11: =AE13 -> Tobias Kristensen | Q11: 7 | R11: =IF(Q11>Q9,1,0) -> 1 | T11: 0 | U11: =IF(T11>T9,1,0) -> 0 | W11: 12 | X11: =IF(W11>W9,1,0) -> 0 | Y11: =IF(Q11="",0,1) -> 1 | Z11: =IF(R11+U11=2,3,IF(R11+U11=1,1,0)) -> 1 | AA11: =IF(Z11=3,3,IF(X11+Z11=2,2,IF(Z11=1,1,0))) -> 1 | AB11: =Q11+T11 -> 7 | AC11: =R11+U11+X11 -> 1 | AE11: ='Players - Men'!B15 -> Liam Dixon | AF11: =J11+Y25+J25+Y21+J21 -> 5 | AG11: =L11+AA25+L25+AA21+L21 -> 9 | AH11: =M11+AB25+M25+AB21+M21 -> 49 | AI11: =N11+AC25+N25+AC21+N21 -> 7
A13: =AE9 -> Andre' Farrugia | B13: 6 | C13: =IF(B13>B15,1,0) -> 1 | E13: 6 | F13: =IF(E13>E15,1,0) -> 1 | I13: =IF(H13>H15,1,0) -> 0 | J13: =IF(B13="",0,1) -> 1 | K13: =IF(C13+F13=2,3,IF(C13+F13=1,1,0)) -> 3 | L13: =IF(K13=3,3,IF(I13+K13=2,2,IF(K13=1,1,0))) -> 3 | M13: =B13+E13 -> 12 | N13: =C13+F13+I13 -> 2 | P13: =AE9 -> Andre' Farrugia | Q13: 6 | R13: =IF(Q13>Q15,1,0) -> 1 | T13: 2 | U13: =IF(T13>T15,1,0) -> 0 | W13: 11 | X13: =IF(W13>W15,1,0) -> 1 | Y13: =IF(Q13="",0,1) -> 1 | Z13: =IF(R13+U13=2,3,IF(R13+U13=1,1,0)) -> 1 | AA13: =IF(Z13=3,3,IF(X13+Z13=2,2,IF(Z13=1,1,0))) -> 2 | AB13: =Q13+T13 -> 8 | AC13: =R13+U13+X13 -> 2 | AE13: ='Players - Men'!B16 -> Tobias Kristensen | AF13: =Y29+Y11+Y33+J33+J23 -> 5 | AG13: =AA29+AA11+AA33+L33+L23 -> 6 | AH13: =AB29+AB11+AB33+M33+M23 -> 52 | AI13: =AC29+AC11+AC33+N33+N23 -> 6
A14: vs. | P14: vs.
A15: =AE15 -> Gabriel Pace | B15: 3 | C15: =IF(B15>B13,1,0) -> 0 | E15: 1 | F15: =IF(E15>E13,1,0) -> 0 | I15: =IF(H15>H13,1,0) -> 0 | J15: =IF(B15="",0,1) -> 1 | K15: =IF(C15+F15=2,3,IF(C15+F15=1,1,0)) -> 0 | L15: =IF(K15=3,3,IF(I15+K15=2,2,IF(K15=1,1,0))) -> 0 | M15: =B15+E15 -> 4 | N15: =C15+F15+I15 -> 0 | P15: =AE17 -> Chi Chi Canonce | Q15: 4 | R15: =IF(Q15>Q13,1,0) -> 0 | T15: 6 | U15: =IF(T15>T13,1,0) -> 1 | W15: 9 | X15: =IF(W15>W13,1,0) -> 0 | Y15: =IF(Q15="",0,1) -> 1 | Z15: =IF(R15+U15=2,3,IF(R15+U15=1,1,0)) -> 1 | AA15: =IF(Z15=3,3,IF(X15+Z15=2,2,IF(Z15=1,1,0))) -> 1 | AB15: =Q15+T15 -> 10 | AC15: =R15+U15+X15 -> 1 | AE15: ='Players - Men'!B17 -> Gabriel Pace | AF15: =Y31+J37+J15+Y23+J29 -> 5 | AG15: =AA31+L37+L15+AA23+L29 -> 3 | AH15: =AB31+M37+M15+AB23+M29 -> 37 | AI15: =AC31+N37+N15+AC23+N29 -> 3
A17: =AE9 -> Andre' Farrugia | B17: 6 | C17: =IF(B17>B19,1,0) -> 1 | E17: 3 | F17: =IF(E17>E19,1,0) -> 0 | H17: 10 | I17: =IF(H17>H19,1,0) -> 1 | J17: =IF(B17="",0,1) -> 1 | K17: =IF(C17+F17=2,3,IF(C17+F17=1,1,0)) -> 1 | L17: =IF(K17=3,3,IF(I17+K17=2,2,IF(K17=1,1,0))) -> 2 | M17: =B17+E17 -> 9 | N17: =C17+F17+I17 -> 2 | P17: =AE17 -> Chi Chi Canonce | Q17: 4 | R17: =IF(Q17>Q19,1,0) -> 0 | T17: 6 | U17: =IF(T17>T19,1,0) -> 1 | W17: 10 | X17: =IF(W17>W19,1,0) -> 1 | Y17: =IF(Q17="",0,1) -> 1 | Z17: =IF(R17+U17=2,3,IF(R17+U17=1,1,0)) -> 1 | AA17: =IF(Z17=3,3,IF(X17+Z17=2,2,IF(Z17=1,1,0))) -> 2 | AB17: =Q17+T17 -> 10 | AC17: =R17+U17+X17 -> 2 | AE17: ='Players - Men'!B18 -> Chi Chi Canonce | AF17: =Y17+J39+J27+Y15+J35 -> 5 | AG17: =AA17+L39+L27+AA15+L35 -> 10 | AH17: =AB17+M39+M27+AB15+M35 -> 51 | AI17: =AC17+N39+N27+AC15+N35 -> 9
A18: vs. | P18: vs.
A19: =AE19 -> Eric Micallef | B19: 1 | C19: =IF(B19>B17,1,0) -> 0 | E19: 6 | F19: =IF(E19>E17,1,0) -> 1 | H19: 4 | I19: =IF(H19>H17,1,0) -> 0 | J19: =IF(B19="",0,1) -> 1 | K19: =IF(C19+F19=2,3,IF(C19+F19=1,1,0)) -> 1 | L19: =IF(K19=3,3,IF(I19+K19=2,2,IF(K19=1,1,0))) -> 1 | M19: =B19+E19 -> 7 | N19: =C19+F19+I19 -> 1 | P19: =AE19 -> Eric Micallef | Q19: 6 | R19: =IF(Q19>Q17,1,0) -> 1 | T19: 3 | U19: =IF(T19>T17,1,0) -> 0 | W19: 4 | X19: =IF(W19>W17,1,0) -> 0 | Y19: =IF(Q19="",0,1) -> 1 | Z19: =IF(R19+U19=2,3,IF(R19+U19=1,1,0)) -> 1 | AA19: =IF(Z19=3,3,IF(X19+Z19=2,2,IF(Z19=1,1,0))) -> 1 | AB19: =Q19+T19 -> 9 | AC19: =R19+U19+X19 -> 1 | AE19: ='Players - Men'!B19 -> Eric Micallef | AF19: =Y19+Y27+Y35+J19+J31 -> 5 | AG19: =AA19+AA35+L31+AA27+L19 -> 5 | AH19: =AB19+AB27+AB35+M19+M31 -> 47 | AI19: =AC19+AC27+AC35+N19+N31 -> 5
A21: =AE11 -> Liam Dixon | B21: 4 | C21: =IF(B21>B23,1,0) -> 0 | E21: 6 | F21: =IF(E21>E23,1,0) -> 1 | H21: 10 | I21: =IF(H21>H23,1,0) -> 1 | J21: =IF(B21="",0,1) -> 1 | K21: =IF(C21+F21=2,3,IF(C21+F21=1,1,0)) -> 1 | L21: =IF(K21=3,3,IF(I21+K21=2,2,IF(K21=1,1,0))) -> 2 | M21: =B21+E21 -> 10 | N21: =C21+F21+I21 -> 2 | P21: =AE11 -> Liam Dixon | Q21: 6 | R21: =IF(Q21>Q23,1,0) -> 1 | T21: 6 | U21: =IF(T21>T23,1,0) -> 1 | X21: =IF(W21>W23,1,0) -> 0 | Y21: =IF(Q21="",0,1) -> 1 | Z21: =IF(R21+U21=2,3,IF(R21+U21=1,1,0)) -> 3 | AA21: =IF(Z21=3,3,IF(X21+Z21=2,2,IF(Z21=1,1,0))) -> 3 | AB21: =Q21+T21 -> 12 | AC21: =R21+U21+X21 -> 2 | AE21: Group A Winner
A22: vs. | P22: vs. | AE22: Andre' Farrugia
A23: =AE13 -> Tobias Kristensen | B23: 6 | C23: =IF(B23>B21,1,0) -> 1 | E23: 4 | F23: =IF(E23>E21,1,0) -> 0 | H23: 5 | I23: =IF(H23>H21,1,0) -> 0 | J23: =IF(B23="",0,1) -> 1 | K23: =IF(C23+F23=2,3,IF(C23+F23=1,1,0)) -> 1 | L23: =IF(K23=3,3,IF(I23+K23=2,2,IF(K23=1,1,0))) -> 1 | M23: =B23+E23 -> 10 | N23: =C23+F23+I23 -> 1 | P23: =AE15 -> Gabriel Pace | Q23: 3 | R23: =IF(Q23>Q21,1,0) -> 0 | T23: 4 | U23: =IF(T23>T21,1,0) -> 0 | X23: =IF(W23>W21,1,0) -> 0 | Y23: =IF(Q23="",0,1) -> 1 | Z23: =IF(R23+U23=2,3,IF(R23+U23=1,1,0)) -> 0 | AA23: =IF(Z23=3,3,IF(X23+Z23=2,2,IF(Z23=1,1,0))) -> 0 | AB23: =Q23+T23 -> 7 | AC23: =R23+U23+X23 -> 0
A25: =AE11 -> Liam Dixon | B25: 4 | C25: =IF(B25>B27,1,0) -> 0 | E25: 6 | F25: =IF(E25>E27,1,0) -> 1 | H25: 8 | I25: =IF(H25>H27,1,0) -> 0 | J25: =IF(B25="",0,1) -> 1 | K25: =IF(C25+F25=2,3,IF(C25+F25=1,1,0)) -> 1 | L25: =IF(K25=3,3,IF(I25+K25=2,2,IF(K25=1,1,0))) -> 1 | M25: =B25+E25 -> 10 | N25: =C25+F25+I25 -> 1 | P25: =AE11 -> Liam Dixon | Q25: 6 | R25: =IF(Q25>Q27,1,0) -> 1 | T25: 6 | U25: =IF(T25>T27,1,0) -> 1 | X25: =IF(W25>W27,1,0) -> 0 | Y25: =IF(Q25="",0,1) -> 1 | Z25: =IF(R25+U25=2,3,IF(R25+U25=1,1,0)) -> 3 | AA25: =IF(Z25=3,3,IF(X25+Z25=2,2,IF(Z25=1,1,0))) -> 3 | AB25: =Q25+T25 -> 12 | AC25: =R25+U25+X25 -> 2
A26: vs. | P26: vs.
A27: =AE17 -> Chi Chi Canonce | B27: 6 | C27: =IF(B27>B25,1,0) -> 1 | E27: 3 | F27: =IF(E27>E25,1,0) -> 0 | H27: 10 | I27: =IF(H27>H25,1,0) -> 1 | J27: =IF(B27="",0,1) -> 1 | K27: =IF(C27+F27=2,3,IF(C27+F27=1,1,0)) -> 1 | L27: =IF(K27=3,3,IF(I27+K27=2,2,IF(K27=1,1,0))) -> 2 | M27: =B27+E27 -> 9 | N27: =C27+F27+I27 -> 2 | P27: =AE19 -> Eric Micallef | Q27: 3 | R27: =IF(Q27>Q25,1,0) -> 0 | T27: 3 | U27: =IF(T27>T25,1,0) -> 0 | X27: =IF(W27>W25,1,0) -> 0 | Y27: =IF(Q27="",0,1) -> 1 | Z27: =IF(R27+U27=2,3,IF(R27+U27=1,1,0)) -> 0 | AA27: =IF(Z27=3,3,IF(X27+Z27=2,2,IF(Z27=1,1,0))) -> 0 | AB27: =Q27+T27 -> 6 | AC27: =R27+U27+X27 -> 0
A29: =AE15 -> Gabriel Pace | B29: 7 | C29: =IF(B29>B31,1,0) -> 1 | E29: 1 | F29: =IF(E29>E31,1,0) -> 0 | H29: 6 | I29: =IF(H29>H31,1,0) -> 0 | J29: =IF(B29="",0,1) -> 1 | K29: =IF(C29+F29=2,3,IF(C29+F29=1,1,0)) -> 1 | L29: =IF(K29=3,3,IF(I29+K29=2,2,IF(K29=1,1,0))) -> 1 | M29: =B29+E29 -> 8 | N29: =C29+F29+I29 -> 1 | P29: =AE13 -> Tobias Kristensen | Q29: 4 | R29: =IF(Q29>Q31,1,0) -> 0 | T29: 6 | U29: =IF(T29>T31,1,0) -> 1 | W29: 10 | X29: =IF(W29>W31,1,0) -> 1 | Y29: =IF(Q29="",0,1) -> 1 | Z29: =IF(R29+U29=2,3,IF(R29+U29=1,1,0)) -> 1 | AA29: =IF(Z29=3,3,IF(X29+Z29=2,2,IF(Z29=1,1,0))) -> 2 | AB29: =Q29+T29 -> 10 | AC29: =R29+U29+X29 -> 2
A30: vs. | P30: vs.
A31: =AE19 -> Eric Micallef | B31: 6 | C31: =IF(B31>B29,1,0) -> 0 | E31: 6 | F31: =IF(E31>E29,1,0) -> 1 | H31: 10 | I31: =IF(H31>H29,1,0) -> 1 | J31: =IF(B31="",0,1) -> 1 | K31: =IF(C31+F31=2,3,IF(C31+F31=1,1,0)) -> 1 | L31: =IF(K31=3,3,IF(I31+K31=2,2,IF(K31=1,1,0))) -> 2 | M31: =B31+E31 -> 12 | N31: =C31+F31+I31 -> 2 | P31: =AE15 -> Gabriel Pace | Q31: 6 | R31: =IF(Q31>Q29,1,0) -> 1 | T31: 3 | U31: =IF(T31>T29,1,0) -> 0 | W31: 1 | X31: =IF(W31>W29,1,0) -> 0 | Y31: =IF(Q31="",0,1) -> 1 | Z31: =IF(R31+U31=2,3,IF(R31+U31=1,1,0)) -> 1 | AA31: =IF(Z31=3,3,IF(X31+Z31=2,2,IF(Z31=1,1,0))) -> 1 | AB31: =Q31+T31 -> 9 | AC31: =R31+U31+X31 -> 1
A33: =AE13 -> Tobias Kristensen | B33: 6 | C33: =IF(B33>B35,1,0) -> 0 | E33: 6 | F33: =IF(E33>E35,1,0) -> 0 | I33: =IF(H33>H35,1,0) -> 0 | J33: =IF(B33="",0,1) -> 1 | K33: =IF(C33+F33=2,3,IF(C33+F33=1,1,0)) -> 0 | L33: =IF(K33=3,3,IF(I33+K33=2,2,IF(K33=1,1,0))) -> 0 | M33: =B33+E33 -> 12 | N33: =C33+F33+I33 -> 0 | P33: =AE13 -> Tobias Kristensen | Q33: 6 | R33: =IF(Q33>Q35,1,0) -> 0 | T33: 7 | U33: =IF(T33>T35,1,0) -> 1 | W33: 10 | X33: =IF(W33>W35,1,0) -> 1 | Y33: =IF(Q33="",0,1) -> 1 | Z33: =IF(R33+U33=2,3,IF(R33+U33=1,1,0)) -> 1 | AA33: =IF(Z33=3,3,IF(X33+Z33=2,2,IF(Z33=1,1,0))) -> 2 | AB33: =Q33+T33 -> 13 | AC33: =R33+U33+X33 -> 2
A34: vs. | P34: vs.
A35: =AE17 -> Chi Chi Canonce | B35: 7 | C35: =IF(B35>B33,1,0) -> 1 | E35: 7 | F35: =IF(E35>E33,1,0) -> 1 | I35: =IF(H35>H33,1,0) -> 0 | J35: =IF(B35="",0,1) -> 1 | K35: =IF(C35+F35=2,3,IF(C35+F35=1,1,0)) -> 3 | L35: =IF(K35=3,3,IF(I35+K35=2,2,IF(K35=1,1,0))) -> 3 | M35: =B35+E35 -> 14 | N35: =C35+F35+I35 -> 2 | P35: =AE19 -> Eric Micallef | Q35: 7 | R35: =IF(Q35>Q33,1,0) -> 1 | T35: 6 | U35: =IF(T35>T33,1,0) -> 0 | W35: 5 | X35: =IF(W35>W33,1,0) -> 0 | Y35: =IF(Q35="",0,1) -> 1 | Z35: =IF(R35+U35=2,3,IF(R35+U35=1,1,0)) -> 1 | AA35: =IF(Z35=3,3,IF(X35+Z35=2,2,IF(Z35=1,1,0))) -> 1 | AB35: =Q35+T35 -> 13 | AC35: =R35+U35+X35 -> 1
A37: =AE15 -> Gabriel Pace | B37: 3 | C37: =IF(B37>B39,1,0) -> 0 | E37: 6 | F37: =IF(E37>E39,1,0) -> 1 | H37: 4 | I37: =IF(H37>H39,1,0) -> 0 | J37: =IF(B37="",0,1) -> 1 | K37: =IF(C37+F37=2,3,IF(C37+F37=1,1,0)) -> 1 | L37: =IF(K37=3,3,IF(I37+K37=2,2,IF(K37=1,1,0))) -> 1 | M37: =B37+E37 -> 9 | N37: =C37+F37+I37 -> 1
A38: vs.
A39: =AE17 -> Chi Chi Canonce | B39: 6 | C39: =IF(B39>B37,1,0) -> 1 | E39: 2 | F39: =IF(E39>E37,1,0) -> 0 | H39: 10 | I39: =IF(H39>H37,1,0) -> 1 | J39: =IF(B39="",0,1) -> 1 | K39: =IF(C39+F39=2,3,IF(C39+F39=1,1,0)) -> 1 | L39: =IF(K39=3,3,IF(I39+K39=2,2,IF(K39=1,1,0))) -> 2 | M39: =B39+E39 -> 8 | N39: =C39+F39+I39 -> 2
A41: Division 2 - Group B
A43: Players | B43: Set Scores | H43: Tie | P43: Players | Q43: Set Scores | W43: Tie | AE43: Player | AF43: Games | AG43: Points | AH43: Games Won | AI43: Sets Won
B44: Score | C44: Set 1 Work | E44: Score | F44: Set 2 Work | H44: Score | I44: Tie Work | J44: Game Played | K44: Sets Points Work | L44: Sets & Tie Points Work | M44: Games Wins Work | N44: Sets Wins Work | Q44: Score | R44: Set 1 Work | T44: Score | U44: Set 2 Work | W44: Score | X44: Tie Work | Y44: Game Played | Z44: Sets Points Work | AA44: Sets & Tie Points Work | AB44: Games Wins Work | AC44: Sets Wins Work | AJ44: Winner Working | AK44: Total Games Work | AL44: Winner
A45: =AE45 -> Roderick Spiteri | B45: 1 | C45: =IF(B45>B47,1,0) -> 0 | E45: 3 | F45: =IF(E45>E47,1,0) -> 0 | I45: =IF(H45>H47,1,0) -> 0 | J45: =IF(B45="",0,1) -> 1 | K45: =IF(C45+F45=2,3,IF(C45+F45=1,1,0)) -> 0 | L45: =IF(K45=3,3,IF(I45+K45=2,2,IF(K45=1,1,0))) -> 0 | M45: =B45+E45 -> 4 | N45: =C45+F45+I45 -> 0 | P45: =AE45 -> Roderick Spiteri | Q45: 2 | R45: =IF(Q45>Q47,1,0) -> 0 | T45: 6 | U45: =IF(T45>T47,1,0) -> 1 | W45: 8 | X45: =IF(W45>W47,1,0) -> 0 | Y45: =IF(Q45="",0,1) -> 1 | Z45: =IF(R45+U45=2,3,IF(R45+U45=1,1,0)) -> 1 | AA45: =IF(Z45=3,3,IF(X45+Z45=2,2,IF(Z45=1,1,0))) -> 1 | AB45: =Q45+T45 -> 8 | AC45: =R45+U45+X45 -> 1 | AE45: ='Players - Men'!E14 -> Roderick Spiteri | AF45: =J45+Y45+J49+Y49+J53 -> 5 | AG45: =L45+AA45+L49+AA49+L53 -> 1 | AH45: =M45+AB45+M49+AB49+M53 -> 25 | AI45: =N45+AC45+N49+AC49+N53 -> 1 | AJ45: =MAX(AG45:AG55) -> 13 | AK45: =SUM(AF45:AF55) -> 30 | AL45: =IF(AG45=$AJ$45,AE45,IF(AG47=$AJ$45,AE47,IF(AG49=$AJ$45,AE49,IF(AG51=$AJ$45,AE51,IF(AG53=$AJ$45,AE53,IF(AG55=$AJ$45,AE55,"")))))) -> Daniel Farrugia
A46: vs. | P46: vs.
A47: =AE47 -> Daniel Farrugia | B47: 6 | C47: =IF(B47>B45,1,0) -> 1 | E47: 6 | F47: =IF(E47>E45,1,0) -> 1 | I47: =IF(H47>H45,1,0) -> 0 | J47: =IF(B47="",0,1) -> 1 | K47: =IF(C47+F47=2,3,IF(C47+F47=1,1,0)) -> 3 | L47: =IF(K47=3,3,IF(I47+K47=2,2,IF(K47=1,1,0))) -> 3 | M47: =B47+E47 -> 12 | N47: =C47+F47+I47 -> 2 | P47: =AE49 -> Georges Meekers | Q47: 6 | R47: =IF(Q47>Q45,1,0) -> 1 | T47: 2 | U47: =IF(T47>T45,1,0) -> 0 | W47: 10 | X47: =IF(W47>W45,1,0) -> 1 | Y47: =IF(Q47="",0,1) -> 1 | Z47: =IF(R47+U47=2,3,IF(R47+U47=1,1,0)) -> 1 | AA47: =IF(Z47=3,3,IF(X47+Z47=2,2,IF(Z47=1,1,0))) -> 2 | AB47: =Q47+T47 -> 8 | AC47: =R47+U47+X47 -> 2 | AE47: ='Players - Men'!E15 -> Daniel Farrugia | AF47: =J47+Y61+J61+Y57+J57 -> 5 | AG47: =L47+AA61+L61+AA57+L57 -> 13 | AH47: =M47+AB61+M61+AB57+M57 -> 57 | AI47: =N47+AC61+N61+AC57+N57 -> 10
A49: =AE45 -> Roderick Spiteri | B49: 3 | C49: =IF(B49>B51,1,0) -> 0 | E49: 5 | F49: =IF(E49>E51,1,0) -> 0 | I49: =IF(H49>H51,1,0) -> 0 | J49: =IF(B49="",0,1) -> 1 | K49: =IF(C49+F49=2,3,IF(C49+F49=1,1,0)) -> 0 | L49: =IF(K49=3,3,IF(I49+K49=2,2,IF(K49=1,1,0))) -> 0 | M49: =B49+E49 -> 8 | N49: =C49+F49+I49 -> 0 | P49: =AE45 -> Roderick Spiteri | Q49: 1 | R49: =IF(Q49>Q51,1,0) -> 0 | T49: 2 | U49: =IF(T49>T51,1,0) -> 0 | X49: =IF(W49>W51,1,0) -> 0 | Y49: =IF(Q49="",0,1) -> 1 | Z49: =IF(R49+U49=2,3,IF(R49+U49=1,1,0)) -> 0 | AA49: =IF(Z49=3,3,IF(X49+Z49=2,2,IF(Z49=1,1,0))) -> 0 | AB49: =Q49+T49 -> 3 | AC49: =R49+U49+X49 -> 0 | AE49: ='Players - Men'!E16 -> Georges Meekers | AF49: =Y65+Y47+Y69+J69+J59 -> 5 | AG49: =AA65+AA47+AA69+L69+L59 -> 2 | AH49: =AB65+AB47+AB69+M69+M59 -> 28 | AI49: =AC65+AC47+AC69+N69+N59 -> 2
A50: vs. | P50: vs.
A51: =AE51 -> Jay Boy Lastimosa | B51: 6 | C51: =IF(B51>B49,1,0) -> 1 | E51: 7 | F51: =IF(E51>E49,1,0) -> 1 | I51: =IF(H51>H49,1,0) -> 0 | J51: =IF(B51="",0,1) -> 1 | K51: =IF(C51+F51=2,3,IF(C51+F51=1,1,0)) -> 3 | L51: =IF(K51=3,3,IF(I51+K51=2,2,IF(K51=1,1,0))) -> 3 | M51: =B51+E51 -> 13 | N51: =C51+F51+I51 -> 2 | P51: =AE53 -> Emman Xuereb | Q51: 6 | R51: =IF(Q51>Q49,1,0) -> 1 | T51: 6 | U51: =IF(T51>T49,1,0) -> 1 | X51: =IF(W51>W49,1,0) -> 0 | Y51: =IF(Q51="",0,1) -> 1 | Z51: =IF(R51+U51=2,3,IF(R51+U51=1,1,0)) -> 3 | AA51: =IF(Z51=3,3,IF(X51+Z51=2,2,IF(Z51=1,1,0))) -> 3 | AB51: =Q51+T51 -> 12 | AC51: =R51+U51+X51 -> 2 | AE51: ='Players - Men'!E17 -> Jay Boy Lastimosa | AF51: =Y67+J73+J51+Y59+J65 -> 5 | AG51: =AA67+L73+L51+AA59+L65 -> 9 | AH51: =AB67+M73+M51+AB59+M65 -> 52 | AI51: =AC67+N73+N51+AC59+N65 -> 6
A53: =AE45 -> Roderick Spiteri | B53: 1 | C53: =IF(B53>B55,1,0) -> 0 | E53: 1 | F53: =IF(E53>E55,1,0) -> 0 | I53: =IF(H53>H55,1,0) -> 0 | J53: =IF(B53="",0,1) -> 1 | K53: =IF(C53+F53=2,3,IF(C53+F53=1,1,0)) -> 0 | L53: =IF(K53=3,3,IF(I53+K53=2,2,IF(K53=1,1,0))) -> 0 | M53: =B53+E53 -> 2 | N53: =C53+F53+I53 -> 0 | P53: =AE53 -> Emman Xuereb | Q53: 6 | R53: =IF(Q53>Q55,1,0) -> 1 | T53: 6 | U53: =IF(T53>T55,1,0) -> 1 | X53: =IF(W53>W55,1,0) -> 0 | Y53: =IF(Q53="",0,1) -> 1 | Z53: =IF(R53+U53=2,3,IF(R53+U53=1,1,0)) -> 3 | AA53: =IF(Z53=3,3,IF(X53+Z53=2,2,IF(Z53=1,1,0))) -> 3 | AB53: =Q53+T53 -> 12 | AC53: =R53+U53+X53 -> 2 | AE53: ='Players - Men'!E18 -> Emman Xuereb | AF53: =Y53+J75+J63+Y51+J71 -> 5 | AG53: =AA53+L75+L63+AA51+L71 -> 13 | AH53: =AB53+M75+M63+AB51+M71 -> 56 | AI53: =AC53+N75+N63+AC51+N71 -> 9
A54: vs. | P54: vs.
A55: =AE55 -> Cyril Lastimosa | B55: 6 | C55: =IF(B55>B53,1,0) -> 1 | E55: 6 | F55: =IF(E55>E53,1,0) -> 1 | I55: =IF(H55>H53,1,0) -> 0 | J55: =IF(B55="",0,1) -> 1 | K55: =IF(C55+F55=2,3,IF(C55+F55=1,1,0)) -> 3 | L55: =IF(K55=3,3,IF(I55+K55=2,2,IF(K55=1,1,0))) -> 3 | M55: =B55+E55 -> 12 | N55: =C55+F55+I55 -> 2 | P55: =AE55 -> Cyril Lastimosa | Q55: 3 | R55: =IF(Q55>Q53,1,0) -> 0 | T55: 2 | U55: =IF(T55>T53,1,0) -> 0 | X55: =IF(W55>W53,1,0) -> 0 | Y55: =IF(Q55="",0,1) -> 1 | Z55: =IF(R55+U55=2,3,IF(R55+U55=1,1,0)) -> 0 | AA55: =IF(Z55=3,3,IF(X55+Z55=2,2,IF(Z55=1,1,0))) -> 0 | AB55: =Q55+T55 -> 5 | AC55: =R55+U55+X55 -> 0 | AE55: ='Players - Men'!E19 -> Cyril Lastimosa | AF55: =Y55+Y63+Y71+J55+J67 -> 5 | AG55: =AA55+AA63+AA71+L55+L67 -> 7 | AH55: =AB55+AB63+AB71+M55+M67 -> 48 | AI55: =AC55+AC63+AC71+N55+N67 -> 5
...

Sheet Men Div 3
A1: Troy Shipping Agency Singles Tournament 2024
A5: Men Division 3
A7: Players | B7: Set Scores | H7: Tie | P7: Players | Q7: Set Scores | W7: Tie | AE7: Player | AF7: Games | AG7: Points | AH7: Games Won | AI7: Sets Won
B8: Score | C8: Set 1 Work | E8: Score | F8: Set 2 Work | H8: Score | I8: Tie Work | J8: Game Played | K8: Sets Points Work | L8: Sets & Tie Points Work | M8: Games Wins Work | N8: Sets Wins Work | Q8: Score | R8: Set 1 Work | T8: Score | U8: Set 2 Work | W8: Score | X8: Tie Work | Y8: Game Played | Z8: Sets Points Work | AA8: Sets & Tie Points Work | AB8: Games Wins Work | AC8: Sets Wins Work | AJ8: Winner Working | AK8: Runner Up Working | AL8: Total Games Work | AM8: Winner | AN8: Runner Up
A9: =AE9 -> Mavric Sawyer | B9: 6 | C9: =IF(B9>B11,1,0) -> 1 | E9: 5 | F9: =IF(E9>E11,1,0) -> 0 | H9: 8 | I9: =IF(H9>H11,1,0) -> 0 | J9: =IF(B9="",0,1) -> 1 | K9: =IF(C9+F9=2,3,IF(C9+F9=1,1,0)) -> 1 | L9: =IF(K9=3,3,IF(I9+K9=2,2,IF(K9=1,1,0))) -> 1 | M9: =B9+E9 -> 11 | N9: =C9+F9+I9 -> 1 | P9: =AE9 -> Mavric Sawyer | Q9: 2 | R9: =IF(Q9>Q11,1,0) -> 0 | T9: 2 | U9: =IF(T9>T11,1,0) -> 0 | X9: =IF(W9>W11,1,0) -> 0 | Y9: =IF(Q9="",0,1) -> 1 | Z9: =IF(R9+U9=2,3,IF(R9+U9=1,1,0)) -> 0 | AA9: =IF(Z9=3,3,IF(X9+Z9=2,2,IF(Z9=1,1,0))) -> 0 | AB9: =Q9+T9 -> 4 | AC9: =R9+U9+X9 -> 0 | AE9: ='Players - Men'!B22 -> Mavric Sawyer | AF9: =J9+Y9+J13+Y13+J17 -> 5 | AG9: =L9+AA9+L13+AA13+L17 -> 9 | AH9: =M9+AB9+M13+AB13+M17 -> 48 | AI9: =N9+AC9+N13+AC13+N17 -> 7 | AJ9: =MAX(AG9:AG19) -> 13 | AK9: =LARGE(AG9:AG19, 2) -> 12 | AL9: =SUM(AF9:AF19) -> 30 | AM9: =IF(AG9=$AJ$9,AE9,IF(AG11=$AJ$9,AE11,IF(AG13=$AJ$9,AE13,IF(AG15=$AJ$9,AE15,IF(AG17=$AJ$9,AE17,""))))) -> Kristen Cachia | AN9: =IF(AG9=$AK$9,AE9,IF(AG11=$AK$9,AE11,IF(AG13=$AK$9,AE13,IF(AG15=$AK$9,AE15,IF(AG17=$AK$9,AE17,""))))) -> Denis Caruana
A10: vs. | P10: vs.
A11: =AE11 -> Artiom Kiricenko | B11: 3 | C11: =IF(B11>B9,1,0) -> 0 | E11: 7 | F11: =IF(E11>E9,1,0) -> 1 | H11: 10 | I11: =IF(H11>H9,1,0) -> 1 | J11: =IF(B11="",0,1) -> 1 | K11: =IF(C11+F11=2,3,IF(C11+F11=1,1,0)) -> 1 | L11: =IF(K11=3,3,IF(I11+K11=2,2,IF(K11=1,1,0))) -> 2 | M11: =B11+E11 -> 10 | N11: =C11+F11+I11 -> 2 | P11: =AE13 -> Kristen Cachia | Q11: 6 | R11: =IF(Q11>Q9,1,0) -> 1 | T11: 6 | U11: =IF(T11>T9,1,0) -> 1 | X11: =IF(W11>W9,1,0) -> 0 | Y11: =IF(Q11="",0,1) -> 1 | Z11: =IF(R11+U11=2,3,IF(R11+U11=1,1,0)) -> 3 | AA11: =IF(Z11=3,3,IF(X11+Z11=2,2,IF(Z11=1,1,0))) -> 3 | AB11: =Q11+T11 -> 12 | AC11: =R11+U11+X11 -> 2 | AE11: ='Players - Men'!B23 -> Artiom Kiricenko | AF11: =J11+Y25+J25+Y21+J21 -> 5 | AG11: =L11+AA25+L25+AA21+L21 -> 7 | AH11: =M11+AB25+M25+AB21+M21 -> 37 | AI11: =N11+AC25+N25+AC21+N21 -> 6
A13: =AE9 -> Mavric Sawyer | B13: 6 | C13: =IF(B13>B15,1,0) -> 1 | E13: 3 | F13: =IF(E13>E15,1,0) -> 0 | H13: 10 | I13: =IF(H13>H15,1,0) -> 1 | J13: =IF(B13="",0,1) -> 1 | K13: =IF(C13+F13=2,3,IF(C13+F13=1,1,0)) -> 1 | L13: =IF(K13=3,3,IF(I13+K13=2,2,IF(K13=1,1,0))) -> 2 | M13: =B13+E13 -> 9 | N13: =C13+F13+I13 -> 2 | P13: =AE9 -> Mavric Sawyer | Q13: 6 | R13: =IF(Q13>Q15,1,0) -> 1 | T13: 6 | U13: =IF(T13>T15,1,0) -> 1 | X13: =IF(W13>W15,1,0) -> 0 | Y13: =IF(Q13="",0,1) -> 1 | Z13: =IF(R13+U13=2,3,IF(R13+U13=1,1,0)) -> 3 | AA13: =IF(Z13=3,3,IF(X13+Z13=2,2,IF(Z13=1,1,0))) -> 3 | AB13: =Q13+T13 -> 12 | AC13: =R13+U13+X13 -> 2 | AE13: ='Players - Men'!B24 -> Kristen Cachia | AF13: =Y29+Y11+Y33+J33+J23 -> 5 | AG13: =AA29+AA11+AA33+L33+L23 -> 13 | AH13: =AB29+AB11+AB33+M33+M23 -> 57 | AI13: =AC29+AC11+AC33+N33+N23 -> 9
A14: vs. | P14: vs.
A15: =AE15 -> Denis Caruana | B15: 2 | C15: =IF(B15>B13,1,0) -> 0 | E15: 6 | F15: =IF(E15>E13,1,0) -> 1 | H15: 4 | I15: =IF(H15>H13,1,0) -> 0 | J15: =IF(B15="",0,1) -> 1 | K15: =IF(C15+F15=2,3,IF(C15+F15=1,1,0)) -> 1 | L15: =IF(K15=3,3,IF(I15+K15=2,2,IF(K15=1,1,0))) -> 1 | M15: =B15+E15 -> 8 | N15: =C15+F15+I15 -> 1 | P15: =AE17 -> Ryan Ebejer | Q15: 1 | R15: =IF(Q15>Q13,1,0) -> 0 | T15: 2 | U15: =IF(T15>T13,1,0) -> 0 | X15: =IF(W15>W13,1,0) -> 0 | Y15: =IF(Q15="",0,1) -> 1 | Z15: =IF(R15+U15=2,3,IF(R15+U15=1,1,0)) -> 0 | AA15: =IF(Z15=3,3,IF(X15+Z15=2,2,IF(Z15=1,1,0))) -> 0 | AB15: =Q15+T15 -> 3 | AC15: =R15+U15+X15 -> 0 | AE15: ='Players - Men'!B25 -> Denis Caruana | AF15: =Y31+J37+J15+Y23+J29 -> 5 | AG15: =AA31+L37+L15+AA23+L29 -> 12 | AH15: =AB31+M37+M15+AB23+M29 -> 52 | AI15: =AC31+N37+N15+AC23+N29 -> 9
A17: =AE9 -> Mavric Sawyer | B17: 6 | C17: =IF(B17>B19,1,0) -> 1 | E17: 6 | F17: =IF(E17>E19,1,0) -> 1 | I17: =IF(H17>H19,1,0) -> 0 | J17: =IF(B17="",0,1) -> 1 | K17: =IF(C17+F17=2,3,IF(C17+F17=1,1,0)) -> 3 | L17: =IF(K17=3,3,IF(I17+K17=2,2,IF(K17=1,1,0))) -> 3 | M17: =B17+E17 -> 12 | N17: =C17+F17+I17 -> 2 | P17: =AE17 -> Ryan Ebejer | Q17: 4 | R17: =IF(Q17>Q19,1,0) -> 0 | T17: 6 | U17: =IF(T17>T19,1,0) -> 1 | W17: 10 | X17: =IF(W17>W19,1,0) -> 1 | Y17: =IF(Q17="",0,1) -> 1 | Z17: =IF(R17+U17=2,3,IF(R17+U17=1,1,0)) -> 1 | AA17: =IF(Z17=3,3,IF(X17+Z17=2,2,IF(Z17=1,1,0))) -> 2 | AB17: =Q17+T17 -> 10 | AC17: =R17+U17+X17 -> 2 | AE17: ='Players - Men'!B26 -> Ryan Ebejer | AF17: =Y17+J39+J27+Y15+J35 -> 5 | AG17: =AA17+L39+L27+AA15+L35 -> 3 | AH17: =AB17+M39+M27+AB15+M35 -> 33 | AI17: =AC17+N39+N27+AC15+N35 -> 3
A18: vs. | P18: vs.
A19: =AE19 -> Max Anastasi Jr | B19: 1 | C19: =IF(B19>B17,1,0) -> 0 | E19: 2 | F19: =IF(E19>E17,1,0) -> 0 | I19: =IF(H19>H17,1,0) -> 0 | J19: =IF(B19="",0,1) -> 1 | K19: =IF(C19+F19=2,3,IF(C19+F19=1,1,0)) -> 0 | L19: =IF(K19=3,3,IF(I19+K19=2,2,IF(K19=1,1,0))) -> 0 | M19: =B19+E19 -> 3 | N19: =C19+F19+I19 -> 0 | P19: =AE19 -> Max Anastasi Jr | Q19: 6 | R19: =IF(Q19>Q17,1,0) -> 1 | T19: 3 | U19: =IF(T19>T17,1,0) -> 0 | W19: 2 | X19: =IF(W19>W17,1,0) -> 0 | Y19: =IF(Q19="",0,1) -> 1 | Z19: =IF(R19+U19=2,3,IF(R19+U19=1,1,0)) -> 1 | AA19: =IF(Z19=3,3,IF(X19+Z19=2,2,IF(Z19=1,1,0))) -> 1 | AB19: =Q19+T19 -> 9 | AC19: =R19+U19+X19 -> 1 | AE19: ='Players - Men'!B27 -> Max Anastasi Jr | AF19: =Y19+Y27+Y35+J19+J31 -> 5 | AG19: =AA19+AA27+AA35+L19+L31 -> 1 | AH19: =AB19+AB27+AB35+M19+M31 -> 25 | AI19: =AC19+AC27+AC35+N19+N31 -> 1
A21: =AE11 -> Artiom Kiricenko | B21: 2 | C21: =IF(B21>B23,1,0) -> 0 | E21: 0 | F21: =IF(E21>E23,1,0) -> 0 | I21: =IF(H21>H23,1,0) -> 0 | J21: =IF(B21="",0,1) -> 1 | K21: =IF(C21+F21=2,3,IF(C21+F21=1,1,0)) -> 0 | L21: =IF(K21=3,3,IF(I21+K21=2,2,IF(K21=1,1,0))) -> 0 | M21: =B21+E21 -> 2 | N21: =C21+F21+I21 -> 0 | P21: =AE11 -> Artiom Kiricenko | Q21: 3 | R21: =IF(Q21>Q23,1,0) -> 0 | T21: 4 | U21: =IF(T21>T23,1,0) -> 0 | X21: =IF(W21>W23,1,0) -> 0 | Y21: =IF(Q21="",0,1) -> 1 | Z21: =IF(R21+U21=2,3,IF(R21+U21=1,1,0)) -> 0 | AA21: =IF(Z21=3,3,IF(X21+Z21=2,2,IF(Z21=1,1,0))) -> 0 | AB21: =Q21+T21 -> 7 | AC21: =R21+U21+X21 -> 0 | AE21: Division Winner
A22: vs. | P22: vs. | AE22: Kristen Cachia
A23: =AE13 -> Kristen Cachia | B23: 6 | C23: =IF(B23>B21,1,0) -> 1 | E23: 6 | F23: =IF(E23>E21,1,0) -> 1 | I23: =IF(H23>H21,1,0) -> 0 | J23: =IF(B23="",0,1) -> 1 | K23: =IF(C23+F23=2,3,IF(C23+F23=1,1,0)) -> 3 | L23: =IF(K23=3,3,IF(I23+K23=2,2,IF(K23=1,1,0))) -> 3 | M23: =B23+E23 -> 12 | N23: =C23+F23+I23 -> 2 | P23: =AE15 -> Denis Caruana | Q23: 6 | R23: =IF(Q23>Q21,1,0) -> 1 | T23: 6 | U23: =IF(T23>T21,1,0) -> 1 | X23: =IF(W23>W21,1,0) -> 0 | Y23: =IF(Q23="",0,1) -> 1 | Z23: =IF(R23+U23=2,3,IF(R23+U23=1,1,0)) -> 3 | AA23: =IF(Z23=3,3,IF(X23+Z23=2,2,IF(Z23=1,1,0))) -> 3 | AB23: =Q23+T23 -> 12 | AC23: =R23+U23+X23 -> 2
A25: =AE11 -> Artiom Kiricenko | B25: 6 | C25: =IF(B25>B27,1,0) -> 1 | E25: 0 | F25: =IF(E25>E27,1,0) -> 0 | H25: 10 | I25: =IF(H25>H27,1,0) -> 1 | J25: =IF(B25="",0,1) -> 1 | K25: =IF(C25+F25=2,3,IF(C25+F25=1,1,0)) -> 1 | L25: =IF(K25=3,3,IF(I25+K25=2,2,IF(K25=1,1,0))) -> 2 | M25: =B25+E25 -> 6 | N25: =C25+F25+I25 -> 2 | P25: =AE11 -> Artiom Kiricenko | Q25: 6 | R25: =IF(Q25>Q27,1,0) -> 1 | T25: 6 | U25: =IF(T25>T27,1,0) -> 1 | X25: =IF(W25>W27,1,0) -> 0 | Y25: =IF(Q25="",0,1) -> 1 | Z25: =IF(R25+U25=2,3,IF(R25+U25=1,1,0)) -> 3 | AA25: =IF(Z25=3,3,IF(X25+Z25=2,2,IF(Z25=1,1,0))) -> 3 | AB25: =Q25+T25 -> 12 | AC25: =R25+U25+X25 -> 2 | AE25: Division Runner Up
A26: vs. | P26: vs. | AE26: Denis Caruana
A27: =AE17 -> Ryan Ebejer | B27: 3 | C27: =IF(B27>B25,1,0) -> 0 | E27: 6 | F27: =IF(E27>E25,1,0) -> 1 | H27: 4 | I27: =IF(H27>H25,1,0) -> 0 | J27: =IF(B27="",0,1) -> 1 | K27: =IF(C27+F27=2,3,IF(C27+F27=1,1,0)) -> 1 | L27: =IF(K27=3,3,IF(I27+K27=2,2,IF(K27=1,1,0))) -> 1 | M27: =B27+E27 -> 9 | N27: =C27+F27+I27 -> 1 | P27: =AE19 -> Max Anastasi Jr | Q27: 4 | R27: =IF(Q27>Q25,1,0) -> 0 | T27: 2 | U27: =IF(T27>T25,1,0) -> 0 | X27: =IF(W27>W25,1,0) -> 0 | Y27: =IF(Q27="",0,1) -> 1 | Z27: =IF(R27+U27=2,3,IF(R27+U27=1,1,0)) -> 0 | AA27: =IF(Z27=3,3,IF(X27+Z27=2,2,IF(Z27=1,1,0))) -> 0 | AB27: =Q27+T27 -> 6 | AC27: =R27+U27+X27 -> 0
A29: =AE15 -> Denis Caruana | B29: 6 | C29: =IF(B29>B31,1,0) -> 1 | E29: 6 | F29: =IF(E29>E31,1,0) -> 1 | I29: =IF(H29>H31,1,0) -> 0 | J29: =IF(B29="",0,1) -> 1 | K29: =IF(C29+F29=2,3,IF(C29+F29=1,1,0)) -> 3 | L29: =IF(K29=3,3,IF(I29+K29=2,2,IF(K29=1,1,0))) -> 3 | M29: =B29+E29 -> 12 | N29: =C29+F29+I29 -> 2 | P29: =AE13 -> Kristen Cachia | Q29: 3 | R29: =IF(Q29>Q31,1,0) -> 0 | T29: 6 | U29: =IF(T29>T31,1,0) -> 1 | W29: 6 | X29: =IF(W29>W31,1,0) -> 0 | Y29: =IF(Q29="",0,1) -> 1 | Z29: =IF(R29+U29=2,3,IF(R29+U29=1,1,0)) -> 1 | AA29: =IF(Z29=3,3,IF(X29+Z29=2,2,IF(Z29=1,1,0))) -> 1 | AB29: =Q29+T29 -> 9 | AC29: =R29+U29+X29 -> 1
A30: vs. | P30: vs.
A31: =AE19 -> Max Anastasi Jr | B31: 3 | C31: =IF(B31>B29,1,0) -> 0 | E31: 1 | F31: =IF(E31>E29,1,0) -> 0 | I31: =IF(H31>H29,1,0) -> 0 | J31: =IF(B31="",0,1) -> 1 | K31: =IF(C31+F31=2,3,IF(C31+F31=1,1,0)) -> 0 | L31: =IF(K31=3,3,IF(I31+K31=2,2,IF(K31=1,1,0))) -> 0 | M31: =B31+E31 -> 4 | N31: =C31+F31+I31 -> 0 | P31: =AE15 -> Denis Caruana | Q31: 6 | R31: =IF(Q31>Q29,1,0) -> 1 | T31: 2 | U31: =IF(T31>T29,1,0) -> 0 | W31: 10 | X31: =IF(W31>W29,1,0) -> 1 | Y31: =IF(Q31="",0,1) -> 1 | Z31: =IF(R31+U31=2,3,IF(R31+U31=1,1,0)) -> 1 | AA31: =IF(Z31=3,3,IF(X31+Z31=2,2,IF(Z31=1,1,0))) -> 2 | AB31: =Q31+T31 -> 8 | AC31: =R31+U31+X31 -> 2
A33: =AE13 -> Kristen Cachia | B33: 6 | C33: =IF(B33>B35,1,0) -> 1 | E33: 6 | F33: =IF(E33>E35,1,0) -> 1 | I33: =IF(H33>H35,1,0) -> 0 | J33: =IF(B33="",0,1) -> 1 | K33: =IF(C33+F33=2,3,IF(C33+F33=1,1,0)) -> 3 | L33: =IF(K33=3,3,IF(I33+K33=2,2,IF(K33=1,1,0))) -> 3 | M33: =B33+E33 -> 12 | N33: =C33+F33+I33 -> 2 | P33: =AE13 -> Kristen Cachia | Q33: 6 | R33: =IF(Q33>Q35,1,0) -> 1 | T33: 6 | U33: =IF(T33>T35,1,0) -> 1 | X33: =IF(W33>W35,1,0) -> 0 | Y33: =IF(Q33="",0,1) -> 1 | Z33: =IF(R33+U33=2,3,IF(R33+U33=1,1,0)) -> 3 | AA33: =IF(Z33=3,3,IF(X33+Z33=2,2,IF(Z33=1,1,0))) -> 3 | AB33: =Q33+T33 -> 12 | AC33: =R33+U33+X33 -> 2
A34: vs. | P34: vs.
A35: =AE17 -> Ryan Ebejer | B35: 3 | C35: =IF(B35>B33,1,0) -> 0 | E35: 4 | F35: =IF(E35>E33,1,0) -> 0 | I35: =IF(H35>H33,1,0) -> 0 | J35: =IF(B35="",0,1) -> 1 | K35: =IF(C35+F35=2,3,IF(C35+F35=1,1,0)) -> 0 | L35: =IF(K35=3,3,IF(I35+K35=2,2,IF(K35=1,1,0))) -> 0 | M35: =B35+E35 -> 7 | N35: =C35+F35+I35 -> 0 | P35: =AE19 -> Max Anastasi Jr | Q35: 1 | R35: =IF(Q35>Q33,1,0) -> 0 | T35: 2 | U35: =IF(T35>T33,1,0) -> 0 | X35: =IF(W35>W33,1,0) -> 0 | Y35: =IF(Q35="",0,1) -> 1 | Z35: =IF(R35+U35=2,3,IF(R35+U35=1,1,0)) -> 0 | AA35: =IF(Z35=3,3,IF(X35+Z35=2,2,IF(Z35=1,1,0))) -> 0 | AB35: =Q35+T35 -> 3 | AC35: =R35+U35+X35 -> 0
A37: =AE15 -> Denis Caruana | B37: 6 | C37: =IF(B37>B39,1,0) -> 1 | E37: 6 | F37: =IF(E37>E39,1,0) -> 1 | I37: =IF(H37>H39,1,0) -> 0 | J37: =IF(B37="",0,1) -> 1 | K37: =IF(C37+F37=2,3,IF(C37+F37=1,1,0)) -> 3 | L37: =IF(K37=3,3,IF(I37+K37=2,2,IF(K37=1,1,0))) -> 3 | M37: =B37+E37 -> 12 | N37: =C37+F37+I37 -> 2
A38: vs.
A39: =AE17 -> Ryan Ebejer | B39: 3 | C39: =IF(B39>B37,1,0) -> 0 | E39: 1 | F39: =IF(E39>E37,1,0) -> 0 | I39: =IF(H39>H37,1,0) -> 0 | J39: =IF(B39="",0,1) -> 1 | K39: =IF(C39+F39=2,3,IF(C39+F39=1,1,0)) -> 0 | L39: =IF(K39=3,3,IF(I39+K39=2,2,IF(K39=1,1,0))) -> 0 | M39: =B39+E39 -> 4 | N39: =C39+F39+I39 -> 0

Sheet Men Div 4
A1: Troy Shipping Agency Singles Tournament 2024
A5: Men Division 4
A7: Players | B7: Set Scores | H7: Tie | P7: Players | Q7: Set Scores | W7: Tie | AE7: Player | AF7: Games | AG7: Points | AH7: Games Won | AI7: Sets Won
B8: Score | C8: Set 1 Work | E8: Score | F8: Set 2 Work | H8: Score | I8: Tie Work | J8: Game Played | K8: Sets Points Work | L8: Sets & Tie Points Work | M8: Games Wins Work | N8: Sets Wins Work | Q8: Score | R8: Set 1 Work | T8: Score | U8: Set 2 Work | W8: Score | X8: Tie Work | Y8: Game Played | Z8: Sets Points Work | AA8: Sets & Tie Points Work | AB8: Games Wins Work | AC8: Sets Wins Work | AJ8: Winner Working | AK8: Runner Up Working | AL8: Total Games Work | AM8: Winner | AN8: Runner Up
A9: =AE9 -> Lydon Vella | B9: 6 | C9: =IF(B9>B11,1,0) -> 1 | E9: 6 | F9: =IF(E9>E11,1,0) -> 1 | I9: =IF(H9>H11,1,0) -> 0 | J9: =IF(B9="",0,1) -> 1 | K9: =IF(C9+F9=2,3,IF(C9+F9=1,1,0)) -> 3 | L9: =IF(K9=3,3,IF(I9+K9=2,2,IF(K9=1,1,0))) -> 3 | M9: =B9+E9 -> 12 | N9: =C9+F9+I9 -> 2 | P9: =AE9 -> Lydon Vella | Q9: 3 | R9: =IF(Q9>Q11,1,0) -> 0 | T9: 6 | U9: =IF(T9>T11,1,0) -> 1 | W9: 10 | X9: =IF(W9>W11,1,0) -> 1 | Y9: =IF(Q9="",0,1) -> 1 | Z9: =IF(R9+U9=2,3,IF(R9+U9=1,1,0)) -> 1 | AA9: =IF(Z9=3,3,IF(X9+Z9=2,2,IF(Z9=1,1,0))) -> 2 | AB9: =Q9+T9 -> 9 | AC9: =R9+U9+X9 -> 2 | AE9: ='Players - Men'!B30 -> Lydon Vella | AF9: =J9+Y9+J13+Y13+J17 -> 5 | AG9: =L9+AA9+L13+AA13+L17 -> 11 | AH9: =M9+AB9+M13+AB13+M17 -> 53 | AI9: =N9+AC9+N13+AC13+N17 -> 9 | AJ9: =MAX(AG9:AG19) -> 12 | AK9: =LARGE(AG9:AG19, 2) -> 11 | AL9: =SUM(AF9:AF19) -> 30 | AM9: =IF(AG9=$AJ$9,AE9,IF(AG11=$AJ$9,AE11,IF(AG13=$AJ$9,AE13,IF(AG15=$AJ$9,AE15,IF(AG17=$AJ$9,AE17,""))))) | AN9: =IF(AG9=$AK$9,AE9,IF(AG11=$AK$9,AE11,IF(AG13=$AK$9,AE13,IF(AG15=$AK$9,AE15,IF(AG17=$AK$9,AE17,""))))) -> Lydon Vella
A10: vs. | P10: vs.
A11: =AE11 -> Kenneth Farrugia | B11: 1 | C11: =IF(B11>B9,1,0) -> 0 | E11: 1 | F11: =IF(E11>E9,1,0) -> 0 | I11: =IF(H11>H9,1,0) -> 0 | J11: =IF(B11="",0,1) -> 1 | K11: =IF(C11+F11=2,3,IF(C11+F11=1,1,0)) -> 0 | L11: =IF(K11=3,3,IF(I11+K11=2,2,IF(K11=1,1,0))) -> 0 | M11: =B11+E11 -> 2 | N11: =C11+F11+I11 -> 0 | P11: =AE13 -> M. Ibnu Wahyudi Mohamad Ibnu Wahyudi | Q11: 6 | R11: =IF(Q11>Q9,1,0) -> 1 | T11: 4 | U11: =IF(T11>T9,1,0) -> 0 | W11: 7 | X11: =IF(W11>W9,1,0) -> 0 | Y11: =IF(Q11="",0,1) -> 1 | Z11: =IF(R11+U11=2,3,IF(R11+U11=1,1,0)) -> 1 | AA11: =IF(Z11=3,3,IF(X11+Z11=2,2,IF(Z11=1,1,0))) -> 1 | AB11: =Q11+T11 -> 10 | AC11: =R11+U11+X11 -> 1 | AE11: ='Players - Men'!B31 -> Kenneth Farrugia | AF11: =J11+Y25+J25+Y21+J21 -> 5 | AG11: =L11+AA25+L25+AA21+L21 -> 3 | AH11: =M11+AB25+M25+AB21+M21 -> 28 | AI11: =N11+AC25+N25+AC21+N21 -> 2
A13: =AE9 -> Lydon Vella | B13: 7 | C13: =IF(B13>B15,1,0) -> 1 | E13: 7 | F13: =IF(E13>E15,1,0) -> 1 | I13: =IF(H13>H15,1,0) -> 0 | J13: =IF(B13="",0,1) -> 1 | K13: =IF(C13+F13=2,3,IF(C13+F13=1,1,0)) -> 3 | L13: =IF(K13=3,3,IF(I13+K13=2,2,IF(K13=1,1,0))) -> 3 | M13: =B13+E13 -> 14 | N13: =C13+F13+I13 -> 2 | P13: =AE9 -> Lydon Vella | Q13: 6 | R13: =IF(Q13>Q15,1,0) -> 1 | T13: 4 | U13: =IF(T13>T15,1,0) -> 0 | W13: 12 | X13: =IF(W13>W15,1,0) -> 1 | Y13: =IF(Q13="",0,1) -> 1 | Z13: =IF(R13+U13=2,3,IF(R13+U13=1,1,0)) -> 1 | AA13: =IF(Z13=3,3,IF(X13+Z13=2,2,IF(Z13=1,1,0))) -> 2 | AB13: =Q13+T13 -> 10 | AC13: =R13+U13+X13 -> 2 | AE13: ='Players - Men'!B32 -> M. Ibnu Wahyudi Mohamad Ibnu Wahyudi | AF13: =Y29+Y11+Y33+J33+J23 -> 5 | AG13: =AA29+AA11+AA33+L33+L23 -> 11 | AH13: =AB29+AB11+AB33+M33+M23 -> 54 | AI13: =AC29+AC11+AC33+N33+N23 -> 9
A14: vs. | P14: vs.
A15: =AE15 -> Etienne Formosa Carabez | B15: 5 | C15: =IF(B15>B13,1,0) -> 0 | E15: 5 | F15: =IF(E15>E13,1,0) -> 0 | I15: =IF(H15>H13,1,0) -> 0 | J15: =IF(B15="",0,1) -> 1 | K15: =IF(C15+F15=2,3,IF(C15+F15=1,1,0)) -> 0 | L15: =IF(K15=3,3,IF(I15+K15=2,2,IF(K15=1,1,0))) -> 0 | M15: =B15+E15 -> 10 | N15: =C15+F15+I15 -> 0 | P15: =AE17 -> Ivan Cassar | Q15: 4 | R15: =IF(Q15>Q13,1,0) -> 0 | T15: 6 | U15: =IF(T15>T13,1,0) -> 1 | W15: 10 | X15: =IF(W15>W13,1,0) -> 0 | Y15: =IF(Q15="",0,1) -> 1 | Z15: =IF(R15+U15=2,3,IF(R15+U15=1,1,0)) -> 1 | AA15: =IF(Z15=3,3,IF(X15+Z15=2,2,IF(Z15=1,1,0))) -> 1 | AB15: =Q15+T15 -> 10 | AC15: =R15+U15+X15 -> 1 | AE15: ='Players - Men'!B33 -> Etienne Formosa Carabez | AF15: =Y31+J37+J15+Y23+J29 -> 5 | AG15: =AA31+L37+L15+AA23+L29 -> 7 | AH15: =AB31+M37+M15+AB23+M29 -> 47 | AI15: =AC31+N37+N15+AC23+N29 -> 5
A17: =AE9 -> Lydon Vella | B17: 2 | C17: =IF(B17>B19,1,0) -> 0 | E17: 6 | F17: =IF(E17>E19,1,0) -> 1 | H17: 8 | I17: =IF(H17>H19,1,0) -> 0 | J17: =IF(B17="",0,1) -> 1 | K17: =IF(C17+F17=2,3,IF(C17+F17=1,1,0)) -> 1 | L17: =IF(K17=3,3,IF(I17+K17=2,2,IF(K17=1,1,0))) -> 1 | M17: =B17+E17 -> 8 | N17: =C17+F17+I17 -> 1 | P17: =AE17 -> Ivan Cassar | Q17: 4 | R17: =IF(Q17>Q19,1,0) -> 0 | T17: 5 | U17: =IF(T17>T19,1,0) -> 0 | X17: =IF(W17>W19,1,0) -> 0 | Y17: =IF(Q17="",0,1) -> 1 | Z17: =IF(R17+U17=2,3,IF(R17+U17=1,1,0)) -> 0 | AA17: =IF(Z17=3,3,IF(X17+Z17=2,2,IF(Z17=1,1,0))) -> 0 | AB17: =Q17+T17 -> 9 | AC17: =R17+U17+X17 -> 0 | AE17: ='Players - Men'!B34 -> Ivan Cassar | AF17: =Y17+J39+J27+Y15+J35 -> 5 | AG17: =AA17+L39+L27+AA15+L35 -> 1 | AH17: =AB17+M39+M27+AB15+M35 -> 44 | AI17: =AC17+N39+N27+AC15+N35 -> 1
A18: vs. | P18: vs.
A19: =AE19 -> Kurt Cassar | B19: 6 | C19: =IF(B19>B17,1,0) -> 1 | E19: 1 | F19: =IF(E19>E17,1,0) -> 0 | H19: 10 | I19: =IF(H19>H17,1,0) -> 1 | J19: =IF(B19="",0,1) -> 1 | K19: =IF(C19+F19=2,3,IF(C19+F19=1,1,0)) -> 1 | L19: =IF(K19=3,3,IF(I19+K19=2,2,IF(K19=1,1,0))) -> 2 | M19: =B19+E19 -> 7 | N19: =C19+F19+I19 -> 2 | P19: =AE19 -> Kurt Cassar | Q19: 6 | R19: =IF(Q19>Q17,1,0) -> 1 | T19: 7 | U19: =IF(T19>T17,1,0) -> 1 | X19: =IF(W19>W17,1,0) -> 0 | Y19: =IF(Q19="",0,1) -> 1 | Z19: =IF(R19+U19=2,3,IF(R19+U19=1,1,0)) -> 3 | AA19: =IF(Z19=3,3,IF(X19+Z19=2,2,IF(Z19=1,1,0))) -> 3 | AB19: =Q19+T19 -> 13 | AC19: =R19+U19+X19 -> 2 | AE19: ='Players - Men'!B35 -> Kurt Cassar | AF19: =Y19+Y27+Y35+J19+J31 -> 5 | AG19: =AA19+AA27+AA35+L19+L31 -> 12 | AH19: =AB19+AB27+AB35+M19+M31 -> 54 | AI19: =AC19+AC27+AC35+N19+N31 -> 9
A21: =AE11 -> Kenneth Farrugia | B21: 2 | C21: =IF(B21>B23,1,0) -> 0 | E21: 1 | F21: =IF(E21>E23,1,0) -> 0 | I21: =IF(H21>H23,1,0) -> 0 | J21: =IF(B21="",0,1) -> 1 | K21: =IF(C21+F21=2,3,IF(C21+F21=1,1,0)) -> 0 | L21: =IF(K21=3,3,IF(I21+K21=2,2,IF(K21=1,1,0))) -> 0 | M21: =B21+E21 -> 3 | N21: =C21+F21+I21 -> 0 | P21: =AE11 -> Kenneth Farrugia | Q21: 4 | R21: =IF(Q21>Q23,1,0) -> 0 | T21: 1 | U21: =IF(T21>T23,1,0) -> 0 | X21: =IF(W21>W23,1,0) -> 0 | Y21: =IF(Q21="",0,1) -> 1 | Z21: =IF(R21+U21=2,3,IF(R21+U21=1,1,0)) -> 0 | AA21: =IF(Z21=3,3,IF(X21+Z21=2,2,IF(Z21=1,1,0))) -> 0 | AB21: =Q21+T21 -> 5 | AC21: =R21+U21+X21 -> 0 | AE21: Divison Winner
A22: vs. | P22: vs. | AE22: Kurt Cassar
A23: =AE13 -> M. Ibnu Wahyudi Mohamad Ibnu Wahyudi | B23: 6 | C23: =IF(B23>B21,1,0) -> 1 | E23: 6 | F23: =IF(E23>E21,1,0) -> 1 | I23: =IF(H23>H21,1,0) -> 0 | J23: =IF(B23="",0,1) -> 1 | K23: =IF(C23+F23=2,3,IF(C23+F23=1,1,0)) -> 3 | L23: =IF(K23=3,3,IF(I23+K23=2,2,IF(K23=1,1,0))) -> 3 | M23: =B23+E23 -> 12 | N23: =C23+F23+I23 -> 2 | P23: =AE15 -> Etienne Formosa Carabez | Q23: 6 | R23: =IF(Q23>Q21,1,0) -> 1 | T23: 6 | U23: =IF(T23>T21,1,0) -> 1 | X23: =IF(W23>W21,1,0) -> 0 | Y23: =IF(Q23="",0,1) -> 1 | Z23: =IF(R23+U23=2,3,IF(R23+U23=1,1,0)) -> 3 | AA23: =IF(Z23=3,3,IF(X23+Z23=2,2,IF(Z23=1,1,0))) -> 3 | AB23: =Q23+T23 -> 12 | AC23: =R23+U23+X23 -> 2
A25: =AE11 -> Kenneth Farrugia | B25: 6 | C25: =IF(B25>B27,1,0) -> 1 | E25: 7 | F25: =IF(E25>E27,1,0) -> 1 | I25: =IF(H25>H27,1,0) -> 0 | J25: =IF(B25="",0,1) -> 1 | K25: =IF(C25+F25=2,3,IF(C25+F25=1,1,0)) -> 3 | L25: =IF(K25=3,3,IF(I25+K25=2,2,IF(K25=1,1,0))) -> 3 | M25: =B25+E25 -> 13 | N25: =C25+F25+I25 -> 2 | P25: =AE11 -> Kenneth Farrugia | Q25: 1 | R25: =IF(Q25>Q27,1,0) -> 0 | T25: 4 | U25: =IF(T25>T27,1,0) -> 0 | X25: =IF(W25>W27,1,0) -> 0 | Y25: =IF(Q25="",0,1) -> 1 | Z25: =IF(R25+U25=2,3,IF(R25+U25=1,1,0)) -> 0 | AA25: =IF(Z25=3,3,IF(X25+Z25=2,2,IF(Z25=1,1,0))) -> 0 | AB25: =Q25+T25 -> 5 | AC25: =R25+U25+X25 -> 0 | AE25: Divison Runner Up
A26: vs. | P26: vs. | AE26: =IF(AL9=30,AN9,"") -> Lydon Vella
A27: =AE17 -> Ivan Cassar | B27: 3 | C27: =IF(B27>B25,1,0) -> 0 | E27: 5 | F27: =IF(E27>E25,1,0) -> 0 | I27: =IF(H27>H25,1,0) -> 0 | J27: =IF(B27="",0,1) -> 1 | K27: =IF(C27+F27=2,3,IF(C27+F27=1,1,0)) -> 0 | L27: =IF(K27=3,3,IF(I27+K27=2,2,IF(K27=1,1,0))) -> 0 | M27: =B27+E27 -> 8 | N27: =C27+F27+I27 -> 0 | P27: =AE19 -> Kurt Cassar | Q27: 6 | R27: =IF(Q27>Q25,1,0) -> 1 | T27: 6 | U27: =IF(T27>T25,1,0) -> 1 | X27: =IF(W27>W25,1,0) -> 0 | Y27: =IF(Q27="",0,1) -> 1 | Z27: =IF(R27+U27=2,3,IF(R27+U27=1,1,0)) -> 3 | AA27: =IF(Z27=3,3,IF(X27+Z27=2,2,IF(Z27=1,1,0))) -> 3 | AB27: =Q27+T27 -> 12 | AC27: =R27+U27+X27 -> 2
A29: =AE15 -> Etienne Formosa Carabez | B29: 0 | C29: =IF(B29>B31,1,0) -> 0 | E29: 5 | F29: =IF(E29>E31,1,0) -> 0 | I29: =IF(H29>H31,1,0) -> 0 | J29: =IF(B29="",0,1) -> 1 | K29: =IF(C29+F29=2,3,IF(C29+F29=1,1,0)) -> 0 | L29: =IF(K29=3,3,IF(I29+K29=2,2,IF(K29=1,1,0))) -> 0 | M29: =B29+E29 -> 5 | N29: =C29+F29+I29 -> 0 | P29: =AE13 -> M. Ibnu Wahyudi Mohamad Ibnu Wahyudi | Q29: 4 | R29: =IF(Q29>Q31,1,0) -> 0 | T29: 6 | U29: =IF(T29>T31,1,0) -> 1 | W29: 10 | X29: =IF(W29>W31,1,0) -> 1 | Y29: =IF(Q29="",0,1) -> 1 | Z29: =IF(R29+U29=2,3,IF(R29+U29=1,1,0)) -> 1 | AA29: =IF(Z29=3,3,IF(X29+Z29=2,2,IF(Z29=1,1,0))) -> 2 | AB29: =Q29+T29 -> 10 | AC29: =R29+U29+X29 -> 2
A30: vs. | P30: vs.
A31: =AE19 -> Kurt Cassar | B31: 6 | C31: =IF(B31>B29,1,0) -> 1 | E31: 7 | F31: =IF(E31>E29,1,0) -> 1 | I31: =IF(H31>H29,1,0) -> 0 | J31: =IF(B31="",0,1) -> 1 | K31: =IF(C31+F31=2,3,IF(C31+F31=1,1,0)) -> 3 | L31: =IF(K31=3,3,IF(I31+K31=2,2,IF(K31=1,1,0))) -> 3 | M31: =B31+E31 -> 13 | N31: =C31+F31+I31 -> 2 | P31: =AE15 -> Etienne Formosa Carabez | Q31: 6 | R31: =IF(Q31>Q29,1,0) -> 1 | T31: 1 | U31: =IF(T31>T29,1,0) -> 0 | W31: 3 | X31: =IF(W31>W29,1,0) -> 0 | Y31: =IF(Q31="",0,1) -> 1 | Z31: =IF(R31+U31=2,3,IF(R31+U31=1,1,0)) -> 1 | AA31: =IF(Z31=3,3,IF(X31+Z31=2,2,IF(Z31=1,1,0))) -> 1 | AB31: =Q31+T31 -> 7 | AC31: =R31+U31+X31 -> 1
A33: =AE13 -> M. Ibnu Wahyudi Mohamad Ibnu Wahyudi | B33: 7 | C33: =IF(B33>B35,1,0) -> 1 | E33: 7 | F33: =IF(E33>E35,1,0) -> 1 | I33: =IF(H33>H35,1,0) -> 0 | J33: =IF(B33="",0,1) -> 1 | K33: =IF(C33+F33=2,3,IF(C33+F33=1,1,0)) -> 3 | L33: =IF(K33=3,3,IF(I33+K33=2,2,IF(K33=1,1,0))) -> 3 | M33: =B33+E33 -> 14 | N33: =C33+F33+I33 -> 2 | P33: =AE13 -> M. Ibnu Wahyudi Mohamad Ibnu Wahyudi | Q33: 2 | R33: =IF(Q33>Q35,1,0) -> 0 | T33: 6 | U33: =IF(T33>T35,1,0) -> 1 | W33: 10 | X33: =IF(W33>W35,1,0) -> 1 | Y33: =IF(Q33="",0,1) -> 1 | Z33: =IF(R33+U33=2,3,IF(R33+U33=1,1,0)) -> 1 | AA33: =IF(Z33=3,3,IF(X33+Z33=2,2,IF(Z33=1,1,0))) -> 2 | AB33: =Q33+T33 -> 8 | AC33: =R33+U33+X33 -> 2
A34: vs. | P34: vs.
A35: =AE17 -> Ivan Cassar | B35: 6 | C35: =IF(B35>B33,1,0) -> 0 | E35: 5 | F35: =IF(E35>E33,1,0) -> 0 | I35: =IF(H35>H33,1,0) -> 0 | J35: =IF(B35="",0,1) -> 1 | K35: =IF(C35+F35=2,3,IF(C35+F35=1,1,0)) -> 0 | L35: =IF(K35=3,3,IF(I35+K35=2,2,IF(K35=1,1,0))) -> 0 | M35: =B35+E35 -> 11 | N35: =C35+F35+I35 -> 0 | P35: =AE19 -> Kurt Cassar | Q35: 6 | R35: =IF(Q35>Q33,1,0) -> 1 | T35: 3 | U35: =IF(T35>T33,1,0) -> 0 | W35: 2 | X35: =IF(W35>W33,1,0) -> 0 | Y35: =IF(Q35="",0,1) -> 1 | Z35: =IF(R35+U35=2,3,IF(R35+U35=1,1,0)) -> 1 | AA35: =IF(Z35=3,3,IF(X35+Z35=2,2,IF(Z35=1,1,0))) -> 1 | AB35: =Q35+T35 -> 9 | AC35: =R35+U35+X35 -> 1
