Workbook

Sheet Players
A1: Elektra Mixed Doubles 2023
B5: Division 1
A6: 1 | B6: Reuben Borg | C6: Erika Azzopardi
A7: 2 | B7: Adrian Chetcuti | C7: Ann Marie Mangion
A8: 3 | B8: Eric Roca | C8: Alison Muscat
A9: 4 | B9: Matthew Mifsud | C9: Lara Pule'
A10: 5 | B10: Duncan D'Alessandro | C10: Anthea Gauci
B12: Division 2
A13: 1 | B13: Keith Micallef | C13: Mirka Micallef
A14: 2 | B14: Melchior Farrugia | C14: Doriana Portelli
A15: 3 | B15: Adrian Manduca | C15: Julie Spiteri
A16: 4 | B16: Andrew Pule' | C16: Celeste Zammit Marquette
A17: 5 | B17: Daniel Falzon | C17: Amanda Falzon
A18: 6 | B18: Manuel Bonello | C18: Alexia Meilak Gouder
B20: Division 3
A21: 1 | B21: Gio Marcos | C21: Jennifer Roca
A22: 2 | B22: Gabriel Pace | C22: Kelsey Gauci
A23: 3 | B23: Cristian Andreozzi | C23: Luiza Andreozzi
A24: 4 | B24: George Grech | C24: Rowena Caruana
A25: 5 | B25: Chi Chi Canonce | C25: Yana Cachia
B27: Division 4
A28: 1 | B28: Willem Steenkamer | C28: Mariska Steenkamer
A29: 2 | B29: James Farrugia | C29: Nancy Wong
A30: 3 | B30: Kristen Cachia | C30: Francesca Sciortino
A31: 4 | B31: Luigi Porto | C31: Vanessa Azzopardi
A32: 5 | B32: Cyril Lastimosa | C32: Laureen Agius
A33: 6 | B33: Jayboy Lastimosa | C33: Ceridwen Scerri
B35: Division 5 - Group A | F35: Division 5 - Group B
A36: 1 | B36: Daniel Farrugia | C36: Diane Farrugia | E36: 1 | F36: Victor Rutter | G36: Jennifer Mifsud
A37: 2 | B37: David Camilleri | C37: Emma Camilleri | E37: 2 | F37: Ryan Ebejer | G37: Sophia Re
A38: 3 | B38: Maurice Borg | C38: Mary Borg | E38: 3 | F38: Matthew Micallef | G38: Josette D'Alessandro
A39: 4 | B39: Robert Attard | C39: Silvana Portelli | E39: 4 | F39: Karl Azzopardi | G39: Dawn Azzopardi
A40: 5 | B40: JP Sciberras | C40: Brenda Baldacchino | E40: 5 | F40: Jake Gatt | G40: Nicole Lia
A41: 6 | B41: Cory Greenland | C41: Marica Cassar | E41: 6 | F41: Dunstan Vella | G41: Heidi Tabone
B43: Division 6
A44: 1 | B44: Kevin Sciberras | C44: Giada Sciberras
A45: 2 | B45: Clayton Saliba Hersey | C45: Frances Saliba Hersey
A46: 3 | B46: Sean Cachia | C46: Daphne Vella
A47: 4 | B47: Dayle Scicluna | C47: Alida Borg
A48: 5 | B48: Sammy Ben Tamer | C48: Martina Murdocco
...

Sheet Division 1
A1: Elektra Mixed Doubles 2023
A5: Division 1
A7: Players | B7: Set Scores | H7: Tie | P7: Players | Q7: Set Scores | W7: Tie | AE7: Player | AF7: Games | AG7: Points | AH7: Games Won | AI7: Sets Won
B8: Score | C8: Set 1 Work | E8: Score | F8: Set 2 Work | H8: Score | I8: Tie Work | J8: Game Played | K8: Sets Points Work | L8: Sets & Tie Points Work | M8: Games Wins Work | N8: Sets Wins Work | Q8: Score | R8: Set 1 Work | T8: Score | U8: Set 2 Work | W8: Score | X8: Tie Work | Y8: Game Played | Z8: Sets Points Work | AA8: Sets & Tie Points Work | AB8: Games Wins Work | AC8: Sets Wins Work | AJ8: Winner Working | AK8: Runner Up Working | AL8: Total Games Work | AM8: Winner | AN8: Runner Up
A9: =AE9 -> Reuben Borg / Erika Azzopardi | B9: 7 | C9: =IF(B9>B11,1,0) -> 1 | E9: 3 | F9: =IF(E9>E11,1,0) -> 0 | H9: 5 | I9: =IF(H9>H11,1,0) -> 0 | J9: =IF(B9="",0,1) -> 1 | K9: =IF(C9+F9=2,3,IF(C9+F9=1,1,0)) -> 1 | L9: =IF(K9=3,3,IF(I9+K9=2,2,IF(K9=1,1,0))) -> 1 | M9: =B9+E9 -> 10 | N9: =C9+F9+I9 -> 1 | P9: =AE9 -> Reuben Borg / Erika Azzopardi | Q9: 6 | R9: =IF(Q9>Q11,1,0) -> 1 | T9: 7 | U9: =IF(T9>T11,1,0) -> 1 | X9: =IF(W9>W11,1,0) -> 0 | Y9: =IF(Q9="",0,1) -> 1 | Z9: =IF(R9+U9=2,3,IF(R9+U9=1,1,0)) -> 3 | AA9: =IF(Z9=3,3,IF(X9+Z9=2,2,IF(Z9=1,1,0))) -> 3 | AB9: =Q9+T9 -> 13 | AC9: =R9+U9+X9 -> 2 | AE9: =Players!B6& " / " &Players!C6 -> Reuben Borg / Erika Azzopardi | AF9: =J17+Y9+J13+J9 -> 4 | AG9: =L17+AA9+L13+L9 -> 9 | AH9: =M17+AB9+M13+M9 -> 47 | AI9: =N17+AC9+N13+N9 -> 7 | AJ9: =MAX(AG9:AG17) -> 9 | AK9: =LARGE(AG9:AG17, 2) -> 9 | AL9: =SUM(AF9:AF17) -> 20 | AM9: =IF(AG9=$AJ$9,AE9,IF(AG11=$AJ$9,AE11,IF(AG13=$AJ$9,AE13,IF(AG15=$AJ$9,AE15,IF(AG17=$AJ$9,AE17,""))))) -> Reuben Borg / Erika Azzopardi | AN9: =IF(AG9=$AK$9,AE9,IF(AG11=$AK$9,AE11,IF(AG13=$AK$9,AE13,IF(AG15=$AK$9,AE15,IF(AG17=$AK$9,AE17,""))))) -> Reuben Borg / Erika Azzopardi
A10: vs. | P10: vs.
A11: =AE11 -> Adrian Chetcuti / Ann Marie Mangion | B11: 5 | C11: =IF(B11>B9,1,0) -> 0 | E11: 6 | F11: =IF(E11>E9,1,0) -> 1 | H11: 10 | I11: =IF(H11>H9,1,0) -> 1 | J11: =IF(B11="",0,1) -> 1 | K11: =IF(C11+F11=2,3,IF(C11+F11=1,1,0)) -> 1 | L11: =IF(K11=3,3,IF(I11+K11=2,2,IF(K11=1,1,0))) -> 2 | M11: =B11+E11 -> 11 | N11: =C11+F11+I11 -> 2 | P11: =AE15 -> Matthew Mifsud / Lara Pule' | Q11: 2 | R11: =IF(Q11>Q9,1,0) -> 0 | T11: 5 | U11: =IF(T11>T9,1,0) -> 0 | X11: =IF(W11>W9,1,0) -> 0 | Y11: =IF(Q11="",0,1) -> 1 | Z11: =IF(R11+U11=2,3,IF(R11+U11=1,1,0)) -> 0 | AA11: =IF(Z11=3,3,IF(X11+Z11=2,2,IF(Z11=1,1,0))) -> 0 | AB11: =Q11+T11 -> 7 | AC11: =R11+U11+X11 -> 0 | AE11: =Players!B7& " / " &Players!C7 -> Adrian Chetcuti / Ann Marie Mangion | AF11: =Y21+Y25+Y13+J11 -> 4 | AG11: =AA21+AA25+AA13+L11 -> 9 | AH11: =AB21+AB25+AB13+M11 -> 43 | AI11: =AC21+AC25+AC13+N11 -> 8
A13: =AE9 -> Reuben Borg / Erika Azzopardi | B13: 6 | C13: =IF(B13>B15,1,0) -> 1 | E13: 6 | F13: =IF(E13>E15,1,0) -> 0 | H13: 10 | I13: =IF(H13>H15,1,0) -> 1 | J13: =IF(B13="",0,1) -> 1 | K13: =IF(C13+F13=2,3,IF(C13+F13=1,1,0)) -> 1 | L13: =IF(K13=3,3,IF(I13+K13=2,2,IF(K13=1,1,0))) -> 2 | M13: =B13+E13 -> 12 | N13: =C13+F13+I13 -> 2 | P13: =AE11 -> Adrian Chetcuti / Ann Marie Mangion | Q13: 2 | R13: =IF(Q13>Q15,1,0) -> 0 | T13: 6 | U13: =IF(T13>T15,1,0) -> 1 | W13: 10 | X13: =IF(W13>W15,1,0) -> 1 | Y13: =IF(Q13="",0,1) -> 1 | Z13: =IF(R13+U13=2,3,IF(R13+U13=1,1,0)) -> 1 | AA13: =IF(Z13=3,3,IF(X13+Z13=2,2,IF(Z13=1,1,0))) -> 2 | AB13: =Q13+T13 -> 8 | AC13: =R13+U13+X13 -> 2 | AE13: =Players!B8& " / " &Players!C8 -> Eric Roca / Alison Muscat | AF13: =Y23+Y17+J15+J21 -> 4 | AG13: =AA23+AA17+L15+L21 -> 3 | AH13: =AB23+AB17+M15+M21 -> 32 | AI13: =AC23+AC17+N15+N21 -> 3
A14: vs. | P14: vs.
A15: =AE13 -> Eric Roca / Alison Muscat | B15: 3 | C15: =IF(B15>B13,1,0) -> 0 | E15: 7 | F15: =IF(E15>E13,1,0) -> 1 | H15: 4 | I15: =IF(H15>H13,1,0) -> 0 | J15: =IF(B15="",0,1) -> 1 | K15: =IF(C15+F15=2,3,IF(C15+F15=1,1,0)) -> 1 | L15: =IF(K15=3,3,IF(I15+K15=2,2,IF(K15=1,1,0))) -> 1 | M15: =B15+E15 -> 10 | N15: =C15+F15+I15 -> 1 | P15: =AE15 -> Matthew Mifsud / Lara Pule' | Q15: 6 | R15: =IF(Q15>Q13,1,0) -> 1 | T15: 4 | U15: =IF(T15>T13,1,0) -> 0 | W15: 7 | X15: =IF(W15>W13,1,0) -> 0 | Y15: =IF(Q15="",0,1) -> 1 | Z15: =IF(R15+U15=2,3,IF(R15+U15=1,1,0)) -> 1 | AA15: =IF(Z15=3,3,IF(X15+Z15=2,2,IF(Z15=1,1,0))) -> 1 | AB15: =Q15+T15 -> 10 | AC15: =R15+U15+X15 -> 1 | AE15: =Players!B9& " / " &Players!C9 -> Matthew Mifsud / Lara Pule' | AF15: =J25+Y19+Y11+Y15 -> 4 | AG15: =L25+AA19+AA11+AA15 -> 7 | AH15: =M25+AB19+AB11+AB15 -> 42 | AI15: =N25+AC19+AC11+AC15 -> 5
A17: =AE9 -> Reuben Borg / Erika Azzopardi | B17: 6 | C17: =IF(B17>B19,1,0) -> 1 | E17: 6 | F17: =IF(E17>E19,1,0) -> 1 | I17: =IF(H17>H19,1,0) -> 0 | J17: =IF(B17="",0,1) -> 1 | K17: =IF(C17+F17=2,3,IF(C17+F17=1,1,0)) -> 3 | L17: =IF(K17=3,3,IF(I17+K17=2,2,IF(K17=1,1,0))) -> 3 | M17: =B17+E17 -> 12 | N17: =C17+F17+I17 -> 2 | P17: =AE13 -> Eric Roca / Alison Muscat | Q17: 1 | R17: =IF(Q17>Q19,1,0) -> 0 | T17: 4 | U17: =IF(T17>T19,1,0) -> 0 | X17: =IF(W17>W19,1,0) -> 0 | Y17: =IF(Q17="",0,1) -> 1 | Z17: =IF(R17+U17=2,3,IF(R17+U17=1,1,0)) -> 0 | AA17: =IF(Z17=3,3,IF(X17+Z17=2,2,IF(Z17=1,1,0))) -> 0 | AB17: =Q17+T17 -> 5 | AC17: =R17+U17+X17 -> 0 | AE17: =Players!B10& " / " &Players!C10 -> Duncan D'Alessandro / Anthea Gauci | AF17: =J27+J19+Y27+J23 -> 4 | AG17: =L27+L19+AA27+L23 -> 2 | AH17: =M27+M19+AB27+M23 -> 34 | AI17: =N27+N19+AC27+N23 -> 2
A18: vs. | P18: vs.
A19: =AE17 -> Duncan D'Alessandro / Anthea Gauci | B19: 4 | C19: =IF(B19>B17,1,0) -> 0 | E19: 1 | F19: =IF(E19>E17,1,0) -> 0 | I19: =IF(H19>H17,1,0) -> 0 | J19: =IF(B19="",0,1) -> 1 | K19: =IF(C19+F19=2,3,IF(C19+F19=1,1,0)) -> 0 | L19: =IF(K19=3,3,IF(I19+K19=2,2,IF(K19=1,1,0))) -> 0 | M19: =B19+E19 -> 5 | N19: =C19+F19+I19 -> 0 | P19: =AE15 -> Matthew Mifsud / Lara Pule' | Q19: 6 | R19: =IF(Q19>Q17,1,0) -> 1 | T19: 6 | U19: =IF(T19>T17,1,0) -> 1 | X19: =IF(W19>W17,1,0) -> 0 | Y19: =IF(Q19="",0,1) -> 1 | Z19: =IF(R19+U19=2,3,IF(R19+U19=1,1,0)) -> 3 | AA19: =IF(Z19=3,3,IF(X19+Z19=2,2,IF(Z19=1,1,0))) -> 3 | AB19: =Q19+T19 -> 12 | AC19: =R19+U19+X19 -> 2
A21: =AE13 -> Eric Roca / Alison Muscat | B21: 6 | C21: =IF(B21>B23,1,0) -> 0 | E21: 6 | F21: =IF(E21>E23,1,0) -> 1 | H21: 10 | I21: =IF(H21>H23,1,0) -> 1 | J21: =IF(B21="",0,1) -> 1 | K21: =IF(C21+F21=2,3,IF(C21+F21=1,1,0)) -> 1 | L21: =IF(K21=3,3,IF(I21+K21=2,2,IF(K21=1,1,0))) -> 2 | M21: =B21+E21 -> 12 | N21: =C21+F21+I21 -> 2 | P21: =AE11 -> Adrian Chetcuti / Ann Marie Mangion | Q21: 6 | R21: =IF(Q21>Q23,1,0) -> 1 | T21: 6 | U21: =IF(T21>T23,1,0) -> 1 | X21: =IF(W21>W23,1,0) -> 0 | Y21: =IF(Q21="",0,1) -> 1 | Z21: =IF(R21+U21=2,3,IF(R21+U21=1,1,0)) -> 3 | AA21: =IF(Z21=3,3,IF(X21+Z21=2,2,IF(Z21=1,1,0))) -> 3 | AB21: =Q21+T21 -> 12 | AC21: =R21+U21+X21 -> 2 | AE21: Divison Winner
A22: vs. | P22: vs. | AE22: Adrian Chetcuti/Annemarie Mangion
A23: =AE17 -> Duncan D'Alessandro / Anthea Gauci | B23: 7 | C23: =IF(B23>B21,1,0) -> 1 | E23: 3 | F23: =IF(E23>E21,1,0) -> 0 | H23: 2 | I23: =IF(H23>H21,1,0) -> 0 | J23: =IF(B23="",0,1) -> 1 | K23: =IF(C23+F23=2,3,IF(C23+F23=1,1,0)) -> 1 | L23: =IF(K23=3,3,IF(I23+K23=2,2,IF(K23=1,1,0))) -> 1 | M23: =B23+E23 -> 10 | N23: =C23+F23+I23 -> 1 | P23: =AE13 -> Eric Roca / Alison Muscat | Q23: 1 | R23: =IF(Q23>Q21,1,0) -> 0 | T23: 4 | U23: =IF(T23>T21,1,0) -> 0 | X23: =IF(W23>W21,1,0) -> 0 | Y23: =IF(Q23="",0,1) -> 1 | Z23: =IF(R23+U23=2,3,IF(R23+U23=1,1,0)) -> 0 | AA23: =IF(Z23=3,3,IF(X23+Z23=2,2,IF(Z23=1,1,0))) -> 0 | AB23: =Q23+T23 -> 5 | AC23: =R23+U23+X23 -> 0
A25: =AE15 -> Matthew Mifsud / Lara Pule' | B25: 6 | C25: =IF(B25>B27,1,0) -> 1 | E25: 7 | F25: =IF(E25>E27,1,0) -> 1 | I25: =IF(H25>H27,1,0) -> 0 | J25: =IF(B25="",0,1) -> 1 | K25: =IF(C25+F25=2,3,IF(C25+F25=1,1,0)) -> 3 | L25: =IF(K25=3,3,IF(I25+K25=2,2,IF(K25=1,1,0))) -> 3 | M25: =B25+E25 -> 13 | N25: =C25+F25+I25 -> 2 | P25: =AE11 -> Adrian Chetcuti / Ann Marie Mangion | Q25: 6 | R25: =IF(Q25>Q27,1,0) -> 1 | T25: 6 | U25: =IF(T25>T27,1,0) -> 0 | W25: 10 | X25: =IF(W25>W27,1,0) -> 1 | Y25: =IF(Q25="",0,1) -> 1 | Z25: =IF(R25+U25=2,3,IF(R25+U25=1,1,0)) -> 1 | AA25: =IF(Z25=3,3,IF(X25+Z25=2,2,IF(Z25=1,1,0))) -> 2 | AB25: =Q25+T25 -> 12 | AC25: =R25+U25+X25 -> 2 | AE25: Divison Runner Up
A26: vs. | P26: vs. | AE26: =IF(AL9=20,AN9,"") -> Reuben Borg / Erika Azzopardi
A27: =AE17 -> Duncan D'Alessandro / Anthea Gauci | B27: 3 | C27: =IF(B27>B25,1,0) -> 0 | E27: 6 | F27: =IF(E27>E25,1,0) -> 0 | I27: =IF(H27>H25,1,0) -> 0 | J27: =IF(B27="",0,1) -> 1 | K27: =IF(C27+F27=2,3,IF(C27+F27=1,1,0)) -> 0 | L27: =IF(K27=3,3,IF(I27+K27=2,2,IF(K27=1,1,0))) -> 0 | M27: =B27+E27 -> 9 | N27: =C27+F27+I27 -> 0 | P27: =AE17 -> Duncan D'Alessandro / Anthea Gauci | Q27: 3 | R27: =IF(Q27>Q25,1,0) -> 0 | T27: 7 | U27: =IF(T27>T25,1,0) -> 1 | W27: 5 | X27: =IF(W27>W25,1,0) -> 0 | Y27: =IF(Q27="",0,1) -> 1 | Z27: =IF(R27+U27=2,3,IF(R27+U27=1,1,0)) -> 1 | AA27: =IF(Z27=3,3,IF(X27+Z27=2,2,IF(Z27=1,1,0))) -> 1 | AB27: =Q27+T27 -> 10 | AC27: =R27+U27+X27 -> 1

Sheet Division 2
A1: Elektra Mixed Doubles 2023
A5: Division 2
A7: Players | B7: Set Scores | H7: Tie | P7: Players | Q7: Set Scores | W7: Tie | AE7: Player | AF7: Games | AG7: Points | AH7: Games Won | AI7: Sets Won
B8: Score | C8: Set 1 Work | E8: Score | F8: Set 2 Work | H8: Score | I8: Tie Work | J8: Game Played | K8: Sets Points Work | L8: Sets & Tie Points Work | M8: Games Wins Work | N8: Sets Wins Work | Q8: Score | R8: Set 1 Work | T8: Score | U8: Set 2 Work | W8: Score | X8: Tie Work | Y8: Game Played | Z8: Sets Points Work | AA8: Sets & Tie Points Work | AB8: Games Wins Work | AC8: Sets Wins Work | AJ8: Winner Working | AK8: Runner Up Working | AL8: Total Games Work | AM8: Winner | AN8: Runner Up
A9: =AE9 -> Keith Micallef / Mirka Micallef | B9: 2 | C9: =IF(B9>B11,1,0) -> 0 | E9: 6 | F9: =IF(E9>E11,1,0) -> 1 | H9: 7 | I9: =IF(H9>H11,1,0) -> 0 | J9: =IF(B9="",0,1) -> 1 | K9: =IF(C9+F9=2,3,IF(C9+F9=1,1,0)) -> 1 | L9: =IF(K9=3,3,IF(I9+K9=2,2,IF(K9=1,1,0))) -> 1 | M9: =B9+E9 -> 8 | N9: =C9+F9+I9 -> 1 | P9: =AE9 -> Keith Micallef / Mirka Micallef | Q9: 6 | R9: =IF(Q9>Q11,1,0) -> 1 | T9: 6 | U9: =IF(T9>T11,1,0) -> 1 | X9: =IF(W9>W11,1,0) -> 0 | Y9: =IF(Q9="",0,1) -> 1 | Z9: =IF(R9+U9=2,3,IF(R9+U9=1,1,0)) -> 3 | AA9: =IF(Z9=3,3,IF(X9+Z9=2,2,IF(Z9=1,1,0))) -> 3 | AB9: =Q9+T9 -> 12 | AC9: =R9+U9+X9 -> 2 | AE9: =Players!B13& " / " &Players!C13 -> Keith Micallef / Mirka Micallef | AF9: =J9+Y9+J13+Y13+J17 -> 5 | AG9: =L9+AA9+L13+AA13+L17 -> 8 | AH9: =M9+AB9+M13+AB13+M17 -> 52 | AI9: =N9+AC9+N13+AC13+N17 -> 6 | AJ9: =MAX(AG9:AG19) -> 12 | AK9: =LARGE(AG9:AG19, 2) -> 12 | AL9: =SUM(AF9:AF19) -> 28 | AM9: =IF(AG9=$AJ$9,AE9,IF(AG11=$AJ$9,AE11,IF(AG13=$AJ$9,AE13,IF(AG15=$AJ$9,AE15,IF(AG17=$AJ$9,AE17,IF(AG19=$AJ$9,AE19,"")))))) -> Melchior Farrugia / Doriana Portelli | AN9: =IF(AG9=$AK$9,AE9,IF(AG11=$AK$9,AE11,IF(AG13=$AK$9,AE13,IF(AG15=$AK$9,AE15,IF(AG17=$AK$9,AE17,IF(AG19=$AK$9,AE19,"")))))) -> Melchior Farrugia / Doriana Portelli
A10: vs. | P10: vs.
A11: =AE11 -> Melchior Farrugia / Doriana Portelli | B11: 6 | C11: =IF(B11>B9,1,0) -> 1 | E11: 4 | F11: =IF(E11>E9,1,0) -> 0 | H11: 10 | I11: =IF(H11>H9,1,0) -> 1 | J11: =IF(B11="",0,1) -> 1 | K11: =IF(C11+F11=2,3,IF(C11+F11=1,1,0)) -> 1 | L11: =IF(K11=3,3,IF(I11+K11=2,2,IF(K11=1,1,0))) -> 2 | M11: =B11+E11 -> 10 | N11: =C11+F11+I11 -> 2 | P11: =AE13 -> Adrian Manduca / Julie Spiteri | Q11: 2 | R11: =IF(Q11>Q9,1,0) -> 0 | T11: 3 | U11: =IF(T11>T9,1,0) -> 0 | X11: =IF(W11>W9,1,0) -> 0 | Y11: =IF(Q11="",0,1) -> 1 | Z11: =IF(R11+U11=2,3,IF(R11+U11=1,1,0)) -> 0 | AA11: =IF(Z11=3,3,IF(X11+Z11=2,2,IF(Z11=1,1,0))) -> 0 | AB11: =Q11+T11 -> 5 | AC11: =R11+U11+X11 -> 0 | AE11: =Players!B14& " / " &Players!C14 -> Melchior Farrugia / Doriana Portelli | AF11: =J11+Y25+J21+Y21+Y17 -> 5 | AG11: =L11+AA25+L21+AA21+AA17 -> 12 | AH11: =M11+AB25+M21+AB21+AB17 -> 54 | AI11: =N11+AC25+N21+AC21+AC17 -> 10
A13: =AE9 -> Keith Micallef / Mirka Micallef | B13: 4 | C13: =IF(B13>B15,1,0) -> 0 | E13: 3 | F13: =IF(E13>E15,1,0) -> 0 | I13: =IF(H13>H15,1,0) -> 0 | J13: =IF(B13="",0,1) -> 1 | K13: =IF(C13+F13=2,3,IF(C13+F13=1,1,0)) -> 0 | L13: =IF(K13=3,3,IF(I13+K13=2,2,IF(K13=1,1,0))) -> 0 | M13: =B13+E13 -> 7 | N13: =C13+F13+I13 -> 0 | P13: =AE9 -> Keith Micallef / Mirka Micallef | Q13: 6 | R13: =IF(Q13>Q15,1,0) -> 0 | T13: 6 | U13: =IF(T13>T15,1,0) -> 1 | W13: 7 | X13: =IF(W13>W15,1,0) -> 0 | Y13: =IF(Q13="",0,1) -> 1 | Z13: =IF(R13+U13=2,3,IF(R13+U13=1,1,0)) -> 1 | AA13: =IF(Z13=3,3,IF(X13+Z13=2,2,IF(Z13=1,1,0))) -> 1 | AB13: =Q13+T13 -> 12 | AC13: =R13+U13+X13 -> 1 | AE13: =Players!B15& " / " &Players!C15 -> Adrian Manduca / Julie Spiteri | AF13: =Y29+Y11+Y33+J25+Y19 -> 4 | AG13: =AA29+AA11+AA33+L25+AA19 -> 0 | AH13: =AB29+AB11+AB33+M25+AB19 -> 17 | AI13: =AC29+AC11+AC33+N25+AC19 -> 0
A14: vs. | P14: vs.
A15: =AE15 -> Andrew Pule' / Celeste Zammit Marquette | B15: 6 | C15: =IF(B15>B13,1,0) -> 1 | E15: 6 | F15: =IF(E15>E13,1,0) -> 1 | I15: =IF(H15>H13,1,0) -> 0 | J15: =IF(B15="",0,1) -> 1 | K15: =IF(C15+F15=2,3,IF(C15+F15=1,1,0)) -> 3 | L15: =IF(K15=3,3,IF(I15+K15=2,2,IF(K15=1,1,0))) -> 3 | M15: =B15+E15 -> 12 | N15: =C15+F15+I15 -> 2 | P15: =AE17 -> Daniel Falzon / Amanda Falzon | Q15: 7 | R15: =IF(Q15>Q13,1,0) -> 1 | T15: 0 | U15: =IF(T15>T13,1,0) -> 0 | W15: 10 | X15: =IF(W15>W13,1,0) -> 1 | Y15: =IF(Q15="",0,1) -> 1 | Z15: =IF(R15+U15=2,3,IF(R15+U15=1,1,0)) -> 1 | AA15: =IF(Z15=3,3,IF(X15+Z15=2,2,IF(Z15=1,1,0))) -> 2 | AB15: =Q15+T15 -> 7 | AC15: =R15+U15+X15 -> 2 | AE15: =Players!B16& " / " &Players!C16 -> Andrew Pule' / Celeste Zammit Marquette | AF15: =Y31+J37+J15+Y23+J29 -> 5 | AG15: =AA31+L37+L15+AA23+L29 -> 12 | AH15: =AB31+M37+M15+AB23+M29 -> 58 | AI15: =AC31+N37+N15+AC23+N29 -> 8
A17: =AE9 -> Keith Micallef / Mirka Micallef | B17: 6 | C17: =IF(B17>B19,1,0) -> 1 | E17: 7 | F17: =IF(E17>E19,1,0) -> 1 | I17: =IF(H17>H19,1,0) -> 0 | J17: =IF(B17="",0,1) -> 1 | K17: =IF(C17+F17=2,3,IF(C17+F17=1,1,0)) -> 3 | L17: =IF(K17=3,3,IF(I17+K17=2,2,IF(K17=1,1,0))) -> 3 | M17: =B17+E17 -> 13 | N17: =C17+F17+I17 -> 2 | P17: =AE11 -> Melchior Farrugia / Doriana Portelli | Q17: 6 | R17: =IF(Q17>Q19,1,0) -> 1 | T17: 6 | U17: =IF(T17>T19,1,0) -> 1 | X17: =IF(W17>W19,1,0) -> 0 | Y17: =IF(Q17="",0,1) -> 1 | Z17: =IF(R17+U17=2,3,IF(R17+U17=1,1,0)) -> 3 | AA17: =IF(Z17=3,3,IF(X17+Z17=2,2,IF(Z17=1,1,0))) -> 3 | AB17: =Q17+T17 -> 12 | AC17: =R17+U17+X17 -> 2 | AE17: =Players!B17& " / " &Players!C17 -> Daniel Falzon / Amanda Falzon | AF17: =J33+J39+J23+Y15+J27 -> 4 | AG17: =L33+L39+L23+AA15+L27 -> 3 | AH17: =M33+M39+M23+AB15+M27 -> 29 | AI17: =N33+N39+N23+AC15+N27 -> 3
A18: vs. | P18: vs.
A19: =AE19 -> Manuel Bonello / Alexia Meilak Gouder | B19: 4 | C19: =IF(B19>B17,1,0) -> 0 | E19: 5 | F19: =IF(E19>E17,1,0) -> 0 | I19: =IF(H19>H17,1,0) -> 0 | J19: =IF(B19="",0,1) -> 1 | K19: =IF(C19+F19=2,3,IF(C19+F19=1,1,0)) -> 0 | L19: =IF(K19=3,3,IF(I19+K19=2,2,IF(K19=1,1,0))) -> 0 | M19: =B19+E19 -> 9 | N19: =C19+F19+I19 -> 0 | P19: =AE13 -> Adrian Manduca / Julie Spiteri | Q19: 2 | R19: =IF(Q19>Q17,1,0) -> 0 | T19: 1 | U19: =IF(T19>T17,1,0) -> 0 | X19: =IF(W19>W17,1,0) -> 0 | Y19: =IF(Q19="",0,1) -> 1 | Z19: =IF(R19+U19=2,3,IF(R19+U19=1,1,0)) -> 0 | AA19: =IF(Z19=3,3,IF(X19+Z19=2,2,IF(Z19=1,1,0))) -> 0 | AB19: =Q19+T19 -> 3 | AC19: =R19+U19+X19 -> 0 | AE19: =Players!B18& " / " &Players!C18 -> Manuel Bonello / Alexia Meilak Gouder | AF19: =J35+Y27+Y35+J19+J31 -> 5 | AG19: =L35+AA27+AA35+L19+L31 -> 7 | AH19: =M35+AB27+AB35+M19+M31 -> 52 | AI19: =N35+AC27+AC35+N19+N31 -> 5
A21: =AE11 -> Melchior Farrugia / Doriana Portelli | B21: 6 | C21: =IF(B21>B23,1,0) -> 1 | E21: 4 | F21: =IF(E21>E23,1,0) -> 0 | H21: 10 | I21: =IF(H21>H23,1,0) -> 1 | J21: =IF(B21="",0,1) -> 1 | K21: =IF(C21+F21=2,3,IF(C21+F21=1,1,0)) -> 1 | L21: =IF(K21=3,3,IF(I21+K21=2,2,IF(K21=1,1,0))) -> 2 | M21: =B21+E21 -> 10 | N21: =C21+F21+I21 -> 2 | P21: =AE11 -> Melchior Farrugia / Doriana Portelli | Q21: 7 | R21: =IF(Q21>Q23,1,0) -> 1 | T21: 6 | U21: =IF(T21>T23,1,0) -> 1 | X21: =IF(W21>W23,1,0) -> 0 | Y21: =IF(Q21="",0,1) -> 1 | Z21: =IF(R21+U21=2,3,IF(R21+U21=1,1,0)) -> 3 | AA21: =IF(Z21=3,3,IF(X21+Z21=2,2,IF(Z21=1,1,0))) -> 3 | AB21: =Q21+T21 -> 13 | AC21: =R21+U21+X21 -> 2 | AE21: Divison Winner
A22: vs. | P22: vs. | AE22: Melchior Farrugia/Doriana Portellil
A23: =AE17 -> Daniel Falzon / Amanda Falzon | B23: 1 | C23: =IF(B23>B21,1,0) -> 0 | E23: 6 | F23: =IF(E23>E21,1,0) -> 1 | H23: 3 | I23: =IF(H23>H21,1,0) -> 0 | J23: =IF(B23="",0,1) -> 1 | K23: =IF(C23+F23=2,3,IF(C23+F23=1,1,0)) -> 1 | L23: =IF(K23=3,3,IF(I23+K23=2,2,IF(K23=1,1,0))) -> 1 | M23: =B23+E23 -> 7 | N23: =C23+F23+I23 -> 1 | P23: =AE15 -> Andrew Pule' / Celeste Zammit Marquette | Q23: 5 | R23: =IF(Q23>Q21,1,0) -> 0 | T23: 3 | U23: =IF(T23>T21,1,0) -> 0 | X23: =IF(W23>W21,1,0) -> 0 | Y23: =IF(Q23="",0,1) -> 1 | Z23: =IF(R23+U23=2,3,IF(R23+U23=1,1,0)) -> 0 | AA23: =IF(Z23=3,3,IF(X23+Z23=2,2,IF(Z23=1,1,0))) -> 0 | AB23: =Q23+T23 -> 8 | AC23: =R23+U23+X23 -> 0
A25: =AE13 -> Adrian Manduca / Julie Spiteri | C25: =IF(B25>B27,1,0) -> 0 | F25: =IF(E25>E27,1,0) -> 0 | I25: =IF(H25>H27,1,0) -> 0 | J25: =IF(B25="",0,1) -> 0 | K25: =IF(C25+F25=2,3,IF(C25+F25=1,1,0)) -> 0 | L25: =IF(K25=3,3,IF(I25+K25=2,2,IF(K25=1,1,0))) -> 0 | M25: =B25+E25 -> 0 | N25: =C25+F25+I25 -> 0 | P25: =AE11 -> Melchior Farrugia / Doriana Portelli | Q25: 6 | R25: =IF(Q25>Q27,1,0) -> 1 | T25: 3 | U25: =IF(T25>T27,1,0) -> 0 | W25: 10 | X25: =IF(W25>W27,1,0) -> 1 | Y25: =IF(Q25="",0,1) -> 1 | Z25: =IF(R25+U25=2,3,IF(R25+U25=1,1,0)) -> 1 | AA25: =IF(Z25=3,3,IF(X25+Z25=2,2,IF(Z25=1,1,0))) -> 2 | AB25: =Q25+T25 -> 9 | AC25: =R25+U25+X25 -> 2 | AE25: Divison Runner Up
A26: vs. | P26: vs. | AE26: Andrew Pule'/Celeste Zammit Marquette
A27: =AE17 -> Daniel Falzon / Amanda Falzon | C27: =IF(B27>B25,1,0) -> 0 | F27: =IF(E27>E25,1,0) -> 0 | I27: =IF(H27>H25,1,0) -> 0 | J27: =IF(B27="",0,1) -> 0 | K27: =IF(C27+F27=2,3,IF(C27+F27=1,1,0)) -> 0 | L27: =IF(K27=3,3,IF(I27+K27=2,2,IF(K27=1,1,0))) -> 0 | M27: =B27+E27 -> 0 | N27: =C27+F27+I27 -> 0 | P27: =AE19 -> Manuel Bonello / Alexia Meilak Gouder | Q27: 4 | R27: =IF(Q27>Q25,1,0) -> 0 | T27: 6 | U27: =IF(T27>T25,1,0) -> 1 | W27: 6 | X27: =IF(W27>W25,1,0) -> 0 | Y27: =IF(Q27="",0,1) -> 1 | Z27: =IF(R27+U27=2,3,IF(R27+U27=1,1,0)) -> 1 | AA27: =IF(Z27=3,3,IF(X27+Z27=2,2,IF(Z27=1,1,0))) -> 1 | AB27: =Q27+T27 -> 10 | AC27: =R27+U27+X27 -> 1
A29: =AE15 -> Andrew Pule' / Celeste Zammit Marquette | B29: 7 | C29: =IF(B29>B31,1,0) -> 1 | E29: 6 | F29: =IF(E29>E31,1,0) -> 1 | I29: =IF(H29>H31,1,0) -> 0 | J29: =IF(B29="",0,1) -> 1 | K29: =IF(C29+F29=2,3,IF(C29+F29=1,1,0)) -> 3 | L29: =IF(K29=3,3,IF(I29+K29=2,2,IF(K29=1,1,0))) -> 3 | M29: =B29+E29 -> 13 | N29: =C29+F29+I29 -> 2 | P29: =AE13 -> Adrian Manduca / Julie Spiteri | Q29: 2 | R29: =IF(Q29>Q31,1,0) -> 0 | T29: 5 | U29: =IF(T29>T31,1,0) -> 0 | X29: =IF(W29>W31,1,0) -> 0 | Y29: =IF(Q29="",0,1) -> 1 | Z29: =IF(R29+U29=2,3,IF(R29+U29=1,1,0)) -> 0 | AA29: =IF(Z29=3,3,IF(X29+Z29=2,2,IF(Z29=1,1,0))) -> 0 | AB29: =Q29+T29 -> 7 | AC29: =R29+U29+X29 -> 0
A30: vs. | P30: vs.
A31: =AE19 -> Manuel Bonello / Alexia Meilak Gouder | B31: 5 | C31: =IF(B31>B29,1,0) -> 0 | E31: 3 | F31: =IF(E31>E29,1,0) -> 0 | I31: =IF(H31>H29,1,0) -> 0 | J31: =IF(B31="",0,1) -> 1 | K31: =IF(C31+F31=2,3,IF(C31+F31=1,1,0)) -> 0 | L31: =IF(K31=3,3,IF(I31+K31=2,2,IF(K31=1,1,0))) -> 0 | M31: =B31+E31 -> 8 | N31: =C31+F31+I31 -> 0 | P31: =AE15 -> Andrew Pule' / Celeste Zammit Marquette | Q31: 6 | R31: =IF(Q31>Q29,1,0) -> 1 | T31: 7 | U31: =IF(T31>T29,1,0) -> 1 | X31: =IF(W31>W29,1,0) -> 0 | Y31: =IF(Q31="",0,1) -> 1 | Z31: =IF(R31+U31=2,3,IF(R31+U31=1,1,0)) -> 3 | AA31: =IF(Z31=3,3,IF(X31+Z31=2,2,IF(Z31=1,1,0))) -> 3 | AB31: =Q31+T31 -> 13 | AC31: =R31+U31+X31 -> 2
A33: =AE17 -> Daniel Falzon / Amanda Falzon | B33: 3 | C33: =IF(B33>B35,1,0) -> 0 | E33: 5 | F33: =IF(E33>E35,1,0) -> 0 | I33: =IF(H33>H35,1,0) -> 0 | J33: =IF(B33="",0,1) -> 1 | K33: =IF(C33+F33=2,3,IF(C33+F33=1,1,0)) -> 0 | L33: =IF(K33=3,3,IF(I33+K33=2,2,IF(K33=1,1,0))) -> 0 | M33: =B33+E33 -> 8 | N33: =C33+F33+I33 -> 0 | P33: =AE13 -> Adrian Manduca / Julie Spiteri | Q33: 1 | R33: =IF(Q33>Q35,1,0) -> 0 | T33: 1 | U33: =IF(T33>T35,1,0) -> 0 | X33: =IF(W33>W35,1,0) -> 0 | Y33: =IF(Q33="",0,1) -> 1 | Z33: =IF(R33+U33=2,3,IF(R33+U33=1,1,0)) -> 0 | AA33: =IF(Z33=3,3,IF(X33+Z33=2,2,IF(Z33=1,1,0))) -> 0 | AB33: =Q33+T33 -> 2 | AC33: =R33+U33+X33 -> 0
A34: vs. | P34: vs.
A35: =AE19 -> Manuel Bonello / Alexia Meilak Gouder | B35: 6 | C35: =IF(B35>B33,1,0) -> 1 | E35: 7 | F35: =IF(E35>E33,1,0) -> 1 | I35: =IF(H35>H33,1,0) -> 0 | J35: =IF(B35="",0,1) -> 1 | K35: =IF(C35+F35=2,3,IF(C35+F35=1,1,0)) -> 3 | L35: =IF(K35=3,3,IF(I35+K35=2,2,IF(K35=1,1,0))) -> 3 | M35: =B35+E35 -> 13 | N35: =C35+F35+I35 -> 2 | P35: =AE19 -> Manuel Bonello / Alexia Meilak Gouder | Q35: 6 | R35: =IF(Q35>Q33,1,0) -> 1 | T35: 6 | U35: =IF(T35>T33,1,0) -> 1 | X35: =IF(W35>W33,1,0) -> 0 | Y35: =IF(Q35="",0,1) -> 1 | Z35: =IF(R35+U35=2,3,IF(R35+U35=1,1,0)) -> 3 | AA35: =IF(Z35=3,3,IF(X35+Z35=2,2,IF(Z35=1,1,0))) -> 3 | AB35: =Q35+T35 -> 12 | AC35: =R35+U35+X35 -> 2
A37: =AE15 -> Andrew Pule' / Celeste Zammit Marquette | B37: 6 | C37: =IF(B37>B39,1,0) -> 1 | E37: 6 | F37: =IF(E37>E39,1,0) -> 1 | I37: =IF(H37>H39,1,0) -> 0 | J37: =IF(B37="",0,1) -> 1 | K37: =IF(C37+F37=2,3,IF(C37+F37=1,1,0)) -> 3 | L37: =IF(K37=3,3,IF(I37+K37=2,2,IF(K37=1,1,0))) -> 3 | M37: =B37+E37 -> 12 | N37: =C37+F37+I37 -> 2
A38: vs.
A39: =AE17 -> Daniel Falzon / Amanda Falzon | B39: 3 | C39: =IF(B39>B37,1,0) -> 0 | E39: 4 | F39: =IF(E39>E37,1,0) -> 0 | I39: =IF(H39>H37,1,0) -> 0 | J39: =IF(B39="",0,1) -> 1 | K39: =IF(C39+F39=2,3,IF(C39+F39=1,1,0)) -> 0 | L39: =IF(K39=3,3,IF(I39+K39=2,2,IF(K39=1,1,0))) -> 0 | M39: =B39+E39 -> 7 | N39: =C39+F39+I39 -> 0

Sheet Division 3
A1: Elektra Mixed Doubles 2023
A5: Division 3
A7: Players | B7: Set Scores | H7: Tie | P7: Players | Q7: Set Scores | W7: Tie | AE7: Player | AF7: Games | AG7: Points | AH7: Games Won | AI7: Sets Won
B8: Score | C8: Set 1 Work | E8: Score | F8: Set 2 Work | H8: Score | I8: Tie Work | J8: Game Played | K8: Sets Points Work | L8: Sets & Tie Points Work | M8: Games Wins Work | N8: Sets Wins Work | Q8: Score | R8: Set 1 Work | T8: Score | U8: Set 2 Work | W8: Score | X8: Tie Work | Y8: Game Played | Z8: Sets Points Work | AA8: Sets & Tie Points Work | AB8: Games Wins Work | AC8: Sets Wins Work | AJ8: Winner Working | AK8: Runner Up Working | AL8: Total Games Work | AM8: Winner | AN8: Runner Up
A9: =AE9 -> Gio Marcos / Jennifer Roca | B9: 4 | C9: =IF(B9>B11,1,0) -> 0 | E9: 3 | F9: =IF(E9>E11,1,0) -> 0 | I9: =IF(H9>H11,1,0) -> 0 | J9: =IF(B9="",0,1) -> 1 | K9: =IF(C9+F9=2,3,IF(C9+F9=1,1,0)) -> 0 | L9: =IF(K9=3,3,IF(I9+K9=2,2,IF(K9=1,1,0))) -> 0 | M9: =B9+E9 -> 7 | N9: =C9+F9+I9 -> 0 | P9: =AE9 -> Gio Marcos / Jennifer Roca | Q9: 6 | R9: =IF(Q9>Q11,1,0) -> 1 | T9: 4 | U9: =IF(T9>T11,1,0) -> 0 | W9: 10 | X9: =IF(W9>W11,1,0) -> 1 | Y9: =IF(Q9="",0,1) -> 1 | Z9: =IF(R9+U9=2,3,IF(R9+U9=1,1,0)) -> 1 | AA9: =IF(Z9=3,3,IF(X9+Z9=2,2,IF(Z9=1,1,0))) -> 2 | AB9: =Q9+T9 -> 10 | AC9: =R9+U9+X9 -> 2 | AE9: =Players!B21& " / " &Players!C21 -> Gio Marcos / Jennifer Roca | AF9: =J9+Y9+J13+Y13 -> 4 | AG9: =L9+AA9+L13+AA13 -> 6 | AH9: =M9+AB9+M13+AB13 -> 40 | AI9: =N9+AC9+N13+AC13 -> 5 | AJ9: =MAX(AG9:AG17) -> 10 | AK9: =LARGE(AG9:AG17, 2) -> 7 | AL9: =SUM(AF9:AF17) -> 20 | AM9: =IF(AG9=$AJ$9,AE9,IF(AG11=$AJ$9,AE11,IF(AG13=$AJ$9,AE13,IF(AG15=$AJ$9,AE15,IF(AG17=$AJ$9,AE17,""))))) -> Chi Chi Canonce / Yana Cachia | AN9: =IF(AG9=$AK$9,AE9,IF(AG11=$AK$9,AE11,IF(AG13=$AK$9,AE13,IF(AG15=$AK$9,AE15,IF(AG17=$AK$9,AE17,""))))) -> Gabriel Pace / Kelsey Gauci
A10: vs. | P10: vs.
A11: =AE11 -> Gabriel Pace / Kelsey Gauci | B11: 6 | C11: =IF(B11>B9,1,0) -> 1 | E11: 6 | F11: =IF(E11>E9,1,0) -> 1 | I11: =IF(H11>H9,1,0) -> 0 | J11: =IF(B11="",0,1) -> 1 | K11: =IF(C11+F11=2,3,IF(C11+F11=1,1,0)) -> 3 | L11: =IF(K11=3,3,IF(I11+K11=2,2,IF(K11=1,1,0))) -> 3 | M11: =B11+E11 -> 12 | N11: =C11+F11+I11 -> 2 | P11: =AE13 -> Cristian Andreozzi / Luiza Andreozzi | Q11: 3 | R11: =IF(Q11>Q9,1,0) -> 0 | T11: 6 | U11: =IF(T11>T9,1,0) -> 1 | W11: 6 | X11: =IF(W11>W9,1,0) -> 0 | Y11: =IF(Q11="",0,1) -> 1 | Z11: =IF(R11+U11=2,3,IF(R11+U11=1,1,0)) -> 1 | AA11: =IF(Z11=3,3,IF(X11+Z11=2,2,IF(Z11=1,1,0))) -> 1 | AB11: =Q11+T11 -> 9 | AC11: =R11+U11+X11 -> 1 | AE11: =Players!B22& " / " &Players!C22 -> Gabriel Pace / Kelsey Gauci | AF11: =J11+J21+Y17+J17 -> 4 | AG11: =L11+L21+AA17+L17 -> 7 | AH11: =M11+M21+AB17+M17 -> 34 | AI11: =N11+N21+AC17+N17 -> 5
A13: =AE9 -> Gio Marcos / Jennifer Roca | B13: 7 | C13: =IF(B13>B15,1,0) -> 1 | E13: 6 | F13: =IF(E13>E15,1,0) -> 1 | I13: =IF(H13>H15,1,0) -> 0 | J13: =IF(B13="",0,1) -> 1 | K13: =IF(C13+F13=2,3,IF(C13+F13=1,1,0)) -> 3 | L13: =IF(K13=3,3,IF(I13+K13=2,2,IF(K13=1,1,0))) -> 3 | M13: =B13+E13 -> 13 | N13: =C13+F13+I13 -> 2 | P13: =AE9 -> Gio Marcos / Jennifer Roca | Q13: 6 | R13: =IF(Q13>Q15,1,0) -> 1 | T13: 4 | U13: =IF(T13>T15,1,0) -> 0 | W13: 7 | X13: =IF(W13>W15,1,0) -> 0 | Y13: =IF(Q13="",0,1) -> 1 | Z13: =IF(R13+U13=2,3,IF(R13+U13=1,1,0)) -> 1 | AA13: =IF(Z13=3,3,IF(X13+Z13=2,2,IF(Z13=1,1,0))) -> 1 | AB13: =Q13+T13 -> 10 | AC13: =R13+U13+X13 -> 1 | AE13: =Players!B23& " / " &Players!C23 -> Cristian Andreozzi / Luiza Andreozzi | AF13: =Y21+Y11+J25+J19 -> 4 | AG13: =AA21+AA11+L25+L19 -> 7 | AH13: =AB21+AB11+M25+M19 -> 40 | AI13: =AC21+AC11+N25+N19 -> 6
A14: vs. | O14: Ret | P14: vs.
A15: =AE15 -> George Grech / Rowena Caruana | B15: 5 | C15: =IF(B15>B13,1,0) -> 0 | E15: 0 | F15: =IF(E15>E13,1,0) -> 0 | I15: =IF(H15>H13,1,0) -> 0 | J15: =IF(B15="",0,1) -> 1 | K15: =IF(C15+F15=2,3,IF(C15+F15=1,1,0)) -> 0 | L15: =IF(K15=3,3,IF(I15+K15=2,2,IF(K15=1,1,0))) -> 0 | M15: =B15+E15 -> 5 | N15: =C15+F15+I15 -> 0 | P15: =AE17 -> Chi Chi Canonce / Yana Cachia | Q15: 3 | R15: =IF(Q15>Q13,1,0) -> 0 | T15: 6 | U15: =IF(T15>T13,1,0) -> 1 | W15: 10 | X15: =IF(W15>W13,1,0) -> 1 | Y15: =IF(Q15="",0,1) -> 1 | Z15: =IF(R15+U15=2,3,IF(R15+U15=1,1,0)) -> 1 | AA15: =IF(Z15=3,3,IF(X15+Z15=2,2,IF(Z15=1,1,0))) -> 2 | AB15: =Q15+T15 -> 9 | AC15: =R15+U15+X15 -> 2 | AE15: =Players!B24& " / " &Players!C24 -> George Grech / Rowena Caruana | AF15: =Y23+J29+J15+Y19 -> 4 | AG15: =AA23+L29+L15+AA19 -> 0 | AH15: =AB23+M29+M15+AB19 -> 18 | AI15: =AC23+N29+N15+AC19 -> 0
A17: =AE11 -> Gabriel Pace / Kelsey Gauci | B17: 6 | C17: =IF(B17>B19,1,0) -> 1 | E17: 3 | F17: =IF(E17>E19,1,0) -> 0 | H17: 4 | I17: =IF(H17>H19,1,0) -> 0 | J17: =IF(B17="",0,1) -> 1 | K17: =IF(C17+F17=2,3,IF(C17+F17=1,1,0)) -> 1 | L17: =IF(K17=3,3,IF(I17+K17=2,2,IF(K17=1,1,0))) -> 1 | M17: =B17+E17 -> 9 | N17: =C17+F17+I17 -> 1 | P17: =AE11 -> Gabriel Pace / Kelsey Gauci | Q17: 6 | R17: =IF(Q17>Q19,1,0) -> 1 | T17: 6 | U17: =IF(T17>T19,1,0) -> 1 | X17: =IF(W17>W19,1,0) -> 0 | Y17: =IF(Q17="",0,1) -> 1 | Z17: =IF(R17+U17=2,3,IF(R17+U17=1,1,0)) -> 3 | AA17: =IF(Z17=3,3,IF(X17+Z17=2,2,IF(Z17=1,1,0))) -> 3 | AB17: =Q17+T17 -> 12 | AC17: =R17+U17+X17 -> 2 | AE17: =Players!B25& " / " &Players!C25 -> Chi Chi Canonce / Yana Cachia | AF17: =J31+J23+Y15+J27 -> 4 | AG17: =L31+L23+AA15+L27 -> 10 | AH17: =M31+M23+AB15+M27 -> 41 | AI17: =N31+N23+AC15+N27 -> 8
A18: vs. | P18: vs.
A19: =AE13 -> Cristian Andreozzi / Luiza Andreozzi | B19: 4 | C19: =IF(B19>B17,1,0) -> 0 | E19: 6 | F19: =IF(E19>E17,1,0) -> 1 | H19: 10 | I19: =IF(H19>H17,1,0) -> 1 | J19: =IF(B19="",0,1) -> 1 | K19: =IF(C19+F19=2,3,IF(C19+F19=1,1,0)) -> 1 | L19: =IF(K19=3,3,IF(I19+K19=2,2,IF(K19=1,1,0))) -> 2 | M19: =B19+E19 -> 10 | N19: =C19+F19+I19 -> 2 | P19: =AE15 -> George Grech / Rowena Caruana | Q19: 2 | R19: =IF(Q19>Q17,1,0) -> 0 | T19: 4 | U19: =IF(T19>T17,1,0) -> 0 | X19: =IF(W19>W17,1,0) -> 0 | Y19: =IF(Q19="",0,1) -> 1 | Z19: =IF(R19+U19=2,3,IF(R19+U19=1,1,0)) -> 0 | AA19: =IF(Z19=3,3,IF(X19+Z19=2,2,IF(Z19=1,1,0))) -> 0 | AB19: =Q19+T19 -> 6 | AC19: =R19+U19+X19 -> 0
A21: =AE11 -> Gabriel Pace / Kelsey Gauci | B21: 0 | C21: =IF(B21>B23,1,0) -> 0 | E21: 1 | F21: =IF(E21>E23,1,0) -> 0 | I21: =IF(H21>H23,1,0) -> 0 | J21: =IF(B21="",0,1) -> 1 | K21: =IF(C21+F21=2,3,IF(C21+F21=1,1,0)) -> 0 | L21: =IF(K21=3,3,IF(I21+K21=2,2,IF(K21=1,1,0))) -> 0 | M21: =B21+E21 -> 1 | N21: =C21+F21+I21 -> 0 | P21: =AE13 -> Cristian Andreozzi / Luiza Andreozzi | Q21: 6 | R21: =IF(Q21>Q23,1,0) -> 1 | T21: 6 | U21: =IF(T21>T23,1,0) -> 1 | X21: =IF(W21>W23,1,0) -> 0 | Y21: =IF(Q21="",0,1) -> 1 | Z21: =IF(R21+U21=2,3,IF(R21+U21=1,1,0)) -> 3 | AA21: =IF(Z21=3,3,IF(X21+Z21=2,2,IF(Z21=1,1,0))) -> 3 | AB21: =Q21+T21 -> 12 | AC21: =R21+U21+X21 -> 2 | AE21: Divison Winner
A22: vs. | P22: vs. | AE22: =IF(AL9=20,AM9,"") -> Chi Chi Canonce / Yana Cachia
A23: =AE17 -> Chi Chi Canonce / Yana Cachia | B23: 6 | C23: =IF(B23>B21,1,0) -> 1 | E23: 6 | F23: =IF(E23>E21,1,0) -> 1 | I23: =IF(H23>H21,1,0) -> 0 | J23: =IF(B23="",0,1) -> 1 | K23: =IF(C23+F23=2,3,IF(C23+F23=1,1,0)) -> 3 | L23: =IF(K23=3,3,IF(I23+K23=2,2,IF(K23=1,1,0))) -> 3 | M23: =B23+E23 -> 12 | N23: =C23+F23+I23 -> 2 | P23: =AE15 -> George Grech / Rowena Caruana | Q23: 0 | R23: =IF(Q23>Q21,1,0) -> 0 | T23: 3 | U23: =IF(T23>T21,1,0) -> 0 | X23: =IF(W23>W21,1,0) -> 0 | Y23: =IF(Q23="",0,1) -> 1 | Z23: =IF(R23+U23=2,3,IF(R23+U23=1,1,0)) -> 0 | AA23: =IF(Z23=3,3,IF(X23+Z23=2,2,IF(Z23=1,1,0))) -> 0 | AB23: =Q23+T23 -> 3 | AC23: =R23+U23+X23 -> 0
A25: =AE13 -> Cristian Andreozzi / Luiza Andreozzi | B25: 3 | C25: =IF(B25>B27,1,0) -> 0 | E25: 6 | F25: =IF(E25>E27,1,0) -> 1 | H25: 9 | I25: =IF(H25>H27,1,0) -> 0 | J25: =IF(B25="",0,1) -> 1 | K25: =IF(C25+F25=2,3,IF(C25+F25=1,1,0)) -> 1 | L25: =IF(K25=3,3,IF(I25+K25=2,2,IF(K25=1,1,0))) -> 1 | M25: =B25+E25 -> 9 | N25: =C25+F25+I25 -> 1 | AE25: Divison Runner Up
A26: vs. | AE26: Cristian Andreozzi/Luiza Andreozzi
A27: =AE17 -> Chi Chi Canonce / Yana Cachia | B27: 6 | C27: =IF(B27>B25,1,0) -> 1 | E27: 2 | F27: =IF(E27>E25,1,0) -> 0 | H27: 11 | I27: =IF(H27>H25,1,0) -> 1 | J27: =IF(B27="",0,1) -> 1 | K27: =IF(C27+F27=2,3,IF(C27+F27=1,1,0)) -> 1 | L27: =IF(K27=3,3,IF(I27+K27=2,2,IF(K27=1,1,0))) -> 2 | M27: =B27+E27 -> 8 | N27: =C27+F27+I27 -> 2
A29: =AE15 -> George Grech / Rowena Caruana | B29: 3 | C29: =IF(B29>B31,1,0) -> 0 | E29: 1 | F29: =IF(E29>E31,1,0) -> 0 | I29: =IF(H29>H31,1,0) -> 0 | J29: =IF(B29="",0,1) -> 1 | K29: =IF(C29+F29=2,3,IF(C29+F29=1,1,0)) -> 0 | L29: =IF(K29=3,3,IF(I29+K29=2,2,IF(K29=1,1,0))) -> 0 | M29: =B29+E29 -> 4 | N29: =C29+F29+I29 -> 0
A30: vs.
A31: =AE17 -> Chi Chi Canonce / Yana Cachia | B31: 6 | C31: =IF(B31>B29,1,0) -> 1 | E31: 6 | F31: =IF(E31>E29,1,0) -> 1 | I31: =IF(H31>H29,1,0) -> 0 | J31: =IF(B31="",0,1) -> 1 | K31: =IF(C31+F31=2,3,IF(C31+F31=1,1,0)) -> 3 | L31: =IF(K31=3,3,IF(I31+K31=2,2,IF(K31=1,1,0))) -> 3 | M31: =B31+E31 -> 12 | N31: =C31+F31+I31 -> 2

Sheet Division 4
A1: Elektra Mixed Doubles 2023
A5: Division 4
A7: Players | B7: Set Scores | H7: Tie | P7: Players | Q7: Set Scores | W7: Tie | AE7: Player | AF7: Games | AG7: Points | AH7: Games Won | AI7: Sets Won
B8: Score | C8: Set 1 Work | E8: Score | F8: Set 2 Work | H8: Score | I8: Tie Work | J8: Game Played | K8: Sets Points Work | L8: Sets & Tie Points Work | M8: Games Wins Work | N8: Sets Wins Work | Q8: Score | R8: Set 1 Work | T8: Score | U8: Set 2 Work | W8: Score | X8: Tie Work | Y8: Game Played | Z8: Sets Points Work | AA8: Sets & Tie Points Work | AB8: Games Wins Work | AC8: Sets Wins Work | AJ8: Winner Working | AK8: Runner Up Working | AL8: Total Games Work | AM8: Winner | AN8: Runner Up
A9: =AE9 -> Willem Steenkamer / Mariska Steenkamer | B9: 6 | C9: =IF(B9>B11,1,0) -> 1 | E9: 6 | F9: =IF(E9>E11,1,0) -> 0 | H9: 4 | I9: =IF(H9>H11,1,0) -> 0 | J9: =IF(B9="",0,1) -> 1 | K9: =IF(C9+F9=2,3,IF(C9+F9=1,1,0)) -> 1 | L9: =IF(K9=3,3,IF(I9+K9=2,2,IF(K9=1,1,0))) -> 1 | M9: =B9+E9 -> 12 | N9: =C9+F9+I9 -> 1 | P9: =AE9 -> Willem Steenkamer / Mariska Steenkamer | Q9: 6 | R9: =IF(Q9>Q11,1,0) -> 1 | T9: 4 | U9: =IF(T9>T11,1,0) -> 0 | W9: 13 | X9: =IF(W9>W11,1,0) -> 1 | Y9: =IF(Q9="",0,1) -> 1 | Z9: =IF(R9+U9=2,3,IF(R9+U9=1,1,0)) -> 1 | AA9: =IF(Z9=3,3,IF(X9+Z9=2,2,IF(Z9=1,1,0))) -> 2 | AB9: =Q9+T9 -> 10 | AC9: =R9+U9+X9 -> 2 | AE9: =Players!B28& " / " &Players!C28 -> Willem Steenkamer / Mariska Steenkamer | AF9: =J9+Y9+J13+Y13+J17 -> 5 | AG9: =L9+AA9+L13+AA13+L17 -> 10 | AH9: =M9+AB9+M13+AB13+M17 -> 58 | AI9: =N9+AC9+N13+AC13+N17 -> 8 | AJ9: =MAX(AG9:AG19) -> 14 | AK9: =LARGE(AG9:AG19, 2) -> 10 | AL9: =SUM(AF9:AF19) -> 28 | AM9: =IF(AG9=$AJ$9,AE9,IF(AG11=$AJ$9,AE11,IF(AG13=$AJ$9,AE13,IF(AG15=$AJ$9,AE15,IF(AG17=$AJ$9,AE17,IF(AG19=$AJ$9,AE19,"")))))) -> James Farrugia / Nancy Wong | AN9: =IF(AG9=$AK$9,AE9,IF(AG11=$AK$9,AE11,IF(AG13=$AK$9,AE13,IF(AG15=$AK$9,AE15,IF(AG17=$AK$9,AE17,IF(AG19=$AK$9,AE19,"")))))) -> Willem Steenkamer / Mariska Steenkamer
A10: vs. | P10: vs.
A11: =AE11 -> James Farrugia / Nancy Wong | B11: 4 | C11: =IF(B11>B9,1,0) -> 0 | E11: 7 | F11: =IF(E11>E9,1,0) -> 1 | H11: 10 | I11: =IF(H11>H9,1,0) -> 1 | J11: =IF(B11="",0,1) -> 1 | K11: =IF(C11+F11=2,3,IF(C11+F11=1,1,0)) -> 1 | L11: =IF(K11=3,3,IF(I11+K11=2,2,IF(K11=1,1,0))) -> 2 | M11: =B11+E11 -> 11 | N11: =C11+F11+I11 -> 2 | P11: =AE13 -> Kristen Cachia / Francesca Sciortino | Q11: 0 | R11: =IF(Q11>Q9,1,0) -> 0 | T11: 6 | U11: =IF(T11>T9,1,0) -> 1 | W11: 11 | X11: =IF(W11>W9,1,0) -> 0 | Y11: =IF(Q11="",0,1) -> 1 | Z11: =IF(R11+U11=2,3,IF(R11+U11=1,1,0)) -> 1 | AA11: =IF(Z11=3,3,IF(X11+Z11=2,2,IF(Z11=1,1,0))) -> 1 | AB11: =Q11+T11 -> 6 | AC11: =R11+U11+X11 -> 1 | AE11: =Players!B29& " / " &Players!C29 -> James Farrugia / Nancy Wong | AF11: =J11+Y25+J25+Y21+J21 -> 5 | AG11: =L11+AA25+L25+AA21+L21 -> 14 | AH11: =M11+AB25+M25+AB21+M21 -> 60 | AI11: =N11+AC25+N25+AC21+N21 -> 10
A13: =AE9 -> Willem Steenkamer / Mariska Steenkamer | B13: 6 | C13: =IF(B13>B15,1,0) -> 1 | E13: 6 | F13: =IF(E13>E15,1,0) -> 1 | I13: =IF(H13>H15,1,0) -> 0 | J13: =IF(B13="",0,1) -> 1 | K13: =IF(C13+F13=2,3,IF(C13+F13=1,1,0)) -> 3 | L13: =IF(K13=3,3,IF(I13+K13=2,2,IF(K13=1,1,0))) -> 3 | M13: =B13+E13 -> 12 | N13: =C13+F13+I13 -> 2 | P13: =AE9 -> Willem Steenkamer / Mariska Steenkamer | Q13: 6 | R13: =IF(Q13>Q15,1,0) -> 1 | T13: 6 | U13: =IF(T13>T15,1,0) -> 0 | W13: 3 | X13: =IF(W13>W15,1,0) -> 0 | Y13: =IF(Q13="",0,1) -> 1 | Z13: =IF(R13+U13=2,3,IF(R13+U13=1,1,0)) -> 1 | AA13: =IF(Z13=3,3,IF(X13+Z13=2,2,IF(Z13=1,1,0))) -> 1 | AB13: =Q13+T13 -> 12 | AC13: =R13+U13+X13 -> 1 | AE13: =Players!B30& " / " &Players!C30 -> Kristen Cachia / Francesca Sciortino | AF13: =Y29+Y11+Y33+J33+J23 -> 4 | AG13: =AA29+AA11+AA33+L33+L23 -> 5 | AH13: =AB29+AB11+AB33+M33+M23 -> 37 | AI13: =AC29+AC11+AC33+N33+N23 -> 4
A14: vs. | P14: vs.
A15: =AE15 -> Luigi Porto / Vanessa Azzopardi | B15: 2 | C15: =IF(B15>B13,1,0) -> 0 | E15: 1 | F15: =IF(E15>E13,1,0) -> 0 | I15: =IF(H15>H13,1,0) -> 0 | J15: =IF(B15="",0,1) -> 1 | K15: =IF(C15+F15=2,3,IF(C15+F15=1,1,0)) -> 0 | L15: =IF(K15=3,3,IF(I15+K15=2,2,IF(K15=1,1,0))) -> 0 | M15: =B15+E15 -> 3 | N15: =C15+F15+I15 -> 0 | P15: =AE17 -> Cyril Lastimosa / Laureen Agius | Q15: 4 | R15: =IF(Q15>Q13,1,0) -> 0 | T15: 7 | U15: =IF(T15>T13,1,0) -> 1 | W15: 10 | X15: =IF(W15>W13,1,0) -> 1 | Y15: =IF(Q15="",0,1) -> 1 | Z15: =IF(R15+U15=2,3,IF(R15+U15=1,1,0)) -> 1 | AA15: =IF(Z15=3,3,IF(X15+Z15=2,2,IF(Z15=1,1,0))) -> 2 | AB15: =Q15+T15 -> 11 | AC15: =R15+U15+X15 -> 2 | AE15: =Players!B31& " / " &Players!C31 -> Luigi Porto / Vanessa Azzopardi | AF15: =Y31+J37+J15+Y23+J29 -> 5 | AG15: =AA31+L37+L15+AA23+L29 -> 3 | AH15: =AB31+M37+M15+AB23+M29 -> 36 | AI15: =AC31+N37+N15+AC23+N29 -> 3
A17: =AE9 -> Willem Steenkamer / Mariska Steenkamer | B17: 6 | C17: =IF(B17>B19,1,0) -> 1 | E17: 6 | F17: =IF(E17>E19,1,0) -> 1 | I17: =IF(H17>H19,1,0) -> 0 | J17: =IF(B17="",0,1) -> 1 | K17: =IF(C17+F17=2,3,IF(C17+F17=1,1,0)) -> 3 | L17: =IF(K17=3,3,IF(I17+K17=2,2,IF(K17=1,1,0))) -> 3 | M17: =B17+E17 -> 12 | N17: =C17+F17+I17 -> 2 | P17: =AE17 -> Cyril Lastimosa / Laureen Agius | Q17: 6 | R17: =IF(Q17>Q19,1,0) -> 0 | T17: 4 | U17: =IF(T17>T19,1,0) -> 0 | X17: =IF(W17>W19,1,0) -> 0 | Y17: =IF(Q17="",0,1) -> 1 | Z17: =IF(R17+U17=2,3,IF(R17+U17=1,1,0)) -> 0 | AA17: =IF(Z17=3,3,IF(X17+Z17=2,2,IF(Z17=1,1,0))) -> 0 | AB17: =Q17+T17 -> 10 | AC17: =R17+U17+X17 -> 0 | AE17: =Players!B32& " / " &Players!C32 -> Cyril Lastimosa / Laureen Agius | AF17: =Y17+J39+J27+Y15+J35 -> 4 | AG17: =AA17+L39+L27+AA15+L35 -> 4 | AH17: =AB17+M39+M27+AB15+M35 -> 36 | AI17: =AC17+N39+N27+AC15+N35 -> 4
A18: vs. | P18: vs.
A19: =AE19 -> Jayboy Lastimosa / Ceridwen Scerri | B19: 3 | C19: =IF(B19>B17,1,0) -> 0 | E19: 4 | F19: =IF(E19>E17,1,0) -> 0 | I19: =IF(H19>H17,1,0) -> 0 | J19: =IF(B19="",0,1) -> 1 | K19: =IF(C19+F19=2,3,IF(C19+F19=1,1,0)) -> 0 | L19: =IF(K19=3,3,IF(I19+K19=2,2,IF(K19=1,1,0))) -> 0 | M19: =B19+E19 -> 7 | N19: =C19+F19+I19 -> 0 | P19: =AE19 -> Jayboy Lastimosa / Ceridwen Scerri | Q19: 7 | R19: =IF(Q19>Q17,1,0) -> 1 | T19: 6 | U19: =IF(T19>T17,1,0) -> 1 | X19: =IF(W19>W17,1,0) -> 0 | Y19: =IF(Q19="",0,1) -> 1 | Z19: =IF(R19+U19=2,3,IF(R19+U19=1,1,0)) -> 3 | AA19: =IF(Z19=3,3,IF(X19+Z19=2,2,IF(Z19=1,1,0))) -> 3 | AB19: =Q19+T19 -> 13 | AC19: =R19+U19+X19 -> 2 | AE19: =Players!B33& " / " &Players!C33 -> Jayboy Lastimosa / Ceridwen Scerri | AF19: =Y19+Y27+Y35+J19+J31 -> 5 | AG19: =AA19+AA27+AA35+L19+L31 -> 6 | AH19: =AB19+AB27+AB35+M19+M31 -> 36 | AI19: =AC19+AC27+AC35+N19+N31 -> 4
A21: =AE11 -> James Farrugia / Nancy Wong | B21: 7 | C21: =IF(B21>B23,1,0) -> 1 | E21: 6 | F21: =IF(E21>E23,1,0) -> 1 | I21: =IF(H21>H23,1,0) -> 0 | J21: =IF(B21="",0,1) -> 1 | K21: =IF(C21+F21=2,3,IF(C21+F21=1,1,0)) -> 3 | L21: =IF(K21=3,3,IF(I21+K21=2,2,IF(K21=1,1,0))) -> 3 | M21: =B21+E21 -> 13 | N21: =C21+F21+I21 -> 2 | P21: =AE11 -> James Farrugia / Nancy Wong | Q21: 6 | R21: =IF(Q21>Q23,1,0) -> 1 | T21: 6 | U21: =IF(T21>T23,1,0) -> 1 | X21: =IF(W21>W23,1,0) -> 0 | Y21: =IF(Q21="",0,1) -> 1 | Z21: =IF(R21+U21=2,3,IF(R21+U21=1,1,0)) -> 3 | AA21: =IF(Z21=3,3,IF(X21+Z21=2,2,IF(Z21=1,1,0))) -> 3 | AB21: =Q21+T21 -> 12 | AC21: =R21+U21+X21 -> 2 | AE21: Divison Winner
A22: vs. | P22: vs. | AE22: James Farrugia/Nancy Wong
A23: =AE13 -> Kristen Cachia / Francesca Sciortino | B23: 6 | C23: =IF(B23>B21,1,0) -> 0 | E23: 3 | F23: =IF(E23>E21,1,0) -> 0 | I23: =IF(H23>H21,1,0) -> 0 | J23: =IF(B23="",0,1) -> 1 | K23: =IF(C23+F23=2,3,IF(C23+F23=1,1,0)) -> 0 | L23: =IF(K23=3,3,IF(I23+K23=2,2,IF(K23=1,1,0))) -> 0 | M23: =B23+E23 -> 9 | N23: =C23+F23+I23 -> 0 | P23: =AE15 -> Luigi Porto / Vanessa Azzopardi | Q23: 3 | R23: =IF(Q23>Q21,1,0) -> 0 | T23: 2 | U23: =IF(T23>T21,1,0) -> 0 | X23: =IF(W23>W21,1,0) -> 0 | Y23: =IF(Q23="",0,1) -> 1 | Z23: =IF(R23+U23=2,3,IF(R23+U23=1,1,0)) -> 0 | AA23: =IF(Z23=3,3,IF(X23+Z23=2,2,IF(Z23=1,1,0))) -> 0 | AB23: =Q23+T23 -> 5 | AC23: =R23+U23+X23 -> 0
A25: =AE11 -> James Farrugia / Nancy Wong | B25: 6 | C25: =IF(B25>B27,1,0) -> 1 | E25: 6 | F25: =IF(E25>E27,1,0) -> 1 | I25: =IF(H25>H27,1,0) -> 0 | J25: =IF(B25="",0,1) -> 1 | K25: =IF(C25+F25=2,3,IF(C25+F25=1,1,0)) -> 3 | L25: =IF(K25=3,3,IF(I25+K25=2,2,IF(K25=1,1,0))) -> 3 | M25: =B25+E25 -> 12 | N25: =C25+F25+I25 -> 2 | P25: =AE11 -> James Farrugia / Nancy Wong | Q25: 6 | R25: =IF(Q25>Q27,1,0) -> 1 | T25: 6 | U25: =IF(T25>T27,1,0) -> 1 | X25: =IF(W25>W27,1,0) -> 0 | Y25: =IF(Q25="",0,1) -> 1 | Z25: =IF(R25+U25=2,3,IF(R25+U25=1,1,0)) -> 3 | AA25: =IF(Z25=3,3,IF(X25+Z25=2,2,IF(Z25=1,1,0))) -> 3 | AB25: =Q25+T25 -> 12 | AC25: =R25+U25+X25 -> 2 | AE25: Divison Runner Up
A26: vs. | P26: vs. | AE26: Willem Steenkamer/Mariska Steenkamer
A27: =AE17 -> Cyril Lastimosa / Laureen Agius | B27: 2 | C27: =IF(B27>B25,1,0) -> 0 | E27: 3 | F27: =IF(E27>E25,1,0) -> 0 | I27: =IF(H27>H25,1,0) -> 0 | J27: =IF(B27="",0,1) -> 1 | K27: =IF(C27+F27=2,3,IF(C27+F27=1,1,0)) -> 0 | L27: =IF(K27=3,3,IF(I27+K27=2,2,IF(K27=1,1,0))) -> 0 | M27: =B27+E27 -> 5 | N27: =C27+F27+I27 -> 0 | P27: =AE19 -> Jayboy Lastimosa / Ceridwen Scerri | Q27: 0 | R27: =IF(Q27>Q25,1,0) -> 0 | T27: 1 | U27: =IF(T27>T25,1,0) -> 0 | X27: =IF(W27>W25,1,0) -> 0 | Y27: =IF(Q27="",0,1) -> 1 | Z27: =IF(R27+U27=2,3,IF(R27+U27=1,1,0)) -> 0 | AA27: =IF(Z27=3,3,IF(X27+Z27=2,2,IF(Z27=1,1,0))) -> 0 | AB27: =Q27+T27 -> 1 | AC27: =R27+U27+X27 -> 0
A29: =AE15 -> Luigi Porto / Vanessa Azzopardi | B29: 4 | C29: =IF(B29>B31,1,0) -> 0 | E29: 3 | F29: =IF(E29>E31,1,0) -> 0 | I29: =IF(H29>H31,1,0) -> 0 | J29: =IF(B29="",0,1) -> 1 | K29: =IF(C29+F29=2,3,IF(C29+F29=1,1,0)) -> 0 | L29: =IF(K29=3,3,IF(I29+K29=2,2,IF(K29=1,1,0))) -> 0 | M29: =B29+E29 -> 7 | N29: =C29+F29+I29 -> 0 | P29: =AE13 -> Kristen Cachia / Francesca Sciortino | Q29: 4 | R29: =IF(Q29>Q31,1,0) -> 0 | T29: 6 | U29: =IF(T29>T31,1,0) -> 1 | W29: 8 | X29: =IF(W29>W31,1,0) -> 0 | Y29: =IF(Q29="",0,1) -> 1 | Z29: =IF(R29+U29=2,3,IF(R29+U29=1,1,0)) -> 1 | AA29: =IF(Z29=3,3,IF(X29+Z29=2,2,IF(Z29=1,1,0))) -> 1 | AB29: =Q29+T29 -> 10 | AC29: =R29+U29+X29 -> 1
A30: vs. | P30: vs.
A31: =AE19 -> Jayboy Lastimosa / Ceridwen Scerri | B31: 6 | C31: =IF(B31>B29,1,0) -> 1 | E31: 6 | F31: =IF(E31>E29,1,0) -> 1 | I31: =IF(H31>H29,1,0) -> 0 | J31: =IF(B31="",0,1) -> 1 | K31: =IF(C31+F31=2,3,IF(C31+F31=1,1,0)) -> 3 | L31: =IF(K31=3,3,IF(I31+K31=2,2,IF(K31=1,1,0))) -> 3 | M31: =B31+E31 -> 12 | N31: =C31+F31+I31 -> 2 | P31: =AE15 -> Luigi Porto / Vanessa Azzopardi | Q31: 6 | R31: =IF(Q31>Q29,1,0) -> 1 | T31: 3 | U31: =IF(T31>T29,1,0) -> 0 | W31: 10 | X31: =IF(W31>W29,1,0) -> 1 | Y31: =IF(Q31="",0,1) -> 1 | Z31: =IF(R31+U31=2,3,IF(R31+U31=1,1,0)) -> 1 | AA31: =IF(Z31=3,3,IF(X31+Z31=2,2,IF(Z31=1,1,0))) -> 2 | AB31: =Q31+T31 -> 9 | AC31: =R31+U31+X31 -> 2
A33: =AE13 -> Kristen Cachia / Francesca Sciortino | C33: =IF(B33>B35,1,0) -> 0 | F33: =IF(E33>E35,1,0) -> 0 | I33: =IF(H33>H35,1,0) -> 0 | J33: =IF(B33="",0,1) -> 0 | K33: =IF(C33+F33=2,3,IF(C33+F33=1,1,0)) -> 0 | L33: =IF(K33=3,3,IF(I33+K33=2,2,IF(K33=1,1,0))) -> 0 | M33: =B33+E33 -> 0 | N33: =C33+F33+I33 -> 0 | P33: =AE13 -> Kristen Cachia / Francesca Sciortino | Q33: 6 | R33: =IF(Q33>Q35,1,0) -> 1 | T33: 6 | U33: =IF(T33>T35,1,0) -> 1 | X33: =IF(W33>W35,1,0) -> 0 | Y33: =IF(Q33="",0,1) -> 1 | Z33: =IF(R33+U33=2,3,IF(R33+U33=1,1,0)) -> 3 | AA33: =IF(Z33=3,3,IF(X33+Z33=2,2,IF(Z33=1,1,0))) -> 3 | AB33: =Q33+T33 -> 12 | AC33: =R33+U33+X33 -> 2
A34: vs. | P34: vs.
A35: =AE17 -> Cyril Lastimosa / Laureen Agius | C35: =IF(B35>B33,1,0) -> 0 | F35: =IF(E35>E33,1,0) -> 0 | I35: =IF(H35>H33,1,0) -> 0 | J35: =IF(B35="",0,1) -> 0 | K35: =IF(C35+F35=2,3,IF(C35+F35=1,1,0)) -> 0 | L35: =IF(K35=3,3,IF(I35+K35=2,2,IF(K35=1,1,0))) -> 0 | M35: =B35+E35 -> 0 | N35: =C35+F35+I35 -> 0 | P35: =AE19 -> Jayboy Lastimosa / Ceridwen Scerri | Q35: 2 | R35: =IF(Q35>Q33,1,0) -> 0 | T35: 1 | U35: =IF(T35>T33,1,0) -> 0 | X35: =IF(W35>W33,1,0) -> 0 | Y35: =IF(Q35="",0,1) -> 1 | Z35: =IF(R35+U35=2,3,IF(R35+U35=1,1,0)) -> 0 | AA35: =IF(Z35=3,3,IF(X35+Z35=2,2,IF(Z35=1,1,0))) -> 0 | AB35: =Q35+T35 -> 3 | AC35: =R35+U35+X35 -> 0
A37: =AE15 -> Luigi Porto / Vanessa Azzopardi | B37: 6 | C37: =IF(B37>B39,1,0) -> 1 | E37: 6 | F37: =IF(E37>E39,1,0) -> 0 | H37: 7 | I37: =IF(H37>H39,1,0) -> 0 | J37: =IF(B37="",0,1) -> 1 | K37: =IF(C37+F37=2,3,IF(C37+F37=1,1,0)) -> 1 | L37: =IF(K37=3,3,IF(I37+K37=2,2,IF(K37=1,1,0))) -> 1 | M37: =B37+E37 -> 12 | N37: =C37+F37+I37 -> 1
A38: vs.
A39: =AE17 -> Cyril Lastimosa / Laureen Agius | B39: 3 | C39: =IF(B39>B37,1,0) -> 0 | E39: 7 | F39: =IF(E39>E37,1,0) -> 1 | H39: 10 | I39: =IF(H39>H37,1,0) -> 1 | J39: =IF(B39="",0,1) -> 1 | K39: =IF(C39+F39=2,3,IF(C39+F39=1,1,0)) -> 1 | L39: =IF(K39=3,3,IF(I39+K39=2,2,IF(K39=1,1,0))) -> 2 | M39: =B39+E39 -> 10 | N39: =C39+F39+I39 -> 2

Sheet Division 5
A1: Elektra Mixed Doubles 2023
A5: Division 5 - Group A
A7: Players | B7: Set Scores | H7: Tie | P7: Players | Q7: Set Scores | W7: Tie | AE7: Player | AF7: Games | AG7: Points | AH7: Games Won | AI7: Sets Won
B8: Score | C8: Set 1 Work | E8: Score | F8: Set 2 Work | H8: Score | I8: Tie Work | J8: Game Played | K8: Sets Points Work | L8: Sets & Tie Points Work | M8: Games Wins Work | N8: Sets Wins Work | Q8: Score | R8: Set 1 Work | T8: Score | U8: Set 2 Work | W8: Score | X8: Tie Work | Y8: Game Played | Z8: Sets Points Work | AA8: Sets & Tie Points Work | AB8: Games Wins Work | AC8: Sets Wins Work | AJ8: Winner Working | AK8: Total Games Work | AL8: Winner
A9: =AE9 -> Daniel Farrugia / Diane Farrugia | B9: 6 | C9: =IF(B9>B11,1,0) -> 1 | E9: 6 | F9: =IF(E9>E11,1,0) -> 1 | I9: =IF(H9>H11,1,0) -> 0 | J9: =IF(B9="",0,1) -> 1 | K9: =IF(C9+F9=2,3,IF(C9+F9=1,1,0)) -> 3 | L9: =IF(K9=3,3,IF(I9+K9=2,2,IF(K9=1,1,0))) -> 3 | M9: =B9+E9 -> 12 | N9: =C9+F9+I9 -> 2 | P9: =AE9 -> Daniel Farrugia / Diane Farrugia | Q9: 6 | R9: =IF(Q9>Q11,1,0) -> 1 | T9: 6 | U9: =IF(T9>T11,1,0) -> 1 | X9: =IF(W9>W11,1,0) -> 0 | Y9: =IF(Q9="",0,1) -> 1 | Z9: =IF(R9+U9=2,3,IF(R9+U9=1,1,0)) -> 3 | AA9: =IF(Z9=3,3,IF(X9+Z9=2,2,IF(Z9=1,1,0))) -> 3 | AB9: =Q9+T9 -> 12 | AC9: =R9+U9+X9 -> 2 | AE9: =Players!B36& " / " &Players!C36 -> Daniel Farrugia / Diane Farrugia | AF9: =J9+Y9+J13+Y13+J17 -> 5 | AG9: =L9+AA9+L13+AA13+L17 -> 15 | AH9: =M9+AB9+M13+AB13+M17 -> 60 | AI9: =N9+AC9+N13+AC13+N17 -> 10 | AJ9: =MAX(AG9:AG19) -> 15 | AK9: =SUM(AF9:AF19) -> 30 | AL9: =IF(AG9=$AJ$9,AE9,IF(AG11=$AJ$9,AE11,IF(AG13=$AJ$9,AE13,IF(AG15=$AJ$9,AE15,IF(AG17=$AJ$9,AE17,IF(AG19=$AJ$9,AE19,"")))))) -> Daniel Farrugia / Diane Farrugia
A10: vs. | P10: vs.
A11: =AE11 -> David Camilleri / Emma Camilleri | B11: 1 | C11: =IF(B11>B9,1,0) -> 0 | E11: 2 | F11: =IF(E11>E9,1,0) -> 0 | I11: =IF(H11>H9,1,0) -> 0 | J11: =IF(B11="",0,1) -> 1 | K11: =IF(C11+F11=2,3,IF(C11+F11=1,1,0)) -> 0 | L11: =IF(K11=3,3,IF(I11+K11=2,2,IF(K11=1,1,0))) -> 0 | M11: =B11+E11 -> 3 | N11: =C11+F11+I11 -> 0 | P11: =AE13 -> Maurice Borg / Mary Borg | Q11: 1 | R11: =IF(Q11>Q9,1,0) -> 0 | T11: 2 | U11: =IF(T11>T9,1,0) -> 0 | X11: =IF(W11>W9,1,0) -> 0 | Y11: =IF(Q11="",0,1) -> 1 | Z11: =IF(R11+U11=2,3,IF(R11+U11=1,1,0)) -> 0 | AA11: =IF(Z11=3,3,IF(X11+Z11=2,2,IF(Z11=1,1,0))) -> 0 | AB11: =Q11+T11 -> 3 | AC11: =R11+U11+X11 -> 0 | AE11: =Players!B37& " / " &Players!C37 -> David Camilleri / Emma Camilleri | AF11: =J11+Y25+J25+Y21+J21 -> 5 | AG11: =L11+AA25+L25+AA21+L21 -> 6 | AH11: =M11+AB25+M25+AB21+M21 -> 43 | AI11: =N11+AC25+N25+AC21+N21 -> 5
A13: =AE9 -> Daniel Farrugia / Diane Farrugia | B13: 6 | C13: =IF(B13>B15,1,0) -> 1 | E13: 6 | F13: =IF(E13>E15,1,0) -> 1 | I13: =IF(H13>H15,1,0) -> 0 | J13: =IF(B13="",0,1) -> 1 | K13: =IF(C13+F13=2,3,IF(C13+F13=1,1,0)) -> 3 | L13: =IF(K13=3,3,IF(I13+K13=2,2,IF(K13=1,1,0))) -> 3 | M13: =B13+E13 -> 12 | N13: =C13+F13+I13 -> 2 | P13: =AE9 -> Daniel Farrugia / Diane Farrugia | Q13: 6 | R13: =IF(Q13>Q15,1,0) -> 1 | T13: 6 | U13: =IF(T13>T15,1,0) -> 1 | X13: =IF(W13>W15,1,0) -> 0 | Y13: =IF(Q13="",0,1) -> 1 | Z13: =IF(R13+U13=2,3,IF(R13+U13=1,1,0)) -> 3 | AA13: =IF(Z13=3,3,IF(X13+Z13=2,2,IF(Z13=1,1,0))) -> 3 | AB13: =Q13+T13 -> 12 | AC13: =R13+U13+X13 -> 2 | AE13: =Players!B38& " / " &Players!C38 -> Maurice Borg / Mary Borg | AF13: =Y29+Y11+Y33+J33+J23 -> 5 | AG13: =AA29+AA11+AA33+L33+L23 -> 9 | AH13: =AB29+AB11+AB33+M33+M23 -> 51 | AI13: =AC29+AC11+AC33+N33+N23 -> 7
A14: vs. | P14: vs.
A15: =AE15 -> Robert Attard / Silvana Portelli | B15: 2 | C15: =IF(B15>B13,1,0) -> 0 | E15: 2 | F15: =IF(E15>E13,1,0) -> 0 | I15: =IF(H15>H13,1,0) -> 0 | J15: =IF(B15="",0,1) -> 1 | K15: =IF(C15+F15=2,3,IF(C15+F15=1,1,0)) -> 0 | L15: =IF(K15=3,3,IF(I15+K15=2,2,IF(K15=1,1,0))) -> 0 | M15: =B15+E15 -> 4 | N15: =C15+F15+I15 -> 0 | P15: =AE17 -> JP Sciberras / Brenda Baldacchino | Q15: 2 | R15: =IF(Q15>Q13,1,0) -> 0 | T15: 1 | U15: =IF(T15>T13,1,0) -> 0 | X15: =IF(W15>W13,1,0) -> 0 | Y15: =IF(Q15="",0,1) -> 1 | Z15: =IF(R15+U15=2,3,IF(R15+U15=1,1,0)) -> 0 | AA15: =IF(Z15=3,3,IF(X15+Z15=2,2,IF(Z15=1,1,0))) -> 0 | AB15: =Q15+T15 -> 3 | AC15: =R15+U15+X15 -> 0 | AE15: =Players!B39& " / " &Players!C39 -> Robert Attard / Silvana Portelli | AF15: =Y31+J37+J15+Y23+J29 -> 5 | AG15: =AA31+L37+L15+AA23+L29 -> 8 | AH15: =AB31+M37+M15+AB23+M29 -> 37 | AI15: =AC31+N37+N15+AC23+N29 -> 6
A17: =AE9 -> Daniel Farrugia / Diane Farrugia | B17: 6 | C17: =IF(B17>B19,1,0) -> 1 | E17: 6 | F17: =IF(E17>E19,1,0) -> 1 | I17: =IF(H17>H19,1,0) -> 0 | J17: =IF(B17="",0,1) -> 1 | K17: =IF(C17+F17=2,3,IF(C17+F17=1,1,0)) -> 3 | L17: =IF(K17=3,3,IF(I17+K17=2,2,IF(K17=1,1,0))) -> 3 | M17: =B17+E17 -> 12 | N17: =C17+F17+I17 -> 2 | P17: =AE17 -> JP Sciberras / Brenda Baldacchino | Q17: 0 | R17: =IF(Q17>Q19,1,0) -> 0 | T17: 5 | U17: =IF(T17>T19,1,0) -> 0 | X17: =IF(W17>W19,1,0) -> 0 | Y17: =IF(Q17="",0,1) -> 1 | Z17: =IF(R17+U17=2,3,IF(R17+U17=1,1,0)) -> 0 | AA17: =IF(Z17=3,3,IF(X17+Z17=2,2,IF(Z17=1,1,0))) -> 0 | AB17: =Q17+T17 -> 5 | AC17: =R17+U17+X17 -> 0 | AE17: =Players!B40& " / " &Players!C40 -> JP Sciberras / Brenda Baldacchino | AF17: =Y17+J39+J27+Y15+J35 -> 5 | AG17: =AA17+L39+L27+AA15+L35 -> 0 | AH17: =AB17+M39+M27+AB15+M35 -> 17 | AI17: =AC17+N39+N27+AC15+N35 -> 0
A18: vs. | P18: vs.
A19: =AE19 -> Cory Greenland / Marica Cassar | B19: 1 | C19: =IF(B19>B17,1,0) -> 0 | E19: 0 | F19: =IF(E19>E17,1,0) -> 0 | I19: =IF(H19>H17,1,0) -> 0 | J19: =IF(B19="",0,1) -> 1 | K19: =IF(C19+F19=2,3,IF(C19+F19=1,1,0)) -> 0 | L19: =IF(K19=3,3,IF(I19+K19=2,2,IF(K19=1,1,0))) -> 0 | M19: =B19+E19 -> 1 | N19: =C19+F19+I19 -> 0 | P19: =AE19 -> Cory Greenland / Marica Cassar | Q19: 6 | R19: =IF(Q19>Q17,1,0) -> 1 | T19: 7 | U19: =IF(T19>T17,1,0) -> 1 | X19: =IF(W19>W17,1,0) -> 0 | Y19: =IF(Q19="",0,1) -> 1 | Z19: =IF(R19+U19=2,3,IF(R19+U19=1,1,0)) -> 3 | AA19: =IF(Z19=3,3,IF(X19+Z19=2,2,IF(Z19=1,1,0))) -> 3 | AB19: =Q19+T19 -> 13 | AC19: =R19+U19+X19 -> 2 | AE19: =Players!B41& " / " &Players!C41 -> Cory Greenland / Marica Cassar | AF19: =Y19+Y27+Y35+J19+J31 -> 5 | AG19: =AA19+AA35+L31+AA27+L19 -> 7 | AH19: =AB19+AB27+AB35+M19+M31 -> 46 | AI19: =AC19+AC27+AC35+N19+N31 -> 5
A21: =AE11 -> David Camilleri / Emma Camilleri | B21: 6 | C21: =IF(B21>B23,1,0) -> 0 | E21: 6 | F21: =IF(E21>E23,1,0) -> 1 | H21: 4 | I21: =IF(H21>H23,1,0) -> 0 | J21: =IF(B21="",0,1) -> 1 | K21: =IF(C21+F21=2,3,IF(C21+F21=1,1,0)) -> 1 | L21: =IF(K21=3,3,IF(I21+K21=2,2,IF(K21=1,1,0))) -> 1 | M21: =B21+E21 -> 12 | N21: =C21+F21+I21 -> 1 | P21: =AE11 -> David Camilleri / Emma Camilleri | Q21: 3 | R21: =IF(Q21>Q23,1,0) -> 0 | T21: 3 | U21: =IF(T21>T23,1,0) -> 0 | X21: =IF(W21>W23,1,0) -> 0 | Y21: =IF(Q21="",0,1) -> 1 | Z21: =IF(R21+U21=2,3,IF(R21+U21=1,1,0)) -> 0 | AA21: =IF(Z21=3,3,IF(X21+Z21=2,2,IF(Z21=1,1,0))) -> 0 | AB21: =Q21+T21 -> 6 | AC21: =R21+U21+X21 -> 0 | AE21: Group A Winner
A22: vs. | P22: vs. | AE22: Daniel Farrugia/Diane Farrugia
A23: =AE13 -> Maurice Borg / Mary Borg | B23: 7 | C23: =IF(B23>B21,1,0) -> 1 | E23: 4 | F23: =IF(E23>E21,1,0) -> 0 | H23: 10 | I23: =IF(H23>H21,1,0) -> 1 | J23: =IF(B23="",0,1) -> 1 | K23: =IF(C23+F23=2,3,IF(C23+F23=1,1,0)) -> 1 | L23: =IF(K23=3,3,IF(I23+K23=2,2,IF(K23=1,1,0))) -> 2 | M23: =B23+E23 -> 11 | N23: =C23+F23+I23 -> 2 | P23: =AE15 -> Robert Attard / Silvana Portelli | Q23: 6 | R23: =IF(Q23>Q21,1,0) -> 1 | T23: 6 | U23: =IF(T23>T21,1,0) -> 1 | X23: =IF(W23>W21,1,0) -> 0 | Y23: =IF(Q23="",0,1) -> 1 | Z23: =IF(R23+U23=2,3,IF(R23+U23=1,1,0)) -> 3 | AA23: =IF(Z23=3,3,IF(X23+Z23=2,2,IF(Z23=1,1,0))) -> 3 | AB23: =Q23+T23 -> 12 | AC23: =R23+U23+X23 -> 2
A25: =AE11 -> David Camilleri / Emma Camilleri | B25: 6 | C25: =IF(B25>B27,1,0) -> 1 | E25: 6 | F25: =IF(E25>E27,1,0) -> 1 | I25: =IF(H25>H27,1,0) -> 0 | J25: =IF(B25="",0,1) -> 1 | K25: =IF(C25+F25=2,3,IF(C25+F25=1,1,0)) -> 3 | L25: =IF(K25=3,3,IF(I25+K25=2,2,IF(K25=1,1,0))) -> 3 | M25: =B25+E25 -> 12 | N25: =C25+F25+I25 -> 2 | P25: =AE11 -> David Camilleri / Emma Camilleri | Q25: 3 | R25: =IF(Q25>Q27,1,0) -> 0 | T25: 7 | U25: =IF(T25>T27,1,0) -> 1 | W25: 10 | X25: =IF(W25>W27,1,0) -> 1 | Y25: =IF(Q25="",0,1) -> 1 | Z25: =IF(R25+U25=2,3,IF(R25+U25=1,1,0)) -> 1 | AA25: =IF(Z25=3,3,IF(X25+Z25=2,2,IF(Z25=1,1,0))) -> 2 | AB25: =Q25+T25 -> 10 | AC25: =R25+U25+X25 -> 2
A26: vs. | P26: vs.
A27: =AE17 -> JP Sciberras / Brenda Baldacchino | B27: 1 | C27: =IF(B27>B25,1,0) -> 0 | E27: 3 | F27: =IF(E27>E25,1,0) -> 0 | I27: =IF(H27>H25,1,0) -> 0 | J27: =IF(B27="",0,1) -> 1 | K27: =IF(C27+F27=2,3,IF(C27+F27=1,1,0)) -> 0 | L27: =IF(K27=3,3,IF(I27+K27=2,2,IF(K27=1,1,0))) -> 0 | M27: =B27+E27 -> 4 | N27: =C27+F27+I27 -> 0 | P27: =AE19 -> Cory Greenland / Marica Cassar | Q27: 6 | R27: =IF(Q27>Q25,1,0) -> 1 | T27: 6 | U27: =IF(T27>T25,1,0) -> 0 | W27: 6 | X27: =IF(W27>W25,1,0) -> 0 | Y27: =IF(Q27="",0,1) -> 1 | Z27: =IF(R27+U27=2,3,IF(R27+U27=1,1,0)) -> 1 | AA27: =IF(Z27=3,3,IF(X27+Z27=2,2,IF(Z27=1,1,0))) -> 1 | AB27: =Q27+T27 -> 12 | AC27: =R27+U27+X27 -> 1
A29: =AE15 -> Robert Attard / Silvana Portelli | B29: 0 | C29: =IF(B29>B31,1,0) -> 0 | E29: 0 | F29: =IF(E29>E31,1,0) -> 0 | I29: =IF(H29>H31,1,0) -> 0 | J29: =IF(B29="",0,1) -> 1 | K29: =IF(C29+F29=2,3,IF(C29+F29=1,1,0)) -> 0 | L29: =IF(K29=3,3,IF(I29+K29=2,2,IF(K29=1,1,0))) -> 0 | M29: =B29+E29 -> 0 | N29: =C29+F29+I29 -> 0 | O29: W/O | P29: =AE13 -> Maurice Borg / Mary Borg | Q29: 6 | R29: =IF(Q29>Q31,1,0) -> 0 | T29: 6 | U29: =IF(T29>T31,1,0) -> 1 | W29: 7 | X29: =IF(W29>W31,1,0) -> 0 | Y29: =IF(Q29="",0,1) -> 1 | Z29: =IF(R29+U29=2,3,IF(R29+U29=1,1,0)) -> 1 | AA29: =IF(Z29=3,3,IF(X29+Z29=2,2,IF(Z29=1,1,0))) -> 1 | AB29: =Q29+T29 -> 12 | AC29: =R29+U29+X29 -> 1
A30: vs. | P30: vs.
A31: =AE19 -> Cory Greenland / Marica Cassar | B31: 6 | C31: =IF(B31>B29,1,0) -> 1 | E31: 6 | F31: =IF(E31>E29,1,0) -> 1 | I31: =IF(H31>H29,1,0) -> 0 | J31: =IF(B31="",0,1) -> 1 | K31: =IF(C31+F31=2,3,IF(C31+F31=1,1,0)) -> 3 | L31: =IF(K31=3,3,IF(I31+K31=2,2,IF(K31=1,1,0))) -> 3 | M31: =B31+E31 -> 12 | N31: =C31+F31+I31 -> 2 | P31: =AE15 -> Robert Attard / Silvana Portelli | Q31: 7 | R31: =IF(Q31>Q29,1,0) -> 1 | T31: 2 | U31: =IF(T31>T29,1,0) -> 0 | W31: 10 | X31: =IF(W31>W29,1,0) -> 1 | Y31: =IF(Q31="",0,1) -> 1 | Z31: =IF(R31+U31=2,3,IF(R31+U31=1,1,0)) -> 1 | AA31: =IF(Z31=3,3,IF(X31+Z31=2,2,IF(Z31=1,1,0))) -> 2 | AB31: =Q31+T31 -> 9 | AC31: =R31+U31+X31 -> 2
A33: =AE13 -> Maurice Borg / Mary Borg | B33: 6 | C33: =IF(B33>B35,1,0) -> 1 | E33: 6 | F33: =IF(E33>E35,1,0) -> 1 | I33: =IF(H33>H35,1,0) -> 0 | J33: =IF(B33="",0,1) -> 1 | K33: =IF(C33+F33=2,3,IF(C33+F33=1,1,0)) -> 3 | L33: =IF(K33=3,3,IF(I33+K33=2,2,IF(K33=1,1,0))) -> 3 | M33: =B33+E33 -> 12 | N33: =C33+F33+I33 -> 2 | P33: =AE13 -> Maurice Borg / Mary Borg | Q33: 7 | R33: =IF(Q33>Q35,1,0) -> 1 | T33: 6 | U33: =IF(T33>T35,1,0) -> 1 | X33: =IF(W33>W35,1,0) -> 0 | Y33: =IF(Q33="",0,1) -> 1 | Z33: =IF(R33+U33=2,3,IF(R33+U33=1,1,0)) -> 3 | AA33: =IF(Z33=3,3,IF(X33+Z33=2,2,IF(Z33=1,1,0))) -> 3 | AB33: =Q33+T33 -> 13 | AC33: =R33+U33+X33 -> 2
A34: vs. | P34: vs.
A35: =AE17 -> JP Sciberras / Brenda Baldacchino | B35: 1 | C35: =IF(B35>B33,1,0) -> 0 | E35: 2 | F35: =IF(E35>E33,1,0) -> 0 | I35: =IF(H35>H33,1,0) -> 0 | J35: =IF(B35="",0,1) -> 1 | K35: =IF(C35+F35=2,3,IF(C35+F35=1,1,0)) -> 0 | L35: =IF(K35=3,3,IF(I35+K35=2,2,IF(K35=1,1,0))) -> 0 | M35: =B35+E35 -> 3 | N35: =C35+F35+I35 -> 0 | P35: =AE19 -> Cory Greenland / Marica Cassar | Q35: 5 | R35: =IF(Q35>Q33,1,0) -> 0 | T35: 3 | U35: =IF(T35>T33,1,0) -> 0 | X35: =IF(W35>W33,1,0) -> 0 | Y35: =IF(Q35="",0,1) -> 1 | Z35: =IF(R35+U35=2,3,IF(R35+U35=1,1,0)) -> 0 | AA35: =IF(Z35=3,3,IF(X35+Z35=2,2,IF(Z35=1,1,0))) -> 0 | AB35: =Q35+T35 -> 8 | AC35: =R35+U35+X35 -> 0
A37: =AE15 -> Robert Attard / Silvana Portelli | B37: 6 | C37: =IF(B37>B39,1,0) -> 1 | E37: 6 | F37: =IF(E37>E39,1,0) -> 1 | I37: =IF(H37>H39,1,0) -> 0 | J37: =IF(B37="",0,1) -> 1 | K37: =IF(C37+F37=2,3,IF(C37+F37=1,1,0)) -> 3 | L37: =IF(K37=3,3,IF(I37+K37=2,2,IF(K37=1,1,0))) -> 3 | M37: =B37+E37 -> 12 | N37: =C37+F37+I37 -> 2
A38: vs.
A39: =AE17 -> JP Sciberras / Brenda Baldacchino | B39: 1 | C39: =IF(B39>B37,1,0) -> 0 | E39: 1 | F39: =IF(E39>E37,1,0) -> 0 | I39: =IF(H39>H37,1,0) -> 0 | J39: =IF(B39="",0,1) -> 1 | K39: =IF(C39+F39=2,3,IF(C39+F39=1,1,0)) -> 0 | L39: =IF(K39=3,3,IF(I39+K39=2,2,IF(K39=1,1,0))) -> 0 | M39: =B39+E39 -> 2 | N39: =C39+F39+I39 -> 0
A41: Division 5 - Group B
A43: Players | B43: Set Scores | H43: Tie | P43: Players | Q43: Set Scores | W43: Tie | AE43: Player | AF43: Games | AG43: Points | AH43: Games Won | AI43: Sets Won
B44: Score | C44: Set 1 Work | E44: Score | F44: Set 2 Work | H44: Score | I44: Tie Work | J44: Game Played | K44: Sets Points Work | L44: Sets & Tie Points Work | M44: Games Wins Work | N44: Sets Wins Work | Q44: Score | R44: Set 1 Work | T44: Score | U44: Set 2 Work | W44: Score | X44: Tie Work | Y44: Game Played | Z44: Sets Points Work | AA44: Sets & Tie Points Work | AB44: Games Wins Work | AC44: Sets Wins Work | AJ44: Winner Working | AK44: Total Games Work | AL44: Winner
A45: =AE45 -> Victor Rutter / Jennifer Mifsud | B45: 3 | C45: =IF(B45>B47,1,0) -> 0 | E45: 6 | F45: =IF(E45>E47,1,0) -> 1 | H45: 7 | I45: =IF(H45>H47,1,0) -> 0 | J45: =IF(B45="",0,1) -> 1 | K45: =IF(C45+F45=2,3,IF(C45+F45=1,1,0)) -> 1 | L45: =IF(K45=3,3,IF(I45+K45=2,2,IF(K45=1,1,0))) -> 1 | M45: =B45+E45 -> 9 | N45: =C45+F45+I45 -> 1 | P45: =AE45 -> Victor Rutter / Jennifer Mifsud | Q45: 6 | R45: =IF(Q45>Q47,1,0) -> 1 | T45: 6 | U45: =IF(T45>T47,1,0) -> 1 | X45: =IF(W45>W47,1,0) -> 0 | Y45: =IF(Q45="",0,1) -> 1 | Z45: =IF(R45+U45=2,3,IF(R45+U45=1,1,0)) -> 3 | AA45: =IF(Z45=3,3,IF(X45+Z45=2,2,IF(Z45=1,1,0))) -> 3 | AB45: =Q45+T45 -> 12 | AC45: =R45+U45+X45 -> 2 | AE45: =Players!F36& " / " &Players!G36 -> Victor Rutter / Jennifer Mifsud | AF45: =J45+Y45+J49+Y49+J53 -> 5 | AG45: =L45+AA45+L49+AA49+L53 -> 12 | AH45: =M45+AB45+M49+AB49+M53 -> 54 | AI45: =N45+AC45+N49+AC49+N53 -> 9 | AJ45: =MAX(AG45:AG55) -> 13 | AK45: =SUM(AF45:AF55) -> 30 | AL45: =IF(AG45=$AJ$45,AE45,IF(AG47=$AJ$45,AE47,IF(AG49=$AJ$45,AE49,IF(AG51=$AJ$45,AE51,IF(AG53=$AJ$45,AE53,IF(AG55=$AJ$45,AE55,"")))))) -> Ryan Ebejer / Sophia Re
A46: vs. | P46: vs.
