Workbook

Sheet Players
A1: ESS Mixed Doubles 2025
B5: Division 1
A6: 1 | B6: Matthew Mifsud | C6: Lara Pule'
A7: 2 | B7: Matthew Borg | C7: Ann Marie Mangion
A8: 3 | B8: Duncan D'alessandro | C8: Renette Magro
A9: 4 | B9: Melchior Farrugia | C9: Julie Spiteri
A10: 5 | B10: Kurt Carabott | C10: Pierina Holmin
A11: 6 | B11: Jean Attard | C11: Yanika Pace
B13: Division 2
A14: 1 | B14: Harvey Wadge | C14: Giada Sciberras
A15: 2 | B15: Kristen Cachia | C15: Francesca Sciortino
A16: 3 | B16: Keith Micallef | C16: Mirka Micallef
A17: 4 | B17: Jonathan Martinelli | C17: Christina Bonett
A18: 5 | B18: Stefan Holmin | C18: Alison Muscat
A19: 6 | B19: Ivan Cassar | C19: Dawn Azzopardi
B21: Division 3
A22: 1 | B22: Ivan Farrugia | C22: Stephanie Farrugia
A23: 2 | B23: Willem Steenkamer | C23: Mariska Steenkamer
A24: 3 | B24: Cyril Lastimosa | C24: Jin Attard
A25: 4 | B25: Javier Viloria | C25: Andrea Magaldi
A26: 5 | B26: Trevor Rutter | C26: Karolina Papiernak
A27: 6 | B27: Jesmond Pule' | C27: Angele Pule'
B29: Division 4
A30: 1 | B30: Luke Genuis | C30: Dorianne Buhagiar
A31: 2 | B31: George Grech | C31: Jade Sammut
A32: 3 | B32: Daniel Farrugia | C32: Diane Farrugia
A33: 4 | B33: Luigi Porto | C33: Vanessa Farrugia
A34: 5 | B34: James Farrugia | C34: Nancy Wong
A35: 6 | B35: Simone Re | C35: Ann Marie Attard
B37: Division 5
A38: 1 | B38: Dylan Birmingham | C38: Sarah Axiaq
A39: 2 | B39: JP Sciberras | C39: Brenda Baldacchino
A40: 3 | B40: Juan Sammut | C40: Maria Angela Gambin
A41: 4 | B41: Robert Attard | C41: Silvana Portelli
A42: 5 | B42: Kenneth Farrugia | C42: Rowena Caruana
A43: 6 | B43: Dorian Demanuele | C43: Maria Ellul
B45: Division 6 - Group A | F45: Division 6 - Group B
A46: 1 | B46: Dayle Scicluna | C46: Alida Borg | E46: 1 | F46: Cory Greenland | G46: Sabrina Xuereb
A47: 2 | B47: Dunstan Vella | C47: Tiziana Spiteri | E47: 2 | F47: Steve Gambin | G47: Suzanne Gambin
A48: 3 | B48: Isaac Baldacchino | C48: Janice Galea | E48: 3 | F48: Justin Scicluna | G48: Leanne Sammut
...

Sheet Division 1
A1: ESS Mixed Doubles 2025
A5: Division 1
A7: Players | B7: Set Scores | H7: Tie | P7: Players | Q7: Set Scores | W7: Tie | AE7: Player | AF7: Matches Played | AG7: Points Overall | AH7: Games Won | AI7: Sets Won
B8: Score | C8: Set 1 Work | E8: Score | F8: Set 2 Work | H8: Score | I8: Tie Work | J8: Game Played | K8: Sets Points Work | L8: Sets & Tie Points Work | M8: Games Wins Work | N8: Sets Wins Work | Q8: Score | R8: Set 1 Work | T8: Score | U8: Set 2 Work | W8: Score | X8: Tie Work | Y8: Game Played | Z8: Sets Points Work | AA8: Sets & Tie Points Work | AB8: Games Wins Work | AC8: Sets Wins Work | AJ8: Winner Working | AK8: Runner Up Working | AL8: Total Games Work | AM8: Winner | AN8: Runner Up
A9: =AE9 -> Matthew Mifsud / Lara Pule' | C9: =IF(B9>B11,1,0) -> 0 | F9: =IF(E9>E11,1,0) -> 0 | I9: =IF(H9>H11,1,0) -> 0 | J9: =IF(B9="",0,1) -> 0 | K9: =IF(C9+F9=2,3,IF(C9+F9=1,1,0)) -> 0 | L9: =IF(K9=3,3,IF(I9+K9=2,2,IF(K9=1,1,0))) -> 0 | M9: =B9+E9 -> 0 | N9: =C9+F9+I9 -> 0 | P9: =AE9 -> Matthew Mifsud / Lara Pule' | Q9: 6 | R9: =IF(Q9>Q11,1,0) -> 1 | T9: 6 | U9: =IF(T9>T11,1,0) -> 1 | X9: =IF(W9>W11,1,0) -> 0 | Y9: =IF(Q9="",0,1) -> 1 | Z9: =IF(R9+U9=2,3,IF(R9+U9=1,1,0)) -> 3 | AA9: =IF(Z9=3,3,IF(X9+Z9=2,2,IF(Z9=1,1,0))) -> 3 | AB9: =Q9+T9 -> 12 | AC9: =R9+U9+X9 -> 2 | AE9: =Players!B6& " / " &Players!C6 -> Matthew Mifsud / Lara Pule' | AF9: =J9+Y9+J13+J17+J29 -> 4 | AG9: =L17+AA9+L13+L9+L29 -> 9 | AH9: =M17+AB9+M13+M9+M29 -> 41 | AI9: =N17+AC9+N13+N9+N29 -> 6
A10: vs. | P10: vs.
A11: =AE11 -> Matthew Borg / Ann Marie Mangion | C11: =IF(B11>B9,1,0) -> 0 | F11: =IF(E11>E9,1,0) -> 0 | I11: =IF(H11>H9,1,0) -> 0 | J11: =IF(B11="",0,1) -> 0 | K11: =IF(C11+F11=2,3,IF(C11+F11=1,1,0)) -> 0 | L11: =IF(K11=3,3,IF(I11+K11=2,2,IF(K11=1,1,0))) -> 0 | M11: =B11+E11 -> 0 | N11: =C11+F11+I11 -> 0 | P11: =AE15 -> Melchior Farrugia / Julie Spiteri | Q11: 3 | R11: =IF(Q11>Q9,1,0) -> 0 | T11: 2 | U11: =IF(T11>T9,1,0) -> 0 | X11: =IF(W11>W9,1,0) -> 0 | Y11: =IF(Q11="",0,1) -> 1 | Z11: =IF(R11+U11=2,3,IF(R11+U11=1,1,0)) -> 0 | AA11: =IF(Z11=3,3,IF(X11+Z11=2,2,IF(Z11=1,1,0))) -> 0 | AB11: =Q11+T11 -> 5 | AC11: =R11+U11+X11 -> 0 | AE11: =Players!B7& " / " &Players!C7 -> Matthew Borg / Ann Marie Mangion | AF11: =Y21+Y25+Y13+J11+Y29 -> 0 | AG11: =AA21+AA25+AA13+L11+AA29 -> 0 | AH11: =AB21+AB25+AB13+M11+AB29 -> 0 | AI11: =AC21+AC25+AC13+N11+AC29 -> 0
A13: =AE9 -> Matthew Mifsud / Lara Pule' | B13: 5 | C13: =IF(B13>B15,1,0) -> 0 | E13: 0 | F13: =IF(E13>E15,1,0) -> 0 | I13: =IF(H13>H15,1,0) -> 0 | J13: =IF(B13="",0,1) -> 1 | K13: =IF(C13+F13=2,3,IF(C13+F13=1,1,0)) -> 0 | L13: =IF(K13=3,3,IF(I13+K13=2,2,IF(K13=1,1,0))) -> 0 | M13: =B13+E13 -> 5 | N13: =C13+F13+I13 -> 0 | P13: =AE11 -> Matthew Borg / Ann Marie Mangion | R13: =IF(Q13>Q15,1,0) -> 0 | U13: =IF(T13>T15,1,0) -> 0 | X13: =IF(W13>W15,1,0) -> 0 | Y13: =IF(Q13="",0,1) -> 0 | Z13: =IF(R13+U13=2,3,IF(R13+U13=1,1,0)) -> 0 | AA13: =IF(Z13=3,3,IF(X13+Z13=2,2,IF(Z13=1,1,0))) -> 0 | AB13: =Q13+T13 -> 0 | AC13: =R13+U13+X13 -> 0 | AE13: =Players!B8& " / " &Players!C8 -> Duncan D'alessandro / Renette Magro | AF13: =Y23+Y17+J15+J21+J33 -> 3 | AG13: =AA23+AA17+L15+L21+L33 -> 9 | AH13: =AB23+AB17+M15+M21+M33 -> 37 | AI13: =AC23+AC17+N15+N21+N33 -> 6
A14: vs. | P14: vs.
A15: =AE13 -> Duncan D'alessandro / Renette Magro | B15: 7 | C15: =IF(B15>B13,1,0) -> 1 | E15: 6 | F15: =IF(E15>E13,1,0) -> 1 | I15: =IF(H15>H13,1,0) -> 0 | J15: =IF(B15="",0,1) -> 1 | K15: =IF(C15+F15=2,3,IF(C15+F15=1,1,0)) -> 3 | L15: =IF(K15=3,3,IF(I15+K15=2,2,IF(K15=1,1,0))) -> 3 | M15: =B15+E15 -> 13 | N15: =C15+F15+I15 -> 2 | P15: =AE15 -> Melchior Farrugia / Julie Spiteri | R15: =IF(Q15>Q13,1,0) -> 0 | U15: =IF(T15>T13,1,0) -> 0 | X15: =IF(W15>W13,1,0) -> 0 | Y15: =IF(Q15="",0,1) -> 0 | Z15: =IF(R15+U15=2,3,IF(R15+U15=1,1,0)) -> 0 | AA15: =IF(Z15=3,3,IF(X15+Z15=2,2,IF(Z15=1,1,0))) -> 0 | AB15: =Q15+T15 -> 0 | AC15: =R15+U15+X15 -> 0 | AE15: =Players!B9& " / " &Players!C9 -> Melchior Farrugia / Julie Spiteri | AF15: =J25+Y19+Y11+Y15+Y33 -> 4 | AG15: =L25+AA19+AA11+AA15+AA33 -> 4 | AH15: =M25+AB19+AB11+AB15+AB33 -> 25 | AI15: =N25+AC19+AC11+AC15+AC33 -> 4
A17: =AE9 -> Matthew Mifsud / Lara Pule' | B17: 6 | C17: =IF(B17>B19,1,0) -> 1 | E17: 6 | F17: =IF(E17>E19,1,0) -> 1 | I17: =IF(H17>H19,1,0) -> 0 | J17: =IF(B17="",0,1) -> 1 | K17: =IF(C17+F17=2,3,IF(C17+F17=1,1,0)) -> 3 | L17: =IF(K17=3,3,IF(I17+K17=2,2,IF(K17=1,1,0))) -> 3 | M17: =B17+E17 -> 12 | N17: =C17+F17+I17 -> 2 | P17: =AE13 -> Duncan D'alessandro / Renette Magro | Q17: 6 | R17: =IF(Q17>Q19,1,0) -> 1 | T17: 6 | U17: =IF(T17>T19,1,0) -> 1 | X17: =IF(W17>W19,1,0) -> 0 | Y17: =IF(Q17="",0,1) -> 1 | Z17: =IF(R17+U17=2,3,IF(R17+U17=1,1,0)) -> 3 | AA17: =IF(Z17=3,3,IF(X17+Z17=2,2,IF(Z17=1,1,0))) -> 3 | AB17: =Q17+T17 -> 12 | AC17: =R17+U17+X17 -> 2 | AE17: =Players!B10& " / " &Players!C10 -> Kurt Carabott / Pierina Holmin | AF17: =J23+J27+Y27+J19+J37 -> 4 | AG17: =L27+L19+AA27+L23+L37 -> 3 | AH17: =M27+M19+AB27+M23+M37 -> 25 | AI17: =N27+N19+AC27+N23+N37 -> 3
A18: vs. | P18: vs.
A19: =AE17 -> Kurt Carabott / Pierina Holmin | B19: 2 | C19: =IF(B19>B17,1,0) -> 0 | E19: 3 | F19: =IF(E19>E17,1,0) -> 0 | I19: =IF(H19>H17,1,0) -> 0 | J19: =IF(B19="",0,1) -> 1 | K19: =IF(C19+F19=2,3,IF(C19+F19=1,1,0)) -> 0 | L19: =IF(K19=3,3,IF(I19+K19=2,2,IF(K19=1,1,0))) -> 0 | M19: =B19+E19 -> 5 | N19: =C19+F19+I19 -> 0 | P19: =AE15 -> Melchior Farrugia / Julie Spiteri | Q19: 3 | R19: =IF(Q19>Q17,1,0) -> 0 | T19: 0 | U19: =IF(T19>T17,1,0) -> 0 | X19: =IF(W19>W17,1,0) -> 0 | Y19: =IF(Q19="",0,1) -> 1 | Z19: =IF(R19+U19=2,3,IF(R19+U19=1,1,0)) -> 0 | AA19: =IF(Z19=3,3,IF(X19+Z19=2,2,IF(Z19=1,1,0))) -> 0 | AB19: =Q19+T19 -> 3 | AC19: =R19+U19+X19 -> 0 | AD19: RET | AE19: =Players!B11& " / " &Players!C11 -> Jean Attard / Yanika Pace | AF19: =J31+J35+J39+Y31+Y35 -> 3 | AG19: =L31+L35+L39+AA31+AA35 -> 2 | AH19: =M31+M35+M39+AB31+AB35 -> 25 | AI19: =N31+N35+N39+AC31+AC35 -> 2
A21: =AE13 -> Duncan D'alessandro / Renette Magro | B21: 6 | C21: =IF(B21>B23,1,0) -> 1 | E21: 6 | F21: =IF(E21>E23,1,0) -> 1 | I21: =IF(H21>H23,1,0) -> 0 | J21: =IF(B21="",0,1) -> 1 | K21: =IF(C21+F21=2,3,IF(C21+F21=1,1,0)) -> 3 | L21: =IF(K21=3,3,IF(I21+K21=2,2,IF(K21=1,1,0))) -> 3 | M21: =B21+E21 -> 12 | N21: =C21+F21+I21 -> 2 | P21: =AE11 -> Matthew Borg / Ann Marie Mangion | R21: =IF(Q21>Q23,1,0) -> 0 | U21: =IF(T21>T23,1,0) -> 0 | X21: =IF(W21>W23,1,0) -> 0 | Y21: =IF(Q21="",0,1) -> 0 | Z21: =IF(R21+U21=2,3,IF(R21+U21=1,1,0)) -> 0 | AA21: =IF(Z21=3,3,IF(X21+Z21=2,2,IF(Z21=1,1,0))) -> 0 | AB21: =Q21+T21 -> 0 | AC21: =R21+U21+X21 -> 0 | AE21: Divison Winner
A22: vs. | P22: vs. | AE22: Duncan D'alessadro/Renette Magro
A23: =AE17 -> Kurt Carabott / Pierina Holmin | B23: 1 | C23: =IF(B23>B21,1,0) -> 0 | E23: 1 | F23: =IF(E23>E21,1,0) -> 0 | I23: =IF(H23>H21,1,0) -> 0 | J23: =IF(B23="",0,1) -> 1 | K23: =IF(C23+F23=2,3,IF(C23+F23=1,1,0)) -> 0 | L23: =IF(K23=3,3,IF(I23+K23=2,2,IF(K23=1,1,0))) -> 0 | M23: =B23+E23 -> 2 | N23: =C23+F23+I23 -> 0 | P23: =AE13 -> Duncan D'alessandro / Renette Magro | R23: =IF(Q23>Q21,1,0) -> 0 | U23: =IF(T23>T21,1,0) -> 0 | X23: =IF(W23>W21,1,0) -> 0 | Y23: =IF(Q23="",0,1) -> 0 | Z23: =IF(R23+U23=2,3,IF(R23+U23=1,1,0)) -> 0 | AA23: =IF(Z23=3,3,IF(X23+Z23=2,2,IF(Z23=1,1,0))) -> 0 | AB23: =Q23+T23 -> 0 | AC23: =R23+U23+X23 -> 0
A25: =AE15 -> Melchior Farrugia / Julie Spiteri | B25: 6 | C25: =IF(B25>B27,1,0) -> 1 | E25: 2 | F25: =IF(E25>E27,1,0) -> 0 | H25: 10 | I25: =IF(H25>H27,1,0) -> 1 | J25: =IF(B25="",0,1) -> 1 | K25: =IF(C25+F25=2,3,IF(C25+F25=1,1,0)) -> 1 | L25: =IF(K25=3,3,IF(I25+K25=2,2,IF(K25=1,1,0))) -> 2 | M25: =B25+E25 -> 8 | N25: =C25+F25+I25 -> 2 | P25: =AE11 -> Matthew Borg / Ann Marie Mangion | R25: =IF(Q25>Q27,1,0) -> 0 | U25: =IF(T25>T27,1,0) -> 0 | X25: =IF(W25>W27,1,0) -> 0 | Y25: =IF(Q25="",0,1) -> 0 | Z25: =IF(R25+U25=2,3,IF(R25+U25=1,1,0)) -> 0 | AA25: =IF(Z25=3,3,IF(X25+Z25=2,2,IF(Z25=1,1,0))) -> 0 | AB25: =Q25+T25 -> 0 | AC25: =R25+U25+X25 -> 0 | AE25: Divison Runner Up
A26: vs. | P26: vs. | AE26: Matthew Mifsud/Lara Pule'
A27: =AE17 -> Kurt Carabott / Pierina Holmin | B27: 4 | C27: =IF(B27>B25,1,0) -> 0 | E27: 6 | F27: =IF(E27>E25,1,0) -> 1 | H27: 8 | I27: =IF(H27>H25,1,0) -> 0 | J27: =IF(B27="",0,1) -> 1 | K27: =IF(C27+F27=2,3,IF(C27+F27=1,1,0)) -> 1 | L27: =IF(K27=3,3,IF(I27+K27=2,2,IF(K27=1,1,0))) -> 1 | M27: =B27+E27 -> 10 | N27: =C27+F27+I27 -> 1 | P27: =AE17 -> Kurt Carabott / Pierina Holmin | R27: =IF(Q27>Q25,1,0) -> 0 | U27: =IF(T27>T25,1,0) -> 0 | X27: =IF(W27>W25,1,0) -> 0 | Y27: =IF(Q27="",0,1) -> 0 | Z27: =IF(R27+U27=2,3,IF(R27+U27=1,1,0)) -> 0 | AA27: =IF(Z27=3,3,IF(X27+Z27=2,2,IF(Z27=1,1,0))) -> 0 | AB27: =Q27+T27 -> 0 | AC27: =R27+U27+X27 -> 0
A29: =AE9 -> Matthew Mifsud / Lara Pule' | B29: 6 | C29: =IF(B29>B31,1,0) -> 1 | E29: 6 | F29: =IF(E29>E31,1,0) -> 1 | I29: =IF(H29>H31,1,0) -> 0 | J29: =IF(B29="",0,1) -> 1 | K29: =IF(C29+F29=2,3,IF(C29+F29=1,1,0)) -> 3 | L29: =IF(K29=3,3,IF(I29+K29=2,2,IF(K29=1,1,0))) -> 3 | M29: =B29+E29 -> 12 | N29: =C29+F29+I29 -> 2 | P29: =AE11 -> Matthew Borg / Ann Marie Mangion | R29: =IF(Q29>Q31,1,0) -> 0 | U29: =IF(T29>T31,1,0) -> 0 | X29: =IF(W29>W31,1,0) -> 0 | Y29: =IF(Q29="",0,1) -> 0 | Z29: =IF(R29+U29=2,3,IF(R29+U29=1,1,0)) -> 0 | AA29: =IF(Z29=3,3,IF(X29+Z29=2,2,IF(Z29=1,1,0))) -> 0 | AB29: =Q29+T29 -> 0 | AC29: =R29+U29+X29 -> 0
A30: vs. | P30: vs.
A31: =AE19 -> Jean Attard / Yanika Pace | B31: 3 | C31: =IF(B31>B29,1,0) -> 0 | E31: 3 | F31: =IF(E31>E29,1,0) -> 0 | I31: =IF(H31>H29,1,0) -> 0 | J31: =IF(B31="",0,1) -> 1 | K31: =IF(C31+F31=2,3,IF(C31+F31=1,1,0)) -> 0 | L31: =IF(K31=3,3,IF(I31+K31=2,2,IF(K31=1,1,0))) -> 0 | M31: =B31+E31 -> 6 | N31: =C31+F31+I31 -> 0 | P31: =AE19 -> Jean Attard / Yanika Pace | R31: =IF(Q31>Q29,1,0) -> 0 | U31: =IF(T31>T29,1,0) -> 0 | X31: =IF(W31>W29,1,0) -> 0 | Y31: =IF(Q31="",0,1) -> 0 | Z31: =IF(R31+U31=2,3,IF(R31+U31=1,1,0)) -> 0 | AA31: =IF(Z31=3,3,IF(X31+Z31=2,2,IF(Z31=1,1,0))) -> 0 | AB31: =Q31+T31 -> 0 | AC31: =R31+U31+X31 -> 0
A33: =AE13 -> Duncan D'alessandro / Renette Magro | C33: =IF(B33>B35,1,0) -> 0 | F33: =IF(E33>E35,1,0) -> 0 | I33: =IF(H33>H35,1,0) -> 0 | J33: =IF(B33="",0,1) -> 0 | K33: =IF(C33+F33=2,3,IF(C33+F33=1,1,0)) -> 0 | L33: =IF(K33=3,3,IF(I33+K33=2,2,IF(K33=1,1,0))) -> 0 | M33: =B33+E33 -> 0 | N33: =C33+F33+I33 -> 0 | P33: =AE15 -> Melchior Farrugia / Julie Spiteri | Q33: 6 | R33: =IF(Q33>Q35,1,0) -> 1 | T33: 3 | U33: =IF(T33>T35,1,0) -> 0 | W33: 10 | X33: =IF(W33>W35,1,0) -> 1 | Y33: =IF(Q33="",0,1) -> 1 | Z33: =IF(R33+U33=2,3,IF(R33+U33=1,1,0)) -> 1 | AA33: =IF(Z33=3,3,IF(X33+Z33=2,2,IF(Z33=1,1,0))) -> 2 | AB33: =Q33+T33 -> 9 | AC33: =R33+U33+X33 -> 2
A34: vs. | P34: vs.
A35: =AE19 -> Jean Attard / Yanika Pace | C35: =IF(B35>B33,1,0) -> 0 | F35: =IF(E35>E33,1,0) -> 0 | I35: =IF(H35>H33,1,0) -> 0 | J35: =IF(B35="",0,1) -> 0 | K35: =IF(C35+F35=2,3,IF(C35+F35=1,1,0)) -> 0 | L35: =IF(K35=3,3,IF(I35+K35=2,2,IF(K35=1,1,0))) -> 0 | M35: =B35+E35 -> 0 | N35: =C35+F35+I35 -> 0 | P35: =AE19 -> Jean Attard / Yanika Pace | Q35: 4 | R35: =IF(Q35>Q33,1,0) -> 0 | T35: 6 | U35: =IF(T35>T33,1,0) -> 1 | W35: 8 | X35: =IF(W35>W33,1,0) -> 0 | Y35: =IF(Q35="",0,1) -> 1 | Z35: =IF(R35+U35=2,3,IF(R35+U35=1,1,0)) -> 1 | AA35: =IF(Z35=3,3,IF(X35+Z35=2,2,IF(Z35=1,1,0))) -> 1 | AB35: =Q35+T35 -> 10 | AC35: =R35+U35+X35 -> 1
A37: =AE17 -> Kurt Carabott / Pierina Holmin | B37: 6 | C37: =IF(B37>B39,1,0) -> 1 | E37: 2 | F37: =IF(E37>E39,1,0) -> 0 | H37: 10 | I37: =IF(H37>H39,1,0) -> 1 | J37: =IF(B37="",0,1) -> 1 | K37: =IF(C37+F37=2,3,IF(C37+F37=1,1,0)) -> 1 | L37: =IF(K37=3,3,IF(I37+K37=2,2,IF(K37=1,1,0))) -> 2 | M37: =B37+E37 -> 8 | N37: =C37+F37+I37 -> 2
A38: vs.
A39: =AE19 -> Jean Attard / Yanika Pace | B39: 3 | C39: =IF(B39>B37,1,0) -> 0 | E39: 6 | F39: =IF(E39>E37,1,0) -> 1 | H39: 4 | I39: =IF(H39>H37,1,0) -> 0 | J39: =IF(B39="",0,1) -> 1 | K39: =IF(C39+F39=2,3,IF(C39+F39=1,1,0)) -> 1 | L39: =IF(K39=3,3,IF(I39+K39=2,2,IF(K39=1,1,0))) -> 1 | M39: =B39+E39 -> 9 | N39: =C39+F39+I39 -> 1

Sheet Division 2
A5: Division 2
A7: Players | B7: Set Scores | H7: Tie | P7: Players | Q7: Set Scores | W7: Tie | AE7: Player | AF7: Matches Played | AG7: Points Overall | AH7: Games Won | AI7: Sets Won
B8: Score | C8: Set 1 Work | E8: Score | F8: Set 2 Work | H8: Score | I8: Tie Work | J8: Game Played | K8: Sets Points Work | L8: Sets & Tie Points Work | M8: Games Wins Work | N8: Sets Wins Work | Q8: Score | R8: Set 1 Work | T8: Score | U8: Set 2 Work | W8: Score | X8: Tie Work | Y8: Game Played | Z8: Sets Points Work | AA8: Sets & Tie Points Work | AB8: Games Wins Work | AC8: Sets Wins Work | AJ8: Winner Working | AK8: Runner Up Working | AL8: Total Games Work | AM8: Winner | AN8: Runner Up
A9: =AE9 -> Harvey Wadge / Giada Sciberras | B9: 6 | C9: =IF(B9>B11,1,0) -> 1 | E9: 6 | F9: =IF(E9>E11,1,0) -> 1 | I9: =IF(H9>H11,1,0) -> 0 | J9: =IF(B9="",0,1) -> 1 | K9: =IF(C9+F9=2,3,IF(C9+F9=1,1,0)) -> 3 | L9: =IF(K9=3,3,IF(I9+K9=2,2,IF(K9=1,1,0))) -> 3 | M9: =B9+E9 -> 12 | N9: =C9+F9+I9 -> 2 | P9: =AE9 -> Harvey Wadge / Giada Sciberras | Q9: 6 | R9: =IF(Q9>Q11,1,0) -> 1 | T9: 7 | U9: =IF(T9>T11,1,0) -> 1 | X9: =IF(W9>W11,1,0) -> 0 | Y9: =IF(Q9="",0,1) -> 1 | Z9: =IF(R9+U9=2,3,IF(R9+U9=1,1,0)) -> 3 | AA9: =IF(Z9=3,3,IF(X9+Z9=2,2,IF(Z9=1,1,0))) -> 3 | AB9: =Q9+T9 -> 13 | AC9: =R9+U9+X9 -> 2 | AE9: =Players!B14& " / " &Players!C14 -> Harvey Wadge / Giada Sciberras | AF9: =J9+Y9+J13+Y13+J17 -> 5 | AG9: =L9+AA9+L13+AA13+L17 -> 14 | AH9: =M9+AB9+M13+AB13+M17 -> 60 | AI9: =N9+AC9+N13+AC13+N17 -> 10
A10: vs. | P10: vs.
A11: =AE11 -> Kristen Cachia / Francesca Sciortino | B11: 3 | C11: =IF(B11>B9,1,0) -> 0 | E11: 2 | F11: =IF(E11>E9,1,0) -> 0 | I11: =IF(H11>H9,1,0) -> 0 | J11: =IF(B11="",0,1) -> 1 | K11: =IF(C11+F11=2,3,IF(C11+F11=1,1,0)) -> 0 | L11: =IF(K11=3,3,IF(I11+K11=2,2,IF(K11=1,1,0))) -> 0 | M11: =B11+E11 -> 5 | N11: =C11+F11+I11 -> 0 | P11: =AE13 -> Keith Micallef / Mirka Micallef | Q11: 3 | R11: =IF(Q11>Q9,1,0) -> 0 | T11: 5 | U11: =IF(T11>T9,1,0) -> 0 | X11: =IF(W11>W9,1,0) -> 0 | Y11: =IF(Q11="",0,1) -> 1 | Z11: =IF(R11+U11=2,3,IF(R11+U11=1,1,0)) -> 0 | AA11: =IF(Z11=3,3,IF(X11+Z11=2,2,IF(Z11=1,1,0))) -> 0 | AB11: =Q11+T11 -> 8 | AC11: =R11+U11+X11 -> 0 | AE11: =Players!B15& " / " &Players!C15 -> Kristen Cachia / Francesca Sciortino | AF11: =J11+Y25+J21+Y21+Y17 -> 5 | AG11: =L11+AA25+L21+AA21+AA17 -> 2 | AH11: =M11+AB25+M21+AB21+AB17 -> 35 | AI11: =N11+AC25+N21+AC21+AC17 -> 2
A13: =AE9 -> Harvey Wadge / Giada Sciberras | B13: 4 | C13: =IF(B13>B15,1,0) -> 0 | E13: 6 | F13: =IF(E13>E15,1,0) -> 1 | H13: 10 | I13: =IF(H13>H15,1,0) -> 1 | J13: =IF(B13="",0,1) -> 1 | K13: =IF(C13+F13=2,3,IF(C13+F13=1,1,0)) -> 1 | L13: =IF(K13=3,3,IF(I13+K13=2,2,IF(K13=1,1,0))) -> 2 | M13: =B13+E13 -> 10 | N13: =C13+F13+I13 -> 2 | P13: =AE9 -> Harvey Wadge / Giada Sciberras | Q13: 6 | R13: =IF(Q13>Q15,1,0) -> 1 | T13: 6 | U13: =IF(T13>T15,1,0) -> 1 | X13: =IF(W13>W15,1,0) -> 0 | Y13: =IF(Q13="",0,1) -> 1 | Z13: =IF(R13+U13=2,3,IF(R13+U13=1,1,0)) -> 3 | AA13: =IF(Z13=3,3,IF(X13+Z13=2,2,IF(Z13=1,1,0))) -> 3 | AB13: =Q13+T13 -> 12 | AC13: =R13+U13+X13 -> 2 | AE13: =Players!B16& " / " &Players!C16 -> Keith Micallef / Mirka Micallef | AF13: =Y29+Y11+Y33+J25+Y19 -> 4 | AG13: =AA29+AA11+AA33+L25+AA19 -> 6 | AH13: =AB29+AB11+AB33+M25+AB19 -> 40 | AI13: =AC29+AC11+AC33+N25+AC19 -> 4
A14: vs. | P14: vs.
A15: =AE15 -> Jonathan Martinelli / Christina Bonett | B15: 6 | C15: =IF(B15>B13,1,0) -> 1 | E15: 4 | F15: =IF(E15>E13,1,0) -> 0 | H15: 8 | I15: =IF(H15>H13,1,0) -> 0 | J15: =IF(B15="",0,1) -> 1 | K15: =IF(C15+F15=2,3,IF(C15+F15=1,1,0)) -> 1 | L15: =IF(K15=3,3,IF(I15+K15=2,2,IF(K15=1,1,0))) -> 1 | M15: =B15+E15 -> 10 | N15: =C15+F15+I15 -> 1 | P15: =AE17 -> Stefan Holmin / Alison Muscat | Q15: 2 | R15: =IF(Q15>Q13,1,0) -> 0 | T15: 1 | U15: =IF(T15>T13,1,0) -> 0 | X15: =IF(W15>W13,1,0) -> 0 | Y15: =IF(Q15="",0,1) -> 1 | Z15: =IF(R15+U15=2,3,IF(R15+U15=1,1,0)) -> 0 | AA15: =IF(Z15=3,3,IF(X15+Z15=2,2,IF(Z15=1,1,0))) -> 0 | AB15: =Q15+T15 -> 3 | AC15: =R15+U15+X15 -> 0 | AE15: =Players!B17& " / " &Players!C17 -> Jonathan Martinelli / Christina Bonett | AF15: =Y31+J37+J15+Y23+J29 -> 5 | AG15: =AA31+L37+L15+AA23+L29 -> 12 | AH15: =AB31+M37+M15+AB23+M29 -> 57 | AI15: =AC31+N37+N15+AC23+N29 -> 9
A17: =AE9 -> Harvey Wadge / Giada Sciberras | B17: 7 | C17: =IF(B17>B19,1,0) -> 1 | E17: 6 | F17: =IF(E17>E19,1,0) -> 1 | I17: =IF(H17>H19,1,0) -> 0 | J17: =IF(B17="",0,1) -> 1 | K17: =IF(C17+F17=2,3,IF(C17+F17=1,1,0)) -> 3 | L17: =IF(K17=3,3,IF(I17+K17=2,2,IF(K17=1,1,0))) -> 3 | M17: =B17+E17 -> 13 | N17: =C17+F17+I17 -> 2 | P17: =AE11 -> Kristen Cachia / Francesca Sciortino | Q17: 3 | R17: =IF(Q17>Q19,1,0) -> 0 | T17: 2 | U17: =IF(T17>T19,1,0) -> 0 | X17: =IF(W17>W19,1,0) -> 0 | Y17: =IF(Q17="",0,1) -> 1 | Z17: =IF(R17+U17=2,3,IF(R17+U17=1,1,0)) -> 0 | AA17: =IF(Z17=3,3,IF(X17+Z17=2,2,IF(Z17=1,1,0))) -> 0 | AB17: =Q17+T17 -> 5 | AC17: =R17+U17+X17 -> 0 | AE17: =Players!B18& " / " &Players!C18 -> Stefan Holmin / Alison Muscat | AF17: =J33+J39+J23+Y15+J27 -> 5 | AG17: =L33+L39+L23+AA15+L27 -> 3 | AH17: =M33+M39+M23+AB15+M27 -> 34 | AI17: =N33+N39+N23+AC15+N27 -> 3
A18: vs. | P18: vs.
A19: =AE19 -> Ivan Cassar / Dawn Azzopardi | B19: 6 | C19: =IF(B19>B17,1,0) -> 0 | E19: 4 | F19: =IF(E19>E17,1,0) -> 0 | I19: =IF(H19>H17,1,0) -> 0 | J19: =IF(B19="",0,1) -> 1 | K19: =IF(C19+F19=2,3,IF(C19+F19=1,1,0)) -> 0 | L19: =IF(K19=3,3,IF(I19+K19=2,2,IF(K19=1,1,0))) -> 0 | M19: =B19+E19 -> 10 | N19: =C19+F19+I19 -> 0 | P19: =AE13 -> Keith Micallef / Mirka Micallef | Q19: 6 | R19: =IF(Q19>Q17,1,0) -> 1 | T19: 6 | U19: =IF(T19>T17,1,0) -> 1 | X19: =IF(W19>W17,1,0) -> 0 | Y19: =IF(Q19="",0,1) -> 1 | Z19: =IF(R19+U19=2,3,IF(R19+U19=1,1,0)) -> 3 | AA19: =IF(Z19=3,3,IF(X19+Z19=2,2,IF(Z19=1,1,0))) -> 3 | AB19: =Q19+T19 -> 12 | AC19: =R19+U19+X19 -> 2 | AE19: =Players!B19& " / " &Players!C19 -> Ivan Cassar / Dawn Azzopardi | AF19: =J35+Y27+Y35+J19+J31 -> 4 | AG19: =L35+AA27+AA35+L19+L31 -> 5 | AH19: =M35+AB27+AB35+M19+M31 -> 38 | AI19: =N35+AC27+AC35+N19+N31 -> 4
A21: =AE11 -> Kristen Cachia / Francesca Sciortino | B21: 7 | C21: =IF(B21>B23,1,0) -> 1 | E21: 3 | F21: =IF(E21>E23,1,0) -> 0 | H21: 5 | I21: =IF(H21>H23,1,0) -> 0 | J21: =IF(B21="",0,1) -> 1 | K21: =IF(C21+F21=2,3,IF(C21+F21=1,1,0)) -> 1 | L21: =IF(K21=3,3,IF(I21+K21=2,2,IF(K21=1,1,0))) -> 1 | M21: =B21+E21 -> 10 | N21: =C21+F21+I21 -> 1 | P21: =AE11 -> Kristen Cachia / Francesca Sciortino | Q21: 6 | R21: =IF(Q21>Q23,1,0) -> 1 | T21: 2 | U21: =IF(T21>T23,1,0) -> 0 | W21: 3 | X21: =IF(W21>W23,1,0) -> 0 | Y21: =IF(Q21="",0,1) -> 1 | Z21: =IF(R21+U21=2,3,IF(R21+U21=1,1,0)) -> 1 | AA21: =IF(Z21=3,3,IF(X21+Z21=2,2,IF(Z21=1,1,0))) -> 1 | AB21: =Q21+T21 -> 8 | AC21: =R21+U21+X21 -> 1 | AE21: Divison Winner
A22: vs. | P22: vs. | AE22: Harvey Wadge/Giada Sciberras
A23: =AE17 -> Stefan Holmin / Alison Muscat | B23: 6 | C23: =IF(B23>B21,1,0) -> 0 | E23: 6 | F23: =IF(E23>E21,1,0) -> 1 | H23: 10 | I23: =IF(H23>H21,1,0) -> 1 | J23: =IF(B23="",0,1) -> 1 | K23: =IF(C23+F23=2,3,IF(C23+F23=1,1,0)) -> 1 | L23: =IF(K23=3,3,IF(I23+K23=2,2,IF(K23=1,1,0))) -> 2 | M23: =B23+E23 -> 12 | N23: =C23+F23+I23 -> 2 | P23: =AE15 -> Jonathan Martinelli / Christina Bonett | Q23: 4 | R23: =IF(Q23>Q21,1,0) -> 0 | T23: 6 | U23: =IF(T23>T21,1,0) -> 1 | W23: 10 | X23: =IF(W23>W21,1,0) -> 1 | Y23: =IF(Q23="",0,1) -> 1 | Z23: =IF(R23+U23=2,3,IF(R23+U23=1,1,0)) -> 1 | AA23: =IF(Z23=3,3,IF(X23+Z23=2,2,IF(Z23=1,1,0))) -> 2 | AB23: =Q23+T23 -> 10 | AC23: =R23+U23+X23 -> 2
A25: =AE13 -> Keith Micallef / Mirka Micallef | B25: 6 | C25: =IF(B25>B27,1,0) -> 1 | E25: 6 | F25: =IF(E25>E27,1,0) -> 1 | I25: =IF(H25>H27,1,0) -> 0 | J25: =IF(B25="",0,1) -> 1 | K25: =IF(C25+F25=2,3,IF(C25+F25=1,1,0)) -> 3 | L25: =IF(K25=3,3,IF(I25+K25=2,2,IF(K25=1,1,0))) -> 3 | M25: =B25+E25 -> 12 | N25: =C25+F25+I25 -> 2 | P25: =AE11 -> Kristen Cachia / Francesca Sciortino | Q25: 5 | R25: =IF(Q25>Q27,1,0) -> 0 | T25: 2 | U25: =IF(T25>T27,1,0) -> 0 | X25: =IF(W25>W27,1,0) -> 0 | Y25: =IF(Q25="",0,1) -> 1 | Z25: =IF(R25+U25=2,3,IF(R25+U25=1,1,0)) -> 0 | AA25: =IF(Z25=3,3,IF(X25+Z25=2,2,IF(Z25=1,1,0))) -> 0 | AB25: =Q25+T25 -> 7 | AC25: =R25+U25+X25 -> 0 | AE25: Divison Runner Up
A26: vs. | P26: vs. | AE26: Jonathan Martinelli/Christina Bonett
A27: =AE17 -> Stefan Holmin / Alison Muscat | B27: 3 | C27: =IF(B27>B25,1,0) -> 0 | E27: 2 | F27: =IF(E27>E25,1,0) -> 0 | I27: =IF(H27>H25,1,0) -> 0 | J27: =IF(B27="",0,1) -> 1 | K27: =IF(C27+F27=2,3,IF(C27+F27=1,1,0)) -> 0 | L27: =IF(K27=3,3,IF(I27+K27=2,2,IF(K27=1,1,0))) -> 0 | M27: =B27+E27 -> 5 | N27: =C27+F27+I27 -> 0 | P27: =AE19 -> Ivan Cassar / Dawn Azzopardi | Q27: 7 | R27: =IF(Q27>Q25,1,0) -> 1 | T27: 6 | U27: =IF(T27>T25,1,0) -> 1 | X27: =IF(W27>W25,1,0) -> 0 | Y27: =IF(Q27="",0,1) -> 1 | Z27: =IF(R27+U27=2,3,IF(R27+U27=1,1,0)) -> 3 | AA27: =IF(Z27=3,3,IF(X27+Z27=2,2,IF(Z27=1,1,0))) -> 3 | AB27: =Q27+T27 -> 13 | AC27: =R27+U27+X27 -> 2
A29: =AE15 -> Jonathan Martinelli / Christina Bonett | B29: 6 | C29: =IF(B29>B31,1,0) -> 1 | E29: 6 | F29: =IF(E29>E31,1,0) -> 1 | I29: =IF(H29>H31,1,0) -> 0 | J29: =IF(B29="",0,1) -> 1 | K29: =IF(C29+F29=2,3,IF(C29+F29=1,1,0)) -> 3 | L29: =IF(K29=3,3,IF(I29+K29=2,2,IF(K29=1,1,0))) -> 3 | M29: =B29+E29 -> 12 | N29: =C29+F29+I29 -> 2 | P29: =AE13 -> Keith Micallef / Mirka Micallef | Q29: 2 | R29: =IF(Q29>Q31,1,0) -> 0 | T29: 6 | U29: =IF(T29>T31,1,0) -> 0 | X29: =IF(W29>W31,1,0) -> 0 | Y29: =IF(Q29="",0,1) -> 1 | Z29: =IF(R29+U29=2,3,IF(R29+U29=1,1,0)) -> 0 | AA29: =IF(Z29=3,3,IF(X29+Z29=2,2,IF(Z29=1,1,0))) -> 0 | AB29: =Q29+T29 -> 8 | AC29: =R29+U29+X29 -> 0
A30: vs. | P30: vs.
A31: =AE19 -> Ivan Cassar / Dawn Azzopardi | B31: 3 | C31: =IF(B31>B29,1,0) -> 0 | E31: 2 | F31: =IF(E31>E29,1,0) -> 0 | I31: =IF(H31>H29,1,0) -> 0 | J31: =IF(B31="",0,1) -> 1 | K31: =IF(C31+F31=2,3,IF(C31+F31=1,1,0)) -> 0 | L31: =IF(K31=3,3,IF(I31+K31=2,2,IF(K31=1,1,0))) -> 0 | M31: =B31+E31 -> 5 | N31: =C31+F31+I31 -> 0 | P31: =AE15 -> Jonathan Martinelli / Christina Bonett | Q31: 6 | R31: =IF(Q31>Q29,1,0) -> 1 | T31: 7 | U31: =IF(T31>T29,1,0) -> 1 | X31: =IF(W31>W29,1,0) -> 0 | Y31: =IF(Q31="",0,1) -> 1 | Z31: =IF(R31+U31=2,3,IF(R31+U31=1,1,0)) -> 3 | AA31: =IF(Z31=3,3,IF(X31+Z31=2,2,IF(Z31=1,1,0))) -> 3 | AB31: =Q31+T31 -> 13 | AC31: =R31+U31+X31 -> 2
A33: =AE17 -> Stefan Holmin / Alison Muscat | B33: 6 | C33: =IF(B33>B35,1,0) -> 1 | E33: 3 | F33: =IF(E33>E35,1,0) -> 0 | H33: 8 | I33: =IF(H33>H35,1,0) -> 0 | J33: =IF(B33="",0,1) -> 1 | K33: =IF(C33+F33=2,3,IF(C33+F33=1,1,0)) -> 1 | L33: =IF(K33=3,3,IF(I33+K33=2,2,IF(K33=1,1,0))) -> 1 | M33: =B33+E33 -> 9 | N33: =C33+F33+I33 -> 1 | P33: =AE13 -> Keith Micallef / Mirka Micallef | R33: =IF(Q33>Q35,1,0) -> 0 | U33: =IF(T33>T35,1,0) -> 0 | X33: =IF(W33>W35,1,0) -> 0 | Y33: =IF(Q33="",0,1) -> 0 | Z33: =IF(R33+U33=2,3,IF(R33+U33=1,1,0)) -> 0 | AA33: =IF(Z33=3,3,IF(X33+Z33=2,2,IF(Z33=1,1,0))) -> 0 | AB33: =Q33+T33 -> 0 | AC33: =R33+U33+X33 -> 0
A34: vs. | P34: vs.
A35: =AE19 -> Ivan Cassar / Dawn Azzopardi | B35: 4 | C35: =IF(B35>B33,1,0) -> 0 | E35: 6 | F35: =IF(E35>E33,1,0) -> 1 | H35: 10 | I35: =IF(H35>H33,1,0) -> 1 | J35: =IF(B35="",0,1) -> 1 | K35: =IF(C35+F35=2,3,IF(C35+F35=1,1,0)) -> 1 | L35: =IF(K35=3,3,IF(I35+K35=2,2,IF(K35=1,1,0))) -> 2 | M35: =B35+E35 -> 10 | N35: =C35+F35+I35 -> 2 | P35: =AE19 -> Ivan Cassar / Dawn Azzopardi | R35: =IF(Q35>Q33,1,0) -> 0 | U35: =IF(T35>T33,1,0) -> 0 | X35: =IF(W35>W33,1,0) -> 0 | Y35: =IF(Q35="",0,1) -> 0 | Z35: =IF(R35+U35=2,3,IF(R35+U35=1,1,0)) -> 0 | AA35: =IF(Z35=3,3,IF(X35+Z35=2,2,IF(Z35=1,1,0))) -> 0 | AB35: =Q35+T35 -> 0 | AC35: =R35+U35+X35 -> 0
A37: =AE15 -> Jonathan Martinelli / Christina Bonett | B37: 6 | C37: =IF(B37>B39,1,0) -> 1 | E37: 6 | F37: =IF(E37>E39,1,0) -> 1 | I37: =IF(H37>H39,1,0) -> 0 | J37: =IF(B37="",0,1) -> 1 | K37: =IF(C37+F37=2,3,IF(C37+F37=1,1,0)) -> 3 | L37: =IF(K37=3,3,IF(I37+K37=2,2,IF(K37=1,1,0))) -> 3 | M37: =B37+E37 -> 12 | N37: =C37+F37+I37 -> 2
A38: vs.
A39: =AE17 -> Stefan Holmin / Alison Muscat | B39: 1 | C39: =IF(B39>B37,1,0) -> 0 | E39: 4 | F39: =IF(E39>E37,1,0) -> 0 | I39: =IF(H39>H37,1,0) -> 0 | J39: =IF(B39="",0,1) -> 1 | K39: =IF(C39+F39=2,3,IF(C39+F39=1,1,0)) -> 0 | L39: =IF(K39=3,3,IF(I39+K39=2,2,IF(K39=1,1,0))) -> 0 | M39: =B39+E39 -> 5 | N39: =C39+F39+I39 -> 0

Sheet Division 3
A1: ESS Mixed Doubles 2025
A5: Division 3
A7: Players | B7: Set Scores | H7: Tie | P7: Players | Q7: Set Scores | W7: Tie | AE7: Player | AF7: Matches Played | AG7: Points Overall | AH7: Games Won | AI7: Sets Won
B8: Score | C8: Set 1 Work | E8: Score | F8: Set 2 Work | H8: Score | I8: Tie Work | J8: Game Played | K8: Sets Points Work | L8: Sets & Tie Points Work | M8: Games Wins Work | N8: Sets Wins Work | Q8: Score | R8: Set 1 Work | T8: Score | U8: Set 2 Work | W8: Score | X8: Tie Work | Y8: Game Played | Z8: Sets Points Work | AA8: Sets & Tie Points Work | AB8: Games Wins Work | AC8: Sets Wins Work | AJ8: Winner Working | AK8: Runner Up Working | AL8: Total Games Work | AM8: Winner | AN8: Runner Up
A9: =AE9 -> Ivan Farrugia / Stephanie Farrugia | B9: 6 | C9: =IF(B9>B11,1,0) -> 1 | E9: 3 | F9: =IF(E9>E11,1,0) -> 0 | H9: 10 | I9: =IF(H9>H11,1,0) -> 1 | J9: =IF(B9="",0,1) -> 1 | K9: =IF(C9+F9=2,3,IF(C9+F9=1,1,0)) -> 1 | L9: =IF(K9=3,3,IF(I9+K9=2,2,IF(K9=1,1,0))) -> 2 | M9: =B9+E9 -> 9 | N9: =C9+F9+I9 -> 2 | P9: =AE9 -> Ivan Farrugia / Stephanie Farrugia | Q9: 6 | R9: =IF(Q9>Q11,1,0) -> 1 | T9: 5 | U9: =IF(T9>T11,1,0) -> 0 | W9: 8 | X9: =IF(W9>W11,1,0) -> 0 | Y9: =IF(Q9="",0,1) -> 1 | Z9: =IF(R9+U9=2,3,IF(R9+U9=1,1,0)) -> 1 | AA9: =IF(Z9=3,3,IF(X9+Z9=2,2,IF(Z9=1,1,0))) -> 1 | AB9: =Q9+T9 -> 11 | AC9: =R9+U9+X9 -> 1 | AE9: =Players!B22& " / " &Players!C22 -> Ivan Farrugia / Stephanie Farrugia | AF9: =J9+Y9+J13+Y13+Y25 -> 5 | AG9: =L9+AA9+L13+AA13+AA25 -> 4 | AH9: =M9+AB9+M13+AB13+AB25 -> 42 | AI9: =N9+AC9+N13+AC13+AC25 -> 4
A10: vs. | P10: vs.
A11: =AE11 -> Willem Steenkamer / Mariska Steenkamer | B11: 4 | C11: =IF(B11>B9,1,0) -> 0 | E11: 6 | F11: =IF(E11>E9,1,0) -> 1 | H11: 7 | I11: =IF(H11>H9,1,0) -> 0 | J11: =IF(B11="",0,1) -> 1 | K11: =IF(C11+F11=2,3,IF(C11+F11=1,1,0)) -> 1 | L11: =IF(K11=3,3,IF(I11+K11=2,2,IF(K11=1,1,0))) -> 1 | M11: =B11+E11 -> 10 | N11: =C11+F11+I11 -> 1 | P11: =AE13 -> Cyril Lastimosa / Jin Attard | Q11: 0 | R11: =IF(Q11>Q9,1,0) -> 0 | T11: 7 | U11: =IF(T11>T9,1,0) -> 1 | W11: 10 | X11: =IF(W11>W9,1,0) -> 1 | Y11: =IF(Q11="",0,1) -> 1 | Z11: =IF(R11+U11=2,3,IF(R11+U11=1,1,0)) -> 1 | AA11: =IF(Z11=3,3,IF(X11+Z11=2,2,IF(Z11=1,1,0))) -> 2 | AB11: =Q11+T11 -> 7 | AC11: =R11+U11+X11 -> 2 | AE11: =Players!B23& " / " &Players!C23 -> Willem Steenkamer / Mariska Steenkamer | AF11: =J11+J21+Y17+J17+Y29 -> 5 | AG11: =L11+L21+AA17+L17+AA29 -> 4 | AH11: =M11+M21+AB17+M17+AB29 -> 35 | AI11: =N11+N21+AC17+N17+AC29 -> 3
A13: =AE9 -> Ivan Farrugia / Stephanie Farrugia | B13: 3 | C13: =IF(B13>B15,1,0) -> 0 | E13: 0 | F13: =IF(E13>E15,1,0) -> 0 | I13: =IF(H13>H15,1,0) -> 0 | J13: =IF(B13="",0,1) -> 1 | K13: =IF(C13+F13=2,3,IF(C13+F13=1,1,0)) -> 0 | L13: =IF(K13=3,3,IF(I13+K13=2,2,IF(K13=1,1,0))) -> 0 | M13: =B13+E13 -> 3 | N13: =C13+F13+I13 -> 0 | P13: =AE9 -> Ivan Farrugia / Stephanie Farrugia | Q13: 5 | R13: =IF(Q13>Q15,1,0) -> 0 | T13: 2 | U13: =IF(T13>T15,1,0) -> 0 | X13: =IF(W13>W15,1,0) -> 0 | Y13: =IF(Q13="",0,1) -> 1 | Z13: =IF(R13+U13=2,3,IF(R13+U13=1,1,0)) -> 0 | AA13: =IF(Z13=3,3,IF(X13+Z13=2,2,IF(Z13=1,1,0))) -> 0 | AB13: =Q13+T13 -> 7 | AC13: =R13+U13+X13 -> 0 | AE13: =Players!B24& " / " &Players!C24 -> Cyril Lastimosa / Jin Attard | AF13: =Y21+Y11+J25+J19+Y33 -> 5 | AG13: =AA21+AA11+L25+L19+AA33 -> 11 | AH13: =AB21+AB11+M25+M19+AB33 -> 55 | AI13: =AC21+AC11+N25+N19+AC33 -> 9
A14: vs. | P14: vs.
A15: =AE15 -> Javier Viloria / Andrea Magaldi | B15: 6 | C15: =IF(B15>B13,1,0) -> 1 | E15: 6 | F15: =IF(E15>E13,1,0) -> 1 | I15: =IF(H15>H13,1,0) -> 0 | J15: =IF(B15="",0,1) -> 1 | K15: =IF(C15+F15=2,3,IF(C15+F15=1,1,0)) -> 3 | L15: =IF(K15=3,3,IF(I15+K15=2,2,IF(K15=1,1,0))) -> 3 | M15: =B15+E15 -> 12 | N15: =C15+F15+I15 -> 2 | P15: =AE17 -> Trevor Rutter / Karolina Papiernak | Q15: 7 | R15: =IF(Q15>Q13,1,0) -> 1 | T15: 6 | U15: =IF(T15>T13,1,0) -> 1 | X15: =IF(W15>W13,1,0) -> 0 | Y15: =IF(Q15="",0,1) -> 1 | Z15: =IF(R15+U15=2,3,IF(R15+U15=1,1,0)) -> 3 | AA15: =IF(Z15=3,3,IF(X15+Z15=2,2,IF(Z15=1,1,0))) -> 3 | AB15: =Q15+T15 -> 13 | AC15: =R15+U15+X15 -> 2 | AE15: =Players!B25& " / " &Players!C25 -> Javier Viloria / Andrea Magaldi | AF15: =Y23+J29+J15+Y19+J33 -> 5 | AG15: =AA23+L29+L15+AA19+L33 -> 9 | AH15: =AB23+M29+M15+AB19+M33 -> 55 | AI15: =AC23+N29+N15+AC19+N33 -> 7
A17: =AE11 -> Willem Steenkamer / Mariska Steenkamer | B17: 1 | C17: =IF(B17>B19,1,0) -> 0 | E17: 2 | F17: =IF(E17>E19,1,0) -> 0 | I17: =IF(H17>H19,1,0) -> 0 | J17: =IF(B17="",0,1) -> 1 | K17: =IF(C17+F17=2,3,IF(C17+F17=1,1,0)) -> 0 | L17: =IF(K17=3,3,IF(I17+K17=2,2,IF(K17=1,1,0))) -> 0 | M17: =B17+E17 -> 3 | N17: =C17+F17+I17 -> 0 | P17: =AE11 -> Willem Steenkamer / Mariska Steenkamer | Q17: 3 | R17: =IF(Q17>Q19,1,0) -> 0 | T17: 3 | U17: =IF(T17>T19,1,0) -> 0 | X17: =IF(W17>W19,1,0) -> 0 | Y17: =IF(Q17="",0,1) -> 1 | Z17: =IF(R17+U17=2,3,IF(R17+U17=1,1,0)) -> 0 | AA17: =IF(Z17=3,3,IF(X17+Z17=2,2,IF(Z17=1,1,0))) -> 0 | AB17: =Q17+T17 -> 6 | AC17: =R17+U17+X17 -> 0 | AE17: =Players!B26& " / " &Players!C26 -> Trevor Rutter / Karolina Papiernak | AF17: =J31+J23+Y15+J27+J37 -> 5 | AG17: =L31+L23+AA15+L27+L37 -> 14 | AH17: =M31+M23+AB15+M27+M37 -> 60 | AI17: =N31+N23+AC15+N27+N37 -> 10
A18: vs. | P18: vs.
A19: =AE13 -> Cyril Lastimosa / Jin Attard | B19: 6 | C19: =IF(B19>B17,1,0) -> 1 | E19: 6 | F19: =IF(E19>E17,1,0) -> 1 | I19: =IF(H19>H17,1,0) -> 0 | J19: =IF(B19="",0,1) -> 1 | K19: =IF(C19+F19=2,3,IF(C19+F19=1,1,0)) -> 3 | L19: =IF(K19=3,3,IF(I19+K19=2,2,IF(K19=1,1,0))) -> 3 | M19: =B19+E19 -> 12 | N19: =C19+F19+I19 -> 2 | P19: =AE15 -> Javier Viloria / Andrea Magaldi | Q19: 6 | R19: =IF(Q19>Q17,1,0) -> 1 | T19: 6 | U19: =IF(T19>T17,1,0) -> 1 | X19: =IF(W19>W17,1,0) -> 0 | Y19: =IF(Q19="",0,1) -> 1 | Z19: =IF(R19+U19=2,3,IF(R19+U19=1,1,0)) -> 3 | AA19: =IF(Z19=3,3,IF(X19+Z19=2,2,IF(Z19=1,1,0))) -> 3 | AB19: =Q19+T19 -> 12 | AC19: =R19+U19+X19 -> 2 | AE19: =Players!B27& " / " &Players!C27 -> Jesmond Pule' / Angele Pule' | AF19: =J35+J39+Y27+Y31+Y35 -> 5 | AG19: =L35+L39+AA27+AA31+AA35 -> 4 | AH19: =M35+M39+AB27+AB31+AB35 -> 42 | AI19: =N35+N39+AC27+AC31+AC35 -> 5
A21: =AE11 -> Willem Steenkamer / Mariska Steenkamer | B21: 2 | C21: =IF(B21>B23,1,0) -> 0 | E21: 1 | F21: =IF(E21>E23,1,0) -> 0 | I21: =IF(H21>H23,1,0) -> 0 | J21: =IF(B21="",0,1) -> 1 | K21: =IF(C21+F21=2,3,IF(C21+F21=1,1,0)) -> 0 | L21: =IF(K21=3,3,IF(I21+K21=2,2,IF(K21=1,1,0))) -> 0 | M21: =B21+E21 -> 3 | N21: =C21+F21+I21 -> 0 | P21: =AE13 -> Cyril Lastimosa / Jin Attard | Q21: 6 | R21: =IF(Q21>Q23,1,0) -> 0 | T21: 7 | U21: =IF(T21>T23,1,0) -> 1 | W21: 10 | X21: =IF(W21>W23,1,0) -> 1 | Y21: =IF(Q21="",0,1) -> 1 | Z21: =IF(R21+U21=2,3,IF(R21+U21=1,1,0)) -> 1 | AA21: =IF(Z21=3,3,IF(X21+Z21=2,2,IF(Z21=1,1,0))) -> 2 | AB21: =Q21+T21 -> 13 | AC21: =R21+U21+X21 -> 2 | AE21: Divison Winner
A22: vs. | P22: vs. | AE22: Trevor Rutter/Karolina Papiernak
A23: =AE17 -> Trevor Rutter / Karolina Papiernak | B23: 6 | C23: =IF(B23>B21,1,0) -> 1 | E23: 6 | F23: =IF(E23>E21,1,0) -> 1 | I23: =IF(H23>H21,1,0) -> 0 | J23: =IF(B23="",0,1) -> 1 | K23: =IF(C23+F23=2,3,IF(C23+F23=1,1,0)) -> 3 | L23: =IF(K23=3,3,IF(I23+K23=2,2,IF(K23=1,1,0))) -> 3 | M23: =B23+E23 -> 12 | N23: =C23+F23+I23 -> 2 | P23: =AE15 -> Javier Viloria / Andrea Magaldi | Q23: 7 | R23: =IF(Q23>Q21,1,0) -> 1 | T23: 6 | U23: =IF(T23>T21,1,0) -> 0 | W23: 8 | X23: =IF(W23>W21,1,0) -> 0 | Y23: =IF(Q23="",0,1) -> 1 | Z23: =IF(R23+U23=2,3,IF(R23+U23=1,1,0)) -> 1 | AA23: =IF(Z23=3,3,IF(X23+Z23=2,2,IF(Z23=1,1,0))) -> 1 | AB23: =Q23+T23 -> 13 | AC23: =R23+U23+X23 -> 1
A25: =AE13 -> Cyril Lastimosa / Jin Attard | B25: 4 | C25: =IF(B25>B27,1,0) -> 0 | E25: 6 | F25: =IF(E25>E27,1,0) -> 1 | H25: 2 | I25: =IF(H25>H27,1,0) -> 0 | J25: =IF(B25="",0,1) -> 1 | K25: =IF(C25+F25=2,3,IF(C25+F25=1,1,0)) -> 1 | L25: =IF(K25=3,3,IF(I25+K25=2,2,IF(K25=1,1,0))) -> 1 | M25: =B25+E25 -> 10 | N25: =C25+F25+I25 -> 1 | P25: =AE9 -> Ivan Farrugia / Stephanie Farrugia | Q25: 6 | R25: =IF(Q25>Q27,1,0) -> 0 | T25: 6 | U25: =IF(T25>T27,1,0) -> 1 | W25: 8 | X25: =IF(W25>W23,1,0) -> 0 | Y25: =IF(Q25="",0,1) -> 1 | Z25: =IF(R25+U25=2,3,IF(R25+U25=1,1,0)) -> 1 | AA25: =IF(Z25=3,3,IF(X25+Z25=2,2,IF(Z25=1,1,0))) -> 1 | AB25: =Q25+T25 -> 12 | AC25: =R25+U25+X25 -> 1 | AE25: Divison Runner Up
A26: vs. | P26: vs. | AE26: Cyril Lastimosa/Jin Attard
A27: =AE17 -> Trevor Rutter / Karolina Papiernak | B27: 6 | C27: =IF(B27>B25,1,0) -> 1 | E27: 4 | F27: =IF(E27>E25,1,0) -> 0 | H27: 10 | I27: =IF(H27>H25,1,0) -> 1 | J27: =IF(B27="",0,1) -> 1 | K27: =IF(C27+F27=2,3,IF(C27+F27=1,1,0)) -> 1 | L27: =IF(K27=3,3,IF(I27+K27=2,2,IF(K27=1,1,0))) -> 2 | M27: =B27+E27 -> 10 | N27: =C27+F27+I27 -> 2 | P27: =AE19 -> Jesmond Pule' / Angele Pule' | Q27: 7 | R27: =IF(Q27>Q25,1,0) -> 1 | T27: 4 | U27: =IF(T27>T25,1,0) -> 0 | W27: 10 | X27: =IF(W27>W25,1,0) -> 1 | Y27: =IF(Q27="",0,1) -> 1 | Z27: =IF(R27+U27=2,3,IF(R27+U27=1,1,0)) -> 1 | AA27: =IF(Z27=3,3,IF(X27+Z27=2,2,IF(Z27=1,1,0))) -> 2 | AB27: =Q27+T27 -> 11 | AC27: =R27+U27+X27 -> 2
A29: =AE15 -> Javier Viloria / Andrea Magaldi | B29: 3 | C29: =IF(B29>B31,1,0) -> 0 | E29: 6 | F29: =IF(E29>E31,1,0) -> 0 | I29: =IF(H29>H31,1,0) -> 0 | J29: =IF(B29="",0,1) -> 1 | K29: =IF(C29+F29=2,3,IF(C29+F29=1,1,0)) -> 0 | L29: =IF(K29=3,3,IF(I29+K29=2,2,IF(K29=1,1,0))) -> 0 | M29: =B29+E29 -> 9 | N29: =C29+F29+I29 -> 0 | P29: =AE11 -> Willem Steenkamer / Mariska Steenkamer | Q29: 7 | R29: =IF(Q29>Q31,1,0) -> 1 | T29: 6 | U29: =IF(T29>T31,1,0) -> 1 | W29: 8 | X29: =IF(W29>W27,1,0) -> 0 | Y29: =IF(Q29="",0,1) -> 1 | Z29: =IF(R29+U29=2,3,IF(R29+U29=1,1,0)) -> 3 | AA29: =IF(Z29=3,3,IF(X29+Z29=2,2,IF(Z29=1,1,0))) -> 3 | AB29: =Q29+T29 -> 13 | AC29: =R29+U29+X29 -> 2
A30: vs. | P30: vs.
A31: =AE17 -> Trevor Rutter / Karolina Papiernak | B31: 6 | C31: =IF(B31>B29,1,0) -> 1 | E31: 7 | F31: =IF(E31>E29,1,0) -> 1 | I31: =IF(H31>H29,1,0) -> 0 | J31: =IF(B31="",0,1) -> 1 | K31: =IF(C31+F31=2,3,IF(C31+F31=1,1,0)) -> 3 | L31: =IF(K31=3,3,IF(I31+K31=2,2,IF(K31=1,1,0))) -> 3 | M31: =B31+E31 -> 13 | N31: =C31+F31+I31 -> 2 | P31: =AE19 -> Jesmond Pule' / Angele Pule' | Q31: 5 | R31: =IF(Q31>Q29,1,0) -> 0 | T31: 1 | U31: =IF(T31>T29,1,0) -> 0 | W31: 10 | X31: =IF(W31>W29,1,0) -> 1 | Y31: =IF(Q31="",0,1) -> 1 | Z31: =IF(R31+U31=2,3,IF(R31+U31=1,1,0)) -> 0 | AA31: =IF(Z31=3,3,IF(X31+Z31=2,2,IF(Z31=1,1,0))) -> 0 | AB31: =Q31+T31 -> 6 | AC31: =R31+U31+X31 -> 1
A33: =AE15 -> Javier Viloria / Andrea Magaldi | B33: 6 | C33: =IF(B33>B35,1,0) -> 1 | E33: 3 | F33: =IF(E33>E35,1,0) -> 0 | H33: 10 | I33: =IF(H33>H35,1,0) -> 1 | J33: =IF(B33="",0,1) -> 1 | K33: =IF(C33+F33=2,3,IF(C33+F33=1,1,0)) -> 1 | L33: =IF(K33=3,3,IF(I33+K33=2,2,IF(K33=1,1,0))) -> 2 | M33: =B33+E33 -> 9 | N33: =C33+F33+I33 -> 2 | P33: =AE13 -> Cyril Lastimosa / Jin Attard | Q33: 7 | R33: =IF(Q33>Q35,1,0) -> 1 | T33: 6 | U33: =IF(T33>T35,1,0) -> 1 | X33: =IF(W33>W31,1,0) -> 0 | Y33: =IF(Q33="",0,1) -> 1 | Z33: =IF(R33+U33=2,3,IF(R33+U33=1,1,0)) -> 3 | AA33: =IF(Z33=3,3,IF(X33+Z33=2,2,IF(Z33=1,1,0))) -> 3 | AB33: =Q33+T33 -> 13 | AC33: =R33+U33+X33 -> 2
A34: vs. | P34: vs.
A35: =AE19 -> Jesmond Pule' / Angele Pule' | B35: 4 | C35: =IF(B35>B33,1,0) -> 0 | E35: 6 | F35: =IF(E35>E33,1,0) -> 1 | H35: 4 | I35: =IF(H35>H37,1,0) -> 1 | J35: =IF(B35="",0,1) -> 1 | K35: =IF(C35+F35=2,3,IF(C35+F35=1,1,0)) -> 1 | L35: =IF(K35=3,3,IF(I35+K35=2,2,IF(K35=1,1,0))) -> 2 | M35: =B35+E35 -> 10 | N35: =C35+F35+I35 -> 2 | P35: =AE19 -> Jesmond Pule' / Angele Pule' | Q35: 6 | R35: =IF(Q35>Q33,1,0) -> 0 | T35: 2 | U35: =IF(T35>T33,1,0) -> 0 | X35: =IF(W35>W33,1,0) -> 0 | Y35: =IF(Q35="",0,1) -> 1 | Z35: =IF(R35+U35=2,3,IF(R35+U35=1,1,0)) -> 0 | AA35: =IF(Z35=3,3,IF(X35+Z35=2,2,IF(Z35=1,1,0))) -> 0 | AB35: =Q35+T35 -> 8 | AC35: =R35+U35+X35 -> 0
A37: =AE17 -> Trevor Rutter / Karolina Papiernak | B37: 6 | C37: =IF(B37>B39,1,0) -> 1 | E37: 6 | F37: =IF(E37>E39,1,0) -> 1 | I37: =IF(H37>H39,1,0) -> 0 | J37: =IF(B37="",0,1) -> 1 | K37: =IF(C37+F37=2,3,IF(C37+F37=1,1,0)) -> 3 | L37: =IF(K37=3,3,IF(I37+K37=2,2,IF(K37=1,1,0))) -> 3 | M37: =B37+E37 -> 12 | N37: =C37+F37+I37 -> 2
A38: vs.
A39: =AE19 -> Jesmond Pule' / Angele Pule' | B39: 4 | C39: =IF(B39>B37,1,0) -> 0 | E39: 3 | F39: =IF(E39>E37,1,0) -> 0 | I39: =IF(H39>H41,1,0) -> 0 | J39: =IF(B39="",0,1) -> 1 | K39: =IF(C39+F39=2,3,IF(C39+F39=1,1,0)) -> 0 | L39: =IF(K39=3,3,IF(I39+K39=2,2,IF(K39=1,1,0))) -> 0 | M39: =B39+E39 -> 7 | N39: =C39+F39+I39 -> 0

Sheet Division 4
A1: ESS Mixed Doubles 2025
A5: Division 4
A7: Players | B7: Set Scores | H7: Tie | P7: Players | Q7: Set Scores | W7: Tie | AE7: Player | AF7: Matches Played | AG7: Points Overall | AH7: Games Won | AI7: Sets Won
B8: Score | C8: Set 1 Work | E8: Score | F8: Set 2 Work | H8: Score | I8: Tie Work | J8: Game Played | K8: Sets Points Work | L8: Sets & Tie Points Work | M8: Games Wins Work | N8: Sets Wins Work | Q8: Score | R8: Set 1 Work | T8: Score | U8: Set 2 Work | W8: Score | X8: Tie Work | Y8: Game Played | Z8: Sets Points Work | AA8: Sets & Tie Points Work | AB8: Games Wins Work | AC8: Sets Wins Work | AJ8: Winner Working | AK8: Runner Up Working | AL8: Total Games Work | AM8: Winner | AN8: Runner Up
A9: =AE9 -> Luke Genuis / Dorianne Buhagiar | B9: 4 | C9: =IF(B9>B11,1,0) -> 0 | E9: 7 | F9: =IF(E9>E11,1,0) -> 1 | H9: 7 | I9: =IF(H9>H11,1,0) -> 0 | J9: =IF(B9="",0,1) -> 1 | K9: =IF(C9+F9=2,3,IF(C9+F9=1,1,0)) -> 1 | L9: =IF(K9=3,3,IF(I9+K9=2,2,IF(K9=1,1,0))) -> 1 | M9: =B9+E9 -> 11 | N9: =C9+F9+I9 -> 1 | P9: =AE9 -> Luke Genuis / Dorianne Buhagiar | Q9: 6 | R9: =IF(Q9>Q11,1,0) -> 1 | T9: 6 | U9: =IF(T9>T11,1,0) -> 1 | X9: =IF(W9>W11,1,0) -> 0 | Y9: =IF(Q9="",0,1) -> 1 | Z9: =IF(R9+U9=2,3,IF(R9+U9=1,1,0)) -> 3 | AA9: =IF(Z9=3,3,IF(X9+Z9=2,2,IF(Z9=1,1,0))) -> 3 | AB9: =Q9+T9 -> 12 | AC9: =R9+U9+X9 -> 2 | AE9: =Players!B30& " / " &Players!C30 -> Luke Genuis / Dorianne Buhagiar | AF9: =J9+Y9+J13+Y13+J17 -> 5 | AG9: =L9+AA9+L13+AA13+L17 -> 11 | AH9: =M9+AB9+M13+AB13+M17 -> 58 | AI9: =N9+AC9+N13+AC13+N17 -> 8
A10: vs. | P10: vs.
A11: =AE11 -> George Grech / Jade Sammut | B11: 6 | C11: =IF(B11>B9,1,0) -> 1 | E11: 5 | F11: =IF(E11>E9,1,0) -> 0 | H11: 10 | I11: =IF(H11>H9,1,0) -> 1 | J11: =IF(B11="",0,1) -> 1 | K11: =IF(C11+F11=2,3,IF(C11+F11=1,1,0)) -> 1 | L11: =IF(K11=3,3,IF(I11+K11=2,2,IF(K11=1,1,0))) -> 2 | M11: =B11+E11 -> 11 | N11: =C11+F11+I11 -> 2 | P11: =AE13 -> Daniel Farrugia / Diane Farrugia | Q11: 4 | R11: =IF(Q11>Q9,1,0) -> 0 | T11: 0 | U11: =IF(T11>T9,1,0) -> 0 | X11: =IF(W11>W9,1,0) -> 0 | Y11: =IF(Q11="",0,1) -> 1 | Z11: =IF(R11+U11=2,3,IF(R11+U11=1,1,0)) -> 0 | AA11: =IF(Z11=3,3,IF(X11+Z11=2,2,IF(Z11=1,1,0))) -> 0 | AB11: =Q11+T11 -> 4 | AC11: =R11+U11+X11 -> 0 | AE11: =Players!B31& " / " &Players!C31 -> George Grech / Jade Sammut | AF11: =J11+Y25+J25+Y21+J21 -> 5 | AG11: =L11+AA25+L25+AA21+L21 -> 7 | AH11: =M11+AB25+M25+AB21+M21 -> 43 | AI11: =N11+AC25+N25+AC21+N21 -> 6
A13: =AE9 -> Luke Genuis / Dorianne Buhagiar | B13: 6 | C13: =IF(B13>B15,1,0) -> 1 | E13: 6 | F13: =IF(E13>E15,1,0) -> 1 | I13: =IF(H13>H15,1,0) -> 0 | J13: =IF(B13="",0,1) -> 1 | K13: =IF(C13+F13=2,3,IF(C13+F13=1,1,0)) -> 3 | L13: =IF(K13=3,3,IF(I13+K13=2,2,IF(K13=1,1,0))) -> 3 | M13: =B13+E13 -> 12 | N13: =C13+F13+I13 -> 2 | P13: =AE9 -> Luke Genuis / Dorianne Buhagiar | Q13: 4 | R13: =IF(Q13>Q15,1,0) -> 0 | T13: 6 | U13: =IF(T13>T15,1,0) -> 1 | W13: 8 | X13: =IF(W13>W15,1,0) -> 0 | Y13: =IF(Q13="",0,1) -> 1 | Z13: =IF(R13+U13=2,3,IF(R13+U13=1,1,0)) -> 1 | AA13: =IF(Z13=3,3,IF(X13+Z13=2,2,IF(Z13=1,1,0))) -> 1 | AB13: =Q13+T13 -> 10 | AC13: =R13+U13+X13 -> 1 | AE13: =Players!B32& " / " &Players!C32 -> Daniel Farrugia / Diane Farrugia | AF13: =Y29+Y11+Y33+J33+J23 -> 5 | AG13: =AA29+AA11+AA33+L33+L23 -> 7 | AH13: =AB29+AB11+AB33+M33+M23 -> 36 | AI13: =AC29+AC11+AC33+N33+N23 -> 6
A14: vs. | P14: vs.
A15: =AE15 -> Luigi Porto / Vanessa Farrugia | B15: 0 | C15: =IF(B15>B13,1,0) -> 0 | E15: 0 | F15: =IF(E15>E13,1,0) -> 0 | I15: =IF(H15>H13,1,0) -> 0 | J15: =IF(B15="",0,1) -> 1 | K15: =IF(C15+F15=2,3,IF(C15+F15=1,1,0)) -> 0 | L15: =IF(K15=3,3,IF(I15+K15=2,2,IF(K15=1,1,0))) -> 0 | M15: =B15+E15 -> 0 | N15: =C15+F15+I15 -> 0 | P15: =AE17 -> James Farrugia / Nancy Wong | Q15: 6 | R15: =IF(Q15>Q13,1,0) -> 1 | T15: 4 | U15: =IF(T15>T13,1,0) -> 0 | W15: 10 | X15: =IF(W15>W13,1,0) -> 1 | Y15: =IF(Q15="",0,1) -> 1 | Z15: =IF(R15+U15=2,3,IF(R15+U15=1,1,0)) -> 1 | AA15: =IF(Z15=3,3,IF(X15+Z15=2,2,IF(Z15=1,1,0))) -> 2 | AB15: =Q15+T15 -> 10 | AC15: =R15+U15+X15 -> 2 | AE15: =Players!B33& " / " &Players!C33 -> Luigi Porto / Vanessa Farrugia | AF15: =Y31+J37+J15+Y23+J29 -> 5 | AG15: =AA31+L37+L15+AA23+L29 -> 4 | AH15: =AB31+M37+M15+AB23+M29 -> 44 | AI15: =AC31+N37+N15+AC23+N29 -> 4
A17: =AE9 -> Luke Genuis / Dorianne Buhagiar | B17: 7 | C17: =IF(B17>B19,1,0) -> 1 | E17: 6 | F17: =IF(E17>E19,1,0) -> 1 | I17: =IF(H17>H19,1,0) -> 0 | J17: =IF(B17="",0,1) -> 1 | K17: =IF(C17+F17=2,3,IF(C17+F17=1,1,0)) -> 3 | L17: =IF(K17=3,3,IF(I17+K17=2,2,IF(K17=1,1,0))) -> 3 | M17: =B17+E17 -> 13 | N17: =C17+F17+I17 -> 2 | P17: =AE17 -> James Farrugia / Nancy Wong | Q17: 6 | R17: =IF(Q17>Q19,1,0) -> 1 | T17: 6 | U17: =IF(T17>T19,1,0) -> 1 | X17: =IF(W17>W19,1,0) -> 0 | Y17: =IF(Q17="",0,1) -> 1 | Z17: =IF(R17+U17=2,3,IF(R17+U17=1,1,0)) -> 3 | AA17: =IF(Z17=3,3,IF(X17+Z17=2,2,IF(Z17=1,1,0))) -> 3 | AB17: =Q17+T17 -> 12 | AC17: =R17+U17+X17 -> 2 | AE17: =Players!B34& " / " &Players!C34 -> James Farrugia / Nancy Wong | AF17: =Y17+J39+J27+Y15+J35 -> 5 | AG17: =AA17+L39+L27+AA15+L35 -> 12 | AH17: =AB17+M39+M27+AB15+M35 -> 59 | AI17: =AC17+N39+N27+AC15+N35 -> 9
A18: vs. | P18: vs.
A19: =AE19 -> Simone Re / Ann Marie Attard | B19: 6 | C19: =IF(B19>B17,1,0) -> 0 | E19: 2 | F19: =IF(E19>E17,1,0) -> 0 | I19: =IF(H19>H17,1,0) -> 0 | J19: =IF(B19="",0,1) -> 1 | K19: =IF(C19+F19=2,3,IF(C19+F19=1,1,0)) -> 0 | L19: =IF(K19=3,3,IF(I19+K19=2,2,IF(K19=1,1,0))) -> 0 | M19: =B19+E19 -> 8 | N19: =C19+F19+I19 -> 0 | P19: =AE19 -> Simone Re / Ann Marie Attard | Q19: 3 | R19: =IF(Q19>Q17,1,0) -> 0 | T19: 2 | U19: =IF(T19>T17,1,0) -> 0 | X19: =IF(W19>W17,1,0) -> 0 | Y19: =IF(Q19="",0,1) -> 1 | Z19: =IF(R19+U19=2,3,IF(R19+U19=1,1,0)) -> 0 | AA19: =IF(Z19=3,3,IF(X19+Z19=2,2,IF(Z19=1,1,0))) -> 0 | AB19: =Q19+T19 -> 5 | AC19: =R19+U19+X19 -> 0 | AE19: =Players!B35& " / " &Players!C35 -> Simone Re / Ann Marie Attard | AF19: =Y19+Y27+Y35+J19+J31 -> 5 | AG19: =AA19+AA27+AA35+L19+L31 -> 4 | AH19: =AB19+AB27+AB35+M19+M31 -> 41 | AI19: =AC19+AC27+AC35+N19+N31 -> 4
A21: =AE11 -> George Grech / Jade Sammut | B21: 3 | C21: =IF(B21>B23,1,0) -> 0 | E21: 3 | F21: =IF(E21>E23,1,0) -> 0 | I21: =IF(H21>H23,1,0) -> 0 | J21: =IF(B21="",0,1) -> 1 | K21: =IF(C21+F21=2,3,IF(C21+F21=1,1,0)) -> 0 | L21: =IF(K21=3,3,IF(I21+K21=2,2,IF(K21=1,1,0))) -> 0 | M21: =B21+E21 -> 6 | N21: =C21+F21+I21 -> 0 | P21: =AE11 -> George Grech / Jade Sammut | Q21: 7 | R21: =IF(Q21>Q23,1,0) -> 1 | T21: 6 | U21: =IF(T21>T23,1,0) -> 1 | X21: =IF(W21>W23,1,0) -> 0 | Y21: =IF(Q21="",0,1) -> 1 | Z21: =IF(R21+U21=2,3,IF(R21+U21=1,1,0)) -> 3 | AA21: =IF(Z21=3,3,IF(X21+Z21=2,2,IF(Z21=1,1,0))) -> 3 | AB21: =Q21+T21 -> 13 | AC21: =R21+U21+X21 -> 2 | AE21: Divison Winner
A22: vs. | P22: vs. | AE22: James Farrugia/Nancy Wong
A23: =AE13 -> Daniel Farrugia / Diane Farrugia | B23: 6 | C23: =IF(B23>B21,1,0) -> 1 | E23: 6 | F23: =IF(E23>E21,1,0) -> 1 | I23: =IF(H23>H21,1,0) -> 0 | J23: =IF(B23="",0,1) -> 1 | K23: =IF(C23+F23=2,3,IF(C23+F23=1,1,0)) -> 3 | L23: =IF(K23=3,3,IF(I23+K23=2,2,IF(K23=1,1,0))) -> 3 | M23: =B23+E23 -> 12 | N23: =C23+F23+I23 -> 2 | P23: =AE15 -> Luigi Porto / Vanessa Farrugia | Q23: 6 | R23: =IF(Q23>Q21,1,0) -> 0 | T23: 2 | U23: =IF(T23>T21,1,0) -> 0 | X23: =IF(W23>W21,1,0) -> 0 | Y23: =IF(Q23="",0,1) -> 1 | Z23: =IF(R23+U23=2,3,IF(R23+U23=1,1,0)) -> 0 | AA23: =IF(Z23=3,3,IF(X23+Z23=2,2,IF(Z23=1,1,0))) -> 0 | AB23: =Q23+T23 -> 8 | AC23: =R23+U23+X23 -> 0
A25: =AE11 -> George Grech / Jade Sammut | B25: 3 | C25: =IF(B25>B27,1,0) -> 0 | E25: 2 | F25: =IF(E25>E27,1,0) -> 0 | I25: =IF(H25>H27,1,0) -> 0 | J25: =IF(B25="",0,1) -> 1 | K25: =IF(C25+F25=2,3,IF(C25+F25=1,1,0)) -> 0 | L25: =IF(K25=3,3,IF(I25+K25=2,2,IF(K25=1,1,0))) -> 0 | M25: =B25+E25 -> 5 | N25: =C25+F25+I25 -> 0 | P25: =AE11 -> George Grech / Jade Sammut | Q25: 6 | R25: =IF(Q25>Q27,1,0) -> 1 | T25: 2 | U25: =IF(T25>T27,1,0) -> 0 | W25: 10 | X25: =IF(W25>W27,1,0) -> 1 | Y25: =IF(Q25="",0,1) -> 1 | Z25: =IF(R25+U25=2,3,IF(R25+U25=1,1,0)) -> 1 | AA25: =IF(Z25=3,3,IF(X25+Z25=2,2,IF(Z25=1,1,0))) -> 2 | AB25: =Q25+T25 -> 8 | AC25: =R25+U25+X25 -> 2 | AE25: Divison Runner Up
A26: vs. | P26: vs. | AE26: Luke Genuis/Dorianne Buhagiar
A27: =AE17 -> James Farrugia / Nancy Wong | B27: 6 | C27: =IF(B27>B25,1,0) -> 1 | E27: 6 | F27: =IF(E27>E25,1,0) -> 1 | I27: =IF(H27>H25,1,0) -> 0 | J27: =IF(B27="",0,1) -> 1 | K27: =IF(C27+F27=2,3,IF(C27+F27=1,1,0)) -> 3 | L27: =IF(K27=3,3,IF(I27+K27=2,2,IF(K27=1,1,0))) -> 3 | M27: =B27+E27 -> 12 | N27: =C27+F27+I27 -> 2 | P27: =AE19 -> Simone Re / Ann Marie Attard | Q27: 1 | R27: =IF(Q27>Q25,1,0) -> 0 | T27: 6 | U27: =IF(T27>T25,1,0) -> 1 | W27: 6 | X27: =IF(W27>W25,1,0) -> 0 | Y27: =IF(Q27="",0,1) -> 1 | Z27: =IF(R27+U27=2,3,IF(R27+U27=1,1,0)) -> 1 | AA27: =IF(Z27=3,3,IF(X27+Z27=2,2,IF(Z27=1,1,0))) -> 1 | AB27: =Q27+T27 -> 7 | AC27: =R27+U27+X27 -> 1
A29: =AE15 -> Luigi Porto / Vanessa Farrugia | B29: 7 | C29: =IF(B29>B31,1,0) -> 1 | E29: 4 | F29: =IF(E29>E31,1,0) -> 0 | H29: 9 | I29: =IF(H29>H31,1,0) -> 0 | J29: =IF(B29="",0,1) -> 1 | K29: =IF(C29+F29=2,3,IF(C29+F29=1,1,0)) -> 1 | L29: =IF(K29=3,3,IF(I29+K29=2,2,IF(K29=1,1,0))) -> 1 | M29: =B29+E29 -> 11 | N29: =C29+F29+I29 -> 1 | P29: =AE13 -> Daniel Farrugia / Diane Farrugia | Q29: 7 | R29: =IF(Q29>Q31,1,0) -> 1 | T29: 0 | U29: =IF(T29>T31,1,0) -> 0 | W29: 10 | X29: =IF(W29>W31,1,0) -> 1 | Y29: =IF(Q29="",0,1) -> 1 | Z29: =IF(R29+U29=2,3,IF(R29+U29=1,1,0)) -> 1 | AA29: =IF(Z29=3,3,IF(X29+Z29=2,2,IF(Z29=1,1,0))) -> 2 | AB29: =Q29+T29 -> 7 | AC29: =R29+U29+X29 -> 2
A30: vs. | P30: vs.
A31: =AE19 -> Simone Re / Ann Marie Attard | B31: 5 | C31: =IF(B31>B29,1,0) -> 0 | E31: 6 | F31: =IF(E31>E29,1,0) -> 1 | H31: 11 | I31: =IF(H31>H29,1,0) -> 1 | J31: =IF(B31="",0,1) -> 1 | K31: =IF(C31+F31=2,3,IF(C31+F31=1,1,0)) -> 1 | L31: =IF(K31=3,3,IF(I31+K31=2,2,IF(K31=1,1,0))) -> 2 | M31: =B31+E31 -> 11 | N31: =C31+F31+I31 -> 2 | P31: =AE15 -> Luigi Porto / Vanessa Farrugia | Q31: 6 | R31: =IF(Q31>Q29,1,0) -> 0 | T31: 6 | U31: =IF(T31>T29,1,0) -> 1 | W31: 3 | X31: =IF(W31>W29,1,0) -> 0 | Y31: =IF(Q31="",0,1) -> 1 | Z31: =IF(R31+U31=2,3,IF(R31+U31=1,1,0)) -> 1 | AA31: =IF(Z31=3,3,IF(X31+Z31=2,2,IF(Z31=1,1,0))) -> 1 | AB31: =Q31+T31 -> 12 | AC31: =R31+U31+X31 -> 1
A33: =AE13 -> Daniel Farrugia / Diane Farrugia | B33: 1 | C33: =IF(B33>B35,1,0) -> 0 | E33: 3 | F33: =IF(E33>E35,1,0) -> 0 | I33: =IF(H33>H35,1,0) -> 0 | J33: =IF(B33="",0,1) -> 1 | K33: =IF(C33+F33=2,3,IF(C33+F33=1,1,0)) -> 0 | L33: =IF(K33=3,3,IF(I33+K33=2,2,IF(K33=1,1,0))) -> 0 | M33: =B33+E33 -> 4 | N33: =C33+F33+I33 -> 0 | P33: =AE13 -> Daniel Farrugia / Diane Farrugia | Q33: 3 | R33: =IF(Q33>Q35,1,0) -> 0 | T33: 6 | U33: =IF(T33>T35,1,0) -> 1 | W33: 10 | X33: =IF(W33>W35,1,0) -> 1 | Y33: =IF(Q33="",0,1) -> 1 | Z33: =IF(R33+U33=2,3,IF(R33+U33=1,1,0)) -> 1 | AA33: =IF(Z33=3,3,IF(X33+Z33=2,2,IF(Z33=1,1,0))) -> 2 | AB33: =Q33+T33 -> 9 | AC33: =R33+U33+X33 -> 2
A34: vs. | P34: vs.
A35: =AE17 -> James Farrugia / Nancy Wong | B35: 6 | C35: =IF(B35>B33,1,0) -> 1 | E35: 6 | F35: =IF(E35>E33,1,0) -> 1 | I35: =IF(H35>H33,1,0) -> 0 | J35: =IF(B35="",0,1) -> 1 | K35: =IF(C35+F35=2,3,IF(C35+F35=1,1,0)) -> 3 | L35: =IF(K35=3,3,IF(I35+K35=2,2,IF(K35=1,1,0))) -> 3 | M35: =B35+E35 -> 12 | N35: =C35+F35+I35 -> 2 | P35: =AE19 -> Simone Re / Ann Marie Attard | Q35: 6 | R35: =IF(Q35>Q33,1,0) -> 1 | T35: 4 | U35: =IF(T35>T33,1,0) -> 0 | W35: 6 | X35: =IF(W35>W33,1,0) -> 0 | Y35: =IF(Q35="",0,1) -> 1 | Z35: =IF(R35+U35=2,3,IF(R35+U35=1,1,0)) -> 1 | AA35: =IF(Z35=3,3,IF(X35+Z35=2,2,IF(Z35=1,1,0))) -> 1 | AB35: =Q35+T35 -> 10 | AC35: =R35+U35+X35 -> 1
A37: =AE15 -> Luigi Porto / Vanessa Farrugia | B37: 7 | C37: =IF(B37>B39,1,0) -> 1 | E37: 6 | F37: =IF(E37>E39,1,0) -> 0 | H37: 10 | I37: =IF(H37>H39,1,0) -> 1 | J37: =IF(B37="",0,1) -> 1 | K37: =IF(C37+F37=2,3,IF(C37+F37=1,1,0)) -> 1 | L37: =IF(K37=3,3,IF(I37+K37=2,2,IF(K37=1,1,0))) -> 2 | M37: =B37+E37 -> 13 | N37: =C37+F37+I37 -> 2
A38: vs.
A39: =AE17 -> James Farrugia / Nancy Wong | B39: 6 | C39: =IF(B39>B37,1,0) -> 0 | E39: 7 | F39: =IF(E39>E37,1,0) -> 1 | H39: 6 | I39: =IF(H39>H37,1,0) -> 0 | J39: =IF(B39="",0,1) -> 1 | K39: =IF(C39+F39=2,3,IF(C39+F39=1,1,0)) -> 1 | L39: =IF(K39=3,3,IF(I39+K39=2,2,IF(K39=1,1,0))) -> 1 | M39: =B39+E39 -> 13 | N39: =C39+F39+I39 -> 1

Sheet Division 5
A1: ESS Mixed Doubles 2025
A5: Division 5
A7: Players | B7: Set Scores | H7: Tie | P7: Players | Q7: Set Scores | W7: Tie | AE7: Player | AF7: Matches Played | AG7: Points Overall | AH7: Games Won | AI7: Sets Won
B8: Score | C8: Set 1 Work | E8: Score | F8: Set 2 Work | H8: Score | I8: Tie Work | J8: Game Played | K8: Sets Points Work | L8: Sets & Tie Points Work | M8: Games Wins Work | N8: Sets Wins Work | Q8: Score | R8: Set 1 Work | T8: Score | U8: Set 2 Work | W8: Score | X8: Tie Work | Y8: Game Played | Z8: Sets Points Work | AA8: Sets & Tie Points Work | AB8: Games Wins Work | AC8: Sets Wins Work | AJ8: Winner Working | AK8: Total Games Work | AL8: Winner
A9: =AE9 -> Dylan Birmingham / Sarah Axiaq | B9: 7 | C9: =IF(B9>B11,1,0) -> 1 | E9: 6 | F9: =IF(E9>E11,1,0) -> 1 | I9: =IF(H9>H11,1,0) -> 0 | J9: =IF(B9="",0,1) -> 1 | K9: =IF(C9+F9=2,3,IF(C9+F9=1,1,0)) -> 3 | L9: =IF(K9=3,3,IF(I9+K9=2,2,IF(K9=1,1,0))) -> 3 | M9: =B9+E9 -> 13 | N9: =C9+F9+I9 -> 2 | P9: =AE9 -> Dylan Birmingham / Sarah Axiaq | Q9: 3 | R9: =IF(Q9>Q11,1,0) -> 0 | T9: 1 | U9: =IF(T9>T11,1,0) -> 0 | X9: =IF(W9>W11,1,0) -> 0 | Y9: =IF(Q9="",0,1) -> 1 | Z9: =IF(R9+U9=2,3,IF(R9+U9=1,1,0)) -> 0 | AA9: =IF(Z9=3,3,IF(X9+Z9=2,2,IF(Z9=1,1,0))) -> 0 | AB9: =Q9+T9 -> 4 | AC9: =R9+U9+X9 -> 0 | AE9: =Players!B38& " / " &Players!C38 -> Dylan Birmingham / Sarah Axiaq | AF9: =J9+Y9+J13+Y13+J17 -> 5 | AG9: =L9+AA9+L13+AA13+L17 -> 6 | AH9: =M9+AB9+M13+AB13+M17 -> 37 | AI9: =N9+AC9+N13+AC13+N17 -> 4
A10: vs. | P10: vs.
A11: =AE11 -> JP Sciberras / Brenda Baldacchino | B11: 6 | C11: =IF(B11>B9,1,0) -> 0 | E11: 3 | F11: =IF(E11>E9,1,0) -> 0 | I11: =IF(H11>H9,1,0) -> 0 | J11: =IF(B11="",0,1) -> 1 | K11: =IF(C11+F11=2,3,IF(C11+F11=1,1,0)) -> 0 | L11: =IF(K11=3,3,IF(I11+K11=2,2,IF(K11=1,1,0))) -> 0 | M11: =B11+E11 -> 9 | N11: =C11+F11+I11 -> 0 | P11: =AE13 -> Juan Sammut / Maria Angela Gambin | Q11: 6 | R11: =IF(Q11>Q9,1,0) -> 1 | T11: 6 | U11: =IF(T11>T9,1,0) -> 1 | X11: =IF(W11>W9,1,0) -> 0 | Y11: =IF(Q11="",0,1) -> 1 | Z11: =IF(R11+U11=2,3,IF(R11+U11=1,1,0)) -> 3 | AA11: =IF(Z11=3,3,IF(X11+Z11=2,2,IF(Z11=1,1,0))) -> 3 | AB11: =Q11+T11 -> 12 | AC11: =R11+U11+X11 -> 2 | AE11: =Players!B39& " / " &Players!C39 -> JP Sciberras / Brenda Baldacchino | AF11: =J11+Y25+J25+Y21+J21 -> 5 | AG11: =L11+AA25+L25+AA21+L21 -> 5 | AH11: =M11+AB25+M25+AB21+M21 -> 42 | AI11: =N11+AC25+N25+AC21+N21 -> 4
A13: =AE9 -> Dylan Birmingham / Sarah Axiaq | B13: 3 | C13: =IF(B13>B15,1,0) -> 0 | E13: 3 | F13: =IF(E13>E15,1,0) -> 0 | I13: =IF(H13>H15,1,0) -> 0 | J13: =IF(B13="",0,1) -> 1 | K13: =IF(C13+F13=2,3,IF(C13+F13=1,1,0)) -> 0 | L13: =IF(K13=3,3,IF(I13+K13=2,2,IF(K13=1,1,0))) -> 0 | M13: =B13+E13 -> 6 | N13: =C13+F13+I13 -> 0 | P13: =AE9 -> Dylan Birmingham / Sarah Axiaq | Q13: 1 | R13: =IF(Q13>Q15,1,0) -> 0 | T13: 0 | U13: =IF(T13>T15,1,0) -> 0 | X13: =IF(W13>W15,1,0) -> 0 | Y13: =IF(Q13="",0,1) -> 1 | Z13: =IF(R13+U13=2,3,IF(R13+U13=1,1,0)) -> 0 | AA13: =IF(Z13=3,3,IF(X13+Z13=2,2,IF(Z13=1,1,0))) -> 0 | AB13: =Q13+T13 -> 1 | AC13: =R13+U13+X13 -> 0 | AE13: =Players!B40& " / " &Players!C40 -> Juan Sammut / Maria Angela Gambin | AF13: =Y29+Y11+Y33+J33+J23 -> 5 | AG13: =AA29+AA11+AA33+L33+L23 -> 14 | AH13: =AB29+AB11+AB33+M33+M23 -> 59 | AI13: =AC29+AC11+AC33+N33+N23 -> 10
A14: vs. | P14: vs.
A15: =AE15 -> Robert Attard / Silvana Portelli | B15: 6 | C15: =IF(B15>B13,1,0) -> 1 | E15: 6 | F15: =IF(E15>E13,1,0) -> 1 | I15: =IF(H15>H13,1,0) -> 0 | J15: =IF(B15="",0,1) -> 1 | K15: =IF(C15+F15=2,3,IF(C15+F15=1,1,0)) -> 3 | L15: =IF(K15=3,3,IF(I15+K15=2,2,IF(K15=1,1,0))) -> 3 | M15: =B15+E15 -> 12 | N15: =C15+F15+I15 -> 2 | P15: =AE17 -> Kenneth Farrugia / Rowena Caruana | Q15: 6 | R15: =IF(Q15>Q13,1,0) -> 1 | T15: 6 | U15: =IF(T15>T13,1,0) -> 1 | X15: =IF(W15>W13,1,0) -> 0 | Y15: =IF(Q15="",0,1) -> 1 | Z15: =IF(R15+U15=2,3,IF(R15+U15=1,1,0)) -> 3 | AA15: =IF(Z15=3,3,IF(X15+Z15=2,2,IF(Z15=1,1,0))) -> 3 | AB15: =Q15+T15 -> 12 | AC15: =R15+U15+X15 -> 2 | AE15: =Players!B41& " / " &Players!C41 -> Robert Attard / Silvana Portelli | AF15: =Y31+J37+J15+Y23+J29 -> 5 | AG15: =AA31+L37+L15+AA23+L29 -> 9 | AH15: =AB31+M37+M15+AB23+M29 -> 49 | AI15: =AC31+N37+N15+AC23+N29 -> 6
A17: =AE9 -> Dylan Birmingham / Sarah Axiaq | B17: 7 | C17: =IF(B17>B19,1,0) -> 1 | E17: 6 | F17: =IF(E17>E19,1,0) -> 1 | I17: =IF(H17>H19,1,0) -> 0 | J17: =IF(B17="",0,1) -> 1 | K17: =IF(C17+F17=2,3,IF(C17+F17=1,1,0)) -> 3 | L17: =IF(K17=3,3,IF(I17+K17=2,2,IF(K17=1,1,0))) -> 3 | M17: =B17+E17 -> 13 | N17: =C17+F17+I17 -> 2 | P17: =AE17 -> Kenneth Farrugia / Rowena Caruana | Q17: 6 | R17: =IF(Q17>Q19,1,0) -> 1 | T17: 6 | U17: =IF(T17>T19,1,0) -> 1 | X17: =IF(W17>W19,1,0) -> 0 | Y17: =IF(Q17="",0,1) -> 1 | Z17: =IF(R17+U17=2,3,IF(R17+U17=1,1,0)) -> 3 | AA17: =IF(Z17=3,3,IF(X17+Z17=2,2,IF(Z17=1,1,0))) -> 3 | AB17: =Q17+T17 -> 12 | AC17: =R17+U17+X17 -> 2 | AE17: =Players!B42& " / " &Players!C42 -> Kenneth Farrugia / Rowena Caruana | AF17: =Y17+J39+J27+Y15+J35 -> 5 | AG17: =AA17+L39+L27+AA15+L35 -> 11 | AH17: =AB17+M39+M27+AB15+M35 -> 57 | AI17: =AC17+N39+N27+AC15+N35 -> 8
A18: vs. | P18: vs.
A19: =AE19 -> Dorian Demanuele / Maria Ellul | B19: 5 | C19: =IF(B19>B17,1,0) -> 0 | E19: 4 | F19: =IF(E19>E17,1,0) -> 0 | I19: =IF(H19>H17,1,0) -> 0 | J19: =IF(B19="",0,1) -> 1 | K19: =IF(C19+F19=2,3,IF(C19+F19=1,1,0)) -> 0 | L19: =IF(K19=3,3,IF(I19+K19=2,2,IF(K19=1,1,0))) -> 0 | M19: =B19+E19 -> 9 | N19: =C19+F19+I19 -> 0 | P19: =AE19 -> Dorian Demanuele / Maria Ellul | Q19: 2 | R19: =IF(Q19>Q17,1,0) -> 0 | T19: 2 | U19: =IF(T19>T17,1,0) -> 0 | X19: =IF(W19>W17,1,0) -> 0 | Y19: =IF(Q19="",0,1) -> 1 | Z19: =IF(R19+U19=2,3,IF(R19+U19=1,1,0)) -> 0 | AA19: =IF(Z19=3,3,IF(X19+Z19=2,2,IF(Z19=1,1,0))) -> 0 | AB19: =Q19+T19 -> 4 | AC19: =R19+U19+X19 -> 0 | AE19: =Players!B43& " / " &Players!C43 -> Dorian Demanuele / Maria Ellul | AF19: =Y19+Y27+Y35+J19+J31 -> 5 | AG19: =AA19+AA35+L31+AA27+L19 -> 0 | AH19: =AB19+AB27+AB35+M19+M31 -> 19 | AI19: =AC19+AC27+AC35+N19+N31 -> 0
A21: =AE11 -> JP Sciberras / Brenda Baldacchino | B21: 4 | C21: =IF(B21>B23,1,0) -> 0 | E21: 2 | F21: =IF(E21>E23,1,0) -> 0 | I21: =IF(H21>H23,1,0) -> 0 | J21: =IF(B21="",0,1) -> 1 | K21: =IF(C21+F21=2,3,IF(C21+F21=1,1,0)) -> 0 | L21: =IF(K21=3,3,IF(I21+K21=2,2,IF(K21=1,1,0))) -> 0 | M21: =B21+E21 -> 6 | N21: =C21+F21+I21 -> 0 | P21: =AE11 -> JP Sciberras / Brenda Baldacchino | Q21: 0 | R21: =IF(Q21>Q23,1,0) -> 0 | T21: 4 | U21: =IF(T21>T23,1,0) -> 0 | X21: =IF(W21>W23,1,0) -> 0 | Y21: =IF(Q21="",0,1) -> 1 | Z21: =IF(R21+U21=2,3,IF(R21+U21=1,1,0)) -> 0 | AA21: =IF(Z21=3,3,IF(X21+Z21=2,2,IF(Z21=1,1,0))) -> 0 | AB21: =Q21+T21 -> 4 | AC21: =R21+U21+X21 -> 0 | AE21: Divison Winner
A22: vs. | AE22: Juan Sammut/Maria Angela Gambin
A23: =AE13 -> Juan Sammut / Maria Angela Gambin | B23: 6 | C23: =IF(B23>B21,1,0) -> 1 | E23: 6 | F23: =IF(E23>E21,1,0) -> 1 | I23: =IF(H23>H21,1,0) -> 0 | J23: =IF(B23="",0,1) -> 1 | K23: =IF(C23+F23=2,3,IF(C23+F23=1,1,0)) -> 3 | L23: =IF(K23=3,3,IF(I23+K23=2,2,IF(K23=1,1,0))) -> 3 | M23: =B23+E23 -> 12 | N23: =C23+F23+I23 -> 2 | P23: =AE15 -> Robert Attard / Silvana Portelli | Q23: 6 | R23: =IF(Q23>Q21,1,0) -> 1 | T23: 6 | U23: =IF(T23>T21,1,0) -> 1 | X23: =IF(W23>W21,1,0) -> 0 | Y23: =IF(Q23="",0,1) -> 1 | Z23: =IF(R23+U23=2,3,IF(R23+U23=1,1,0)) -> 3 | AA23: =IF(Z23=3,3,IF(X23+Z23=2,2,IF(Z23=1,1,0))) -> 3 | AB23: =Q23+T23 -> 12 | AC23: =R23+U23+X23 -> 2
A25: =AE11 -> JP Sciberras / Brenda Baldacchino | B25: 5 | C25: =IF(B25>B27,1,0) -> 0 | E25: 6 | F25: =IF(E25>E27,1,0) -> 1 | H25: 10 | I25: =IF(H25>H27,1,0) -> 1 | J25: =IF(B25="",0,1) -> 1 | K25: =IF(C25+F25=2,3,IF(C25+F25=1,1,0)) -> 1 | L25: =IF(K25=3,3,IF(I25+K25=2,2,IF(K25=1,1,0))) -> 2 | M25: =B25+E25 -> 11 | N25: =C25+F25+I25 -> 2 | P25: =AE11 -> JP Sciberras / Brenda Baldacchino | Q25: 6 | R25: =IF(Q25>Q27,1,0) -> 1 | T25: 6 | U25: =IF(T25>T27,1,0) -> 1 | X25: =IF(W25>W27,1,0) -> 0 | Y25: =IF(Q25="",0,1) -> 1 | Z25: =IF(R25+U25=2,3,IF(R25+U25=1,1,0)) -> 3 | AA25: =IF(Z25=3,3,IF(X25+Z25=2,2,IF(Z25=1,1,0))) -> 3 | AB25: =Q25+T25 -> 12 | AC25: =R25+U25+X25 -> 2 | AE25: Divison Runner Up
A26: vs. | P26: vs. | AE26: Kenneth Farrugia/Rowena Caruana
A27: =AE17 -> Kenneth Farrugia / Rowena Caruana | B27: 7 | C27: =IF(B27>B25,1,0) -> 1 | E27: 4 | F27: =IF(E27>E25,1,0) -> 0 | H27: 5 | I27: =IF(H27>H25,1,0) -> 0 | J27: =IF(B27="",0,1) -> 1 | K27: =IF(C27+F27=2,3,IF(C27+F27=1,1,0)) -> 1 | L27: =IF(K27=3,3,IF(I27+K27=2,2,IF(K27=1,1,0))) -> 1 | M27: =B27+E27 -> 11 | N27: =C27+F27+I27 -> 1 | P27: =AE19 -> Dorian Demanuele / Maria Ellul | Q27: 0 | R27: =IF(Q27>Q25,1,0) -> 0 | T27: 1 | U27: =IF(T27>T25,1,0) -> 0 | X27: =IF(W27>W25,1,0) -> 0 | Y27: =IF(Q27="",0,1) -> 1 | Z27: =IF(R27+U27=2,3,IF(R27+U27=1,1,0)) -> 0 | AA27: =IF(Z27=3,3,IF(X27+Z27=2,2,IF(Z27=1,1,0))) -> 0 | AB27: =Q27+T27 -> 1 | AC27: =R27+U27+X27 -> 0
