Workbook

Sheet Players - Men
A1: VLTC Singles Tournament 2025
B5: Men Division 1 - Group A | E5: Men Division 1 - Group B
A6: 1 | B6: Trevor Rutter | D6: 1 | E6: Jean Carl Azzopardi
A7: 2 | B7: Melchior Farrugia | D7: 2 | E7: Karl Debattista
A8: 3 | B8: Ryan Mizzi | D8: 3 | E8: Claude Mifsud Wismayer
A9: 4 | B9: Andre' Farrugia | D9: 4 | E9: Daniel Farrugia
A10: 5 | B10: Marco Mercieca | D10: 5 | E10: Fotios Evangelou
A11: 6 | B11: Kurt Cassar | D11: 6 | E11: Eric Roca
B13: Men Division 2 - Group A | E13: Men Division 2 - Group B
A14: 1 | B14: Tobias Kristensen | D14: 1 | E14: John Mifsud
A15: 2 | B15: Kristen Cachia | D15: 2 | E15: Roderick Spiteri
A16: 3 | B16: Justin Graeme Christie | D16: 3 | E16: Jonathan Martinelli
A17: 4 | B17: Emman Xuereb | D17: 4 | E17: Liam Dixon
A18: 5 | B18: Ivan Cassar | D18: 5 | E18: Georges Meekers
A19: 6 | B19: Kyle Magro | D19: 6 | E19: Julian Bilocca
B21: Men Division 3 Group A | E21: Men Division 3 - Group B
A22: 1 | B22: Etienne Formosa Carabez | D22: 1 | E22: Sam Zammit
A23: 2 | B23: David Camilleri | D23: 2 | E23: Steve Gambin
A24: 3 | B24: Cory Greenland | D24: 3 | E24: Sean Cachia
A25: 4 | B25: Jason Lee Evans | D25: 4 | E25: Sebastian Attard
A26: 5 | B26: Adrian Duca | D26: 5 | E26: Matthew Micallef
A27: 6 | B27: Juan Sammut | D27: 6 | E27: Simone Re
B29: Men Division 4 Group A | E29: Men Division 4 Group B
A30: 1 | B30: Sammy Ben Tamer | D30: 1 | E30: Matthew Caruana
A31: 2 | B31: Kevin Sciberras | D31: 2 | E31: Jurgen Cachia
A32: 3 | B32: Liam Vella | D32: 3 | E32: Redent Scicluna
A33: 4 | B33: Chris Vella | D33: 4 | E33: Glenn Micallef
A34: 5 | B34: Braydon Galea | D34: 5 | E34: JP Sciberras
A35: 6 | B35: Michael Bugeja | D35: 6 | E35: Matthew Napier

Sheet Men Div 1
A1: VLTC Singles Tournament 2025
A5: Division 1 - Group A
A7: Players | B7: Set Scores | H7: Tie | P7: Players | Q7: Set Scores | W7: Tie | AE7: Player | AF7: Matches Played | AG7: Points Overall | AH7: Games Won | AI7: Sets Won
B8: Score | C8: Set 1 Work | E8: Score | F8: Set 2 Work | H8: Score | I8: Tie Work | J8: Game Played | K8: Sets Points Work | L8: Sets & Tie Points Work | M8: Games Wins Work | N8: Sets Wins Work | Q8: Score | R8: Set 1 Work | T8: Score | U8: Set 2 Work | W8: Score | X8: Tie Work | Y8: Game Played | Z8: Sets Points Work | AA8: Sets & Tie Points Work | AB8: Games Wins Work | AC8: Sets Wins Work | AJ8: Winner Working | AK8: Total Games Work | AL8: Winner
A9: =AE9 -> Trevor Rutter | B9: 7 | C9: =IF(B9>B11,1,0) -> 1 | E9: 6 | F9: =IF(E9>E11,1,0) -> 1 | I9: =IF(H9>H11,1,0) -> 0 | J9: =IF(B9="",0,1) -> 1 | K9: =IF(C9+F9=2,3,IF(C9+F9=1,1,0)) -> 3 | L9: =IF(K9=3,3,IF(I9+K9=2,2,IF(K9=1,1,0))) -> 3 | M9: =B9+E9 -> 13 | N9: =C9+F9+I9 -> 2 | P9: =AE9 -> Trevor Rutter | Q9: 3 | R9: =IF(Q9>Q11,1,0) -> 0 | T9: 2 | U9: =IF(T9>T11,1,0) -> 0 | X9: =IF(W9>W11,1,0) -> 0 | Y9: =IF(Q9="",0,1) -> 1 | Z9: =IF(R9+U9=2,3,IF(R9+U9=1,1,0)) -> 0 | AA9: =IF(Z9=3,3,IF(X9+Z9=2,2,IF(Z9=1,1,0))) -> 0 | AB9: =Q9+T9 -> 5 | AC9: =R9+U9+X9 -> 0 | AE9: ='Players - Men'!B6 -> Trevor Rutter | AF9: =J9+Y9+J13+Y13+J17 -> 5 | AG9: =L9+AA9+L13+AA13+L17 -> 12 | AH9: =M9+AB9+M13+AB13+M17 -> 54 | AI9: =N9+AC9+N13+AC13+N17 -> 8 | AJ9: =MAX(AG9:AG19) -> 12 | AK9: =SUM(AF9:AF19) -> 30 | AL9: =IF(AG9=$AJ$9,AE9,IF(AG11=$AJ$9,AE11,IF(AG13=$AJ$9,AE13,IF(AG15=$AJ$9,AE15,IF(AG17=$AJ$9,AE17,IF(AG19=$AJ$9,AE19,"")))))) -> Trevor Rutter
A10: vs. | P10: vs.
A11: =AE11 -> Melchior Farrugia | B11: 5 | C11: =IF(B11>B9,1,0) -> 0 | E11: 3 | F11: =IF(E11>E9,1,0) -> 0 | I11: =IF(H11>H9,1,0) -> 0 | J11: =IF(B11="",0,1) -> 1 | K11: =IF(C11+F11=2,3,IF(C11+F11=1,1,0)) -> 0 | L11: =IF(K11=3,3,IF(I11+K11=2,2,IF(K11=1,1,0))) -> 0 | M11: =B11+E11 -> 8 | N11: =C11+F11+I11 -> 0 | P11: =AE13 -> Ryan Mizzi | Q11: 6 | R11: =IF(Q11>Q9,1,0) -> 1 | T11: 6 | U11: =IF(T11>T9,1,0) -> 1 | X11: =IF(W11>W9,1,0) -> 0 | Y11: =IF(Q11="",0,1) -> 1 | Z11: =IF(R11+U11=2,3,IF(R11+U11=1,1,0)) -> 3 | AA11: =IF(Z11=3,3,IF(X11+Z11=2,2,IF(Z11=1,1,0))) -> 3 | AB11: =Q11+T11 -> 12 | AC11: =R11+U11+X11 -> 2 | AE11: ='Players - Men'!B7 -> Melchior Farrugia | AF11: =J11+Y25+J25+Y21+J21 -> 5 | AG11: =L11+AA25+L25+AA21+L21 -> 10 | AH11: =M11+AB25+M25+AB21+M21 -> 54 | AI11: =N11+AC25+N25+AC21+N21 -> 7
A13: =AE9 -> Trevor Rutter | B13: 6 | C13: =IF(B13>B15,1,0) -> 1 | E13: 6 | F13: =IF(E13>E15,1,0) -> 1 | I13: =IF(H13>H15,1,0) -> 0 | J13: =IF(B13="",0,1) -> 1 | K13: =IF(C13+F13=2,3,IF(C13+F13=1,1,0)) -> 3 | L13: =IF(K13=3,3,IF(I13+K13=2,2,IF(K13=1,1,0))) -> 3 | M13: =B13+E13 -> 12 | N13: =C13+F13+I13 -> 2 | P13: =AE9 -> Trevor Rutter | Q13: 6 | R13: =IF(Q13>Q15,1,0) -> 1 | T13: 6 | U13: =IF(T13>T15,1,0) -> 1 | X13: =IF(W13>W15,1,0) -> 0 | Y13: =IF(Q13="",0,1) -> 1 | Z13: =IF(R13+U13=2,3,IF(R13+U13=1,1,0)) -> 3 | AA13: =IF(Z13=3,3,IF(X13+Z13=2,2,IF(Z13=1,1,0))) -> 3 | AB13: =Q13+T13 -> 12 | AC13: =R13+U13+X13 -> 2 | AE13: ='Players - Men'!B8 -> Ryan Mizzi | AF13: =Y29+Y11+Y33+J33+J23 -> 5 | AG13: =AA29+AA11+AA33+L33+L23 -> 9 | AH13: =AB29+AB11+AB33+M33+M23 -> 48 | AI13: =AC29+AC11+AC33+N33+N23 -> 7
A14: vs. | P14: vs.
A15: =AE15 -> Andre' Farrugia | B15: 0 | C15: =IF(B15>B13,1,0) -> 0 | E15: 0 | F15: =IF(E15>E13,1,0) -> 0 | I15: =IF(H15>H13,1,0) -> 0 | J15: =IF(B15="",0,1) -> 1 | K15: =IF(C15+F15=2,3,IF(C15+F15=1,1,0)) -> 0 | L15: =IF(K15=3,3,IF(I15+K15=2,2,IF(K15=1,1,0))) -> 0 | M15: =B15+E15 -> 0 | N15: =C15+F15+I15 -> 0 | P15: =AE17 -> Marco Mercieca | Q15: 4 | R15: =IF(Q15>Q13,1,0) -> 0 | T15: 3 | U15: =IF(T15>T13,1,0) -> 0 | X15: =IF(W15>W13,1,0) -> 0 | Y15: =IF(Q15="",0,1) -> 1 | Z15: =IF(R15+U15=2,3,IF(R15+U15=1,1,0)) -> 0 | AA15: =IF(Z15=3,3,IF(X15+Z15=2,2,IF(Z15=1,1,0))) -> 0 | AB15: =Q15+T15 -> 7 | AC15: =R15+U15+X15 -> 0 | AE15: ='Players - Men'!B9 -> Andre' Farrugia | AF15: =Y31+J37+J15+Y23+J29 -> 5 | AG15: =AA31+L37+L15+AA23+L29 -> 3 | AH15: =AB31+M37+M15+AB23+M29 -> 14 | AI15: =AC31+N37+N15+AC23+N29 -> 3
A17: =AE9 -> Trevor Rutter | B17: 6 | C17: =IF(B17>B19,1,0) -> 1 | E17: 6 | F17: =IF(E17>E19,1,0) -> 1 | I17: =IF(H17>H19,1,0) -> 0 | J17: =IF(B17="",0,1) -> 1 | K17: =IF(C17+F17=2,3,IF(C17+F17=1,1,0)) -> 3 | L17: =IF(K17=3,3,IF(I17+K17=2,2,IF(K17=1,1,0))) -> 3 | M17: =B17+E17 -> 12 | N17: =C17+F17+I17 -> 2 | P17: =AE17 -> Marco Mercieca | Q17: 6 | R17: =IF(Q17>Q19,1,0) -> 1 | T17: 6 | U17: =IF(T17>T19,1,0) -> 1 | X17: =IF(W17>W19,1,0) -> 0 | Y17: =IF(Q17="",0,1) -> 1 | Z17: =IF(R17+U17=2,3,IF(R17+U17=1,1,0)) -> 3 | AA17: =IF(Z17=3,3,IF(X17+Z17=2,2,IF(Z17=1,1,0))) -> 3 | AB17: =Q17+T17 -> 12 | AC17: =R17+U17+X17 -> 2 | AE17: ='Players - Men'!B10 -> Marco Mercieca | AF17: =Y17+J39+J27+Y15+J35 -> 5 | AG17: =AA17+L39+L27+AA15+L35 -> 6 | AH17: =AB17+M39+M27+AB15+M35 -> 36 | AI17: =AC17+N39+N27+AC15+N35 -> 5
A18: vs. | P18: vs.
A19: =AE19 -> Kurt Cassar | B19: 1 | C19: =IF(B19>B21,1,0) -> 0 | E19: 1 | F19: =IF(E19>E17,1,0) -> 0 | I19: =IF(H19>H17,1,0) -> 0 | J19: =IF(B19="",0,1) -> 1 | K19: =IF(C19+F19=2,3,IF(C19+F19=1,1,0)) -> 0 | L19: =IF(K19=3,3,IF(I19+K19=2,2,IF(K19=1,1,0))) -> 0 | M19: =B19+E19 -> 2 | N19: =C19+F19+I19 -> 0 | P19: =AE19 -> Kurt Cassar | Q19: 0 | R19: =IF(Q19>Q17,1,0) -> 0 | T19: 3 | U19: =IF(T19>T17,1,0) -> 0 | X19: =IF(W19>W17,1,0) -> 0 | Y19: =IF(Q19="",0,1) -> 1 | Z19: =IF(R19+U19=2,3,IF(R19+U19=1,1,0)) -> 0 | AA19: =IF(Z19=3,3,IF(X19+Z19=2,2,IF(Z19=1,1,0))) -> 0 | AB19: =Q19+T19 -> 3 | AC19: =R19+U19+X19 -> 0 | AE19: ='Players - Men'!B11 -> Kurt Cassar | AF19: =Y19+Y27+Y35+J19+J31 -> 5 | AG19: =AA19+AA35+L31+AA27+L19 -> 1 | AH19: =AB19+AB27+AB35+M19+M31 -> 25 | AI19: =AC19+AC27+AC35+N19+N31 -> 2
A21: =AE11 -> Melchior Farrugia | B21: 6 | C21: =IF(B21>B23,1,0) -> 1 | E21: 6 | F21: =IF(E21>E23,1,0) -> 1 | I21: =IF(H21>H23,1,0) -> 0 | J21: =IF(B21="",0,1) -> 1 | K21: =IF(C21+F21=2,3,IF(C21+F21=1,1,0)) -> 3 | L21: =IF(K21=3,3,IF(I21+K21=2,2,IF(K21=1,1,0))) -> 3 | M21: =B21+E21 -> 12 | N21: =C21+F21+I21 -> 2 | P21: =AE11 -> Melchior Farrugia | Q21: 6 | R21: =IF(Q21>Q23,1,0) -> 1 | T21: 6 | U21: =IF(T21>T23,1,0) -> 1 | X21: =IF(W21>W23,1,0) -> 0 | Y21: =IF(Q21="",0,1) -> 1 | Z21: =IF(R21+U21=2,3,IF(R21+U21=1,1,0)) -> 3 | AA21: =IF(Z21=3,3,IF(X21+Z21=2,2,IF(Z21=1,1,0))) -> 3 | AB21: =Q21+T21 -> 12 | AC21: =R21+U21+X21 -> 2 | AE21: Group A Winner
A22: vs. | P22: vs. | AE22: Trevor Rutter
A23: =AE13 -> Ryan Mizzi | B23: 2 | C23: =IF(B23>B25,1,0) -> 0 | E23: 2 | F23: =IF(E23>E21,1,0) -> 0 | I23: =IF(H23>H21,1,0) -> 0 | J23: =IF(B23="",0,1) -> 1 | K23: =IF(C23+F23=2,3,IF(C23+F23=1,1,0)) -> 0 | L23: =IF(K23=3,3,IF(I23+K23=2,2,IF(K23=1,1,0))) -> 0 | M23: =B23+E23 -> 4 | N23: =C23+F23+I23 -> 0 | P23: =AE15 -> Andre' Farrugia | Q23: 1 | R23: =IF(Q23>Q21,1,0) -> 0 | T23: 1 | U23: =IF(T23>T21,1,0) -> 0 | X23: =IF(W23>W21,1,0) -> 0 | Y23: =IF(Q23="",0,1) -> 1 | Z23: =IF(R23+U23=2,3,IF(R23+U23=1,1,0)) -> 0 | AA23: =IF(Z23=3,3,IF(X23+Z23=2,2,IF(Z23=1,1,0))) -> 0 | AB23: =Q23+T23 -> 2 | AC23: =R23+U23+X23 -> 0
A25: =AE11 -> Melchior Farrugia | B25: 6 | C25: =IF(B25>B27,1,0) -> 1 | E25: 4 | F25: =IF(E25>E27,1,0) -> 0 | H25: 9 | I25: =IF(H25>H27,1,0) -> 0 | J25: =IF(B25="",0,1) -> 1 | K25: =IF(C25+F25=2,3,IF(C25+F25=1,1,0)) -> 1 | L25: =IF(K25=3,3,IF(I25+K25=2,2,IF(K25=1,1,0))) -> 1 | M25: =B25+E25 -> 10 | N25: =C25+F25+I25 -> 1 | P25: =AE11 -> Melchior Farrugia | Q25: 6 | R25: =IF(Q25>Q27,1,0) -> 1 | T25: 6 | U25: =IF(T25>T27,1,0) -> 1 | X25: =IF(W25>W27,1,0) -> 0 | Y25: =IF(Q25="",0,1) -> 1 | Z25: =IF(R25+U25=2,3,IF(R25+U25=1,1,0)) -> 3 | AA25: =IF(Z25=3,3,IF(X25+Z25=2,2,IF(Z25=1,1,0))) -> 3 | AB25: =Q25+T25 -> 12 | AC25: =R25+U25+X25 -> 2
A26: vs. | P26: vs.
A27: =AE17 -> Marco Mercieca | B27: 0 | C27: =IF(B27>B29,1,0) -> 0 | E27: 6 | F27: =IF(E27>E25,1,0) -> 1 | H27: 11 | I27: =IF(H27>H25,1,0) -> 1 | J27: =IF(B27="",0,1) -> 1 | K27: =IF(C27+F27=2,3,IF(C27+F27=1,1,0)) -> 1 | L27: =IF(K27=3,3,IF(I27+K27=2,2,IF(K27=1,1,0))) -> 2 | M27: =B27+E27 -> 6 | N27: =C27+F27+I27 -> 2 | P27: =AE19 -> Kurt Cassar | Q27: 1 | R27: =IF(Q27>Q25,1,0) -> 0 | T27: 1 | U27: =IF(T27>T25,1,0) -> 0 | X27: =IF(W27>W25,1,0) -> 0 | Y27: =IF(Q27="",0,1) -> 1 | Z27: =IF(R27+U27=2,3,IF(R27+U27=1,1,0)) -> 0 | AA27: =IF(Z27=3,3,IF(X27+Z27=2,2,IF(Z27=1,1,0))) -> 0 | AB27: =Q27+T27 -> 2 | AC27: =R27+U27+X27 -> 0
A29: =AE15 -> Andre' Farrugia | B29: 0 | C29: =IF(B29>B31,1,0) -> 0 | E29: 6 | F29: =IF(E29>E31,1,0) -> 1 | H29: 9 | I29: =IF(H29>H31,1,0) -> 0 | J29: =IF(B29="",0,1) -> 1 | K29: =IF(C29+F29=2,3,IF(C29+F29=1,1,0)) -> 1 | L29: =IF(K29=3,3,IF(I29+K29=2,2,IF(K29=1,1,0))) -> 1 | M29: =B29+E29 -> 6 | N29: =C29+F29+I29 -> 1 | P29: =AE13 -> Ryan Mizzi | Q29: 6 | R29: =IF(Q29>Q31,1,0) -> 1 | T29: 4 | U29: =IF(T29>T31,1,0) -> 0 | W29: 11 | X29: =IF(W29>W31,1,0) -> 0 | Y29: =IF(Q29="",0,1) -> 1 | Z29: =IF(R29+U29=2,3,IF(R29+U29=1,1,0)) -> 1 | AA29: =IF(Z29=3,3,IF(X29+Z29=2,2,IF(Z29=1,1,0))) -> 1 | AB29: =Q29+T29 -> 10 | AC29: =R29+U29+X29 -> 1
A30: vs. | P30: vs.
A31: =AE19 -> Kurt Cassar | B31: 6 | C31: =IF(B31>B33,1,0) -> 0 | E31: 3 | F31: =IF(E31>E29,1,0) -> 0 | H31: 11 | I31: =IF(H31>H29,1,0) -> 1 | J31: =IF(B31="",0,1) -> 1 | K31: =IF(C31+F31=2,3,IF(C31+F31=1,1,0)) -> 0 | L31: =IF(K31=3,3,IF(I31+K31=2,2,IF(K31=1,1,0))) -> 0 | M31: =B31+E31 -> 9 | N31: =C31+F31+I31 -> 1 | P31: =AE15 -> Andre' Farrugia | Q31: 0 | R31: =IF(Q31>Q29,1,0) -> 0 | T31: 6 | U31: =IF(T31>T29,1,0) -> 1 | W31: 13 | X31: =IF(W31>W29,1,0) -> 1 | Y31: =IF(Q31="",0,1) -> 1 | Z31: =IF(R31+U31=2,3,IF(R31+U31=1,1,0)) -> 1 | AA31: =IF(Z31=3,3,IF(X31+Z31=2,2,IF(Z31=1,1,0))) -> 2 | AB31: =Q31+T31 -> 6 | AC31: =R31+U31+X31 -> 2
A33: =AE13 -> Ryan Mizzi | B33: 6 | C33: =IF(B33>B35,1,0) -> 1 | E33: 7 | F33: =IF(E33>E35,1,0) -> 1 | I33: =IF(H33>H35,1,0) -> 0 | J33: =IF(B33="",0,1) -> 1 | K33: =IF(C33+F33=2,3,IF(C33+F33=1,1,0)) -> 3 | L33: =IF(K33=3,3,IF(I33+K33=2,2,IF(K33=1,1,0))) -> 3 | M33: =B33+E33 -> 13 | N33: =C33+F33+I33 -> 2 | P33: =AE13 -> Ryan Mizzi | Q33: 3 | R33: =IF(Q33>Q35,1,0) -> 0 | T33: 6 | U33: =IF(T33>T35,1,0) -> 1 | W33: 10 | X33: =IF(W33>W35,1,0) -> 1 | Y33: =IF(Q33="",0,1) -> 1 | Z33: =IF(R33+U33=2,3,IF(R33+U33=1,1,0)) -> 1 | AA33: =IF(Z33=3,3,IF(X33+Z33=2,2,IF(Z33=1,1,0))) -> 2 | AB33: =Q33+T33 -> 9 | AC33: =R33+U33+X33 -> 2
A34: vs. | P34: vs.
A35: =AE17 -> Marco Mercieca | B35: 0 | C35: =IF(B35>B37,1,0) -> 0 | E35: 5 | F35: =IF(E35>E33,1,0) -> 0 | I35: =IF(H35>H33,1,0) -> 0 | J35: =IF(B35="",0,1) -> 1 | K35: =IF(C35+F35=2,3,IF(C35+F35=1,1,0)) -> 0 | L35: =IF(K35=3,3,IF(I35+K35=2,2,IF(K35=1,1,0))) -> 0 | M35: =B35+E35 -> 5 | N35: =C35+F35+I35 -> 0 | P35: =AE19 -> Kurt Cassar | Q35: 6 | R35: =IF(Q35>Q33,1,0) -> 1 | T35: 3 | U35: =IF(T35>T33,1,0) -> 0 | W35: 6 | X35: =IF(W35>W33,1,0) -> 0 | Y35: =IF(Q35="",0,1) -> 1 | Z35: =IF(R35+U35=2,3,IF(R35+U35=1,1,0)) -> 1 | AA35: =IF(Z35=3,3,IF(X35+Z35=2,2,IF(Z35=1,1,0))) -> 1 | AB35: =Q35+T35 -> 9 | AC35: =R35+U35+X35 -> 1
A37: =AE15 -> Andre' Farrugia | B37: 0 | C37: =IF(B37>B39,1,0) -> 0 | E37: 0 | F37: =IF(E37>E39,1,0) -> 0 | I37: =IF(H37>H39,1,0) -> 0 | J37: =IF(B37="",0,1) -> 1 | K37: =IF(C37+F37=2,3,IF(C37+F37=1,1,0)) -> 0 | L37: =IF(K37=3,3,IF(I37+K37=2,2,IF(K37=1,1,0))) -> 0 | M37: =B37+E37 -> 0 | N37: =C37+F37+I37 -> 0
A38: vs.
A39: =AE17 -> Marco Mercieca | B39: 6 | C39: =IF(B39>B41,1,0) -> 1 | F39: =IF(E39>E37,1,0) -> 0 | I39: =IF(H39>H37,1,0) -> 0 | J39: =IF(B39="",0,1) -> 1 | K39: =IF(C39+F39=2,3,IF(C39+F39=1,1,0)) -> 1 | L39: =IF(K39=3,3,IF(I39+K39=2,2,IF(K39=1,1,0))) -> 1 | M39: =B39+E39 -> 6 | N39: =C39+F39+I39 -> 1
A47: Division 1 - Group B
A49: Players | B49: Set Scores | H49: Tie | P49: Players | Q49: Set Scores | W49: Tie | AE49: Player | AF49: Matches Played | AG49: Points Overall | AH49: Games Won | AI49: Sets Won
B50: Score | C50: Set 1 Work | E50: Score | F50: Set 2 Work | H50: Score | I50: Tie Work | J50: Game Played | K50: Sets Points Work | L50: Sets & Tie Points Work | M50: Games Wins Work | N50: Sets Wins Work | Q50: Score | R50: Set 1 Work | T50: Score | U50: Set 2 Work | W50: Score | X50: Tie Work | Y50: Game Played | Z50: Sets Points Work | AA50: Sets & Tie Points Work | AB50: Games Wins Work | AC50: Sets Wins Work | AJ50: Winner Working | AK50: Total Games Work | AL50: Winner
A51: =AE51 -> Jean Carl Azzopardi | B51: 3 | C51: =IF(B51>B53,1,0) -> 0 | E51: 6 | F51: =IF(E51>E53,1,0) -> 1 | H51: 10 | I51: =IF(H51>H53,1,0) -> 1 | J51: =IF(B51="",0,1) -> 1 | K51: =IF(C51+F51=2,3,IF(C51+F51=1,1,0)) -> 1 | L51: =IF(K51=3,3,IF(I51+K51=2,2,IF(K51=1,1,0))) -> 2 | M51: =B51+E51 -> 9 | N51: =C51+F51+I51 -> 2 | P51: =AE51 -> Jean Carl Azzopardi | R51: =IF(Q51>Q53,1,0) -> 0 | U51: =IF(T51>T53,1,0) -> 0 | X51: =IF(W51>W53,1,0) -> 0 | Y51: =IF(Q51="",0,1) -> 0 | Z51: =IF(R51+U51=2,3,IF(R51+U51=1,1,0)) -> 0 | AA51: =IF(Z51=3,3,IF(X51+Z51=2,2,IF(Z51=1,1,0))) -> 0 | AB51: =Q51+T51 -> 0 | AC51: =R51+U51+X51 -> 0 | AE51: ='Players - Men'!E6 -> Jean Carl Azzopardi | AF51: =J51+Y51+J55+Y55+J59 -> 4 | AG51: =L51+AA51+L55+AA55+L59 -> 11 | AH51: =M51+AB51+M55+AB55+M59 -> 46 | AI51: =N51+AC51+N55+AC55+N59 -> 8 | AJ51: =MAX(AG51:AG61) -> 11 | AK51: =SUM(AF51:AF61) -> 20 | AL51: =IF(AG51=$AJ$51,AE51,IF(AG53=$AJ$51,AE53,IF(AG55=$AJ$51,AE55,IF(AG57=$AJ$51,AE57,IF(AG59=$AJ$51,AE59,IF(AG61=$AJ$51,AE61,"")))))) -> Jean Carl Azzopardi
A52: vs. | P52: vs.
A53: =AE53 -> Karl Debattista | B53: 6 | C53: =IF(B53>B51,1,0) -> 1 | E53: 2 | F53: =IF(E53>E51,1,0) -> 0 | H53: 7 | I53: =IF(H53>H51,1,0) -> 0 | J53: =IF(B53="",0,1) -> 1 | K53: =IF(C53+F53=2,3,IF(C53+F53=1,1,0)) -> 1 | L53: =IF(K53=3,3,IF(I53+K53=2,2,IF(K53=1,1,0))) -> 1 | M53: =B53+E53 -> 8 | N53: =C53+F53+I53 -> 1 | P53: =AE55 -> Claude Mifsud Wismayer | R53: =IF(Q53>Q51,1,0) -> 0 | U53: =IF(T53>T51,1,0) -> 0 | X53: =IF(W53>W51,1,0) -> 0 | Y53: =IF(Q53="",0,1) -> 0 | Z53: =IF(R53+U53=2,3,IF(R53+U53=1,1,0)) -> 0 | AA53: =IF(Z53=3,3,IF(X53+Z53=2,2,IF(Z53=1,1,0))) -> 0 | AB53: =Q53+T53 -> 0 | AC53: =R53+U53+X53 -> 0 | AE53: ='Players - Men'!E7 -> Karl Debattista | AF53: =J53+Y67+J67+Y63+J63 -> 4 | AG53: =L53+AA67+L67+AA63+L63 -> 10 | AH53: =M53+AB67+M67+AB63+M63 -> 45 | AI53: =N53+AC67+N67+AC63+N63 -> 7
A55: =AE51 -> Jean Carl Azzopardi | B55: 6 | C55: =IF(B55>B57,1,0) -> 1 | E55: 6 | F55: =IF(E55>E57,1,0) -> 1 | I55: =IF(H55>H57,1,0) -> 0 | J55: =IF(B55="",0,1) -> 1 | K55: =IF(C55+F55=2,3,IF(C55+F55=1,1,0)) -> 3 | L55: =IF(K55=3,3,IF(I55+K55=2,2,IF(K55=1,1,0))) -> 3 | M55: =B55+E55 -> 12 | N55: =C55+F55+I55 -> 2 | P55: =AE51 -> Jean Carl Azzopardi | Q55: 6 | R55: =IF(Q55>Q57,1,0) -> 1 | T55: 6 | U55: =IF(T55>T57,1,0) -> 1 | X55: =IF(W55>W57,1,0) -> 0 | Y55: =IF(Q55="",0,1) -> 1 | Z55: =IF(R55+U55=2,3,IF(R55+U55=1,1,0)) -> 3 | AA55: =IF(Z55=3,3,IF(X55+Z55=2,2,IF(Z55=1,1,0))) -> 3 | AB55: =Q55+T55 -> 12 | AC55: =R55+U55+X55 -> 2 | AE55: ='Players - Men'!E8 -> Claude Mifsud Wismayer | AF55: =Y71+Y53+Y75+J75+J65 -> 0 | AG55: =AA71+AA53+AA75+L75+L65 -> 0 | AH55: =AB71+AB53+AB75+M75+M65 -> 0 | AI55: =AC71+AC53+AC75+N75+N65 -> 0
A56: vs. | P56: vs.
A57: =AE57 -> Daniel Farrugia | B57: 1 | C57: =IF(B57>B55,1,0) -> 0 | E57: 1 | F57: =IF(E57>E55,1,0) -> 0 | I57: =IF(H57>H55,1,0) -> 0 | J57: =IF(B57="",0,1) -> 1 | K57: =IF(C57+F57=2,3,IF(C57+F57=1,1,0)) -> 0 | L57: =IF(K57=3,3,IF(I57+K57=2,2,IF(K57=1,1,0))) -> 0 | M57: =B57+E57 -> 2 | N57: =C57+F57+I57 -> 0 | P57: =AE59 -> Fotios Evangelou | Q57: 0 | R57: =IF(Q57>Q55,1,0) -> 0 | T57: 2 | U57: =IF(T57>T55,1,0) -> 0 | X57: =IF(W57>W55,1,0) -> 0 | Y57: =IF(Q57="",0,1) -> 1 | Z57: =IF(R57+U57=2,3,IF(R57+U57=1,1,0)) -> 0 | AA57: =IF(Z57=3,3,IF(X57+Z57=2,2,IF(Z57=1,1,0))) -> 0 | AB57: =Q57+T57 -> 2 | AC57: =R57+U57+X57 -> 0 | AE57: ='Players - Men'!E9 -> Daniel Farrugia | AF57: =Y73+J79+J57+Y65+J71 -> 4 | AG57: =AA73+L79+L57+AA65+L71 -> 0 | AH57: =AB73+M79+M57+AB65+M71 -> 18 | AI57: =AC73+N79+N57+AC65+N71 -> 0
A59: =AE51 -> Jean Carl Azzopardi | B59: 6 | C59: =IF(B59>B61,1,0) -> 1 | E59: 7 | F59: =IF(E59>E61,1,0) -> 1 | I59: =IF(H59>H61,1,0) -> 0 | J59: =IF(B59="",0,1) -> 1 | K59: =IF(C59+F59=2,3,IF(C59+F59=1,1,0)) -> 3 | L59: =IF(K59=3,3,IF(I59+K59=2,2,IF(K59=1,1,0))) -> 3 | M59: =B59+E59 -> 13 | N59: =C59+F59+I59 -> 2 | P59: =AE59 -> Fotios Evangelou | Q59: 3 | R59: =IF(Q59>Q61,1,0) -> 0 | T59: 4 | U59: =IF(T59>T61,1,0) -> 0 | X59: =IF(W59>W61,1,0) -> 0 | Y59: =IF(Q59="",0,1) -> 1 | Z59: =IF(R59+U59=2,3,IF(R59+U59=1,1,0)) -> 0 | AA59: =IF(Z59=3,3,IF(X59+Z59=2,2,IF(Z59=1,1,0))) -> 0 | AB59: =Q59+T59 -> 7 | AC59: =R59+U59+X59 -> 0 | AE59: ='Players - Men'!E10 -> Fotios Evangelou | AF59: =Y59+J81+J69+Y57+J77 -> 4 | AG59: =AA59+L81+L69+AA57+L77 -> 3 | AH59: =AB59+M81+M69+AB57+M77 -> 32 | AI59: =AC59+N81+N69+AC57+N77 -> 2
A60: vs. | P60: vs.
A61: =AE61 -> Eric Roca | B61: 3 | C61: =IF(B61>B59,1,0) -> 0 | E61: 6 | F61: =IF(E61>E59,1,0) -> 0 | I61: =IF(H61>H59,1,0) -> 0 | J61: =IF(B61="",0,1) -> 1 | K61: =IF(C61+F61=2,3,IF(C61+F61=1,1,0)) -> 0 | L61: =IF(K61=3,3,IF(I61+K61=2,2,IF(K61=1,1,0))) -> 0 | M61: =B61+E61 -> 9 | N61: =C61+F61+I61 -> 0 | P61: =AE61 -> Eric Roca | Q61: 6 | R61: =IF(Q61>Q59,1,0) -> 1 | T61: 6 | U61: =IF(T61>T59,1,0) -> 1 | X61: =IF(W61>W59,1,0) -> 0 | Y61: =IF(Q61="",0,1) -> 1 | Z61: =IF(R61+U61=2,3,IF(R61+U61=1,1,0)) -> 3 | AA61: =IF(Z61=3,3,IF(X61+Z61=2,2,IF(Z61=1,1,0))) -> 3 | AB61: =Q61+T61 -> 12 | AC61: =R61+U61+X61 -> 2 | AE61: ='Players - Men'!E11 -> Eric Roca | AF61: =Y61+Y69+Y77+J61+J73 -> 4 | AG61: =AA61+AA69+AA77+L61+L73 -> 6 | AH61: =AB61+AB69+AB77+M61+M73 -> 33 | AI61: =AC61+AC69+AC77+N61+N73 -> 4
...

Sheet Men Div 2
A1: VLTC Singles Tournament 2025
A5: Division 2 - Group A
A7: Players | B7: Set Scores | H7: Tie | P7: Players | Q7: Set Scores | W7: Tie | AE7: Player | AF7: Matches Played | AG7: Points Overall | AH7: Games Won | AI7: Sets Won
B8: Score | C8: Set 1 Work | E8: Score | F8: Set 2 Work | H8: Score | I8: Tie Work | J8: Game Played | K8: Sets Points Work | L8: Sets & Tie Points Work | M8: Games Wins Work | N8: Sets Wins Work | Q8: Score | R8: Set 1 Work | T8: Score | U8: Set 2 Work | W8: Score | X8: Tie Work | Y8: Game Played | Z8: Sets Points Work | AA8: Sets & Tie Points Work | AB8: Games Wins Work | AC8: Sets Wins Work | AJ8: Winner Working | AK8: Total Games Work | AL8: Winner
A9: =AE9 -> Tobias Kristensen | B9: 1 | C9: =IF(B9>B11,1,0) -> 0 | E9: 4 | F9: =IF(E9>E11,1,0) -> 0 | I9: =IF(H9>H11,1,0) -> 0 | J9: =IF(B9="",0,1) -> 1 | K9: =IF(C9+F9=2,3,IF(C9+F9=1,1,0)) -> 0 | L9: =IF(K9=3,3,IF(I9+K9=2,2,IF(K9=1,1,0))) -> 0 | M9: =B9+E9 -> 5 | N9: =C9+F9+I9 -> 0 | P9: =AE9 -> Tobias Kristensen | Q9: 4 | R9: =IF(Q9>Q11,1,0) -> 0 | T9: 0 | U9: =IF(T9>T11,1,0) -> 0 | X9: =IF(W9>W11,1,0) -> 0 | Y9: =IF(Q9="",0,1) -> 1 | Z9: =IF(R9+U9=2,3,IF(R9+U9=1,1,0)) -> 0 | AA9: =IF(Z9=3,3,IF(X9+Z9=2,2,IF(Z9=1,1,0))) -> 0 | AB9: =Q9+T9 -> 4 | AC9: =R9+U9+X9 -> 0 | AE9: ='Players - Men'!B14 -> Tobias Kristensen | AF9: =J9+Y9+J13+Y13+J17 -> 5 | AG9: =L9+AA9+L13+AA13+L17 -> 1 | AH9: =M9+AB9+M13+AB13+M17 -> 32 | AI9: =N9+AC9+N13+AC13+N17 -> 1 | AJ9: =MAX(AG9:AG19) -> 13 | AK9: =SUM(AF9:AF19) -> 30 | AL9: =IF(AG9=$AJ$9,AE9,IF(AG11=$AJ$9,AE11,IF(AG13=$AJ$9,AE13,IF(AG15=$AJ$9,AE15,IF(AG17=$AJ$9,AE17,IF(AG19=$AJ$9,AE19,"")))))) -> Justin Graeme Christie
A10: vs.
A11: =AE11 -> Kristen Cachia | B11: 6 | C11: =IF(B11>B9,1,0) -> 1 | E11: 6 | F11: =IF(E11>E9,1,0) -> 1 | I11: =IF(H11>H9,1,0) -> 0 | J11: =IF(B11="",0,1) -> 1 | K11: =IF(C11+F11=2,3,IF(C11+F11=1,1,0)) -> 3 | L11: =IF(K11=3,3,IF(I11+K11=2,2,IF(K11=1,1,0))) -> 3 | M11: =B11+E11 -> 12 | N11: =C11+F11+I11 -> 2 | P11: =AE13 -> Justin Graeme Christie | Q11: 6 | R11: =IF(Q11>Q9,1,0) -> 1 | T11: 6 | U11: =IF(T11>T9,1,0) -> 1 | X11: =IF(W11>W9,1,0) -> 0 | Y11: =IF(Q11="",0,1) -> 1 | Z11: =IF(R11+U11=2,3,IF(R11+U11=1,1,0)) -> 3 | AA11: =IF(Z11=3,3,IF(X11+Z11=2,2,IF(Z11=1,1,0))) -> 3 | AB11: =Q11+T11 -> 12 | AC11: =R11+U11+X11 -> 2 | AE11: ='Players - Men'!B15 -> Kristen Cachia | AF11: =J11+Y25+J25+Y21+J21 -> 5 | AG11: =L11+AA25+L25+AA21+L21 -> 9 | AH11: =M11+AB25+M25+AB21+M21 -> 50 | AI11: =N11+AC25+N25+AC21+N21 -> 6
A13: =AE9 -> Tobias Kristensen | B13: 4 | C13: =IF(B13>B15,1,0) -> 0 | E13: 3 | F13: =IF(E13>E15,1,0) -> 0 | I13: =IF(H13>H15,1,0) -> 0 | J13: =IF(B13="",0,1) -> 1 | K13: =IF(C13+F13=2,3,IF(C13+F13=1,1,0)) -> 0 | L13: =IF(K13=3,3,IF(I13+K13=2,2,IF(K13=1,1,0))) -> 0 | M13: =B13+E13 -> 7 | N13: =C13+F13+I13 -> 0 | P13: =AE9 -> Tobias Kristensen | Q13: 1 | R13: =IF(Q13>Q15,1,0) -> 0 | T13: 6 | U13: =IF(T13>T15,1,0) -> 1 | W13: 7 | X13: =IF(W13>W15,1,0) -> 0 | Y13: =IF(Q13="",0,1) -> 1 | Z13: =IF(R13+U13=2,3,IF(R13+U13=1,1,0)) -> 1 | AA13: =IF(Z13=3,3,IF(X13+Z13=2,2,IF(Z13=1,1,0))) -> 1 | AB13: =Q13+T13 -> 7 | AC13: =R13+U13+X13 -> 1 | AE13: ='Players - Men'!B16 -> Justin Graeme Christie | AF13: =Y29+Y11+Y33+J33+J23 -> 5 | AG13: =AA29+AA11+AA33+L33+L23 -> 13 | AH13: =AB29+AB11+AB33+M33+M23 -> 57 | AI13: =AC29+AC11+AC33+N33+N23 -> 9
A14: vs. | P14: vs.
A15: =AE15 -> Emman Xuereb | B15: 6 | C15: =IF(B15>B13,1,0) -> 1 | E15: 6 | F15: =IF(E15>E13,1,0) -> 1 | I15: =IF(H15>H13,1,0) -> 0 | J15: =IF(B15="",0,1) -> 1 | K15: =IF(C15+F15=2,3,IF(C15+F15=1,1,0)) -> 3 | L15: =IF(K15=3,3,IF(I15+K15=2,2,IF(K15=1,1,0))) -> 3 | M15: =B15+E15 -> 12 | N15: =C15+F15+I15 -> 2 | P15: =AE17 -> Ivan Cassar | Q15: 6 | R15: =IF(Q15>Q13,1,0) -> 1 | T15: 1 | U15: =IF(T15>T13,1,0) -> 0 | W15: 10 | X15: =IF(W15>W13,1,0) -> 1 | Y15: =IF(Q15="",0,1) -> 1 | Z15: =IF(R15+U15=2,3,IF(R15+U15=1,1,0)) -> 1 | AA15: =IF(Z15=3,3,IF(X15+Z15=2,2,IF(Z15=1,1,0))) -> 2 | AB15: =Q15+T15 -> 7 | AC15: =R15+U15+X15 -> 2 | AE15: ='Players - Men'!B17 -> Emman Xuereb | AF15: =Y31+J37+J15+Y23+J29 -> 5 | AG15: =AA31+L37+L15+AA23+L29 -> 13 | AH15: =AB31+M37+M15+AB23+M29 -> 59 | AI15: =AC31+N37+N15+AC23+N29 -> 10
A17: =AE9 -> Tobias Kristensen | B17: 6 | C17: =IF(B17>B19,1,0) -> 0 | E17: 3 | F17: =IF(E17>E19,1,0) -> 0 | I17: =IF(H17>H19,1,0) -> 0 | J17: =IF(B17="",0,1) -> 1 | K17: =IF(C17+F17=2,3,IF(C17+F17=1,1,0)) -> 0 | L17: =IF(K17=3,3,IF(I17+K17=2,2,IF(K17=1,1,0))) -> 0 | M17: =B17+E17 -> 9 | N17: =C17+F17+I17 -> 0 | P17: =AE17 -> Ivan Cassar | Q17: 4 | R17: =IF(Q17>Q19,1,0) -> 0 | T17: 2 | U17: =IF(T17>T19,1,0) -> 0 | X17: =IF(W17>W19,1,0) -> 0 | Y17: =IF(Q17="",0,1) -> 1 | Z17: =IF(R17+U17=2,3,IF(R17+U17=1,1,0)) -> 0 | AA17: =IF(Z17=3,3,IF(X17+Z17=2,2,IF(Z17=1,1,0))) -> 0 | AB17: =Q17+T17 -> 6 | AC17: =R17+U17+X17 -> 0 | AE17: ='Players - Men'!B18 -> Ivan Cassar | AF17: =Y17+J39+J27+Y15+J35 -> 5 | AG17: =AA17+L39+L27+AA15+L35 -> 2 | AH17: =AB17+M39+M27+AB15+M35 -> 23 | AI17: =AC17+N39+N27+AC15+N35 -> 2
A18: vs. | P18: vs.
A19: =AE19 -> Kyle Magro | B19: 7 | C19: =IF(B19>B17,1,0) -> 1 | E19: 6 | F19: =IF(E19>E17,1,0) -> 1 | I19: =IF(H19>H17,1,0) -> 0 | J19: =IF(B19="",0,1) -> 1 | K19: =IF(C19+F19=2,3,IF(C19+F19=1,1,0)) -> 3 | L19: =IF(K19=3,3,IF(I19+K19=2,2,IF(K19=1,1,0))) -> 3 | M19: =B19+E19 -> 13 | N19: =C19+F19+I19 -> 2 | P19: =AE19 -> Kyle Magro | Q19: 6 | R19: =IF(Q19>Q17,1,0) -> 1 | T19: 6 | U19: =IF(T19>T17,1,0) -> 1 | X19: =IF(W19>W17,1,0) -> 0 | Y19: =IF(Q19="",0,1) -> 1 | Z19: =IF(R19+U19=2,3,IF(R19+U19=1,1,0)) -> 3 | AA19: =IF(Z19=3,3,IF(X19+Z19=2,2,IF(Z19=1,1,0))) -> 3 | AB19: =Q19+T19 -> 12 | AC19: =R19+U19+X19 -> 2 | AE19: ='Players - Men'!B19 -> Kyle Magro | AF19: =Y19+Y27+Y35+J19+J31 -> 5 | AG19: =AA19+AA35+L31+AA27+L19 -> 7 | AH19: =AB19+AB27+AB35+M19+M31 -> 46 | AI19: =AC19+AC27+AC35+N19+N31 -> 5
A21: =AE11 -> Kristen Cachia | B21: 3 | C21: =IF(B21>B23,1,0) -> 0 | E21: 4 | F21: =IF(E21>E23,1,0) -> 0 | I21: =IF(H21>H23,1,0) -> 0 | J21: =IF(B21="",0,1) -> 1 | K21: =IF(C21+F21=2,3,IF(C21+F21=1,1,0)) -> 0 | L21: =IF(K21=3,3,IF(I21+K21=2,2,IF(K21=1,1,0))) -> 0 | M21: =B21+E21 -> 7 | N21: =C21+F21+I21 -> 0 | P21: =AE11 -> Kristen Cachia | Q21: 3 | R21: =IF(Q21>Q23,1,0) -> 0 | T21: 3 | U21: =IF(T21>T23,1,0) -> 0 | X21: =IF(W21>W23,1,0) -> 0 | Y21: =IF(Q21="",0,1) -> 1 | Z21: =IF(R21+U21=2,3,IF(R21+U21=1,1,0)) -> 0 | AA21: =IF(Z21=3,3,IF(X21+Z21=2,2,IF(Z21=1,1,0))) -> 0 | AB21: =Q21+T21 -> 6 | AC21: =R21+U21+X21 -> 0 | AE21: Group A Winner
A22: vs. | P22: vs. | AE22: Emman Xuereb
A23: =AE13 -> Justin Graeme Christie | B23: 6 | C23: =IF(B23>B21,1,0) -> 1 | E23: 6 | F23: =IF(E23>E21,1,0) -> 1 | I23: =IF(H23>H21,1,0) -> 0 | J23: =IF(B23="",0,1) -> 1 | K23: =IF(C23+F23=2,3,IF(C23+F23=1,1,0)) -> 3 | L23: =IF(K23=3,3,IF(I23+K23=2,2,IF(K23=1,1,0))) -> 3 | M23: =B23+E23 -> 12 | N23: =C23+F23+I23 -> 2 | P23: =AE15 -> Emman Xuereb | Q23: 6 | R23: =IF(Q23>Q21,1,0) -> 1 | T23: 6 | U23: =IF(T23>T21,1,0) -> 1 | X23: =IF(W23>W21,1,0) -> 0 | Y23: =IF(Q23="",0,1) -> 1 | Z23: =IF(R23+U23=2,3,IF(R23+U23=1,1,0)) -> 3 | AA23: =IF(Z23=3,3,IF(X23+Z23=2,2,IF(Z23=1,1,0))) -> 3 | AB23: =Q23+T23 -> 12 | AC23: =R23+U23+X23 -> 2
A25: =AE11 -> Kristen Cachia | B25: 6 | C25: =IF(B25>B27,1,0) -> 1 | E25: 7 | F25: =IF(E25>E27,1,0) -> 1 | I25: =IF(H25>H27,1,0) -> 0 | J25: =IF(B25="",0,1) -> 1 | K25: =IF(C25+F25=2,3,IF(C25+F25=1,1,0)) -> 3 | L25: =IF(K25=3,3,IF(I25+K25=2,2,IF(K25=1,1,0))) -> 3 | M25: =B25+E25 -> 13 | N25: =C25+F25+I25 -> 2 | P25: =AE11 -> Kristen Cachia | Q25: 6 | R25: =IF(Q25>Q27,1,0) -> 1 | T25: 6 | U25: =IF(T25>T27,1,0) -> 1 | X25: =IF(W25>W27,1,0) -> 0 | Y25: =IF(Q25="",0,1) -> 1 | Z25: =IF(R25+U25=2,3,IF(R25+U25=1,1,0)) -> 3 | AA25: =IF(Z25=3,3,IF(X25+Z25=2,2,IF(Z25=1,1,0))) -> 3 | AB25: =Q25+T25 -> 12 | AC25: =R25+U25+X25 -> 2
A26: vs. | P26: vs.
A27: =AE17 -> Ivan Cassar | B27: 1 | C27: =IF(B27>B25,1,0) -> 0 | E27: 5 | F27: =IF(E27>E25,1,0) -> 0 | I27: =IF(H27>H25,1,0) -> 0 | J27: =IF(B27="",0,1) -> 1 | K27: =IF(C27+F27=2,3,IF(C27+F27=1,1,0)) -> 0 | L27: =IF(K27=3,3,IF(I27+K27=2,2,IF(K27=1,1,0))) -> 0 | M27: =B27+E27 -> 6 | N27: =C27+F27+I27 -> 0 | P27: =AE19 -> Kyle Magro | Q27: 2 | R27: =IF(Q27>Q25,1,0) -> 0 | T27: 2 | U27: =IF(T27>T25,1,0) -> 0 | X27: =IF(W27>W25,1,0) -> 0 | Y27: =IF(Q27="",0,1) -> 1 | Z27: =IF(R27+U27=2,3,IF(R27+U27=1,1,0)) -> 0 | AA27: =IF(Z27=3,3,IF(X27+Z27=2,2,IF(Z27=1,1,0))) -> 0 | AB27: =Q27+T27 -> 4 | AC27: =R27+U27+X27 -> 0
A29: =AE15 -> Emman Xuereb | B29: 4 | C29: =IF(B29>B31,1,0) -> 0 | E29: 7 | F29: =IF(E29>E31,1,0) -> 1 | H29: 10 | I29: =IF(H29>H31,1,0) -> 1 | J29: =IF(B29="",0,1) -> 1 | K29: =IF(C29+F29=2,3,IF(C29+F29=1,1,0)) -> 1 | L29: =IF(K29=3,3,IF(I29+K29=2,2,IF(K29=1,1,0))) -> 2 | M29: =B29+E29 -> 11 | N29: =C29+F29+I29 -> 2 | P29: =AE13 -> Justin Graeme Christie | Q29: 2 | R29: =IF(Q29>Q31,1,0) -> 0 | T29: 7 | U29: =IF(T29>T31,1,0) -> 1 | W29: 6 | X29: =IF(W29>W31,1,0) -> 0 | Y29: =IF(Q29="",0,1) -> 1 | Z29: =IF(R29+U29=2,3,IF(R29+U29=1,1,0)) -> 1 | AA29: =IF(Z29=3,3,IF(X29+Z29=2,2,IF(Z29=1,1,0))) -> 1 | AB29: =Q29+T29 -> 9 | AC29: =R29+U29+X29 -> 1
A30: vs. | P30: vs.
A31: =AE19 -> Kyle Magro | B31: 6 | C31: =IF(B31>B29,1,0) -> 1 | E31: 6 | F31: =IF(E31>E29,1,0) -> 0 | H31: 7 | I31: =IF(H31>H29,1,0) -> 0 | J31: =IF(B31="",0,1) -> 1 | K31: =IF(C31+F31=2,3,IF(C31+F31=1,1,0)) -> 1 | L31: =IF(K31=3,3,IF(I31+K31=2,2,IF(K31=1,1,0))) -> 1 | M31: =B31+E31 -> 12 | N31: =C31+F31+I31 -> 1 | P31: =AE15 -> Emman Xuereb | Q31: 6 | R31: =IF(Q31>Q29,1,0) -> 1 | T31: 6 | U31: =IF(T31>T29,1,0) -> 0 | W31: 10 | X31: =IF(W31>W29,1,0) -> 1 | Y31: =IF(Q31="",0,1) -> 1 | Z31: =IF(R31+U31=2,3,IF(R31+U31=1,1,0)) -> 1 | AA31: =IF(Z31=3,3,IF(X31+Z31=2,2,IF(Z31=1,1,0))) -> 2 | AB31: =Q31+T31 -> 12 | AC31: =R31+U31+X31 -> 2
A33: =AE13 -> Justin Graeme Christie | B33: 6 | C33: =IF(B33>B35,1,0) -> 1 | E33: 6 | F33: =IF(E33>E35,1,0) -> 1 | I33: =IF(H33>H35,1,0) -> 0 | J33: =IF(B33="",0,1) -> 1 | K33: =IF(C33+F33=2,3,IF(C33+F33=1,1,0)) -> 3 | L33: =IF(K33=3,3,IF(I33+K33=2,2,IF(K33=1,1,0))) -> 3 | M33: =B33+E33 -> 12 | N33: =C33+F33+I33 -> 2 | P33: =AE13 -> Justin Graeme Christie | Q33: 6 | R33: =IF(Q33>Q35,1,0) -> 1 | T33: 6 | U33: =IF(T33>T35,1,0) -> 1 | X33: =IF(W33>W35,1,0) -> 0 | Y33: =IF(Q33="",0,1) -> 1 | Z33: =IF(R33+U33=2,3,IF(R33+U33=1,1,0)) -> 3 | AA33: =IF(Z33=3,3,IF(X33+Z33=2,2,IF(Z33=1,1,0))) -> 3 | AB33: =Q33+T33 -> 12 | AC33: =R33+U33+X33 -> 2
A34: vs. | P34: vs.
A35: =AE17 -> Ivan Cassar | B35: 0 | C35: =IF(B35>B33,1,0) -> 0 | E35: 0 | F35: =IF(E35>E33,1,0) -> 0 | I35: =IF(H35>H33,1,0) -> 0 | J35: =IF(B35="",0,1) -> 1 | K35: =IF(C35+F35=2,3,IF(C35+F35=1,1,0)) -> 0 | L35: =IF(K35=3,3,IF(I35+K35=2,2,IF(K35=1,1,0))) -> 0 | M35: =B35+E35 -> 0 | N35: =C35+F35+I35 -> 0 | P35: =AE19 -> Kyle Magro | Q35: 3 | R35: =IF(Q35>Q33,1,0) -> 0 | T35: 2 | U35: =IF(T35>T33,1,0) -> 0 | X35: =IF(W35>W33,1,0) -> 0 | Y35: =IF(Q35="",0,1) -> 1 | Z35: =IF(R35+U35=2,3,IF(R35+U35=1,1,0)) -> 0 | AA35: =IF(Z35=3,3,IF(X35+Z35=2,2,IF(Z35=1,1,0))) -> 0 | AB35: =Q35+T35 -> 5 | AC35: =R35+U35+X35 -> 0
A37: =AE15 -> Emman Xuereb | B37: 6 | C37: =IF(B37>B39,1,0) -> 1 | E37: 6 | F37: =IF(E37>E39,1,0) -> 1 | I37: =IF(H37>H39,1,0) -> 0 | J37: =IF(B37="",0,1) -> 1 | K37: =IF(C37+F37=2,3,IF(C37+F37=1,1,0)) -> 3 | L37: =IF(K37=3,3,IF(I37+K37=2,2,IF(K37=1,1,0))) -> 3 | M37: =B37+E37 -> 12 | N37: =C37+F37+I37 -> 2
A38: vs.
A39: =AE17 -> Ivan Cassar | B39: 0 | C39: =IF(B39>B37,1,0) -> 0 | E39: 4 | F39: =IF(E39>E37,1,0) -> 0 | I39: =IF(H39>H37,1,0) -> 0 | J39: =IF(B39="",0,1) -> 1 | K39: =IF(C39+F39=2,3,IF(C39+F39=1,1,0)) -> 0 | L39: =IF(K39=3,3,IF(I39+K39=2,2,IF(K39=1,1,0))) -> 0 | M39: =B39+E39 -> 4 | N39: =C39+F39+I39 -> 0
A41: Division 2 - Group B
A43: Players | B43: Set Scores | H43: Tie | P43: Players | Q43: Set Scores | W43: Tie | AE43: Player | AF43: Matches Played | AG43: Points Overall | AH43: Games Won | AI43: Sets Won
B44: Score | C44: Set 1 Work | E44: Score | F44: Set 2 Work | H44: Score | I44: Tie Work | J44: Game Played | K44: Sets Points Work | L44: Sets & Tie Points Work | M44: Games Wins Work | N44: Sets Wins Work | Q44: Score | R44: Set 1 Work | T44: Score | U44: Set 2 Work | W44: Score | X44: Tie Work | Y44: Game Played | Z44: Sets Points Work | AA44: Sets & Tie Points Work | AB44: Games Wins Work | AC44: Sets Wins Work | AJ44: Winner Working | AK44: Total Games Work | AL44: Winner
A45: =AE45 -> John Mifsud | B45: 6 | C45: =IF(B45>B47,1,0) -> 1 | E45: 6 | F45: =IF(E45>E47,1,0) -> 1 | I45: =IF(H45>H47,1,0) -> 0 | J45: =IF(B45="",0,1) -> 1 | K45: =IF(C45+F45=2,3,IF(C45+F45=1,1,0)) -> 3 | L45: =IF(K45=3,3,IF(I45+K45=2,2,IF(K45=1,1,0))) -> 3 | M45: =B45+E45 -> 12 | N45: =C45+F45+I45 -> 2 | P45: =AE45 -> John Mifsud | Q45: 6 | R45: =IF(Q45>Q47,1,0) -> 1 | T45: 2 | U45: =IF(T45>T47,1,0) -> 0 | W45: 10 | X45: =IF(W45>W47,1,0) -> 1 | Y45: =IF(Q45="",0,1) -> 1 | Z45: =IF(R45+U45=2,3,IF(R45+U45=1,1,0)) -> 1 | AA45: =IF(Z45=3,3,IF(X45+Z45=2,2,IF(Z45=1,1,0))) -> 2 | AB45: =Q45+T45 -> 8 | AC45: =R45+U45+X45 -> 2 | AE45: ='Players - Men'!E14 -> John Mifsud | AF45: =J45+Y45+J49+Y49+J53 -> 5 | AG45: =L45+AA45+L49+AA49+L53 -> 11 | AH45: =M45+AB45+M49+AB49+M53 -> 52 | AI45: =N45+AC45+N49+AC49+N53 -> 8 | AJ45: =MAX(AG45:AG55) -> 13 | AK45: =SUM(AF45:AF55) -> 30 | AL45: =IF(AG45=$AJ$45,AE45,IF(AG47=$AJ$45,AE47,IF(AG49=$AJ$45,AE49,IF(AG51=$AJ$45,AE51,IF(AG53=$AJ$45,AE53,IF(AG55=$AJ$45,AE55,"")))))) -> Liam Dixon
A46: vs. | P46: vs.
A47: =AE47 -> Roderick Spiteri | B47: 3 | C47: =IF(B47>B45,1,0) -> 0 | E47: 1 | F47: =IF(E47>E45,1,0) -> 0 | I47: =IF(H47>H45,1,0) -> 0 | J47: =IF(B47="",0,1) -> 1 | K47: =IF(C47+F47=2,3,IF(C47+F47=1,1,0)) -> 0 | L47: =IF(K47=3,3,IF(I47+K47=2,2,IF(K47=1,1,0))) -> 0 | M47: =B47+E47 -> 4 | N47: =C47+F47+I47 -> 0 | P47: =AE49 -> Jonathan Martinelli | Q47: 3 | R47: =IF(Q47>Q45,1,0) -> 0 | T47: 6 | U47: =IF(T47>T45,1,0) -> 1 | W47: 8 | X47: =IF(W47>W45,1,0) -> 0 | Y47: =IF(Q47="",0,1) -> 1 | Z47: =IF(R47+U47=2,3,IF(R47+U47=1,1,0)) -> 1 | AA47: =IF(Z47=3,3,IF(X47+Z47=2,2,IF(Z47=1,1,0))) -> 1 | AB47: =Q47+T47 -> 9 | AC47: =R47+U47+X47 -> 1 | AE47: ='Players - Men'!E15 -> Roderick Spiteri | AF47: =J47+Y61+J61+Y57+J57 -> 5 | AG47: =L47+AA61+L61+AA57+L57 -> 6 | AH47: =M47+AB61+M61+AB57+M57 -> 45 | AI47: =N47+AC61+N61+AC57+N57 -> 4
A49: =AE45 -> John Mifsud | B49: 6 | C49: =IF(B49>B51,1,0) -> 0 | E49: 2 | F49: =IF(E49>E51,1,0) -> 0 | I49: =IF(H49>H51,1,0) -> 0 | J49: =IF(B49="",0,1) -> 1 | K49: =IF(C49+F49=2,3,IF(C49+F49=1,1,0)) -> 0 | L49: =IF(K49=3,3,IF(I49+K49=2,2,IF(K49=1,1,0))) -> 0 | M49: =B49+E49 -> 8 | N49: =C49+F49+I49 -> 0 | P49: =AE45 -> John Mifsud | Q49: 6 | R49: =IF(Q49>Q51,1,0) -> 1 | T49: 6 | U49: =IF(T49>T51,1,0) -> 1 | X49: =IF(W49>W51,1,0) -> 0 | Y49: =IF(Q49="",0,1) -> 1 | Z49: =IF(R49+U49=2,3,IF(R49+U49=1,1,0)) -> 3 | AA49: =IF(Z49=3,3,IF(X49+Z49=2,2,IF(Z49=1,1,0))) -> 3 | AB49: =Q49+T49 -> 12 | AC49: =R49+U49+X49 -> 2 | AE49: ='Players - Men'!E16 -> Jonathan Martinelli | AF49: =Y65+Y47+Y69+J69+J59 -> 5 | AG49: =AA65+AA47+AA69+L69+L59 -> 12 | AH49: =AB65+AB47+AB69+M69+M59 -> 57 | AI49: =AC65+AC47+AC69+N69+N59 -> 9
A50: vs. | P50: vs.
A51: =AE51 -> Liam Dixon | B51: 7 | C51: =IF(B51>B49,1,0) -> 1 | E51: 6 | F51: =IF(E51>E49,1,0) -> 1 | I51: =IF(H51>H49,1,0) -> 0 | J51: =IF(B51="",0,1) -> 1 | K51: =IF(C51+F51=2,3,IF(C51+F51=1,1,0)) -> 3 | L51: =IF(K51=3,3,IF(I51+K51=2,2,IF(K51=1,1,0))) -> 3 | M51: =B51+E51 -> 13 | N51: =C51+F51+I51 -> 2 | P51: =AE53 -> Georges Meekers | Q51: 1 | R51: =IF(Q51>Q49,1,0) -> 0 | T51: 3 | U51: =IF(T51>T49,1,0) -> 0 | X51: =IF(W51>W49,1,0) -> 0 | Y51: =IF(Q51="",0,1) -> 1 | Z51: =IF(R51+U51=2,3,IF(R51+U51=1,1,0)) -> 0 | AA51: =IF(Z51=3,3,IF(X51+Z51=2,2,IF(Z51=1,1,0))) -> 0 | AB51: =Q51+T51 -> 4 | AC51: =R51+U51+X51 -> 0 | AE51: ='Players - Men'!E17 -> Liam Dixon | AF51: =Y67+J73+J51+Y59+J65 -> 5 | AG51: =AA67+L73+L51+AA59+L65 -> 13 | AH51: =AB67+M73+M51+AB59+M65 -> 60 | AI51: =AC67+N73+N51+AC59+N65 -> 9
A53: =AE45 -> John Mifsud | B53: 6 | C53: =IF(B53>B55,1,0) -> 1 | E53: 6 | F53: =IF(E53>E55,1,0) -> 1 | I53: =IF(H53>H55,1,0) -> 0 | J53: =IF(B53="",0,1) -> 1 | K53: =IF(C53+F53=2,3,IF(C53+F53=1,1,0)) -> 3 | L53: =IF(K53=3,3,IF(I53+K53=2,2,IF(K53=1,1,0))) -> 3 | M53: =B53+E53 -> 12 | N53: =C53+F53+I53 -> 2 | P53: =AE53 -> Georges Meekers | Q53: 6 | R53: =IF(Q53>Q55,1,0) -> 1 | T53: 6 | U53: =IF(T53>T55,1,0) -> 1 | X53: =IF(W53>W55,1,0) -> 0 | Y53: =IF(Q53="",0,1) -> 1 | Z53: =IF(R53+U53=2,3,IF(R53+U53=1,1,0)) -> 3 | AA53: =IF(Z53=3,3,IF(X53+Z53=2,2,IF(Z53=1,1,0))) -> 3 | AB53: =Q53+T53 -> 12 | AC53: =R53+U53+X53 -> 2 | AE53: ='Players - Men'!E18 -> Georges Meekers | AF53: =Y53+J75+J63+Y51+J71 -> 5 | AG53: =AA53+L75+L63+AA51+L71 -> 3 | AH53: =AB53+M75+M63+AB51+M71 -> 29 | AI53: =AC53+N75+N63+AC51+N71 -> 2
A54: vs. | P54: vs.
A55: =AE55 -> Julian Bilocca | B55: 2 | C55: =IF(B55>B53,1,0) -> 0 | E55: 0 | F55: =IF(E55>E53,1,0) -> 0 | I55: =IF(H55>H53,1,0) -> 0 | J55: =IF(B55="",0,1) -> 1 | K55: =IF(C55+F55=2,3,IF(C55+F55=1,1,0)) -> 0 | L55: =IF(K55=3,3,IF(I55+K55=2,2,IF(K55=1,1,0))) -> 0 | M55: =B55+E55 -> 2 | N55: =C55+F55+I55 -> 0 | P55: =AE55 -> Julian Bilocca | Q55: 2 | R55: =IF(Q55>Q53,1,0) -> 0 | T55: 2 | U55: =IF(T55>T53,1,0) -> 0 | X55: =IF(W55>W53,1,0) -> 0 | Y55: =IF(Q55="",0,1) -> 1 | Z55: =IF(R55+U55=2,3,IF(R55+U55=1,1,0)) -> 0 | AA55: =IF(Z55=3,3,IF(X55+Z55=2,2,IF(Z55=1,1,0))) -> 0 | AB55: =Q55+T55 -> 4 | AC55: =R55+U55+X55 -> 0 | AE55: ='Players - Men'!E19 -> Julian Bilocca | AF55: =Y55+Y63+Y71+J55+J67 -> 5 | AG55: =AA55+AA63+AA71+L55+L67 -> 0 | AH55: =AB55+AB63+AB71+M55+M67 -> 15 | AI55: =AC55+AC63+AC71+N55+N67 -> 0
...

Sheet Men Div 3
A1: VLTC Singles Tournament 2025
A5: Men Division 3 - Group A
A7: Players | B7: Set Scores | H7: Tie | P7: Players | Q7: Set Scores | W7: Tie | AE7: Player | AF7: Matches Played | AG7: Points Overall | AH7: Games Won | AI7: Sets Won
B8: Score | C8: Set 1 Work | E8: Score | F8: Set 2 Work | H8: Score | I8: Tie Work | J8: Game Played | K8: Sets Points Work | L8: Sets & Tie Points Work | M8: Games Wins Work | N8: Sets Wins Work | Q8: Score | R8: Set 1 Work | T8: Score | U8: Set 2 Work | W8: Score | X8: Tie Work | Y8: Game Played | Z8: Sets Points Work | AA8: Sets & Tie Points Work | AB8: Games Wins Work | AC8: Sets Wins Work | AJ8: Winner Working | AK8: Runner Up Working | AL8: Total Games Work | AM8: Winner | AN8: Runner Up
A9: =AE9 -> Etienne Formosa Carabez | B9: 6 | C9: =IF(B9>B11,1,0) -> 1 | E9: 6 | F9: =IF(E9>E11,1,0) -> 1 | I9: =IF(H9>H11,1,0) -> 0 | J9: =IF(B9="",0,1) -> 1 | K9: =IF(C9+F9=2,3,IF(C9+F9=1,1,0)) -> 3 | L9: =IF(K9=3,3,IF(I9+K9=2,2,IF(K9=1,1,0))) -> 3 | M9: =B9+E9 -> 12 | N9: =C9+F9+I9 -> 2 | P9: =AE9 -> Etienne Formosa Carabez | Q9: 6 | R9: =IF(Q9>Q11,1,0) -> 1 | T9: 6 | U9: =IF(T9>T11,1,0) -> 1 | X9: =IF(W9>W11,1,0) -> 0 | Y9: =IF(Q9="",0,1) -> 1 | Z9: =IF(R9+U9=2,3,IF(R9+U9=1,1,0)) -> 3 | AA9: =IF(Z9=3,3,IF(X9+Z9=2,2,IF(Z9=1,1,0))) -> 3 | AB9: =Q9+T9 -> 12 | AC9: =R9+U9+X9 -> 2 | AE9: ='Players - Men'!B22 -> Etienne Formosa Carabez | AF9: =J9+Y9+J13+Y13+J17 -> 5 | AG9: =L9+AA9+L13+AA13+L17 -> 13 | AH9: =M9+AB9+M13+AB13+M17 -> 57 | AI9: =N9+AC9+N13+AC13+N17 -> 9 | AJ9: =MAX(AG9:AG19) -> 13 | AK9: =LARGE(AG9:AG19, 2) -> 10 | AL9: =SUM(AF9:AF19) -> 30 | AM9: =IF(AG9=$AJ$9,AE9,IF(AG11=$AJ$9,AE11,IF(AG13=$AJ$9,AE13,IF(AG15=$AJ$9,AE15,IF(AG17=$AJ$9,AE17,""))))) -> Etienne Formosa Carabez | AN9: =IF(AG9=$AK$9,AE9,IF(AG11=$AK$9,AE11,IF(AG13=$AK$9,AE13,IF(AG15=$AK$9,AE15,IF(AG17=$AK$9,AE17,"")))))
A10: vs. | P10: vs.
A11: =AE11 -> David Camilleri | B11: 3 | C11: =IF(B11>B9,1,0) -> 0 | E11: 3 | F11: =IF(E11>E9,1,0) -> 0 | I11: =IF(H11>H9,1,0) -> 0 | J11: =IF(B11="",0,1) -> 1 | K11: =IF(C11+F11=2,3,IF(C11+F11=1,1,0)) -> 0 | L11: =IF(K11=3,3,IF(I11+K11=2,2,IF(K11=1,1,0))) -> 0 | M11: =B11+E11 -> 6 | N11: =C11+F11+I11 -> 0 | P11: =AE13 -> Cory Greenland | Q11: 3 | R11: =IF(Q11>Q9,1,0) -> 0 | T11: 2 | U11: =IF(T11>T9,1,0) -> 0 | X11: =IF(W11>W9,1,0) -> 0 | Y11: =IF(Q11="",0,1) -> 1 | Z11: =IF(R11+U11=2,3,IF(R11+U11=1,1,0)) -> 0 | AA11: =IF(Z11=3,3,IF(X11+Z11=2,2,IF(Z11=1,1,0))) -> 0 | AB11: =Q11+T11 -> 5 | AC11: =R11+U11+X11 -> 0 | AE11: ='Players - Men'!B23 -> David Camilleri | AF11: =J11+Y25+J25+Y21+J21 -> 5 | AG11: =L11+AA25+L25+AA21+L21 -> 5 | AH11: =M11+AB25+M25+AB21+M21 -> 33 | AI11: =N11+AC25+N25+AC21+N21 -> 5
A13: =AE9 -> Etienne Formosa Carabez | B13: 6 | C13: =IF(B13>B15,1,0) -> 1 | E13: 6 | F13: =IF(E13>E15,1,0) -> 1 | I13: =IF(H13>H15,1,0) -> 0 | J13: =IF(B13="",0,1) -> 1 | K13: =IF(C13+F13=2,3,IF(C13+F13=1,1,0)) -> 3 | L13: =IF(K13=3,3,IF(I13+K13=2,2,IF(K13=1,1,0))) -> 3 | M13: =B13+E13 -> 12 | N13: =C13+F13+I13 -> 2 | P13: =AE9 -> Etienne Formosa Carabez | Q13: 7 | R13: =IF(Q13>Q15,1,0) -> 1 | T13: 2 | U13: =IF(T13>T15,1,0) -> 0 | W13: 6 | X13: =IF(W13>W15,1,0) -> 0 | Y13: =IF(Q13="",0,1) -> 1 | Z13: =IF(R13+U13=2,3,IF(R13+U13=1,1,0)) -> 1 | AA13: =IF(Z13=3,3,IF(X13+Z13=2,2,IF(Z13=1,1,0))) -> 1 | AB13: =Q13+T13 -> 9 | AC13: =R13+U13+X13 -> 1 | AE13: ='Players - Men'!B24 -> Cory Greenland | AF13: =Y29+Y11+Y33+J33+J23 -> 5 | AG13: =AA29+AA11+AA33+L33+L23 -> 8 | AH13: =AB29+AB11+AB33+M33+M23 -> 43 | AI13: =AC29+AC11+AC33+N33+N23 -> 6
A14: vs. | P14: vs.
A15: =AE15 -> Jason Lee Evans | B15: 0 | C15: =IF(B15>B13,1,0) -> 0 | E15: 1 | F15: =IF(E15>E13,1,0) -> 0 | I15: =IF(H15>H13,1,0) -> 0 | J15: =IF(B15="",0,1) -> 1 | K15: =IF(C15+F15=2,3,IF(C15+F15=1,1,0)) -> 0 | L15: =IF(K15=3,3,IF(I15+K15=2,2,IF(K15=1,1,0))) -> 0 | M15: =B15+E15 -> 1 | N15: =C15+F15+I15 -> 0 | P15: =AE17 -> Adrian Duca | Q15: 5 | R15: =IF(Q15>Q13,1,0) -> 0 | T15: 6 | U15: =IF(T15>T13,1,0) -> 1 | W15: 10 | X15: =IF(W15>W13,1,0) -> 1 | Y15: =IF(Q15="",0,1) -> 1 | Z15: =IF(R15+U15=2,3,IF(R15+U15=1,1,0)) -> 1 | AA15: =IF(Z15=3,3,IF(X15+Z15=2,2,IF(Z15=1,1,0))) -> 2 | AB15: =Q15+T15 -> 11 | AC15: =R15+U15+X15 -> 2 | AE15: ='Players - Men'!B25 -> Jason Lee Evans | AF15: =Y31+J37+J15+Y23+J29 -> 5 | AG15: =AA31+L37+L15+AA23+L29 -> 1 | AH15: =AB31+M37+M15+AB23+M29 -> 25 | AI15: =AC31+N37+N15+AC23+N29 -> 1
A17: =AE9 -> Etienne Formosa Carabez | B17: 6 | C17: =IF(B17>B19,1,0) -> 1 | E17: 6 | F17: =IF(E17>E19,1,0) -> 1 | I17: =IF(H17>H19,1,0) -> 0 | J17: =IF(B17="",0,1) -> 1 | K17: =IF(C17+F17=2,3,IF(C17+F17=1,1,0)) -> 3 | L17: =IF(K17=3,3,IF(I17+K17=2,2,IF(K17=1,1,0))) -> 3 | M17: =B17+E17 -> 12 | N17: =C17+F17+I17 -> 2 | P17: =AE17 -> Adrian Duca | Q17: 2 | R17: =IF(Q17>Q19,1,0) -> 0 | T17: 6 | U17: =IF(T17>T19,1,0) -> 0 | X17: =IF(W17>W19,1,0) -> 0 | Y17: =IF(Q17="",0,1) -> 1 | Z17: =IF(R17+U17=2,3,IF(R17+U17=1,1,0)) -> 0 | AA17: =IF(Z17=3,3,IF(X17+Z17=2,2,IF(Z17=1,1,0))) -> 0 | AB17: =Q17+T17 -> 8 | AC17: =R17+U17+X17 -> 0 | AE17: ='Players - Men'!B26 -> Adrian Duca | AF17: =Y17+J39+J27+Y15+J35 -> 5 | AG17: =AA17+L39+L27+AA15+L35 -> 8 | AH17: =AB17+M39+M27+AB15+M35 -> 50 | AI17: =AC17+N39+N27+AC15+N35 -> 6
A18: vs. | P18: vs.
A19: =AE19 -> Juan Sammut | B19: 2 | C19: =IF(B19>B17,1,0) -> 0 | E19: 2 | F19: =IF(E19>E17,1,0) -> 0 | I19: =IF(H19>H17,1,0) -> 0 | J19: =IF(B19="",0,1) -> 1 | K19: =IF(C19+F19=2,3,IF(C19+F19=1,1,0)) -> 0 | L19: =IF(K19=3,3,IF(I19+K19=2,2,IF(K19=1,1,0))) -> 0 | M19: =B19+E19 -> 4 | N19: =C19+F19+I19 -> 0 | P19: =AE19 -> Juan Sammut | Q19: 6 | R19: =IF(Q19>Q17,1,0) -> 1 | T19: 7 | U19: =IF(T19>T17,1,0) -> 1 | X19: =IF(W19>W17,1,0) -> 0 | Y19: =IF(Q19="",0,1) -> 1 | Z19: =IF(R19+U19=2,3,IF(R19+U19=1,1,0)) -> 3 | AA19: =IF(Z19=3,3,IF(X19+Z19=2,2,IF(Z19=1,1,0))) -> 3 | AB19: =Q19+T19 -> 13 | AC19: =R19+U19+X19 -> 2 | AE19: ='Players - Men'!B27 -> Juan Sammut | AF19: =Y19+Y27+Y35+J19+J31 -> 5 | AG19: =AA19+AA27+AA35+L19+L31 -> 10 | AH19: =AB19+AB27+AB35+M19+M31 -> 49 | AI19: =AC19+AC27+AC35+N19+N31 -> 7
A21: =AE11 -> David Camilleri | B21: 3 | C21: =IF(B21>B23,1,0) -> 0 | E21: 6 | F21: =IF(E21>E23,1,0) -> 1 | H21: 4 | I21: =IF(H21>H23,1,0) -> 0 | J21: =IF(B21="",0,1) -> 1 | K21: =IF(C21+F21=2,3,IF(C21+F21=1,1,0)) -> 1 | L21: =IF(K21=3,3,IF(I21+K21=2,2,IF(K21=1,1,0))) -> 1 | M21: =B21+E21 -> 9 | N21: =C21+F21+I21 -> 1 | P21: =AE11 -> David Camilleri | Q21: 2 | R21: =IF(Q21>Q23,1,0) -> 0 | T21: 6 | U21: =IF(T21>T23,1,0) -> 1 | W21: 10 | X21: =IF(W21>W23,1,0) -> 1 | Y21: =IF(Q21="",0,1) -> 1 | Z21: =IF(R21+U21=2,3,IF(R21+U21=1,1,0)) -> 1 | AA21: =IF(Z21=3,3,IF(X21+Z21=2,2,IF(Z21=1,1,0))) -> 2 | AB21: =Q21+T21 -> 8 | AC21: =R21+U21+X21 -> 2 | AE21: Division Winner
A22: vs. | P22: vs. | AE22: Etienne Formosa Carabez
A23: =AE13 -> Cory Greenland | B23: 6 | C23: =IF(B23>B21,1,0) -> 1 | E23: 2 | F23: =IF(E23>E21,1,0) -> 0 | H23: 10 | I23: =IF(H23>H21,1,0) -> 1 | J23: =IF(B23="",0,1) -> 1 | K23: =IF(C23+F23=2,3,IF(C23+F23=1,1,0)) -> 1 | L23: =IF(K23=3,3,IF(I23+K23=2,2,IF(K23=1,1,0))) -> 2 | M23: =B23+E23 -> 8 | N23: =C23+F23+I23 -> 2 | P23: =AE15 -> Jason Lee Evans | Q23: 6 | R23: =IF(Q23>Q21,1,0) -> 1 | T23: 2 | U23: =IF(T23>T21,1,0) -> 0 | W23: 8 | X23: =IF(W23>W21,1,0) -> 0 | Y23: =IF(Q23="",0,1) -> 1 | Z23: =IF(R23+U23=2,3,IF(R23+U23=1,1,0)) -> 1 | AA23: =IF(Z23=3,3,IF(X23+Z23=2,2,IF(Z23=1,1,0))) -> 1 | AB23: =Q23+T23 -> 8 | AC23: =R23+U23+X23 -> 1
A25: =AE11 -> David Camilleri | B25: 0 | C25: =IF(B25>B27,1,0) -> 0 | E25: 1 | F25: =IF(E25>E27,1,0) -> 0 | I25: =IF(H25>H27,1,0) -> 0 | J25: =IF(B25="",0,1) -> 1 | K25: =IF(C25+F25=2,3,IF(C25+F25=1,1,0)) -> 0 | L25: =IF(K25=3,3,IF(I25+K25=2,2,IF(K25=1,1,0))) -> 0 | M25: =B25+E25 -> 1 | N25: =C25+F25+I25 -> 0 | P25: =AE11 -> David Camilleri | Q25: 3 | R25: =IF(Q25>Q27,1,0) -> 0 | T25: 6 | U25: =IF(T25>T27,1,0) -> 1 | W25: 10 | X25: =IF(W25>W27,1,0) -> 1 | Y25: =IF(Q25="",0,1) -> 1 | Z25: =IF(R25+U25=2,3,IF(R25+U25=1,1,0)) -> 1 | AA25: =IF(Z25=3,3,IF(X25+Z25=2,2,IF(Z25=1,1,0))) -> 2 | AB25: =Q25+T25 -> 9 | AC25: =R25+U25+X25 -> 2
A26: vs. | P26: vs.
A27: =AE17 -> Adrian Duca | B27: 6 | C27: =IF(B27>B25,1,0) -> 1 | E27: 6 | F27: =IF(E27>E25,1,0) -> 1 | I27: =IF(H27>H25,1,0) -> 0 | J27: =IF(B27="",0,1) -> 1 | K27: =IF(C27+F27=2,3,IF(C27+F27=1,1,0)) -> 3 | L27: =IF(K27=3,3,IF(I27+K27=2,2,IF(K27=1,1,0))) -> 3 | M27: =B27+E27 -> 12 | N27: =C27+F27+I27 -> 2 | P27: =AE19 -> Juan Sammut | Q27: 6 | R27: =IF(Q27>Q25,1,0) -> 1 | T27: 1 | U27: =IF(T27>T25,1,0) -> 0 | W27: 8 | X27: =IF(W27>W25,1,0) -> 0 | Y27: =IF(Q27="",0,1) -> 1 | Z27: =IF(R27+U27=2,3,IF(R27+U27=1,1,0)) -> 1 | AA27: =IF(Z27=3,3,IF(X27+Z27=2,2,IF(Z27=1,1,0))) -> 1 | AB27: =Q27+T27 -> 7 | AC27: =R27+U27+X27 -> 1
A29: =AE15 -> Jason Lee Evans | B29: 4 | C29: =IF(B29>B31,1,0) -> 0 | E29: 5 | F29: =IF(E29>E31,1,0) -> 0 | I29: =IF(H29>H31,1,0) -> 0 | J29: =IF(B29="",0,1) -> 1 | K29: =IF(C29+F29=2,3,IF(C29+F29=1,1,0)) -> 0 | L29: =IF(K29=3,3,IF(I29+K29=2,2,IF(K29=1,1,0))) -> 0 | M29: =B29+E29 -> 9 | N29: =C29+F29+I29 -> 0 | P29: =AE13 -> Cory Greenland | Q29: 6 | R29: =IF(Q29>Q31,1,0) -> 1 | T29: 6 | U29: =IF(T29>T31,1,0) -> 1 | X29: =IF(W29>W31,1,0) -> 0 | Y29: =IF(Q29="",0,1) -> 1 | Z29: =IF(R29+U29=2,3,IF(R29+U29=1,1,0)) -> 3 | AA29: =IF(Z29=3,3,IF(X29+Z29=2,2,IF(Z29=1,1,0))) -> 3 | AB29: =Q29+T29 -> 12 | AC29: =R29+U29+X29 -> 2
A30: vs. | P30: vs.
A31: =AE19 -> Juan Sammut | B31: 6 | C31: =IF(B31>B29,1,0) -> 1 | E31: 7 | F31: =IF(E31>E29,1,0) -> 1 | I31: =IF(H31>H29,1,0) -> 0 | J31: =IF(B31="",0,1) -> 1 | K31: =IF(C31+F31=2,3,IF(C31+F31=1,1,0)) -> 3 | L31: =IF(K31=3,3,IF(I31+K31=2,2,IF(K31=1,1,0))) -> 3 | M31: =B31+E31 -> 13 | N31: =C31+F31+I31 -> 2 | P31: =AE15 -> Jason Lee Evans | Q31: 0 | R31: =IF(Q31>Q29,1,0) -> 0 | T31: 1 | U31: =IF(T31>T29,1,0) -> 0 | X31: =IF(W31>W29,1,0) -> 0 | Y31: =IF(Q31="",0,1) -> 1 | Z31: =IF(R31+U31=2,3,IF(R31+U31=1,1,0)) -> 0 | AA31: =IF(Z31=3,3,IF(X31+Z31=2,2,IF(Z31=1,1,0))) -> 0 | AB31: =Q31+T31 -> 1 | AC31: =R31+U31+X31 -> 0
A33: =AE13 -> Cory Greenland | B33: 7 | C33: =IF(B33>B35,1,0) -> 1 | E33: 6 | F33: =IF(E33>E35,1,0) -> 1 | I33: =IF(H33>H35,1,0) -> 0 | J33: =IF(B33="",0,1) -> 1 | K33: =IF(C33+F33=2,3,IF(C33+F33=1,1,0)) -> 3 | L33: =IF(K33=3,3,IF(I33+K33=2,2,IF(K33=1,1,0))) -> 3 | M33: =B33+E33 -> 13 | N33: =C33+F33+I33 -> 2 | P33: =AE13 -> Cory Greenland | Q33: 2 | R33: =IF(Q33>Q35,1,0) -> 0 | T33: 3 | U33: =IF(T33>T35,1,0) -> 0 | X33: =IF(W33>W35,1,0) -> 0 | Y33: =IF(Q33="",0,1) -> 1 | Z33: =IF(R33+U33=2,3,IF(R33+U33=1,1,0)) -> 0 | AA33: =IF(Z33=3,3,IF(X33+Z33=2,2,IF(Z33=1,1,0))) -> 0 | AB33: =Q33+T33 -> 5 | AC33: =R33+U33+X33 -> 0
A34: vs. | P34: vs.
A35: =AE17 -> Adrian Duca | B35: 6 | C35: =IF(B35>B33,1,0) -> 0 | E35: 1 | F35: =IF(E35>E33,1,0) -> 0 | I35: =IF(H35>H33,1,0) -> 0 | J35: =IF(B35="",0,1) -> 1 | K35: =IF(C35+F35=2,3,IF(C35+F35=1,1,0)) -> 0 | L35: =IF(K35=3,3,IF(I35+K35=2,2,IF(K35=1,1,0))) -> 0 | M35: =B35+E35 -> 7 | N35: =C35+F35+I35 -> 0 | P35: =AE19 -> Juan Sammut | Q35: 6 | R35: =IF(Q35>Q33,1,0) -> 1 | T35: 6 | U35: =IF(T35>T33,1,0) -> 1 | X35: =IF(W35>W33,1,0) -> 0 | Y35: =IF(Q35="",0,1) -> 1 | Z35: =IF(R35+U35=2,3,IF(R35+U35=1,1,0)) -> 3 | AA35: =IF(Z35=3,3,IF(X35+Z35=2,2,IF(Z35=1,1,0))) -> 3 | AB35: =Q35+T35 -> 12 | AC35: =R35+U35+X35 -> 2
A37: =AE15 -> Jason Lee Evans | B37: 3 | C37: =IF(B37>B39,1,0) -> 0 | E37: 3 | F37: =IF(E37>E39,1,0) -> 0 | I37: =IF(H37>H39,1,0) -> 0 | J37: =IF(B37="",0,1) -> 1 | K37: =IF(C37+F37=2,3,IF(C37+F37=1,1,0)) -> 0 | L37: =IF(K37=3,3,IF(I37+K37=2,2,IF(K37=1,1,0))) -> 0 | M37: =B37+E37 -> 6 | N37: =C37+F37+I37 -> 0
A38: vs.
A39: =AE17 -> Adrian Duca | B39: 6 | C39: =IF(B39>B37,1,0) -> 1 | E39: 6 | F39: =IF(E39>E37,1,0) -> 1 | I39: =IF(H39>H37,1,0) -> 0 | J39: =IF(B39="",0,1) -> 1 | K39: =IF(C39+F39=2,3,IF(C39+F39=1,1,0)) -> 3 | L39: =IF(K39=3,3,IF(I39+K39=2,2,IF(K39=1,1,0))) -> 3 | M39: =B39+E39 -> 12 | N39: =C39+F39+I39 -> 2
A42: Men Division 3 - Group B
A44: Players | B44: Set Scores | H44: Tie | P44: Players | Q44: Set Scores | W44: Tie | AE44: Player | AF44: Matches Played | AG44: Points Overall | AH44: Games Won | AI44: Sets Won
B45: Score | C45: Set 1 Work | E45: Score | F45: Set 2 Work | H45: Score | I45: Tie Work | J45: Game Played | K45: Sets Points Work | L45: Sets & Tie Points Work | M45: Games Wins Work | N45: Sets Wins Work | Q45: Score | R45: Set 1 Work | T45: Score | U45: Set 2 Work | W45: Score | X45: Tie Work | Y45: Game Played | Z45: Sets Points Work | AA45: Sets & Tie Points Work | AB45: Games Wins Work | AC45: Sets Wins Work
A46: =AE46 -> Sam Zammit | B46: 3 | C46: =IF(B46>B48,1,0) -> 0 | E46: 7 | F46: =IF(E46>E48,1,0) -> 1 | H46: 4 | I46: =IF(H46>H48,1,0) -> 0 | J46: =IF(B46="",0,1) -> 1 | K46: =IF(C46+F46=2,3,IF(C46+F46=1,1,0)) -> 1 | L46: =IF(K46=3,3,IF(I46+K46=2,2,IF(K46=1,1,0))) -> 1 | M46: =B46+E46 -> 10 | N46: =C46+F46+I46 -> 1 | P46: =AE46 -> Sam Zammit | Q46: 6 | R46: =IF(Q46>Q48,1,0) -> 1 | T46: 6 | U46: =IF(T46>T48,1,0) -> 1 | X46: =IF(W46>W48,1,0) -> 0 | Y46: =IF(Q46="",0,1) -> 1 | Z46: =IF(R46+U46=2,3,IF(R46+U46=1,1,0)) -> 3 | AA46: =IF(Z46=3,3,IF(X46+Z46=2,2,IF(Z46=1,1,0))) -> 3 | AB46: =Q46+T46 -> 12 | AC46: =R46+U46+X46 -> 2 | AE46: ='Players - Men'!E22 -> Sam Zammit | AF46: =J46+Y46+J50+Y50+J54 -> 5 | AG46: =L46+AA46+L50+AA50+L54 -> 13 | AH46: =M46+AB46+M50+AB50+M54 -> 59 | AI46: =N46+AC46+N50+AC50+N54 -> 9
A47: vs. | P47: vs.
A48: =AE48 -> Steve Gambin | B48: 6 | C48: =IF(B48>B46,1,0) -> 1 | E48: 6 | F48: =IF(E48>E46,1,0) -> 0 | H48: 10 | I48: =IF(H48>H46,1,0) -> 1 | J48: =IF(B48="",0,1) -> 1 | K48: =IF(C48+F48=2,3,IF(C48+F48=1,1,0)) -> 1 | L48: =IF(K48=3,3,IF(I48+K48=2,2,IF(K48=1,1,0))) -> 2 | M48: =B48+E48 -> 12 | N48: =C48+F48+I48 -> 2 | P48: =AE50 -> Sean Cachia | Q48: 3 | R48: =IF(Q48>Q46,1,0) -> 0 | T48: 3 | U48: =IF(T48>T46,1,0) -> 0 | X48: =IF(W48>W46,1,0) -> 0 | Y48: =IF(Q48="",0,1) -> 1 | Z48: =IF(R48+U48=2,3,IF(R48+U48=1,1,0)) -> 0 | AA48: =IF(Z48=3,3,IF(X48+Z48=2,2,IF(Z48=1,1,0))) -> 0 | AB48: =Q48+T48 -> 6 | AC48: =R48+U48+X48 -> 0 | AE48: ='Players - Men'!E23 -> Steve Gambin | AF48: =J48+Y62+J62+Y58+J58 -> 5 | AG48: =L48+AA62+L62+AA58+L58 -> 10 | AH48: =M48+AB62+M62+AB58+M58 -> 50 | AI48: =N48+AC62+N62+AC58+N58 -> 10
A50: =AE46 -> Sam Zammit | B50: 6 | C50: =IF(B50>B52,1,0) -> 1 | E50: 6 | F50: =IF(E50>E52,1,0) -> 1 | I50: =IF(H50>H52,1,0) -> 0 | J50: =IF(B50="",0,1) -> 1 | K50: =IF(C50+F50=2,3,IF(C50+F50=1,1,0)) -> 3 | L50: =IF(K50=3,3,IF(I50+K50=2,2,IF(K50=1,1,0))) -> 3 | M50: =B50+E50 -> 12 | N50: =C50+F50+I50 -> 2 | P50: =AE46 -> Sam Zammit | Q50: 6 | R50: =IF(Q50>Q52,1,0) -> 1 | T50: 6 | U50: =IF(T50>T52,1,0) -> 1 | X50: =IF(W50>W52,1,0) -> 0 | Y50: =IF(Q50="",0,1) -> 1 | Z50: =IF(R50+U50=2,3,IF(R50+U50=1,1,0)) -> 3 | AA50: =IF(Z50=3,3,IF(X50+Z50=2,2,IF(Z50=1,1,0))) -> 3 | AB50: =Q50+T50 -> 12 | AC50: =R50+U50+X50 -> 2 | AE50: ='Players - Men'!E24 -> Sean Cachia | AF50: =Y66+Y48+Y70+J70+J60 -> 5 | AG50: =AA66+AA48+AA70+L70+L60 -> 7 | AH50: =AB66+AB48+AB70+M70+M60 -> 45 | AI50: =AC66+AC48+AC70+N70+N60 -> 5
A51: vs. | P51: vs.
A52: =AE52 -> Sebastian Attard | B52: 0 | C52: =IF(B52>B50,1,0) -> 0 | E52: 0 | F52: =IF(E52>E50,1,0) -> 0 | I52: =IF(H52>H50,1,0) -> 0 | J52: =IF(B52="",0,1) -> 1 | K52: =IF(C52+F52=2,3,IF(C52+F52=1,1,0)) -> 0 | L52: =IF(K52=3,3,IF(I52+K52=2,2,IF(K52=1,1,0))) -> 0 | M52: =B52+E52 -> 0 | N52: =C52+F52+I52 -> 0 | P52: =AE54 -> Matthew Micallef | Q52: 4 | R52: =IF(Q52>Q50,1,0) -> 0 | T52: 2 | U52: =IF(T52>T50,1,0) -> 0 | X52: =IF(W52>W50,1,0) -> 0 | Y52: =IF(Q52="",0,1) -> 1 | Z52: =IF(R52+U52=2,3,IF(R52+U52=1,1,0)) -> 0 | AA52: =IF(Z52=3,3,IF(X52+Z52=2,2,IF(Z52=1,1,0))) -> 0 | AB52: =Q52+T52 -> 6 | AC52: =R52+U52+X52 -> 0 | AE52: ='Players - Men'!E25 -> Sebastian Attard | AF52: =Y68+J74+J52+Y60+J66 -> 5 | AG52: =AA68+L74+L52+AA60+L66 -> 7 | AH52: =AB68+M74+M52+AB60+M66 -> 41 | AI52: =AC68+N74+N52+AC60+N66 -> 5
A54: =AE46 -> Sam Zammit | B54: 6 | C54: =IF(B54>B56,1,0) -> 1 | E54: 7 | F54: =IF(E54>E56,1,0) -> 1 | I54: =IF(H54>H56,1,0) -> 0 | J54: =IF(B54="",0,1) -> 1 | K54: =IF(C54+F54=2,3,IF(C54+F54=1,1,0)) -> 3 | L54: =IF(K54=3,3,IF(I54+K54=2,2,IF(K54=1,1,0))) -> 3 | M54: =B54+E54 -> 13 | N54: =C54+F54+I54 -> 2 | P54: =AE54 -> Matthew Micallef | Q54: 4 | R54: =IF(Q54>Q56,1,0) -> 0 | T54: 6 | U54: =IF(T54>T56,1,0) -> 1 | W54: 5 | X54: =IF(W54>W56,1,0) -> 0 | Y54: =IF(Q54="",0,1) -> 1 | Z54: =IF(R54+U54=2,3,IF(R54+U54=1,1,0)) -> 1 | AA54: =IF(Z54=3,3,IF(X54+Z54=2,2,IF(Z54=1,1,0))) -> 1 | AB54: =Q54+T54 -> 10 | AC54: =R54+U54+X54 -> 1 | AE54: ='Players - Men'!E26 -> Matthew Micallef | AF54: =Y54+J76+J64+Y52+J72 -> 5 | AG54: =AA54+L76+L64+AA52+L72 -> 5 | AH54: =AB54+M76+M64+AB52+M72 -> 47 | AI54: =AC54+N76+N64+AC52+N72 -> 4
A55: vs. | P55: vs.
A56: =AE56 -> Simone Re | B56: 4 | C56: =IF(B56>B54,1,0) -> 0 | E56: 6 | F56: =IF(E56>E54,1,0) -> 0 | I56: =IF(H56>H54,1,0) -> 0 | J56: =IF(B56="",0,1) -> 1 | K56: =IF(C56+F56=2,3,IF(C56+F56=1,1,0)) -> 0 | L56: =IF(K56=3,3,IF(I56+K56=2,2,IF(K56=1,1,0))) -> 0 | M56: =B56+E56 -> 10 | N56: =C56+F56+I56 -> 0 | P56: =AE56 -> Simone Re | Q56: 6 | R56: =IF(Q56>Q54,1,0) -> 1 | T56: 2 | U56: =IF(T56>T54,1,0) -> 0 | W56: 10 | X56: =IF(W56>W54,1,0) -> 1 | Y56: =IF(Q56="",0,1) -> 1 | Z56: =IF(R56+U56=2,3,IF(R56+U56=1,1,0)) -> 1 | AA56: =IF(Z56=3,3,IF(X56+Z56=2,2,IF(Z56=1,1,0))) -> 2 | AB56: =Q56+T56 -> 8 | AC56: =R56+U56+X56 -> 2 | AE56: ='Players - Men'!E27 -> Simone Re | AF56: =Y56+Y64+Y72+J56+J68 -> 5 | AG56: =AA56+AA64+AA72+L56+L68 -> 3 | AH56: =AB56+AB64+AB72+M56+M68 -> 41 | AI56: =AC56+AC64+AC72+N56+N68 -> 3
...

Sheet Men Div 4
A1: VLTC Singles Tournament 2025
A5: Men Division 4 - Group A
A7: Players | B7: Set Scores | H7: Tie | P7: Players | Q7: Set Scores | W7: Tie | AE7: Player | AF7: Matches Played | AG7: Points Overall | AH7: Games Won | AI7: Sets Won
B8: Score | C8: Set 1 Work | E8: Score | F8: Set 2 Work | H8: Score | I8: Tie Work | J8: Game Played | K8: Sets Points Work | L8: Sets & Tie Points Work | M8: Games Wins Work | N8: Sets Wins Work | Q8: Score | R8: Set 1 Work | T8: Score | U8: Set 2 Work | W8: Score | X8: Tie Work | Y8: Game Played | Z8: Sets Points Work | AA8: Sets & Tie Points Work | AB8: Games Wins Work | AC8: Sets Wins Work | AJ8: Winner Working | AK8: Runner Up Working | AL8: Total Games Work | AM8: Winner | AN8: Runner Up
A9: =AE9 -> Sammy Ben Tamer | B9: 1 | C9: =IF(B9>B11,1,0) -> 0 | E9: 2 | F9: =IF(E9>E11,1,0) -> 0 | I9: =IF(H9>H11,1,0) -> 0 | J9: =IF(B9="",0,1) -> 1 | K9: =IF(C9+F9=2,3,IF(C9+F9=1,1,0)) -> 0 | L9: =IF(K9=3,3,IF(I9+K9=2,2,IF(K9=1,1,0))) -> 0 | M9: =B9+E9 -> 3 | N9: =C9+F9+I9 -> 0 | P9: =AE9 -> Sammy Ben Tamer | Q9: 4 | R9: =IF(Q9>Q11,1,0) -> 0 | T9: 1 | U9: =IF(T9>T11,1,0) -> 0 | X9: =IF(W9>W11,1,0) -> 0 | Y9: =IF(Q9="",0,1) -> 1 | Z9: =IF(R9+U9=2,3,IF(R9+U9=1,1,0)) -> 0 | AA9: =IF(Z9=3,3,IF(X9+Z9=2,2,IF(Z9=1,1,0))) -> 0 | AB9: =Q9+T9 -> 5 | AC9: =R9+U9+X9 -> 0 | AE9: ='Players - Men'!B30 -> Sammy Ben Tamer | AF9: =J9+Y9+J13+Y13+J17 -> 5 | AG9: =L9+AA9+L13+AA13+L17 -> 2 | AH9: =M9+AB9+M13+AB13+M17 -> 30 | AI9: =N9+AC9+N13+AC13+N17 -> 2 | AJ9: =MAX(AG9:AG19) -> 15 | AK9: =LARGE(AG9:AG19, 2) -> 11 | AL9: =SUM(AF9:AF19) -> 30 | AM9: =IF(AG9=$AJ$9,AE9,IF(AG11=$AJ$9,AE11,IF(AG13=$AJ$9,AE13,IF(AG15=$AJ$9,AE15,IF(AG17=$AJ$9,AE17,""))))) -> Chris Vella | AN9: =IF(AG9=$AK$9,AE9,IF(AG11=$AK$9,AE11,IF(AG13=$AK$9,AE13,IF(AG15=$AK$9,AE15,IF(AG17=$AK$9,AE17,""))))) -> Liam Vella
A10: vs. | P10: vs.
A11: =AE11 -> Kevin Sciberras | B11: 6 | C11: =IF(B11>B9,1,0) -> 1 | E11: 6 | F11: =IF(E11>E9,1,0) -> 1 | I11: =IF(H11>H9,1,0) -> 0 | J11: =IF(B11="",0,1) -> 1 | K11: =IF(C11+F11=2,3,IF(C11+F11=1,1,0)) -> 3 | L11: =IF(K11=3,3,IF(I11+K11=2,2,IF(K11=1,1,0))) -> 3 | M11: =B11+E11 -> 12 | N11: =C11+F11+I11 -> 2 | P11: =AE13 -> Liam Vella | Q11: 6 | R11: =IF(Q11>Q9,1,0) -> 1 | T11: 6 | U11: =IF(T11>T9,1,0) -> 1 | X11: =IF(W11>W9,1,0) -> 0 | Y11: =IF(Q11="",0,1) -> 1 | Z11: =IF(R11+U11=2,3,IF(R11+U11=1,1,0)) -> 3 | AA11: =IF(Z11=3,3,IF(X11+Z11=2,2,IF(Z11=1,1,0))) -> 3 | AB11: =Q11+T11 -> 12 | AC11: =R11+U11+X11 -> 2 | AE11: ='Players - Men'!B31 -> Kevin Sciberras | AF11: =J11+Y25+J25+Y21+J21 -> 5 | AG11: =L11+AA25+L25+AA21+L21 -> 6 | AH11: =M11+AB25+M25+AB21+M21 -> 41 | AI11: =N11+AC25+N25+AC21+N21 -> 4
A13: =AE9 -> Sammy Ben Tamer | B13: 0 | C13: =IF(B13>B15,1,0) -> 0 | E13: 4 | F13: =IF(E13>E15,1,0) -> 0 | I13: =IF(H13>H15,1,0) -> 0 | J13: =IF(B13="",0,1) -> 1 | K13: =IF(C13+F13=2,3,IF(C13+F13=1,1,0)) -> 0 | L13: =IF(K13=3,3,IF(I13+K13=2,2,IF(K13=1,1,0))) -> 0 | M13: =B13+E13 -> 4 | N13: =C13+F13+I13 -> 0 | P13: =AE9 -> Sammy Ben Tamer | Q13: 6 | R13: =IF(Q13>Q15,1,0) -> 1 | T13: 4 | U13: =IF(T13>T15,1,0) -> 0 | W13: 10 | X13: =IF(W13>W15,1,0) -> 1 | Y13: =IF(Q13="",0,1) -> 1 | Z13: =IF(R13+U13=2,3,IF(R13+U13=1,1,0)) -> 1 | AA13: =IF(Z13=3,3,IF(X13+Z13=2,2,IF(Z13=1,1,0))) -> 2 | AB13: =Q13+T13 -> 10 | AC13: =R13+U13+X13 -> 2 | AE13: ='Players - Men'!B32 -> Liam Vella | AF13: =Y29+Y11+Y33+J33+J23 -> 5 | AG13: =AA29+AA11+AA33+L33+L23 -> 11 | AH13: =AB29+AB11+AB33+M33+M23 -> 50 | AI13: =AC29+AC11+AC33+N33+N23 -> 8
A14: vs. | P14: vs.
A15: =AE15 -> Chris Vella | B15: 6 | C15: =IF(B15>B13,1,0) -> 1 | E15: 6 | F15: =IF(E15>E13,1,0) -> 1 | I15: =IF(H15>H13,1,0) -> 0 | J15: =IF(B15="",0,1) -> 1 | K15: =IF(C15+F15=2,3,IF(C15+F15=1,1,0)) -> 3 | L15: =IF(K15=3,3,IF(I15+K15=2,2,IF(K15=1,1,0))) -> 3 | M15: =B15+E15 -> 12 | N15: =C15+F15+I15 -> 2 | P15: =AE17 -> Braydon Galea | Q15: 4 | R15: =IF(Q15>Q13,1,0) -> 0 | T15: 6 | U15: =IF(T15>T13,1,0) -> 1 | W15: 3 | X15: =IF(W15>W13,1,0) -> 0 | Y15: =IF(Q15="",0,1) -> 1 | Z15: =IF(R15+U15=2,3,IF(R15+U15=1,1,0)) -> 1 | AA15: =IF(Z15=3,3,IF(X15+Z15=2,2,IF(Z15=1,1,0))) -> 1 | AB15: =Q15+T15 -> 10 | AC15: =R15+U15+X15 -> 1 | AE15: ='Players - Men'!B33 -> Chris Vella | AF15: =Y31+J37+J15+Y23+J29 -> 5 | AG15: =AA31+L37+L15+AA23+L29 -> 15 | AH15: =AB31+M37+M15+AB23+M29 -> 60 | AI15: =AC31+N37+N15+AC23+N29 -> 10
A17: =AE9 -> Sammy Ben Tamer | B17: 4 | C17: =IF(B17>B19,1,0) -> 0 | E17: 4 | F17: =IF(E17>E19,1,0) -> 0 | I17: =IF(H17>H19,1,0) -> 0 | J17: =IF(B17="",0,1) -> 1 | K17: =IF(C17+F17=2,3,IF(C17+F17=1,1,0)) -> 0 | L17: =IF(K17=3,3,IF(I17+K17=2,2,IF(K17=1,1,0))) -> 0 | M17: =B17+E17 -> 8 | N17: =C17+F17+I17 -> 0 | P17: =AE17 -> Braydon Galea | Q17: 6 | R17: =IF(Q17>Q19,1,0) -> 1 | T17: 6 | U17: =IF(T17>T19,1,0) -> 1 | X17: =IF(W17>W19,1,0) -> 0 | Y17: =IF(Q17="",0,1) -> 1 | Z17: =IF(R17+U17=2,3,IF(R17+U17=1,1,0)) -> 3 | AA17: =IF(Z17=3,3,IF(X17+Z17=2,2,IF(Z17=1,1,0))) -> 3 | AB17: =Q17+T17 -> 12 | AC17: =R17+U17+X17 -> 2 | AE17: ='Players - Men'!B34 -> Braydon Galea | AF17: =Y17+J39+J27+Y15+J35 -> 5 | AG17: =AA17+L39+L27+AA15+L35 -> 8 | AH17: =AB17+M39+M27+AB15+M35 -> 46 | AI17: =AC17+N39+N27+AC15+N35 -> 6
A18: vs. | P18: vs.
