Workbook

Sheet Standings
C2: VLTC SAN MICHEL TEAM TOURNAMENT 2023
C8: ROUND 1
D10: Day 1 | F10: Total Day 1 | I10: Day 2 | K10: Total Day 2 | N10: Day 3 | P10: Total Day 3 | S10: Day 4 | U10: Total Day 4 | X10: Day 5 | Z10: Total Day 5 | AC10: Total Round 1
D11: G | E11: S | F11: G | G11: S | I11: G | J11: S | K11: G | L11: S | N11: G | O11: S | P11: G | Q11: S | S11: G | T11: S | U11: G | V11: S | X11: G | Y11: S | Z11: G | AA11: S | AC11: G | AD11: S
B13: TEAM A: Gabriel Pace | C13: Fri | D13: ='Day 1'!J25 -> 43 | E13: ='Day 1'!L25 -> 6 | F13: =D13+D14 -> 79 | G13: =SUM(E13+E14) -> 10 | I13: ='Day 2 '!J60 -> 27 | J13: ='Day 2 '!L60 -> 2 | K13: =I13+I14 -> 58 | L13: =J13+J14 -> 4 | N13: ='Day 3'!J95 -> 42 | O13: ='Day 3'!L95 -> 5 | P13: =N13+N14 -> 75 | Q13: =O13+O14 -> 8 | S13: ='Day 4'!J95 -> 33 | T13: ='Day 4'!L95 -> 3 | U13: =S13+S14 -> 73 | V13: =T13+T14 -> 9 | X13: ='Day 5'!J25 -> 26 | Y13: ='Day 5'!L25 -> 3 | Z13: =X13+X14 -> 70 | AA13: =Y13+Y14 -> 9 | AC13: =D13+D14+I13+I14+N13+N14+S13+S14+X13+X14 -> 355 | AD13: =SUM(G13+G14+L13+L14+Q13+Q14+V13+V14+AA13+AA14) -> 40
C14: Sat | D14: ='Day 1'!J40 -> 36 | E14: ='Day 1'!L40 -> 4 | I14: ='Day 2 '!J75 -> 31 | J14: ='Day 2 '!L75 -> 2 | N14: ='Day 3'!J110 -> 33 | O14: ='Day 3'!L110 -> 3 | S14: ='Day 4'!J110 -> 40 | T14: ='Day 4'!L110 -> 6 | X14: ='Day 5'!J40 -> 44 | Y14: ='Day 5'!L40 -> 6
B16: TEAM B: Frans Ellul | C16: Fri | D16: ='Day 1'!J95 -> 32 | E16: ='Day 1'!L95 -> 4 | F16: =SUM(D16+D17) -> 64 | G16: =SUM(E16:E17) -> 7 | I16: ='Day 2 '!J25 -> 50 | J16: ='Day 2 '!L25 -> 6 | K16: =SUM(I16+I17) -> 87 | L16: =SUM(J16+J17) -> 9 | N16: ='Day 3'!K60 -> 31 | O16: ='Day 3'!M60 -> 3 | P16: =SUM(N16+N17) -> 72 | Q16: =SUM(O16+O17) -> 8 | S16: ='Day 4'!K95 -> 36 | T16: ='Day 4'!M95 -> 5 | U16: =SUM(S16+S17) -> 64 | V16: =T16+T17 -> 7 | X16: ='Day 5'!J60 -> 31 | Y16: ='Day 5'!L60 -> 4 | Z16: =SUM(X16+X17) -> 75 | AA16: =SUM(Y16+Y17) -> 11 | AC16: =D16+D17+I16+I17+N16+N17+S16+S17+X16+X17 -> 362 | AD16: =SUM(G16+G17+L16+L17+Q16+Q17+V16+V17+AA16+AA17) -> 42
C17: Sat | D17: ='Day 1'!J110 -> 32 | E17: ='Day 1'!L110 -> 3 | I17: ='Day 2 '!J40 -> 37 | J17: ='Day 2 '!L40 -> 3 | N17: ='Day 3'!K75 -> 41 | O17: ='Day 3'!M75 -> 5 | S17: ='Day 4'!K110 -> 28 | T17: ='Day 4'!M110 -> 2 | X17: ='Day 5'!J75 -> 44 | Y17: ='Day 5'!L75 -> 7
B19: TEAM C: Lucienne Meli | C19: Fri | D19: ='Day 1'!K25 -> 29 | E19: ='Day 1'!M25 -> 2 | F19: =D19+D20 -> 66 | G19: =E19+E20 -> 6 | I19: ='Day 2 '!J95 -> 41 | J19: ='Day 2 '!L95 -> 6 | K19: =I19+I20 -> 80 | L19: =J19+J20 -> 11 | N19: ='Day 3'!J25 -> 16 | O19: ='Day 3'!L25 -> 0 | P19: =N19+N20 -> 54 | Q19: =O19+O20 -> 3 | S19: ='Day 4'!J60 -> 36 | T19: ='Day 4'!L60 -> 3 | U19: =S19+S20 -> 81 | V19: =T19+T20 -> 8 | X19: ='Day 5'!K60 -> 37 | Y19: ='Day 5'!M60 -> 4 | Z19: =X19+X20 -> 67 | AA19: =SUM(Y19+Y20) -> 5 | AC19: =D19+D20+I19+I20+N19+N20+S19+S20+X19+X20 -> 348 | AD19: =SUM(E19+E20+J19+J20+O19+O20+T19+T20+Y19+Y20) -> 33
C20: Sat | D20: ='Day 1'!K40 -> 37 | E20: ='Day 1'!M40 -> 4 | I20: ='Day 2 '!J110 -> 39 | J20: ='Day 2 '!L110 -> 5 | N20: ='Day 3'!J40 -> 38 | O20: ='Day 3'!L40 -> 3 | S20: ='Day 4'!J75 -> 45 | T20: ='Day 4'!L75 -> 5 | X20: ='Day 5'!K75 -> 30 | Y20: ='Day 5'!M75 -> 1
B22: TEAM D: Roberto Murdocco | C22: Fri | D22: ='Day 1'!J60 -> 46 | E22: ='Day 1'!L60 -> 7 | F22: =D22+D23 -> 87 | G22: =SUM(E22+E23) -> 12 | I22: ='Day 2 '!K95 -> 23 | J22: ='Day 2 '!M95 -> 2 | K22: =I22+I23 -> 63 | L22: =J22+J23 -> 5 | N22: ='Day 3'!J60 -> 38 | O22: ='Day 3'!L60 -> 5 | P22: =N22+N23 -> 71 | Q22: =O22+O23 -> 8 | S22: ='Day 4'!J25 -> 25 | T22: ='Day 4'!L25 -> 1 | U22: =S22+S23 -> 71 | V22: =T22+T23 -> 8 | X22: ='Day 5'!K25 -> 40 | Y22: ='Day 5'!M25 -> 5 | Z22: =X22+X23 -> 70 | AA22: =SUM(Y22+Y23) -> 7 | AC22: =D22+D23+I22+I23+N22+N23+S22+S23+X22+X23 -> 362 | AD22: =SUM(E22+E23+J22+J23+O22+O23+T22+T23+Y22+Y23) -> 40
C23: Sat | D23: ='Day 1'!J75 -> 41 | E23: ='Day 1'!L75 -> 5 | I23: ='Day 2 '!K110 -> 40 | J23: ='Day 2 '!M110 -> 3 | N23: ='Day 3'!J75 -> 33 | O23: ='Day 3'!L75 -> 3 | S23: ='Day 4'!J40 -> 46 | T23: ='Day 4'!L40 -> 7 | X23: ='Day 5'!K40 -> 30 | Y23: ='Day 5'!M40 -> 2
B25: TEAM E: Aaron Micallef Piccione | C25: Fri | D25: ='Day 1'!K60 -> 17 | E25: ='Day 1'!M60 -> 1 | F25: =D25+D26 -> 52 | G25: =E25+E26 -> 4 | I25: ='Day 2 '!K25 -> 39 | J25: ='Day 2 '!M25 -> 2 | K25: =I25+I26 -> 81 | L25: =J25+J26 -> 7 | N25: ='Day 3'!K95 -> 32 | O25: ='Day 3'!M95 -> 3 | P25: =N25+N26 -> 69 | Q25: =O25+O26 -> 8 | S25: ='Day 4'!K60 -> 44 | T25: ='Day 4'!M60 -> 5 | U25: =S25+S26 -> 79 | V25: =T25+T26 -> 8 | X25: ='Day 5'!J95 -> 33 | Y25: ='Day 5'!L95 -> 2 | Z25: =X25+X26 -> 48 | AA25: =Y25+Y26 -> 3 | AC25: =D25+D26+I25+I26+N25+N26+S25+S26+X25+X26 -> 329 | AD25: =E25+E26+J25+J26+O25+O26+T25+T26+Y25+Y26 -> 30
C26: Sat | D26: ='Day 1'!K75 -> 35 | E26: ='Day 1'!M75 -> 3 | I26: ='Day 2 '!K40 -> 42 | J26: ='Day 2 '!M40 -> 5 | N26: ='Day 3'!K110 -> 37 | O26: ='Day 3'!M110 -> 5 | S26: ='Day 4'!K75 -> 35 | T26: ='Day 4'!M75 -> 3 | X26: ='Day 5'!J110 -> 15 | Y26: ='Day 5'!L110 -> 1
B28: TEAM F: Lonia Carabott | C28: Fri | D28: ='Day 1'!K95 -> 34 | E28: ='Day 1'!M95 -> 4 | F28: =D28+D29 -> 73 | G28: =E28+E29 -> 9 | I28: ='Day 2 '!K60 -> 45 | J28: ='Day 2 '!M60 -> 6 | K28: =I28+I29 -> 86 | L28: =J28+J29 -> 12 | N28: ='Day 3'!K25 -> 48 | O28: ='Day 3'!M25 -> 8 | P28: =N28+N29 -> 89 | Q28: =O28+O29 -> 13 | S28: ='Day 4'!K25 -> 45 | T28: ='Day 4'!M25 -> 7 | U28: =S28+S29 -> 70 | V28: =SUM(T28+T29) -> 8 | X28: ='Day 5'!K95 -> 46 | Y28: ='Day 5'!M95 -> 6 | Z28: =X28+X29 -> 91 | AA28: =Y28+Y29 -> 13 | AC28: =D28+D29+I28+I29+N28+N29+S28+S29+X28+X29 -> 409 | AD28: =E28+E29+J28+J29+O28+O29+T28+T29+Y28+Y29 -> 55
C29: Sat | D29: ='Day 1'!K110 -> 39 | E29: ='Day 1'!M110 -> 5 | I29: ='Day 2 '!K75 -> 41 | J29: ='Day 2 '!M75 -> 6 | N29: ='Day 3'!K40 -> 41 | O29: ='Day 3'!M40 -> 5 | S29: ='Day 4'!K40 -> 25 | T29: ='Day 4'!M40 -> 1 | X29: ='Day 5'!K110 -> 45 | Y29: ='Day 5'!M110 -> 7
C32: ROUND 2
D34: Day 6 | F34: Total Day 6 | I34: Day 7 | K34: Total Day 7 | N34: Day 8 | P34: Total Day 8 | S34: Day 9 | U34: Total Day 9 | X34: Day 10 | Z34: Total Day 10 | AC34: Total Rounds 1 & 2
D35: G | E35: S | F35: G | G35: S | I35: G | J35: S | K35: G | L35: S | N35: G | O35: S | P35: G | Q35: S | S35: G | T35: S | U35: G | V35: S | X35: G | Y35: S | Z35: G | AA35: S | AC35: G | AD35: S
B37: TEAM A: Gabriel Pace | C37: Fri | D37: ='Day 6'!J25 -> 31 | E37: ='Day 6'!L25 -> 3 | F37: =SUM(D37+D38) -> 66 | G37: =SUM(E37+E38) -> 7 | I37: ='Day 7'!J60 -> 29 | J37: ='Day 7'!L60 -> 2 | K37: =I37+I38 -> 70 | L37: =J37+J38 -> 5 | N37: ='Day 8'!J95 -> 46 | O37: ='Day 8'!L95 -> 7 | P37: =N37+N38 -> 79 | Q37: =O37+O38 -> 10 | S37: =SUM('Day 9'!J95) -> 38 | T37: =SUM('Day 9'!L95) -> 5 | U37: =S37+S38 -> 84 | V37: =T37+T38 -> 12 | X37: =SUM('Day 10'!J25) -> 46 | Y37: =SUM('Day 10'!L25) -> 6 | Z37: =X37+X38 -> 88 | AA37: =Y37+Y38 -> 12 | AC37: =SUM(AC13+AC14+F37+F38+K37+K38+P37+P38+U37+U38+Z37+Z38) -> 742 | AD37: =SUM(AD13+G37+L37+Q37+V37+AA37) -> 86
C38: Sat | D38: ='Day 6'!J40 -> 35 | E38: ='Day 6'!L40 -> 4 | I38: ='Day 7'!J75 -> 41 | J38: ='Day 7'!L75 -> 3 | N38: ='Day 8'!J110 -> 33 | O38: ='Day 8'!L110 -> 3 | S38: =SUM('Day 9'!J110) -> 46 | T38: =SUM('Day 9'!L110) -> 7 | X38: =SUM('Day 10'!J40) -> 42 | Y38: =SUM('Day 10'!L40) -> 6
B40: TEAM B: Frans Ellul | C40: Fri | D40: ='Day 6'!J95 -> 38 | E40: ='Day 6'!L95 -> 3 | F40: =SUM(D40+D41) -> 62 | G40: =SUM(E40+E41) -> 5 | I40: ='Day 7'!J25 -> 37 | J40: ='Day 7'!L25 -> 3 | K40: =I40+I41 -> 72 | L40: =J40+J41 -> 5 | N40: ='Day 8'!K60 -> 37 | O40: ='Day 8'!M60 -> 3 | P40: =N40+N41 -> 84 | Q40: =O40+O41 -> 8 | S40: =SUM('Day 9'!K95) -> 29 | T40: =SUM('Day 9'!M95) -> 3 | U40: =S40+S41 -> 56 | V40: =T40+T41 -> 4 | X40: =SUM('Day 10'!J60) -> 41 | Y40: =SUM('Day 10'!L60) -> 5 | Z40: =X40+X41 -> 77 | AA40: =Y40+Y41 -> 9 | AC40: =SUM(AC16+AC17+F40+F41+K40+K41+P40+P41+U40+U41+Z40+Z41) -> 713 | AD40: =SUM(AD16+G40+L40+Q40+V40+AA40) -> 73
C41: Sat | D41: ='Day 6'!J110 -> 24 | E41: ='Day 6'!L110 -> 2 | I41: ='Day 7'!J40 -> 35 | J41: ='Day 7'!L40 -> 2 | N41: ='Day 8'!K75 -> 47 | O41: ='Day 8'!M75 -> 5 | S41: =SUM('Day 9'!K110) -> 27 | T41: =SUM('Day 9'!M110) -> 1 | X41: =SUM('Day 10'!J75) -> 36 | Y41: =SUM('Day 10'!L75) -> 4
B43: TEAM C: Lucienne Meli | C43: Fri | D43: ='Day 6'!K25 -> 42 | E43: ='Day 6'!M25 -> 5 | F43: =SUM(D43+D44) -> 82 | G43: =SUM(E43+E44) -> 9 | I43: ='Day 7'!K95 -> 24 | J43: ='Day 7'!M95 -> 0 | K43: =I43+I44 -> 73 | L43: =J43+J44 -> 8 | N43: ='Day 8'!J25 -> 26 | O43: ='Day 8'!L25 -> 2 | P43: =N43+N44 -> 56 | Q43: =O43+O44 -> 6 | S43: =SUM('Day 9'!J60) -> 48 | T43: =SUM('Day 9'!L60) -> 6 | U43: =S43+S44 -> 86 | V43: =T43+T44 -> 10 | X43: =SUM('Day 10'!K60) -> 25 | Y43: =SUM('Day 10'!M60) -> 3 | Z43: =X43+X44 -> 61 | AA43: =Y43+Y44 -> 7 | AC43: =SUM(AC19+AC20+F43+F44+K43+K44+P43+P44+U43+U44+Z43+Z44) -> 706 | AD43: =SUM(AD19+G43+L43+Q43+V43+AA43) -> 73
C44: Sat | D44: ='Day 6'!K40 -> 40 | E44: ='Day 6'!M40 -> 4 | I44: ='Day 7'!K110 -> 49 | J44: ='Day 7'!M110 -> 8 | N44: ='Day 8'!J40 -> 30 | O44: ='Day 8'!L40 -> 4 | S44: =SUM('Day 9'!J75) -> 38 | T44: =SUM('Day 9'!L75) -> 4 | X44: =SUM('Day 10'!K75) -> 36 | Y44: =SUM('Day 10'!M75) -> 4
B46: TEAM D: Roberto Murdocco | C46: Fri | D46: ='Day 6'!J60 -> 32 | E46: ='Day 6'!L60 -> 1 | F46: =SUM(D46+D47) -> 78 | G46: =SUM(E46+E47) -> 8 | I46: ='Day 7'!J95 -> 48 | J46: ='Day 7'!L95 -> 8 | K46: =I46+I47 -> 73 | L46: =J46+J47 -> 8 | N46: ='Day 8'!J60 -> 39 | O46: ='Day 8'!L60 -> 5 | P46: =N46+N47 -> 79 | Q46: =O46+O47 -> 8 | S46: =SUM('Day 9'!J25) -> 5 | T46: =SUM('Day 9'!L25) -> 0 | U46: =S46+S47 -> 40 | V46: =T46+T47 -> 3 | X46: =SUM('Day 10'!K25) -> 27 | Y46: =SUM('Day 10'!M25) -> 2 | Z46: =X46+X47 -> 59 | AA46: =Y46+Y47 -> 4 | AC46: =SUM(AC22+AC23+F46+F47+K46+K47+P46+P47+U46+U47+Z46+Z47) -> 691 | AD46: =SUM(AD22+G46+L46+Q46+V46+AA46) -> 71
C47: Sat | D47: ='Day 6'!J75 -> 46 | E47: ='Day 6'!L75 -> 7 | I47: ='Day 7'!J110 -> 25 | J47: ='Day 7'!L110 -> 0 | N47: ='Day 8'!J75 -> 40 | O47: ='Day 8'!L75 -> 3 | S47: =SUM('Day 9'!J40) -> 35 | T47: =SUM('Day 9'!L40) -> 3 | X47: =SUM('Day 10'!K40) -> 32 | Y47: =SUM('Day 10'!M40) -> 2
B49: TEAM E: Aaron Micallef Piccione | C49: Fri | D49: ='Day 6'!K60 -> 47 | E49: ='Day 6'!M60 -> 7 | F49: =SUM(D49+D50) -> 75 | G49: =SUM(E49+E50) -> 8 | I49: ='Day 7'!K25 -> 44 | J49: ='Day 7'!M25 -> 5 | K49: =I49+I50 -> 92 | L49: =J49+J50 -> 11 | N49: ='Day 8'!K95 -> 29 | O49: ='Day 8'!M95 -> 1 | P49: =N49+N50 -> 69 | Q49: =O49+O50 -> 6 | S49: =SUM('Day 9'!K60) -> 36 | T49: =SUM('Day 9'!M60) -> 2 | U49: =S49+S50 -> 72 | V49: =T49+T50 -> 6 | X49: =SUM('Day 10'!J95) -> 28 | Y49: =SUM('Day 10'!L95) -> 3 | Z49: =X49+X50 -> 56 | AA49: =Y49+Y50 -> 6 | AC49: =SUM(AC25+AC26+F49+F50+K49+K50+P49+P50+U49+U50+Z49+Z50) -> 693 | AD49: =SUM(AD25+G49+L49+Q49+V49+AA49) -> 67
C50: Sat | D50: ='Day 6'!K75 -> 28 | E50: ='Day 6'!M75 -> 1 | I50: ='Day 7'!K40 -> 48 | J50: ='Day 7'!M40 -> 6 | N50: ='Day 8'!K110 -> 40 | O50: ='Day 8'!M110 -> 5 | S50: =SUM('Day 9'!K75) -> 36 | T50: =SUM('Day 9'!M75) -> 4 | X50: =SUM('Day 10'!J110) -> 28 | Y50: =SUM('Day 10'!L110) -> 3
B52: TEAM F: Lonia Carabott | C52: Fri | D52: ='Day 6'!K95 -> 40 | E52: ='Day 6'!M95 -> 5 | F52: =SUM(D52+D53) -> 87 | G52: =SUM(E52+E53) -> 11 | I52: ='Day 7'!K60 -> 44 | J52: ='Day 7'!M60 -> 6 | K52: =I52+I53 -> 86 | L52: =J52+J53 -> 11 | N52: ='Day 8'!K25 -> 38 | O52: ='Day 8'!M25 -> 6 | P52: =N52+N53 -> 79 | Q52: =O52+O53 -> 10 | S52: =SUM('Day 9'!K25) -> 48 | T52: =SUM('Day 9'!M25) -> 8 | U52: =S52+S53 -> 87 | V52: =T52+T53 -> 13 | X52: =SUM('Day 10'!K95) -> 34 | Y52: =SUM('Day 10'!M95) -> 5 | Z52: =X52+X53 -> 75 | AA52: =Y52+Y53 -> 10 | AC52: =SUM(AC28+AC29+F52+F53+K52+K53+P52+P53+U52+U53+Z52+Z53) -> 823 | AD52: =SUM(AD28+G52+L52+Q52+V52+AA52) -> 110
C53: Sat | D53: ='Day 6'!K110 -> 47 | E53: ='Day 6'!M110 -> 6 | I53: ='Day 7'!K75 -> 42 | J53: ='Day 7'!M75 -> 5 | N53: ='Day 8'!K40 -> 41 | O53: ='Day 8'!M40 -> 4 | S53: =SUM('Day 9'!K40) -> 39 | T53: =SUM('Day 9'!M40) -> 5 | X53: =SUM('Day 10'!K110) -> 41 | Y53: =SUM('Day 10'!M110) -> 5
Q56: `

Sheet Team Selection
A1: VITTORIOSA LAWN TENNIS CLUB
A2: SAN MICHEL TEAM TOURNAMENT - 2023
B4: TEAM A | C4: TEAM B | D4: TEAM C | E4: TEAM D | F4: TEAM E | G4: TEAM F
A5: CAPTAIN | B5: Gabriel Pace | C5: Frans Ellul | D5: Lucienne Meli | E5: Roberto Murdocco | F5: Aaron Micallef Piccione | G5: Lonia Carabott
A6: MEN
A7: A1 | B7: Mark Vella Bonnici | C7: Marcelo Villanueva | D7: Matthew Mifsud | E7: Jesmond Pule' | F7: Adrian Chetcuti | G7: Kurt Carabott
A8: A2 | B8: Andrew Pule' | C8: Eric Roca | D8: Trevor Rutter | E8: Duncan D'Alessandro | F8: John Azzopardi | G8: Nikolai Belli
A9: A3 | B9: Keith Micallef | C9: Reuben Borg | D9: Massimo Giovannini | E9: Luigi Porto | F9: Marco Mercieca | G9: Melchior Farrugia
A11: B1 | B11: Earvin Grech Meli | C11: James Farrugia | D11: Richard Curmi | E11: Fotios Evangelov | F11: George Grech | G11: David Schembri
A12: B2 | B12: Gene Zammit | C12: Clint Agius | D12: Richard Byrne | E12: Kevin Formosa | F12: Ivan Cachia | G12: Ryan Mizzi
A13: B3 | B13: Gabriel Pace | C13: Julian Bilocca | D13: Jonathan Vella | E13: Roberto Murdocco | F13: Stefan Holmin | G13: Willem Steenkamer
A14: B4 | B14: Charles Sacco | C14: George Meekers | D14: Stephen Belli | E14: Manuel Gatt | F14: Manuel Mifsud | G14: Jonathan Martinelli
A16: C1 | B16: Maurice Borg | C16: Juan Debono | D16: Joe Carabott | E16: Sebastian Attard | F16: Matthew Schembri | G16: Max Anastasi
A17: C2 | B17: Jean Paul Vella | C17: Alain Frendo | D17: Victor Rutter | E17: Kristen Cachia | F17: Ivan Saliba | G17: Artiom Kiricenko
A18: C3 | B18: Darrell Pace | C18: Max Anastasi Jr. | D18: Ray Ciantar | E18: Ryan Ebejer | F18: Aaron Micallef Piccione | G18: Julian Esposito
A20: D1 | B20: Twanny Pule' | C20: Denis Caruana | D20: Charles Grech | E20: Simone Re | F20: Joseph Randich | G20: Kenneth Caruana
A21: D2 | B21: Charles Micallef | C21: Kenneth Farrugia | D21: Ahmed Eln Akroud | E21: David Camilleri | F21: Adrian Duca | G21: Charles Borg Grech
A22: D3 | B22: Sean Cachia | C22: Adam Green | D22: Eman Meli | E22: Donald Deguzman | F22: Cory Greenland | G22: Mario Abdilla
A24: LADIES
A25: A1 | B25: Sharon Mizzi | C25: Christine Schembri | D25: Annmarie Mangion | E25: Nicole Fava | F25: Alexia Spiteri Willets | G25: Martina Cuschieri
A26: A2 | B26: Olivia Belli | C26: Celeste Zammit Marquette | D26: Lucienne Meli | E26: Pierina Holmin | F26: Natalya Abela | G26: Elaine Grech
A27: A3 | B27: Kirsty Mercieca | C27: Yasmine Hefny | D27: Anabelle Abela | E27: Romina Gauci | F27: Alison Muscat | G27: Anthea Gauci
A28: A4 | B28: Silvana Portelli | C28: Brenda Baldacchino | D28: Mariska Steenkamer | E28: Alexia Gouder | F28: Julia Barbara | G28: Dorianne Buhagiar
A30: B1 | B30: Deborah Farrugia | C30: Francesca Sciortino | D30: Anabel Borg | E30: Anna Buhagiar | F30: Marthese Camoin | G30: Kristina Briffa
A31: B2 | B31: Nancy Wong | C31: Ann-Marie Attard | D31: Carmen Difesa | E31: Sarah Axiaq | F31: Ruth Micallef | G31: Diane Fenech
A32: B3 | B32: Kelsey Gauci | C32: Diane Debono | D32: Jennifer Roca | E32: Ceridwen Scerri | F32: Jin Attard | G32: Lonia Carabott
A34: C1 | B34: Jodie Stivala | C34: Stefania Camilleri | D34: Mary Borg | E34: Anna Casingena | F34: Christine Seychell | G34: Julie Spiteri
A35: C2 | B35: Elisa Sacco | C35: Anna Ancilleri | D35: Josette Cassar | E35: Anna Napier | F35: Christabelle Chetcuti | G35: Christine Scerri
A36: C3 | B36: Stephanie Hercegovac | C36: Rose Falzon | D36: Jean Frendo | E36: Claire Genovese | F36: Lillian Baldacchino | G36: Anna Fenech

Sheet Encounters Played
C2: VLTC SAN MICHEL TEAM TOURNAMENT 2023
A5: Gabriel Pace | C5: Day 1 | D5: Day 2 | E5: Day 3 | F5: Day 4 | G5: Day 5 | H5: Day 6 | I5: Day 7 | J5: Day 8 | K5: Day 9 | L5: Day 10 | M5: TOTAL
A6: A1 | B6: Mark Vella Bonnici | D6: 1 | E6: 1 | G6: 1 | H6: 1 | I6: 1 | J6: 1 | K6: 1 | L6: 1 | M6: =SUM(C6:L6) -> 8
A7: A2 | B7: Andrew Pule' | C7: 1 | E7: 1 | F7: 1 | G7: 1 | I7: 1 | K7: 1 | M7: =SUM(C7:L7) -> 6
A8: A3 | B8: Keith Micallef | C8: 1 | D8: 1 | F8: 1 | H8: 1 | J8: 1 | L8: 1 | M8: =SUM(C8:L8) -> 6
A9: B1 | B9: Earvin Grech Meli | C9: 1 | E9: 1 | F9: 1 | G9: 1 | H9: 1 | I9: 1 | J9: 1 | L9: 1 | M9: =SUM(C9:L9) -> 8
A10: B2 | B10: Gene Zammit | C10: 1 | D10: 1 | F10: 1 | G10: 1 | H10: 1 | J10: 1 | K10: 1 | L10: 1 | M10: =SUM(C10:L10) -> 8
A11: B3 | B11: Gabriel Pace | C11: 1 | D11: 1 | E11: 1 | G11: 1 | I11: 1 | J11: 1 | K11: 1 | L11: 1 | M11: =SUM(C11:L11) -> 8
A12: B4 | B12: Charles Sacco | D12: 1 | E12: 1 | F12: 1 | H12: 1 | I12: 1 | K12: 1 | M12: =SUM(C12:L12) -> 6
A13: C1 | B13: Maurice Borg | C13: 1 | G13: 1 | H13: 1 | J13: 1 | K13: 1 | L13: 1 | M13: =SUM(C13:L13) -> 6
A14: C2 | B14: Jean Paul Vella | D14: 1 | E14: 1 | F14: 1 | G14: 1 | I14: 1 | K14: 1 | L14: 1 | M14: =SUM(C14:L14) -> 7
A15: C3 | B15: Darrell Pace | C15: 1 | D15: 1 | E15: 1 | F15: 1 | H15: 1 | I15: 1 | J15: 1 | M15: =SUM(C15:L15) -> 7
A16: D1 | B16: Twanny Pule' | C16: 1 | E16: 1 | F16: 1 | G16: 1 | H16: 1 | I16: 1 | J16: 1 | L16: 1 | M16: =SUM(C16:L16) -> 8
A17: D2 | B17: Charles Micallef | D17: 1 | E17: 1 | F17: 1 | H17: 1 | J17: 1 | K17: 1 | M17: =SUM(C17:L17) -> 6
A18: D3 | B18: Sean Cachia | C18: 1 | D18: 1 | G18: 1 | I18: 1 | K18: 1 | L18: 1 | M18: =SUM(C18:L18) -> 6
A19: A1 | B19: Sharon Mizzi | C19: 1 | D19: 1 | F19: 1 | G19: 1 | H19: 1 | I19: 1 | K19: 1 | L19: 1 | M19: =SUM(C19:L19) -> 8
A20: A2 | B20: Olivia Belli | C20: 1 | D20: 1 | E20: 1 | G20: 1 | H20: 1 | I20: 1 | J20: 1 | L20: 1 | M20: =SUM(C20:L20) -> 8
A21: A3 | B21: Kirsty Mercieca | D21: 1 | E21: 1 | F21: 1 | G21: 1 | I21: 1 | J21: 1 | K21: 1 | L21: 1 | M21: =SUM(C21:L21) -> 8
A22: A4 | B22: Silvana Portelli | C22: 1 | E22: 1 | F22: 1 | H22: 1 | J22: 1 | K22: 1 | M22: =SUM(C22:L22) -> 6
A23: B1 | B23: Deborah Farrugia | C23: 1 | E23: 1 | F23: 1 | G23: 1 | J23: 1 | K23: 1 | L23: 1 | M23: =SUM(C23:L23) -> 7
A24: B2 | B24: Nancy Wong | C24: 1 | D24: 1 | F24: 1 | H24: 1 | I24: 1 | J24: 1 | M24: =SUM(C24:L24) -> 6
A25: B3 | B25: Kelsey Gauci | D25: 1 | E25: 1 | G25: 1 | H25: 1 | I25: 1 | K25: 1 | L25: 1 | M25: =SUM(C25:L25) -> 7
A26: C1 | B26: Jodie Stivala | C26: 1 | D26: 1 | F26: 1 | G26: 1 | H26: 1 | I26: 1 | K26: 1 | M26: =SUM(C26:L26) -> 7
A27: C2 | B27: Elisa Sacco | D27: 1 | E27: 1 | F27: 1 | H27: 1 | J27: 1 | K27: 1 | L27: 1 | M27: =SUM(C27:L27) -> 7
A28: C3 | B28: Stephanie Hercegovac | C28: 1 | E28: 1 | G28: 1 | I28: 1 | J28: 1 | L28: 1 | M28: =SUM(C28:L28) -> 6
A30: Frans Ellul | C30: Day 1 | D30: Day 2 | E30: Day 3 | F30: Day 4 | G30: Day 5 | H30: Day 6 | I30: Day 7 | J30: Day 8 | K30: Day 9 | L30: Day 10 | M30: TOTAL
A31: A1 | B31: Marcelo Villanueva | C31: 1 | D31: 1 | F31: 1 | G31: 1 | I31: 1 | J31: 1 | L31: 1 | M31: =SUM(C31:L31) -> 7
A32: A2 | B32: Eric Roca | C32: 1 | E32: 1 | F32: 1 | G32: 1 | H32: 1 | K32: 1 | L32: 1 | M32: =SUM(C32:L32) -> 7
A33: A3 | B33: Reuben Borg | D33: 1 | E33: 1 | H33: 1 | I33: 1 | J33: 1 | K33: 1 | M33: =SUM(C33:L33) -> 6
A34: B1 | B34: James Farrugia | C34: 1 | D34: 1 | E34: 1 | F34: 1 | G34: 1 | H34: 1 | K34: 1 | L34: 1 | M34: =SUM(C34:L34) -> 8
A35: B2 | B35: Clint Agius | C35: 1 | D35: 1 | F35: 1 | G35: 1 | I35: 1 | J35: 1 | K35: 1 | L35: 1 | M35: =SUM(C35:L35) -> 8
A36: B3 | B36: Julian Bilocca | D36: 1 | E36: 1 | G36: 1 | H36: 1 | I36: 1 | J36: 1 | L36: 1 | M36: =SUM(C36:L36) -> 7
A37: B4 | B37: George Meekers | C37: 1 | E37: 1 | F37: 1 | H37: 1 | I37: 1 | J37: 1 | K37: 1 | M37: =SUM(C37:L37) -> 7
A38: C1 | B38: Juan Debono | C38: 1 | D38: 1 | E38: 1 | F38: 1 | K38: 1 | L38: 1 | M38: =SUM(C38:L38) -> 6
A39: C2 | B39: Alain Frendo | C39: 1 | D39: 1 | F39: 1 | G39: 1 | H39: 1 | I39: 1 | J39: 1 | L39: 1 | M39: =SUM(C39:L39) -> 8
A40: C3 | B40: Max Anastasi Jr. | E40: 1 | G40: 1 | H40: 1 | I40: 1 | J40: 1 | K40: 1 | M40: =SUM(C40:L40) -> 6
A41: D1 | B41: Denis Caruana | C41: 1 | D41: 1 | E41: 1 | G41: 1 | H41: 1 | I41: 1 | K41: 1 | L41: 1 | M41: =SUM(C41:L41) -> 8
A42: D2 | B42: Kenneth Farrugia | C42: 1 | F42: 1 | H42: 1 | I42: 1 | J42: 1 | K42: 1 | M42: =SUM(C42:L42) -> 6
A43: D3 | B43: Adam Green | D43: 1 | E43: 1 | F43: 1 | G43: 1 | J43: 1 | L43: 1 | M43: =SUM(C43:L43) -> 6
A44: A1 | B44: Christine Schembri | D44: 1 | E44: 1 | H44: 1 | I44: 1 | J44: 1 | K44: 1 | L44: 1 | M44: =SUM(C44:L44) -> 7
...

Sheet Team Schedule
B2: VLTC SAN MICHEL TEAM TOURNAMENT 2023
D5: COURT 1 | F5: COURT 2 | H5: COURT 4
B7: D A Y 1 | C7: D A T E
B8: Friday | C8: 44581 | D8: A - C | F8: D - E | H8: B - F
B9: Saturday | C9: 44582
B11: D A Y 2
B12: Friday | C12: 44595 | D12: B - E | F12: A - F | H12: C - D
B13: Saturday | C13: 44596
B15: D A Y 3
B16: Mon | C16: 44598 | D16: C - F | F16: D - B | H16: A - E
B17: Wednesday | C17: 44600
B18: Saturday | C18: 44603
B20: D A Y 4
B21: Friday | C21: 44609 | D21: D - F | F21: C - E | H21: A - B
B22: Saturday | C22: 44610
B24: D A Y 5
B25: Friday | C25: 44623 | D25: A - D | F25: B - C | H25: E - F
B26: Saturday | C26: 44624
B28: D A Y 6
B29: Friday | C29: 44630 | D29: A - C | F29: D - E | H29: B - F
B30: Saturday | C30: 44631
B32: D A Y 7
B33: Friday | C33: 44637 | D33: B - E | F33: A - F | H33: C - D
B34: Saturday | C34: 44638
B36: D A Y 8
B37: Friday | C37: 44644 | D37: C - F | F37: D - B | H37: A - E
B38: Saturday | C38: 44645
B40: D A Y 9
B41: Monday | C41: 45012 | D41: D - F | F41: C - E | H41: A - B
B42: Saturday | C42: 45017
B44: D A Y 10
B45: Friday | C45: 45030 | D45: A - D | F45: B - C | H45: E - F
B46: Saturday | C46: 45031

Sheet Day 1
C1: VLTC SAN MICHEL TEAM TOURNAMENT 2023
C6: DAY 1 - 21/01/2023 & 01/02/2023
C9: Court 1
C11: Time | D11: Rubber | E11: TEAM A: Gabriel Pace | G11: vs | H11: TEAM C: Lucienne Meli | J11: Games | L11: Sets
C13: 6.30 pm | D13: Men A | E13: Keith Micallef | F13: Andrew Pule' | G13: vs | H13: Matthew Mifsud | I13: Trevor Rutter | J13: 6 | K13: 4 | L13: =IF(AND(J13>K13,J14>K14),2,IF(J13>K13,1,IF(J14>K14,1,0))) -> 1 | M13: =IF(AND(K13>J13,K14>J14),2,IF(K13>J13,1,IF(K14>J14,1,0))) -> 1
J14: 3 | K14: 6
C16: 6.30 pm | D16: Men C | E16: Maurice Borg | F16: Darrell Pace | G16: vs | H16: Ray Ciantar | I16: Joe Carabott | J16: 6 | K16: 3 | L16: =IF(AND(J16>K16,J17>K17),2,IF(J16>K16,1,IF(J17>K17,1,0))) -> 2 | M16: =IF(AND(K16>J16,K17>J17),2,IF(K16>J16,1,IF(K17>J17,1,0))) -> 0
J17: 6 | K17: 4
C19: 9.00 pm | D19: Lad A | E19: Olivia Belli | F19: Sharon Mizzi | G19: vs | H19: Lucienne Meli | I19: Annabelle Abela | J19: 6 | K19: 2 | L19: =IF(AND(J19>K19,J20>K20),2,IF(J19>K19,1,IF(J20>K20,1,0))) -> 2 | M19: =IF(AND(K19>J19,K20>J20),2,IF(K19>J19,1,IF(K20>J20,1,0))) -> 0
J20: 6 | K20: 4
C22: 6.30 pm | D22: Lad B | E22: Deborah Farrugia | F22: Nancy Wong | G22: vs | H22: Anabel Borg | I22: Jennifer Roca | J22: 4 | K22: 6 | L22: =IF(AND(J22>K22,J23>K23),2,IF(J22>K22,1,IF(J23>K23,1,0))) -> 1 | M22: =IF(AND(K22>J22,K23>J23),2,IF(K22>J22,1,IF(K23>J23,1,0))) -> 1
J23: 6 | K23: 0
C25: Total Day 1 A | J25: =SUM(J13:J23) -> 43 | K25: =SUM(K13:K23) -> 29 | L25: =SUM(L13:L23) -> 6 | M25: =SUM(M13:M23) -> 2
C28: 3.30 pm | D28: Mxd BA | E28: Gene Zammit | F28: Silvana Portelli | G28: vs | H28: Stephen Belli | I28: Ann Marie Mangion | J28: 2 | K28: 6 | L28: =IF(AND(J28>K28,J29>K29),2,IF(J28>K28,1,IF(J29>K29,1,0))) -> 1 | M28: =IF(AND(K28>J28,K29>J29),2,IF(K28>J28,1,IF(K29>J29,1,0))) -> 1
J29: 6 | K29: 4
C31: 4.45 pm | D31: Men B | E31: Earvin Grech Meli | F31: Gabriel Pace | G31: vs | H31: Richard Byrne | I31: Jonathan Vella | J31: 1 | K31: 6 | L31: =IF(AND(J31>K31,J32>K32),2,IF(J31>K31,1,IF(J32>K32,1,0))) -> 1 | M31: =IF(AND(K31>J31,K32>J32),2,IF(K31>J31,1,IF(K32>J32,1,0))) -> 1
J32: 6 | K32: 1
C34: 6.00 pm | D34: Lad C | E34: Jodie Stivala | F34: Stephanie Hercegovac | G34: vs | H34: Josette Cassar | I34: Jean Frendo | J34: 3 | K34: 6 | L34: =IF(AND(J34>K34,J35>K35),2,IF(J34>K34,1,IF(J35>K35,1,0))) -> 1 | M34: =IF(AND(K34>J34,K35>J35),2,IF(K34>J34,1,IF(K35>J35,1,0))) -> 1
J35: 6 | K35: 4
C37: 3.30 pm | D37: Men D | E37: Twanny Pule' | F37: Sean Cachia | G37: vs | H37: Charles Grech | I37: Ahmed Eln Akroud | J37: 6 | K37: 7 | L37: =IF(AND(J37>K37,J38>K38),2,IF(J37>K37,1,IF(J38>K38,1,0))) -> 1 | M37: =IF(AND(K37>J37,K38>J38),2,IF(K37>J37,1,IF(K38>J38,1,0))) -> 1
J38: 6 | K38: 3
C40: Total Day 1B | J40: =SUM(J28:J38) -> 36 | K40: =SUM(K28:K38) -> 37 | L40: =SUM(L28:L38) -> 4 | M40: =SUM(M28:M38) -> 4
C42: Total Day 1 | J42: =J40+J25 -> 79 | K42: =K40+K25 -> 66 | L42: =L40+L25 -> 10 | M42: =M40+M25 -> 6
C44: Court 2
C46: Time | D46: Rubber | E46: TEAM D: Roberto Murdocco | G46: vs | H46: TEAM E: Aaron Micallef Piccione | J46: Games | L46: Sets
C48: 6.30 pm | D48: Lad C | E48: Anna Casingena | F48: Claire Genovese | G48: vs | H48: Christabelle Chetcuti | I48: Lilian Baldacchino | J48: 6 | K48: 0 | L48: =IF(AND(J48>K48,J49>K49),2,IF(J48>K48,1,IF(J49>K49,1,0))) -> 2 | M48: =IF(AND(K48>J48,K49>J49),2,IF(K48>J48,1,IF(K49>J49,1,0))) -> 0
J49: 6 | K49: 0
C51: 7.45 pm | D51: Men A | E51: Jesmond Pule' | F51: Duncan D'alessandro | G51: vs | H51: Clyde Grech | I51: John Azzopardi | J51: 6 | K51: 1 | L51: =IF(AND(J51>K51,J52>K52),2,IF(J51>K51,1,IF(J52>K52,1,0))) -> 2 | M51: =IF(AND(K51>J51,K52>J52),2,IF(K51>J51,1,IF(K52>J52,1,0))) -> 0
J52: 6 | K52: 3
C54: 9.00 pm | D54: Men B | E54: Fotios Evangelou | F54: Kevin Formosa | G54: vs | H54: George Grech | I54: Ivan Cachia | J54: 4 | K54: 6 | L54: =IF(AND(J54>K54,J55>K55),2,IF(J54>K54,1,IF(J55>K55,1,0))) -> 1 | M54: =IF(AND(K54>J54,K55>J55),2,IF(K54>J54,1,IF(K55>J55,1,0))) -> 1
J55: 6 | K55: 1
C57: 7.45 pm | D57: Lad A | E57: Nicole Fava | F57: Pierina Holmin | G57: vs | H57: Alexia Spiteri Willets | I57: Natalya Abela | J57: 6 | K57: 3 | L57: =IF(AND(J57>K57,J58>K58),2,IF(J57>K57,1,IF(J58>K58,1,0))) -> 2 | M57: =IF(AND(K57>J57,K58>J58),2,IF(K57>J57,1,IF(K58>J58,1,0))) -> 0
J58: 6 | K58: 3
C60: Total Day 1 A | J60: =SUM(J48:J58) -> 46 | K60: =SUM(K48:K58) -> 17 | L60: =SUM(L48:L58) -> 7 | M60: =SUM(M48:M58) -> 1
C63: 3.30 pm | D63: Lad B | E63: Anna Buhagiar | F63: Sarah Axiaq | G63: vs | H63: Marthese Camoin | I63: Ruth Micallef | J63: 1 | K63: 6 | L63: =IF(AND(J63>K63,J64>K64),2,IF(J63>K63,1,IF(J64>K64,1,0))) -> 1 | M63: =IF(AND(K63>J63,K64>J64),2,IF(K63>J63,1,IF(K64>J64,1,0))) -> 1
J64: 7 | K64: 5
C66: 4.45 pm | D66: Mxd BA | E66: Roberto Murdocco | F66: Alexia Gouder | G66: vs | H66: Manuel Mifsud | I66: Alison Muscat | J66: 3 | K66: 6 | L66: =IF(AND(J66>K66,J67>K67),2,IF(J66>K66,1,IF(J67>K67,1,0))) -> 1 | M66: =IF(AND(K66>J66,K67>J67),2,IF(K66>J66,1,IF(K67>J67,1,0))) -> 1
J67: 6 | K67: 4
C69: 4.45 pm | D69: Men C | E69: Kristen Cachia | F69: Ryan Ebejer | G69: vs | H69: Matthew Schembri | I69: Aaron Micallef Piccione | J69: 7 | K69: 5 | L69: =IF(AND(J69>K69,J70>K70),2,IF(J69>K69,1,IF(J70>K70,1,0))) -> 2 | M69: =IF(AND(K69>J69,K70>J70),2,IF(K69>J69,1,IF(K70>J70,1,0))) -> 0
J70: 6 | K70: 1
...

Sheet Day 2 
C1: SAN MICHEL TEAM TOURNAMENT 2023
C6: DAY 2 - 03/02/23 & 04/02/23
C9: Court 1
C11: Time | D11: Rubber | E11: Team B: Frans Ellul | G11: vs | H11: Team E: Aaron Micallef Piccione | J11: Games | L11: Sets
C13: 6.30 pm | D13: Lad B | E13: Francesca Sciortino | F13: Ann Marie Attard | G13: vs | H13: Marthese Camoin | I13: Jin Attard | J13: 7 | K13: 5 | L13: =IF(AND(J13>K13,J14>K14),2,IF(J13>K13,1,IF(J14>K14,1,0))) -> 1 | M13: =IF(AND(K13>J13,K14>J14),2,IF(K13>J13,1,IF(K14>J14,1,0))) -> 1
J14: 6 | K14: 7
C16: 7.45 pm | D16: Lad A | E16: Christine Schembri | F16: Celeste Zammit Marquette | G16: vs | H16: Alexia Spiteri Willets | I16: Alison Muscat | J16: 5 | K16: 7 | L16: =IF(AND(J16>K16,J17>K17),2,IF(J16>K16,1,IF(J17>K17,1,0))) -> 1 | M16: =IF(AND(K16>J16,K17>J17),2,IF(K16>J16,1,IF(K17>J17,1,0))) -> 1
J17: 7 | K17: 5
C19: 9.00 pm | D19: Men A | E19: Marcelo Villanueva | F19: Reuben Borg | G19: vs | H19: Clyde Grech | I19: Marco Mercieca | J19: 6 | K19: 3 | L19: =IF(AND(J19>K19,J20>K20),2,IF(J19>K19,1,IF(J20>K20,1,0))) -> 2 | M19: =IF(AND(K19>J19,K20>J20),2,IF(K19>J19,1,IF(K20>J20,1,0))) -> 0
J20: 6 | K20: 4
C22: 6.30 pm | D22: Men C | E22: Juan Debono | F22: Alain Frendo | G22: vs | H22: Matthew Schembri | I22: Ivan Saliba | J22: 6 | K22: 3 | L22: =IF(AND(J22>K22,J23>K23),2,IF(J22>K22,1,IF(J23>K23,1,0))) -> 2 | M22: =IF(AND(K22>J22,K23>J23),2,IF(K22>J22,1,IF(K23>J23,1,0))) -> 0
J23: 7 | K23: 5
C25: Total Day 2 A | J25: =SUM(J13:J23) -> 50 | K25: =SUM(K13:K23) -> 39 | L25: =SUM(L13:L23) -> 6 | M25: =SUM(M13:M23) -> 2
C28: 3.30 pm | D28: Lad C | E28: Stefania Camilleri | F28: Anna Ancilleri | G28: vs | H28: Christine Seychell | I28: Lillian Baldacchino | J28: 4 | K28: 6 | L28: =IF(AND(J28>K28,J29>K29),2,IF(J28>K28,1,IF(J29>K29,1,0))) -> 0 | M28: =IF(AND(K28>J28,K29>J29),2,IF(K28>J28,1,IF(K29>J29,1,0))) -> 2
J29: 3 | K29: 6
C31: 4.45pm | D31: MXD | E31: Julian Bilocca | F31: Brenda Baldacchino | G31: vs | H31: Manuel Mifsud | I31: Natlaya Abela | J31: 2 | K31: 6 | L31: =IF(AND(J31>K31,J32>K32),2,IF(J31>K31,1,IF(J32>K32,1,0))) -> 0 | M31: =IF(AND(K31>J31,K32>J32),2,IF(K31>J31,1,IF(K32>J32,1,0))) -> 2
J32: 4 | K32: 6
C34: 6.00pm | D34: Men B | E34: James Camilleri | F34: Clint Agius | G34: vs | H34: Ivan Cachia | I34: Stefan Holmin | J34: 4 | K34: 6 | L34: =IF(AND(J34>K34,J35>K35),2,IF(J34>K34,1,IF(J35>K35,1,0))) -> 1 | M34: =IF(AND(K34>J34,K35>J35),2,IF(K34>J34,1,IF(K35>J35,1,0))) -> 1
J35: 7 | K35: 5
C37: 3.30 pm | D37: Men D | E37: Adam Green | F37: Denis Caruana | G37: vs | H37: Joseph Randich | I37: Cory Greenland | J37: 6 | K37: 2 | L37: =IF(AND(J37>K37,J38>K38),2,IF(J37>K37,1,IF(J38>K38,1,0))) -> 2 | M37: =IF(AND(K37>J37,K38>J38),2,IF(K37>J37,1,IF(K38>J38,1,0))) -> 0
J38: 7 | K38: 5
C40: Total Day 2B | J40: =SUM(J28:J38) -> 37 | K40: =SUM(K28:K38) -> 42 | L40: =SUM(L28:L38) -> 3 | M40: =SUM(M28:M38) -> 5
C42: Total Day 2 | J42: =J40+J25 -> 87 | K42: =K40+K25 -> 81 | L42: =L40+L25 -> 9 | M42: =M40+M25 -> 7
C44: Court 2
C46: Time | D46: Rubber | E46: Team A: Gabriel Pace | G46: vs | H46: Team F: Lonia Carabott | J46: Games | L46: Sets
C48: 6.30 pm | D48: MXD | E48: Gabriel Pace | F48: Sharon Mizzi | G48: vs | H48: David Schembri | I48: Elaine Grech | J48: 6 | K48: 4 | L48: =IF(AND(J48>K48,J49>K49),2,IF(J48>K48,1,IF(J49>K49,1,0))) -> 1 | M48: =IF(AND(K48>J48,K49>J49),2,IF(K48>J48,1,IF(K49>J49,1,0))) -> 1
J49: 4 | K49: 6
C51: 7.45 pm | D51: Men B | E51: Gene Zammit | F51: Charles Sacco | G51: vs | H51: Ryan Mizzi | I51: Willem Steenkamer | J51: 5 | K51: 7 | L51: =IF(AND(J51>K51,J52>K52),2,IF(J51>K51,1,IF(J52>K52,1,0))) -> 0 | M51: =IF(AND(K51>J51,K52>J52),2,IF(K51>J51,1,IF(K52>J52,1,0))) -> 2
J52: 4 | K52: 6
C54: 9.00 pm | D54: Men A | E54: Marc Vella Bonnici | F54: Keith Micallef | G54: vs | H54: Kurt Carabott | I54: Nikolai Belli | J54: 1 | K54: 6 | L54: =IF(AND(J54>K54,J55>K55),2,IF(J54>K54,1,IF(J55>K55,1,0))) -> 1 | M54: =IF(AND(K54>J54,K55>J55),2,IF(K54>J54,1,IF(K55>J55,1,0))) -> 1
J55: 6 | K55: 4
C57: 7.45 pm | D57: Lad B | E57: Nancy Wong | F57: Kelsey Gauci | G57: vs | H57: Kristina Briffa | I57: Diane Fenech | J57: 0 | K57: 6 | L57: =IF(AND(J57>K57,J58>K58),2,IF(J57>K57,1,IF(J58>K58,1,0))) -> 0 | M57: =IF(AND(K57>J57,K58>J58),2,IF(K57>J57,1,IF(K58>J58,1,0))) -> 2
J58: 1 | K58: 6
C60: Total Day 2 A | J60: =SUM(J48:J58) -> 27 | K60: =SUM(K48:K58) -> 45 | L60: =SUM(L48:L58) -> 2 | M60: =SUM(M48:M58) -> 6
C63: 3.30 pm | D63: Men D | E63: Charles Micallef | F63: Sean Cachia | G63: vs | H63: Kenneth Caruana | I63: Charles Borg Grech | J63: 3 | K63: 6 | L63: =IF(AND(J63>K63,J64>K64),2,IF(J63>K63,1,IF(J64>K64,1,0))) -> 0 | M63: =IF(AND(K63>J63,K64>J64),2,IF(K63>J63,1,IF(K64>J64,1,0))) -> 2
J64: 3 | K64: 6
C66: 4.45 pm | D66: Men C | E66: Jean Paul Vella | F66: Darrell Pace | G66: vs | H66: Artiom Kiricenko | I66: Julian Esposito | J66: 1 | K66: 6 | L66: =IF(AND(J66>K66,J67>K67),2,IF(J66>K66,1,IF(J67>K67,1,0))) -> 0 | M66: =IF(AND(K66>J66,K67>J67),2,IF(K66>J66,1,IF(K67>J67,1,0))) -> 2
J67: 4 | K67: 6
C69: 6.00 pm | D69: Lad A | E69: Olivia Belli | F69: Kirsty Mercieca | G69: vs | H69: Anthea Gauci | I69: Dorianne Buhagiar | J69: 6 | K69: 7 | L69: =IF(AND(J69>K69,J70>K70),2,IF(J69>K69,1,IF(J70>K70,1,0))) -> 1 | M69: =IF(AND(K69>J69,K70>J70),2,IF(K69>J69,1,IF(K70>J70,1,0))) -> 1
J70: 6 | K70: 3
...

Sheet Day 3
B1: z | C1: SAN MICHEL TEAM TOURNAMENT 2023
C6: DAY 3 - 06/02/2023, 08/02/2023 & 11/02/2023
C9: Court 1
C11: Time | D11: Rubber | E11: TEAM C: Lucienne Meli | G11: vs | H11: TEAM F: Lonia Carabott | J11: Games | L11: Sets
C13: 6.30 pm | D13: MXD | E13: Jonathan Vella | F13: Mariska Steenkamer | G13: vs | H13: David Schembri | I13: Dorianne Buhagiar | J13: 2 | K13: 6 | L13: =IF(AND(J13>K13,J14>K14),2,IF(J13>K13,1,IF(J14>K14,1,0))) -> 0 | M13: =IF(AND(K13>J13,K14>J14),2,IF(K13>J13,1,IF(K14>J14,1,0))) -> 2
J14: 3 | K14: 6
C16: 7.45 pm | D16: Men D | E16: Ahmed Elnakroud | F16: Eman Meli | G16: vs | H16: Kenneth Caruana | I16: Charles Borg Grech | J16: 2 | K16: 6 | L16: =IF(AND(J16>K16,J17>K17),2,IF(J16>K16,1,IF(J17>K17,1,0))) -> 0 | M16: =IF(AND(K16>J16,K17>J17),2,IF(K16>J16,1,IF(K17>J17,1,0))) -> 2
J17: 1 | K17: 6
C19: 9.00 pm | D19: Men A | E19: Matthew Mifsud | F19: Massimo Giovannini | G19: vs | H19: Melchior Farrugia | I19: Nikolai Belli | J19: 3 | K19: 6 | L19: =IF(AND(J19>K19,J20>K20),2,IF(J19>K19,1,IF(J20>K20,1,0))) -> 0 | M19: =IF(AND(K19>J19,K20>J20),2,IF(K19>J19,1,IF(K20>J20,1,0))) -> 2
J20: 1 | K20: 6
C22: 9.00 pm | D22: Lad A | E22: Ann Marie Mangion | F22: Annabelle Abela | G22: vs | H22: Martina Cuschieri | I22: Elaine Grech | J22: 2 | K22: 6 | L22: =IF(AND(J22>K22,J23>K23),2,IF(J22>K22,1,IF(J23>K23,1,0))) -> 0 | M22: =IF(AND(K22>J22,K23>J23),2,IF(K22>J22,1,IF(K23>J23,1,0))) -> 2
J23: 2 | K23: 6
C25: Total Day 3 A | J25: =SUM(J13:J23) -> 16 | K25: =SUM(K13:K23) -> 48 | L25: =SUM(L13:L23) -> 0 | M25: =SUM(M13:M23) -> 8
C28: 3.30 pm | D28: Men C | E28: Victor Rutter | F28: Ray Ciantar | G28: vs | H28: Artium Kiricenko | I28: Julian Esposito | J28: 5 | K28: 7 | L28: =IF(AND(J28>K28,J29>K29),2,IF(J28>K28,1,IF(J29>K29,1,0))) -> 0 | M28: =IF(AND(K28>J28,K29>J29),2,IF(K28>J28,1,IF(K29>J29,1,0))) -> 2
J29: 2 | K29: 6
C31: 4.45 pm | D31: Lad C | E31: Mary Borg | F31: Josette Cassar | G31: vs | H31: Julie Spiteri | I31: Christine Scerri | J31: 6 | K31: 2 | L31: =IF(AND(J31>K31,J32>K32),2,IF(J31>K31,1,IF(J32>K32,1,0))) -> 1 | M31: =IF(AND(K31>J31,K32>J32),2,IF(K31>J31,1,IF(K32>J32,1,0))) -> 1
J32: 4 | K32: 6
C34: 6.00 pm | D34: Lad B | E34: Jennifer Roca | F34: Anabel Borg | G34: vs | H34: Lonia Carabott | I34: Diane Fenech | J34: 7 | K34: 5 | L34: =IF(AND(J34>K34,J35>K35),2,IF(J34>K34,1,IF(J35>K35,1,0))) -> 1 | M34: =IF(AND(K34>J34,K35>J35),2,IF(K34>J34,1,IF(K35>J35,1,0))) -> 1
J35: 4 | K35: 6
C37: 3.00 pm | D37: Men B | E37: Richard Curmi | F37: Stephen Belli | G37: vs | H37: Willem Steenkamer | I37: Jonathan Martinelli | J37: 4 | K37: 6 | L37: =IF(AND(J37>K37,J38>K38),2,IF(J37>K37,1,IF(J38>K38,1,0))) -> 1 | M37: =IF(AND(K37>J37,K38>J38),2,IF(K37>J37,1,IF(K38>J38,1,0))) -> 1
J38: 6 | K38: 3
C40: Total Day 3B | J40: =SUM(J28:J38) -> 38 | K40: =SUM(K28:K38) -> 41 | L40: =SUM(L28:L38) -> 3 | M40: =SUM(M28:M38) -> 5
C42: Total Day 3 | J42: =J40+J25 -> 54 | K42: =K40+K25 -> 89 | L42: =L40+L25 -> 3 | M42: =M40+M25 -> 13
C44: Court 2
C46: Time | D46: Rubber | E46: TEAM D: Roberto Murdocco | G46: vs | H46: TEAM B: Frans Ellul | J46: Games | L46: Sets
C48: 6.30 pm | D48: Lad C | E48: Anna Napier | F48: Claire Genovese | G48: vs | H48: Anna Ancilleri | I48: Rose Falzon | J48: 6 | K48: 0 | L48: =IF(AND(J48>K48,J49>K49),2,IF(J48>K48,1,IF(J49>K49,1,0))) -> 2 | M48: =IF(AND(K48>J48,K49>J49),2,IF(K48>J48,1,IF(K49>J49,1,0))) -> 0
J49: 6 | K49: 2
C51: 7.45 pm | D51: Men C | E51: Sebastian Attard | F51: Kristen Cachia | G51: vs | H51: Juan Debono | I51: Max Anastasi Jr | J51: 7 | K51: 5 | L51: =IF(AND(J51>K51,J52>K52),2,IF(J51>K51,1,IF(J52>K52,1,0))) -> 1 | M51: =IF(AND(K51>J51,K52>J52),2,IF(K51>J51,1,IF(K52>J52,1,0))) -> 1
J52: 3 | K52: 6
C54: 9.00 pm | D54: MXD | E54: Kevin Formosa | F54: Pierina Holmin | G54: vs | H54: James Farrugia | I54: Brenda Baldacchino | J54: 7 | K54: 5 | L54: =IF(AND(J54>K54,J55>K55),2,IF(J54>K54,1,IF(J55>K55,1,0))) -> 2 | M54: =IF(AND(K54>J54,K55>J55),2,IF(K54>J54,1,IF(K55>J55,1,0))) -> 0
J55: 6 | K55: 1
D57: Men D | E57: Simone Re | F57: Donald Deguzman | G57: vs | H57: Adam Green | I57: Denis Caruana | J57: 3 | K57: 6 | L57: =IF(AND(J57>K57,J58>K58),2,IF(J57>K57,1,IF(J58>K58,1,0))) -> 0 | M57: =IF(AND(K57>J57,K58>J58),2,IF(K57>J57,1,IF(K58>J58,1,0))) -> 2
J58: 0 | K58: 6
C60: Total Day 3 A | J60: =SUM(J48:J58) -> 38 | K60: =SUM(K48:K58) -> 31 | L60: =SUM(L48:L58) -> 5 | M60: =SUM(M48:M58) -> 3
C63: 3.30 pm | D63: Men B | E63: Fotios Evangelou | F63: Manuel Gatt | G63: vs | H63: Georges Meekers | I63: Julian Bilocca | J63: 7 | K63: 5 | L63: =IF(AND(J63>K63,J64>K64),2,IF(J63>K63,1,IF(J64>K64,1,0))) -> 2 | M63: =IF(AND(K63>J63,K64>J64),2,IF(K63>J63,1,IF(K64>J64,1,0))) -> 0
J64: 6 | K64: 1
C66: 4.45 pm | D66: Lad B | E66: Anna Buhagiar | F66: Ceridwen Scerri | G66: vs | H66: Ann-Marie Attard | I66: Francesca Sciortino | J66: 2 | K66: 6 | L66: =IF(AND(J66>K66,J67>K67),2,IF(J66>K66,1,IF(J67>K67,1,0))) -> 0 | M66: =IF(AND(K66>J66,K67>J67),2,IF(K66>J66,1,IF(K67>J67,1,0))) -> 2
J67: 1 | K67: 6
C69: 6.00 pm | D69: Lad A | E69: Nicole Meli | F69: Alexia Gouder | G69: vs | H69: Christine Schembri | I69: Yasmine Hefny | J69: 4 | K69: 6 | L69: =IF(AND(J69>K69,J70>K70),2,IF(J69>K69,1,IF(J70>K70,1,0))) -> 0 | M69: =IF(AND(K69>J69,K70>J70),2,IF(K69>J69,1,IF(K70>J70,1,0))) -> 2
J70: 2 | K70: 6
...

Sheet Day 4
C1: SAN MICHEL TEAM TOURNAMENT 2023
C6: DAY 4 - 17/02/2023 & 18/02/2023
C9: Court 1
C11: Time | D11: Rubber | E11: Team D: Roberto Murdocco | H11: Team F: Lonia Carabott | J11: Games | L11: Sets
C13: 6.30 pm | D13: Men B | E13: Kevin Formosa | F13: Roberto Murdocco | G13: vs | H13: David Schembri | I13: Ryan Mizzi | J13: 3 | K13: 6 | L13: =IF(AND(J13>K13,J14>K14),2,IF(J13>K13,1,IF(J14>K14,1,0))) -> 0 | M13: =IF(AND(K13>J13,K14>J14),2,IF(K13>J13,1,IF(K14>J14,1,0))) -> 2
J14: 5 | K14: 7
C16: 7.45 pm | D16: Lad A | E16: Pierina Holmin | F16: Aleixa Gouder | G16: vs | H16: Martina Cuschieri | I16: Elaine Grech | J16: 3 | K16: 6 | L16: =IF(AND(J16>K16,J17>K17),2,IF(J16>K16,1,IF(J17>K17,1,0))) -> 0 | M16: =IF(AND(K16>J16,K17>J17),2,IF(K16>J16,1,IF(K17>J17,1,0))) -> 2
J17: 1 | K17: 6
C19: 9.00 pm | D19: Men A | E19: Duncan D'Allessandro | F19: Luigi Porto | G19: vs | H19: Kurt Carabott | I19: Melchior Farrugia | J19: 1 | K19: 6 | L19: =IF(AND(J19>K19,J20>K20),2,IF(J19>K19,1,IF(J20>K20,1,0))) -> 0 | M19: =IF(AND(K19>J19,K20>J20),2,IF(K19>J19,1,IF(K20>J20,1,0))) -> 2
J20: 2 | K20: 6
C22: 7.45 pm | D22: Lad B | E22: Sarah Axiaq | F22: Ceridwen Scerri | G22: vs | H22: Kristina Briffa | I22: Julie Spiteri (PRO Lonia Carabott) | J22: 6 | K22: 2 | L22: =IF(AND(J22>K22,J23>K23),2,IF(J22>K22,1,IF(J23>K23,1,0))) -> 1 | M22: =IF(AND(K22>J22,K23>J23),2,IF(K22>J22,1,IF(K23>J23,1,0))) -> 1
J23: 4 | K23: 6
C25: Total Day 4 A | J25: =SUM(J13:J23) -> 25 | K25: =SUM(K13:K23) -> 45 | L25: =SUM(L13:L23) -> 1 | M25: =SUM(M13:M23) -> 7
C28: 3.30 pm | D28: Lad C | E28: Anna Casingena | F28: Anna Napier | G28: vs | H28: Christine Scerri | I28: Anna Fenech | J28: 6 | K28: 1 | L28: =IF(AND(J28>K28,J29>K29),2,IF(J28>K28,1,IF(J29>K29,1,0))) -> 2 | M28: =IF(AND(K28>J28,K29>J29),2,IF(K28>J28,1,IF(K29>J29,1,0))) -> 0
J29: 6 | K29: 2
C31: 4.45 pm | D31: MXD BA | E31: Manuel Gatt | F31: Romina Gauci | G31: vs | H31: Willem Steenkamer | I31: Dorianne Buhagiar | J31: 6 | K31: 3 | L31: =IF(AND(J31>K31,J32>K32),2,IF(J31>K31,1,IF(J32>K32,1,0))) -> 2 | M31: =IF(AND(K31>J31,K32>J32),2,IF(K31>J31,1,IF(K32>J32,1,0))) -> 0
J32: 6 | K32: 3
C34: 6.00 pm | D34: Men C | E34: Sebastian Attard | F34: Ryan Ebejer | G34: vs | H34: Julian Esposito | I34: Charles Borg Grech (Pro Max Anastasi) | J34: 6 | K34: 3 | L34: =IF(AND(J34>K34,J35>K35),2,IF(J34>K34,1,IF(J35>K35,1,0))) -> 1 | M34: =IF(AND(K34>J34,K35>J35),2,IF(K34>J34,1,IF(K35>J35,1,0))) -> 1
J35: 3 | K35: 6
C37: 3.00 pm | D37: Men D | E37: Simone Re | F37: David Camilleri | G37: vs | H37: Kenneth Caruana | I37: Charles Borg Grech | J37: 7 | K37: 5 | L37: =IF(AND(J37>K37,J38>K38),2,IF(J37>K37,1,IF(J38>K38,1,0))) -> 2 | M37: =IF(AND(K37>J37,K38>J38),2,IF(K37>J37,1,IF(K38>J38,1,0))) -> 0
J38: 6 | K38: 2
C40: Total Day 4B | J40: =SUM(J28:J38) -> 46 | K40: =SUM(K28:K38) -> 25 | L40: =SUM(L28:L38) -> 7 | M40: =SUM(M28:M38) -> 1
C42: Total Day 4 | J42: =J40+J25 -> 71 | K42: =K40+K25 -> 70 | L42: =L40+L25 -> 8 | M42: =M40+M25 -> 8
C44: Court 2
C46: Time | D46: Rubber | E46: TEAM C: Lucienne Meli | H46: TEAM E: Aaron Micallef Piccione | J46: Games | L46: Sets
C48: 6.30 pm | D48: MXD BA | E48: Jonathan Vella | F48: Lucienne Meli | G48: vs | H48: George Grech | I48: Alison Muscat | J48: 5 | K48: 7 | L48: =IF(AND(J48>K48,J49>K49),2,IF(J48>K48,1,IF(J49>K49,1,0))) -> 1 | M48: =IF(AND(K48>J48,K49>J49),2,IF(K48>J48,1,IF(K49>J49,1,0))) -> 1
J49: 7 | K49: 6
C50: 6
C51: 7.45 pm | D51: Lad C | E51: Mary Borg | F51: Jean Frendo | G51: vs | H51: Christine Seychell | I51: Christabelle Chetcuti | J51: 6 | K51: 7 | L51: =IF(AND(J51>K51,J52>K52),2,IF(J51>K51,1,IF(J52>K52,1,0))) -> 0 | M51: =IF(AND(K51>J51,K52>J52),2,IF(K51>J51,1,IF(K52>J52,1,0))) -> 2
J52: 4 | K52: 6
C54: 9.00 pm | D54: Men C | E54: Victor Rutter | F54: Joe Carabott | G54: vs | H54: Matthew Schembri | I54: Ivan Saliba | J54: 6 | K54: 3 | L54: =IF(AND(J54>K54,J55>K55),2,IF(J54>K54,1,IF(J55>K55,1,0))) -> 2 | M54: =IF(AND(K54>J54,K55>J55),2,IF(K54>J54,1,IF(K55>J55,1,0))) -> 0
J55: 6 | K55: 3
C57: 6.30 pm | D57: Men D | E57: Ahmed El Nakraud | F57: Eman Meli | G57: vs | H57: Joseph Randich | I57: Cory Greenland | J57: 2 | K57: 6 | L57: =IF(AND(J57>K57,J58>K58),2,IF(J57>K57,1,IF(J58>K58,1,0))) -> 0 | M57: =IF(AND(K57>J57,K58>J58),2,IF(K57>J57,1,IF(K58>J58,1,0))) -> 2
J58: 0 | K58: 6
C60: Total Day 4 A | J60: =SUM(J48:J58) -> 36 | K60: =SUM(K48:K58) -> 44 | L60: =SUM(L48:L58) -> 3 | M60: =SUM(M48:M58) -> 5
C63: 3.30 pm | D63: Men B | E63: Richard Byrne | F63: Jonathan Vella (Richard Curmi) | G63: vs | H63: Ivan Cachia | I63: Stefan Holmin | J63: 6 | K63: 7 | L63: =IF(AND(J63>K63,J64>K64),2,IF(J63>K63,1,IF(J64>K64,1,0))) -> 0 | M63: =IF(AND(K63>J63,K64>J64),2,IF(K63>J63,1,IF(K64>J64,1,0))) -> 2
J64: 6 | K64: 7
C66: 4.45 pm | D66: Men A | E66: Matthew Mifsud | F66: Trevor Rutter | G66: vs | H66: Clyde Grech | I66: Marco Mercieca | J66: 6 | K66: 0 | L66: =IF(AND(J66>K66,J67>K67),2,IF(J66>K66,1,IF(J67>K67,1,0))) -> 2 | M66: =IF(AND(K66>J66,K67>J67),2,IF(K66>J66,1,IF(K67>J67,1,0))) -> 0
J67: 6 | K67: 3
C69: 6.00 pm | D69: Lad B | E69: Anabel Borg | F69: Carmen Difesa | G69: vs | H69: Marthese Camoin | I69: Ruth Micallef | J69: 7 | K69: 5 | L69: =IF(AND(J69>K69,J70>K70),2,IF(J69>K69,1,IF(J70>K70,1,0))) -> 1 | M69: =IF(AND(K69>J69,K70>J70),2,IF(K69>J69,1,IF(K70>J70,1,0))) -> 1
...

Sheet Day 5
C1: SAN MICHEL TEAM TOURNAMENT 2023
C6: DAY 5 - 03/03/2023 & 04/03/2023
C9: Court 1
C11: Time | D11: Rubber | E11: TEAM A: Gabriel Pace | H11: TEAM D: Roberto Murdocco | J11: Games | L11: Sets
C13: 6.30pm | D13: Lad C | E13: Jodie Stivala | F13: Stephanie Hercegovac | G13: vs | H13: Anna Casingena | I13: Anna Napier | J13: 0 | K13: 6 | L13: =IF(AND(J13>K13,J14>K14),2,IF(J13>K13,1,IF(J14>K14,1,0))) -> 0 | M13: =IF(AND(K13>J13,K14>J14),2,IF(K13>J13,1,IF(K14>J14,1,0))) -> 2
J14: 1 | K14: 6
C16: 7.45pm | D16: MXD BA | E16: Gene Zammit | F16: Sharon Mizzi | G16: vs | H16: Roberto Murdocco | I16: Alexia Gouder | J16: 6 | K16: 3 | L16: =IF(AND(J16>K16,J17>K17),2,IF(J16>K16,1,IF(J17>K17,1,0))) -> 2 | M16: =IF(AND(K16>J16,K17>J17),2,IF(K16>J16,1,IF(K17>J17,1,0))) -> 0
J17: 6 | K17: 1
C19: 9.00pm | D19: Men B | E19: Earvin Grech Meli | F19: Gabriel Pace | G19: vs | H19: Fotios Evangelou | I19: Kevin Formosa | J19: 1 | K19: 6 | L19: =IF(AND(J19>K19,J20>K20),2,IF(J19>K19,1,IF(J20>K20,1,0))) -> 0 | M19: =IF(AND(K19>J19,K20>J20),2,IF(K19>J19,1,IF(K20>J20,1,0))) -> 2
J20: 1 | K20: 6
D22: Men D | E22: Twanny Pule' | F22: Sean Cachia | G22: vs | H22: David Camilleri | I22: Donald Deguzman | J22: 7 | K22: 6 | L22: =IF(AND(J22>K22,J23>K23),2,IF(J22>K22,1,IF(J23>K23,1,0))) -> 1 | M22: =IF(AND(K22>J22,K23>J23),2,IF(K22>J22,1,IF(K23>J23,1,0))) -> 1
J23: 4 | K23: 6
C25: Total Day 5 A | J25: =SUM(J13:J23) -> 26 | K25: =SUM(K13:K23) -> 40 | L25: =SUM(L13:L23) -> 3 | M25: =SUM(M13:M23) -> 5
C28: 3.30pm | D28: Men A | E28: Marc Vella Bonnici | F28: Andrew Pule' | G28: vs | H28: Jesmond Pule' | I28: Luigi Porto | J28: 6 | K28: 4 | L28: =IF(AND(J28>K28,J29>K29),2,IF(J28>K28,1,IF(J29>K29,1,0))) -> 2 | M28: =IF(AND(K28>J28,K29>J29),2,IF(K28>J28,1,IF(K29>J29,1,0))) -> 0
J29: 6 | K29: 4
C31: 4.45pm | D31: Men C | E31: Maurice Borg | F31: Jean Paul Vella | G31: vs | H31: Ryan Ebejer | I31: Kristen Cachia | J31: 2 | K31: 6 | L31: =IF(AND(J31>K31,J32>K32),2,IF(J31>K31,1,IF(J32>K32,1,0))) -> 0 | M31: =IF(AND(K31>J31,K32>J32),2,IF(K31>J31,1,IF(K32>J32,1,0))) -> 2
J32: 6 | K32: 7
C34: 7.00pm | D34: Lad A | E34: Olivia Belli | F34: Kirsty Mercieca | G34: vs | H34: Nicole Fava | I34: Romina Gauci | J34: 6 | K34: 1 | L34: =IF(AND(J34>K34,J35>K35),2,IF(J34>K34,1,IF(J35>K35,1,0))) -> 2 | M34: =IF(AND(K34>J34,K35>J35),2,IF(K34>J34,1,IF(K35>J35,1,0))) -> 0
J35: 6 | K35: 3
C37: 3.30pm | D37: Lad B | E37: Kelsey Gauci | F37: Deborah Farrugia | G37: vs | H37: Anna Buhagiar | I37: Sarah Axiaq | J37: 6 | K37: 3 | L37: =IF(AND(J37>K37,J38>K38),2,IF(J37>K37,1,IF(J38>K38,1,0))) -> 2 | M37: =IF(AND(K37>J37,K38>J38),2,IF(K37>J37,1,IF(K38>J38,1,0))) -> 0
J38: 6 | K38: 2
C40: Total Day 5B | J40: =SUM(J28:J38) -> 44 | K40: =SUM(K28:K38) -> 30 | L40: =SUM(L28:L38) -> 6 | M40: =SUM(M28:M38) -> 2
C42: Total Day 5 | J42: =J40+J25 -> 70 | K42: =K40+K25 -> 70 | L42: =L40+L25 -> 9 | M42: =M40+M25 -> 7
C44: Court 2
C46: Time | D46: Rubber | E46: TEAM B: Frans Ellul | H46: TEAM C: Lucienne Meli | J46: Games | L46: Sets
C48: 6.30 pm | D48: Men C | E48: Alain Frendo | F48: Max Anastasi Jr | G48: vs | H48: Ray Ciantar | I48: Victor Rutter | J48: 0 | K48: 6 | L48: =IF(AND(J48>K48,J49>K49),2,IF(J48>K48,1,IF(J49>K49,1,0))) -> 0 | M48: =IF(AND(K48>J48,K49>J49),2,IF(K48>J48,1,IF(K49>J49,1,0))) -> 2
J49: 0 | K49: 6 | N49: w/o
C51: 7.45 pm | D51: Men B | E51: Clint Agius | F51: James Farrugia | G51: vs | H51: Richard Byrne | I51: Stephen Belli | J51: 6 | K51: 2 | L51: =IF(AND(J51>K51,J52>K52),2,IF(J51>K51,1,IF(J52>K52,1,0))) -> 2 | M51: =IF(AND(K51>J51,K52>J52),2,IF(K51>J51,1,IF(K52>J52,1,0))) -> 0
J52: 6 | K52: 4
C54: 9.00 pm | D54: Lad A | E54: Celeste Zammit Marquette | F54: Yasmine Hefny | G54: vs | H54: Ann Marie Mangion | I54: Lucienne Meli | J54: 2 | K54: 6 | L54: =IF(AND(J54>K54,J55>K55),2,IF(J54>K54,1,IF(J55>K55,1,0))) -> 0 | M54: =IF(AND(K54>J54,K55>J55),2,IF(K54>J54,1,IF(K55>J55,1,0))) -> 2
J55: 5 | K55: 7
C57: 7.45 pm | D57: Lad B | E57: Francesca Sciortino | F57: Ann-Marie Attard | G57: vs | H57: Jennifer Roca | I57: Carmen Difesa | J57: 6 | K57: 3 | L57: =IF(AND(J57>K57,J58>K58),2,IF(J57>K57,1,IF(J58>K58,1,0))) -> 2 | M57: =IF(AND(K57>J57,K58>J58),2,IF(K57>J57,1,IF(K58>J58,1,0))) -> 0
J58: 6 | K58: 3
C60: Total Day 5 A | J60: =SUM(J48:J58) -> 31 | K60: =SUM(K48:K58) -> 37 | L60: =SUM(L48:L58) -> 4 | M60: =SUM(M48:M58) -> 4
C63: 3.30 pm | D63: Lad C | E63: Stefania Camilleri | F63: Anna Ancilleri | G63: vs | H63: Josette Cassar | I63: Jean Frendo | J63: 6 | K63: 4 | L63: =IF(AND(J63>K63,J64>K64),2,IF(J63>K63,1,IF(J64>K64,1,0))) -> 2 | M63: =IF(AND(K63>J63,K64>J64),2,IF(K63>J63,1,IF(K64>J64,1,0))) -> 0
J64: 7 | K64: 6
C66: 4.45pm | D66: MXD | E66: Brenda Baldacchino | F66: Julian Bilocca | G66: vs | H66: Richard Curmi | I66: Mariska Steenkamer | J66: 1 | K66: 6 | L66: =IF(AND(J66>K66,J67>K67),2,IF(J66>K66,1,IF(J67>K67,1,0))) -> 1 | M66: =IF(AND(K66>J66,K67>J67),2,IF(K66>J66,1,IF(K67>J67,1,0))) -> 1
J67: 6 | K67: 4
C69: 6.00pm | D69: Men A | E69: Marcelo Villanueva | F69: Eric Roca | G69: vs | H69: Trevor Rutter | I69: Massimo Giovanni | J69: 6 | K69: 2 | L69: =IF(AND(J69>K69,J70>K70),2,IF(J69>K69,1,IF(J70>K70,1,0))) -> 2 | M69: =IF(AND(K69>J69,K70>J70),2,IF(K69>J69,1,IF(K70>J70,1,0))) -> 0
J70: 6 | K70: 3
...

Sheet Day 6
C1: SAN MICHEL TEAM TOURNAMENT 2023
C6: DAY 6 - 10/03/2023 & 24/03/2023
C9: Court 1
C11: Time | D11: Rubber | E11: TEAM A: Gabriel Pace | H11: TEAM C: Lucienne Meli | J11: Games | L11: Sets
C13: 6.30 pm | D13: Lad B | E13: Nancy Wong | F13: Kelsey Gauci | G13: vs | H13: Anabel Borg | I13: Carmen Difesa | J13: 7 | K13: 6 | L13: =IF(AND(J13>K13,J14>K14),2,IF(J13>K13,1,IF(J14>K14,1,0))) -> 1 | M13: =IF(AND(K13>J13,K14>J14),2,IF(K13>J13,1,IF(K14>J14,1,0))) -> 1
J14: 3 | K14: 6
C16: 7.45 pm | D16: Men C | E16: Maurice Borg | F16: Darrell Pace | G16: vs | H16: Joe Carabott | I16: Ray Ciantar | J16: 2 | K16: 6 | L16: =IF(AND(J16>K16,J17>K17),2,IF(J16>K16,1,IF(J17>K17,1,0))) -> 0 | M16: =IF(AND(K16>J16,K17>J17),2,IF(K16>J16,1,IF(K17>J17,1,0))) -> 2
J17: 3 | K17: 6
C19: 9.00 pm | D19: Mxd BA | E19: Earvin Grech Meli | F19: Silvana Portelli | G19: vs | H19: Jonathan Vella | I19: Annabelle Abela | J19: 4 | K19: 6 | L19: =IF(AND(J19>K19,J20>K20),2,IF(J19>K19,1,IF(J20>K20,1,0))) -> 0 | M19: =IF(AND(K19>J19,K20>J20),2,IF(K19>J19,1,IF(K20>J20,1,0))) -> 2
J20: 0 | K20: 6
C22: 6.30 pm | D22: Men D | E22: Twanny Pule' | F22: Charles Micallef | G22: vs | H22: Charles Grech | I22: Eman Meli | J22: 6 | K22: 4 | L22: =IF(AND(J22>K22,J23>K23),2,IF(J22>K22,1,IF(J23>K23,1,0))) -> 2 | M22: =IF(AND(K22>J22,K23>J23),2,IF(K22>J22,1,IF(K23>J23,1,0))) -> 0
J23: 6 | K23: 2
C25: Total Day 6 A | J25: =SUM(J13:J23) -> 31 | K25: =SUM(K13:K23) -> 42 | L25: =SUM(L13:L23) -> 3 | M25: =SUM(M13:M23) -> 5
C28: 3.00 pm | D28: Men A | E28: Marc Vella Bonnici | F28: Keith Micallef | G28: vs | H28: Matthew Mifsud | I28: Massimo Giovannini | J28: 6 | K28: 4 | L28: =IF(AND(J28>K28,J29>K29),2,IF(J28>K28,1,IF(J29>K29,1,0))) -> 2 | M28: =IF(AND(K28>J28,K29>J29),2,IF(K28>J28,1,IF(K29>J29,1,0))) -> 0
J29: 6 | K29: 4
C31: 4.15 pm | D31: Lad A | E31: Sharon Mizzi | F31: Olivia Belli | G31: vs | H31: Ann Marie Mangion | I31: Lucienne Meli Bellizzi | J31: 7 | K31: 6 | L31: =IF(AND(J31>K31,J32>K32),2,IF(J31>K31,1,IF(J32>K32,1,0))) -> 1 | M31: =IF(AND(K31>J31,K32>J32),2,IF(K31>J31,1,IF(K32>J32,1,0))) -> 1
J32: 4 | K32: 6
C34: 5.30 pm | D34: Men B | E34: Gene Zammit | F34: Charles Sacco | G34: vs | H34: Richard Curmi | I34: Richard Byrne | J34: 2 | K34: 6 | L34: =IF(AND(J34>K34,J35>K35),2,IF(J34>K34,1,IF(J35>K35,1,0))) -> 0 | M34: =IF(AND(K34>J34,K35>J35),2,IF(K34>J34,1,IF(K35>J35,1,0))) -> 2
J35: 1 | K35: 6
C37: 3.00 pm | D37: Lad C | E37: Eilsa Sacco | F37: Jodie Stivala | G37: vs | H37: Mary Borg | I37: Josette Cassar | J37: 3 | K37: 6 | L37: =IF(AND(J37>K37,J38>K38),2,IF(J37>K37,1,IF(J38>K38,1,0))) -> 1 | M37: =IF(AND(K37>J37,K38>J38),2,IF(K37>J37,1,IF(K38>J38,1,0))) -> 1
J38: 6 | K38: 2
C40: Total Day 6B | J40: =SUM(J28:J38) -> 35 | K40: =SUM(K28:K38) -> 40 | L40: =SUM(L28:L38) -> 4 | M40: =SUM(M28:M38) -> 4
C42: Total Day 6 | J42: =J40+J25 -> 66 | K42: =K40+K25 -> 82 | L42: =L40+L25 -> 7 | M42: =M40+M25 -> 9
C44: Court 2
C46: Time | D46: Rubber | E46: TEAM D: Roberto Murdocco | H46: TEAM E: Aaron Micallef Piccione | J46: Games | L46: Sets
C48: 6.30 pm | D48: Lad C | E48: Anna Casingena | F48: Claire Genovese | G48: vs | H48: Christine Seychell | I48: Christabelle Chetcuti | J48: 4 | K48: 6 | L48: =IF(AND(J48>K48,J49>K49),2,IF(J48>K48,1,IF(J49>K49,1,0))) -> 0 | M48: =IF(AND(K48>J48,K49>J49),2,IF(K48>J48,1,IF(K49>J49,1,0))) -> 2
J49: 4 | K49: 6
C51: 7.45 pm | D51: Men B | E51: Fotios Evangelou | F51: Roberto Murdocco | G51: vs | H51: George Grech | I51: Stefan Holmin | J51: 6 | K51: 4 | L51: =IF(AND(J51>K51,J52>K52),2,IF(J51>K51,1,IF(J52>K52,1,0))) -> 1 | M51: =IF(AND(K51>J51,K52>J52),2,IF(K51>J51,1,IF(K52>J52,1,0))) -> 1
J52: 5 | K52: 7
C54: 8.00 pm | D54: Men A | E54: Duncan D'Alessandro | F54: Luigi Porto | G54: vs | H54: Adrian Chetcuti | I54: Marco Mercieca | J54: 4 | K54: 6 | L54: =IF(AND(J54>K54,J55>K55),2,IF(J54>K54,1,IF(J55>K55,1,0))) -> 0 | M54: =IF(AND(K54>J54,K55>J55),2,IF(K54>J54,1,IF(K55>J55,1,0))) -> 2
J55: 2 | K55: 6
C57: 7.45 pm | D57: Lad A | E57: Romina Gauci | F57: Alexia Gouder | G57: vs | H57: Alexia Spiteri Willets | I57: Alison Muscat | J57: 4 | K57: 6 | L57: =IF(AND(J57>K57,J58>K58),2,IF(J57>K57,1,IF(J58>K58,1,0))) -> 0 | M57: =IF(AND(K57>J57,K58>J58),2,IF(K57>J57,1,IF(K58>J58,1,0))) -> 2
J58: 3 | K58: 6
C60: Total Day 6 A | J60: =SUM(J48:J58) -> 32 | K60: =SUM(K48:K58) -> 47 | L60: =SUM(L48:L58) -> 1 | M60: =SUM(M48:M58) -> 7
C63: 3.00 pm | D63: Mxd BA | E63: Kevin Formosa | F63: Pierina Holmin | G63: vs | H63: Manuel Mifsud | I63: Natalya Abela | J63: 6 | K63: 3 | L63: 2 | M63: =IF(AND(K63>J63,K64>J64),2,IF(K63>J63,1,IF(K64>J64,1,0))) -> 0
J64: 6 | K64: 4
C66: 4.15 pm | D66: Lad B | E66: Anne Buhagiar | F66: Sarah Axiaq | G66: vs | H66: Ruth Micallef | I66: Jin Attard | J66: 6 | K66: 3 | L66: =IF(AND(J66>K66,J67>K67),2,IF(J66>K66,1,IF(J67>K67,1,0))) -> 1 | M66: =IF(AND(K66>J66,K67>J67),2,IF(K66>J66,1,IF(K67>J67,1,0))) -> 1
J67: 4 | K67: 6
C69: 5.30 pm | D69: Men D | E69: Donald Deguzman | F69: Simone Re | G69: vs | H69: Joseph Randich | I69: Cory Greenland | J69: 6 | K69: 3 | L69: =IF(AND(J69>K69,J70>K70),2,IF(J69>K69,1,IF(J70>K70,1,0))) -> 2 | M69: =IF(AND(K69>J69,K70>J70),2,IF(K69>J69,1,IF(K70>J70,1,0))) -> 0
J70: 6 | K70: 3
...

Sheet Day 7
C1: SAN MICHEL TEAM TOURNAMENT 2023
C6: DAY 7 - 17/03/2023 & 18/03/2023
C9: Court 1
C11: Time | D11: Rubber | E11: TEAM B: Frans Ellul | H11: TEAM E: Aaron Micallef Piccione | J11: Games | L11: Sets
C13: 6.30 pm | D13: Men B | E13: Clint Agius | F13: Julian Bilocca | G13: vs | H13: George Grech | I13: Manuel Mifsud | J13: 6 | K13: 4 | L13: =IF(AND(J13>K13,J14>K14),2,IF(J13>K13,1,IF(J14>K14,1,0))) -> 1 | M13: =IF(AND(K13>J13,K14>J14),2,IF(K13>J13,1,IF(K14>J14,1,0))) -> 1
J14: 4 | K14: 6
C16: 7.45 pm | D16: Men C | E16: Alain Frendo | F16: Max Anastasi Jr | G16: vs | H16: Ivan Saliba | I16: Aaron Micallef Piccione | J16: 3 | K16: 6 | L16: =IF(AND(J16>K16,J17>K17),2,IF(J16>K16,1,IF(J17>K17,1,0))) -> 0 | M16: =IF(AND(K16>J16,K17>J17),2,IF(K16>J16,1,IF(K17>J17,1,0))) -> 2
J17: 6 | K17: 7
C19: 9.00 pm | D19: Men D | E19: Denis Caruana | F19: Kenneth Farrugia | G19: vs | H19: Joseph Randich | I19: Adrian Duca | J19: 6 | K19: 4 | L19: =IF(AND(J19>K19,J20>K20),2,IF(J19>K19,1,IF(J20>K20,1,0))) -> 2 | M19: =IF(AND(K19>J19,K20>J20),2,IF(K19>J19,1,IF(K20>J20,1,0))) -> 0
J20: 6 | K20: 4
C22: 6.30 pm | D22: Lad B | E22: Francesca Sciortino | F22: Diane Debono | G22: vs | H22: Marthese Camoin | I22: Ruth Micallef | J22: 6 | K22: 7 | L22: =IF(AND(J22>K22,J23>K23),2,IF(J22>K22,1,IF(J23>K23,1,0))) -> 0 | M22: =IF(AND(K22>J22,K23>J23),2,IF(K22>J22,1,IF(K23>J23,1,0))) -> 2
J23: 0 | K23: 6
C25: Total Day 7 A | J25: =SUM(J13:J23) -> 37 | K25: =SUM(K13:K23) -> 44 | L25: =SUM(L13:L23) -> 3 | M25: =SUM(M13:M23) -> 5
C28: 3.30 pm | D28: Men A | E28: Marcelo Villanueva | F28: Reuben Borg | G28: vs | H28: Adrian Chetcuti | I28: John Azzopardi | J28: 4 | K28: 6 | L28: =IF(AND(J28>K28,J29>K29),2,IF(J28>K28,1,IF(J29>K29,1,0))) -> 1 | M28: =IF(AND(K28>J28,K29>J29),2,IF(K28>J28,1,IF(K29>J29,1,0))) -> 1
J29: 7 | K29: 5
C31: 4.45 pm | D31: MXD BA | E31: Georges Meekers | F31: Brenda Baldacchino | G31: vs | H31: Ivan Cachia | I31: Julia Barbara | J31: 4 | K31: 6 | L31: =IF(AND(J31>K31,J32>K32),2,IF(J31>K31,1,IF(J32>K32,1,0))) -> 0 | M31: =IF(AND(K31>J31,K32>J32),2,IF(K31>J31,1,IF(K32>J32,1,0))) -> 2
J32: 3 | K32: 6
C34: 6.00 pm | D34: Lad C | E34: Stefania Camilleri | F34: Anna Ancilleri | G34: vs | H34: Christine Seychell | I34: Christabelle Chetcuti | J34: 4 | K34: 6 | L34: =IF(AND(J34>K34,J35>K35),2,IF(J34>K34,1,IF(J35>K35,1,0))) -> 1 | M34: =IF(AND(K34>J34,K35>J35),2,IF(K34>J34,1,IF(K35>J35,1,0))) -> 1
J35: 7 | K35: 6
C37: 3.30 pm | D37: Lad A | E37: Yasmine Hefny | F37: Celeste Zammit Marquette (Pro Christine Schembri) | G37: vs | H37: Alexia Spiteri Willets | I37: Natalya Abela | J37: 5 | K37: 7 | L37: =IF(AND(J37>K37,J38>K38),2,IF(J37>K37,1,IF(J38>K38,1,0))) -> 0 | M37: =IF(AND(K37>J37,K38>J38),2,IF(K37>J37,1,IF(K38>J38,1,0))) -> 2
J38: 1 | K38: 6
C40: Total Day 7B | J40: =SUM(J28:J38) -> 35 | K40: =SUM(K28:K38) -> 48 | L40: =SUM(L28:L38) -> 2 | M40: =SUM(M28:M38) -> 6
C42: Total Day 7 | J42: =J40+J25 -> 72 | K42: =K40+K25 -> 92 | L42: =L40+L25 -> 5 | M42: =M40+M25 -> 11
C44: Court 2
C46: Time | D46: Rubber | E46: TEAM A: Gabriel Pace | H46: TEAM F: Lonia Carabott | J46: Games | L46: Sets
C48: 6.30 pm | D48: Men C | E48: Jean Paul Vella | F48: Darrell Pace | G48: vs | H48: Max Anastasi | I48: Julian Esposito | J48: 4 | K48: 6 | L48: =IF(AND(J48>K48,J49>K49),2,IF(J48>K48,1,IF(J49>K49,1,0))) -> 0 | M48: =IF(AND(K48>J48,K49>J49),2,IF(K48>J48,1,IF(K49>J49,1,0))) -> 2
J49: 0 | K49: 6
C51: 7.45 pm | D51: Lad A | E51: Olivia Belli | F51: Kirsty Mercieca | G51: vs | H51: Martina Cuschieri | I51: Anthea Gauci | J51: 6 | K51: 4 | L51: =IF(AND(J51>K51,J52>K52),2,IF(J51>K51,1,IF(J52>K52,1,0))) -> 1 | M51: =IF(AND(K51>J51,K52>J52),2,IF(K51>J51,1,IF(K52>J52,1,0))) -> 1
J52: 2 | K52: 6
C54: 9.00 pm | D54: Men B | E54: Earvin Grech Meli | F54: Charles Sacco | G54: vs | H54: Jonathan Martinelli | I54: Willem Steenkamer | J54: 2 | K54: 6 | L54: =IF(AND(J54>K54,J55>K55),2,IF(J54>K54,1,IF(J55>K55,1,0))) -> 0 | M54: =IF(AND(K54>J54,K55>J55),2,IF(K54>J54,1,IF(K55>J55,1,0))) -> 2
J55: 4 | K55: 6
C57: 7.45 pm | D57: Lad C | E57: Jodie Stivala | F57: Stephanie Hercegovac | G57: vs | H57: Christine Scerri | I57: Anna Fenech | J57: 5 | K57: 7 | L57: =IF(AND(J57>K57,J58>K58),2,IF(J57>K57,1,IF(J58>K58,1,0))) -> 1 | M57: =IF(AND(K57>J57,K58>J58),2,IF(K57>J57,1,IF(K58>J58,1,0))) -> 1
J58: 6 | K58: 3
C60: Total Day 7 A | J60: =SUM(J48:J58) -> 29 | K60: =SUM(K48:K58) -> 44 | L60: =SUM(L48:L58) -> 2 | M60: =SUM(M48:M58) -> 6
C63: 3.30 pm | D63: Lad B | E63: Kelsye Gauci | F63: Nancy Wong | G63: vs | H63: Diane Fenech | I63: Lonia Carabott | J63: 3 | K63: 6 | L63: =IF(AND(J63>K63,J64>K64),2,IF(J63>K63,1,IF(J64>K64,1,0))) -> 0 | M63: =IF(AND(K63>J63,K64>J64),2,IF(K63>J63,1,IF(K64>J64,1,0))) -> 2
J64: 3 | K64: 6
C66: 4.45 pm | D66: MXD BA | E66: Gabriel Pace | F66: Sharon Mizzi | G66: vs | H66: Ryan Mizzi | I66: Elaine Grech | J66: 6 | K66: 7 | L66: =IF(AND(J66>K66,J67>K67),2,IF(J66>K66,1,IF(J67>K67,1,0))) -> 0 | M66: =IF(AND(K66>J66,K67>J67),2,IF(K66>J66,1,IF(K67>J67,1,0))) -> 2
J67: 6 | K67: 7
C69: 6.00 pm | D69: Men A | E69: Marc Vella Bonnici | F69: Andrew Pule' | G69: vs | H69: Nikolai Belli | I69: Melchior Farrugia | J69: 6 | K69: 3 | L69: =IF(AND(J69>K69,J70>K70),2,IF(J69>K69,1,IF(J70>K70,1,0))) -> 2 | M69: =IF(AND(K69>J69,K70>J70),2,IF(K69>J69,1,IF(K70>J70,1,0))) -> 0
J70: 7 | K70: 5
...

Sheet Day 8
C1: SAN MICHEL TEAM TOURNAMENT 2023
C6: DAY 8 - 14/04/2023 & 15/04/2023
C9: Court 1
C11: Time | D11: Rubber | E11: TEAM C: Lucienne Meli | H11: TEAM F: Lonia Carabott | J11: Games | L11: Sets
C13: 6.30 pm | D13: Lad B | E13: Carmen Difesa | F13: Jennifer Roca | G13: vs | H13: Kristina Briffa | I13: Diane Fenech | J13: 4 | K13: 6 | L13: =IF(AND(J13>K13,J14>K14),2,IF(J13>K13,1,IF(J14>K14,1,0))) -> 0 | M13: =IF(AND(K13>J13,K14>J14),2,IF(K13>J13,1,IF(K14>J14,1,0))) -> 2
J14: 1 | K14: 6
C16: 7.45 pm | D16: Men C | E16: Joe Carabott | F16: Ray Ciantar | G16: vs | H16: Max Anastasi | I16: Artiom Kiricenko | J16: 2 | K16: 6 | L16: =IF(AND(J16>K16,J17>K17),2,IF(J16>K16,1,IF(J17>K17,1,0))) -> 0 | M16: =IF(AND(K16>J16,K17>J17),2,IF(K16>J16,1,IF(K17>J17,1,0))) -> 2
J17: 1 | K17: 6
C19: 9.00 pm | D19: Men A | E19: Matthew Mifsud | F19: Trevor Rutter | G19: vs | H19: Nikolai Belli | I19: Melchior Farrugia | J19: 6 | K19: 2 | L19: =IF(AND(J19>K19,J20>K20),2,IF(J19>K19,1,IF(J20>K20,1,0))) -> 2 | M19: =IF(AND(K19>J19,K20>J20),2,IF(K19>J19,1,IF(K20>J20,1,0))) -> 0
J20: 6 | K20: 0
C22: 6.30 pm | D22: Men B | E22: Richard Byrne | F22: Richard Curmi | G22: vs | H22: David Schembri | I22: Ryan Mizzi | J22: 2 | K22: 6 | L22: =IF(AND(J22>K22,J23>K23),2,IF(J22>K22,1,IF(J23>K23,1,0))) -> 0 | M22: =IF(AND(K22>J22,K23>J23),2,IF(K22>J22,1,IF(K23>J23,1,0))) -> 2
J23: 4 | K23: 6
C25: Total Day 8 A | J25: =SUM(J13:J23) -> 26 | K25: =SUM(K13:K23) -> 38 | L25: =SUM(L13:L23) -> 2 | M25: =SUM(M13:M23) -> 6
