Workbook

Sheet Players Men
A1: VITTORIOSA LAWN TENNIS CLUB
A2: Sports Experience Chosen Doubles 2025
B5: Men Division 1 - Group A
A6: 1 | B6: Duncan D'Alessandro/Clayton Zammit Cesare
A7: 2 | B7: Mark Gatt/Manuel Bonello
A8: 3 | B8: Gabriel Pace/Nikolai Belli
A9: 4 | B9: Trevor Rutter/Jean Carl Azzopardi
A10: 5 | B10: Matthew Mifsud/Melchior Farrugia
A11: 6 | B11: Eric Roca/Roderick Spiteri
B13: Men Division 2 - Group A
A14: 1 | B14: Fotis Evangelou/Kristen Cachia
A15: 2 | B15: Willem Steenkamer/Javier Villoria
A16: 3 | B16: Jonathan Vella/Clint Agius
A17: 4 | B17: Jonathan Martinelli/Luigi Porto
A18: 5 | B18: Ivan Cassar/Kurt Cassar
A19: 6 | B19: Peter Khiev/Sam Zammit
B21: Men Division 3 - Group A | E21: Men Division 3 - Group B
A22: 1 | B22: Roberto Murdocco/James Brincat | D22: 1 | E22: Dunstan Vella/Cyril Lastimosa
A23: 2 | B23: Neville Sciriha/Matthias Sciriha | D23: 2 | E23: Manuel Mifsud/Julian Esposito
A24: 3 | B24: Kenneth Farrugia/Juan Sammut | D24: 3 | E24: David Camilleri/Joseph Zammit
A25: 4 | B25: Simone Re/Ryan Ebejer | D25: 4 | E25: Cory Greenland/Christan Xuereb
A26: 5 | B26: Chris Vella/Matthew Micallef | D26: 5 | E26: Aaron Micallef Piccione/Clinton Cutajar
B28: Men Division 4 - Group A | E28: Men Division 4 - Group B
A29: 1 | B29: Steve Gambin/Luke Gambin | D29: 1 | E29: Clifford Debono/Glenn Micallef
A30: 2 | B30: JP Sciberras/Justin Scicluna | D30: 2 | E30: Robert Attard/ Isaac Baldacchino
A31: 3 | B31: Kevin Sciberras/Liam Vella | D31: 3 | E31: Matthias Cremona/Oliver Brincat
A32: 4 | B32: Conrad Treeby Ward/Mark Treeby Ward | D32: 4 | E32: Braydon Galea/Gabriel Gauci
A33: 5 | B33: Adam Green/Franco Montesin | D33: 5 | E33: Jason Lee Evans/Sammy Ben Tamer

Sheet Men Div 1
A1: VITTORIOSA LAWN TENNIS CLUB Sports Experience Chosen Doubles 2025
A5: Men Division 1
A7: Players | B7: Set Scores | H7: Tie | P7: Players | Q7: Set Scores | W7: Tie | AE7: Player | AF7: Matches Played | AG7: Points Overall | AH7: Games Won | AI7: Sets Won
B8: Score | C8: Set 1 Work | E8: Score | F8: Set 2 Work | H8: Score | I8: Tie Work | J8: Game Played | K8: Sets Points Work | L8: Sets & Tie Points Work | M8: Games Wins Work | N8: Sets Wins Work | Q8: Score | R8: Set 1 Work | T8: Score | U8: Set 2 Work | W8: Score | X8: Tie Work | Y8: Game Played | Z8: Sets Points Work | AA8: Sets & Tie Points Work | AB8: Games Wins Work | AC8: Sets Wins Work | AJ8: Winner Working | AK8: Total Games Work | AL8: Winner
A9: =AE9 -> Duncan D'Alessandro/Clayton Zammit Cesare | B9: 6 | C9: =IF(B9>B11,1,0) -> 1 | E9: 4 | F9: =IF(E9>E11,1,0) -> 0 | H9: 10 | I9: =IF(H9>H11,1,0) -> 1 | J9: =IF(B9="",0,1) -> 1 | K9: =IF(C9+F9=2,3,IF(C9+F9=1,1,0)) -> 1 | L9: =IF(K9=3,3,IF(I9+K9=2,2,IF(K9=1,1,0))) -> 2 | M9: =B9+E9 -> 10 | N9: =C9+F9+I9 -> 2 | P9: =AE9 -> Duncan D'Alessandro/Clayton Zammit Cesare | Q9: 6 | R9: =IF(Q9>Q11,1,0) -> 1 | T9: 6 | U9: =IF(T9>T11,1,0) -> 1 | X9: =IF(W9>W11,1,0) -> 0 | Y9: =IF(Q9="",0,1) -> 1 | Z9: =IF(R9+U9=2,3,IF(R9+U9=1,1,0)) -> 3 | AA9: =IF(Z9=3,3,IF(X9+Z9=2,2,IF(Z9=1,1,0))) -> 3 | AB9: =Q9+T9 -> 12 | AC9: =R9+U9+X9 -> 2 | AE9: ='Players Men'!B6 -> Duncan D'Alessandro/Clayton Zammit Cesare | AF9: =J9+Y9+Y13+J13+Y25 -> 5 | AG9: =L9+AA9+L13+AA13+AA25 -> 14 | AH9: =M9+AB9+M13+AB13+AB25 -> 59 | AI9: =N9+AC9+N13+AC13+AC25 -> 10
A10: vs. | P10: vs.
A11: =AE11 -> Mark Gatt/Manuel Bonello | B11: 4 | C11: =IF(B11>B9,1,0) -> 0 | E11: 6 | F11: =IF(E11>E9,1,0) -> 1 | H11: 3 | I11: =IF(H11>H9,1,0) -> 0 | J11: =IF(B11="",0,1) -> 1 | K11: =IF(C11+F11=2,3,IF(C11+F11=1,1,0)) -> 1 | L11: =IF(K11=3,3,IF(I11+K11=2,2,IF(K11=1,1,0))) -> 1 | M11: =B11+E11 -> 10 | N11: =C11+F11+I11 -> 1 | P11: =AE13 -> Gabriel Pace/Nikolai Belli | Q11: 0 | R11: =IF(Q11>Q9,1,0) -> 0 | T11: 3 | U11: =IF(T11>T9,1,0) -> 0 | X11: =IF(W11>W9,1,0) -> 0 | Y11: =IF(Q11="",0,1) -> 1 | Z11: =IF(R11+U11=2,3,IF(R11+U11=1,1,0)) -> 0 | AA11: =IF(Z11=3,3,IF(X11+Z11=2,2,IF(Z11=1,1,0))) -> 0 | AB11: =Q11+T11 -> 3 | AC11: =R11+U11+X11 -> 0 | AE11: ='Players Men'!B7 -> Mark Gatt/Manuel Bonello | AF11: =J11+J25+Y21+J21+J37 -> 5 | AG11: =L11+L25+AA21+L21+L37 -> 12 | AH11: =M11+M25+AB21+M21+M37 -> 58 | AI11: =N11+N25+AC21+N21+N37 -> 10
A13: =AE9 -> Duncan D'Alessandro/Clayton Zammit Cesare | B13: 6 | C13: =IF(B13>B15,1,0) -> 1 | E13: 6 | F13: =IF(E13>E15,1,0) -> 1 | I13: =IF(H13>H15,1,0) -> 0 | J13: =IF(B13="",0,1) -> 1 | K13: =IF(C13+F13=2,3,IF(C13+F13=1,1,0)) -> 3 | L13: =IF(K13=3,3,IF(I13+K13=2,2,IF(K13=1,1,0))) -> 3 | M13: =B13+E13 -> 12 | N13: =C13+F13+I13 -> 2 | P13: =AE9 -> Duncan D'Alessandro/Clayton Zammit Cesare | Q13: 7 | R13: =IF(Q13>Q15,1,0) -> 1 | T13: 6 | U13: =IF(T13>T15,1,0) -> 1 | X13: =IF(W13>W15,1,0) -> 0 | Y13: =IF(Q13="",0,1) -> 1 | Z13: =IF(R13+U13=2,3,IF(R13+U13=1,1,0)) -> 3 | AA13: =IF(Z13=3,3,IF(X13+Z13=2,2,IF(Z13=1,1,0))) -> 3 | AB13: =Q13+T13 -> 13 | AC13: =R13+U13+X13 -> 2 | AE13: ='Players Men'!B8 -> Gabriel Pace/Nikolai Belli | AF13: =Y17+J23+J17+Y11+J33 -> 5 | AG13: =L17+AA17+AA11+L23+L33 -> 3 | AH13: =M17+AB11+M23+AB17+M33 -> 21 | AI13: =N17+AC17+AC11+N23+N33 -> 2
A14: vs. | P14: vs.
A15: =AE15 -> Trevor Rutter/Jean Carl Azzopardi | B15: 4 | C15: =IF(B15>B13,1,0) -> 0 | E15: 4 | F15: =IF(E15>E13,1,0) -> 0 | I15: =IF(H15>H13,1,0) -> 0 | J15: =IF(B15="",0,1) -> 1 | K15: =IF(C15+F15=2,3,IF(C15+F15=1,1,0)) -> 0 | L15: =IF(K15=3,3,IF(I15+K15=2,2,IF(K15=1,1,0))) -> 0 | M15: =B15+E15 -> 8 | N15: =C15+F15+I15 -> 0 | P15: =AE17 -> Matthew Mifsud/Melchior Farrugia | Q15: 6 | R15: =IF(Q15>Q13,1,0) -> 0 | T15: 3 | U15: =IF(T15>T13,1,0) -> 0 | X15: =IF(W15>W13,1,0) -> 0 | Y15: =IF(Q15="",0,1) -> 1 | Z15: =IF(R15+U15=2,3,IF(R15+U15=1,1,0)) -> 0 | AA15: =IF(Z15=3,3,IF(X15+Z15=2,2,IF(Z15=1,1,0))) -> 0 | AB15: =Q15+T15 -> 9 | AC15: =R15+U15+X15 -> 0 | AE15: ='Players Men'!B9 -> Trevor Rutter/Jean Carl Azzopardi | AF15: =Y19+J15+Y23+Y29+J29 -> 5 | AG15: =AA19+L15+AA23+L29+AA29 -> 7 | AH15: =AB19+M15+AB23+M29+AB29 -> 48 | AI15: =AC19+N15+AC23+N29+AC29 -> 5
A17: =AE13 -> Gabriel Pace/Nikolai Belli | B17: 0 | C17: =IF(B17>B19,1,0) -> 0 | E17: 1 | F17: =IF(E17>E19,1,0) -> 0 | I17: =IF(H17>H19,1,0) -> 0 | J17: =IF(B17="",0,1) -> 1 | K17: =IF(C17+F17=2,3,IF(C17+F17=1,1,0)) -> 0 | L17: =IF(K17=3,3,IF(I17+K17=2,2,IF(K17=1,1,0))) -> 0 | M17: =B17+E17 -> 1 | N17: =C17+F17+I17 -> 0 | P17: =AE13 -> Gabriel Pace/Nikolai Belli | Q17: 0 | R17: =IF(Q17>Q19,1,0) -> 0 | T17: 0 | U17: =IF(T17>T19,1,0) -> 0 | X17: =IF(W17>W19,1,0) -> 0 | Y17: =IF(Q17="",0,1) -> 1 | Z17: =IF(R17+U17=2,3,IF(R17+U17=1,1,0)) -> 0 | AA17: =IF(Z17=3,3,IF(X17+Z17=2,2,IF(Z17=1,1,0))) -> 0 | AB17: =Q17+T17 -> 0 | AC17: =R17+U17+X17 -> 0 | AE17: ='Players Men'!B10 -> Matthew Mifsud/Melchior Farrugia | AF17: =Y15+J27+J19+J31+Y33 -> 5 | AG17: =AA15+L27+L19+L31+AA33 -> 9 | AH17: =AB15+M27+M19+M31+AB33 -> 56 | AI17: =N31+N27+AC15+N19+AC33 -> 7
A18: vs. | P18: vs.
A19: =AE17 -> Matthew Mifsud/Melchior Farrugia | B19: 6 | C19: =IF(B19>B17,1,0) -> 1 | E19: 6 | F19: =IF(E19>E17,1,0) -> 1 | I19: =IF(H19>H17,1,0) -> 0 | J19: =IF(B19="",0,1) -> 1 | K19: =IF(C19+F19=2,3,IF(C19+F19=1,1,0)) -> 3 | L19: =IF(K19=3,3,IF(I19+K19=2,2,IF(K19=1,1,0))) -> 3 | M19: =B19+E19 -> 12 | N19: =C19+F19+I19 -> 2 | P19: =AE15 -> Trevor Rutter/Jean Carl Azzopardi | Q19: 6 | R19: =IF(Q19>Q17,1,0) -> 1 | T19: 6 | U19: =IF(T19>T17,1,0) -> 1 | X19: =IF(W19>W17,1,0) -> 0 | Y19: =IF(Q19="",0,1) -> 1 | Z19: =IF(R19+U19=2,3,IF(R19+U19=1,1,0)) -> 3 | AA19: =IF(Z19=3,3,IF(X19+Z19=2,2,IF(Z19=1,1,0))) -> 3 | AB19: =Q19+T19 -> 12 | AC19: =R19+U19+X19 -> 2 | AE19: ='Players Men'!B11 -> Eric Roca/Roderick Spiteri | AF19: =Y35+Y31+Y27+J39+J35 -> 5 | AG19: =L39+L35+AA31+AA35+AA27 -> 0 | AH19: =AB27+M39+AB31+M35+AB35 -> 15 | AI19: =N35+N39+AC31+AC35+AC27 -> 0
A21: =AE11 -> Mark Gatt/Manuel Bonello | B21: 6 | C21: =IF(B21>B23,1,0) -> 1 | E21: 6 | F21: =IF(E21>E23,1,0) -> 1 | I21: =IF(H21>H23,1,0) -> 0 | J21: =IF(B21="",0,1) -> 1 | K21: =IF(C21+F21=2,3,IF(C21+F21=1,1,0)) -> 3 | L21: =IF(K21=3,3,IF(I21+K21=2,2,IF(K21=1,1,0))) -> 3 | M21: =B21+E21 -> 12 | N21: =C21+F21+I21 -> 2 | P21: =AE11 -> Mark Gatt/Manuel Bonello | Q21: 6 | R21: =IF(Q21>Q23,1,0) -> 1 | T21: 6 | U21: =IF(T21>T23,1,0) -> 1 | W21: 10 | X21: =IF(W21>W23,1,0) -> 1 | Y21: =IF(Q21="",0,1) -> 1 | Z21: =IF(R21+U21=2,3,IF(R21+U21=1,1,0)) -> 3 | AA21: =IF(Z21=3,3,IF(X21+Z21=2,2,IF(Z21=1,1,0))) -> 3 | AB21: =Q21+T21 -> 12 | AC21: =R21+U21+X21 -> 3 | AE21: Division Winner
A22: vs. | P22: vs. | AE22: Duncan D'Alessandro/Clayton Zammit Cesare
A23: =AE13 -> Gabriel Pace/Nikolai Belli | B23: 1 | C23: =IF(B23>B21,1,0) -> 0 | E23: 4 | F23: =IF(E23>E21,1,0) -> 0 | I23: =IF(H23>H21,1,0) -> 0 | J23: =IF(B23="",0,1) -> 1 | K23: =IF(C23+F23=2,3,IF(C23+F23=1,1,0)) -> 0 | L23: =IF(K23=3,3,IF(I23+K23=2,2,IF(K23=1,1,0))) -> 0 | M23: =B23+E23 -> 5 | N23: =C23+F23+I23 -> 0 | P23: =AE15 -> Trevor Rutter/Jean Carl Azzopardi | Q23: 4 | R23: =IF(Q23>Q21,1,0) -> 0 | T23: 3 | U23: =IF(T23>T21,1,0) -> 0 | W23: 4 | X23: =IF(W23>W21,1,0) -> 0 | Y23: =IF(Q23="",0,1) -> 1 | Z23: =IF(R23+U23=2,3,IF(R23+U23=1,1,0)) -> 0 | AA23: =IF(Z23=3,3,IF(X23+Z23=2,2,IF(Z23=1,1,0))) -> 0 | AB23: =Q23+T23 -> 7 | AC23: =R23+U23+X23 -> 0 | AE23: Division Runner Up
AE24: Mark Gatt/Manuel Bonello
A25: =AE11 -> Mark Gatt/Manuel Bonello | B25: 5 | C25: =IF(B25>B27,1,0) -> 0 | E25: 7 | F25: =IF(E25>E27,1,0) -> 1 | H25: 10 | I25: =IF(H25>H27,1,0) -> 1 | J25: =IF(B25="",0,1) -> 1 | K25: =IF(C25+F25=2,3,IF(C25+F25=1,1,0)) -> 1 | L25: =IF(K25=3,3,IF(I25+K25=2,2,IF(K25=1,1,0))) -> 2 | M25: =B25+E25 -> 12 | N25: =C25+F25+I25 -> 2 | P25: =AE9 -> Duncan D'Alessandro/Clayton Zammit Cesare | Q25: 6 | R25: =IF(Q25>Q27,1,0) -> 1 | T25: 6 | U25: =IF(T25>T27,1,0) -> 1 | X25: =IF(W25>W23,1,0) -> 0 | Y25: =IF(Q25="",0,1) -> 1 | Z25: =IF(R25+U25=2,3,IF(R25+U25=1,1,0)) -> 3 | AA25: =IF(Z25=3,3,IF(X25+Z25=2,2,IF(Z25=1,1,0))) -> 3 | AB25: =Q25+T25 -> 12 | AC25: =R25+U25+X25 -> 2
A26: vs. | P26: vs.
A27: =AE17 -> Matthew Mifsud/Melchior Farrugia | B27: 7 | C27: =IF(B27>B25,1,0) -> 1 | E27: 6 | F27: =IF(E27>E25,1,0) -> 0 | H27: 7 | I27: =IF(H27>H25,1,0) -> 0 | J27: =IF(B27="",0,1) -> 1 | K27: =IF(C27+F27=2,3,IF(C27+F27=1,1,0)) -> 1 | L27: =IF(K27=3,3,IF(I27+K27=2,2,IF(K27=1,1,0))) -> 1 | M27: =B27+E27 -> 13 | N27: =C27+F27+I27 -> 1 | P27: =AE19 -> Eric Roca/Roderick Spiteri | Q27: 1 | R27: =IF(Q27>Q25,1,0) -> 0 | T27: 0 | U27: =IF(T27>T25,1,0) -> 0 | X27: =IF(W27>W25,1,0) -> 0 | Y27: =IF(Q27="",0,1) -> 1 | Z27: =IF(R27+U27=2,3,IF(R27+U27=1,1,0)) -> 0 | AA27: =IF(Z27=3,3,IF(X27+Z27=2,2,IF(Z27=1,1,0))) -> 0 | AB27: =Q27+T27 -> 1 | AC27: =R27+U27+X27 -> 0
A29: =AE15 -> Trevor Rutter/Jean Carl Azzopardi | B29: 6 | C29: =IF(B29>B31,1,0) -> 1 | E29: 3 | F29: =IF(E29>E31,1,0) -> 0 | H29: 7 | I29: =IF(H29>H31,1,0) -> 0 | J29: =IF(B29="",0,1) -> 1 | K29: =IF(C29+F29=2,3,IF(C29+F29=1,1,0)) -> 1 | L29: =IF(K29=3,3,IF(I29+K29=2,2,IF(K29=1,1,0))) -> 1 | M29: =B29+E29 -> 9 | N29: =C29+F29+I29 -> 1 | P29: =AE15 -> Trevor Rutter/Jean Carl Azzopardi | Q29: 6 | R29: =IF(Q29>Q31,1,0) -> 1 | T29: 6 | U29: =IF(T29>T31,1,0) -> 1 | X29: =IF(W29>W27,1,0) -> 0 | Y29: =IF(Q29="",0,1) -> 1 | Z29: =IF(R29+U29=2,3,IF(R29+U29=1,1,0)) -> 3 | AA29: =IF(Z29=3,3,IF(X29+Z29=2,2,IF(Z29=1,1,0))) -> 3 | AB29: =Q29+T29 -> 12 | AC29: =R29+U29+X29 -> 2
A30: vs. | P30: vs.
A31: =AE17 -> Matthew Mifsud/Melchior Farrugia | B31: 4 | C31: =IF(B31>B29,1,0) -> 0 | E31: 6 | F31: =IF(E31>E29,1,0) -> 1 | H31: 10 | I31: =IF(H31>H29,1,0) -> 1 | J31: =IF(B31="",0,1) -> 1 | K31: =IF(C31+F31=2,3,IF(C31+F31=1,1,0)) -> 1 | L31: =IF(K31=3,3,IF(I31+K31=2,2,IF(K31=1,1,0))) -> 2 | M31: =B31+E31 -> 10 | N31: =C31+F31+I31 -> 2 | P31: =AE19 -> Eric Roca/Roderick Spiteri | Q31: 3 | R31: =IF(Q31>Q29,1,0) -> 0 | T31: 4 | U31: =IF(T31>T29,1,0) -> 0 | X31: =IF(W31>W29,1,0) -> 0 | Y31: =IF(Q31="",0,1) -> 1 | Z31: =IF(R31+U31=2,3,IF(R31+U31=1,1,0)) -> 0 | AA31: =IF(Z31=3,3,IF(X31+Z31=2,2,IF(Z31=1,1,0))) -> 0 | AB31: =Q31+T31 -> 7 | AC31: =R31+U31+X31 -> 0
A33: =P17 -> Gabriel Pace/Nikolai Belli | B33: 6 | C33: =IF(B33>B35,1,0) -> 1 | E33: 6 | F33: =IF(E33>E35,1,0) -> 1 | I33: =IF(H33>H31,1,0) -> 0 | J33: =IF(B33="",0,1) -> 1 | K33: =IF(C33+F33=2,3,IF(C33+F33=1,1,0)) -> 3 | L33: =IF(K33=3,3,IF(I33+K33=2,2,IF(K33=1,1,0))) -> 3 | M33: =B33+E33 -> 12 | N33: =C33+F33+I33 -> 2 | P33: =AE17 -> Matthew Mifsud/Melchior Farrugia | Q33: 6 | R33: =IF(Q33>Q35,1,0) -> 1 | T33: 6 | U33: =IF(T33>T35,1,0) -> 1 | X33: =IF(W33>W31,1,0) -> 0 | Y33: =IF(Q33="",0,1) -> 1 | Z33: =IF(R33+U33=2,3,IF(R33+U33=1,1,0)) -> 3 | AA33: =IF(Z33=3,3,IF(X33+Z33=2,2,IF(Z33=1,1,0))) -> 3 | AB33: =Q33+T33 -> 12 | AC33: =R33+U33+X33 -> 2
A34: vs. | P34: vs.
A35: =P27 -> Eric Roca/Roderick Spiteri | B35: 2 | C35: =IF(B35>B33,1,0) -> 0 | E35: 0 | F35: =IF(E35>E33,1,0) -> 0 | I35: =IF(H35>H33,1,0) -> 0 | J35: =IF(B35="",0,1) -> 1 | K35: =IF(C35+F35=2,3,IF(C35+F35=1,1,0)) -> 0 | L35: =IF(K35=3,3,IF(I35+K35=2,2,IF(K35=1,1,0))) -> 0 | M35: =B35+E35 -> 2 | N35: =C35+F35+I35 -> 0 | P35: =AE19 -> Eric Roca/Roderick Spiteri | Q35: 0 | R35: =IF(Q35>Q33,1,0) -> 0 | T35: 1 | U35: =IF(T35>T33,1,0) -> 0 | X35: =IF(W35>W33,1,0) -> 0 | Y35: =IF(Q35="",0,1) -> 1 | Z35: =IF(R35+U35=2,3,IF(R35+U35=1,1,0)) -> 0 | AA35: =IF(Z35=3,3,IF(X35+Z35=2,2,IF(Z35=1,1,0))) -> 0 | AB35: =Q35+T35 -> 1 | AC35: =R35+U35+X35 -> 0
A37: =AE11 -> Mark Gatt/Manuel Bonello | B37: 6 | C37: =IF(B37>B39,1,0) -> 1 | E37: 6 | F37: =IF(E37>E39,1,0) -> 1 | I37: =IF(H37>H35,1,0) -> 0 | J37: =IF(B37="",0,1) -> 1 | K37: =IF(C37+F37=2,3,IF(C37+F37=1,1,0)) -> 3 | L37: =IF(K37=3,3,IF(I37+K37=2,2,IF(K37=1,1,0))) -> 3 | M37: =B37+E37 -> 12 | N37: =C37+F37+I37 -> 2
A38: vs.
A39: =AE19 -> Eric Roca/Roderick Spiteri | B39: 1 | C39: =IF(B39>B37,1,0) -> 0 | E39: 3 | F39: =IF(E39>E37,1,0) -> 0 | I39: =IF(H39>H37,1,0) -> 0 | J39: =IF(B39="",0,1) -> 1 | K39: =IF(C39+F39=2,3,IF(C39+F39=1,1,0)) -> 0 | L39: =IF(K39=3,3,IF(I39+K39=2,2,IF(K39=1,1,0))) -> 0 | M39: =B39+E39 -> 4 | N39: =C39+F39+I39 -> 0

Sheet Men Div 2
A1: VITTORIOSA LAWN TENNIS CLUB Sports Experience Chosen Doubles 2025
A5: Men Division 2
A7: Players | B7: Set Scores | H7: Tie | P7: Players | Q7: Set Scores | W7: Tie | AE7: Player | AF7: Matches Played | AG7: Points Overall | AH7: Games Won | AI7: Sets Won
B8: Score | C8: Set 1 Work | E8: Score | F8: Set 2 Work | H8: Score | I8: Tie Work | J8: Game Played | K8: Sets Points Work | L8: Sets & Tie Points Work | M8: Games Wins Work | N8: Sets Wins Work | Q8: Score | R8: Set 1 Work | T8: Score | U8: Set 2 Work | W8: Score | X8: Tie Work | Y8: Game Played | Z8: Sets Points Work | AA8: Sets & Tie Points Work | AB8: Games Wins Work | AC8: Sets Wins Work | AJ8: Winner Working | AK8: Total Games Work | AL8: Winner
A9: =AE9 -> Fotis Evangelou/Kristen Cachia | B9: 6 | C9: =IF(B9>B11,1,0) -> 1 | E9: 6 | F9: =IF(E9>E11,1,0) -> 1 | I9: =IF(H9>H11,1,0) -> 0 | J9: =IF(B9="",0,1) -> 1 | K9: =IF(C9+F9=2,3,IF(C9+F9=1,1,0)) -> 3 | L9: =IF(K9=3,3,IF(I9+K9=2,2,IF(K9=1,1,0))) -> 3 | M9: =B9+E9 -> 12 | N9: =C9+F9+I9 -> 2 | P9: =AE9 -> Fotis Evangelou/Kristen Cachia | Q9: 6 | R9: =IF(Q9>Q11,1,0) -> 1 | T9: 6 | U9: =IF(T9>T11,1,0) -> 1 | X9: =IF(W9>W11,1,0) -> 0 | Y9: =IF(Q9="",0,1) -> 1 | Z9: =IF(R9+U9=2,3,IF(R9+U9=1,1,0)) -> 3 | AA9: =IF(Z9=3,3,IF(X9+Z9=2,2,IF(Z9=1,1,0))) -> 3 | AB9: =Q9+T9 -> 12 | AC9: =R9+U9+X9 -> 2 | AE9: ='Players Men'!B14 -> Fotis Evangelou/Kristen Cachia | AF9: =J9+Y9+Y13+J13+Y25 -> 5 | AG9: =L9+AA9+L13+AA13+AA25 -> 13 | AH9: =M9+AB9+M13+AB13+AB25 -> 60 | AI9: =N9+AC9+N13+AC13+AC25 -> 9
A10: vs. | P10: vs.
A11: =AE11 -> Willem Steenkamer/Javier Villoria | B11: 4 | C11: =IF(B11>B9,1,0) -> 0 | E11: 3 | F11: =IF(E11>E9,1,0) -> 0 | I11: =IF(H11>H9,1,0) -> 0 | J11: =IF(B11="",0,1) -> 1 | K11: =IF(C11+F11=2,3,IF(C11+F11=1,1,0)) -> 0 | L11: =IF(K11=3,3,IF(I11+K11=2,2,IF(K11=1,1,0))) -> 0 | M11: =B11+E11 -> 7 | N11: =C11+F11+I11 -> 0 | P11: =AE13 -> Jonathan Vella/Clint Agius | Q11: 0 | R11: =IF(Q11>Q9,1,0) -> 0 | T11: 2 | U11: =IF(T11>T9,1,0) -> 0 | X11: =IF(W11>W9,1,0) -> 0 | Y11: =IF(Q11="",0,1) -> 1 | Z11: =IF(R11+U11=2,3,IF(R11+U11=1,1,0)) -> 0 | AA11: =IF(Z11=3,3,IF(X11+Z11=2,2,IF(Z11=1,1,0))) -> 0 | AB11: =Q11+T11 -> 2 | AC11: =R11+U11+X11 -> 0 | AE11: ='Players Men'!B15 -> Willem Steenkamer/Javier Villoria | AF11: =J11+J25+Y21+J21+J33 -> 5 | AG11: =L11+L25+AA21+L21+L33 -> 5 | AH11: =M11+M25+AB21+M21+M33 -> 47 | AI11: =N11+N25+AC21+N21+N33 -> 5
A13: =AE9 -> Fotis Evangelou/Kristen Cachia | B13: 6 | C13: =IF(B13>B15,1,0) -> 0 | E13: 6 | F13: =IF(E13>E15,1,0) -> 1 | H13: 7 | I13: =IF(H13>H15,1,0) -> 0 | J13: =IF(B13="",0,1) -> 1 | K13: =IF(C13+F13=2,3,IF(C13+F13=1,1,0)) -> 1 | L13: =IF(K13=3,3,IF(I13+K13=2,2,IF(K13=1,1,0))) -> 1 | M13: =B13+E13 -> 12 | N13: =C13+F13+I13 -> 1 | P13: =AE9 -> Fotis Evangelou/Kristen Cachia | Q13: 6 | R13: =IF(Q13>Q15,1,0) -> 1 | T13: 6 | U13: =IF(T13>T15,1,0) -> 1 | X13: =IF(W13>W15,1,0) -> 0 | Y13: =IF(Q13="",0,1) -> 1 | Z13: =IF(R13+U13=2,3,IF(R13+U13=1,1,0)) -> 3 | AA13: =IF(Z13=3,3,IF(X13+Z13=2,2,IF(Z13=1,1,0))) -> 3 | AB13: =Q13+T13 -> 12 | AC13: =R13+U13+X13 -> 2 | AE13: ='Players Men'!B16 -> Jonathan Vella/Clint Agius | AF13: =Y17+J23+J17+Y11+Y29 -> 5 | AG13: =L17+AA17+AA11+L23+AA29 -> 3 | AH13: =M17+AB11+M23+AB17+AB29 -> 34 | AI13: =N17+AC17+AC11+N23+AC29 -> 3
A14: vs. | P14: vs.
A15: =AE15 -> Jonathan Martinelli/Luigi Porto | B15: 7 | C15: =IF(B15>B13,1,0) -> 1 | E15: 3 | F15: =IF(E15>E13,1,0) -> 0 | H15: 10 | I15: =IF(H15>H13,1,0) -> 1 | J15: =IF(B15="",0,1) -> 1 | K15: =IF(C15+F15=2,3,IF(C15+F15=1,1,0)) -> 1 | L15: =IF(K15=3,3,IF(I15+K15=2,2,IF(K15=1,1,0))) -> 2 | M15: =B15+E15 -> 10 | N15: =C15+F15+I15 -> 2 | P15: =AE17 -> Ivan Cassar/Kurt Cassar | Q15: 2 | R15: =IF(Q15>Q13,1,0) -> 0 | T15: 4 | U15: =IF(T15>T13,1,0) -> 0 | X15: =IF(W15>W13,1,0) -> 0 | Y15: =IF(Q15="",0,1) -> 1 | Z15: =IF(R15+U15=2,3,IF(R15+U15=1,1,0)) -> 0 | AA15: =IF(Z15=3,3,IF(X15+Z15=2,2,IF(Z15=1,1,0))) -> 0 | AB15: =Q15+T15 -> 6 | AC15: =R15+U15+X15 -> 0 | AE15: ='Players Men'!B17 -> Jonathan Martinelli/Luigi Porto | AF15: =Y19+J15+Y23+J29+J37 -> 5 | AG15: =AA19+L15+AA23+L29+L37 -> 13 | AH15: =AB19+M15+AB23+M29+M37 -> 57 | AI15: =AC19+N15+AC23+N29+N37 -> 10
A17: =AE13 -> Jonathan Vella/Clint Agius | B17: 6 | C17: =IF(B17>B19,1,0) -> 0 | E17: 6 | F17: =IF(E17>E19,1,0) -> 1 | H17: 10 | I17: =IF(H17>H19,1,0) -> 1 | J17: =IF(B17="",0,1) -> 1 | K17: =IF(C17+F17=2,3,IF(C17+F17=1,1,0)) -> 1 | L17: =IF(K17=3,3,IF(I17+K17=2,2,IF(K17=1,1,0))) -> 2 | M17: =B17+E17 -> 12 | N17: =C17+F17+I17 -> 2 | P17: =AE13 -> Jonathan Vella/Clint Agius | Q17: 1 | R17: =IF(Q17>Q19,1,0) -> 0 | T17: 2 | U17: =IF(T17>T19,1,0) -> 0 | X17: =IF(W17>W19,1,0) -> 0 | Y17: =IF(Q17="",0,1) -> 1 | Z17: =IF(R17+U17=2,3,IF(R17+U17=1,1,0)) -> 0 | AA17: =IF(Z17=3,3,IF(X17+Z17=2,2,IF(Z17=1,1,0))) -> 0 | AB17: =Q17+T17 -> 3 | AC17: =R17+U17+X17 -> 0 | AE17: ='Players Men'!B18 -> Ivan Cassar/Kurt Cassar | AF17: =Y15+J27+J19+J31+Y33 -> 5 | AG17: =AA15+L27+L19+L31+AA33 -> 6 | AH17: =AB15+M27+M19+M31+AB33 -> 45 | AI17: =N31+N27+AC15+N19+AC33 -> 5
A18: vs. | P18: vs.
A19: =AE17 -> Ivan Cassar/Kurt Cassar | B19: 7 | C19: =IF(B19>B17,1,0) -> 1 | E19: 3 | F19: =IF(E19>E17,1,0) -> 0 | H19: 7 | I19: =IF(H19>H17,1,0) -> 0 | J19: =IF(B19="",0,1) -> 1 | K19: =IF(C19+F19=2,3,IF(C19+F19=1,1,0)) -> 1 | L19: =IF(K19=3,3,IF(I19+K19=2,2,IF(K19=1,1,0))) -> 1 | M19: =B19+E19 -> 10 | N19: =C19+F19+I19 -> 1 | P19: =AE15 -> Jonathan Martinelli/Luigi Porto | Q19: 6 | R19: =IF(Q19>Q17,1,0) -> 1 | T19: 6 | U19: =IF(T19>T17,1,0) -> 1 | X19: =IF(W19>W17,1,0) -> 0 | Y19: =IF(Q19="",0,1) -> 1 | Z19: =IF(R19+U19=2,3,IF(R19+U19=1,1,0)) -> 3 | AA19: =IF(Z19=3,3,IF(X19+Z19=2,2,IF(Z19=1,1,0))) -> 3 | AB19: =Q19+T19 -> 12 | AC19: =R19+U19+X19 -> 2 | AE19: ='Players Men'!B19 -> Peter Khiev/Sam Zammit | AF19: =Y27+J39+J35+Y31+Y35 -> 5 | AG19: =L39+L35+AA31+AA35+AA27 -> 7 | AH19: =AB27+M39+AB31+M35+AB35 -> 42 | AI19: =N35+N39+AC31+AC35+AC27 -> 6
A21: =AE11 -> Willem Steenkamer/Javier Villoria | B21: 4 | C21: =IF(B21>B23,1,0) -> 0 | E21: 6 | F21: =IF(E21>E23,1,0) -> 1 | H21: 10 | I21: =IF(H21>H23,1,0) -> 1 | J21: =IF(B21="",0,1) -> 1 | K21: =IF(C21+F21=2,3,IF(C21+F21=1,1,0)) -> 1 | L21: =IF(K21=3,3,IF(I21+K21=2,2,IF(K21=1,1,0))) -> 2 | M21: =B21+E21 -> 10 | N21: =C21+F21+I21 -> 2 | P21: =AE11 -> Willem Steenkamer/Javier Villoria | Q21: 6 | R21: =IF(Q21>Q23,1,0) -> 1 | T21: 4 | U21: =IF(T21>T23,1,0) -> 0 | W21: 10 | X21: =IF(W21>W23,1,0) -> 0 | Y21: =IF(Q21="",0,1) -> 1 | Z21: =IF(R21+U21=2,3,IF(R21+U21=1,1,0)) -> 1 | AA21: =IF(Z21=3,3,IF(X21+Z21=2,2,IF(Z21=1,1,0))) -> 1 | AB21: =Q21+T21 -> 10 | AC21: =R21+U21+X21 -> 1 | AE21: Division Winner
A22: vs. | P22: vs. | AE22: Jonathan Martinelli/Luigi Porto
A23: =AE13 -> Jonathan Vella/Clint Agius | B23: 6 | C23: =IF(B23>B21,1,0) -> 1 | E23: 3 | F23: =IF(E23>E21,1,0) -> 0 | H23: 6 | I23: =IF(H23>H21,1,0) -> 0 | J23: =IF(B23="",0,1) -> 1 | K23: =IF(C23+F23=2,3,IF(C23+F23=1,1,0)) -> 1 | L23: =IF(K23=3,3,IF(I23+K23=2,2,IF(K23=1,1,0))) -> 1 | M23: =B23+E23 -> 9 | N23: =C23+F23+I23 -> 1 | P23: =AE15 -> Jonathan Martinelli/Luigi Porto | Q23: 4 | R23: =IF(Q23>Q21,1,0) -> 0 | T23: 6 | U23: =IF(T23>T21,1,0) -> 1 | W23: 12 | X23: =IF(W23>W21,1,0) -> 1 | Y23: =IF(Q23="",0,1) -> 1 | Z23: =IF(R23+U23=2,3,IF(R23+U23=1,1,0)) -> 1 | AA23: =IF(Z23=3,3,IF(X23+Z23=2,2,IF(Z23=1,1,0))) -> 2 | AB23: =Q23+T23 -> 10 | AC23: =R23+U23+X23 -> 2 | AE23: Division Runner Up
AE24: Fotis Evangelou/Kristen Cachia
A25: =AE11 -> Willem Steenkamer/Javier Villoria | B25: 5 | C25: =IF(B25>B27,1,0) -> 0 | E25: 4 | F25: =IF(E25>E27,1,0) -> 0 | I25: =IF(H25>H27,1,0) -> 0 | J25: =IF(B25="",0,1) -> 1 | K25: =IF(C25+F25=2,3,IF(C25+F25=1,1,0)) -> 0 | L25: =IF(K25=3,3,IF(I25+K25=2,2,IF(K25=1,1,0))) -> 0 | M25: =B25+E25 -> 9 | N25: =C25+F25+I25 -> 0 | P25: =AE9 -> Fotis Evangelou/Kristen Cachia | Q25: 6 | R25: =IF(Q25>Q27,1,0) -> 1 | T25: 6 | U25: =IF(T25>T27,1,0) -> 1 | X25: =IF(W25>W23,1,0) -> 0 | Y25: =IF(Q25="",0,1) -> 1 | Z25: =IF(R25+U25=2,3,IF(R25+U25=1,1,0)) -> 3 | AA25: =IF(Z25=3,3,IF(X25+Z25=2,2,IF(Z25=1,1,0))) -> 3 | AB25: =Q25+T25 -> 12 | AC25: =R25+U25+X25 -> 2
A26: vs. | P26: vs
A27: =AE17 -> Ivan Cassar/Kurt Cassar | B27: 7 | C27: =IF(B27>B25,1,0) -> 1 | E27: 6 | F27: =IF(E27>E25,1,0) -> 1 | I27: =IF(H27>H25,1,0) -> 0 | J27: =IF(B27="",0,1) -> 1 | K27: =IF(C27+F27=2,3,IF(C27+F27=1,1,0)) -> 3 | L27: =IF(K27=3,3,IF(I27+K27=2,2,IF(K27=1,1,0))) -> 3 | M27: =B27+E27 -> 13 | N27: =C27+F27+I27 -> 2 | P27: =AE19 -> Peter Khiev/Sam Zammit | Q27: 1 | R27: =IF(Q27>Q25,1,0) -> 0 | T27: 0 | U27: =IF(T27>T25,1,0) -> 0 | X27: =IF(W27>W25,1,0) -> 0 | Y27: =IF(Q27="",0,1) -> 1 | Z27: =IF(R27+U27=2,3,IF(R27+U27=1,1,0)) -> 0 | AA27: =IF(Z27=3,3,IF(X27+Z27=2,2,IF(Z27=1,1,0))) -> 0 | AB27: =Q27+T27 -> 1 | AC27: =R27+U27+X27 -> 0
A29: =AE15 -> Jonathan Martinelli/Luigi Porto | B29: 7 | C29: =IF(B29>B31,1,0) -> 1 | E29: 6 | F29: =IF(E29>E31,1,0) -> 1 | I29: =IF(H29>H31,1,0) -> 0 | J29: =IF(B29="",0,1) -> 1 | K29: =IF(C29+F29=2,3,IF(C29+F29=1,1,0)) -> 3 | L29: =IF(K29=3,3,IF(I29+K29=2,2,IF(K29=1,1,0))) -> 3 | M29: =B29+E29 -> 13 | N29: =C29+F29+I29 -> 2 | P29: =AE13 -> Jonathan Vella/Clint Agius | Q29: 3 | R29: =IF(Q29>Q31,1,0) -> 0 | T29: 5 | U29: =IF(T29>T31,1,0) -> 0 | X29: =IF(W29>W27,1,0) -> 0 | Y29: =IF(Q29="",0,1) -> 1 | Z29: =IF(R29+U29=2,3,IF(R29+U29=1,1,0)) -> 0 | AA29: =IF(Z29=3,3,IF(X29+Z29=2,2,IF(Z29=1,1,0))) -> 0 | AB29: =Q29+T29 -> 8 | AC29: =R29+U29+X29 -> 0
A30: vs. | P30: vs
A31: =AE17 -> Ivan Cassar/Kurt Cassar | B31: 6 | C31: =IF(B31>B29,1,0) -> 0 | E31: 2 | F31: =IF(E31>E29,1,0) -> 0 | I31: =IF(H31>H29,1,0) -> 0 | J31: =IF(B31="",0,1) -> 1 | K31: =IF(C31+F31=2,3,IF(C31+F31=1,1,0)) -> 0 | L31: =IF(K31=3,3,IF(I31+K31=2,2,IF(K31=1,1,0))) -> 0 | M31: =B31+E31 -> 8 | N31: =C31+F31+I31 -> 0 | P31: =AE19 -> Peter Khiev/Sam Zammit | Q31: 6 | R31: =IF(Q31>Q29,1,0) -> 1 | T31: 7 | U31: =IF(T31>T29,1,0) -> 1 | X31: =IF(W31>W29,1,0) -> 0 | Y31: =IF(Q31="",0,1) -> 1 | Z31: =IF(R31+U31=2,3,IF(R31+U31=1,1,0)) -> 3 | AA31: =IF(Z31=3,3,IF(X31+Z31=2,2,IF(Z31=1,1,0))) -> 3 | AB31: =Q31+T31 -> 13 | AC31: =R31+U31+X31 -> 2
A33: =AE11 -> Willem Steenkamer/Javier Villoria | B33: 5 | C33: =IF(B33>B35,1,0) -> 0 | E33: 6 | F33: =IF(E33>E35,1,0) -> 1 | H33: 7 | I33: =IF(H33>H31,1,0) -> 1 | J33: =IF(B33="",0,1) -> 1 | K33: =IF(C33+F33=2,3,IF(C33+F33=1,1,0)) -> 1 | L33: =IF(K33=3,3,IF(I33+K33=2,2,IF(K33=1,1,0))) -> 2 | M33: =B33+E33 -> 11 | N33: =C33+F33+I33 -> 2 | P33: =AE17 -> Ivan Cassar/Kurt Cassar | Q33: 1 | R33: =IF(Q33>Q35,1,0) -> 0 | T33: 7 | U33: =IF(T33>T35,1,0) -> 1 | W33: 4 | X33: =IF(W33>W31,1,0) -> 1 | Y33: =IF(Q33="",0,1) -> 1 | Z33: =IF(R33+U33=2,3,IF(R33+U33=1,1,0)) -> 1 | AA33: =IF(Z33=3,3,IF(X33+Z33=2,2,IF(Z33=1,1,0))) -> 2 | AB33: =Q33+T33 -> 8 | AC33: =R33+U33+X33 -> 2
A34: vs | P34: vs
A35: =AE19 -> Peter Khiev/Sam Zammit | B35: 7 | C35: =IF(B35>B33,1,0) -> 1 | E35: 4 | F35: =IF(E35>E33,1,0) -> 0 | H35: 10 | I35: =IF(H35>H33,1,0) -> 1 | J35: =IF(B35="",0,1) -> 1 | K35: =IF(C35+F35=2,3,IF(C35+F35=1,1,0)) -> 1 | L35: =IF(K35=3,3,IF(I35+K35=2,2,IF(K35=1,1,0))) -> 2 | M35: =B35+E35 -> 11 | N35: =C35+F35+I35 -> 2 | P35: =AE19 -> Peter Khiev/Sam Zammit | Q35: 6 | R35: =IF(Q35>Q33,1,0) -> 1 | T35: 5 | U35: =IF(T35>T33,1,0) -> 0 | W35: 10 | X35: =IF(W35>W33,1,0) -> 1 | Y35: =IF(Q35="",0,1) -> 1 | Z35: =IF(R35+U35=2,3,IF(R35+U35=1,1,0)) -> 1 | AA35: =IF(Z35=3,3,IF(X35+Z35=2,2,IF(Z35=1,1,0))) -> 2 | AB35: =Q35+T35 -> 11 | AC35: =R35+U35+X35 -> 2
A37: =+AE15 -> Jonathan Martinelli/Luigi Porto | B37: 6 | C37: =IF(B37>B39,1,0) -> 1 | E37: 6 | F37: =IF(E37>E39,1,0) -> 1 | I37: =IF(H37>H35,1,0) -> 0 | J37: =IF(B37="",0,1) -> 1 | K37: =IF(C37+F37=2,3,IF(C37+F37=1,1,0)) -> 3 | L37: =IF(K37=3,3,IF(I37+K37=2,2,IF(K37=1,1,0))) -> 3 | M37: =B37+E37 -> 12 | N37: =C37+F37+I37 -> 2
A38: vs
A39: =P31 -> Peter Khiev/Sam Zammit | B39: 3 | C39: =IF(B39>B37,1,0) -> 0 | E39: 3 | F39: =IF(E39>E37,1,0) -> 0 | I39: =IF(H39>H37,1,0) -> 0 | J39: =IF(B39="",0,1) -> 1 | K39: =IF(C39+F39=2,3,IF(C39+F39=1,1,0)) -> 0 | L39: =IF(K39=3,3,IF(I39+K39=2,2,IF(K39=1,1,0))) -> 0 | M39: =B39+E39 -> 6 | N39: =C39+F39+I39 -> 0

Sheet Men Div 3
A1: VITTORIOSA LAWN TENNIS CLUB Sports Experience Chosen Doubles 2025
A5: Men Division 3 - Group A
A7: Players | B7: Set Scores | H7: Tie | P7: Players | Q7: Set Scores | W7: Tie | AE7: Player | AF7: Matches Played | AG7: Points Overall | AH7: Games Won | AI7: Sets Won
B8: Score | C8: Set 1 Work | E8: Score | F8: Set 2 Work | H8: Score | I8: Tie Work | J8: Game Played | K8: Sets Points Work | L8: Sets & Tie Points Work | M8: Games Wins Work | N8: Sets Wins Work | Q8: Score | R8: Set 1 Work | T8: Score | U8: Set 2 Work | W8: Score | X8: Tie Work | Y8: Game Played | Z8: Sets Points Work | AA8: Sets & Tie Points Work | AB8: Games Wins Work | AC8: Sets Wins Work | AJ8: Winner Working | AK8: Runner Up Working | AL8: Total Games Work | AM8: Winner | AN8: Runner Up
A9: =AE9 -> Roberto Murdocco/James Brincat | B9: 4 | C9: =IF(B9>B11,1,0) -> 0 | E9: 2 | F9: =IF(E9>E11,1,0) -> 0 | I9: =IF(H9>H11,1,0) -> 0 | J9: =IF(B9="",0,1) -> 1 | K9: =IF(C9+F9=2,3,IF(C9+F9=1,1,0)) -> 0 | L9: =IF(K9=3,3,IF(I9+K9=2,2,IF(K9=1,1,0))) -> 0 | M9: =B9+E9 -> 6 | N9: =C9+F9+I9 -> 0 | P9: =AE9 -> Roberto Murdocco/James Brincat | Q9: 6 | R9: =IF(Q9>Q11,1,0) -> 1 | T9: 6 | U9: =IF(T9>T11,1,0) -> 1 | X9: =IF(W9>W11,1,0) -> 0 | Y9: =IF(Q9="",0,1) -> 1 | Z9: =IF(R9+U9=2,3,IF(R9+U9=1,1,0)) -> 3 | AA9: =IF(Z9=3,3,IF(X9+Z9=2,2,IF(Z9=1,1,0))) -> 3 | AB9: =Q9+T9 -> 12 | AC9: =R9+U9+X9 -> 2 | AE9: ='Players Men'!B22 -> Roberto Murdocco/James Brincat | AF9: =J9+Y9+J13+Y13 -> 4 | AG9: =L9+AA9+L13+AA13 -> 9 | AH9: =M9+AB9+M13+AB13 -> 42 | AI9: =N9+AC9+N13+AC13 -> 6
A10: vs. | P10: vs.
A11: =AE11 -> Neville Sciriha/Matthias Sciriha | B11: 6 | C11: =IF(B11>B9,1,0) -> 1 | E11: 6 | F11: =IF(E11>E9,1,0) -> 1 | I11: =IF(H11>H9,1,0) -> 0 | J11: =IF(B11="",0,1) -> 1 | K11: =IF(C11+F11=2,3,IF(C11+F11=1,1,0)) -> 3 | L11: =IF(K11=3,3,IF(I11+K11=2,2,IF(K11=1,1,0))) -> 3 | M11: =B11+E11 -> 12 | N11: =C11+F11+I11 -> 2 | P11: =AE13 -> Kenneth Farrugia/Juan Sammut | Q11: 2 | R11: =IF(Q11>Q9,1,0) -> 0 | T11: 1 | U11: =IF(T11>T9,1,0) -> 0 | X11: =IF(W11>W9,1,0) -> 0 | Y11: =IF(Q11="",0,1) -> 1 | Z11: =IF(R11+U11=2,3,IF(R11+U11=1,1,0)) -> 0 | AA11: =IF(Z11=3,3,IF(X11+Z11=2,2,IF(Z11=1,1,0))) -> 0 | AB11: =Q11+T11 -> 3 | AC11: =R11+U11+X11 -> 0 | AE11: ='Players Men'!B23 -> Neville Sciriha/Matthias Sciriha | AF11: =J11+J25+Y21+J21 -> 4 | AG11: =L11+L25+AA21+L21 -> 11 | AH11: =M11+M25+AB21+M21 -> 46 | AI11: =N11+N25+AC21+N21 -> 8
A13: =AE9 -> Roberto Murdocco/James Brincat | B13: 6 | C13: =IF(B13>B15,1,0) -> 1 | E13: 6 | F13: =IF(E13>E15,1,0) -> 1 | I13: =IF(H13>H15,1,0) -> 0 | J13: =IF(B13="",0,1) -> 1 | K13: =IF(C13+F13=2,3,IF(C13+F13=1,1,0)) -> 3 | L13: =IF(K13=3,3,IF(I13+K13=2,2,IF(K13=1,1,0))) -> 3 | M13: =B13+E13 -> 12 | N13: =C13+F13+I13 -> 2 | P13: =AE9 -> Roberto Murdocco/James Brincat | Q13: 6 | R13: =IF(Q13>Q15,1,0) -> 1 | T13: 6 | U13: =IF(T13>T15,1,0) -> 1 | X13: =IF(W13>W15,1,0) -> 0 | Y13: =IF(Q13="",0,1) -> 1 | Z13: =IF(R13+U13=2,3,IF(R13+U13=1,1,0)) -> 3 | AA13: =IF(Z13=3,3,IF(X13+Z13=2,2,IF(Z13=1,1,0))) -> 3 | AB13: =Q13+T13 -> 12 | AC13: =R13+U13+X13 -> 2 | AE13: ='Players Men'!B24 -> Kenneth Farrugia/Juan Sammut | AF13: =Y17+Y11+J17+J23 -> 4 | AG13: =AA17+AA11+L17+L23 -> 7 | AH13: =AB17+AB11+M17+M23 -> 39 | AI13: =AC17+AC11+N17+N23 -> 5
A14: vs. | P14: vs.
A15: =AE15 -> Simone Re/Ryan Ebejer | B15: 1 | C15: =IF(B15>B13,1,0) -> 0 | E15: 4 | F15: =IF(E15>E13,1,0) -> 0 | I15: =IF(H15>H13,1,0) -> 0 | J15: =IF(B15="",0,1) -> 1 | K15: =IF(C15+F15=2,3,IF(C15+F15=1,1,0)) -> 0 | L15: =IF(K15=3,3,IF(I15+K15=2,2,IF(K15=1,1,0))) -> 0 | M15: =B15+E15 -> 5 | N15: =C15+F15+I15 -> 0 | P15: =AE17 -> Chris Vella/Matthew Micallef | Q15: 3 | R15: =IF(Q15>Q13,1,0) -> 0 | T15: 3 | U15: =IF(T15>T13,1,0) -> 0 | X15: =IF(W15>W13,1,0) -> 0 | Y15: =IF(Q15="",0,1) -> 1 | Z15: =IF(R15+U15=2,3,IF(R15+U15=1,1,0)) -> 0 | AA15: =IF(Z15=3,3,IF(X15+Z15=2,2,IF(Z15=1,1,0))) -> 0 | AB15: =Q15+T15 -> 6 | AC15: =R15+U15+X15 -> 0 | AE15: ='Players Men'!B25 -> Simone Re/Ryan Ebejer | AF15: =Y19+J29+J15+Y23 -> 4 | AG15: =AA19+L29+L15+AA23 -> 2 | AH15: =AB19+M29+M15+AB23 -> 27 | AI15: =AC19+N29+N15+AC23 -> 2
A17: =AE13 -> Kenneth Farrugia/Juan Sammut | B17: 6 | C17: =IF(B17>B19,1,0) -> 1 | E17: 6 | F17: =IF(E17>E19,1,0) -> 1 | I17: =IF(H17>H19,1,0) -> 0 | J17: =IF(B17="",0,1) -> 1 | K17: =IF(C17+F17=2,3,IF(C17+F17=1,1,0)) -> 3 | L17: =IF(K17=3,3,IF(I17+K17=2,2,IF(K17=1,1,0))) -> 3 | M17: =B17+E17 -> 12 | N17: =C17+F17+I17 -> 2 | P17: =AE13 -> Kenneth Farrugia/Juan Sammut | Q17: 6 | R17: =IF(Q17>Q19,1,0) -> 1 | T17: 6 | U17: =IF(T17>T19,1,0) -> 1 | X17: =IF(W17>W19,1,0) -> 0 | Y17: =IF(Q17="",0,1) -> 1 | Z17: =IF(R17+U17=2,3,IF(R17+U17=1,1,0)) -> 3 | AA17: =IF(Z17=3,3,IF(X17+Z17=2,2,IF(Z17=1,1,0))) -> 3 | AB17: =Q17+T17 -> 12 | AC17: =R17+U17+X17 -> 2 | AE17: ='Players Men'!B26 -> Chris Vella/Matthew Micallef | AF17: =J31+J27+Y15+J19 -> 4 | AG17: =L31+L27+AA15+L19 -> 1 | AH17: =M31+M27+AB15+M19 -> 21 | AI17: =N31+N27+AC15+N19 -> 1
A18: vs. | P18: vs.
A19: =AE17 -> Chris Vella/Matthew Micallef | B19: 0 | C19: =IF(B19>B17,1,0) -> 0 | E19: 1 | F19: =IF(E19>E17,1,0) -> 0 | I19: =IF(H19>H17,1,0) -> 0 | J19: =IF(B19="",0,1) -> 1 | K19: =IF(C19+F19=2,3,IF(C19+F19=1,1,0)) -> 0 | L19: =IF(K19=3,3,IF(I19+K19=2,2,IF(K19=1,1,0))) -> 0 | M19: =B19+E19 -> 1 | N19: =C19+F19+I19 -> 0 | P19: =AE15 -> Simone Re/Ryan Ebejer | Q19: 3 | R19: =IF(Q19>Q17,1,0) -> 0 | T19: 4 | U19: =IF(T19>T17,1,0) -> 0 | X19: =IF(W19>W17,1,0) -> 0 | Y19: =IF(Q19="",0,1) -> 1 | Z19: =IF(R19+U19=2,3,IF(R19+U19=1,1,0)) -> 0 | AA19: =IF(Z19=3,3,IF(X19+Z19=2,2,IF(Z19=1,1,0))) -> 0 | AB19: =Q19+T19 -> 7 | AC19: =R19+U19+X19 -> 0 | AE19: Group A Winner
AE20: Neville Sciriha/Matthias Sciriha
A21: =AE11 -> Neville Sciriha/Matthias Sciriha | B21: 7 | C21: =IF(B21>B23,1,0) -> 1 | E21: 3 | F21: =IF(E21>E23,1,0) -> 0 | H21: 10 | I21: =IF(H21>H23,1,0) -> 1 | J21: =IF(B21="",0,1) -> 1 | K21: =IF(C21+F21=2,3,IF(C21+F21=1,1,0)) -> 1 | L21: =IF(K21=3,3,IF(I21+K21=2,2,IF(K21=1,1,0))) -> 2 | M21: =B21+E21 -> 10 | N21: =C21+F21+I21 -> 2 | P21: =AE11 -> Neville Sciriha/Matthias Sciriha | Q21: 6 | R21: =IF(Q21>Q23,1,0) -> 1 | T21: 6 | U21: =IF(T21>T23,1,0) -> 1 | X21: =IF(W21>W23,1,0) -> 0 | Y21: =IF(Q21="",0,1) -> 1 | Z21: =IF(R21+U21=2,3,IF(R21+U21=1,1,0)) -> 3 | AA21: =IF(Z21=3,3,IF(X21+Z21=2,2,IF(Z21=1,1,0))) -> 3 | AB21: =Q21+T21 -> 12 | AC21: =R21+U21+X21 -> 2
A22: vs. | P22: vs.
A23: =AE13 -> Kenneth Farrugia/Juan Sammut | B23: 6 | C23: =IF(B23>B21,1,0) -> 0 | E23: 6 | F23: =IF(E23>E21,1,0) -> 1 | H23: 4 | I23: =IF(H23>H21,1,0) -> 0 | J23: =IF(B23="",0,1) -> 1 | K23: =IF(C23+F23=2,3,IF(C23+F23=1,1,0)) -> 1 | L23: =IF(K23=3,3,IF(I23+K23=2,2,IF(K23=1,1,0))) -> 1 | M23: =B23+E23 -> 12 | N23: =C23+F23+I23 -> 1 | P23: =AE15 -> Simone Re/Ryan Ebejer | Q23: 1 | R23: =IF(Q23>Q21,1,0) -> 0 | T23: 2 | U23: =IF(T23>T21,1,0) -> 0 | X23: =IF(W23>W21,1,0) -> 0 | Y23: =IF(Q23="",0,1) -> 1 | Z23: =IF(R23+U23=2,3,IF(R23+U23=1,1,0)) -> 0 | AA23: =IF(Z23=3,3,IF(X23+Z23=2,2,IF(Z23=1,1,0))) -> 0 | AB23: =Q23+T23 -> 3 | AC23: =R23+U23+X23 -> 0
A25: =AE11 -> Neville Sciriha/Matthias Sciriha | B25: 6 | C25: =IF(B25>B27,1,0) -> 1 | E25: 6 | F25: =IF(E25>E27,1,0) -> 1 | I25: =IF(H25>H27,1,0) -> 0 | J25: =IF(B25="",0,1) -> 1 | K25: =IF(C25+F25=2,3,IF(C25+F25=1,1,0)) -> 3 | L25: =IF(K25=3,3,IF(I25+K25=2,2,IF(K25=1,1,0))) -> 3 | M25: =B25+E25 -> 12 | N25: =C25+F25+I25 -> 2
A26: vs. | AE26: =IF(AL9=30,AN9,"")
A27: =AE17 -> Chris Vella/Matthew Micallef | B27: 0 | C27: =IF(B27>B25,1,0) -> 0 | E27: 3 | F27: =IF(E27>E25,1,0) -> 0 | I27: =IF(H27>H25,1,0) -> 0 | J27: =IF(B27="",0,1) -> 1 | K27: =IF(C27+F27=2,3,IF(C27+F27=1,1,0)) -> 0 | L27: =IF(K27=3,3,IF(I27+K27=2,2,IF(K27=1,1,0))) -> 0 | M27: =B27+E27 -> 3 | N27: =C27+F27+I27 -> 0
A29: =AE15 -> Simone Re/Ryan Ebejer | B29: 6 | C29: =IF(B29>B31,1,0) -> 1 | E29: 6 | F29: =IF(E29>E31,1,0) -> 0 | H29: 9 | I29: =IF(H29>H31,1,0) -> 1 | J29: =IF(B29="",0,1) -> 1 | K29: =IF(C29+F29=2,3,IF(C29+F29=1,1,0)) -> 1 | L29: =IF(K29=3,3,IF(I29+K29=2,2,IF(K29=1,1,0))) -> 2 | M29: =B29+E29 -> 12 | N29: =C29+F29+I29 -> 2
A30: vs.
A31: =AE17 -> Chris Vella/Matthew Micallef | B31: 4 | C31: =IF(B31>B29,1,0) -> 0 | E31: 7 | F31: =IF(E31>E29,1,0) -> 1 | H31: 5 | I31: =IF(H31>H29,1,0) -> 0 | J31: =IF(B31="",0,1) -> 1 | K31: =IF(C31+F31=2,3,IF(C31+F31=1,1,0)) -> 1 | L31: =IF(K31=3,3,IF(I31+K31=2,2,IF(K31=1,1,0))) -> 1 | M31: =B31+E31 -> 11 | N31: =C31+F31+I31 -> 1
A35: Men Division 3 - Group B
A37: Players | B37: Set Scores | H37: Tie | P37: Players | Q37: Set Scores | W37: Tie | AE37: Player | AF37: Games | AG37: Points | AH37: Games Won | AI37: Sets Won
B38: Score | C38: Set 1 Work | E38: Score | F38: Set 2 Work | H38: Score | I38: Tie Work | J38: Game Played | K38: Sets Points Work | L38: Sets & Tie Points Work | M38: Games Wins Work | N38: Sets Wins Work | Q38: Score | R38: Set 1 Work | T38: Score | U38: Set 2 Work | W38: Score | X38: Tie Work | Y38: Game Played | Z38: Sets Points Work | AA38: Sets & Tie Points Work | AB38: Games Wins Work | AC38: Sets Wins Work
A39: =AE39 -> Dunstan Vella/Cyril Lastimosa | B39: 3 | C39: =IF(B39>B41,1,0) -> 0 | E39: 6 | F39: =IF(E39>E41,1,0) -> 1 | H39: 10 | I39: =IF(H39>H41,1,0) -> 1 | J39: =IF(B39="",0,1) -> 1 | K39: =IF(C39+F39=2,3,IF(C39+F39=1,1,0)) -> 1 | L39: =IF(K39=3,3,IF(I39+K39=2,2,IF(K39=1,1,0))) -> 2 | M39: =B39+E39 -> 9 | N39: =C39+F39+I39 -> 2 | P39: =AE39 -> Dunstan Vella/Cyril Lastimosa | Q39: 6 | R39: =IF(Q39>Q41,1,0) -> 1 | T39: 6 | U39: =IF(T39>T41,1,0) -> 1 | X39: =IF(W39>W41,1,0) -> 0 | Y39: =IF(Q39="",0,1) -> 1 | Z39: =IF(R39+U39=2,3,IF(R39+U39=1,1,0)) -> 3 | AA39: =IF(Z39=3,3,IF(X39+Z39=2,2,IF(Z39=1,1,0))) -> 3 | AB39: =Q39+T39 -> 12 | AC39: =R39+U39+X39 -> 2 | AE39: ='Players Men'!E22 -> Dunstan Vella/Cyril Lastimosa | AF39: =J39+Y39+J43+Y43 -> 4 | AG39: =L39+AA39+L43+AA43 -> 11 | AH39: =M39+AB39+M43+AB43 -> 45 | AI39: =N39+AC39+N43+AC43 -> 8
A40: vs. | P40: vs.
A41: =AE41 -> Manuel Mifsud/Julian Esposito | B41: 6 | C41: =IF(B41>B39,1,0) -> 1 | E41: 3 | F41: =IF(E41>E39,1,0) -> 0 | H41: 3 | I41: =IF(H41>H39,1,0) -> 0 | J41: =IF(B41="",0,1) -> 1 | K41: =IF(C41+F41=2,3,IF(C41+F41=1,1,0)) -> 1 | L41: =IF(K41=3,3,IF(I41+K41=2,2,IF(K41=1,1,0))) -> 1 | M41: =B41+E41 -> 9 | N41: =C41+F41+I41 -> 1 | P41: =AE43 -> David Camilleri/Joseph Zammit | Q41: 2 | R41: =IF(Q41>Q39,1,0) -> 0 | T41: 1 | U41: =IF(T41>T39,1,0) -> 0 | X41: =IF(W41>W39,1,0) -> 0 | Y41: =IF(Q41="",0,1) -> 1 | Z41: =IF(R41+U41=2,3,IF(R41+U41=1,1,0)) -> 0 | AA41: =IF(Z41=3,3,IF(X41+Z41=2,2,IF(Z41=1,1,0))) -> 0 | AB41: =Q41+T41 -> 3 | AC41: =R41+U41+X41 -> 0 | AE41: ='Players Men'!E23 -> Manuel Mifsud/Julian Esposito | AF41: =J41+J55+Y51+J51 -> 4 | AG41: =L41+L55+AA51+L51 -> 8 | AH41: =M41+M55+AB51+M51 -> 40 | AI41: =N41+N55+AC51+N51 -> 6
A43: =AE39 -> Dunstan Vella/Cyril Lastimosa | B43: 6 | C43: =IF(B43>B45,1,0) -> 1 | E43: 6 | F43: =IF(E43>E45,1,0) -> 1 | I43: =IF(H43>H45,1,0) -> 0 | J43: =IF(B43="",0,1) -> 1 | K43: =IF(C43+F43=2,3,IF(C43+F43=1,1,0)) -> 3 | L43: =IF(K43=3,3,IF(I43+K43=2,2,IF(K43=1,1,0))) -> 3 | M43: =B43+E43 -> 12 | N43: =C43+F43+I43 -> 2 | P43: =AE39 -> Dunstan Vella/Cyril Lastimosa | Q43: 6 | R43: =IF(Q43>Q45,1,0) -> 1 | T43: 6 | U43: =IF(T43>T45,1,0) -> 1 | X43: =IF(W43>W45,1,0) -> 0 | Y43: =IF(Q43="",0,1) -> 1 | Z43: =IF(R43+U43=2,3,IF(R43+U43=1,1,0)) -> 3 | AA43: =IF(Z43=3,3,IF(X43+Z43=2,2,IF(Z43=1,1,0))) -> 3 | AB43: =Q43+T43 -> 12 | AC43: =R43+U43+X43 -> 2 | AE43: ='Players Men'!E24 -> David Camilleri/Joseph Zammit | AF43: =Y47+Y41+J47+J53 -> 4 | AG43: =AA47+AA41+L47+L53 -> 1 | AH43: =AB47+AB41+M47+M53 -> 20 | AI43: =AC47+AC41+N47+N53 -> 1
A44: vs. | P44: vs.
A45: =AE45 -> Cory Greenland/Christan Xuereb | B45: 1 | C45: =IF(B45>B43,1,0) -> 0 | E45: 1 | F45: =IF(E45>E43,1,0) -> 0 | I45: =IF(H45>H43,1,0) -> 0 | J45: =IF(B45="",0,1) -> 1 | K45: =IF(C45+F45=2,3,IF(C45+F45=1,1,0)) -> 0 | L45: =IF(K45=3,3,IF(I45+K45=2,2,IF(K45=1,1,0))) -> 0 | M45: =B45+E45 -> 2 | N45: =C45+F45+I45 -> 0 | P45: =AE47 -> Aaron Micallef Piccione/Clinton Cutajar | Q45: 2 | R45: =IF(Q45>Q43,1,0) -> 0 | T45: 2 | U45: =IF(T45>T43,1,0) -> 0 | X45: =IF(W45>W43,1,0) -> 0 | Y45: =IF(Q45="",0,1) -> 1 | Z45: =IF(R45+U45=2,3,IF(R45+U45=1,1,0)) -> 0 | AA45: =IF(Z45=3,3,IF(X45+Z45=2,2,IF(Z45=1,1,0))) -> 0 | AB45: =Q45+T45 -> 4 | AC45: =R45+U45+X45 -> 0 | AE45: ='Players Men'!E25 -> Cory Greenland/Christan Xuereb | AF45: =Y49+J59+J45+Y53 -> 4 | AG45: =AA49+L59+L45+AA53 -> 8 | AH45: =AB49+M59+M45+AB53 -> 33 | AI45: =AC49+N59+N45+AC53 -> 6
A47: =AE43 -> David Camilleri/Joseph Zammit | B47: 6 | C47: =IF(B47>B49,1,0) -> 1 | E47: 4 | F47: =IF(E47>E49,1,0) -> 0 | H47: 24 | I47: =IF(H47>H49,1,0) -> 0 | J47: =IF(B47="",0,1) -> 1 | K47: =IF(C47+F47=2,3,IF(C47+F47=1,1,0)) -> 1 | L47: =IF(K47=3,3,IF(I47+K47=2,2,IF(K47=1,1,0))) -> 1 | M47: =B47+E47 -> 10 | N47: =C47+F47+I47 -> 1 | P47: =AE43 -> David Camilleri/Joseph Zammit | Q47: 1 | R47: =IF(Q47>Q49,1,0) -> 0 | T47: 3 | U47: =IF(T47>T49,1,0) -> 0 | X47: =IF(W47>W49,1,0) -> 0 | Y47: =IF(Q47="",0,1) -> 1 | Z47: =IF(R47+U47=2,3,IF(R47+U47=1,1,0)) -> 0 | AA47: =IF(Z47=3,3,IF(X47+Z47=2,2,IF(Z47=1,1,0))) -> 0 | AB47: =Q47+T47 -> 4 | AC47: =R47+U47+X47 -> 0 | AE47: ='Players Men'!E26 -> Aaron Micallef Piccione/Clinton Cutajar | AF47: =J61+J57+Y45+J49 -> 4 | AG47: =L61+L57+AA45+L49 -> 2 | AH47: =M61+M57+AB45+M49 -> 23 | AI47: =N61+N57+AC45+N49 -> 2
A48: vs. | P48: vs.
A49: =AE47 -> Aaron Micallef Piccione/Clinton Cutajar | B49: 4 | C49: =IF(B49>B47,1,0) -> 0 | E49: 6 | F49: =IF(E49>E47,1,0) -> 1 | H49: 26 | I49: =IF(H49>H47,1,0) -> 1 | J49: =IF(B49="",0,1) -> 1 | K49: =IF(C49+F49=2,3,IF(C49+F49=1,1,0)) -> 1 | L49: =IF(K49=3,3,IF(I49+K49=2,2,IF(K49=1,1,0))) -> 2 | M49: =B49+E49 -> 10 | N49: =C49+F49+I49 -> 2 | P49: =AE45 -> Cory Greenland/Christan Xuereb | Q49: 6 | R49: =IF(Q49>Q47,1,0) -> 1 | T49: 6 | U49: =IF(T49>T47,1,0) -> 1 | X49: =IF(W49>W47,1,0) -> 0 | Y49: =IF(Q49="",0,1) -> 1 | Z49: =IF(R49+U49=2,3,IF(R49+U49=1,1,0)) -> 3 | AA49: =IF(Z49=3,3,IF(X49+Z49=2,2,IF(Z49=1,1,0))) -> 3 | AB49: =Q49+T49 -> 12 | AC49: =R49+U49+X49 -> 2 | AE49: Group B Winner
AE50: Dunstan Vella/Cyril Lastimosa
A51: =AE41 -> Manuel Mifsud/Julian Esposito | B51: 6 | C51: =IF(B51>B53,1,0) -> 1 | E51: 6 | F51: =IF(E51>E53,1,0) -> 1 | I51: =IF(H51>H53,1,0) -> 0 | J51: =IF(B51="",0,1) -> 1 | K51: =IF(C51+F51=2,3,IF(C51+F51=1,1,0)) -> 3 | L51: =IF(K51=3,3,IF(I51+K51=2,2,IF(K51=1,1,0))) -> 3 | M51: =B51+E51 -> 12 | N51: =C51+F51+I51 -> 2 | P51: =AE41 -> Manuel Mifsud/Julian Esposito | Q51: 1 | R51: =IF(Q51>Q53,1,0) -> 0 | T51: 6 | U51: =IF(T51>T53,1,0) -> 1 | W51: 5 | X51: =IF(W51>W53,1,0) -> 0 | Y51: =IF(Q51="",0,1) -> 1 | Z51: =IF(R51+U51=2,3,IF(R51+U51=1,1,0)) -> 1 | AA51: =IF(Z51=3,3,IF(X51+Z51=2,2,IF(Z51=1,1,0))) -> 1 | AB51: =Q51+T51 -> 7 | AC51: =R51+U51+X51 -> 1
A52: vs. | P52: vs.
A53: =AE43 -> David Camilleri/Joseph Zammit | B53: 2 | C53: =IF(B53>B51,1,0) -> 0 | E53: 1 | F53: =IF(E53>E51,1,0) -> 0 | I53: =IF(H53>H51,1,0) -> 0 | J53: =IF(B53="",0,1) -> 1 | K53: =IF(C53+F53=2,3,IF(C53+F53=1,1,0)) -> 0 | L53: =IF(K53=3,3,IF(I53+K53=2,2,IF(K53=1,1,0))) -> 0 | M53: =B53+E53 -> 3 | N53: =C53+F53+I53 -> 0 | P53: =AE45 -> Cory Greenland/Christan Xuereb | Q53: 6 | R53: =IF(Q53>Q51,1,0) -> 1 | T53: 1 | U53: =IF(T53>T51,1,0) -> 0 | W53: 10 | X53: =IF(W53>W51,1,0) -> 1 | Y53: =IF(Q53="",0,1) -> 1 | Z53: =IF(R53+U53=2,3,IF(R53+U53=1,1,0)) -> 1 | AA53: =IF(Z53=3,3,IF(X53+Z53=2,2,IF(Z53=1,1,0))) -> 2 | AB53: =Q53+T53 -> 7 | AC53: =R53+U53+X53 -> 2
A55: =AE41 -> Manuel Mifsud/Julian Esposito | B55: 6 | C55: =IF(B55>B57,1,0) -> 1 | E55: 6 | F55: =IF(E55>E57,1,0) -> 1 | I55: =IF(H55>H57,1,0) -> 0 | J55: =IF(B55="",0,1) -> 1 | K55: =IF(C55+F55=2,3,IF(C55+F55=1,1,0)) -> 3 | L55: =IF(K55=3,3,IF(I55+K55=2,2,IF(K55=1,1,0))) -> 3 | M55: =B55+E55 -> 12 | N55: =C55+F55+I55 -> 2
...

Sheet Men Div 4
A1: VITTORIOSA LAWN TENNIS CLUB Sports Experience Chosen Doubles 2025
A5: Men Division 4 - Group A
A7: Players | B7: Set Scores | H7: Tie | P7: Players | Q7: Set Scores | W7: Tie | AE7: Player | AF7: Matches Played | AG7: Points Overall | AH7: Games Won | AI7: Sets Won
B8: Score | C8: Set 1 Work | E8: Score | F8: Set 2 Work | H8: Score | I8: Tie Work | J8: Game Played | K8: Sets Points Work | L8: Sets & Tie Points Work | M8: Games Wins Work | N8: Sets Wins Work | Q8: Score | R8: Set 1 Work | T8: Score | U8: Set 2 Work | W8: Score | X8: Tie Work | Y8: Game Played | Z8: Sets Points Work | AA8: Sets & Tie Points Work | AB8: Games Wins Work | AC8: Sets Wins Work | AJ8: Winner Working | AK8: Runner Up Working | AL8: Total Games Work | AM8: Winner | AN8: Runner Up
A9: =AE9 -> Steve Gambin/Luke Gambin | B9: 6 | C9: =IF(B9>B11,1,0) -> 1 | E9: 6 | F9: =IF(E9>E11,1,0) -> 1 | I9: =IF(H9>H11,1,0) -> 0 | J9: =IF(B9="",0,1) -> 1 | K9: =IF(C9+F9=2,3,IF(C9+F9=1,1,0)) -> 3 | L9: =IF(K9=3,3,IF(I9+K9=2,2,IF(K9=1,1,0))) -> 3 | M9: =B9+E9 -> 12 | N9: =C9+F9+I9 -> 2 | P9: =AE9 -> Steve Gambin/Luke Gambin | Q9: 6 | R9: =IF(Q9>Q11,1,0) -> 1 | T9: 7 | U9: =IF(T9>T11,1,0) -> 1 | X9: =IF(W9>W11,1,0) -> 0 | Y9: =IF(Q9="",0,1) -> 1 | Z9: =IF(R9+U9=2,3,IF(R9+U9=1,1,0)) -> 3 | AA9: =IF(Z9=3,3,IF(X9+Z9=2,2,IF(Z9=1,1,0))) -> 3 | AB9: =Q9+T9 -> 13 | AC9: =R9+U9+X9 -> 2 | AE9: ='Players Men'!B29 -> Steve Gambin/Luke Gambin | AF9: =J9+Y9+J13+Y13 -> 4 | AG9: =L9+AA9+L13+AA13 -> 11 | AH9: =M9+AB9+M13+AB13 -> 49 | AI9: =N9+AC9+N13+AC13 -> 8
A10: vs. | P10: vs.
A11: =AE11 -> JP Sciberras/Justin Scicluna | B11: 3 | C11: =IF(B11>B9,1,0) -> 0 | E11: 2 | F11: =IF(E11>E9,1,0) -> 0 | I11: =IF(H11>H9,1,0) -> 0 | J11: =IF(B11="",0,1) -> 1 | K11: =IF(C11+F11=2,3,IF(C11+F11=1,1,0)) -> 0 | L11: =IF(K11=3,3,IF(I11+K11=2,2,IF(K11=1,1,0))) -> 0 | M11: =B11+E11 -> 5 | N11: =C11+F11+I11 -> 0 | P11: =AE13 -> Kevin Sciberras/Liam Vella | Q11: 2 | R11: =IF(Q11>Q9,1,0) -> 0 | T11: 5 | U11: =IF(T11>T9,1,0) -> 0 | X11: =IF(W11>W9,1,0) -> 0 | Y11: =IF(Q11="",0,1) -> 1 | Z11: =IF(R11+U11=2,3,IF(R11+U11=1,1,0)) -> 0 | AA11: =IF(Z11=3,3,IF(X11+Z11=2,2,IF(Z11=1,1,0))) -> 0 | AB11: =Q11+T11 -> 7 | AC11: =R11+U11+X11 -> 0 | AE11: ='Players Men'!B30 -> JP Sciberras/Justin Scicluna | AF11: =J11+J25+Y21+J21 -> 4 | AG11: =L11+L25+AA21+L21 -> 4 | AH11: =M11+M25+AB21+M21 -> 33 | AI11: =N11+N25+AC21+N21 -> 4
A13: =AE9 -> Steve Gambin/Luke Gambin | B13: 7 | C13: =IF(B13>B15,1,0) -> 1 | E13: 6 | F13: =IF(E13>E15,1,0) -> 1 | I13: =IF(H13>H15,1,0) -> 0 | J13: =IF(B13="",0,1) -> 1 | K13: =IF(C13+F13=2,3,IF(C13+F13=1,1,0)) -> 3 | L13: =IF(K13=3,3,IF(I13+K13=2,2,IF(K13=1,1,0))) -> 3 | M13: =B13+E13 -> 13 | N13: =C13+F13+I13 -> 2 | P13: =AE9 -> Steve Gambin/Luke Gambin | Q13: 4 | R13: =IF(Q13>Q15,1,0) -> 0 | T13: 7 | U13: =IF(T13>T15,1,0) -> 1 | W13: 12 | X13: =IF(W13>W15,1,0) -> 1 | Y13: =IF(Q13="",0,1) -> 1 | Z13: =IF(R13+U13=2,3,IF(R13+U13=1,1,0)) -> 1 | AA13: =IF(Z13=3,3,IF(X13+Z13=2,2,IF(Z13=1,1,0))) -> 2 | AB13: =Q13+T13 -> 11 | AC13: =R13+U13+X13 -> 2 | AE13: ='Players Men'!B31 -> Kevin Sciberras/Liam Vella | AF13: =Y17+Y11+J17+J23 -> 4 | AG13: =AA17+AA11+L17+L23 -> 5 | AH13: =AB17+AB11+M17+M23 -> 40 | AI13: =AC17+AC11+N17+N23 -> 4
A14: vs. | P14: vs.
A15: =AE15 -> Conrad Treeby Ward/Mark Treeby Ward | B15: 5 | C15: =IF(B15>B13,1,0) -> 0 | E15: 1 | F15: =IF(E15>E13,1,0) -> 0 | I15: =IF(H15>H13,1,0) -> 0 | J15: =IF(B15="",0,1) -> 1 | K15: =IF(C15+F15=2,3,IF(C15+F15=1,1,0)) -> 0 | L15: =IF(K15=3,3,IF(I15+K15=2,2,IF(K15=1,1,0))) -> 0 | M15: =B15+E15 -> 6 | N15: =C15+F15+I15 -> 0 | P15: =AE17 -> Adam Green/Franco Montesin | Q15: 6 | R15: =IF(Q15>Q13,1,0) -> 1 | T15: 6 | U15: =IF(T15>T13,1,0) -> 0 | W15: 10 | X15: =IF(W15>W13,1,0) -> 0 | Y15: =IF(Q15="",0,1) -> 1 | Z15: =IF(R15+U15=2,3,IF(R15+U15=1,1,0)) -> 1 | AA15: =IF(Z15=3,3,IF(X15+Z15=2,2,IF(Z15=1,1,0))) -> 1 | AB15: =Q15+T15 -> 12 | AC15: =R15+U15+X15 -> 1 | AE15: ='Players Men'!B32 -> Conrad Treeby Ward/Mark Treeby Ward | AF15: =Y19+J29+J15+Y23 -> 4 | AG15: =AA19+L29+L15+AA23 -> 2 | AH15: =AB19+M29+M15+AB23 -> 33 | AI15: =AC19+N29+N15+AC23 -> 2
A17: =AE13 -> Kevin Sciberras/Liam Vella | B17: 4 | C17: =IF(B17>B19,1,0) -> 0 | E17: 6 | F17: =IF(E17>E19,1,0) -> 0 | I17: =IF(H17>H19,1,0) -> 0 | J17: =IF(B17="",0,1) -> 1 | K17: =IF(C17+F17=2,3,IF(C17+F17=1,1,0)) -> 0 | L17: =IF(K17=3,3,IF(I17+K17=2,2,IF(K17=1,1,0))) -> 0 | M17: =B17+E17 -> 10 | N17: =C17+F17+I17 -> 0 | P17: =AE13 -> Kevin Sciberras/Liam Vella | Q17: 6 | R17: =IF(Q17>Q19,1,0) -> 1 | T17: 5 | U17: =IF(T17>T19,1,0) -> 0 | W17: 10 | X17: =IF(W17>W19,1,0) -> 1 | Y17: =IF(Q17="",0,1) -> 1 | Z17: =IF(R17+U17=2,3,IF(R17+U17=1,1,0)) -> 1 | AA17: =IF(Z17=3,3,IF(X17+Z17=2,2,IF(Z17=1,1,0))) -> 2 | AB17: =Q17+T17 -> 11 | AC17: =R17+U17+X17 -> 2 | AE17: ='Players Men'!B33 -> Adam Green/Franco Montesin | AF17: =J31+J27+Y15+J19 -> 4 | AG17: =L31+L27+AA15+L19 -> 8 | AH17: =M31+M27+AB15+M19 -> 47 | AI17: =N31+N27+AC15+N19 -> 6
A18: vs. | P18: vs.
A19: =AE17 -> Adam Green/Franco Montesin | B19: 6 | C19: =IF(B19>B17,1,0) -> 1 | E19: 7 | F19: =IF(E19>E17,1,0) -> 1 | I19: =IF(H19>H17,1,0) -> 0 | J19: =IF(B19="",0,1) -> 1 | K19: =IF(C19+F19=2,3,IF(C19+F19=1,1,0)) -> 3 | L19: =IF(K19=3,3,IF(I19+K19=2,2,IF(K19=1,1,0))) -> 3 | M19: =B19+E19 -> 13 | N19: =C19+F19+I19 -> 2 | P19: =AE15 -> Conrad Treeby Ward/Mark Treeby Ward | Q19: 4 | R19: =IF(Q19>Q17,1,0) -> 0 | T19: 7 | U19: =IF(T19>T17,1,0) -> 1 | X19: =IF(W19>W17,1,0) -> 0 | Y19: =IF(Q19="",0,1) -> 1 | Z19: =IF(R19+U19=2,3,IF(R19+U19=1,1,0)) -> 1 | AA19: =IF(Z19=3,3,IF(X19+Z19=2,2,IF(Z19=1,1,0))) -> 1 | AB19: =Q19+T19 -> 11 | AC19: =R19+U19+X19 -> 1 | AE19: Group A Winner
AE20: Steve Gambin/Luke Gambin
A21: =AE11 -> JP Sciberras/Justin Scicluna | B21: 3 | C21: =IF(B21>B23,1,0) -> 0 | E21: 3 | F21: =IF(E21>E23,1,0) -> 0 | I21: =IF(H21>H23,1,0) -> 0 | J21: =IF(B21="",0,1) -> 1 | K21: =IF(C21+F21=2,3,IF(C21+F21=1,1,0)) -> 0 | L21: =IF(K21=3,3,IF(I21+K21=2,2,IF(K21=1,1,0))) -> 0 | M21: =B21+E21 -> 6 | N21: =C21+F21+I21 -> 0 | P21: =AE11 -> JP Sciberras/Justin Scicluna | Q21: 6 | R21: =IF(Q21>Q23,1,0) -> 1 | T21: 4 | U21: =IF(T21>T23,1,0) -> 0 | W21: 10 | X21: =IF(W21>W23,1,0) -> 1 | Y21: =IF(Q21="",0,1) -> 1 | Z21: =IF(R21+U21=2,3,IF(R21+U21=1,1,0)) -> 1 | AA21: =IF(Z21=3,3,IF(X21+Z21=2,2,IF(Z21=1,1,0))) -> 2 | AB21: =Q21+T21 -> 10 | AC21: =R21+U21+X21 -> 2
A22: vs. | P22: vs.
A23: =AE13 -> Kevin Sciberras/Liam Vella | B23: 6 | C23: =IF(B23>B21,1,0) -> 1 | E23: 6 | F23: =IF(E23>E21,1,0) -> 1 | I23: =IF(H23>H21,1,0) -> 0 | J23: =IF(B23="",0,1) -> 1 | K23: =IF(C23+F23=2,3,IF(C23+F23=1,1,0)) -> 3 | L23: =IF(K23=3,3,IF(I23+K23=2,2,IF(K23=1,1,0))) -> 3 | M23: =B23+E23 -> 12 | N23: =C23+F23+I23 -> 2 | P23: =AE15 -> Conrad Treeby Ward/Mark Treeby Ward | Q23: 2 | R23: =IF(Q23>Q21,1,0) -> 0 | T23: 6 | U23: =IF(T23>T21,1,0) -> 1 | W23: 4 | X23: =IF(W23>W21,1,0) -> 0 | Y23: =IF(Q23="",0,1) -> 1 | Z23: =IF(R23+U23=2,3,IF(R23+U23=1,1,0)) -> 1 | AA23: =IF(Z23=3,3,IF(X23+Z23=2,2,IF(Z23=1,1,0))) -> 1 | AB23: =Q23+T23 -> 8 | AC23: =R23+U23+X23 -> 1
A25: =AE11 -> JP Sciberras/Justin Scicluna | B25: 6 | C25: =IF(B25>B27,1,0) -> 0 | E25: 6 | F25: =IF(E25>E27,1,0) -> 1 | H25: 10 | I25: =IF(H25>H27,1,0) -> 1 | J25: =IF(B25="",0,1) -> 1 | K25: =IF(C25+F25=2,3,IF(C25+F25=1,1,0)) -> 1 | L25: =IF(K25=3,3,IF(I25+K25=2,2,IF(K25=1,1,0))) -> 2 | M25: =B25+E25 -> 12 | N25: =C25+F25+I25 -> 2
A26: vs.
A27: =A31 -> Adam Green/Franco Montesin | B27: 7 | C27: =IF(B27>B25,1,0) -> 1 | E27: 2 | F27: =IF(E27>E25,1,0) -> 0 | H27: 6 | I27: =IF(H27>H25,1,0) -> 0 | J27: =IF(B27="",0,1) -> 1 | K27: =IF(C27+F27=2,3,IF(C27+F27=1,1,0)) -> 1 | L27: =IF(K27=3,3,IF(I27+K27=2,2,IF(K27=1,1,0))) -> 1 | M27: =B27+E27 -> 9 | N27: =C27+F27+I27 -> 1
A29: =AE15 -> Conrad Treeby Ward/Mark Treeby Ward | B29: 6 | C29: =IF(B29>B31,1,0) -> 0 | E29: 2 | F29: =IF(E29>E31,1,0) -> 0 | I29: =IF(H29>H31,1,0) -> 0 | J29: =IF(B29="",0,1) -> 1 | K29: =IF(C29+F29=2,3,IF(C29+F29=1,1,0)) -> 0 | L29: =IF(K29=3,3,IF(I29+K29=2,2,IF(K29=1,1,0))) -> 0 | M29: =B29+E29 -> 8 | N29: =C29+F29+I29 -> 0
A30: vs.
A31: =AE17 -> Adam Green/Franco Montesin | B31: 7 | C31: =IF(B31>B29,1,0) -> 1 | E31: 6 | F31: =IF(E31>E29,1,0) -> 1 | I31: =IF(H31>H29,1,0) -> 0 | J31: =IF(B31="",0,1) -> 1 | K31: =IF(C31+F31=2,3,IF(C31+F31=1,1,0)) -> 3 | L31: =IF(K31=3,3,IF(I31+K31=2,2,IF(K31=1,1,0))) -> 3 | M31: =B31+E31 -> 13 | N31: =C31+F31+I31 -> 2
A35: Men Division 4 - Group B
A37: Players | B37: Set Scores | H37: Tie | P37: Players | Q37: Set Scores | W37: Tie | AE37: Player | AF37: Matches Played | AG37: Points Overall | AH37: Games Won | AI37: Sets Won
B38: Score | C38: Set 1 Work | E38: Score | F38: Set 2 Work | H38: Score | I38: Tie Work | J38: Game Played | K38: Sets Points Work | L38: Sets & Tie Points Work | M38: Games Wins Work | N38: Sets Wins Work | Q38: Score | R38: Set 1 Work | T38: Score | U38: Set 2 Work | W38: Score | X38: Tie Work | Y38: Game Played | Z38: Sets Points Work | AA38: Sets & Tie Points Work | AB38: Games Wins Work | AC38: Sets Wins Work
A39: =AE39 -> Clifford Debono/Glenn Micallef | B39: 0 | C39: =IF(B39>B41,1,0) -> 0 | E39: 6 | F39: =IF(E39>E41,1,0) -> 1 | H39: 4 | I39: =IF(H39>H41,1,0) -> 0 | J39: =IF(B39="",0,1) -> 1 | K39: =IF(C39+F39=2,3,IF(C39+F39=1,1,0)) -> 1 | L39: =IF(K39=3,3,IF(I39+K39=2,2,IF(K39=1,1,0))) -> 1 | M39: =B39+E39 -> 6 | N39: =C39+F39+I39 -> 1 | P39: =AE39 -> Clifford Debono/Glenn Micallef | Q39: 4 | R39: =IF(Q39>Q41,1,0) -> 0 | T39: 6 | U39: =IF(T39>T41,1,0) -> 1 | W39: 13 | X39: =IF(W39>W41,1,0) -> 1 | Y39: =IF(Q39="",0,1) -> 1 | Z39: =IF(R39+U39=2,3,IF(R39+U39=1,1,0)) -> 1 | AA39: =IF(Z39=3,3,IF(X39+Z39=2,2,IF(Z39=1,1,0))) -> 2 | AB39: =Q39+T39 -> 10 | AC39: =R39+U39+X39 -> 2 | AE39: ='Players Men'!E29 -> Clifford Debono/Glenn Micallef | AF39: =J39+Y39+J43+Y43 -> 4 | AG39: =L39+AA39+L43+AA43 -> 4 | AH39: =M39+AB39+M43+AB43 -> 31 | AI39: =N39+AC39+N43+AC43 -> 4
A40: vs. | P40: vs.
A41: =AE41 -> Robert Attard/ Isaac Baldacchino | B41: 6 | C41: =IF(B41>B39,1,0) -> 1 | E41: 4 | F41: =IF(E41>E39,1,0) -> 0 | H41: 10 | I41: =IF(H41>H39,1,0) -> 1 | J41: =IF(B41="",0,1) -> 1 | K41: =IF(C41+F41=2,3,IF(C41+F41=1,1,0)) -> 1 | L41: =IF(K41=3,3,IF(I41+K41=2,2,IF(K41=1,1,0))) -> 2 | M41: =B41+E41 -> 10 | N41: =C41+F41+I41 -> 2 | P41: =AE43 -> Matthias Cremona/Oliver Brincat | Q41: 6 | R41: =IF(Q41>Q39,1,0) -> 1 | T41: 2 | U41: =IF(T41>T39,1,0) -> 0 | W41: 11 | X41: =IF(W41>W39,1,0) -> 0 | Y41: =IF(Q41="",0,1) -> 1 | Z41: =IF(R41+U41=2,3,IF(R41+U41=1,1,0)) -> 1 | AA41: =IF(Z41=3,3,IF(X41+Z41=2,2,IF(Z41=1,1,0))) -> 1 | AB41: =Q41+T41 -> 8 | AC41: =R41+U41+X41 -> 1 | AE41: ='Players Men'!E30 -> Robert Attard/ Isaac Baldacchino | AF41: =J41+J55+Y51+J51 -> 4 | AG41: =L41+L55+AA51+L51 -> 3 | AH41: =M41+M55+AB51+M51 -> 36 | AI41: =N41+N55+AC51+N51 -> 3
A43: =AE39 -> Clifford Debono/Glenn Micallef | B43: 6 | C43: =IF(B43>B45,1,0) -> 1 | E43: 5 | F43: =IF(E43>E45,1,0) -> 0 | H43: 17 | I43: =IF(H43>H45,1,0) -> 0 | J43: =IF(B43="",0,1) -> 1 | K43: =IF(C43+F43=2,3,IF(C43+F43=1,1,0)) -> 1 | L43: =IF(K43=3,3,IF(I43+K43=2,2,IF(K43=1,1,0))) -> 1 | M43: =B43+E43 -> 11 | N43: =C43+F43+I43 -> 1 | P43: =AE39 -> Clifford Debono/Glenn Micallef | Q43: 3 | R43: =IF(Q43>Q45,1,0) -> 0 | T43: 1 | U43: =IF(T43>T45,1,0) -> 0 | X43: =IF(W43>W45,1,0) -> 0 | Y43: =IF(Q43="",0,1) -> 1 | Z43: =IF(R43+U43=2,3,IF(R43+U43=1,1,0)) -> 0 | AA43: =IF(Z43=3,3,IF(X43+Z43=2,2,IF(Z43=1,1,0))) -> 0 | AB43: =Q43+T43 -> 4 | AC43: =R43+U43+X43 -> 0 | AE43: ='Players Men'!E31 -> Matthias Cremona/Oliver Brincat | AF43: =Y47+Y41+J47+J53 -> 4 | AG43: =AA47+AA41+L47+L53 -> 6 | AH43: =AB47+AB41+M47+M53 -> 40 | AI43: =AC47+AC41+N47+N53 -> 5
A44: vs. | P44: vs.
A45: =AE45 -> Braydon Galea/Gabriel Gauci | B45: 4 | C45: =IF(B45>B43,1,0) -> 0 | E45: 7 | F45: =IF(E45>E43,1,0) -> 1 | H45: 19 | I45: =IF(H45>H43,1,0) -> 1 | J45: =IF(B45="",0,1) -> 1 | K45: =IF(C45+F45=2,3,IF(C45+F45=1,1,0)) -> 1 | L45: =IF(K45=3,3,IF(I45+K45=2,2,IF(K45=1,1,0))) -> 2 | M45: =B45+E45 -> 11 | N45: =C45+F45+I45 -> 2 | P45: =AE47 -> Jason Lee Evans/Sammy Ben Tamer | Q45: 6 | R45: =IF(Q45>Q43,1,0) -> 1 | T45: 6 | U45: =IF(T45>T43,1,0) -> 1 | X45: =IF(W45>W43,1,0) -> 0 | Y45: =IF(Q45="",0,1) -> 1 | Z45: =IF(R45+U45=2,3,IF(R45+U45=1,1,0)) -> 3 | AA45: =IF(Z45=3,3,IF(X45+Z45=2,2,IF(Z45=1,1,0))) -> 3 | AB45: =Q45+T45 -> 12 | AC45: =R45+U45+X45 -> 2 | AE45: ='Players Men'!E32 -> Braydon Galea/Gabriel Gauci | AF45: =Y49+J59+J45+Y53 -> 4 | AG45: =AA49+L59+L45+AA53 -> 7 | AH45: =AB49+M59+M45+AB53 -> 36 | AI45: =AC49+N59+N45+AC53 -> 6
A47: =AE43 -> Matthias Cremona/Oliver Brincat | B47: 4 | C47: =IF(B47>B49,1,0) -> 0 | E47: 5 | F47: =IF(E47>E49,1,0) -> 0 | I47: =IF(H47>H49,1,0) -> 0 | J47: =IF(B47="",0,1) -> 1 | K47: =IF(C47+F47=2,3,IF(C47+F47=1,1,0)) -> 0 | L47: =IF(K47=3,3,IF(I47+K47=2,2,IF(K47=1,1,0))) -> 0 | M47: =B47+E47 -> 9 | N47: =C47+F47+I47 -> 0 | P47: =AE43 -> Matthias Cremona/Oliver Brincat | Q47: 6 | R47: =IF(Q47>Q49,1,0) -> 1 | T47: 6 | U47: =IF(T47>T49,1,0) -> 1 | X47: =IF(W47>W49,1,0) -> 0 | Y47: =IF(Q47="",0,1) -> 1 | Z47: =IF(R47+U47=2,3,IF(R47+U47=1,1,0)) -> 3 | AA47: =IF(Z47=3,3,IF(X47+Z47=2,2,IF(Z47=1,1,0))) -> 3 | AB47: =Q47+T47 -> 12 | AC47: =R47+U47+X47 -> 2 | AE47: ='Players Men'!E33 -> Jason Lee Evans/Sammy Ben Tamer | AF47: =J61+J57+Y45+J49 -> 4 | AG47: =L61+L57+AA45+L49 -> 10 | AH47: =M61+M57+AB45+M49 -> 48 | AI47: =N61+N57+AC45+N49 -> 7
A48: vs. | P48: vs.
A49: =AE47 -> Jason Lee Evans/Sammy Ben Tamer | B49: 6 | C49: =IF(B49>B47,1,0) -> 1 | E49: 7 | F49: =IF(E49>E47,1,0) -> 1 | I49: =IF(H49>H47,1,0) -> 0 | J49: =IF(B49="",0,1) -> 1 | K49: =IF(C49+F49=2,3,IF(C49+F49=1,1,0)) -> 3 | L49: =IF(K49=3,3,IF(I49+K49=2,2,IF(K49=1,1,0))) -> 3 | M49: =B49+E49 -> 13 | N49: =C49+F49+I49 -> 2 | P49: =AE45 -> Braydon Galea/Gabriel Gauci | Q49: 2 | R49: =IF(Q49>Q47,1,0) -> 0 | T49: 4 | U49: =IF(T49>T47,1,0) -> 0 | X49: =IF(W49>W47,1,0) -> 0 | Y49: =IF(Q49="",0,1) -> 1 | Z49: =IF(R49+U49=2,3,IF(R49+U49=1,1,0)) -> 0 | AA49: =IF(Z49=3,3,IF(X49+Z49=2,2,IF(Z49=1,1,0))) -> 0 | AB49: =Q49+T49 -> 6 | AC49: =R49+U49+X49 -> 0 | AE49: Group B Winner
AE50: Jason Lee Evans/Sammy Ben Tamer
A51: =AE41 -> Robert Attard/ Isaac Baldacchino | B51: 4 | C51: =IF(B51>B53,1,0) -> 0 | E51: 7 | F51: =IF(E51>E53,1,0) -> 1 | H51: 8 | I51: =IF(H51>H53,1,0) -> 0 | J51: =IF(B51="",0,1) -> 1 | K51: =IF(C51+F51=2,3,IF(C51+F51=1,1,0)) -> 1 | L51: =IF(K51=3,3,IF(I51+K51=2,2,IF(K51=1,1,0))) -> 1 | M51: =B51+E51 -> 11 | N51: =C51+F51+I51 -> 1 | P51: =AE41 -> Robert Attard/ Isaac Baldacchino | Q51: 2 | R51: =IF(Q51>Q53,1,0) -> 0 | T51: 4 | U51: =IF(T51>T53,1,0) -> 0 | X51: =IF(W51>W53,1,0) -> 0 | Y51: =IF(Q51="",0,1) -> 1 | Z51: =IF(R51+U51=2,3,IF(R51+U51=1,1,0)) -> 0 | AA51: =IF(Z51=3,3,IF(X51+Z51=2,2,IF(Z51=1,1,0))) -> 0 | AB51: =Q51+T51 -> 6 | AC51: =R51+U51+X51 -> 0
A52: vs. | P52: vs.
A53: =AE43 -> Matthias Cremona/Oliver Brincat | B53: 6 | C53: =IF(B53>B51,1,0) -> 1 | E53: 5 | F53: =IF(E53>E51,1,0) -> 0 | H53: 10 | I53: =IF(H53>H51,1,0) -> 1 | J53: =IF(B53="",0,1) -> 1 | K53: =IF(C53+F53=2,3,IF(C53+F53=1,1,0)) -> 1 | L53: =IF(K53=3,3,IF(I53+K53=2,2,IF(K53=1,1,0))) -> 2 | M53: =B53+E53 -> 11 | N53: =C53+F53+I53 -> 2 | P53: =AE45 -> Braydon Galea/Gabriel Gauci | Q53: 6 | R53: =IF(Q53>Q51,1,0) -> 1 | T53: 6 | U53: =IF(T53>T51,1,0) -> 1 | X53: =IF(W53>W51,1,0) -> 0 | Y53: =IF(Q53="",0,1) -> 1 | Z53: =IF(R53+U53=2,3,IF(R53+U53=1,1,0)) -> 3 | AA53: =IF(Z53=3,3,IF(X53+Z53=2,2,IF(Z53=1,1,0))) -> 3 | AB53: =Q53+T53 -> 12 | AC53: =R53+U53+X53 -> 2
A55: =AE41 -> Robert Attard/ Isaac Baldacchino | B55: 4 | C55: =IF(B55>B57,1,0) -> 0 | E55: 5 | F55: =IF(E55>E57,1,0) -> 0 | I55: =IF(H55>H57,1,0) -> 0 | J55: =IF(B55="",0,1) -> 1 | K55: =IF(C55+F55=2,3,IF(C55+F55=1,1,0)) -> 0 | L55: =IF(K55=3,3,IF(I55+K55=2,2,IF(K55=1,1,0))) -> 0 | M55: =B55+E55 -> 9 | N55: =C55+F55+I55 -> 0
...

Sheet Players Ladies
A1: VITTORIOSA LAWN TENNIS CLUB
A2: Sports Experience Chosen Doubles 2025
B5: Ladies Division 1
A6: 1 | B6: Renette Magro/Diane Fenech
A7: 2 | B7: Alexia Spiteri Willets/Pamela Cohen
A8: 3 | B8: Lucienne Meli Belizzi/Alison Muscat
A9: 4 | B9: Martina Cuschieri/Elaine Grech
A10: 5 | B10: Kim Fava/Annmarie Mangion
A11: 5 | B11: Kirsty Mercieca/Christina Bonett
B13: Ladies Division 2 - Group A
A14: 1 | B14: Kristina Briffa/Sarah Axiaq
A15: 2 | B15: Mariska Steenkamer/Yanika Pace
A16: 3 | B16: Giada Sciberras/Jade Sammut
A17: 4 | B17: Francesca Sciortino/Julie Spiteri
A18: 5 | B18: Brenda Baldacchino/Deborah Farrugia
A19: 6 | B19: Katrina Grech/Dawn Azzopardi
B21: Ladies Division 3 - Group A | E21: Ladies Division 3 - Group B
A22: 1 | B22: Nancy Wong/Jin Attard | D22: 1 | E22: Rowena Caruana/Ceridwen Scerri
A23: 2 | B23: Helga Azzopardi/Angele Pule' | D23: 2 | E23: Ann Marie Attard/Christine Seychell
A24: 3 | B24: Tiffany Fenech/Martina Murdocco | D24: 3 | E24: Karolina Papiernak/Jennifer Roca
A25: 4 | B25: Leanne Sammut/Daphne Vella | D25: 4 | E25: Janice Galea/Tiziana Spiteri
A26: 5 | B26: Mary Borg/Sharleen Sciberras | D26: 5 | E26: Roberta Grixti/Francesca Mamo
A27: 6 | B27: Jean Frendo/Antoinette Aquilina | D27: 6 | E27: Maria Angela Gambin/Maria Ellul

Sheet Lad Div 1
A1: VITTORIOSA LAWN TENNIS CLUB Sports Experience Chosen Doubles 2025
A5: Ladies Division 1
A7: Players | B7: Set Scores | H7: Tie | P7: Players | Q7: Set Scores | W7: Tie | AE7: Player | AF7: Matches Played | AG7: Points Overall | AH7: Games Won | AI7: Sets Won
B8: Score | C8: Set 1 Work | E8: Score | F8: Set 2 Work | H8: Score | I8: Tie Work | J8: Game Played | K8: Sets Points Work | L8: Sets & Tie Points Work | M8: Games Wins Work | N8: Sets Wins Work | Q8: Score | R8: Set 1 Work | T8: Score | U8: Set 2 Work | W8: Score | X8: Tie Work | Y8: Game Played | Z8: Sets Points Work | AA8: Sets & Tie Points Work | AB8: Games Wins Work | AC8: Sets Wins Work | AJ8: Winner Working | AK8: Runner Up Working | AL8: Total Games Work | AM8: Winner | AN8: Runner Up
