Workbook

Sheet Team Selection 1-3
B1: VITTORIOSA LAWN TENNIS CLUB
A2: “The Joe Carabott Memorial Team Tournament - Sponsored by Antes.”
C3: A | D3: B | E3: C | F3: D | G3: E | H3: F
B4: CAPTAIN
B6: MEN
B7: A1
B8: A2
B9: A3
B11: B1
B12: B2
B13: B3
B15: C1
B16: C2
B17: C3
B19: D1
... B34: C3

Sheet Team Selection 1-4
A1: VITTORIOSA LAWN TENNIS CLUB
A2: WILSON AUTUMN TEAM TOURNAMENT 20
B3: A | C3: B | D3: C | E3: D | F3: E | G3: F
A4: CAPTAIN
A6: MEN
A7: A1
A8: A2
A9: A3
A11: B1
A12: B2
A13: B3
A15: C1
A16: C2
A17: C3
A18: C4
... A36: C3

Sheet Standings
B2: VITTORIOSA LAWN TENNIS CLUB
A3: “The Joe Carabott Memorial Team Tournament - Sponsored by Antes.”
D5: Day 1 | F5: Total Day 1 | I5: Day 2 | K5: Total Day 2 | N5: Day 3 | P5: Total Day 3 | S5: Day 4 | U5: Total Day 4 | X5: Day 5 | Z5: Total Day 5 | AC5: Total Round 1
D6: G | E6: S | F6: G | G6: S | I6: G | J6: S | K6: G | L6: S | N6: G | O6: S | P6: G | Q6: S | S6: G | T6: S | U6: G | V6: S | X6: G | Y6: S | Z6: G | AA6: S | AC6: G | AD6: S
B8: TEAM A: | C8: Wednesday | D8: =SUM('Day 1'!J22) -> 0 | E8: =SUM('Day 1'!L22) -> 0 | F8: =D8+D9 -> 0 | G8: =E8+E9 -> 0 | I8: =SUM('Day 2'!J60) -> 0 | J8: =SUM('Day 2'!L60) -> 0 | K8: =I8+I9 -> 0 | L8: =SUM(J8+J9) -> 0 | N8: =SUM('Day 3'!J95) -> 0 | O8: =SUM('Day 3'!L95) -> 0 | P8: =N8+N9 -> 0 | Q8: =O8+O9 -> 0 | S8: =SUM('Day 4'!J60) -> 0 | T8: =SUM('Day 4'!L60) -> 0 | U8: =S8+S9 -> 0 | V8: =T8+T9 -> 0 | X8: =SUM('Day 5'!J95) -> 0 | Y8: =SUM('Day 5'!L95) -> 0 | Z8: =X8+X9 -> 0 | AA8: =Y8+Y9 -> 0 | AC8: =+F8+K8+P8+U8+Z8 -> 0 | AD8: =+G8+L8+Q8+V8+AA8 -> 0
C9: Friday | D9: =SUM('Day 1'!J36) -> 0 | E9: =SUM('Day 1'!L36) -> 0 | I9: =SUM('Day 2'!J75) -> 0 | J9: =SUM('Day 2'!L75) -> 0 | N9: =SUM('Day 3'!J110) -> 0 | O9: =SUM('Day 3'!L110) -> 0 | S9: =SUM('Day 4'!J75) -> 0 | T9: =SUM('Day 4'!L75) -> 0 | X9: =SUM('Day 5'!J110) -> 0 | Y9: =SUM('Day 5'!L110) -> 0
B11: TEAM B: | C11: Wednesday | D11: =SUM('Day 1'!J55) -> 0 | E11: =SUM('Day 1'!L55) -> 0 | F11: =D11+D12 -> 0 | G11: =E11+E12 -> 0 | I11: =SUM('Day 2'!J25) -> 0 | J11: =SUM('Day 2'!L25) -> 0 | K11: =I11+I12 -> 0 | L11: =SUM(J11+J12) -> 0 | N11: =SUM('Day 3'!J60) -> 0 | O11: =SUM('Day 3'!L60) -> 0 | P11: =N11+N12 -> 0 | Q11: =O11+O12 -> 0 | S11: =SUM('Day 4'!J95) -> 0 | T11: =SUM('Day 4'!L95) -> 0 | U11: =S11+S12 -> 0 | V11: =T11+T12 -> 0 | X11: =SUM('Day 5'!K95) -> 0 | Y11: =SUM('Day 5'!M95) -> 0 | Z11: =X11+X12 -> 0 | AA11: =Y11+Y12 -> 0 | AC11: =+F11+K11+P11+U11+Z11 -> 0 | AD11: =+G11+L11+Q11+V11+AA11 -> 0
C12: Friday | D12: =SUM('Day 1'!J69) -> 0 | E12: =SUM('Day 1'!L69) -> 0 | I12: =SUM('Day 2'!J40) -> 0 | J12: =SUM('Day 2'!L40) -> 0 | N12: =SUM('Day 3'!J75) -> 0 | O12: =SUM('Day 3'!L75) -> 0 | S12: =SUM('Day 4'!J110) -> 0 | T12: =SUM('Day 4'!L110) -> 0 | X12: =SUM('Day 5'!K110) -> 0 | Y12: =SUM('Day 5'!M110) -> 0
B14: TEAM C: | C14: Wednesday | D14: =SUM('Day 1'!K22) -> 0 | E14: =SUM('Day 1'!M22) -> 0 | F14: =D14+D15 -> 0 | G14: =E14+E15 -> 0 | I14: =SUM('Day 2'!J95) -> 0 | J14: =SUM('Day 2'!L95) -> 0 | K14: =I14+I15 -> 0 | L14: =SUM(J14+J15) -> 0 | N14: =SUM('Day 3'!K60) -> 0 | O14: =SUM('Day 3'!M60) -> 0 | P14: =N14+N15 -> 0 | Q14: =O14+O15 -> 0 | S14: =SUM('Day 4'!J25) -> 0 | T14: =SUM('Day 4'!L25) -> 0 | U14: =S14+S15 -> 0 | V14: =T14+T15 -> 0 | X14: =SUM('Day 5'!J25) -> 0 | Y14: =SUM('Day 5'!L25) -> 0 | Z14: =X14+X15 -> 0 | AA14: =Y14+Y15 -> 0 | AC14: =+F14+K14+P14+U14+Z14 -> 0 | AD14: =+G14+L14+Q14+V14+AA14 -> 0
C15: Friday | D15: =SUM('Day 1'!K36) -> 0 | E15: =SUM('Day 1'!M36) -> 0 | I15: =SUM('Day 2'!J110) -> 0 | J15: =SUM('Day 2'!L110) -> 0 | N15: =SUM('Day 3'!K75) -> 0 | O15: =SUM('Day 3'!M75) -> 0 | S15: =SUM('Day 4'!J40) -> 0 | T15: =SUM('Day 4'!L113) -> 0 | X15: =SUM('Day 5'!J40) -> 0 | Y15: =SUM('Day 5'!L40) -> 0
B17: TEAM D: | C17: Wednesday | D17: =SUM('Day 1'!J86) -> 0 | E17: =SUM('Day 1'!L86) -> 0 | F17: =D17+D18 -> 0 | G17: =E17+E18 -> 0 | I17: =SUM('Day 2'!K25) -> 0 | J17: =SUM('Day 2'!M25) -> 0 | K17: =I17+I18 -> 0 | L17: =SUM(J17+J18) -> 0 | N17: =SUM('Day 3'!K95) -> 0 | O17: =SUM('Day 3'!M95) -> 0 | P17: =N17+N18 -> 0 | Q17: =O17+O18 -> 0 | S17: =SUM('Day 4'!K25) -> 0 | T17: =SUM('Day 4'!M25) -> 0 | U17: =S17+S18 -> 0 | V17: =T17+T18 -> 0 | X17: =SUM('Day 5'!J60) -> 0 | Y17: =SUM('Day 5'!L60) -> 0 | Z17: =X17+X18 -> 0 | AA17: =Y17+Y18 -> 0 | AC17: =+F17+K17+P17+U17+Z17 -> 0 | AD17: =+G17+L17+Q17+V17+AA17 -> 0
C18: Friday | D18: =SUM('Day 1'!J100) -> 0 | E18: =SUM('Day 1'!L100) -> 0 | I18: =SUM('Day 2'!K40) -> 0 | J18: =SUM('Day 2'!M40) -> 0 | N18: =SUM('Day 3'!K110) -> 0 | O18: =SUM('Day 3'!M110) -> 0 | S18: =SUM('Day 4'!K40) -> 0 | T18: =SUM('Day 4'!M40) -> 0 | X18: =SUM('Day 5'!J75) -> 0 | Y18: =SUM('Day 5'!L75) -> 0
B20: TEAM E: | C20: Wednesday | D20: =SUM('Day 1'!K55) -> 0 | E20: =SUM('Day 1'!M55) -> 0 | F20: =D20+D21 -> 0 | G20: =E20+E21 -> 0 | I20: =SUM('Day 2'!K95) -> 0 | J20: =SUM('Day 2'!M95) -> 0 | K20: =I20+I21 -> 0 | L20: =SUM(J20+J21) -> 0 | N20: =SUM('Day 3'!J25) -> 0 | O20: =SUM('Day 3'!L25) -> 0 | P20: =N20+N21 -> 0 | Q20: =O20+O21 -> 0 | S20: =SUM('Day 4'!K60) -> 0 | T20: =SUM('Day 4'!M60) -> 0 | U20: =S20+S21 -> 0 | V20: =T20+T21 -> 0 | X20: =SUM('Day 5'!K60) -> 0 | Y20: =SUM('Day 5'!M60) -> 0 | Z20: =X20+X21 -> 0 | AA20: =Y20+Y21 -> 0 | AC20: =+F20+K20+P20+U20+Z20 -> 0 | AD20: =+G20+L20+Q20+V20+AA20 -> 0
C21: Friday | D21: =SUM('Day 1'!K69) -> 0 | E21: =SUM('Day 1'!M69) -> 0 | I21: =SUM('Day 2'!K110) -> 0 | J21: =SUM('Day 2'!M110) -> 0 | N21: =SUM('Day 3'!J40) -> 0 | O21: =SUM('Day 3'!L40) -> 0 | S21: =SUM('Day 4'!K75) -> 0 | T21: =SUM('Day 4'!M75) -> 0 | X21: =SUM('Day 5'!K75) -> 0 | Y21: =SUM('Day 5'!M75) -> 0
B23: TEAM F: | C23: Wednesday | D23: =SUM('Day 1'!K86) -> 0 | E23: =SUM('Day 1'!M86) -> 0 | F23: =D23+D24 -> 0 | G23: =E23+E24 -> 0 | I23: =SUM('Day 2'!K60) -> 0 | J23: =SUM('Day 2'!M60) -> 0 | K23: =I23+I24 -> 0 | L23: =SUM(J23+J24) -> 0 | N23: =SUM('Day 3'!K25) -> 0 | O23: =SUM('Day 3'!M25) -> 0 | P23: =N23+N24 -> 0 | Q23: =O23+O24 -> 0 | S23: =SUM('Day 4'!K95) -> 0 | T23: =SUM('Day 4'!M95) -> 0 | U23: =S23+S24 -> 0 | V23: =T23+T24 -> 0 | X23: =SUM('Day 5'!K25) -> 0 | Y23: =SUM('Day 5'!M25) -> 0 | Z23: =X23+X24 -> 0 | AA23: =Y23+Y24 -> 0 | AC23: =+F23+K23+P23+U23+Z23 -> 0 | AD23: =+G23+L23+Q23+V23+AA23 -> 0
C24: Friday | D24: =SUM('Day 1'!K100) -> 0 | E24: =SUM('Day 1'!M100) -> 0 | I24: =SUM('Day 2'!K75) -> 0 | J24: =SUM('Day 2'!M75) -> 0 | N24: =SUM('Day 3'!K40) -> 0 | O24: =SUM('Day 3'!M40) -> 0 | S24: =SUM('Day 4'!K110) -> 0 | T24: =SUM('Day 4'!M110) -> 0 | X24: =SUM('Day 5'!K40) -> 0 | Y24: =SUM('Day 5'!M40) -> 0
B30: Winners:
B32: Runners Up:

Sheet Encounters played
B2: VITTORIOSA LAWN TENNIS CLUB
A3: “The Joe Carabott Memorial Team Tournament - Sponsored by Antes.”
B5: Day | C5: 1 | D5: 2 | E5: 3 | F5: 4 | G5: 5 | H5: Total | J5: Day | K5: 1 | L5: 2 | M5: 3 | N5: 4 | O5: 5 | P5: Total
A6: A | I6: B
A7: A1 | H7: =SUM(C7:G7) -> 0 | I7: A1 | P7: =SUM(K7:O7) -> 0
A8: A2 | H8: =SUM(C8:G8) -> 0 | I8: A2 | P8: =SUM(K8:O8) -> 0
A9: A3 | H9: =SUM(C9:G9) -> 0 | I9: A3 | P9: =SUM(K9:O9) -> 0
A10: B1 | H10: =SUM(C10:G10) -> 0 | I10: B1 | P10: =SUM(K10:O10) -> 0
A11: B2 | H11: =SUM(C11:G11) -> 0 | I11: B2 | P11: =SUM(K11:O11) -> 0
A12: B3 | H12: =SUM(C12:G12) -> 0 | I12: B3 | P12: =SUM(K12:O12) -> 0
A13: C1 | H13: =SUM(C13:G13) -> 0 | I13: C1 | P13: =SUM(K13:O13) -> 0
A14: C2 | H14: =SUM(C14:G14) -> 0 | I14: C2 | P14: =SUM(K14:O14) -> 0
A15: C3 | H15: =SUM(C15:G15) -> 0 | I15: C3 | P15: =SUM(K15:O15) -> 0
A16: C4 | H16: =SUM(C16:G16) -> 0 | I16: C4 | P16: =SUM(K16:O16) -> 0
A17: D1 | H17: =SUM(C17:G17) -> 0 | I17: D1 | P17: =SUM(K17:O17) -> 0
A18: D2 | H18: =SUM(C18:G18) -> 0 | I18: D2 | P18: =SUM(K18:O18) -> 0
... A30: C3 | H30: =SUM(C30:G30) -> 0 | I30: C3 | P30: =SUM(K30:O30) -> 0
B42: Day | C42: 1 | D42: 2 | E42: 3 | F42: 4 | G42: 5 | H42: Total | J42: Day | K42: 1 | L42: 2 | M42: 3 | N42: 4 | O42: 5 | P42: Total
A43: C | I43: D
A44: A1 | H44: =SUM(C44:G44) -> 0 | I44: A1 | P44: =SUM(K44:O44) -> 0
A45: A2 | H45: =SUM(C45:G45) -> 0 | I45: A2 | P45: =SUM(K45:O45) -> 0
A46: A3 | H46: =SUM(C46:G46) -> 0 | I46: A3 | P46: =SUM(K46:O46) -> 0
A47: B1 | H47: =SUM(C47:G47) -> 0 | I47: B1 | P47: =SUM(K47:O47) -> 0
A48: B2 | H48: =SUM(C48:G48) -> 0 | I48: B2 | P48: =SUM(K48:O48) -> 0
A49: B3 | H49: =SUM(C49:G49) -> 0 | I49: B3 | P49: =SUM(K49:O49) -> 0
A50: C1 | H50: =SUM(C50:G50) -> 0 | I50: C1 | P50: =SUM(K50:O50) -> 0
A51: C2 | H51: =SUM(C51:G51) -> 0 | I51: C2 | P51: =SUM(K51:O51) -> 0
A52: C3 | H52: =SUM(C52:G52) -> 0 | I52: C3 | P52: =SUM(K52:O52) -> 0
A53: C4 | H53: =SUM(C53:G53) -> 0 | I53: C4 | P53: =SUM(K53:O53) -> 0
A54: D1 | H54: =SUM(C54:G54) -> 0 | I54: D1 | P54: =SUM(K54:O54) -> 0
A55: D2 | H55: =SUM(C55:G55) -> 0 | I55: D2 | P55: =SUM(K55:O55) -> 0
... A67: C3 | H67: =SUM(C67:G67) -> 0 | I67: C3 | P67: =SUM(K67:O67) -> 0
B78: Day | C78: 1 | D78: 2 | E78: 3 | F78: 4 | G78: 5 | H78: Total | J78: Day | K78: 1 | L78: 2 | M78: 3 | N78: 4 | O78: 5 | P78: Total
A79: E | I79: F
A80: A1 | H80: =SUM(C80:G80) -> 0 | I80: A1 | P80: =SUM(K80:O80) -> 0
A81: A2 | H81: =SUM(C81:G81) -> 0 | I81: A2 | P81: =SUM(K81:O81) -> 0
A82: A3 | H82: =SUM(C82:G82) -> 0 | I82: A3 | P82: =SUM(K82:O82) -> 0
A83: B1 | H83: =SUM(C83:G83) -> 0 | I83: B1 | P83: =SUM(K83:O83) -> 0
A84: B2 | H84: =SUM(C84:G84) -> 0 | I84: B2 | P84: =SUM(K84:O84) -> 0
A85: B3 | H85: =SUM(C85:G85) -> 0 | I85: B3 | P85: =SUM(K85:O85) -> 0
...

Sheet Day 1
C2: VITTORIOSA LAWN TENNIS CLUB
C3: “The Joe Carabott Memorial Team Tournament - Sponsored by Antes.”
C6: DAY 1
C9: Court 1
C11: Time | D11: Rubber | E11: Team A: | G11: vs | H11: Team C: | J11: Games | L11: Sets
C12: 6.30 pm | G12: vs | L12: =IF(J12+J13=12,2,IF(J12=6,1,IF(J13=6,1,0))) -> 0 | M12: =IF(K12+K13=12,2,IF(K12=6,1,IF(K13=6,1,0))) -> 0
C15: 7.45 pm | G15: vs | L15: =IF(J15+J16=12,2,IF(J15=6,1,IF(J16=6,1,0))) -> 0 | M15: 0
C18: 9.00 pm | G18: vs | L18: =IF(J18+J19=12,2,IF(J18=6,1,IF(J19=6,1,0))) -> 0 | M18: =IF(K18+K19=12,2,IF(K18=6,1,IF(K19=6,1,0))) -> 0
C22: Total Day 1 A | J22: =SUM(J12:J20) -> 0 | K22: =SUM(K12:K20) -> 0 | L22: =SUM(L12:L20) -> 0 | M22: =SUM(M12:M20) -> 0
C24: 6.30 pm | G24: vs | L24: =IF(J24+J25=12,2,IF(J24=6,1,IF(J25=6,1,0))) -> 0 | M24: =IF(K24+K25=12,2,IF(K24=6,1,IF(K25=6,1,0))) -> 0
C27: 7.45 pm | G27: vs | L27: =IF(J27+J28=12,2,IF(J27=6,1,IF(J28=6,1,0))) -> 0 | M27: =IF(K27+K28=12,2,IF(K27=6,1,IF(K28=6,1,0))) -> 0
C30: 9.00 pm | G30: vs | L30: =IF(J30+J31=12,2,IF(J30=6,1,IF(J31=6,1,0))) -> 0 | M30: =IF(K30+K31=12,2,IF(K30=6,1,IF(K31=6,1,0))) -> 0
C33: 6.30 pm | G33: vs | L33: =IF(J33+J34=12,2,IF(J33=6,1,IF(J34=6,1,0))) -> 0 | M33: =IF(K33+K34=12,2,IF(K33=6,1,IF(K34=6,1,0))) -> 0
C36: Total Day 1B | J36: =SUM(J24:J34) -> 0 | K36: =SUM(K24:K34) -> 0 | L36: =SUM(L24:L34) -> 0 | M36: =SUM(M24:M34) -> 0
C38: Total Day 1 | J38: =J36+J22 -> 0 | K38: =K36+K22 -> 0 | L38: =L36+L22 -> 0 | M38: =M36+M22 -> 0
C40: Court 2
C42: Time | D42: Rubber | E42: Team B: | G42: vs | H42: Team E: | J42: Games | L42: Sets
C43: 6.30 pm | G43: vs | L43: =IF(J43+J44=12,2,IF(J43=6,1,IF(J44=6,1,0))) -> 0 | M43: =IF(K43+K44=12,2,IF(K43=6,1,IF(K44=6,1,0))) -> 0
C46: 7.45 pm | G46: vs | L46: =IF(J46+J47=12,2,IF(J46=6,1,IF(J47=6,1,0))) -> 0 | M46: =IF(K46+K47=12,2,IF(K46=6,1,IF(K47=6,1,0))) -> 0
C49: 9.00 pm | G49: vs | L49: =IF(J49+J50=12,2,IF(J49=6,1,IF(J50=6,1,0))) -> 0 | M49: =IF(K49+K50=12,2,IF(K49=6,1,IF(K50=6,1,0))) -> 0
C52: 7.45 pm | G52: vs | L52: =IF(J52+J53=12,2,IF(J52=6,1,IF(J53=6,1,0))) -> 0 | M52: =IF(K52+K53=12,2,IF(K52=6,1,IF(K53=6,1,0))) -> 0
C55: Total Day 1 A | J55: =SUM(J43:J53) -> 0 | K55: =SUM(K43:K53) -> 0 | L55: =SUM(L43:L53) -> 0 | M55: =SUM(M43:M53) -> 0
C57: 6.3 | G57: vs | L57: =IF(J57+J58=12,2,IF(J57=6,1,IF(J58=6,1,0))) -> 0 | M57: =IF(K57+K58=12,2,IF(K57=6,1,IF(K58=6,1,0))) -> 0
C60: 7.45 | G60: vs | L60: =IF(J60+J61=12,2,IF(J60=6,1,IF(J61=6,1,0))) -> 0 | M60: =IF(K60+K61=12,2,IF(K60=6,1,IF(K61=6,1,0))) -> 0
C63: 9 | G63: vs | L63: =IF(J63+J64=12,2,IF(J63=6,1,IF(J64=6,1,0))) -> 0 | M63: =IF(K63+K64=12,2,IF(K63=6,1,IF(K64=6,1,0))) -> 0
C66: 7.45 pm | G66: vs | L66: =IF(J66+J67=12,2,IF(J66=6,1,IF(J67=6,1,0))) -> 0 | M66: =IF(K66+K67=12,2,IF(K66=6,1,IF(K67=6,1,0))) -> 0
C69: Total Day 1B | J69: =SUM(J57:J67) -> 0 | K69: =SUM(K57:K67) -> 0 | L69: =SUM(L57:L67) -> 0 | M69: =SUM(M57:M67) -> 0
C71: Total Day 1 | J71: =SUM(J55+J69) -> 0 | K71: =K69+K55 -> 0 | L71: =L69+L55 -> 0 | M71: =M69+M55 -> 0
C73: Court 4
C75: Time | D75: Rubber | E75: Team D: | G75: vs | H75: Team F: | J75: Games | L75: Sets
C76: 6.30 pm | G76: vs | L76: =IF(J76+J77=12,2,IF(J76=6,1,IF(J77=6,1,0))) -> 0 | M76: =IF(K76+K77=12,2,IF(K76=6,1,IF(K77=6,1,0))) -> 0
C79: 7.45 pm | G79: vs | L79: =IF(J79+J80=12,2,IF(J79=6,1,IF(J80=6,1,0))) -> 0 | M79: =IF(K79+K80=12,2,IF(K79=6,1,IF(K80=6,1,0))) -> 0
C82: 9.00 pm | G82: vs | L82: =IF(J82+J83=12,2,IF(J82=6,1,IF(J83=6,1,0))) -> 0 | M82: =IF(K82+K83=12,2,IF(K82=6,1,IF(K83=6,1,0))) -> 0
C86: Total Day 1 A | J86: =SUM(J76:J83) -> 0 | K86: =SUM(K76:K83) -> 0 | L86: =SUM(L76:L83) -> 0 | M86: =SUM(M76:M83) -> 0
C88: 6.30 pm | G88: vs | L88: =IF(J88+J89=12,2,IF(J88=6,1,IF(J89=6,1,0))) -> 0 | M88: =IF(K88+K89=12,2,IF(K88=6,1,IF(K89=6,1,0))) -> 0
C91: 7.45 pm | G91: vs | L91: =IF(J91+J92=12,2,IF(J91=6,1,IF(J92=6,1,0))) -> 0 | M91: =IF(K91+K92=12,2,IF(K91=6,1,IF(K92=6,1,0))) -> 0
C94: 9.00 pm | G94: vs | L94: =IF(J94+J95=12,2,IF(J94=6,1,IF(J95=6,1,0))) -> 0 | M94: =IF(K94+K95=12,2,IF(K94=6,1,IF(K95=6,1,0))) -> 0
C97: 9.00 pm | G97: vs | L97: =IF(J97+J98=12,2,IF(J97=6,1,IF(J98=6,1,0))) -> 0 | M97: =IF(K97+K98=12,2,IF(K97=6,1,IF(K98=6,1,0))) -> 0
C100: Total Day 1B | J100: =SUM(J88:J98) -> 0 | K100: =SUM(K88:K98) -> 0 | L100: =SUM(L88:L98) -> 0 | M100: =SUM(M88:M98) -> 0
C102: Total Day 1 | J102: =J100+J86 -> 0 | K102: =K100+K86 -> 0 | L102: =L100+L86 -> 0 | M102: =M100+M86 -> 0

Sheet Day 2
C2: VITTORIOSA LAWN TENNIS CLUB
C3: “The Joe Carabott Memorial Team Tournament - Sponsored by Antes.”
C6: Day 2
C9: Court 1
C11: Time | D11: Rubber | E11: Team B: | H11: Team D: | J11: Games | L11: Sets
C13: 6.30 pm | G13: vs | L13: =IF(J13+J14=12,2,IF(J13=6,1,IF(J14=6,1,0))) -> 0 | M13: =IF(K13+K14=12,2,IF(K13=6,1,IF(K14=6,1,0))) -> 0
C16: 7.45 pm | G16: vs | L16: =IF(J16+J17=12,2,IF(J16=6,1,IF(J17=6,1,0))) -> 0 | M16: =IF(K16+K17=12,2,IF(K16=6,1,IF(K17=6,1,0))) -> 0
C19: 9.00 pm | G19: vs | L19: =IF(J19+J20=12,2,IF(J19=6,1,IF(J20=6,1,0))) -> 0 | M19: =IF(K19+K20=12,2,IF(K19=6,1,IF(K20=6,1,0))) -> 0
C22: 6.30 pm | G22: vs | L22: =IF(J22+J23=12,2,IF(J22=6,1,IF(J23=6,1,0))) -> 0 | M22: =IF(K22+K23=12,2,IF(K22=6,1,IF(K23=6,1,0))) -> 0
C25: Total Day 2 A | J25: =SUM(J13:J23) -> 0 | K25: =SUM(K13:K23) -> 0 | L25: =SUM(L13:L23) -> 0 | M25: =SUM(M13:M23) -> 0
C28: 6.30 pm | G28: vs | L28: =IF(J28+J29=12,2,IF(J28=6,1,IF(J29=6,1,0))) -> 0 | M28: =IF(K28+K29=12,2,IF(K28=6,1,IF(K29=6,1,0))) -> 0
C31: 7.45 pm | G31: vs | L31: =IF(J31+J32=12,2,IF(J31=6,1,IF(J32=6,1,0))) -> 0 | M31: =IF(K31+K32=12,2,IF(K31=6,1,IF(K32=6,1,0))) -> 0
C34: 9.00 pm | G34: vs | L34: =IF(J34+J35=12,2,IF(J34=6,1,IF(J35=6,1,0))) -> 0 | M34: =IF(K34+K35=12,2,IF(K34=6,1,IF(K35=6,1,0))) -> 0
C37: 6.30 pm | G37: vs | L37: =IF(J37+J38=12,2,IF(J37=6,1,IF(J38=6,1,0))) -> 0 | M37: =IF(K37+K38=12,2,IF(K37=6,1,IF(K38=6,1,0))) -> 0
C40: Total Day 2 B | J40: =SUM(J28:J38) -> 0 | K40: =SUM(K28:K38) -> 0 | L40: =SUM(L28:L38) -> 0 | M40: =SUM(M28:M38) -> 0
C42: Total Day 2 | J42: =J40+J25 -> 0 | K42: =K40+K25 -> 0 | L42: =L40+L25 -> 0 | M42: =M40+M25 -> 0
C44: Court 2
C46: Time | D46: Rubber | E46: Team A: | G46: vs | H46: Team F: | J46: Games | L46: Sets
C48: 6.30 pm | G48: vs | L48: =IF(J48+J49=12,2,IF(J48=6,1,IF(J49=6,1,0))) -> 0 | M48: =IF(K48+K49=12,2,IF(K48=6,1,IF(K49=6,1,0))) -> 0
C51: 7.45 pm | G51: vs | L51: =IF(J51+J52=12,2,IF(J51=6,1,IF(J52=6,1,0))) -> 0 | M51: =IF(K51+K52=12,2,IF(K51=6,1,IF(K52=6,1,0))) -> 0
C54: 9.00 pm | L54: =IF(J54+J55=12,2,IF(J54=6,1,IF(J55=6,1,0))) -> 0 | M54: =IF(K54+K55=12,2,IF(K54=6,1,IF(K55=6,1,0))) -> 0
C57: 7.45pm | G57: vs | L57: =IF(J57+J58=12,2,IF(J57=6,1,IF(J58=6,1,0))) -> 0 | M57: =IF(K57+K58=12,2,IF(K57=6,1,IF(K58=6,1,0))) -> 0
J60: =SUM(J48:J58) -> 0 | K60: =SUM(K48:K58) -> 0 | L60: =SUM(L48:L58) -> 0 | M60: =SUM(M48:M58) -> 0
C63: 6.30 pm | G63: vs | L63: =IF(J63+J64=12,2,IF(J63=6,1,IF(J64=6,1,0))) -> 0 | M63: =IF(K63+K64=12,2,IF(K63=6,1,IF(K64=6,1,0))) -> 0
C66: 7.45 pm | G66: vs | L66: =IF(J66+J67=12,2,IF(J66=6,1,IF(J67=6,1,0))) -> 0 | M66: =IF(K66+K67=12,2,IF(K66=6,1,IF(K67=6,1,0))) -> 0
C69: 9.00 pm | G69: vs | L69: =IF(J69+J70=12,2,IF(J69=6,1,IF(J70=6,1,0))) -> 0 | M69: =IF(K69+K70=12,2,IF(K69=6,1,IF(K70=6,1,0))) -> 0
C72: 7.45 pm | G72: vs | L72: =IF(J72+J73=12,2,IF(J72=6,1,IF(J73=6,1,0))) -> 0 | M72: =IF(K72+K73=12,2,IF(K72=6,1,IF(K73=6,1,0))) -> 0
C75: Total Day 2 B | J75: =SUM(J63:J73) -> 0 | K75: =SUM(K63:K73) -> 0 | L75: =SUM(L63:L73) -> 0 | M75: =SUM(M63:M73) -> 0
C77: Total Day 2 | J77: =J75+J60 -> 0 | K77: =K75+K60 -> 0 | L77: =L75+L60 -> 0 | M77: =M75+M60 -> 0
C79: Court 4
C81: Time | D81: Rubber | E81: Team C: | H81: Team E: | J81: Games | L81: Sets
C83: 6.30 pm | G83: vs | L83: =IF(J83+J84=12,2,IF(J83=6,1,IF(J84=6,1,0))) -> 0 | M83: =IF(K83+K84=12,2,IF(K83=6,1,IF(K84=6,1,0))) -> 0
C86: 7.45 pm | G86: vs | L86: =IF(J86+J87=12,2,IF(J86=6,1,IF(J87=6,1,0))) -> 0 | M86: =IF(K86+K87=12,2,IF(K86=6,1,IF(K87=6,1,0))) -> 0
C89: 9.00 pm | G89: vs | L89: =IF(J89+J90=12,2,IF(J89=6,1,IF(J90=6,1,0))) -> 0 | M89: =IF(K89+K90=12,2,IF(K89=6,1,IF(K90=6,1,0))) -> 0
C92: 9.00 pm | G92: vs | L92: =IF(J92+J93=12,2,IF(J92=6,1,IF(J93=6,1,0))) -> 0 | M92: =IF(K92+K93=12,2,IF(K92=6,1,IF(K93=6,1,0))) -> 0
C95: Total Day 2 A | J95: =SUM(J83:J93) -> 0 | K95: =SUM(K83:K93) -> 0 | L95: =SUM(L83:L93) -> 0 | M95: =SUM(M83:M93) -> 0
C98: 6.30 pm | G98: vs | L98: =IF(J98+J99=12,2,IF(J98=6,1,IF(J99=6,1,0))) -> 0 | M98: =IF(K98+K99=12,2,IF(K98=6,1,IF(K99=6,1,0))) -> 0
C101: 7.45 pm | G101: vs | L101: =IF(J101+J102=12,2,IF(J101=6,1,IF(J102=6,1,0))) -> 0 | M101: =IF(K101+K102=12,2,IF(K101=6,1,IF(K102=6,1,0))) -> 0
C104: 9.00 pm | G104: vs | L104: =IF(J104+J105=12,2,IF(J104=6,1,IF(J105=6,1,0))) -> 0 | M104: =IF(K104+K105=12,2,IF(K104=6,1,IF(K105=6,1,0))) -> 0
C107: 9.00 pm | G107: vs | L107: =IF(J107+J108=12,2,IF(J107=6,1,IF(J108=6,1,0))) -> 0 | M107: =IF(K107+K108=12,2,IF(K107=6,1,IF(K108=6,1,0))) -> 0
...

Sheet Day 3
C2: VITTORIOSA LAWN TENNIS CLUB
A3: “The Joe Carabott Memorial Team Tournament - Sponsored by Antes.”
C6: Day 3
C9: Court 1
C11: Time | D11: Rubber | E11: Team E: | G11: vs | H11: Team F: | J11: Games | L11: Sets
C13: 6.30 pm | G13: vs | L13: =IF(J13+J14=12,2,IF(J13=6,1,IF(J14=6,1,0))) -> 0 | M13: =IF(K13+K14=12,2,IF(K13=6,1,IF(K14=6,1,0))) -> 0
C16: 7.45 pm | G16: vs | L16: =IF(J16+J17=12,2,IF(J16=6,1,IF(J17=6,1,0))) -> 0 | M16: =IF(K16+K17=12,2,IF(K16=6,1,IF(K17=6,1,0))) -> 0
C19: 9.00 pm | G19: vs | L19: =IF(J19+J20=12,2,IF(J19=6,1,IF(J20=6,1,0))) -> 0 | M19: =IF(K19+K20=12,2,IF(K19=6,1,IF(K20=6,1,0))) -> 0
C22: 6.30 pm | G22: vs | L22: =IF(J22+J23=12,2,IF(J22=6,1,IF(J23=6,1,0))) -> 0 | M22: =IF(K22+K23=12,2,IF(K22=6,1,IF(K23=6,1,0))) -> 0
C25: Total Day 3 A | J25: =SUM(J13:J23) -> 0 | K25: =SUM(K13:K23) -> 0 | L25: =SUM(L13:L23) -> 0 | M25: =SUM(M13:M23) -> 0
C28: 6.30 pm | G28: vs | L28: =IF(J28+J29=12,2,IF(J28=6,1,IF(J29=6,1,0))) -> 0 | M28: =IF(K28+K29=12,2,IF(K28=6,1,IF(K29=6,1,0))) -> 0
C31: 7.45 pm | G31: vs | L31: =IF(J31+J32=12,2,IF(J31=6,1,IF(J32=6,1,0))) -> 0 | M31: =IF(K31+K32=12,2,IF(K31=6,1,IF(K32=6,1,0))) -> 0
C34: 9.00 pm | G34: vs | L34: =IF(J34+J35=12,2,IF(J34=6,1,IF(J35=6,1,0))) -> 0 | M34: =IF(K34+K35=12,2,IF(K34=6,1,IF(K35=6,1,0))) -> 0
C37: 6.30pm | G37: vs | L37: =IF(J37+J38=12,2,IF(J37=6,1,IF(J38=6,1,0))) -> 0 | M37: =IF(K37+K38=12,2,IF(K37=6,1,IF(K38=6,1,0))) -> 0
C40: Total Day 3 B | J40: =SUM(J28:J38) -> 0 | K40: =SUM(K28:K38) -> 0 | L40: =SUM(L28:L38) -> 0 | M40: =SUM(M28:M38) -> 0
C42: Total Day 3 | J42: =J40+J25 -> 0 | K42: =K40+K25 -> 0 | L42: =L40+L25 -> 0 | M42: =M40+M25 -> 0
C44: Court 2
C46: Time | D46: Rubber | E46: Team B: | G46: vs | H46: Team C: | J46: Games | L46: Sets
C48: 6.30 pm | G48: vs | L48: =IF(J48+J49=12,2,IF(J48=6,1,IF(J49=6,1,0))) -> 0 | M48: =IF(K48+K49=12,2,IF(K48=6,1,IF(K49=6,1,0))) -> 0
C51: 7.45 pm | G51: vs | L51: =IF(J51+J52=12,2,IF(J51=6,1,IF(J52=6,1,0))) -> 0 | M51: =IF(K51+K52=12,2,IF(K51=6,1,IF(K52=6,1,0))) -> 0
C54: 9.00 pm | G54: vs | L54: =IF(J54+J55=12,2,IF(J54=6,1,IF(J55=6,1,0))) -> 0 | M54: =IF(K54+K55=12,2,IF(K54=6,1,IF(K55=6,1,0))) -> 0
C57: 9.00 pm | G57: vs | L57: =IF(J57+J58=12,2,IF(J57=6,1,IF(J58=6,1,0))) -> 0 | M57: =IF(K57+K58=12,2,IF(K57=6,1,IF(K58=6,1,0))) -> 0
C60: Total Day 3 A | J60: =SUM(J48:J58) -> 0 | K60: =SUM(K48:K58) -> 0 | L60: =SUM(L48:L58) -> 0 | M60: =SUM(M48:M58) -> 0
C63: 6.30 pm | G63: vs | L63: =IF(J63+J64=12,2,IF(J63=6,1,IF(J64=6,1,0))) -> 0 | M63: 0
C66: 7.45 pm | G66: vs | L66: =IF(J66+J67=12,2,IF(J66=6,1,IF(J67=6,1,0))) -> 0 | M66: 0
C69: 9.00 pm | G69: vs | L69: =IF(J69+J70=12,2,IF(J69=6,1,IF(J70=6,1,0))) -> 0 | M69: =IF(K69+K70=12,2,IF(K69=6,1,IF(K70=6,1,0))) -> 0
C72: 7.45pm | G72: vs | L72: =IF(J72+J73=12,2,IF(J72=6,1,IF(J73=6,1,0))) -> 0 | M72: =IF(K72+K73=12,2,IF(K72=6,1,IF(K73=6,1,0))) -> 0
C75: Total Day 3 B | J75: =SUM(J63:J73) -> 0 | K75: =SUM(K63:K73) -> 0 | L75: =SUM(L63:L73) -> 0 | M75: =SUM(M63:M73) -> 0
C77: Total Day 3 | J77: =J75+J60 -> 0 | K77: =K75+K60 -> 0 | L77: =L75+L60 -> 0 | M77: =M75+M60 -> 0
C79: Court 4
C81: Time | D81: Rubber | E81: Team A: | G81: vs | H81: Team D: | J81: Games | L81: Sets
C83: 6.30 pm | G83: vs | L83: =IF(J83+J84=12,2,IF(J83=6,1,IF(J84=6,1,0))) -> 0 | M83: =IF(K83+K84=12,2,IF(K83=6,1,IF(K84=6,1,0))) -> 0
C86: 7.45 pm | G86: vs | L86: =IF(J86+J87=12,2,IF(J86=6,1,IF(J87=6,1,0))) -> 0 | M86: =IF(K86+K87=12,2,IF(K86=6,1,IF(K87=6,1,0))) -> 0
C89: 9.00 pm | G89: vs | L89: =IF(J89+J90=12,2,IF(J89=6,1,IF(J90=6,1,0))) -> 0 | M89: =IF(K89+K90=12,2,IF(K89=6,1,IF(K90=6,1,0))) -> 0
C92: 7.45 pm | G92: vs | L92: =IF(J92+J93=12,2,IF(J92=6,1,IF(J93=6,1,0))) -> 0 | M92: =IF(K92+K93=12,2,IF(K92=6,1,IF(K93=6,1,0))) -> 0
C95: Total Day 3 A | J95: =SUM(J83:J93) -> 0 | K95: =SUM(K83:K93) -> 0 | L95: =SUM(L83:L93) -> 0 | M95: =SUM(M83:M93) -> 0
C98: 6.30 pm | G98: vs | L98: =IF(J98+J99=12,2,IF(J98=6,1,IF(J99=6,1,0))) -> 0 | M98: =IF(K98+K99=12,2,IF(K98=6,1,IF(K99=6,1,0))) -> 0
C101: 7.45 pm | G101: vs | L101: =IF(J101+J102=12,2,IF(J101=6,1,IF(J102=6,1,0))) -> 0 | M101: =IF(K101+K102=12,2,IF(K101=6,1,IF(K102=6,1,0))) -> 0
C104: 9.00 pm | G104: vs | L104: =IF(J104+J105=12,2,IF(J104=6,1,IF(J105=6,1,0))) -> 0 | M104: =IF(K104+K105=12,2,IF(K104=6,1,IF(K105=6,1,0))) -> 0
C107: 9.00pm | G107: vs | L107: =IF(J107+J108=12,2,IF(J107=6,1,IF(J108=6,1,0))) -> 0 | M107: =IF(K107+K108=12,2,IF(K107=6,1,IF(K108=6,1,0))) -> 0
...

Sheet Day 4
C2: VITTORIOSA LAWN TENNIS CLUB
A3: “The Joe Carabott Memorial Team Tournament - Sponsored by Antes.”
C6: Day 4
C9: Court 1
C11: Time | D11: Rubber | E11: Team C: | G11: vs | H11: Team D: | J11: Games | L11: Sets
C12: Court 1
C13: 6.30 pm | G13: vs | L13: =IF(J13+J14=12,2,IF(J13=6,1,IF(J14=6,1,0))) -> 0 | M13: 0
C16: 7.45 pm | G16: vs | L16: =IF(J16+J17=12,2,IF(J16=6,1,IF(J17=6,1,0))) -> 0 | M16: =IF(K16+K17=12,2,IF(K16=6,1,IF(K17=6,1,0))) -> 0
C19: 9.00 pm | G19: vs | L19: =IF(J19+J20=12,2,IF(J19=6,1,IF(J20=6,1,0))) -> 0 | M19: =IF(K19+K20=12,2,IF(K19=6,1,IF(K20=6,1,0))) -> 0
C22: 6.30 pm | G22: vs | L22: =IF(J22+J23=12,2,IF(J22=6,1,IF(J23=6,1,0))) -> 0 | M22: =IF(K22+K23=12,2,IF(K22=6,1,IF(K23=6,1,0))) -> 0
C25: Total Day 4 A | J25: =SUM(J13:J23) -> 0 | K25: =SUM(K13:K23) -> 0 | L25: =SUM(L13:L23) -> 0 | M25: =SUM(M13:M23) -> 0
C28: 6.30 pm | G28: vs | L28: =IF(J28+J29=12,2,IF(J28=6,1,IF(J29=6,1,0))) -> 0 | M28: =IF(K28+K29=12,2,IF(K28=6,1,IF(K29=6,1,0))) -> 0
C31: 7.45 pm | G31: vs | L31: =IF(J31+J32=12,2,IF(J31=6,1,IF(J32=6,1,0))) -> 0 | M31: =IF(K31+K32=12,2,IF(K31=6,1,IF(K32=6,1,0))) -> 0
C34: 9.00 pm | G34: vs | L34: =IF(J34+J35=12,2,IF(J34=6,1,IF(J35=6,1,0))) -> 0 | M34: =IF(K34+K35=12,2,IF(K34=6,1,IF(K35=6,1,0))) -> 0
C37: 7.45 pm | G37: vs | L37: =IF(J37+J38=12,2,IF(J37=6,1,IF(J38=6,1,0))) -> 0 | M37: =IF(K37+K38=12,2,IF(K37=6,1,IF(K38=6,1,0))) -> 0
C40: Total Day 4 B | J40: =SUM(J28:J38) -> 0 | K40: =SUM(K28:K38) -> 0 | L40: =SUM(L28:L38) -> 0 | M40: =SUM(M28:M38) -> 0
C42: Total Day 4 | J42: =J40+J25 -> 0 | K42: =K40+K25 -> 0 | L42: =L40+L25 -> 0 | M42: =M40+M25 -> 0
C44: Court 2
C46: Time | D46: Rubber | E46: Team A: | G46: vs | H46: Team E: | J46: Games | L46: Sets
C48: 6.30 pm | G48: vs | L48: =IF(J48+J49=12,2,IF(J48=6,1,IF(J49=6,1,0))) -> 0 | M48: =IF(K48+K49=12,2,IF(K48=6,1,IF(K49=6,1,0))) -> 0
C51: 7.45 pm | G51: vs | L51: =IF(J51+J52=12,2,IF(J51=6,1,IF(J52=6,1,0))) -> 0 | M51: =IF(K51+K52=12,2,IF(K51=6,1,IF(K52=6,1,0))) -> 0
C54: 9.00 pm | G54: vs | L54: =IF(J54+J55=12,2,IF(J54=6,1,IF(J55=6,1,0))) -> 0 | M54: =IF(K54+K55=12,2,IF(K54=6,1,IF(K55=6,1,0))) -> 0
C57: 7.45 pm | G57: vs | L57: =IF(J57+J58=12,2,IF(J57=6,1,IF(J58=6,1,0))) -> 0 | M57: =IF(K57+K58=12,2,IF(K57=6,1,IF(K58=6,1,0))) -> 0
C60: Total Day 4 A | J60: =SUM(J48:J58) -> 0 | K60: =SUM(K48:K58) -> 0 | L60: =SUM(L48:L58) -> 0 | M60: =SUM(M48:M58) -> 0
C63: 6.30 pm | G63: vs | L63: =IF(J63+J64=12,2,IF(J63=6,1,IF(J64=6,1,0))) -> 0 | M63: =IF(K63+K64=12,2,IF(K63=6,1,IF(K64=6,1,0))) -> 0
C66: 7.45 pm | G66: vs | L66: =IF(J66+J67=12,2,IF(J66=6,1,IF(J67=6,1,0))) -> 0 | M66: =IF(K66+K67=12,2,IF(K66=6,1,IF(K67=6,1,0))) -> 0
C69: 7.45 pm | G69: vs | L69: =IF(J69+J70=12,2,IF(J69=6,1,IF(J70=6,1,0))) -> 0 | M69: =IF(K69+K70=12,2,IF(K69=6,1,IF(K70=6,1,0))) -> 0
G72: vs | L72: =IF(J72+J73=12,2,IF(J72=6,1,IF(J73=6,1,0))) -> 0 | M72: =IF(K72+K73=12,2,IF(K72=6,1,IF(K73=6,1,0))) -> 0
C75: Total Day 4 B | J75: =SUM(J63:J73) -> 0 | K75: =SUM(K63:K73) -> 0 | L75: =SUM(L63:L73) -> 0 | M75: =SUM(M63:M73) -> 0
C77: Total Day 4 | J77: =J75+J60 -> 0 | K77: =K75+K60 -> 0 | L77: =L75+L60 -> 0 | M77: =M75+M60 -> 0
C79: Court 4
C81: Time | D81: Rubber | E81: Team B: | G81: vs | H81: Team F: | J81: Games | L81: Sets
C83: 6.30 pm | G83: vs | L83: =IF(J83+J84=12,2,IF(J83=6,1,IF(J84=6,1,0))) -> 0 | M83: =IF(K83+K84=12,2,IF(K83=6,1,IF(K84=6,1,0))) -> 0
C86: 7.45 pm | G86: vs | L86: =IF(J86+J87=12,2,IF(J86=6,1,IF(J87=6,1,0))) -> 0 | M86: =IF(K86+K87=12,2,IF(K86=6,1,IF(K87=6,1,0))) -> 0
C89: 9.00 pm | G89: vs | L89: =IF(J89+J90=12,2,IF(J89=6,1,IF(J90=6,1,0))) -> 0 | M89: =IF(K89+K90=12,2,IF(K89=6,1,IF(K90=6,1,0))) -> 0
C92: 6.30 pm | G92: vs | L92: =IF(J92+J93=12,2,IF(J92=6,1,IF(J93=6,1,0))) -> 0 | M92: =IF(K92+K93=12,2,IF(K92=6,1,IF(K93=6,1,0))) -> 0
C95: Total Day 4 A | J95: =SUM(J83:J93) -> 0 | K95: =SUM(K83:K93) -> 0 | L95: =SUM(L83:L93) -> 0 | M95: =SUM(M83:M93) -> 0
C98: 6.30 pm | G98: vs | L98: =IF(J98+J99=12,2,IF(J98=6,1,IF(J99=6,1,0))) -> 0 | M98: =IF(K98+K99=12,2,IF(K98=6,1,IF(K99=6,1,0))) -> 0
C101: 7.45 pm | G101: vs | L101: =IF(J101+J102=12,2,IF(J101=6,1,IF(J102=6,1,0))) -> 0 | M101: =IF(K101+K102=12,2,IF(K101=6,1,IF(K102=6,1,0))) -> 0
C104: 9.00 pm | G104: vs | L104: =IF(J104+J105=12,2,IF(J104=6,1,IF(J105=6,1,0))) -> 0 | M104: =IF(K104+K105=12,2,IF(K104=6,1,IF(K105=6,1,0))) -> 0
...

Sheet Day 5
B2: VITTORIOSA LAWN TENNIS CLUB
B3: “The Joe Carabott Memorial Team Tournament - Sponsored by Antes.”
C6: Day 5
C9: Court 1
C11: Time | D11: Rubber | E11: Team C: | G11: vs | H11: Team F: | J11: Games | L11: Sets
C13: 6.30 pm | G13: vs | L13: =IF(J13+J14=12,2,IF(J13=6,1,IF(J14=6,1,0))) -> 0 | M13: =IF(K13+K14=12,2,IF(K13=6,1,IF(K14=6,1,0))) -> 0
C16: 7.45 pm | G16: vs | L16: =IF(J16+J17=12,2,IF(J16=6,1,IF(J17=6,1,0))) -> 0 | M16: =IF(K16+K17=12,2,IF(K16=6,1,IF(K17=6,1,0))) -> 0
C19: 9.00 pm | G19: vs | L19: =IF(J19+J20=12,2,IF(J19=6,1,IF(J20=6,1,0))) -> 0 | M19: =IF(K19+K20=12,2,IF(K19=6,1,IF(K20=6,1,0))) -> 0
C22: 6.30 pm | G22: vs | L22: =IF(J22+J23=12,2,IF(J22=6,1,IF(J23=6,1,0))) -> 0 | M22: =IF(K22+K23=12,2,IF(K22=6,1,IF(K23=6,1,0))) -> 0
C25: Total Day 5 A | J25: =SUM(J13:J23) -> 0 | K25: =SUM(K13:K23) -> 0 | L25: =SUM(L13:L23) -> 0 | M25: =SUM(M13:M23) -> 0
C28: 6.30 pm | G28: vs | L28: =IF(J28+J29=12,2,IF(J28=6,1,IF(J29=6,1,0))) -> 0 | M28: =IF(K28+K29=12,2,IF(K28=6,1,IF(K29=6,1,0))) -> 0
C31: 7.45 pm | G31: vs | L31: =IF(J31+J32=12,2,IF(J31=6,1,IF(J32=6,1,0))) -> 0 | M31: =IF(K31+K32=12,2,IF(K31=6,1,IF(K32=6,1,0))) -> 0
C34: 9.00 pm | G34: vs | L34: =IF(J34+J35=12,2,IF(J34=6,1,IF(J35=6,1,0))) -> 0 | M34: =IF(K34+K35=12,2,IF(K34=6,1,IF(K35=6,1,0))) -> 0
C37: 6.30pm | G37: vs | L37: =IF(J37+J38=12,2,IF(J37=6,1,IF(J38=6,1,0))) -> 0 | M37: 0
C40: Total Day 5B | J40: =SUM(J28:J38) -> 0 | K40: =SUM(K28:K38) -> 0 | L40: =SUM(L28:L38) -> 0 | M40: =SUM(M28:M38) -> 0
C42: Total Day 5 | J42: =J40+J25 -> 0 | K42: =K40+K25 -> 0 | L42: =L40+L25 -> 0 | M42: =M40+M25 -> 0
C44: Court 2
C46: Time | D46: Rubber | E46: Team D: | G46: vs | H46: Team E: | J46: Games | L46: Sets
C48: 6.30 pm | G48: vs | L48: =IF(J48+J49=12,2,IF(J48=6,1,IF(J49=6,1,0))) -> 0 | M48: =IF(K48+K49=12,2,IF(K48=6,1,IF(K49=6,1,0))) -> 0
C51: 7.45 pm | G51: vs | L51: =IF(J51+J52=12,2,IF(J51=6,1,IF(J52=6,1,0))) -> 0 | M51: =IF(K51+K52=12,2,IF(K51=6,1,IF(K52=6,1,0))) -> 0
C54: 9.00 pm | G54: vs | L54: =IF(J54+J55=12,2,IF(J54=6,1,IF(J55=6,1,0))) -> 0 | M54: =IF(K54+K55=12,2,IF(K54=6,1,IF(K55=6,1,0))) -> 0
C57: 7.45 pm | G57: vs | L57: =IF(J57+J58=12,2,IF(J57=6,1,IF(J58=6,1,0))) -> 0 | M57: =IF(K57+K58=12,2,IF(K57=6,1,IF(K58=6,1,0))) -> 0
C60: Total Day 5 A | J60: =SUM(J48:J58) -> 0 | K60: =SUM(K48:K58) -> 0 | L60: =SUM(L48:L58) -> 0 | M60: =SUM(M48:M58) -> 0
C63: 6.30 pm | G63: vs | L63: =IF(J63+J64=12,2,IF(J63=6,1,IF(J64=6,1,0))) -> 0 | M63: =IF(K63+K64=12,2,IF(K63=6,1,IF(K64=6,1,0))) -> 0
C66: 7.45 pm | G66: vs | L66: =IF(J66+J67=12,2,IF(J66=6,1,IF(J67=6,1,0))) -> 0 | M66: =IF(K66+K67=12,2,IF(K66=6,1,IF(K67=6,1,0))) -> 0
C69: 9.00 pm | G69: vs | L69: =IF(J69+J70=12,2,IF(J69=6,1,IF(J70=6,1,0))) -> 0 | M69: =IF(K69+K70=12,2,IF(K69=6,1,IF(K70=6,1,0))) -> 0
C72: 7.45pm | G72: vs | L72: =IF(J72+J73=12,2,IF(J72=6,1,IF(J73=6,1,0))) -> 0 | M72: =IF(K72+K73=12,2,IF(K72=6,1,IF(K73=6,1,0))) -> 0
C75: Total Day 5B | J75: =SUM(J63:J73) -> 0 | K75: =SUM(K63:K73) -> 0 | L75: =SUM(L63:L73) -> 0 | M75: =SUM(M63:M73) -> 0
C77: Total Day 5 | J77: =J75+J60 -> 0 | K77: =K75+K60 -> 0 | L77: =L75+L60 -> 0 | M77: =M75+M60 -> 0
C79: Court 4
C81: Time | D81: Rubber | E81: Team A: | G81: vs | H81: Team B: | J81: Games | L81: Sets
C83: 6.30 pm | G83: vs | L83: =IF(J83+J84=12,2,IF(J83=6,1,IF(J84=6,1,0))) -> 0 | M83: =IF(K83+K84=12,2,IF(K83=6,1,IF(K84=6,1,0))) -> 0
C86: 7.45 pm | G86: vs | L86: =IF(J86+J87=12,2,IF(J86=6,1,IF(J87=6,1,0))) -> 0 | M86: =IF(K86+K87=12,2,IF(K86=6,1,IF(K87=6,1,0))) -> 0
C89: 9.00 pm | G89: vs | L89: =IF(J89+J90=12,2,IF(J89=6,1,IF(J90=6,1,0))) -> 0 | M89: =IF(K89+K90=12,2,IF(K89=6,1,IF(K90=6,1,0))) -> 0
C92: 9.00 pm | G92: vs | L92: =IF(J92+J93=12,2,IF(J92=6,1,IF(J93=6,1,0))) -> 0 | M92: =IF(K92+K93=12,2,IF(K92=6,1,IF(K93=6,1,0))) -> 0
C95: Total Day 5 A | J95: =SUM(J83:J93) -> 0 | K95: =SUM(K83:K93) -> 0 | L95: =SUM(L83:L93) -> 0 | M95: =SUM(M83:M93) -> 0
C98: 6.30 pm | G98: vs | L98: =IF(J98+J99=12,2,IF(J98=6,1,IF(J99=6,1,0))) -> 0 | M98: =IF(K98+K99=12,2,IF(K98=6,1,IF(K99=6,1,0))) -> 0
C104: 9.00 pm | G104: vs | L104: =IF(J104+J105=12,2,IF(J104=6,1,IF(J105=6,1,0))) -> 0 | M104: =IF(K104+K105=12,2,IF(K104=6,1,IF(K105=6,1,0))) -> 0
C107: 9.00 pm | G107: vs | L107: =IF(J107+J108=12,2,IF(J107=6,1,IF(J108=6,1,0))) -> 0 | M107: =IF(K107+K108=12,2,IF(K107=6,1,IF(K108=6,1,0))) -> 0
C110: Total Day 5 B | J110: =SUM(J98:J108) -> 0 | K110: =SUM(K98:K108) -> 0 | L110: =SUM(L98:L108) -> 0 | M110: =SUM(M98:M108) -> 0
...

Sheet Semi Final
B2: VITTORIOSA LAWN TENNIS CLUB
B3: “The Joe Carabott Memorial Team Tournament - Sponsored by Antes.”
C6: Semi Final
C9: Court 1
C11: Time | D11: Rubber | E11: Team : | G11: vs | H11: Team : | J11: Games | L11: Sets
C13: 6.30 pm | G13: vs
C16: 7.45 pm | G16: vs
C19: 9.00 pm | G19: vs
C22: 6.30 pm | G22: vs
C25: Total Day 2 A | J25: =SUM(J13:J23) -> 0 | K25: =SUM(K13:K23) -> 0 | L25: =SUM(L13:L23) -> 0 | M25: =SUM(M13:M23) -> 0
C28: 6.30 pm | G28: vs
C31: 7.45 pm | G31: vs
C34: 9.00 pm | G34: vs
C37: 7.45 pm
C40: Total Day 2B | J40: =SUM(J28:J38) -> 0 | K40: =SUM(K28:K38) -> 0 | L40: =SUM(L28:L38) -> 0 | M40: =SUM(M28:M38) -> 0
C42: Total Day 2 | J42: =J40+J25 -> 0 | K42: =K40+K25 -> 0 | L42: =L40+L25 -> 0 | M42: =M40+M25 -> 0
C44: Court 2
C46: Time | D46: Rubber | E46: Team : | G46: vs | H46: Team : | J46: Games | L46: Sets
C48: 6.30 pm | G48: vs
C51: 7.45 pm | G51: vs
C54: 9.00 pm | G54: vs
C57: 7.45 pm | G57: vs
C60: Total Day 2 A | J60: =SUM(J48:J58) -> 0 | K60: =SUM(K48:K58) -> 0 | L60: =SUM(L48:L58) -> 0 | M60: =SUM(M48:M58) -> 0
C63: 6.30 pm | G63: vs
C66: 7.45 pm | G66: vs
C69: 9.00 pm | G69: vs
C72: 7.45 pm | G72: vs
C75: Total Day 2B | J75: =SUM(J63:J73) -> 0 | K75: =SUM(K63:K73) -> 0 | L75: =SUM(L63:L73) -> 0 | M75: =SUM(M63:M73) -> 0
C77: Total Day 2 | J77: =J75+J60 -> 0 | K77: =K75+K60 -> 0 | L77: =L75+L60 -> 0 | M77: =M75+M60 -> 0

Sheet Final
B2: VITTORIOSA LAWN TENNIS CLUB
B3: “The Joe Carabott Memorial Team Tournament - Sponsored by Antes.”
C6: FINAL
C11: Time | D11: Rubber | E11: Team : | G11: vs | H11: Team : | J11: Games | L11: Sets
C13: 6.30 pm | G13: vs
C16: 6.30 pm | G16: vs
C19: 6.30 pm | G19: vs
C22: 7.45 pm | G22: vs
C25: 7.45 pm | G25: vs
C31: 9.00 pm | G31: vs
C34: 9.00pm | G34: vs
G37: vs
C40: Total Final
