Workbook

Sheet Players Men
A1: VITTORIOSA LAWN TENNIS CLUB
A2: Sports Experience Chosen Doubles 2023
B5: Men Division 1
A6: 1 | B6: Clayton Zammit Cesare | C6: Matthew Pace
A7: 2 | B7: Marc Vella Bonnici | C7: Marcelo Villanueva
A8: 3 | B8: Eric Roca | C8: Duncan D’Alessandro
A9: 4 | B9: Trevor Rutter | C9: Jean Carl Azzopardi
A10: 5 | B10: Claude Mifsud Wismayer | C10: Adrian Chetcuti
B12: Men Division 2
A13: 1 | B13: Ignazio Andreozzi | C13: Cristian Andreozzi
A14: 2 | B14: Gabriel Pace | C14: Jonathan Vella
A15: 3 | B15: Gio Marcos | C15: Chi Chi Canonce
A16: 4 | B16: Fotis Evangelou | C16: Eric Micallef
A17: 5 | B17: Jesmond Pule’ | C17: Manuel Bonello
A18: 6 | B18: Ivan Cachia | C18: Willem Steenkamer
B20: Men Division 3
A21: 1 | B21: Clint Agius | C21: Kevin Formosa
A22: 2 | B22: Aaron Micallef Piccione | C22: Adrian Sciberras
A23: 3 | B23: James Farrugia | C23: Jean Paul Vella
A24: 4 | B24: Denis Caruana | C24: Kristen Cachia
A25: 5 | B25: Manuel Mifsud | C25: Julian Esposito
A26: 6 | B26: Stephen Belli | C26: Matthew Schembri
B28: Men Division 4
A29: 1 | B29: Charles Micallef | C29: Twanny Pule
A30: 2 | B30: Simone Re | C30: David Camilleri
A31: 3 | B31: Ryan Ebejer | C31: Etienne Formosa Carabez
A32: 4 | B32: Jayboy Lastimosa | C32: Cyril Lastimosa
A33: 5 | B33: Isaac Joseph Zammit | C33: Conrad Treeby Ward
A34: 6 | B34: Ivan Saliba | C34: Clayton Saliba Hersey
B36: Men Division 5
A37: 1 | B37: Kenneth Farrugia | C37: Juan Sammut
A38: 2 | B38: Donald Deguzman | C38: Teddy Padullon
A39: 3 | B39: Mark Cini | C39: Dunstan Vella
A40: 4 | B40: Sean Cachia | C40: Antoine Bugeja
A41: 5 | B41: Robert Attard | C41: Kevin Wood
A42: 6 | B42: Matthew Micallef | C42: Chris Vella

Sheet Men Div 1
A1: VITTORIOSA LAWN TENNIS CLUB
A2: Sports Experience Chosen Doubles 2023
B5: Men Division 1
B7: Players | C7: Set Scores | I7: Tie | Q7: Players | R7: Set Scores | X7: Tie | AE7: Player | AF7: Games | AG7: Points | AH7: Games Won | AI7: Sets Won
C8: Score | D8: Set 1 Work | F8: Score | G8: Set 2 Work | I8: Score | J8: Tie Work | K8: Sets Points Work | L8: Sets & Tie Points Work | M8: Games Wins Work | N8: Sets Wins Work | R8: Score | S8: Set 1 Work | U8: Score | V8: Set 2 Work | X8: Score | Y8: Tie Work | Z8: Sets Points Work | AA8: Sets & Tie Points Work | AB8: Games Wins Work | AC8: Sets Wins Work | AJ8: To See Winners | AK8: Total Games Work | AL8: Player 1 Work
B9: =AE9 -> Clayton Zammit Cesare / Matthew Pace | C9: 5 | D9: =IF(C9>C11,1,0) -> 0 | F9: 4 | G9: =IF(F9>F11,1,0) -> 0 | J9: =IF(I9>I11,1,0) -> 0 | K9: =IF(D9+G9=2,3,IF(D9+G9=1,1,0)) -> 0 | L9: =IF(K9=3,3,IF(J9+K9=2,2,IF(K9=1,1,0))) -> 0 | M9: =C9+F9 -> 9 | N9: =D9+G9+J9 -> 0 | Q9: =AE9 -> Clayton Zammit Cesare / Matthew Pace | R9: 6 | S9: =IF(R9>R11,1,0) -> 1 | U9: 6 | V9: =IF(U9>U11,1,0) -> 1 | Y9: =IF(X9>X11,1,0) -> 0 | Z9: =IF(S9+V9=2,3,IF(S9+V9=1,1,0)) -> 3 | AA9: =IF(Z9=3,3,IF(Y9+Z9=2,2,IF(Z9=1,1,0))) -> 3 | AB9: =R9+U9 -> 12 | AC9: =S9+V9+Y9 -> 2 | AE9: ='Players Men'!B6& " / " &'Players Men'!C6 -> Clayton Zammit Cesare / Matthew Pace | AF9: =C12+R12+C17+R17 -> 4 | AG9: =L9+AA9+L14+AA14 -> 6 | AH9: =M9+AB9+M14+AB14 -> 41 | AI9: =N9+AC9+N14+AC14 -> 4 | AJ9: =MAX(AG16,AG14,AG11,AG9,AG19) -> 10 | AK9: =SUM(AF9:AF19) -> 20 | AL9: =IF(AG9=$AJ$9,AE9,IF(AG11=$AJ$9,AE11,IF(AG14=$AJ$9,AE14,IF(AG16=$AJ$9,AE16,IF(AG19=$AJ$9,AE19,""))))) -> Marc Vella Bonnici / Marcelo Villanueva
B10: vs. | Q10: vs.
B11: =AE11 -> Marc Vella Bonnici / Marcelo Villanueva | C11: 7 | D11: =IF(C11>C9,1,0) -> 1 | F11: 6 | G11: =IF(F11>F9,1,0) -> 1 | J11: =IF(I11>I9,1,0) -> 0 | K11: =IF(D11+G11=2,3,IF(D11+G11=1,1,0)) -> 3 | L11: =IF(K11=3,3,IF(J11+K11=2,2,IF(K11=1,1,0))) -> 3 | M11: =C11+F11 -> 13 | N11: =D11+G11+J11 -> 2 | Q11: =AE14 -> Eric Roca / Duncan D’Alessandro | R11: 1 | S11: =IF(R11>R9,1,0) -> 0 | U11: 2 | V11: =IF(U11>U9,1,0) -> 0 | Y11: =IF(X11>X9,1,0) -> 0 | Z11: =IF(S11+V11=2,3,IF(S11+V11=1,1,0)) -> 0 | AA11: =IF(Z11=3,3,IF(Y11+Z11=2,2,IF(Z11=1,1,0))) -> 0 | AB11: =R11+U11 -> 3 | AC11: =S11+V11+Y11 -> 0 | AE11: ='Players Men'!B7& " / " &'Players Men'!C7 -> Marc Vella Bonnici / Marcelo Villanueva | AF11: =F12+C27+R22+C22 -> 4 | AG11: =L11+L24+AA19+L19 -> 10 | AH11: =M11+M24+AB19+M19 -> 47 | AI11: =N11+N24+AC19+N19 -> 7
A12: Work | C12: =IF(C9="",0,1) -> 1 | F12: =IF(C11="",0,1) -> 1 | P12: Work | R12: =IF(R9="",0,1) -> 1 | U12: =IF(R11="",0,1) -> 1
B14: =AE9 -> Clayton Zammit Cesare / Matthew Pace | C14: 6 | D14: =IF(C14>C16,1,0) -> 1 | F14: 6 | G14: =IF(F14>F16,1,0) -> 1 | J14: =IF(I14>I16,1,0) -> 0 | K14: =IF(D14+G14=2,3,IF(D14+G14=1,1,0)) -> 3 | L14: =IF(K14=3,3,IF(J14+K14=2,2,IF(K14=1,1,0))) -> 3 | M14: =C14+F14 -> 12 | N14: =D14+G14+J14 -> 2 | Q14: =AE9 -> Clayton Zammit Cesare / Matthew Pace | R14: 4 | S14: =IF(R14>R16,1,0) -> 0 | U14: 4 | V14: =IF(U14>U16,1,0) -> 0 | Y14: =IF(X14>X16,1,0) -> 0 | Z14: =IF(S14+V14=2,3,IF(S14+V14=1,1,0)) -> 0 | AA14: =IF(Z14=3,3,IF(Y14+Z14=2,2,IF(Z14=1,1,0))) -> 0 | AB14: =R14+U14 -> 8 | AC14: =S14+V14+Y14 -> 0 | AE14: ='Players Men'!B8& " / " &'Players Men'!C8 -> Eric Roca / Duncan D’Alessandro | AF14: =R27+U12+C32+F22 -> 4 | AG14: =AA24+AA11+L29+L21 -> 3 | AH14: =AB24+AB11+M29+M21 -> 30 | AI14: =AC24+AC11+N29+N21 -> 3
B15: vs. | Q15: vs.
B16: =AE16 -> Trevor Rutter / Jean Carl Azzopardi | C16: 0 | D16: =IF(C16>C14,1,0) -> 0 | F16: 3 | G16: =IF(F16>F14,1,0) -> 0 | J16: =IF(I16>I14,1,0) -> 0 | K16: =IF(D16+G16=2,3,IF(D16+G16=1,1,0)) -> 0 | L16: =IF(K16=3,3,IF(J16+K16=2,2,IF(K16=1,1,0))) -> 0 | M16: =C16+F16 -> 3 | N16: =D16+G16+J16 -> 0 | Q16: =AE19 -> Claude Mifsud Wismayer / Adrian Chetcuti | R16: 6 | S16: =IF(R16>R14,1,0) -> 1 | U16: 6 | V16: =IF(U16>U14,1,0) -> 1 | Y16: =IF(X16>X14,1,0) -> 0 | Z16: =IF(S16+V16=2,3,IF(S16+V16=1,1,0)) -> 3 | AA16: =IF(Z16=3,3,IF(Y16+Z16=2,2,IF(Z16=1,1,0))) -> 3 | AB16: =R16+U16 -> 12 | AC16: =S16+V16+Y16 -> 2 | AE16: ='Players Men'!B9& " / " &'Players Men'!C9 -> Trevor Rutter / Jean Carl Azzopardi | AF16: =U27+R32+F17+U22 -> 4 | AG16: =AA26+AA29+L16+AA21 -> 2 | AH16: =AB26+AB29+M16+AB21 -> 25 | AI16: =AC26+AC29+N16+AC21 -> 2
A17: Work | C17: =IF(C14="",0,1) -> 1 | F17: =IF(C16="",0,1) -> 1 | P17: Work | R17: =IF(R14="",0,1) -> 1 | U17: =IF(R16="",0,1) -> 1
B19: =AE11 -> Marc Vella Bonnici / Marcelo Villanueva | C19: 6 | D19: =IF(C19>C21,1,0) -> 1 | F19: 3 | G19: =IF(F19>F21,1,0) -> 0 | I19: 3 | J19: =IF(I19>I21,1,0) -> 0 | K19: =IF(D19+G19=2,3,IF(D19+G19=1,1,0)) -> 1 | L19: =IF(K19=3,3,IF(J19+K19=2,2,IF(K19=1,1,0))) -> 1 | M19: =C19+F19 -> 9 | N19: =D19+G19+J19 -> 1 | Q19: =AE11 -> Marc Vella Bonnici / Marcelo Villanueva | R19: 6 | S19: =IF(R19>R21,1,0) -> 1 | U19: 6 | V19: =IF(U19>U21,1,0) -> 1 | Y19: =IF(X19>X21,1,0) -> 0 | Z19: =IF(S19+V19=2,3,IF(S19+V19=1,1,0)) -> 3 | AA19: =IF(Z19=3,3,IF(Y19+Z19=2,2,IF(Z19=1,1,0))) -> 3 | AB19: =R19+U19 -> 12 | AC19: =S19+V19+Y19 -> 2 | AE19: ='Players Men'!B10& " / " &'Players Men'!C10 -> Claude Mifsud Wismayer / Adrian Chetcuti | AF19: =U32+F27+U17+F32 -> 4 | AG19: =AA31+L26+AA16+L31 -> 9 | AH19: =AB31+M26+AB16+M31 -> 44 | AI19: =AC31+N26+AC16+N31 -> 6
B20: vs. | Q20: vs.
B21: =AE14 -> Eric Roca / Duncan D’Alessandro | C21: 2 | D21: =IF(C21>C19,1,0) -> 0 | F21: 6 | G21: =IF(F21>F19,1,0) -> 1 | I21: 10 | J21: =IF(I21>I19,1,0) -> 1 | K21: =IF(D21+G21=2,3,IF(D21+G21=1,1,0)) -> 1 | L21: =IF(K21=3,3,IF(J21+K21=2,2,IF(K21=1,1,0))) -> 2 | M21: =C21+F21 -> 8 | N21: =D21+G21+J21 -> 2 | Q21: =AE16 -> Trevor Rutter / Jean Carl Azzopardi | R21: 3 | S21: =IF(R21>R19,1,0) -> 0 | U21: 4 | V21: =IF(U21>U19,1,0) -> 0 | Y21: =IF(X21>X19,1,0) -> 0 | Z21: =IF(S21+V21=2,3,IF(S21+V21=1,1,0)) -> 0 | AA21: =IF(Z21=3,3,IF(Y21+Z21=2,2,IF(Z21=1,1,0))) -> 0 | AB21: =R21+U21 -> 7 | AC21: =S21+V21+Y21 -> 0
A22: Work | C22: =IF(C19="",0,1) -> 1 | F22: =IF(C21="",0,1) -> 1 | P22: Work | R22: =IF(R19="",0,1) -> 1 | U22: =IF(R21="",0,1) -> 1
B24: =AE11 -> Marc Vella Bonnici / Marcelo Villanueva | C24: 7 | D24: =IF(C24>C26,1,0) -> 1 | F24: 6 | G24: =IF(F24>F26,1,0) -> 1 | J24: =IF(I24>I26,1,0) -> 0 | K24: =IF(D24+G24=2,3,IF(D24+G24=1,1,0)) -> 3 | L24: =IF(K24=3,3,IF(J24+K24=2,2,IF(K24=1,1,0))) -> 3 | M24: =C24+F24 -> 13 | N24: =D24+G24+J24 -> 2 | Q24: =AE14 -> Eric Roca / Duncan D’Alessandro | R24: 1 | S24: =IF(R24>R26,1,0) -> 0 | U24: 6 | V24: =IF(U24>U26,1,0) -> 1 | X24: 7 | Y24: =IF(X24>X26,1,0) -> 0 | Z24: =IF(S24+V24=2,3,IF(S24+V24=1,1,0)) -> 1 | AA24: =IF(Z24=3,3,IF(Y24+Z24=2,2,IF(Z24=1,1,0))) -> 1 | AB24: =R24+U24 -> 7 | AC24: =S24+V24+Y24 -> 1 | AE24: Divison Winner
B25: vs. | Q25: vs. | AE25: Marc Vella Bonnici/Marcelo Villanueva
B26: =AE19 -> Claude Mifsud Wismayer / Adrian Chetcuti | C26: 5 | D26: =IF(C26>C24,1,0) -> 0 | F26: 1 | G26: =IF(F26>F24,1,0) -> 0 | J26: =IF(I26>I24,1,0) -> 0 | K26: =IF(D26+G26=2,3,IF(D26+G26=1,1,0)) -> 0 | L26: =IF(K26=3,3,IF(J26+K26=2,2,IF(K26=1,1,0))) -> 0 | M26: =C26+F26 -> 6 | N26: =D26+G26+J26 -> 0 | Q26: =AE16 -> Trevor Rutter / Jean Carl Azzopardi | R26: 6 | S26: =IF(R26>R24,1,0) -> 1 | U26: 4 | V26: =IF(U26>U24,1,0) -> 0 | X26: 10 | Y26: =IF(X26>X24,1,0) -> 1 | Z26: =IF(S26+V26=2,3,IF(S26+V26=1,1,0)) -> 1 | AA26: =IF(Z26=3,3,IF(Y26+Z26=2,2,IF(Z26=1,1,0))) -> 2 | AB26: =R26+U26 -> 10 | AC26: =S26+V26+Y26 -> 2 | AE26: Divison Runner Up
A27: Work | C27: =IF(C24="",0,1) -> 1 | F27: =IF(C26="",0,1) -> 1 | P27: Work | R27: =IF(R24="",0,1) -> 1 | U27: =IF(R26="",0,1) -> 1
AE28: Claude Mifsud Bonnici/Adrian Chetcuti
B29: =AE14 -> Eric Roca / Duncan D’Alessandro | C29: 6 | D29: =IF(C29>C31,1,0) -> 0 | F29: 6 | G29: =IF(F29>F31,1,0) -> 0 | J29: =IF(I29>I31,1,0) -> 0 | K29: =IF(D29+G29=2,3,IF(D29+G29=1,1,0)) -> 0 | L29: =IF(K29=3,3,IF(J29+K29=2,2,IF(K29=1,1,0))) -> 0 | M29: =C29+F29 -> 12 | N29: =D29+G29+J29 -> 0 | Q29: =AE16 -> Trevor Rutter / Jean Carl Azzopardi | R29: 1 | S29: =IF(R29>R31,1,0) -> 0 | U29: 4 | V29: =IF(U29>U31,1,0) -> 0 | Y29: =IF(X29>X31,1,0) -> 0 | Z29: =IF(S29+V29=2,3,IF(S29+V29=1,1,0)) -> 0 | AA29: =IF(Z29=3,3,IF(Y29+Z29=2,2,IF(Z29=1,1,0))) -> 0 | AB29: =R29+U29 -> 5 | AC29: =S29+V29+Y29 -> 0
B30: vs. | Q30: vs.
B31: =AE19 -> Claude Mifsud Wismayer / Adrian Chetcuti | C31: 7 | D31: =IF(C31>C29,1,0) -> 1 | F31: 7 | G31: =IF(F31>F29,1,0) -> 1 | J31: =IF(I31>I29,1,0) -> 0 | K31: =IF(D31+G31=2,3,IF(D31+G31=1,1,0)) -> 3 | L31: =IF(K31=3,3,IF(J31+K31=2,2,IF(K31=1,1,0))) -> 3 | M31: =C31+F31 -> 14 | N31: =D31+G31+J31 -> 2 | Q31: =AE19 -> Claude Mifsud Wismayer / Adrian Chetcuti | R31: 6 | S31: =IF(R31>R29,1,0) -> 1 | U31: 6 | V31: =IF(U31>U29,1,0) -> 1 | Y31: =IF(X31>X29,1,0) -> 0 | Z31: =IF(S31+V31=2,3,IF(S31+V31=1,1,0)) -> 3 | AA31: =IF(Z31=3,3,IF(Y31+Z31=2,2,IF(Z31=1,1,0))) -> 3 | AB31: =R31+U31 -> 12 | AC31: =S31+V31+Y31 -> 2
A32: Work | C32: =IF(C29="",0,1) -> 1 | F32: =IF(C31="",0,1) -> 1 | P32: Work | R32: =IF(R29="",0,1) -> 1 | U32: =IF(R31="",0,1) -> 1

Sheet Men Div 2
A1: VITTORIOSA LAWN TENNIS CLUB
A2: Sports Experience Chosen Doubles 2023
B5: Men Division 2
B7: Players | C7: Set Scores | I7: Tie | Q7: Players | R7: Set Scores | X7: Tie | AE7: Player | AF7: Games | AG7: Points | AH7: Games Won | AI7: Sets Won
C8: Score | D8: Set 1 Work | F8: Score | G8: Set 2 Work | I8: Score | J8: Tie Work | K8: Sets Points Work | L8: Sets & Tie Points Work | M8: Games Wins Work | N8: Sets Wins Work | R8: Score | S8: Set 1 Work | U8: Score | V8: Set 2 Work | X8: Score | Y8: Tie Work | Z8: Sets Points Work | AA8: Sets & Tie Points Work | AB8: Games Wins Work | AC8: Sets Wins Work | AJ8: To See Winners | AK8: Total Games Work | AL8: Player 1 Work
B9: =AE9 -> Ignazio Andreozzi / Cristian Andreozzi | C9: 6 | D9: =IF(C9>C11,1,0) -> 1 | F9: 6 | G9: =IF(F9>F11,1,0) -> 1 | J9: =IF(I9>I11,1,0) -> 0 | K9: =IF(D9+G9=2,3,IF(D9+G9=1,1,0)) -> 3 | L9: =IF(K9=3,3,IF(J9+K9=2,2,IF(K9=1,1,0))) -> 3 | M9: =C9+F9 -> 12 | N9: =D9+G9+J9 -> 2 | Q9: =AE9 -> Ignazio Andreozzi / Cristian Andreozzi | R9: 4 | S9: =IF(R9>R11,1,0) -> 0 | U9: 5 | V9: =IF(U9>U11,1,0) -> 0 | Y9: =IF(X9>X11,1,0) -> 0 | Z9: =IF(S9+V9=2,3,IF(S9+V9=1,1,0)) -> 0 | AA9: =IF(Z9=3,3,IF(Y9+Z9=2,2,IF(Z9=1,1,0))) -> 0 | AB9: =R9+U9 -> 9 | AC9: =S9+V9+Y9 -> 0 | AE9: ='Players Men'!B13& " / " &'Players Men'!C13 -> Ignazio Andreozzi / Cristian Andreozzi | AF9: =C12+R12+C17+R17+C22 -> 5 | AG9: =L9+AA9+L14+AA14+L19 -> 7 | AH9: =M9+AB9+M14+AB14+M19 -> 49 | AI9: =N9+AC9+N14+AC14+N19 -> 5 | AJ9: =MAX(AG16,AG14,AG11,AG9,AG19,AG21) -> 15 | AK9: =SUM(AF9:AF21) -> 30 | AL9: =IF(AG9=$AJ$9,AE9,IF(AG11=$AJ$9,AE11,IF(AG14=$AJ$9,AE14,IF(AG16=$AJ$9,AE16,IF(AG19=$AJ$9,AE19,IF(AG21=$AJ$9,AE21,"")))))) -> Jesmond Pule’ / Manuel Bonello
B10: vs. | Q10: vs.
B11: =AE11 -> Gabriel Pace / Jonathan Vella | C11: 1 | D11: =IF(C11>C9,1,0) -> 0 | F11: 1 | G11: =IF(F11>F9,1,0) -> 0 | J11: =IF(I11>I9,1,0) -> 0 | K11: =IF(D11+G11=2,3,IF(D11+G11=1,1,0)) -> 0 | L11: =IF(K11=3,3,IF(J11+K11=2,2,IF(K11=1,1,0))) -> 0 | M11: =C11+F11 -> 2 | N11: =D11+G11+J11 -> 0 | Q11: =AE14 -> Gio Marcos / Chi Chi Canonce | R11: 6 | S11: =IF(R11>R9,1,0) -> 1 | U11: 7 | V11: =IF(U11>U9,1,0) -> 1 | Y11: =IF(X11>X9,1,0) -> 0 | Z11: =IF(S11+V11=2,3,IF(S11+V11=1,1,0)) -> 3 | AA11: =IF(Z11=3,3,IF(Y11+Z11=2,2,IF(Z11=1,1,0))) -> 3 | AB11: =R11+U11 -> 13 | AC11: =S11+V11+Y11 -> 2 | AE11: ='Players Men'!B14& " / " &'Players Men'!C14 -> Gabriel Pace / Jonathan Vella | AF11: =F12+R32+C27+R27+R22 -> 5 | AG11: =L11+AA29+L24+AA24+AA19 -> 1 | AH11: =M11+AB29+M24+AB24+AB19 -> 27 | AI11: =N11+AC29+N24+AC24+AC19 -> 1
A12: Work | C12: =IF(C9="",0,1) -> 1 | F12: =IF(C11="",0,1) -> 1 | P12: Work | R12: =IF(R9="",0,1) -> 1 | U12: =IF(R11="",0,1) -> 1
B14: =AE9 -> Ignazio Andreozzi / Cristian Andreozzi | C14: 6 | D14: =IF(C14>C16,1,0) -> 1 | F14: 6 | G14: =IF(F14>F16,1,0) -> 1 | J14: =IF(I14>I16,1,0) -> 0 | K14: =IF(D14+G14=2,3,IF(D14+G14=1,1,0)) -> 3 | L14: =IF(K14=3,3,IF(J14+K14=2,2,IF(K14=1,1,0))) -> 3 | M14: =C14+F14 -> 12 | N14: =D14+G14+J14 -> 2 | Q14: =AE9 -> Ignazio Andreozzi / Cristian Andreozzi | R14: 2 | S14: =IF(R14>R16,1,0) -> 0 | U14: 3 | V14: =IF(U14>U16,1,0) -> 0 | Y14: =IF(X14>X16,1,0) -> 0 | Z14: =IF(S14+V14=2,3,IF(S14+V14=1,1,0)) -> 0 | AA14: =IF(Z14=3,3,IF(Y14+Z14=2,2,IF(Z14=1,1,0))) -> 0 | AB14: =R14+U14 -> 5 | AC14: =S14+V14+Y14 -> 0 | AE14: ='Players Men'!B15& " / " &'Players Men'!C15 -> Gio Marcos / Chi Chi Canonce | AF14: =R37+U12+R42+C32+U22 -> 5 | AG14: =AA34+AA11+AA39+L29+AA21 -> 10 | AH14: =AB34+AB11+AB39+M29+AB21 -> 48 | AI14: =AC34+AC11+AC39+N29+AC21 -> 8
B15: vs. | Q15: vs.
B16: =AE16 -> Fotis Evangelou / Eric Micallef | C16: 3 | D16: =IF(C16>C14,1,0) -> 0 | F16: 0 | G16: =IF(F16>F14,1,0) -> 0 | J16: =IF(I16>I14,1,0) -> 0 | K16: =IF(D16+G16=2,3,IF(D16+G16=1,1,0)) -> 0 | L16: =IF(K16=3,3,IF(J16+K16=2,2,IF(K16=1,1,0))) -> 0 | M16: =C16+F16 -> 3 | N16: =D16+G16+J16 -> 0 | Q16: =AE19 -> Jesmond Pule’ / Manuel Bonello | R16: 6 | S16: =IF(R16>R14,1,0) -> 1 | U16: 6 | V16: =IF(U16>U14,1,0) -> 1 | Y16: =IF(X16>X14,1,0) -> 0 | Z16: =IF(S16+V16=2,3,IF(S16+V16=1,1,0)) -> 3 | AA16: =IF(Z16=3,3,IF(Y16+Z16=2,2,IF(Z16=1,1,0))) -> 3 | AB16: =R16+U16 -> 12 | AC16: =S16+V16+Y16 -> 2 | AE16: ='Players Men'!B16& " / " &'Players Men'!C16 -> Fotis Evangelou / Eric Micallef | AF16: =U37+C47+F17+U27+C37 -> 5 | AG16: =AA36+L44+L16+AA26+L34 -> 4 | AH16: =AB36+M44+M16+AB26+M34 -> 37 | AI16: =AC36+N44+N16+AC26+N34 -> 3
A17: Work | C17: =IF(C14="",0,1) -> 1 | F17: =IF(C16="",0,1) -> 1 | P17: Work | R17: =IF(R14="",0,1) -> 1 | U17: =IF(R16="",0,1) -> 1
B19: =AE9 -> Ignazio Andreozzi / Cristian Andreozzi | C19: 5 | D19: =IF(C19>C21,1,0) -> 0 | F19: 6 | G19: =IF(F19>F21,1,0) -> 1 | I19: 6 | J19: =IF(I19>I21,1,0) -> 0 | K19: =IF(D19+G19=2,3,IF(D19+G19=1,1,0)) -> 1 | L19: =IF(K19=3,3,IF(J19+K19=2,2,IF(K19=1,1,0))) -> 1 | M19: =C19+F19 -> 11 | N19: =D19+G19+J19 -> 1 | Q19: =AE11 -> Gabriel Pace / Jonathan Vella | R19: 6 | S19: =IF(R19>R21,1,0) -> 1 | U19: 0 | V19: =IF(U19>U21,1,0) -> 0 | X19: 5 | Y19: =IF(X19>X21,1,0) -> 0 | Z19: =IF(S19+V19=2,3,IF(S19+V19=1,1,0)) -> 1 | AA19: =IF(Z19=3,3,IF(Y19+Z19=2,2,IF(Z19=1,1,0))) -> 1 | AB19: =R19+U19 -> 6 | AC19: =S19+V19+Y19 -> 1 | AE19: ='Players Men'!B17& " / " &'Players Men'!C17 -> Jesmond Pule’ / Manuel Bonello | AF19: =C42+F47+F27+U17+F32 -> 5 | AG19: =L39+L46+L26+AA16+L31 -> 15 | AH19: =M39+M46+M26+AB16+M31 -> 60 | AI19: =N39+N46+N26+AC16+N31 -> 10
B20: vs. | Q20: vs.
B21: =AE21 -> Ivan Cachia / Willem Steenkamer | C21: 7 | D21: =IF(C21>C19,1,0) -> 1 | F21: 2 | G21: =IF(F21>F19,1,0) -> 0 | I21: 10 | J21: =IF(I21>I19,1,0) -> 1 | K21: =IF(D21+G21=2,3,IF(D21+G21=1,1,0)) -> 1 | L21: =IF(K21=3,3,IF(J21+K21=2,2,IF(K21=1,1,0))) -> 2 | M21: =C21+F21 -> 9 | N21: =D21+G21+J21 -> 2 | Q21: =AE14 -> Gio Marcos / Chi Chi Canonce | R21: 4 | S21: =IF(R21>R19,1,0) -> 0 | U21: 6 | V21: =IF(U21>U19,1,0) -> 1 | X21: 10 | Y21: =IF(X21>X19,1,0) -> 1 | Z21: =IF(S21+V21=2,3,IF(S21+V21=1,1,0)) -> 1 | AA21: =IF(Z21=3,3,IF(Y21+Z21=2,2,IF(Z21=1,1,0))) -> 2 | AB21: =R21+U21 -> 10 | AC21: =S21+V21+Y21 -> 2 | AE21: ='Players Men'!B18& " / " &'Players Men'!C18 -> Ivan Cachia / Willem Steenkamer | AF21: =F42+U32+U42+F22+F37 -> 5 | AG21: =L41+AA31+AA41+L21+L36 -> 8 | AH21: =M41+AB31+AB41+M21+M36 -> 45 | AI21: =N41+AC31+AC41+N21+N36 -> 7
A22: Work | C22: =IF(C19="",0,1) -> 1 | F22: =IF(C21="",0,1) -> 1 | P22: Work | R22: =IF(R19="",0,1) -> 1 | U22: =IF(R21="",0,1) -> 1
B24: =AE11 -> Gabriel Pace / Jonathan Vella | C24: 0 | D24: =IF(C24>C26,1,0) -> 0 | F24: 1 | G24: =IF(F24>F26,1,0) -> 0 | J24: =IF(I24>I26,1,0) -> 0 | K24: =IF(D24+G24=2,3,IF(D24+G24=1,1,0)) -> 0 | L24: =IF(K24=3,3,IF(J24+K24=2,2,IF(K24=1,1,0))) -> 0 | M24: =C24+F24 -> 1 | N24: =D24+G24+J24 -> 0 | Q24: =AE11 -> Gabriel Pace / Jonathan Vella | R24: 6 | S24: =IF(R24>R26,1,0) -> 0 | U24: 1 | V24: =IF(U24>U26,1,0) -> 0 | Y24: =IF(X24>X26,1,0) -> 0 | Z24: =IF(S24+V24=2,3,IF(S24+V24=1,1,0)) -> 0 | AA24: =IF(Z24=3,3,IF(Y24+Z24=2,2,IF(Z24=1,1,0))) -> 0 | AB24: =R24+U24 -> 7 | AC24: =S24+V24+Y24 -> 0 | AE24: Divison Winner
B25: vs. | Q25: vs. | AE25: Jesmond Pule'/Manuel Bonello
B26: =AE19 -> Jesmond Pule’ / Manuel Bonello | C26: 6 | D26: =IF(C26>C24,1,0) -> 1 | F26: 6 | G26: =IF(F26>F24,1,0) -> 1 | J26: =IF(I26>I24,1,0) -> 0 | K26: =IF(D26+G26=2,3,IF(D26+G26=1,1,0)) -> 3 | L26: =IF(K26=3,3,IF(J26+K26=2,2,IF(K26=1,1,0))) -> 3 | M26: =C26+F26 -> 12 | N26: =D26+G26+J26 -> 2 | Q26: =AE16 -> Fotis Evangelou / Eric Micallef | R26: 7 | S26: =IF(R26>R24,1,0) -> 1 | U26: 6 | V26: =IF(U26>U24,1,0) -> 1 | Y26: =IF(X26>X24,1,0) -> 0 | Z26: =IF(S26+V26=2,3,IF(S26+V26=1,1,0)) -> 3 | AA26: =IF(Z26=3,3,IF(Y26+Z26=2,2,IF(Z26=1,1,0))) -> 3 | AB26: =R26+U26 -> 13 | AC26: =S26+V26+Y26 -> 2 | AE26: Divison Runner Up
A27: Work | C27: =IF(C24="",0,1) -> 1 | F27: =IF(C26="",0,1) -> 1 | P27: Work | R27: =IF(R24="",0,1) -> 1 | U27: =IF(R26="",0,1) -> 1
AE28: Gio Marcos/Chi Chi Canonce
B29: =AE14 -> Gio Marcos / Chi Chi Canonce | C29: 4 | D29: =IF(C29>C31,1,0) -> 0 | F29: 1 | G29: =IF(F29>F31,1,0) -> 0 | J29: =IF(I29>I31,1,0) -> 0 | K29: =IF(D29+G29=2,3,IF(D29+G29=1,1,0)) -> 0 | L29: =IF(K29=3,3,IF(J29+K29=2,2,IF(K29=1,1,0))) -> 0 | M29: =C29+F29 -> 5 | N29: =D29+G29+J29 -> 0 | Q29: =AE11 -> Gabriel Pace / Jonathan Vella | R29: 5 | S29: =IF(R29>R31,1,0) -> 0 | U29: 6 | V29: =IF(U29>U31,1,0) -> 0 | Y29: =IF(X29>X31,1,0) -> 0 | Z29: =IF(S29+V29=2,3,IF(S29+V29=1,1,0)) -> 0 | AA29: =IF(Z29=3,3,IF(Y29+Z29=2,2,IF(Z29=1,1,0))) -> 0 | AB29: =R29+U29 -> 11 | AC29: =S29+V29+Y29 -> 0
B30: vs. | Q30: vs.
B31: =AE19 -> Jesmond Pule’ / Manuel Bonello | C31: 6 | D31: =IF(C31>C29,1,0) -> 1 | F31: 6 | G31: =IF(F31>F29,1,0) -> 1 | J31: =IF(I31>I29,1,0) -> 0 | K31: =IF(D31+G31=2,3,IF(D31+G31=1,1,0)) -> 3 | L31: =IF(K31=3,3,IF(J31+K31=2,2,IF(K31=1,1,0))) -> 3 | M31: =C31+F31 -> 12 | N31: =D31+G31+J31 -> 2 | Q31: =AE21 -> Ivan Cachia / Willem Steenkamer | R31: 7 | S31: =IF(R31>R29,1,0) -> 1 | U31: 7 | V31: =IF(U31>U29,1,0) -> 1 | Y31: =IF(X31>X29,1,0) -> 0 | Z31: =IF(S31+V31=2,3,IF(S31+V31=1,1,0)) -> 3 | AA31: =IF(Z31=3,3,IF(Y31+Z31=2,2,IF(Z31=1,1,0))) -> 3 | AB31: =R31+U31 -> 14 | AC31: =S31+V31+Y31 -> 2
A32: Work | C32: =IF(C29="",0,1) -> 1 | F32: =IF(C31="",0,1) -> 1 | P32: Work | R32: =IF(R29="",0,1) -> 1 | U32: =IF(R31="",0,1) -> 1
B34: =AE16 -> Fotis Evangelou / Eric Micallef | C34: 4 | D34: =IF(C34>C36,1,0) -> 0 | F34: 6 | G34: =IF(F34>F36,1,0) -> 1 | I34: 3 | J34: =IF(I34>I36,1,0) -> 0 | K34: =IF(D34+G34=2,3,IF(D34+G34=1,1,0)) -> 1 | L34: =IF(K34=3,3,IF(J34+K34=2,2,IF(K34=1,1,0))) -> 1 | M34: =C34+F34 -> 10 | N34: =D34+G34+J34 -> 1 | Q34: =AE14 -> Gio Marcos / Chi Chi Canonce | R34: 6 | S34: =IF(R34>R36,1,0) -> 1 | U34: 6 | V34: =IF(U34>U36,1,0) -> 1 | Y34: =IF(X34>X36,1,0) -> 0 | Z34: =IF(S34+V34=2,3,IF(S34+V34=1,1,0)) -> 3 | AA34: =IF(Z34=3,3,IF(Y34+Z34=2,2,IF(Z34=1,1,0))) -> 3 | AB34: =R34+U34 -> 12 | AC34: =S34+V34+Y34 -> 2
B35: vs. | Q35: vs.
B36: =AE21 -> Ivan Cachia / Willem Steenkamer | C36: 6 | D36: =IF(C36>C34,1,0) -> 1 | F36: 3 | G36: =IF(F36>F34,1,0) -> 0 | I36: 10 | J36: =IF(I36>I34,1,0) -> 1 | K36: =IF(D36+G36=2,3,IF(D36+G36=1,1,0)) -> 1 | L36: =IF(K36=3,3,IF(J36+K36=2,2,IF(K36=1,1,0))) -> 2 | M36: =C36+F36 -> 9 | N36: =D36+G36+J36 -> 2 | Q36: =AE16 -> Fotis Evangelou / Eric Micallef | R36: 3 | S36: =IF(R36>R34,1,0) -> 0 | U36: 4 | V36: =IF(U36>U34,1,0) -> 0 | Y36: =IF(X36>X34,1,0) -> 0 | Z36: =IF(S36+V36=2,3,IF(S36+V36=1,1,0)) -> 0 | AA36: =IF(Z36=3,3,IF(Y36+Z36=2,2,IF(Z36=1,1,0))) -> 0 | AB36: =R36+U36 -> 7 | AC36: =S36+V36+Y36 -> 0
A37: Work | C37: =IF(C34="",0,1) -> 1 | F37: =IF(C36="",0,1) -> 1 | P37: Work | R37: =IF(R34="",0,1) -> 1 | U37: =IF(R36="",0,1) -> 1
B39: =AE19 -> Jesmond Pule’ / Manuel Bonello | C39: 6 | D39: =IF(C39>C41,1,0) -> 1 | F39: 6 | G39: =IF(F39>F41,1,0) -> 1 | J39: =IF(I39>I41,1,0) -> 0 | K39: =IF(D39+G39=2,3,IF(D39+G39=1,1,0)) -> 3 | L39: =IF(K39=3,3,IF(J39+K39=2,2,IF(K39=1,1,0))) -> 3 | M39: =C39+F39 -> 12 | N39: =D39+G39+J39 -> 2 | Q39: =AE14 -> Gio Marcos / Chi Chi Canonce | R39: 1 | S39: =IF(R39>R41,1,0) -> 0 | U39: 7 | V39: =IF(U39>U41,1,0) -> 1 | X39: 10 | Y39: =IF(X39>X41,1,0) -> 1 | Z39: =IF(S39+V39=2,3,IF(S39+V39=1,1,0)) -> 1 | AA39: =IF(Z39=3,3,IF(Y39+Z39=2,2,IF(Z39=1,1,0))) -> 2 | AB39: =R39+U39 -> 8 | AC39: =S39+V39+Y39 -> 2
B40: vs. | Q40: vs.
B41: =AE21 -> Ivan Cachia / Willem Steenkamer | C41: 1 | D41: =IF(C41>C39,1,0) -> 0 | F41: 1 | G41: =IF(F41>F39,1,0) -> 0 | J41: =IF(I41>I39,1,0) -> 0 | K41: =IF(D41+G41=2,3,IF(D41+G41=1,1,0)) -> 0 | L41: =IF(K41=3,3,IF(J41+K41=2,2,IF(K41=1,1,0))) -> 0 | M41: =C41+F41 -> 2 | N41: =D41+G41+J41 -> 0 | Q41: =AE21 -> Ivan Cachia / Willem Steenkamer | R41: 6 | S41: =IF(R41>R39,1,0) -> 1 | U41: 5 | V41: =IF(U41>U39,1,0) -> 0 | X41: 5 | Y41: =IF(X41>X39,1,0) -> 0 | Z41: =IF(S41+V41=2,3,IF(S41+V41=1,1,0)) -> 1 | AA41: =IF(Z41=3,3,IF(Y41+Z41=2,2,IF(Z41=1,1,0))) -> 1 | AB41: =R41+U41 -> 11 | AC41: =S41+V41+Y41 -> 1
A42: Work | C42: =IF(C39="",0,1) -> 1 | F42: =IF(C41="",0,1) -> 1 | P42: Work | R42: =IF(R39="",0,1) -> 1 | U42: =IF(R41="",0,1) -> 1
B44: =AE16 -> Fotis Evangelou / Eric Micallef | C44: 1 | D44: =IF(C44>C46,1,0) -> 0 | F44: 3 | G44: =IF(F44>F46,1,0) -> 0 | J44: =IF(I44>I46,1,0) -> 0 | K44: =IF(D44+G44=2,3,IF(D44+G44=1,1,0)) -> 0 | L44: =IF(K44=3,3,IF(J44+K44=2,2,IF(K44=1,1,0))) -> 0 | M44: =C44+F44 -> 4 | N44: =D44+G44+J44 -> 0
B45: vs.
B46: =AE19 -> Jesmond Pule’ / Manuel Bonello | C46: 6 | D46: =IF(C46>C44,1,0) -> 1 | F46: 6 | G46: =IF(F46>F44,1,0) -> 1 | J46: =IF(I46>I44,1,0) -> 0 | K46: =IF(D46+G46=2,3,IF(D46+G46=1,1,0)) -> 3 | L46: =IF(K46=3,3,IF(J46+K46=2,2,IF(K46=1,1,0))) -> 3 | M46: =C46+F46 -> 12 | N46: =D46+G46+J46 -> 2
A47: Work | C47: =IF(C44="",0,1) -> 1 | F47: =IF(C46="",0,1) -> 1

Sheet Men Div 3
A1: VITTORIOSA LAWN TENNIS CLUB
A2: Sports Experience Chosen Doubles 2023
B5: Men Division 3
B7: Players | C7: Set Scores | I7: Tie | Q7: Players | R7: Set Scores | X7: Tie | AE7: Player | AF7: Games | AG7: Points | AH7: Games Won | AI7: Sets Won
C8: Score | D8: Set 1 Work | F8: Score | G8: Set 2 Work | I8: Score | J8: Tie Work | K8: Sets Points Work | L8: Sets & Tie Points Work | M8: Games Wins Work | N8: Sets Wins Work | R8: Score | S8: Set 1 Work | U8: Score | V8: Set 2 Work | X8: Score | Y8: Tie Work | Z8: Sets Points Work | AA8: Sets & Tie Points Work | AB8: Games Wins Work | AC8: Sets Wins Work | AJ8: To See Winners | AK8: Total Games Work | AL8: Player 1 Work
B9: =AE9 -> Clint Agius / Kevin Formosa | C9: 6 | D9: =IF(C9>C11,1,0) -> 1 | F9: 6 | G9: =IF(F9>F11,1,0) -> 1 | J9: =IF(I9>I11,1,0) -> 0 | K9: =IF(D9+G9=2,3,IF(D9+G9=1,1,0)) -> 3 | L9: =IF(K9=3,3,IF(J9+K9=2,2,IF(K9=1,1,0))) -> 3 | M9: =C9+F9 -> 12 | N9: =D9+G9+J9 -> 2 | Q9: =AE9 -> Clint Agius / Kevin Formosa | R9: 4 | S9: =IF(R9>R11,1,0) -> 0 | U9: 3 | V9: =IF(U9>U11,1,0) -> 0 | Y9: =IF(X9>X11,1,0) -> 0 | Z9: =IF(S9+V9=2,3,IF(S9+V9=1,1,0)) -> 0 | AA9: =IF(Z9=3,3,IF(Y9+Z9=2,2,IF(Z9=1,1,0))) -> 0 | AB9: =R9+U9 -> 7 | AC9: =S9+V9+Y9 -> 0 | AE9: ='Players Men'!B21& " / " &'Players Men'!C21 -> Clint Agius / Kevin Formosa | AF9: =C12+R12+C17+R17+C22 -> 5 | AG9: =L9+AA9+L14+AA14+L19 -> 10 | AH9: =M9+AB9+M14+AB14+M19 -> 51 | AI9: =N9+AC9+N14+AC14+N19 -> 8 | AJ9: =MAX(AG16,AG14,AG11,AG9,AG19,AG21) -> 15 | AK9: =SUM(AF9:AF21) -> 30 | AL9: =IF(AG9=$AJ$9,AE9,IF(AG11=$AJ$9,AE11,IF(AG14=$AJ$9,AE14,IF(AG16=$AJ$9,AE16,IF(AG19=$AJ$9,AE19,IF(AG21=$AJ$9,AE21,"")))))) -> James Farrugia / Jean Paul Vella
B10: vs. | Q10: vs.
B11: =AE11 -> Aaron Micallef Piccione / Adrian Sciberras | C11: 4 | D11: =IF(C11>C9,1,0) -> 0 | F11: 3 | G11: =IF(F11>F9,1,0) -> 0 | J11: =IF(I11>I9,1,0) -> 0 | K11: =IF(D11+G11=2,3,IF(D11+G11=1,1,0)) -> 0 | L11: =IF(K11=3,3,IF(J11+K11=2,2,IF(K11=1,1,0))) -> 0 | M11: =C11+F11 -> 7 | N11: =D11+G11+J11 -> 0 | Q11: =AE14 -> James Farrugia / Jean Paul Vella | R11: 6 | S11: =IF(R11>R9,1,0) -> 1 | U11: 6 | V11: =IF(U11>U9,1,0) -> 1 | Y11: =IF(X11>X9,1,0) -> 0 | Z11: =IF(S11+V11=2,3,IF(S11+V11=1,1,0)) -> 3 | AA11: =IF(Z11=3,3,IF(Y11+Z11=2,2,IF(Z11=1,1,0))) -> 3 | AB11: =R11+U11 -> 12 | AC11: =S11+V11+Y11 -> 2 | AE11: ='Players Men'!B22& " / " &'Players Men'!C22 -> Aaron Micallef Piccione / Adrian Sciberras | AF11: =F12+R32+C32+R27+C27 -> 5 | AG11: =L11+AA29+L29+AA24+L24 -> 2 | AH11: =M11+AB29+M29+AB24+M24 -> 34 | AI11: =N11+AC29+N29+AC24+N24 -> 2
A12: Work | C12: =IF(C9="",0,1) -> 1 | F12: =IF(C11="",0,1) -> 1 | P12: Work | R12: =IF(R9="",0,1) -> 1 | U12: =IF(R11="",0,1) -> 1
B14: =AE9 -> Clint Agius / Kevin Formosa | C14: 6 | D14: =IF(C14>C16,1,0) -> 1 | F14: 5 | G14: =IF(F14>F16,1,0) -> 0 | I14: 10 | J14: =IF(I14>I16,1,0) -> 1 | K14: =IF(D14+G14=2,3,IF(D14+G14=1,1,0)) -> 1 | L14: =IF(K14=3,3,IF(J14+K14=2,2,IF(K14=1,1,0))) -> 2 | M14: =C14+F14 -> 11 | N14: =D14+G14+J14 -> 2 | Q14: =AE9 -> Clint Agius / Kevin Formosa | R14: 3 | S14: =IF(R14>R16,1,0) -> 0 | U14: 6 | V14: =IF(U14>U16,1,0) -> 1 | X14: 11 | Y14: =IF(X14>X16,1,0) -> 1 | Z14: =IF(S14+V14=2,3,IF(S14+V14=1,1,0)) -> 1 | AA14: =IF(Z14=3,3,IF(Y14+Z14=2,2,IF(Z14=1,1,0))) -> 2 | AB14: =R14+U14 -> 9 | AC14: =S14+V14+Y14 -> 2 | AE14: ='Players Men'!B23& " / " &'Players Men'!C23 -> James Farrugia / Jean Paul Vella | AF14: =R37+U12+R42+C42+F27 -> 5 | AG14: =AA34+AA11+AA39+L39+L26 -> 15 | AH14: =AB34+AB11+AB39+M39+M26 -> 60 | AI14: =AC34+AC11+AC39+N39+N26 -> 10
B15: vs. | Q15: vs.
B16: =AE16 -> Denis Caruana / Kristen Cachia | C16: 1 | D16: =IF(C16>C14,1,0) -> 0 | F16: 7 | G16: =IF(F16>F14,1,0) -> 1 | I16: 7 | J16: =IF(I16>I14,1,0) -> 0 | K16: =IF(D16+G16=2,3,IF(D16+G16=1,1,0)) -> 1 | L16: =IF(K16=3,3,IF(J16+K16=2,2,IF(K16=1,1,0))) -> 1 | M16: =C16+F16 -> 8 | N16: =D16+G16+J16 -> 1 | Q16: =AE19 -> Manuel Mifsud / Julian Esposito | R16: 6 | S16: =IF(R16>R14,1,0) -> 1 | U16: 3 | V16: =IF(U16>U14,1,0) -> 0 | X16: 9 | Y16: =IF(X16>X14,1,0) -> 0 | Z16: =IF(S16+V16=2,3,IF(S16+V16=1,1,0)) -> 1 | AA16: =IF(Z16=3,3,IF(Y16+Z16=2,2,IF(Z16=1,1,0))) -> 1 | AB16: =R16+U16 -> 9 | AC16: =S16+V16+Y16 -> 1 | AE16: ='Players Men'!B24& " / " &'Players Men'!C24 -> Denis Caruana / Kristen Cachia | AF16: =U37+C47+F17+U27+C37 -> 5 | AG16: =AA36+L44+L16+AA26+L34 -> 9 | AH16: =AB36+M44+M16+AB26+M34 -> 46 | AI16: =AC36+N44+N16+AC26+N34 -> 7
A17: Work | C17: =IF(C14="",0,1) -> 1 | F17: =IF(C16="",0,1) -> 1 | P17: Work | R17: =IF(R14="",0,1) -> 1 | U17: =IF(R16="",0,1) -> 1
B19: =AE9 -> Clint Agius / Kevin Formosa | C19: 6 | D19: =IF(C19>C21,1,0) -> 1 | F19: 6 | G19: =IF(F19>F21,1,0) -> 1 | J19: =IF(I19>I21,1,0) -> 0 | K19: =IF(D19+G19=2,3,IF(D19+G19=1,1,0)) -> 3 | L19: =IF(K19=3,3,IF(J19+K19=2,2,IF(K19=1,1,0))) -> 3 | M19: =C19+F19 -> 12 | N19: =D19+G19+J19 -> 2 | Q19: =AE19 -> Manuel Mifsud / Julian Esposito | R19: 7 | S19: =IF(R19>R21,1,0) -> 1 | U19: 6 | V19: =IF(U19>U21,1,0) -> 0 | X19: 13 | Y19: =IF(X19>X21,1,0) -> 0 | Z19: =IF(S19+V19=2,3,IF(S19+V19=1,1,0)) -> 1 | AA19: =IF(Z19=3,3,IF(Y19+Z19=2,2,IF(Z19=1,1,0))) -> 1 | AB19: =R19+U19 -> 13 | AC19: =S19+V19+Y19 -> 1 | AE19: ='Players Men'!B25& " / " &'Players Men'!C25 -> Manuel Mifsud / Julian Esposito | AF19: =R22+F47+F32+U17+F42 -> 5 | AG19: =AA19+L46+L31+AA16+L41 -> 5 | AH19: =AB19+M46+M31+AB16+M41 -> 44 | AI19: =AC19+N46+N31+AC16+N41 -> 5
B20: vs. | Q20: vs.
B21: =AE21 -> Stephen Belli / Matthew Schembri | C21: 1 | D21: =IF(C21>C19,1,0) -> 0 | F21: 1 | G21: =IF(F21>F19,1,0) -> 0 | J21: =IF(I21>I19,1,0) -> 0 | K21: =IF(D21+G21=2,3,IF(D21+G21=1,1,0)) -> 0 | L21: =IF(K21=3,3,IF(J21+K21=2,2,IF(K21=1,1,0))) -> 0 | M21: =C21+F21 -> 2 | N21: =D21+G21+J21 -> 0 | Q21: =AE21 -> Stephen Belli / Matthew Schembri | R21: 6 | S21: =IF(R21>R19,1,0) -> 0 | U21: 7 | V21: =IF(U21>U19,1,0) -> 1 | X21: 15 | Y21: =IF(X21>X19,1,0) -> 1 | Z21: =IF(S21+V21=2,3,IF(S21+V21=1,1,0)) -> 1 | AA21: =IF(Z21=3,3,IF(Y21+Z21=2,2,IF(Z21=1,1,0))) -> 2 | AB21: =R21+U21 -> 13 | AC21: =S21+V21+Y21 -> 2 | AE21: ='Players Men'!B26& " / " &'Players Men'!C26 -> Stephen Belli / Matthew Schembri | AF21: =U22+U32+U42+F22+F37 -> 5 | AG21: =AA21+AA31+AA41+L21+L36 -> 4 | AH21: =AB21+AB31+AB41+M21+M36 -> 40 | AI21: =AC21+AC31+AC41+N21+N36 -> 4
A22: Work | C22: =IF(C19="",0,1) -> 1 | F22: =IF(C21="",0,1) -> 1 | P22: Work | R22: =IF(R19="",0,1) -> 1 | U22: =IF(R21="",0,1) -> 1
B24: =AE11 -> Aaron Micallef Piccione / Adrian Sciberras | C24: 3 | D24: =IF(C24>C26,1,0) -> 0 | F24: 0 | G24: =IF(F24>F26,1,0) -> 0 | J24: =IF(I24>I26,1,0) -> 0 | K24: =IF(D24+G24=2,3,IF(D24+G24=1,1,0)) -> 0 | L24: =IF(K24=3,3,IF(J24+K24=2,2,IF(K24=1,1,0))) -> 0 | M24: =C24+F24 -> 3 | N24: =D24+G24+J24 -> 0 | Q24: =AE11 -> Aaron Micallef Piccione / Adrian Sciberras | R24: 1 | S24: =IF(R24>R26,1,0) -> 0 | U24: 3 | V24: =IF(U24>U26,1,0) -> 0 | Y24: =IF(X24>X26,1,0) -> 0 | Z24: =IF(S24+V24=2,3,IF(S24+V24=1,1,0)) -> 0 | AA24: =IF(Z24=3,3,IF(Y24+Z24=2,2,IF(Z24=1,1,0))) -> 0 | AB24: =R24+U24 -> 4 | AC24: =S24+V24+Y24 -> 0 | AE24: Divison Winner
B25: vs. | Q25: vs. | AE25: James Farrugia/Jean Paul Vella
B26: =AE14 -> James Farrugia / Jean Paul Vella | C26: 6 | D26: =IF(C26>C24,1,0) -> 1 | F26: 6 | G26: =IF(F26>F24,1,0) -> 1 | J26: =IF(I26>I24,1,0) -> 0 | K26: =IF(D26+G26=2,3,IF(D26+G26=1,1,0)) -> 3 | L26: =IF(K26=3,3,IF(J26+K26=2,2,IF(K26=1,1,0))) -> 3 | M26: =C26+F26 -> 12 | N26: =D26+G26+J26 -> 2 | Q26: =AE16 -> Denis Caruana / Kristen Cachia | R26: 6 | S26: =IF(R26>R24,1,0) -> 1 | U26: 6 | V26: =IF(U26>U24,1,0) -> 1 | Y26: =IF(X26>X24,1,0) -> 0 | Z26: =IF(S26+V26=2,3,IF(S26+V26=1,1,0)) -> 3 | AA26: =IF(Z26=3,3,IF(Y26+Z26=2,2,IF(Z26=1,1,0))) -> 3 | AB26: =R26+U26 -> 12 | AC26: =S26+V26+Y26 -> 2 | AE26: Divison Runner Up
A27: Work | C27: =IF(C24="",0,1) -> 1 | F27: =IF(C26="",0,1) -> 1 | P27: Work | R27: =IF(R24="",0,1) -> 1 | U27: =IF(R26="",0,1) -> 1
AE28: Clint Agius/Kevin Formosa
B29: =AE11 -> Aaron Micallef Piccione / Adrian Sciberras | C29: 6 | D29: =IF(C29>C31,1,0) -> 1 | F29: 3 | G29: =IF(F29>F31,1,0) -> 0 | I29: 6 | J29: =IF(I29>I31,1,0) -> 0 | K29: =IF(D29+G29=2,3,IF(D29+G29=1,1,0)) -> 1 | L29: =IF(K29=3,3,IF(J29+K29=2,2,IF(K29=1,1,0))) -> 1 | M29: =C29+F29 -> 9 | N29: =D29+G29+J29 -> 1 | Q29: =AE11 -> Aaron Micallef Piccione / Adrian Sciberras | R29: 7 | S29: =IF(R29>R31,1,0) -> 1 | U29: 4 | V29: =IF(U29>U31,1,0) -> 0 | X29: 7 | Y29: =IF(X29>X31,1,0) -> 0 | Z29: =IF(S29+V29=2,3,IF(S29+V29=1,1,0)) -> 1 | AA29: =IF(Z29=3,3,IF(Y29+Z29=2,2,IF(Z29=1,1,0))) -> 1 | AB29: =R29+U29 -> 11 | AC29: =S29+V29+Y29 -> 1
B30: vs. | Q30: vs.
B31: =AE19 -> Manuel Mifsud / Julian Esposito | C31: 3 | D31: =IF(C31>C29,1,0) -> 0 | F31: 6 | G31: =IF(F31>F29,1,0) -> 1 | I31: 10 | J31: =IF(I31>I29,1,0) -> 1 | K31: =IF(D31+G31=2,3,IF(D31+G31=1,1,0)) -> 1 | L31: =IF(K31=3,3,IF(J31+K31=2,2,IF(K31=1,1,0))) -> 2 | M31: =C31+F31 -> 9 | N31: =D31+G31+J31 -> 2 | Q31: =AE21 -> Stephen Belli / Matthew Schembri | R31: 5 | S31: =IF(R31>R29,1,0) -> 0 | U31: 6 | V31: =IF(U31>U29,1,0) -> 1 | X31: 10 | Y31: =IF(X31>X29,1,0) -> 1 | Z31: =IF(S31+V31=2,3,IF(S31+V31=1,1,0)) -> 1 | AA31: =IF(Z31=3,3,IF(Y31+Z31=2,2,IF(Z31=1,1,0))) -> 2 | AB31: =R31+U31 -> 11 | AC31: =S31+V31+Y31 -> 2
A32: Work | C32: =IF(C29="",0,1) -> 1 | F32: =IF(C31="",0,1) -> 1 | P32: Work | R32: =IF(R29="",0,1) -> 1 | U32: =IF(R31="",0,1) -> 1
B34: =AE16 -> Denis Caruana / Kristen Cachia | C34: 7 | D34: =IF(C34>C36,1,0) -> 1 | F34: 6 | G34: =IF(F34>F36,1,0) -> 1 | J34: =IF(I34>I36,1,0) -> 0 | K34: =IF(D34+G34=2,3,IF(D34+G34=1,1,0)) -> 3 | L34: =IF(K34=3,3,IF(J34+K34=2,2,IF(K34=1,1,0))) -> 3 | M34: =C34+F34 -> 13 | N34: =D34+G34+J34 -> 2 | Q34: =AE14 -> James Farrugia / Jean Paul Vella | R34: 6 | S34: =IF(R34>R36,1,0) -> 1 | U34: 6 | V34: =IF(U34>U36,1,0) -> 1 | Y34: =IF(X34>X36,1,0) -> 0 | Z34: =IF(S34+V34=2,3,IF(S34+V34=1,1,0)) -> 3 | AA34: =IF(Z34=3,3,IF(Y34+Z34=2,2,IF(Z34=1,1,0))) -> 3 | AB34: =R34+U34 -> 12 | AC34: =S34+V34+Y34 -> 2
B35: vs. | Q35: vs.
B36: =AE21 -> Stephen Belli / Matthew Schembri | C36: 6 | D36: =IF(C36>C34,1,0) -> 0 | F36: 2 | G36: =IF(F36>F34,1,0) -> 0 | J36: =IF(I36>I34,1,0) -> 0 | K36: =IF(D36+G36=2,3,IF(D36+G36=1,1,0)) -> 0 | L36: =IF(K36=3,3,IF(J36+K36=2,2,IF(K36=1,1,0))) -> 0 | M36: =C36+F36 -> 8 | N36: =D36+G36+J36 -> 0 | Q36: =AE16 -> Denis Caruana / Kristen Cachia | R36: 1 | S36: =IF(R36>R34,1,0) -> 0 | U36: 0 | V36: =IF(U36>U34,1,0) -> 0 | Y36: =IF(X36>X34,1,0) -> 0 | Z36: =IF(S36+V36=2,3,IF(S36+V36=1,1,0)) -> 0 | AA36: =IF(Z36=3,3,IF(Y36+Z36=2,2,IF(Z36=1,1,0))) -> 0 | AB36: =R36+U36 -> 1 | AC36: =S36+V36+Y36 -> 0
A37: Work | C37: =IF(C34="",0,1) -> 1 | F37: =IF(C36="",0,1) -> 1 | P37: Work | R37: =IF(R34="",0,1) -> 1 | U37: =IF(R36="",0,1) -> 1
B39: =AE14 -> James Farrugia / Jean Paul Vella | C39: 6 | D39: =IF(C39>C41,1,0) -> 1 | F39: 6 | G39: =IF(F39>F41,1,0) -> 1 | J39: =IF(I39>I41,1,0) -> 0 | K39: =IF(D39+G39=2,3,IF(D39+G39=1,1,0)) -> 3 | L39: =IF(K39=3,3,IF(J39+K39=2,2,IF(K39=1,1,0))) -> 3 | M39: =C39+F39 -> 12 | N39: =D39+G39+J39 -> 2 | Q39: =AE14 -> James Farrugia / Jean Paul Vella | R39: 6 | S39: =IF(R39>R41,1,0) -> 1 | U39: 6 | V39: =IF(U39>U41,1,0) -> 1 | Y39: =IF(X39>X41,1,0) -> 0 | Z39: =IF(S39+V39=2,3,IF(S39+V39=1,1,0)) -> 3 | AA39: =IF(Z39=3,3,IF(Y39+Z39=2,2,IF(Z39=1,1,0))) -> 3 | AB39: =R39+U39 -> 12 | AC39: =S39+V39+Y39 -> 2
B40: vs. | Q40: vs.
B41: =AE19 -> Manuel Mifsud / Julian Esposito | C41: 4 | D41: =IF(C41>C39,1,0) -> 0 | F41: 1 | G41: =IF(F41>F39,1,0) -> 0 | J41: =IF(I41>I39,1,0) -> 0 | K41: =IF(D41+G41=2,3,IF(D41+G41=1,1,0)) -> 0 | L41: =IF(K41=3,3,IF(J41+K41=2,2,IF(K41=1,1,0))) -> 0 | M41: =C41+F41 -> 5 | N41: =D41+G41+J41 -> 0 | Q41: =AE21 -> Stephen Belli / Matthew Schembri | R41: 2 | S41: =IF(R41>R39,1,0) -> 0 | U41: 4 | V41: =IF(U41>U39,1,0) -> 0 | Y41: =IF(X41>X39,1,0) -> 0 | Z41: =IF(S41+V41=2,3,IF(S41+V41=1,1,0)) -> 0 | AA41: =IF(Z41=3,3,IF(Y41+Z41=2,2,IF(Z41=1,1,0))) -> 0 | AB41: =R41+U41 -> 6 | AC41: =S41+V41+Y41 -> 0
A42: Work | C42: =IF(C39="",0,1) -> 1 | F42: =IF(C41="",0,1) -> 1 | P42: Work | R42: =IF(R39="",0,1) -> 1 | U42: =IF(R41="",0,1) -> 1
B44: =AE16 -> Denis Caruana / Kristen Cachia | C44: 6 | D44: =IF(C44>C46,1,0) -> 1 | F44: 6 | G44: =IF(F44>F46,1,0) -> 0 | I44: 10 | J44: =IF(I44>I46,1,0) -> 1 | K44: =IF(D44+G44=2,3,IF(D44+G44=1,1,0)) -> 1 | L44: =IF(K44=3,3,IF(J44+K44=2,2,IF(K44=1,1,0))) -> 2 | M44: =C44+F44 -> 12 | N44: =D44+G44+J44 -> 2
B45: vs.
B46: =AE19 -> Manuel Mifsud / Julian Esposito | C46: 1 | D46: =IF(C46>C44,1,0) -> 0 | F46: 7 | G46: =IF(F46>F44,1,0) -> 1 | I46: 8 | J46: =IF(I46>I44,1,0) -> 0 | K46: =IF(D46+G46=2,3,IF(D46+G46=1,1,0)) -> 1 | L46: =IF(K46=3,3,IF(J46+K46=2,2,IF(K46=1,1,0))) -> 1 | M46: =C46+F46 -> 8 | N46: =D46+G46+J46 -> 1
A47: Work | C47: =IF(C44="",0,1) -> 1 | F47: =IF(C46="",0,1) -> 1

Sheet Men Div 4
A1: VITTORIOSA LAWN TENNIS CLUB
A2: Sports Experience Chosen Doubles 2023
B5: Men Division 4
B7: Players | C7: Set Scores | I7: Tie | Q7: Players | R7: Set Scores | X7: Tie | AE7: Player | AF7: Games | AG7: Points | AH7: Games Won | AI7: Sets Won
C8: Score | D8: Set 1 Work | F8: Score | G8: Set 2 Work | I8: Score | J8: Tie Work | K8: Sets Points Work | L8: Sets & Tie Points Work | M8: Games Wins Work | N8: Sets Wins Work | R8: Score | S8: Set 1 Work | U8: Score | V8: Set 2 Work | X8: Score | Y8: Tie Work | Z8: Sets Points Work | AA8: Sets & Tie Points Work | AB8: Games Wins Work | AC8: Sets Wins Work | AJ8: To See Winners | AK8: Total Games Work | AL8: Player 1 Work
B9: =AE9 -> Charles Micallef / Twanny Pule | C9: 6 | D9: =IF(C9>C11,1,0) -> 1 | F9: 6 | G9: =IF(F9>F11,1,0) -> 1 | J9: =IF(I9>I11,1,0) -> 0 | K9: =IF(D9+G9=2,3,IF(D9+G9=1,1,0)) -> 3 | L9: =IF(K9=3,3,IF(J9+K9=2,2,IF(K9=1,1,0))) -> 3 | M9: =C9+F9 -> 12 | N9: =D9+G9+J9 -> 2 | Q9: =AE9 -> Charles Micallef / Twanny Pule | R9: 7 | S9: =IF(R9>R11,1,0) -> 1 | U9: 1 | V9: =IF(U9>U11,1,0) -> 0 | X9: 9 | Y9: =IF(X9>X11,1,0) -> 0 | Z9: =IF(S9+V9=2,3,IF(S9+V9=1,1,0)) -> 1 | AA9: =IF(Z9=3,3,IF(Y9+Z9=2,2,IF(Z9=1,1,0))) -> 1 | AB9: =R9+U9 -> 8 | AC9: =S9+V9+Y9 -> 1 | AE9: ='Players Men'!B29& " / " &'Players Men'!C29 -> Charles Micallef / Twanny Pule | AF9: =C12+R12+C17+R17+C22 -> 5 | AG9: =L9+AA9+L14+AA14+L19 -> 9 | AH9: =M9+AB9+M14+AB14+M19 -> 47 | AI9: =N9+AC9+N14+AC14+N19 -> 7 | AJ9: =MAX(AG16,AG14,AG11,AG9,AG19,AG21) -> 15 | AK9: =SUM(AF9:AF21) -> 30 | AL9: =IF(AG9=$AJ$9,AE9,IF(AG11=$AJ$9,AE11,IF(AG14=$AJ$9,AE14,IF(AG16=$AJ$9,AE16,IF(AG19=$AJ$9,AE19,IF(AG21=$AJ$9,AE21,"")))))) -> Jayboy Lastimosa / Cyril Lastimosa
B10: vs. | Q10: vs.
B11: =AE11 -> Simone Re / David Camilleri | C11: 4 | D11: =IF(C11>C9,1,0) -> 0 | F11: 4 | G11: =IF(F11>F9,1,0) -> 0 | J11: =IF(I11>I9,1,0) -> 0 | K11: =IF(D11+G11=2,3,IF(D11+G11=1,1,0)) -> 0 | L11: =IF(K11=3,3,IF(J11+K11=2,2,IF(K11=1,1,0))) -> 0 | M11: =C11+F11 -> 8 | N11: =D11+G11+J11 -> 0 | Q11: =AE14 -> Ryan Ebejer / Etienne Formosa Carabez | R11: 6 | S11: =IF(R11>R9,1,0) -> 0 | U11: 6 | V11: =IF(U11>U9,1,0) -> 1 | X11: 11 | Y11: =IF(X11>X9,1,0) -> 1 | Z11: =IF(S11+V11=2,3,IF(S11+V11=1,1,0)) -> 1 | AA11: =IF(Z11=3,3,IF(Y11+Z11=2,2,IF(Z11=1,1,0))) -> 2 | AB11: =R11+U11 -> 12 | AC11: =S11+V11+Y11 -> 2 | AE11: ='Players Men'!B30& " / " &'Players Men'!C30 -> Simone Re / David Camilleri | AF11: =F12+R32+C32+R27+C27 -> 5 | AG11: =L11+AA29+L29+AA24+L24 -> 6 | AH11: =M11+AB29+M29+AB24+M24 -> 39 | AI11: =N11+AC29+N29+AC24+N24 -> 5
A12: Work | C12: =IF(C9="",0,1) -> 1 | F12: =IF(C11="",0,1) -> 1 | P12: Work | R12: =IF(R9="",0,1) -> 1 | U12: =IF(R11="",0,1) -> 1
B14: =AE9 -> Charles Micallef / Twanny Pule | C14: 1 | D14: =IF(C14>C16,1,0) -> 0 | F14: 4 | G14: =IF(F14>F16,1,0) -> 0 | J14: =IF(I14>I16,1,0) -> 0 | K14: =IF(D14+G14=2,3,IF(D14+G14=1,1,0)) -> 0 | L14: =IF(K14=3,3,IF(J14+K14=2,2,IF(K14=1,1,0))) -> 0 | M14: =C14+F14 -> 5 | N14: =D14+G14+J14 -> 0 | Q14: =AE9 -> Charles Micallef / Twanny Pule | R14: 3 | S14: =IF(R14>R16,1,0) -> 0 | U14: 7 | V14: =IF(U14>U16,1,0) -> 1 | X14: 10 | Y14: =IF(X14>X16,1,0) -> 1 | Z14: =IF(S14+V14=2,3,IF(S14+V14=1,1,0)) -> 1 | AA14: =IF(Z14=3,3,IF(Y14+Z14=2,2,IF(Z14=1,1,0))) -> 2 | AB14: =R14+U14 -> 10 | AC14: =S14+V14+Y14 -> 2 | AE14: ='Players Men'!B31& " / " &'Players Men'!C31 -> Ryan Ebejer / Etienne Formosa Carabez | AF14: =R37+U12+R42+C42+F27 -> 5 | AG14: =AA34+AA11+AA39+L39+L26 -> 10 | AH14: =AB34+AB11+AB39+M39+M26 -> 51 | AI14: =AC34+AC11+AC39+N39+N26 -> 8
B15: vs. | Q15: vs.
B16: =AE16 -> Jayboy Lastimosa / Cyril Lastimosa | C16: 6 | D16: =IF(C16>C14,1,0) -> 1 | F16: 6 | G16: =IF(F16>F14,1,0) -> 1 | J16: =IF(I16>I14,1,0) -> 0 | K16: =IF(D16+G16=2,3,IF(D16+G16=1,1,0)) -> 3 | L16: =IF(K16=3,3,IF(J16+K16=2,2,IF(K16=1,1,0))) -> 3 | M16: =C16+F16 -> 12 | N16: =D16+G16+J16 -> 2 | Q16: =AE19 -> Isaac Joseph Zammit / Conrad Treeby Ward | R16: 6 | S16: =IF(R16>R14,1,0) -> 1 | U16: 5 | V16: =IF(U16>U14,1,0) -> 0 | X16: 5 | Y16: =IF(X16>X14,1,0) -> 0 | Z16: =IF(S16+V16=2,3,IF(S16+V16=1,1,0)) -> 1 | AA16: =IF(Z16=3,3,IF(Y16+Z16=2,2,IF(Z16=1,1,0))) -> 1 | AB16: =R16+U16 -> 11 | AC16: =S16+V16+Y16 -> 1 | AE16: ='Players Men'!B32& " / " &'Players Men'!C32 -> Jayboy Lastimosa / Cyril Lastimosa | AF16: =U37+C47+F17+U27+C37 -> 5 | AG16: =AA36+L44+L16+AA26+L34 -> 15 | AH16: =AB36+M44+M16+AB26+M34 -> 60 | AI16: =AC36+N44+N16+AC26+N34 -> 10
A17: Work | C17: =IF(C14="",0,1) -> 1 | F17: =IF(C16="",0,1) -> 1 | P17: Work | R17: =IF(R14="",0,1) -> 1 | U17: =IF(R16="",0,1) -> 1
B19: =AE9 -> Charles Micallef / Twanny Pule | C19: 6 | D19: =IF(C19>C21,1,0) -> 1 | F19: 6 | G19: =IF(F19>F21,1,0) -> 1 | J19: =IF(I19>I21,1,0) -> 0 | K19: =IF(D19+G19=2,3,IF(D19+G19=1,1,0)) -> 3 | L19: =IF(K19=3,3,IF(J19+K19=2,2,IF(K19=1,1,0))) -> 3 | M19: =C19+F19 -> 12 | N19: =D19+G19+J19 -> 2 | Q19: =AE19 -> Isaac Joseph Zammit / Conrad Treeby Ward | R19: 7 | S19: =IF(R19>R21,1,0) -> 1 | U19: 6 | V19: =IF(U19>U21,1,0) -> 1 | Y19: =IF(X19>X21,1,0) -> 0 | Z19: =IF(S19+V19=2,3,IF(S19+V19=1,1,0)) -> 3 | AA19: =IF(Z19=3,3,IF(Y19+Z19=2,2,IF(Z19=1,1,0))) -> 3 | AB19: =R19+U19 -> 13 | AC19: =S19+V19+Y19 -> 2 | AE19: ='Players Men'!B33& " / " &'Players Men'!C33 -> Isaac Joseph Zammit / Conrad Treeby Ward | AF19: =R22+F47+F32+U17+F42 -> 5 | AG19: =AA19+L46+L31+AA16+L41 -> 5 | AH19: =AB19+M46+M31+AB16+M41 -> 37 | AI19: =AC19+N46+N31+AC16+N41 -> 4
B20: vs. | Q20: vs.
B21: =AE21 -> Ivan Saliba / Clayton Saliba Hersey | C21: 3 | D21: =IF(C21>C19,1,0) -> 0 | F21: 3 | G21: =IF(F21>F19,1,0) -> 0 | J21: =IF(I21>I19,1,0) -> 0 | K21: =IF(D21+G21=2,3,IF(D21+G21=1,1,0)) -> 0 | L21: =IF(K21=3,3,IF(J21+K21=2,2,IF(K21=1,1,0))) -> 0 | M21: =C21+F21 -> 6 | N21: =D21+G21+J21 -> 0 | Q21: =AE21 -> Ivan Saliba / Clayton Saliba Hersey | R21: 5 | S21: =IF(R21>R19,1,0) -> 0 | U21: 3 | V21: =IF(U21>U19,1,0) -> 0 | Y21: =IF(X21>X19,1,0) -> 0 | Z21: =IF(S21+V21=2,3,IF(S21+V21=1,1,0)) -> 0 | AA21: =IF(Z21=3,3,IF(Y21+Z21=2,2,IF(Z21=1,1,0))) -> 0 | AB21: =R21+U21 -> 8 | AC21: =S21+V21+Y21 -> 0 | AE21: ='Players Men'!B34& " / " &'Players Men'!C34 -> Ivan Saliba / Clayton Saliba Hersey | AF21: =U22+U32+U42+F22+F37 -> 5 | AG21: =AA21+AA31+AA41+L21+L36 -> 0 | AH21: =AB21+AB31+AB41+M21+M36 -> 25 | AI21: =AC21+AC31+AC41+N21+N36 -> 0
A22: Work | C22: =IF(C19="",0,1) -> 1 | F22: =IF(C21="",0,1) -> 1 | P22: Work | R22: =IF(R19="",0,1) -> 1 | U22: =IF(R21="",0,1) -> 1
B24: =AE11 -> Simone Re / David Camilleri | C24: 7 | D24: =IF(C24>C26,1,0) -> 1 | F24: 2 | G24: =IF(F24>F26,1,0) -> 0 | I24: 5 | J24: =IF(I24>I26,1,0) -> 0 | K24: =IF(D24+G24=2,3,IF(D24+G24=1,1,0)) -> 1 | L24: =IF(K24=3,3,IF(J24+K24=2,2,IF(K24=1,1,0))) -> 1 | M24: =C24+F24 -> 9 | N24: =D24+G24+J24 -> 1 | Q24: =AE11 -> Simone Re / David Camilleri | R24: 0 | S24: =IF(R24>R26,1,0) -> 0 | U24: 0 | V24: =IF(U24>U26,1,0) -> 0 | Y24: =IF(X24>X26,1,0) -> 0 | Z24: =IF(S24+V24=2,3,IF(S24+V24=1,1,0)) -> 0 | AA24: =IF(Z24=3,3,IF(Y24+Z24=2,2,IF(Z24=1,1,0))) -> 0 | AB24: =R24+U24 -> 0 | AC24: =S24+V24+Y24 -> 0 | AE24: Divison Winner
B25: vs. | Q25: vs. | AE25: Jayboy Lastimosa/Cyril Lastimosa
B26: =AE14 -> Ryan Ebejer / Etienne Formosa Carabez | C26: 5 | D26: =IF(C26>C24,1,0) -> 0 | F26: 6 | G26: =IF(F26>F24,1,0) -> 1 | I26: 10 | J26: =IF(I26>I24,1,0) -> 1 | K26: =IF(D26+G26=2,3,IF(D26+G26=1,1,0)) -> 1 | L26: =IF(K26=3,3,IF(J26+K26=2,2,IF(K26=1,1,0))) -> 2 | M26: =C26+F26 -> 11 | N26: =D26+G26+J26 -> 2 | Q26: =AE16 -> Jayboy Lastimosa / Cyril Lastimosa | R26: 6 | S26: =IF(R26>R24,1,0) -> 1 | U26: 6 | V26: =IF(U26>U24,1,0) -> 1 | Y26: =IF(X26>X24,1,0) -> 0 | Z26: =IF(S26+V26=2,3,IF(S26+V26=1,1,0)) -> 3 | AA26: =IF(Z26=3,3,IF(Y26+Z26=2,2,IF(Z26=1,1,0))) -> 3 | AB26: =R26+U26 -> 12 | AC26: =S26+V26+Y26 -> 2 | AE26: Divison Runner Up
A27: Work | C27: =IF(C24="",0,1) -> 1 | F27: =IF(C26="",0,1) -> 1 | P27: Work | R27: =IF(R24="",0,1) -> 1 | U27: =IF(R26="",0,1) -> 1 | AE27: =IF(AK11=42,AL11,"")
AE28: Ryan Ebejer/Etienne Formosa Carabez
B29: =AE11 -> Simone Re / David Camilleri | C29: 3 | D29: =IF(C29>C31,1,0) -> 0 | F29: 6 | G29: =IF(F29>F31,1,0) -> 1 | I29: 10 | J29: =IF(I29>I31,1,0) -> 1 | K29: =IF(D29+G29=2,3,IF(D29+G29=1,1,0)) -> 1 | L29: =IF(K29=3,3,IF(J29+K29=2,2,IF(K29=1,1,0))) -> 2 | M29: =C29+F29 -> 9 | N29: =D29+G29+J29 -> 2 | Q29: =AE11 -> Simone Re / David Camilleri | R29: 7 | S29: =IF(R29>R31,1,0) -> 1 | U29: 6 | V29: =IF(U29>U31,1,0) -> 1 | Y29: =IF(X29>X31,1,0) -> 0 | Z29: =IF(S29+V29=2,3,IF(S29+V29=1,1,0)) -> 3 | AA29: =IF(Z29=3,3,IF(Y29+Z29=2,2,IF(Z29=1,1,0))) -> 3 | AB29: =R29+U29 -> 13 | AC29: =S29+V29+Y29 -> 2
B30: vs. | Q30: vs.
B31: =AE19 -> Isaac Joseph Zammit / Conrad Treeby Ward | C31: 6 | D31: =IF(C31>C29,1,0) -> 1 | F31: 0 | G31: =IF(F31>F29,1,0) -> 0 | I31: 8 | J31: =IF(I31>I29,1,0) -> 0 | K31: =IF(D31+G31=2,3,IF(D31+G31=1,1,0)) -> 1 | L31: =IF(K31=3,3,IF(J31+K31=2,2,IF(K31=1,1,0))) -> 1 | M31: =C31+F31 -> 6 | N31: =D31+G31+J31 -> 1 | Q31: =AE21 -> Ivan Saliba / Clayton Saliba Hersey | R31: 5 | S31: =IF(R31>R29,1,0) -> 0 | U31: 1 | V31: =IF(U31>U29,1,0) -> 0 | Y31: =IF(X31>X29,1,0) -> 0 | Z31: =IF(S31+V31=2,3,IF(S31+V31=1,1,0)) -> 0 | AA31: =IF(Z31=3,3,IF(Y31+Z31=2,2,IF(Z31=1,1,0))) -> 0 | AB31: =R31+U31 -> 6 | AC31: =S31+V31+Y31 -> 0
A32: Work | C32: =IF(C29="",0,1) -> 1 | F32: =IF(C31="",0,1) -> 1 | P32: Work | R32: =IF(R29="",0,1) -> 1 | U32: =IF(R31="",0,1) -> 1
B34: =AE16 -> Jayboy Lastimosa / Cyril Lastimosa | C34: 6 | D34: =IF(C34>C36,1,0) -> 1 | F34: 6 | G34: =IF(F34>F36,1,0) -> 1 | J34: =IF(I34>I36,1,0) -> 0 | K34: =IF(D34+G34=2,3,IF(D34+G34=1,1,0)) -> 3 | L34: =IF(K34=3,3,IF(J34+K34=2,2,IF(K34=1,1,0))) -> 3 | M34: =C34+F34 -> 12 | N34: =D34+G34+J34 -> 2 | Q34: =AE14 -> Ryan Ebejer / Etienne Formosa Carabez | R34: 2 | S34: =IF(R34>R36,1,0) -> 0 | U34: 2 | V34: =IF(U34>U36,1,0) -> 0 | Y34: =IF(X34>X36,1,0) -> 0 | Z34: =IF(S34+V34=2,3,IF(S34+V34=1,1,0)) -> 0 | AA34: =IF(Z34=3,3,IF(Y34+Z34=2,2,IF(Z34=1,1,0))) -> 0 | AB34: =R34+U34 -> 4 | AC34: =S34+V34+Y34 -> 0
B35: vs. | Q35: vs.
B36: =AE21 -> Ivan Saliba / Clayton Saliba Hersey | C36: 0 | D36: =IF(C36>C34,1,0) -> 0 | F36: 2 | G36: =IF(F36>F34,1,0) -> 0 | J36: =IF(I36>I34,1,0) -> 0 | K36: =IF(D36+G36=2,3,IF(D36+G36=1,1,0)) -> 0 | L36: =IF(K36=3,3,IF(J36+K36=2,2,IF(K36=1,1,0))) -> 0 | M36: =C36+F36 -> 2 | N36: =D36+G36+J36 -> 0 | Q36: =AE16 -> Jayboy Lastimosa / Cyril Lastimosa | R36: 6 | S36: =IF(R36>R34,1,0) -> 1 | U36: 6 | V36: =IF(U36>U34,1,0) -> 1 | Y36: =IF(X36>X34,1,0) -> 0 | Z36: =IF(S36+V36=2,3,IF(S36+V36=1,1,0)) -> 3 | AA36: =IF(Z36=3,3,IF(Y36+Z36=2,2,IF(Z36=1,1,0))) -> 3 | AB36: =R36+U36 -> 12 | AC36: =S36+V36+Y36 -> 2
A37: Work | C37: =IF(C34="",0,1) -> 1 | F37: =IF(C36="",0,1) -> 1 | P37: Work | R37: =IF(R34="",0,1) -> 1 | U37: =IF(R36="",0,1) -> 1
B39: =AE14 -> Ryan Ebejer / Etienne Formosa Carabez | C39: 6 | D39: =IF(C39>C41,1,0) -> 1 | F39: 6 | G39: =IF(F39>F41,1,0) -> 1 | J39: =IF(I39>I41,1,0) -> 0 | K39: =IF(D39+G39=2,3,IF(D39+G39=1,1,0)) -> 3 | L39: =IF(K39=3,3,IF(J39+K39=2,2,IF(K39=1,1,0))) -> 3 | M39: =C39+F39 -> 12 | N39: =D39+G39+J39 -> 2 | Q39: =AE14 -> Ryan Ebejer / Etienne Formosa Carabez | R39: 6 | S39: =IF(R39>R41,1,0) -> 1 | U39: 6 | V39: =IF(U39>U41,1,0) -> 1 | Y39: =IF(X39>X41,1,0) -> 0 | Z39: =IF(S39+V39=2,3,IF(S39+V39=1,1,0)) -> 3 | AA39: =IF(Z39=3,3,IF(Y39+Z39=2,2,IF(Z39=1,1,0))) -> 3 | AB39: =R39+U39 -> 12 | AC39: =S39+V39+Y39 -> 2
B40: vs. | Q40: vs.
B41: =AE19 -> Isaac Joseph Zammit / Conrad Treeby Ward | C41: 2 | D41: =IF(C41>C39,1,0) -> 0 | F41: 2 | G41: =IF(F41>F39,1,0) -> 0 | J41: =IF(I41>I39,1,0) -> 0 | K41: =IF(D41+G41=2,3,IF(D41+G41=1,1,0)) -> 0 | L41: =IF(K41=3,3,IF(J41+K41=2,2,IF(K41=1,1,0))) -> 0 | M41: =C41+F41 -> 4 | N41: =D41+G41+J41 -> 0 | Q41: =AE21 -> Ivan Saliba / Clayton Saliba Hersey | R41: 3 | S41: =IF(R41>R39,1,0) -> 0 | U41: 0 | V41: =IF(U41>U39,1,0) -> 0 | Y41: =IF(X41>X39,1,0) -> 0 | Z41: =IF(S41+V41=2,3,IF(S41+V41=1,1,0)) -> 0 | AA41: =IF(Z41=3,3,IF(Y41+Z41=2,2,IF(Z41=1,1,0))) -> 0 | AB41: =R41+U41 -> 3 | AC41: =S41+V41+Y41 -> 0
A42: Work | C42: =IF(C39="",0,1) -> 1 | F42: =IF(C41="",0,1) -> 1 | P42: Work | R42: =IF(R39="",0,1) -> 1 | U42: =IF(R41="",0,1) -> 1
B44: =AE16 -> Jayboy Lastimosa / Cyril Lastimosa | C44: 6 | D44: =IF(C44>C46,1,0) -> 1 | F44: 6 | G44: =IF(F44>F46,1,0) -> 1 | J44: =IF(I44>I46,1,0) -> 0 | K44: =IF(D44+G44=2,3,IF(D44+G44=1,1,0)) -> 3 | L44: =IF(K44=3,3,IF(J44+K44=2,2,IF(K44=1,1,0))) -> 3 | M44: =C44+F44 -> 12 | N44: =D44+G44+J44 -> 2
B45: vs.
B46: =AE19 -> Isaac Joseph Zammit / Conrad Treeby Ward | C46: 2 | D46: =IF(C46>C44,1,0) -> 0 | F46: 1 | G46: =IF(F46>F44,1,0) -> 0 | J46: =IF(I46>I44,1,0) -> 0 | K46: =IF(D46+G46=2,3,IF(D46+G46=1,1,0)) -> 0 | L46: =IF(K46=3,3,IF(J46+K46=2,2,IF(K46=1,1,0))) -> 0 | M46: =C46+F46 -> 3 | N46: =D46+G46+J46 -> 0
A47: Work | C47: =IF(C44="",0,1) -> 1 | F47: =IF(C46="",0,1) -> 1

Sheet Men Div 5
A1: VITTORIOSA LAWN TENNIS CLUB
A2: Sports Experience Chosen Doubles 2023
B5: Men Division 5
B7: Players | C7: Set Scores | I7: Tie | Q7: Players | R7: Set Scores | X7: Tie | AE7: Player | AF7: Games | AG7: Points | AH7: Games Won | AI7: Sets Won
C8: Score | D8: Set 1 Work | F8: Score | G8: Set 2 Work | I8: Score | J8: Tie Work | K8: Sets Points Work | L8: Sets & Tie Points Work | M8: Games Wins Work | N8: Sets Wins Work | R8: Score | S8: Set 1 Work | U8: Score | V8: Set 2 Work | X8: Score | Y8: Tie Work | Z8: Sets Points Work | AA8: Sets & Tie Points Work | AB8: Games Wins Work | AC8: Sets Wins Work | AJ8: To See Winners | AK8: Total Games Work | AL8: Player 1 Work
B9: =AE9 -> Kenneth Farrugia / Juan Sammut | C9: 6 | D9: =IF(C9>C11,1,0) -> 1 | F9: 6 | G9: =IF(F9>F11,1,0) -> 1 | J9: =IF(I9>I11,1,0) -> 0 | K9: =IF(D9+G9=2,3,IF(D9+G9=1,1,0)) -> 3 | L9: =IF(K9=3,3,IF(J9+K9=2,2,IF(K9=1,1,0))) -> 3 | M9: =C9+F9 -> 12 | N9: =D9+G9+J9 -> 2 | Q9: =AE9 -> Kenneth Farrugia / Juan Sammut | R9: 6 | S9: =IF(R9>R11,1,0) -> 1 | U9: 1 | V9: =IF(U9>U11,1,0) -> 0 | X9: 10 | Y9: =IF(X9>X11,1,0) -> 1 | Z9: =IF(S9+V9=2,3,IF(S9+V9=1,1,0)) -> 1 | AA9: =IF(Z9=3,3,IF(Y9+Z9=2,2,IF(Z9=1,1,0))) -> 2 | AB9: =R9+U9 -> 7 | AC9: =S9+V9+Y9 -> 2 | AE9: ='Players Men'!B37& " / " &'Players Men'!C37 -> Kenneth Farrugia / Juan Sammut | AF9: =C12+R12+C17+R17+C22 -> 4 | AG9: =L9+AA9+L14+AA14+L19 -> 7 | AH9: =M9+AB9+M14+AB14+M19 -> 36 | AI9: =N9+AC9+N14+AC14+N19 -> 6 | AJ9: =MAX(AG16,AG14,AG11,AG9,AG19,AG21) -> 9 | AK9: =SUM(AF9:AF21) -> 20 | AL9: =IF(AG9=$AJ$9,AE9,IF(AG11=$AJ$9,AE11,IF(AG14=$AJ$9,AE14,IF(AG16=$AJ$9,AE16,IF(AG19=$AJ$9,AE19,IF(AG21=$AJ$9,AE21,"")))))) -> Sean Cachia / Antoine Bugeja
B10: vs. | Q10: vs.
B11: =AE11 -> Donald Deguzman / Teddy Padullon | C11: 0 | D11: =IF(C11>C9,1,0) -> 0 | F11: 0 | G11: =IF(F11>F9,1,0) -> 0 | J11: =IF(I11>I9,1,0) -> 0 | K11: =IF(D11+G11=2,3,IF(D11+G11=1,1,0)) -> 0 | L11: =IF(K11=3,3,IF(J11+K11=2,2,IF(K11=1,1,0))) -> 0 | M11: =C11+F11 -> 0 | N11: =D11+G11+J11 -> 0 | Q11: =AE14 -> Mark Cini / Dunstan Vella | R11: 4 | S11: =IF(R11>R9,1,0) -> 0 | U11: 6 | V11: =IF(U11>U9,1,0) -> 1 | X11: 5 | Y11: =IF(X11>X9,1,0) -> 0 | Z11: =IF(S11+V11=2,3,IF(S11+V11=1,1,0)) -> 1 | AA11: =IF(Z11=3,3,IF(Y11+Z11=2,2,IF(Z11=1,1,0))) -> 1 | AB11: =R11+U11 -> 10 | AC11: =S11+V11+Y11 -> 1 | AE11: ='Players Men'!B38& " / " &'Players Men'!C38 -> Donald Deguzman / Teddy Padullon | AF11: =F12+R32+C32+R27+C27 -> 4 | AG11: =L11+AA29+L29+AA24+L24 -> 3 | AH11: =M11+AB29+M29+AB24+M24 -> 15 | AI11: =N11+AC29+N29+AC24+N24 -> 2
A12: Work | C12: =IF(C9="",0,1) -> 1 | F12: =IF(C11="",0,1) -> 1 | P12: Work | R12: =IF(R9="",0,1) -> 1 | U12: =IF(R11="",0,1) -> 1
B14: =AE9 -> Kenneth Farrugia / Juan Sammut | C14: 4 | D14: =IF(C14>C16,1,0) -> 0 | F14: 1 | G14: =IF(F14>F16,1,0) -> 0 | J14: =IF(I14>I16,1,0) -> 0 | K14: =IF(D14+G14=2,3,IF(D14+G14=1,1,0)) -> 0 | L14: =IF(K14=3,3,IF(J14+K14=2,2,IF(K14=1,1,0))) -> 0 | M14: =C14+F14 -> 5 | N14: =D14+G14+J14 -> 0 | Q14: =AE9 -> Kenneth Farrugia / Juan Sammut | R14: 6 | S14: =IF(R14>R16,1,0) -> 1 | U14: 6 | V14: =IF(U14>U16,1,0) -> 0 | X14: 10 | Y14: =IF(X14>X16,1,0) -> 1 | Z14: =IF(S14+V14=2,3,IF(S14+V14=1,1,0)) -> 1 | AA14: =IF(Z14=3,3,IF(Y14+Z14=2,2,IF(Z14=1,1,0))) -> 2 | AB14: =R14+U14 -> 12 | AC14: =S14+V14+Y14 -> 2 | AE14: ='Players Men'!B39& " / " &'Players Men'!C39 -> Mark Cini / Dunstan Vella | AF14: =R37+U12+R42+C42+F27 -> 4 | AG14: =AA34+AA11+AA39+L39+L26 -> 7 | AH14: =AB34+AB11+AB39+M39+M26 -> 34 | AI14: =AC34+AC11+AC39+N39+N26 -> 5
B15: vs. | Q15: vs.
B16: =AE16 -> Sean Cachia / Antoine Bugeja | C16: 6 | D16: =IF(C16>C14,1,0) -> 1 | F16: 6 | G16: =IF(F16>F14,1,0) -> 1 | J16: =IF(I16>I14,1,0) -> 0 | K16: =IF(D16+G16=2,3,IF(D16+G16=1,1,0)) -> 3 | L16: =IF(K16=3,3,IF(J16+K16=2,2,IF(K16=1,1,0))) -> 3 | M16: =C16+F16 -> 12 | N16: =D16+G16+J16 -> 2 | Q16: =AE19 -> Robert Attard / Kevin Wood | R16: 3 | S16: =IF(R16>R14,1,0) -> 0 | U16: 7 | V16: =IF(U16>U14,1,0) -> 1 | X16: 8 | Y16: =IF(X16>X14,1,0) -> 0 | Z16: =IF(S16+V16=2,3,IF(S16+V16=1,1,0)) -> 1 | AA16: =IF(Z16=3,3,IF(Y16+Z16=2,2,IF(Z16=1,1,0))) -> 1 | AB16: =R16+U16 -> 10 | AC16: =S16+V16+Y16 -> 1 | AE16: ='Players Men'!B40& " / " &'Players Men'!C40 -> Sean Cachia / Antoine Bugeja | AF16: =U37+C47+F17+U27+C37 -> 4 | AG16: =AA36+L44+L16+AA26+L34 -> 9 | AH16: =AB36+M44+M16+AB26+M34 -> 43 | AI16: =AC36+N44+N16+AC26+N34 -> 6
A17: Work | C17: =IF(C14="",0,1) -> 1 | F17: =IF(C16="",0,1) -> 1 | P17: Work | R17: =IF(R14="",0,1) -> 1 | U17: =IF(R16="",0,1) -> 1
B19: =AE9 -> Kenneth Farrugia / Juan Sammut | J19: =IF(I19>I21,1,0) -> 0 | K19: =IF(D19+G19=2,3,IF(D19+G19=1,1,0)) -> 0 | L19: =IF(K19=3,3,IF(J19+K19=2,2,IF(K19=1,1,0))) -> 0 | M19: =C19+F19 -> 0 | N19: =D19+G19+J19 -> 0 | Q19: =AE19 -> Robert Attard / Kevin Wood | S19: =IF(R19>R21,1,0) -> 0 | V19: =IF(U19>U21,1,0) -> 0 | Y19: =IF(X19>X21,1,0) -> 0 | Z19: =IF(S19+V19=2,3,IF(S19+V19=1,1,0)) -> 0 | AA19: =IF(Z19=3,3,IF(Y19+Z19=2,2,IF(Z19=1,1,0))) -> 0 | AB19: =R19+U19 -> 0 | AC19: =S19+V19+Y19 -> 0 | AE19: ='Players Men'!B41& " / " &'Players Men'!C41 -> Robert Attard / Kevin Wood | AF19: =R22+F47+F32+U17+F42 -> 4 | AG19: =AA19+L46+L31+AA16+L41 -> 4 | AH19: =AB19+M46+M31+AB16+M41 -> 37 | AI19: =AC19+N46+N31+AC16+N41 -> 3
B20: vs. | Q20: vs.
B21: =AE21 -> Matthew Micallef / Chris Vella | J21: =IF(I21>I19,1,0) -> 0 | K21: =IF(D21+G21=2,3,IF(D21+G21=1,1,0)) -> 0 | L21: =IF(K21=3,3,IF(J21+K21=2,2,IF(K21=1,1,0))) -> 0 | M21: =C21+F21 -> 0 | N21: =D21+G21+J21 -> 0 | O21: Ret. | Q21: =AE21 -> Matthew Micallef / Chris Vella | S21: =IF(R21>R19,1,0) -> 0 | V21: =IF(U21>U19,1,0) -> 0 | Y21: =IF(X21>X19,1,0) -> 0 | Z21: =IF(S21+V21=2,3,IF(S21+V21=1,1,0)) -> 0 | AA21: =IF(Z21=3,3,IF(Y21+Z21=2,2,IF(Z21=1,1,0))) -> 0 | AB21: =R21+U21 -> 0 | AC21: =S21+V21+Y21 -> 0 | AE21: ='Players Men'!B42& " / " &'Players Men'!C42 -> Matthew Micallef / Chris Vella | AF21: =U22+U32+U42+F22+F37 -> 0 | AG21: =AA21+AA31+AA41+L21+L36 -> 0 | AH21: =AB21+AB31+AB41+M21+M36 -> 0 | AI21: =AC21+AC31+AC41+N21+N36 -> 0 | AM21: Withdrew due to injury Chris vella
A22: Work | C22: =IF(C19="",0,1) -> 0 | F22: =IF(C21="",0,1) -> 0 | P22: Work | R22: =IF(R19="",0,1) -> 0 | U22: =IF(R21="",0,1) -> 0
B24: =AE11 -> Donald Deguzman / Teddy Padullon | C24: 2 | D24: =IF(C24>C26,1,0) -> 0 | F24: 0 | G24: =IF(F24>F26,1,0) -> 0 | J24: =IF(I24>I26,1,0) -> 0 | K24: =IF(D24+G24=2,3,IF(D24+G24=1,1,0)) -> 0 | L24: =IF(K24=3,3,IF(J24+K24=2,2,IF(K24=1,1,0))) -> 0 | M24: =C24+F24 -> 2 | N24: =D24+G24+J24 -> 0 | Q24: =AE11 -> Donald Deguzman / Teddy Padullon | R24: 0 | S24: =IF(R24>R26,1,0) -> 0 | U24: 0 | V24: =IF(U24>U26,1,0) -> 0 | Y24: =IF(X24>X26,1,0) -> 0 | Z24: =IF(S24+V24=2,3,IF(S24+V24=1,1,0)) -> 0 | AA24: =IF(Z24=3,3,IF(Y24+Z24=2,2,IF(Z24=1,1,0))) -> 0 | AB24: =R24+U24 -> 0 | AC24: =S24+V24+Y24 -> 0 | AE24: Divison Winner
B25: vs. | Q25: vs. | AE25: Sean Cachia/Antoine Bugeja
B26: =AE14 -> Mark Cini / Dunstan Vella | C26: 6 | D26: =IF(C26>C24,1,0) -> 1 | F26: 6 | G26: =IF(F26>F24,1,0) -> 1 | J26: =IF(I26>I24,1,0) -> 0 | K26: =IF(D26+G26=2,3,IF(D26+G26=1,1,0)) -> 3 | L26: =IF(K26=3,3,IF(J26+K26=2,2,IF(K26=1,1,0))) -> 3 | M26: =C26+F26 -> 12 | N26: =D26+G26+J26 -> 2 | Q26: =AE16 -> Sean Cachia / Antoine Bugeja | R26: 6 | S26: =IF(R26>R24,1,0) -> 1 | U26: 6 | V26: =IF(U26>U24,1,0) -> 1 | Y26: =IF(X26>X24,1,0) -> 0 | Z26: =IF(S26+V26=2,3,IF(S26+V26=1,1,0)) -> 3 | AA26: =IF(Z26=3,3,IF(Y26+Z26=2,2,IF(Z26=1,1,0))) -> 3 | AB26: =R26+U26 -> 12 | AC26: =S26+V26+Y26 -> 2 | AE26: Divison Runner Up
A27: Work | C27: =IF(C24="",0,1) -> 1 | F27: =IF(C26="",0,1) -> 1 | P27: Work | R27: =IF(R24="",0,1) -> 1 | U27: =IF(R26="",0,1) -> 1 | AE27: =IF(AK11=42,AL11,"")
AE28: Kenneth Farrugia/Juan Sammut
B29: =AE11 -> Donald Deguzman / Teddy Padullon | C29: 6 | D29: =IF(C29>C31,1,0) -> 1 | F29: 7 | G29: =IF(F29>F31,1,0) -> 1 | J29: =IF(I29>I31,1,0) -> 0 | K29: =IF(D29+G29=2,3,IF(D29+G29=1,1,0)) -> 3 | L29: =IF(K29=3,3,IF(J29+K29=2,2,IF(K29=1,1,0))) -> 3 | M29: =C29+F29 -> 13 | N29: =D29+G29+J29 -> 2 | Q29: =AE11 -> Donald Deguzman / Teddy Padullon | S29: =IF(R29>R31,1,0) -> 0 | V29: =IF(U29>U31,1,0) -> 0 | Y29: =IF(X29>X31,1,0) -> 0 | Z29: =IF(S29+V29=2,3,IF(S29+V29=1,1,0)) -> 0 | AA29: =IF(Z29=3,3,IF(Y29+Z29=2,2,IF(Z29=1,1,0))) -> 0 | AB29: =R29+U29 -> 0 | AC29: =S29+V29+Y29 -> 0
B30: vs. | Q30: vs.
B31: =AE19 -> Robert Attard / Kevin Wood | C31: 2 | D31: =IF(C31>C29,1,0) -> 0 | F31: 5 | G31: =IF(F31>F29,1,0) -> 0 | J31: =IF(I31>I29,1,0) -> 0 | K31: =IF(D31+G31=2,3,IF(D31+G31=1,1,0)) -> 0 | L31: =IF(K31=3,3,IF(J31+K31=2,2,IF(K31=1,1,0))) -> 0 | M31: =C31+F31 -> 7 | N31: =D31+G31+J31 -> 0 | Q31: =AE21 -> Matthew Micallef / Chris Vella | S31: =IF(R31>R29,1,0) -> 0 | V31: =IF(U31>U29,1,0) -> 0 | Y31: =IF(X31>X29,1,0) -> 0 | Z31: =IF(S31+V31=2,3,IF(S31+V31=1,1,0)) -> 0 | AA31: =IF(Z31=3,3,IF(Y31+Z31=2,2,IF(Z31=1,1,0))) -> 0 | AB31: =R31+U31 -> 0 | AC31: =S31+V31+Y31 -> 0
A32: Work | C32: =IF(C29="",0,1) -> 1 | F32: =IF(C31="",0,1) -> 1 | P32: Work | R32: =IF(R29="",0,1) -> 0 | U32: =IF(R31="",0,1) -> 0
B34: =AE16 -> Sean Cachia / Antoine Bugeja | J34: =IF(I34>I36,1,0) -> 0 | K34: =IF(D34+G34=2,3,IF(D34+G34=1,1,0)) -> 0 | L34: =IF(K34=3,3,IF(J34+K34=2,2,IF(K34=1,1,0))) -> 0 | M34: =C34+F34 -> 0 | N34: =D34+G34+J34 -> 0 | Q34: =AE14 -> Mark Cini / Dunstan Vella | R34: 0 | S34: =IF(R34>R36,1,0) -> 0 | U34: 0 | V34: =IF(U34>U36,1,0) -> 0 | Y34: =IF(X34>X36,1,0) -> 0 | Z34: =IF(S34+V34=2,3,IF(S34+V34=1,1,0)) -> 0 | AA34: =IF(Z34=3,3,IF(Y34+Z34=2,2,IF(Z34=1,1,0))) -> 0 | AB34: =R34+U34 -> 0 | AC34: =S34+V34+Y34 -> 0
B35: vs. | Q35: vs.
B36: =AE21 -> Matthew Micallef / Chris Vella | J36: =IF(I36>I34,1,0) -> 0 | K36: =IF(D36+G36=2,3,IF(D36+G36=1,1,0)) -> 0 | L36: =IF(K36=3,3,IF(J36+K36=2,2,IF(K36=1,1,0))) -> 0 | M36: =C36+F36 -> 0 | N36: =D36+G36+J36 -> 0 | Q36: =AE16 -> Sean Cachia / Antoine Bugeja | R36: 6 | S36: =IF(R36>R34,1,0) -> 1 | U36: 6 | V36: =IF(U36>U34,1,0) -> 1 | Y36: =IF(X36>X34,1,0) -> 0 | Z36: =IF(S36+V36=2,3,IF(S36+V36=1,1,0)) -> 3 | AA36: =IF(Z36=3,3,IF(Y36+Z36=2,2,IF(Z36=1,1,0))) -> 3 | AB36: =R36+U36 -> 12 | AC36: =S36+V36+Y36 -> 2
A37: Work | C37: =IF(C34="",0,1) -> 0 | F37: =IF(C36="",0,1) -> 0 | P37: Work | R37: =IF(R34="",0,1) -> 1 | U37: =IF(R36="",0,1) -> 1
B39: =AE14 -> Mark Cini / Dunstan Vella | C39: 6 | D39: =IF(C39>C41,1,0) -> 1 | F39: 6 | G39: =IF(F39>F41,1,0) -> 1 | J39: =IF(I39>I41,1,0) -> 0 | K39: =IF(D39+G39=2,3,IF(D39+G39=1,1,0)) -> 3 | L39: =IF(K39=3,3,IF(J39+K39=2,2,IF(K39=1,1,0))) -> 3 | M39: =C39+F39 -> 12 | N39: =D39+G39+J39 -> 2 | Q39: =AE14 -> Mark Cini / Dunstan Vella | S39: =IF(R39>R41,1,0) -> 0 | V39: =IF(U39>U41,1,0) -> 0 | Y39: =IF(X39>X41,1,0) -> 0 | Z39: =IF(S39+V39=2,3,IF(S39+V39=1,1,0)) -> 0 | AA39: =IF(Z39=3,3,IF(Y39+Z39=2,2,IF(Z39=1,1,0))) -> 0 | AB39: =R39+U39 -> 0 | AC39: =S39+V39+Y39 -> 0
B40: vs. | Q40: vs.
